Workbook
Name CH4_Ar4_to_AR5: #REF!
Name gal_per_barrel: [1]About!$A$75
Name gal_per_barrel: #REF!
Name HHV_Adjust: [2]About!$A$211
Name IQ_CH: 110000
Name IQ_CQ: 5000
Name IQ_CY: 10000
Name IQ_DAILY: 500000
Name IQ_FH: 100000
Name IQ_FQ: 500
Name IQ_FY: 1000
Name IQ_LTM: 2000
Name IQ_MONTH: 15000
Name IQ_NTM: 6000
Name IQ_WEEK: 50000
Name IQ_YTD: 3000
Name metricton_to_shortton: #REF!
Name million: #REF!
Name N2O_AR4_to_AR5: #REF!
Name quadrillion: [2]About!$A$227
Name shorttons_to_grams: [2]About!$A$226
Name trillion: [2]About!$A$228
Name use_lifecycle_biofuel_EIs: [2]About!$A$97

Sheet About
A1: BPoEFUbVT BAU Perc of Each Fuel Used by Veh Technology
A3: Sources: | B3: most vehicles and fuels
B4: EIA
B5: 2021, 2022
B6: Annual Energy Outlook 2021, 2022
B7: https://www.eia.gov/outlooks/aeo/index.php
B8: Table 36
B10: biodiesel
B11: EIA
B12: 2021, 2022
B13: Annual Energy Outlook 2021, 2022
B14: https://www.eia.gov/outlooks/aeo/index.php
B15: Table 17
B17: fraction of electricity used by plug-in hybrids
... B25: EIA
B26: 2020
B27: Monthly Energy Review, May 2020
B28: https://www.eia.gov/energyexplained//biofuels/charts/fuel-ethanol-motor-gasoline.csv
A31: About
A32: We include sheets for all possible vehicle type / cargo type / vehicle technology
A33: combinations that the model supports, even though some combinations are not used
A34: in the U.S. dataset. (For example, there are no freight motorbikes in the U.S. model.)
A35: This is to support adaptation to other countries that may wish to use that vehicle
A36: combination. (For example, some countries may wish to represent three-wheeled,
A37: motorized carts used for urban hauling and commerce as freight motorbikes.
A38: Another example: battery electric freight HDVs barely exist today, but the model
A39: includes a sheet for them, so it can support them in the future without changing
A40: the model structure.)
A42: For the U.S., we have the quantity of biodiesel used in the transportation sector, but
A43: not divided by vehicle type. The "Biodiesel Fraction" tab includes calculations to
... A58: for them here contain zeroes.

Sheet EIA-fuel-ethanol-motor-gasoline
A1: U.S. fuel ethanol consumption and percent of total U.S. motor gasoline consumption, 1981-2019
A2: fuel ethanol consumption - billion gallons
A3: fuel ethanol % of motor gasoline consumption
A4: Note: Motor gasoline is finished motor gasoline.
A5: Source: U.S. Energy Information Administration, <em>Monthly Energy Review</em> and <em>Petroleum Supply Monthly</em>, May 2020
B7: consumption | C7: % of gasoline consumption
A8: 1981 | B8: 0.083 | C8: 0.08
A9: 1982 | B9: 0.226 | C9: 0.22
A10: 1983 | B10: 0.415 | C10: 0.41
A11: 1984 | B11: 0.51 | C11: 0.5
A12: 1985 | B12: 0.617 | C12: 0.59
A13: 1986 | B13: 0.712 | C13: 0.66
A14: 1987 | B14: 0.819 | C14: 0.74
A15: 1988 | B15: 0.831 | C15: 0.74
A16: 1989 | B16: 0.843 | C16: 0.75
A17: 1990 | B17: 0.748 | C17: 0.67
A18: 1991 | B18: 0.866 | C18: 0.79
A19: 1992 | B19: 0.985 | C19: 0.88
... A47: 2020 | B47: 12.629 | C47: 10.23

Sheet AEO Table 73
B1: ref2019.d111618a | C1: 2017 | D1: 2018 | E1: 2019 | F1: 2020 | G1: 2021 | H1: 2022 | I1: 2023 | J1: 2024 | K1: 2025 | L1: 2026 | M1: 2027 | N1: 2028 | O1: 2029 | P1: 2030 | Q1: 2031 | R1: 2032 | S1: 2033 | T1: 2034 | U1: 2035 | V1: 2036 | W1: 2037 | X1: 2038 | Y1: 2039 | Z1: 2040 | AA1: 2041 | AB1: 2042 | AC1: 2043 | AD1: 2044 | AE1: 2045 | AF1: 2046 | AG1: 2047 | AH1: 2048 | AI1: 2049 | AJ1: 2050
C3: Report | D3: Annual Energy Outlook 2019
C4: Scenario | D4: ref2019 | G4: Reference case
C5: Datekey | D5: d111618a
C6: Release Date | E6: January 2019
C9: =C32/C35 -> 0.96828263 | F9: =(C33-((1-0.102)*C35))/0.102 -> 3.5983878
A10: CNV000 | B10: 73. Conversion Factors
B11: (from physical units to million Btu)
AK12: 2018-
C13: 2017 | D13: 2018 | E13: 2019 | F13: 2020 | G13: 2021 | H13: 2022 | I13: 2023 | J13: 2024 | K13: 2025 | L13: 2026 | M13: 2027 | N13: 2028 | O13: 2029 | P13: 2030 | Q13: 2031 | R13: 2032 | S13: 2033 | T13: 2034 | U13: 2035 | V13: 2036 | W13: 2037 | X13: 2038 | Y13: 2039 | Z13: 2040 | AA13: 2041 | AB13: 2042 | AC13: 2043 | AD13: 2044 | AE13: 2045 | AF13: 2046 | AG13: 2047 | AH13: 2048 | AI13: 2049 | AJ13: 2050 | AK13: 2050
B14: Petroleum and Other Liquids
B15: (million Btu per barrel)
A16: CNV000:aa_AsphaltandRoa | B16: Asphalt and Road Oil | C16: 6.636 | D16: 6.636 | E16: 6.636 | F16: 6.636 | G16: 6.636 | H16: 6.636 | I16: 6.636 | J16: 6.636 | K16: 6.636 | L16: 6.636 | M16: 6.636 | N16: 6.636 | O16: 6.636 | P16: 6.636 | Q16: 6.636 | R16: 6.636 | S16: 6.636 | T16: 6.636 | U16: 6.636 | V16: 6.636 | W16: 6.636 | X16: 6.636 | Y16: 6.636 | Z16: 6.636 | AA16: 6.636 | AB16: 6.636 | AC16: 6.636 | AD16: 6.636 | AE16: 6.636 | AF16: 6.636 | AG16: 6.636 | AH16: 6.636 | AI16: 6.636 | AJ16: 6.636 | AK16: 0
A17: CNV000:aa_AviationGasol | B17: Aviation Gasoline | C17: 5.048 | D17: 5.048 | E17: 5.048 | F17: 5.048 | G17: 5.048 | H17: 5.048 | I17: 5.048 | J17: 5.048 | K17: 5.048 | L17: 5.048 | M17: 5.048 | N17: 5.048 | O17: 5.048 | P17: 5.048 | Q17: 5.048 | R17: 5.048 | S17: 5.048 | T17: 5.048 | U17: 5.048 | V17: 5.048 | W17: 5.048 | X17: 5.048 | Y17: 5.048 | Z17: 5.048 | AA17: 5.048 | AB17: 5.048 | AC17: 5.048 | AD17: 5.048 | AE17: 5.048 | AF17: 5.048 | AG17: 5.048 | AH17: 5.048 | AI17: 5.048 | AJ17: 5.048 | AK17: 0
A18: CNV000:ea_Biodiesel | B18: Biodiesel | C18: 5.359 | D18: 5.359 | E18: 5.359 | F18: 5.359 | G18: 5.359 | H18: 5.359 | I18: 5.359 | J18: 5.359 | K18: 5.359 | L18: 5.359 | M18: 5.359 | N18: 5.359 | O18: 5.359 | P18: 5.359 | Q18: 5.359 | R18: 5.359 | S18: 5.359 | T18: 5.359 | U18: 5.359 | V18: 5.359 | W18: 5.359 | X18: 5.359 | Y18: 5.359 | Z18: 5.359 | AA18: 5.359 | AB18: 5.359 | AC18: 5.359 | AD18: 5.359 | AE18: 5.359 | AF18: 5.359 | AG18: 5.359 | AH18: 5.359 | AI18: 5.359 | AJ18: 5.359 | AK18: 0
A19: CNV000:aa_Distillate | B19: Distillate Fuel Oil | C19: 5.825 | D19: 5.825 | E19: 5.825 | F19: 5.825 | G19: 5.825 | H19: 5.825 | I19: 5.825 | J19: 5.825 | K19: 5.825 | L19: 5.825 | M19: 5.825 | N19: 5.825 | O19: 5.825 | P19: 5.825 | Q19: 5.825 | R19: 5.825 | S19: 5.825 | T19: 5.825 | U19: 5.825 | V19: 5.825 | W19: 5.825 | X19: 5.825 | Y19: 5.825 | Z19: 5.825 | AA19: 5.825 | AB19: 5.825 | AC19: 5.825 | AD19: 5.825 | AE19: 5.825 | AF19: 5.825 | AG19: 5.825 | AH19: 5.825 | AI19: 5.825 | AJ19: 5.825 | AK19: 0
A20: CNV000:aa_Residential | B20: Residential | C20: 5.774651 | D20: 5.773824 | E20: 5.773629 | F20: 5.772928 | G20: 5.773119 | H20: 5.773727 | I20: 5.772429 | J20: 5.773784 | K20: 5.772606 | L20: 5.773323 | M20: 5.774547 | N20: 5.774744 | O20: 5.773522 | P20: 5.773616 | Q20: 5.773581 | R20: 5.773493 | S20: 5.774485 | T20: 5.773373 | U20: 5.773317 | V20: 5.772994 | W20: 5.773236 | X20: 5.773163 | Y20: 5.773045 | Z20: 5.773002 | AA20: 5.772993 | AB20: 5.772738 | AC20: 5.772945 | AD20: 5.772616 | AE20: 5.772657 | AF20: 5.772504 | AG20: 5.772273 | AH20: 5.772147 | AI20: 5.771948 | AJ20: 5.771775 | AK20: -1.1e-05
A21: CNV000:aa_Commercial | B21: Commercial | C21: 5.774651 | D21: 5.773824 | E21: 5.773629 | F21: 5.772928 | G21: 5.773119 | H21: 5.773727 | I21: 5.772429 | J21: 5.773784 | K21: 5.772606 | L21: 5.773323 | M21: 5.774547 | N21: 5.774744 | O21: 5.773522 | P21: 5.773616 | Q21: 5.773581 | R21: 5.773493 | S21: 5.774485 | T21: 5.773373 | U21: 5.773317 | V21: 5.772994 | W21: 5.773236 | X21: 5.773163 | Y21: 5.773045 | Z21: 5.773002 | AA21: 5.772993 | AB21: 5.772738 | AC21: 5.772945 | AD21: 5.772616 | AE21: 5.772657 | AF21: 5.772504 | AG21: 5.772273 | AH21: 5.772147 | AI21: 5.771948 | AJ21: 5.771775 | AK21: -1.1e-05
A22: CNV000:aa_Transportatio | B22: Transportation | C22: 5.774651 | D22: 5.773824 | E22: 5.773629 | F22: 5.772928 | G22: 5.773119 | H22: 5.773727 | I22: 5.772429 | J22: 5.773784 | K22: 5.772606 | L22: 5.773323 | M22: 5.774547 | N22: 5.774744 | O22: 5.773522 | P22: 5.773616 | Q22: 5.773581 | R22: 5.773493 | S22: 5.774485 | T22: 5.773373 | U22: 5.773317 | V22: 5.772994 | W22: 5.773236 | X22: 5.773163 | Y22: 5.773045 | Z22: 5.773002 | AA22: 5.772993 | AB22: 5.772738 | AC22: 5.772945 | AD22: 5.772616 | AE22: 5.772657 | AF22: 5.772504 | AG22: 5.772273 | AH22: 5.772147 | AI22: 5.771948 | AJ22: 5.771775 | AK22: -1.1e-05
A23: CNV000:aa_Industrial | B23: Industrial | C23: 5.774651 | D23: 5.773824 | E23: 5.773629 | F23: 5.772928 | G23: 5.773119 | H23: 5.773727 | I23: 5.772429 | J23: 5.773784 | K23: 5.772606 | L23: 5.773323 | M23: 5.774547 | N23: 5.774744 | O23: 5.773522 | P23: 5.773616 | Q23: 5.773581 | R23: 5.773493 | S23: 5.774485 | T23: 5.773373 | U23: 5.773317 | V23: 5.772994 | W23: 5.773236 | X23: 5.773163 | Y23: 5.773045 | Z23: 5.773002 | AA23: 5.772993 | AB23: 5.772738 | AC23: 5.772945 | AD23: 5.772616 | AE23: 5.772657 | AF23: 5.772504 | AG23: 5.772273 | AH23: 5.772147 | AI23: 5.771948 | AJ23: 5.771775 | AK23: -1.1e-05
A24: CNV000:aa_ElectricPower | B24: Electric Power | C24: 5.774651 | D24: 5.773824 | E24: 5.773629 | F24: 5.772928 | G24: 5.773119 | H24: 5.773727 | I24: 5.772429 | J24: 5.773784 | K24: 5.772606 | L24: 5.773323 | M24: 5.774547 | N24: 5.774744 | O24: 5.773522 | P24: 5.773616 | Q24: 5.773581 | R24: 5.773493 | S24: 5.774485 | T24: 5.773373 | U24: 5.773317 | V24: 5.772994 | W24: 5.773236 | X24: 5.773163 | Y24: 5.773045 | Z24: 5.773002 | AA24: 5.772993 | AB24: 5.772738 | AC24: 5.772945 | AD24: 5.772616 | AE24: 5.772657 | AF24: 5.772504 | AG24: 5.772273 | AH24: 5.772147 | AI24: 5.771948 | AJ24: 5.771775 | AK24: -1.1e-05
A25: CNV000:aa_TotalDistilla | B25: Total Distillate | C25: 5.774651 | D25: 5.773824 | E25: 5.773628 | F25: 5.772927 | G25: 5.773119 | H25: 5.773727 | I25: 5.772429 | J25: 5.773784 | K25: 5.772606 | L25: 5.773322 | M25: 5.774548 | N25: 5.774744 | O25: 5.773522 | P25: 5.773616 | Q25: 5.77358 | R25: 5.773493 | S25: 5.774485 | T25: 5.773373 | U25: 5.773317 | V25: 5.772994 | W25: 5.773236 | X25: 5.773162 | Y25: 5.773044 | Z25: 5.773002 | AA25: 5.772993 | AB25: 5.772738 | AC25: 5.772945 | AD25: 5.772617 | AE25: 5.772656 | AF25: 5.772504 | AG25: 5.772274 | AH25: 5.772147 | AI25: 5.771948 | AJ25: 5.771775 | AK25: -1.1e-05
A26: CNV000:aa_DistLowSulf | B26: Distillate Fuel Oil - Low Sulfur Diesel | C26: 5.817 | D26: 5.817 | E26: 5.817 | F26: 5.817 | G26: 5.817 | H26: 5.817 | I26: 5.817 | J26: 5.817 | K26: 5.817 | L26: 5.817 | M26: 5.817 | N26: 5.817 | O26: 5.817 | P26: 5.817 | Q26: 5.817 | R26: 5.817 | S26: 5.817 | T26: 5.817 | U26: 5.817 | V26: 5.817 | W26: 5.817 | X26: 5.817 | Y26: 5.817 | Z26: 5.817 | AA26: 5.817 | AB26: 5.817 | AC26: 5.817 | AD26: 5.817 | AE26: 5.817 | AF26: 5.817 | AG26: 5.817 | AH26: 5.817 | AI26: 5.817 | AJ26: 5.817 | AK26: 0
A27: CNV000:aa_DistUltraLow | B27: Distillate Fuel Oil - Ultra Low Sulfur Diesel | C27: 5.77 | D27: 5.77 | E27: 5.77 | F27: 5.77 | G27: 5.77 | H27: 5.77 | I27: 5.77 | J27: 5.77 | K27: 5.77 | L27: 5.77 | M27: 5.77 | N27: 5.77 | O27: 5.77 | P27: 5.77 | Q27: 5.77 | R27: 5.77 | S27: 5.77 | T27: 5.77 | U27: 5.77 | V27: 5.77 | W27: 5.77 | X27: 5.77 | Y27: 5.77 | Z27: 5.77 | AA27: 5.77 | AB27: 5.77 | AC27: 5.77 | AD27: 5.77 | AE27: 5.77 | AF27: 5.77 | AG27: 5.77 | AH27: 5.77 | AI27: 5.77 | AJ27: 5.77 | AK27: 0
... A46: CNV000:aa_Exports | B46: Petroleum Product Exports | C46: 5.151 | D46: 5.274418 | E46: 5.250621 | F46: 5.275748 | G46: 5.243052 | H46: 5.234149 | I46: 5.231354 | J46: 5.245845 | K46: 5.231759 | L46: 5.195461 | M46: 5.187126 | N46: 5.189112 | O46: 5.179728 | P46: 5.182778 | Q46: 5.171607 | R46: 5.172073 | S46: 5.166301 | T46: 5.159403 | U46: 5.153961 | V46: 5.156905 | W46: 5.147167 | X46: 5.14539 | Y46: 5.135945 | Z46: 5.139299 | AA46: 5.137618 | AB46: 5.122315 | AC46: 5.131875 | AD46: 5.13061 | AE46: 5.139469 | AF46: 5.128032 | AG46: 5.124009 | AH46: 5.121249 | AI46: 5.111982 | AJ46: 5.1061 | AK46: -0.001013
B47: Crude Oil
A48: CNV000:aa_CrudeOilProdu | B48: Production | C48: 5.723 | D48: 5.719936 | E48: 5.709374 | F48: 5.702021 | G48: 5.699036 | H48: 5.702903 | I48: 5.701469 | J48: 5.697845 | K48: 5.696569 | L48: 5.695571 | M48: 5.691691 | N48: 5.689583 | O48: 5.687317 | P48: 5.686403 | Q48: 5.685931 | R48: 5.686055 | S48: 5.686259 | T48: 5.685382 | U48: 5.685214 | V48: 5.685896 | W48: 5.686885 | X48: 5.687922 | Y48: 5.69017 | Z48: 5.690964 | AA48: 5.689439 | AB48: 5.688754 | AC48: 5.686469 | AD48: 5.684444 | AE48: 5.683516 | AF48: 5.682888 | AG48: 5.681393 | AH48: 5.679274 | AI48: 5.678185 | AJ48: 5.676202 | AK48: -0.00024
A49: CNV000:aa_CrudeOilImpor | B49: Imports | C49: 6.05 | D49: 6.134721 | E49: 6.118438 | F49: 6.117281 | G49: 6.117947 | H49: 6.10254 | I49: 6.103374 | J49: 6.107163 | K49: 6.106585 | L49: 6.124556 | M49: 6.090179 | N49: 6.118682 | O49: 6.080531 | P49: 6.103808 | Q49: 6.113566 | R49: 6.107624 | S49: 6.084678 | T49: 6.134057 | U49: 6.131942 | V49: 6.08976 | W49: 6.138575 | X49: 6.138392 | Y49: 6.136396 | Z49: 6.138 | AA49: 6.141398 | AB49: 6.105396 | AC49: 6.119062 | AD49: 6.132329 | AE49: 6.140251 | AF49: 6.144131 | AG49: 6.141787 | AH49: 6.139135 | AI49: 6.137544 | AJ49: 6.134161 | AK49: -3e-06
A50: CNV000:aa_CrudeOilExpor | B50: Exports | C50: 5.738 | D50: 5.55477 | E50: 5.557237 | F50: 5.558167 | G50: 5.565951 | H50: 5.562354 | I50: 5.563715 | J50: 5.562271 | K50: 5.566788 | L50: 5.565995 | M50: 5.557513 | N50: 5.560513 | O50: 5.560773 | P50: 5.561747 | Q50: 5.562641 | R50: 5.562265 | S50: 5.569706 | T50: 5.594789 | U50: 5.596409 | V50: 5.603838 | W50: 5.603039 | X50: 5.612446 | Y50: 5.616357 | Z50: 5.622301 | AA50: 5.617278 | AB50: 5.611703 | AC50: 5.598722 | AD50: 5.586086 | AE50: 5.576109 | AF50: 5.561272 | AG50: 5.559134 | AH50: 5.558311 | AI50: 5.558477 | AJ50: 5.558816 | AK50: 2.3e-05
A51: CNV000:aa_NaturalGasPla | B51: Natural Gas Plant Liquids | C51: 3.699432 | D51: 3.680335 | E51: 3.675178 | F51: 3.67226 | G51: 3.661632 | H51: 3.661705 | I51: 3.660451 | J51: 3.65821 | K51: 3.656909 | L51: 3.655905 | M51: 3.655815 | N51: 3.654926 | O51: 3.65379 | P51: 3.654275 | Q51: 3.654194 | R51: 3.65518 | S51: 3.655222 | T51: 3.655784 | U51: 3.655432 | V51: 3.656329 | W51: 3.656425 | X51: 3.65846 | Y51: 3.659478 | Z51: 3.660426 | AA51: 3.659603 | AB51: 3.659032 | AC51: 3.657537 | AD51: 3.655983 | AE51: 3.654918 | AF51: 3.653574 | AG51: 3.651659 | AH51: 3.650127 | AI51: 3.64905 | AJ51: 3.6478 | AK51: -0.000277
B53: Natural Gas (thousand Btu per cubic foot)
A54: CNV000:ba_Consumption | B54: Consumption | C54: 1.037 | D54: 1.037 | E54: 1.037 | F54: 1.037 | G54: 1.037 | H54: 1.037 | I54: 1.037 | J54: 1.037 | K54: 1.037 | L54: 1.037 | M54: 1.037 | N54: 1.037 | O54: 1.037 | P54: 1.037 | Q54: 1.037 | R54: 1.037 | S54: 1.037 | T54: 1.037 | U54: 1.037 | V54: 1.037 | W54: 1.037 | X54: 1.037 | Y54: 1.037 | Z54: 1.037 | AA54: 1.037 | AB54: 1.037 | AC54: 1.037 | AD54: 1.037 | AE54: 1.037 | AF54: 1.037 | AG54: 1.037 | AH54: 1.037 | AI54: 1.037 | AJ54: 1.037 | AK54: 0
A55: CNV000:ba_Utility | B55: Electric Power Sector 2/ | C55: 1.033 | D55: 1.033 | E55: 1.033 | F55: 1.033 | G55: 1.033 | H55: 1.033 | I55: 1.033 | J55: 1.033 | K55: 1.033 | L55: 1.033 | M55: 1.033 | N55: 1.033 | O55: 1.033 | P55: 1.033 | Q55: 1.033 | R55: 1.033 | S55: 1.033 | T55: 1.033 | U55: 1.033 | V55: 1.033 | W55: 1.033 | X55: 1.033 | Y55: 1.033 | Z55: 1.033 | AA55: 1.033 | AB55: 1.033 | AC55: 1.033 | AD55: 1.033 | AE55: 1.033 | AF55: 1.033 | AG55: 1.033 | AH55: 1.033 | AI55: 1.033 | AJ55: 1.033 | AK55: 0
A56: CNV000:ba_Nonutility | B56: End-use Sector | C56: 1.039 | D56: 1.039 | E56: 1.039 | F56: 1.039 | G56: 1.039 | H56: 1.039 | I56: 1.039 | J56: 1.039 | K56: 1.039 | L56: 1.039 | M56: 1.039 | N56: 1.039 | O56: 1.039 | P56: 1.039 | Q56: 1.039 | R56: 1.039 | S56: 1.039 | T56: 1.039 | U56: 1.039 | V56: 1.039 | W56: 1.039 | X56: 1.039 | Y56: 1.039 | Z56: 1.039 | AA56: 1.039 | AB56: 1.039 | AC56: 1.039 | AD56: 1.039 | AE56: 1.039 | AF56: 1.039 | AG56: 1.039 | AH56: 1.039 | AI56: 1.039 | AJ56: 1.039 | AK56: 0
A57: CNV000:ba_Production | B57: Production | C57: 1.037 | D57: 1.037 | E57: 1.037 | F57: 1.037 | G57: 1.037 | H57: 1.037 | I57: 1.037 | J57: 1.037 | K57: 1.037 | L57: 1.037 | M57: 1.037 | N57: 1.037 | O57: 1.037 | P57: 1.037 | Q57: 1.037 | R57: 1.037 | S57: 1.037 | T57: 1.037 | U57: 1.037 | V57: 1.037 | W57: 1.037 | X57: 1.037 | Y57: 1.037 | Z57: 1.037 | AA57: 1.037 | AB57: 1.037 | AC57: 1.037 | AD57: 1.037 | AE57: 1.037 | AF57: 1.037 | AG57: 1.037 | AH57: 1.037 | AI57: 1.037 | AJ57: 1.037 | AK57: 0
A58: CNV000:ba_Imports | B58: Imports | C58: 1.025 | D58: 1.025 | E58: 1.025 | F58: 1.025 | G58: 1.025 | H58: 1.025 | I58: 1.025 | J58: 1.025 | K58: 1.025 | L58: 1.025 | M58: 1.025 | N58: 1.025 | O58: 1.025 | P58: 1.025 | Q58: 1.025 | R58: 1.025 | S58: 1.025 | T58: 1.025 | U58: 1.025 | V58: 1.025 | W58: 1.025 | X58: 1.025 | Y58: 1.025 | Z58: 1.025 | AA58: 1.025 | AB58: 1.025 | AC58: 1.025 | AD58: 1.025 | AE58: 1.025 | AF58: 1.025 | AG58: 1.025 | AH58: 1.025 | AI58: 1.025 | AJ58: 1.025 | AK58: 0
A59: CNV000:ba_Exports | B59: Exports | C59: 1.009 | D59: 1.009 | E59: 1.009 | F59: 1.009 | G59: 1.009 | H59: 1.009 | I59: 1.009 | J59: 1.009 | K59: 1.009 | L59: 1.009 | M59: 1.009 | N59: 1.009 | O59: 1.009 | P59: 1.009 | Q59: 1.009 | R59: 1.009 | S59: 1.009 | T59: 1.009 | U59: 1.009 | V59: 1.009 | W59: 1.009 | X59: 1.009 | Y59: 1.009 | Z59: 1.009 | AA59: 1.009 | AB59: 1.009 | AC59: 1.009 | AD59: 1.009 | AE59: 1.009 | AF59: 1.009 | AG59: 1.009 | AH59: 1.009 | AI59: 1.009 | AJ59: 1.009 | AK59: 0
A60: CNV000:ba_CompressedNat | B60: Compressed/Liquefied Natural Gas | C60: 0.96 | D60: 0.96 | E60: 0.96 | F60: 0.96 | G60: 0.96 | H60: 0.96 | I60: 0.96 | J60: 0.96 | K60: 0.96 | L60: 0.96 | M60: 0.96 | N60: 0.96 | O60: 0.96 | P60: 0.96 | Q60: 0.96 | R60: 0.96 | S60: 0.96 | T60: 0.96 | U60: 0.96 | V60: 0.96 | W60: 0.96 | X60: 0.96 | Y60: 0.96 | Z60: 0.96 | AA60: 0.96 | AB60: 0.96 | AC60: 0.96 | AD60: 0.96 | AE60: 0.96 | AF60: 0.96 | AG60: 0.96 | AH60: 0.96 | AI60: 0.96 | AJ60: 0.96 | AK60: 0
B62: Coal (million Btu per short ton)
A63: CNV000:ca_Production | B63: Production | C63: 20.53714 | D63: 20.439445 | E63: 20.349045 | F63: 20.46627 | G63: 20.363602 | H63: 20.554329 | I63: 20.653105 | J63: 20.626196 | K63: 20.621487 | L63: 20.64123 | M63: 20.627844 | N63: 20.53694 | O63: 20.501505 | P63: 20.413282 | Q63: 20.399071 | R63: 20.458256 | S63: 20.429285 | T63: 20.364529 | U63: 20.373262 | V63: 20.367174 | W63: 20.397617 | X63: 20.405455 | Y63: 20.39472 | Z63: 20.372593 | AA63: 20.382772 | AB63: 20.366734 | AC63: 20.354519 | AD63: 20.35523 | AE63: 20.38698 | AF63: 20.356945 | AG63: 20.336355 | AH63: 20.357395 | AI63: 20.34404 | AJ63: 20.347267 | AK63: -0.000141
...

Sheet ethanol content
A1: https://www.eia.gov/environment/emissions/co2_vol_mass.php
A3: Carbon Dioxide Emissions Coefficients by Fuel | I3: Percentage of BTUs per barrel from ethanol | J3: =1-J8 -> 0.072894654
B4: Pounds CO2 | C4: Kilograms CO2 | D4: Pounds CO2 | E4: Kilograms CO2
A5: Carbon Dioxide (CO2) Factors: | B5: Per Unit of Volume or Mass | C5: Per Unit of Volume or Mass | D5: Per Million Btu | E5: Per Million Btu | I5: BTU per barrel, finished gasoline | J5: ='AEO Table 73'!C32 -> 5.056643
A6: For homes and businesses | I6: BTU per barrel, motor gasoline before blending | J6: ='AEO Table 73'!C35 -> 5.22228
A7: Propane | B7: 12.68 gallon | C7: 5.75 gallon | D7: 138.63 | E7: 62.88 | I7: BTUs per barrel from motor gasoline | J7: =J6*(1-'EIA-fuel-ethanol-motor-gasoline'!C47/100) -> 4.6880408
A8: Diesel and Home Heating Fuel (Distillate Fuel Oil) | B8: 22.45 gallon | C8: 10.19 gallon | D8: 163.45 | E8: 74.14 | I8: Percentage of BTUs per barrel from motor gasoline | J8: =J7/J5 -> 0.92710535
A9: Kerosene | B9: 21.78 gallon | C9: 9.88 gallon | D9: 161.35 | E9: 73.19
A10: Coal (All types) | B10: 3,890.78 short ton | C10: 1,764.83 short ton | D10: 211.47 | E10: 95.92
A11: Natural Gas | B11: 120.96 thousand cubic feet | C11: 54.87 thousand cubic feet | D11: 116.65 | E11: 52.91
A12: Finished Motor Gasolinea | B12: 17.86 gallon | C12: 8.10 gallon | D12: 148.57 | E12: 67.39
A13: Motor Gasoline | B13: 19.37 gallon | C13: 8.78 gallon | D13: 155.77 | E13: 70.66
A14: Residual Heating Fuel (Businesses only) | B14: 24.78 gallon | C14: 11.24 gallon | D14: 165.55 | E14: 75.09
A15: Other transportation fuels
A16: Jet Fuel | B16: 21.50 gallon | C16: 9.75 gallon | D16: 159.25 | E16: 72.23
A17: Aviation Gas | B17: 18.32 gallon | C17: 8.31 gallon | D17: 152.46 | E17: 69.15
A18: Industrial fuels and others not listed above
A19: Petroleum coke | B19: 32.88 gallon | C19: 14.920 gallon | D19: 225.13 | E19: 102.12
A20: Nonfuel uses
A21: Asphalt and Road Oil | B21: 26.25 gallon | C21: 11.91 gallon | D21: 166.12 | E21: 75.35
A22: Lubricants | B22: 23.58 gallon | C22: 10.70 gallon | D22: 163.29 | E22: 74.07
A23: Naphthas for Petrochemical Feedstock Use | B23: 18.74 gallon | C23: 8.50 gallon | D23: 149.95 | E23: 68.02
A24: Other Oils for Petrochemical Feedstock Use | B24: 22.61 gallon | C24: 10.26 gallon | D24: 163.05 | E24: 73.96
A25: Special Naphthas (solvents) | B25: 19.94 gallon | C25: 9.04 gallon | D25: 159.57 | E25: 72.38
A26: Waxes | B26: 21.10 gallon | C26: 9.57 gallon | D26: 160.06 | E26: 72.6
A27: Coals by type
A28: Anthracite | B28: 5,735.68 short ton | C28: 2,601.67 short ton | D28: 228.6 | E28: 103.69
A29: Bituminous | B29: 4,783.52 short ton | C29: 2,169.77 short ton | D29: 205.57 | E29: 93.24
A30: Subbituminous | B30: 3,745.22 short ton | C30: 1,698.80 short ton | D30: 214.13 | E30: 97.13
A31: Lignite | B31: 2,809.83 short ton | C31: 1,274.52 short ton | D31: 216.64 | E31: 98.27
A32: Coke | B32: 7,183.46 short ton | C32: 3,258.37 short ton | D32: 250.59 | E32: 113.67
A33: Other fuels
A34: Geothermal (steam) | B34: NA | C34: NA | D34: 26.03 | E34: 11.81
A35: Geothermal (binary cycle) | B35: NA | C35: NA | D35: 0 | E35: 0
A36: Municipal solid wasteb,c | B36: 1,562.78 short ton | C36: 708.87 short ton | D36: 109.98 | E36: 49.89
A37: Tire-derived fuelb | B37: 5,306.87 short ton | C37: 2,407.16 short ton | D37: 189.53 | E37: 85.97
A38: Waste oilb | B38: 22.51 gallon | C38: 10.21 gallon | D38: 163.14 | E38: 74

Sheet AEO 2023 Table 17
B1: ref2023.d020623a | C1: 2022 | D1: 2023 | E1: 2024 | F1: 2025 | G1: 2026 | H1: 2027 | I1: 2028 | J1: 2029 | K1: 2030 | L1: 2031 | M1: 2032 | N1: 2033 | O1: 2034 | P1: 2035 | Q1: 2036 | R1: 2037 | S1: 2038 | T1: 2039 | U1: 2040 | V1: 2041 | W1: 2042 | X1: 2043 | Y1: 2044 | Z1: 2045 | AA1: 2046 | AB1: 2047 | AC1: 2048 | AD1: 2049 | AE1: 2050
C3: Report | D3: Annual Energy Outlook 2023
C4: Scenario | D4: ref2023 | G4: Reference
C5: Datekey | D5: d020623a
C6: Release Date | E6: March 2023
A10: REM000 | B10: 17. Renewable Energy Consumption by Sector and Source | AF10: Average
B11: (quadrillion Btu, unless otherwise noted) | AF11: Annual
AF12: Change
B13: Sector and Source | C13: 2022 | D13: 2023 | E13: 2024 | F13: 2025 | G13: 2026 | H13: 2027 | I13: 2028 | J13: 2029 | K13: 2030 | L13: 2031 | M13: 2032 | N13: 2033 | O13: 2034 | P13: 2035 | Q13: 2036 | R13: 2037 | S13: 2038 | T13: 2039 | U13: 2040 | V13: 2041 | W13: 2042 | X13: 2043 | Y13: 2044 | Z13: 2045 | AA13: 2046 | AB13: 2047 | AC13: 2048 | AD13: 2049 | AE13: 2050 | AF13: 2022–2050
B15: Marketed Renewable Energy 1/
A17: REM000:ca_Residential(w | B17: Residential (wood) | C17: 0.538932 | D17: 0.57441 | E17: 0.513068 | F17: 0.489864 | G17: 0.472164 | H17: 0.45764 | I17: 0.4452 | J17: 0.435137 | K17: 0.426017 | L17: 0.41791 | M17: 0.409804 | N17: 0.402631 | O17: 0.395039 | P17: 0.387514 | Q17: 0.379935 | R17: 0.372857 | S17: 0.366083 | T17: 0.359575 | U17: 0.353241 | V17: 0.347622 | W17: 0.342071 | X17: 0.337054 | Y17: 0.332011 | Z17: 0.327538 | AA17: 0.323872 | AB17: 0.320083 | AC17: 0.316089 | AD17: 0.312111 | AE17: 0.308024 | AF17: -0.019781
A19: REM000:da_Commercial(bi | B19: Commercial (biomass) | C19: 0.120805 | D19: 0.120805 | E19: 0.120805 | F19: 0.120805 | G19: 0.120805 | H19: 0.120805 | I19: 0.120805 | J19: 0.120805 | K19: 0.120805 | L19: 0.120805 | M19: 0.120805 | N19: 0.120805 | O19: 0.120805 | P19: 0.120805 | Q19: 0.120805 | R19: 0.120805 | S19: 0.120805 | T19: 0.120805 | U19: 0.120805 | V19: 0.120805 | W19: 0.120805 | X19: 0.120805 | Y19: 0.120805 | Z19: 0.120805 | AA19: 0.120805 | AB19: 0.120805 | AC19: 0.120805 | AD19: 0.120805 | AE19: 0.120805 | AF19: 0
A21: REM000:ea_Industrial | B21: Industrial 2/ | C21: 2.418849 | D21: 2.558293 | E21: 2.454399 | F21: 2.458783 | G21: 2.461936 | H21: 2.469083 | I21: 2.484627 | J21: 2.491801 | K21: 2.494826 | L21: 2.500568 | M21: 2.509977 | N21: 2.521396 | O21: 2.534965 | P21: 2.553261 | Q21: 2.557693 | R21: 2.567496 | S21: 2.576616 | T21: 2.588815 | U21: 2.604867 | V21: 2.630121 | W21: 2.648243 | X21: 2.664851 | Y21: 2.671741 | Z21: 2.681419 | AA21: 2.697925 | AB21: 2.720405 | AC21: 2.747052 | AD21: 2.763744 | AE21: 2.78549 | AF21: 0.005053
A22: REM000:ea_ConventionalH | B22: Conventional Hydroelectric Power | C22: 0.010773 | D22: 0.010913 | E22: 0.010875 | F22: 0.010837 | G22: 0.010801 | H22: 0.010767 | I22: 0.010736 | J22: 0.010707 | K22: 0.010682 | L22: 0.010661 | M22: 0.010644 | N22: 0.010632 | O22: 0.010624 | P22: 0.010622 | Q22: 0.010622 | R22: 0.010622 | S22: 0.010622 | T22: 0.010622 | U22: 0.010622 | V22: 0.010622 | W22: 0.010622 | X22: 0.010622 | Y22: 0.010622 | Z22: 0.010622 | AA22: 0.010622 | AB22: 0.010622 | AC22: 0.010622 | AD22: 0.010622 | AE22: 0.010622 | AF22: -0.000504
A23: REM000:ea_MunicipalSoli | B23: Municipal Waste 3/ | C23: 0.161768 | D23: 0.159976 | E23: 0.160365 | F23: 0.16234 | G23: 0.164713 | H23: 0.166676 | I23: 0.167756 | J23: 0.167014 | K23: 0.166274 | L23: 0.165657 | M23: 0.164915 | N23: 0.164057 | O23: 0.163178 | P23: 0.162395 | Q23: 0.161408 | R23: 0.16053 | S23: 0.159728 | T23: 0.159956 | U23: 0.160357 | V23: 0.160718 | W23: 0.160969 | X23: 0.161029 | Y23: 0.160963 | Z23: 0.161255 | AA23: 0.161468 | AB23: 0.161673 | AC23: 0.161871 | AD23: 0.162026 | AE23: 0.162219 | AF23: 9.9e-05
A24: REM000:ea_Biomass | B24: Biomass | C24: 1.328232 | D24: 1.402826 | E24: 1.37287 | F24: 1.379027 | G24: 1.38159 | H24: 1.387895 | I24: 1.399337 | J24: 1.41076 | K24: 1.418932 | L24: 1.429157 | M24: 1.443031 | N24: 1.456508 | O24: 1.470957 | P24: 1.482958 | Q24: 1.48898 | R24: 1.498773 | S24: 1.506998 | T24: 1.516537 | U24: 1.528081 | V24: 1.540243 | W24: 1.552132 | X24: 1.562002 | Y24: 1.568192 | Z24: 1.57093 | AA24: 1.577018 | AB24: 1.587632 | AC24: 1.593003 | AD24: 1.600503 | AE24: 1.615781 | AF24: 0.007023
A25: REM000:ea_BiomasHeat&Co | B25: Biofuels Heat and Coproducts | C25: 0.918076 | D25: 0.984578 | E25: 0.910289 | F25: 0.906579 | G25: 0.904831 | H25: 0.903745 | I25: 0.906798 | J25: 0.90332 | K25: 0.898938 | L25: 0.895093 | M25: 0.891387 | N25: 0.8902 | O25: 0.890206 | P25: 0.897286 | Q25: 0.896683 | R25: 0.897571 | S25: 0.899268 | T25: 0.901701 | U25: 0.905807 | V25: 0.918538 | W25: 0.924521 | X25: 0.931198 | Y25: 0.931964 | Z25: 0.938613 | AA25: 0.948817 | AB25: 0.960478 | AC25: 0.981557 | AD25: 0.990594 | AE25: 0.996868 | AF25: 0.002945
A27: REM000:fa_Transportatio | B27: Transportation | C27: 1.643957 | D27: 1.68746 | E27: 1.750144 | F27: 1.713519 | G27: 1.703839 | H27: 1.701528 | I27: 1.5877 | J27: 1.586966 | K27: 1.586138 | L27: 1.585172 | M27: 1.583934 | N27: 1.582892 | O27: 1.581595 | P27: 1.580019 | Q27: 1.578644 | R27: 1.57726 | S27: 1.575864 | T27: 1.574471 | U27: 1.57305 | V27: 1.571346 | W27: 1.569874 | X27: 1.568397 | Y27: 1.567132 | Z27: 1.565676 | AA27: 1.579699 | AB27: 1.603261 | AC27: 1.648387 | AD27: 1.678537 | AE27: 1.699064 | AF27: 0.001178
A28: REM000:fa_Ethanolusedin | B28: Ethanol used in E85 4/ | C28: 0.022316 | D28: 0.022565 | E28: 0.021182 | F28: 0.021098 | G28: 0.020573 | H28: 0.020002 | I28: 0.019309 | J28: 0.018533 | K28: 0.017717 | L28: 0.016916 | M28: 0.016133 | N28: 0.015434 | O28: 0.014803 | P28: 0.014241 | Q28: 0.013707 | R28: 0.013317 | S28: 0.013026 | T28: 0.012829 | U28: 0.012724 | V28: 0.012669 | W28: 0.012661 | X28: 0.012716 | Y28: 0.01278 | Z28: 0.012875 | AA28: 0.01296 | AB28: 0.013117 | AC28: 0.013259 | AD28: 0.013443 | AE28: 0.013617 | AF28: -0.017487
A29: REM000:ga_Ethanolusedin | B29: Ethanol used in Gasoline Blending | C29: 1.12509 | D29: 1.122732 | E29: 1.151931 | F29: 1.142379 | G29: 1.135865 | H29: 1.130649 | I29: 1.123475 | J29: 1.114464 | K29: 1.103905 | L29: 1.094237 | M29: 1.084963 | N29: 1.07876 | O29: 1.074166 | P29: 1.069304 | Q29: 1.063241 | R29: 1.058996 | S29: 1.055871 | T29: 1.053339 | U29: 1.052924 | V29: 1.052812 | W29: 1.054361 | X29: 1.056869 | Y29: 1.061329 | Z29: 1.067279 | AA29: 1.075243 | AB29: 1.084963 | AC29: 1.095266 | AD29: 1.106839 | AE29: 1.120543 | AF29: -0.000145
A30: REM000:ga_BioDieselBlen | B30: Biodiesel used in Distillate Blending | C30: 0.201563 | D30: 0.18984 | E30: 0.219119 | F30: 0.20335 | G30: 0.200004 | H30: 0.203061 | I30: 0.154942 | J30: 0.16418 | K30: 0.172856 | L30: 0.177873 | M30: 0.176632 | N30: 0.179796 | O30: 0.177057 | P30: 0.173708 | Q30: 0.17023 | R30: 0.166623 | S30: 0.162883 | T30: 0.159519 | U30: 0.155506 | V30: 0.151353 | W30: 0.147056 | X30: 0.142614 | Y30: 0.138021 | Z30: 0.133277 | AA30: 0.128377 | AB30: 0.123319 | AC30: 0.118099 | AD30: 0.112828 | AE30: 0.107556 | AF30: -0.022182
A31: REM000:trans_biobute | B31: Biobutanol | C31: 0 | D31: 0 | E31: 0 | F31: 0 | G31: 0 | H31: 0 | I31: 0 | J31: 0 | K31: 0 | L31: 0 | M31: 0 | N31: 0 | O31: 0 | P31: 0 | Q31: 0 | R31: 0 | S31: 0 | T31: 0 | U31: 0 | V31: 0 | W31: 0 | X31: 0 | Y31: 0 | Z31: 0 | AA31: 0 | AB31: 0 | AC31: 0 | AD31: 0 | AE31: 0 | AF31: --
A32: REM000:gb_LiquidfromBio | B32: Liquids from Biomass | C32: 0.001026 | D32: 0.001154 | E32: 0.001159 | F32: 0.001159 | G32: 0.001223 | H32: 0.001159 | I32: 0.001223 | J32: 0.00225 | K32: 0.00167 | L32: 0.001853 | M32: 0.001884 | N32: 0.00225 | O32: 0.00225 | P32: 0.00225 | Q32: 0.00225 | R32: 0.00225 | S32: 0.00225 | T32: 0.00225 | U32: 0.00225 | V32: 0.002682 | W32: 0.00225 | X32: 0.00225 | Y32: 0.001992 | Z32: 0.001223 | AA32: 0.002185 | AB32: 0.002185 | AC32: 0.002185 | AD32: 0.002225 | AE32: 0.001882 | AF32: 0.021892
A33: REM000:gb_GreenLiquids | B33: Renewable Diesel and Gasoline 5/ | C33: 0.293962 | D33: 0.35117 | E33: 0.356753 | F33: 0.345533 | G33: 0.346173 | H33: 0.346656 | I33: 0.288751 | J33: 0.287539 | K33: 0.28999 | L33: 0.294293 | M33: 0.304321 | N33: 0.306653 | O33: 0.313318 | P33: 0.320518 | Q33: 0.329216 | R33: 0.336075 | S33: 0.341834 | T33: 0.346535 | U33: 0.349645 | V33: 0.351831 | W33: 0.353546 | X33: 0.353948 | Y33: 0.353009 | Z33: 0.351022 | AA33: 0.360933 | AB33: 0.379677 | AC33: 0.419578 | AD33: 0.443202 | AE33: 0.455466 | AF33: 0.015761
A35: REM000:ha_ElectricPower | B35: Electric Power 6/ | C35: 8.08409 | D35: 8.605595 | E35: 9.2536 | F35: 10.769812 | G35: 12.489632 | H35: 14.207677 | I35: 15.657 | J35: 16.679596 | K35: 17.569942 | L35: 18.211523 | M35: 18.849072 | N35: 19.601135 | O35: 20.207752 | P35: 20.684017 | Q35: 21.174015 | R35: 21.527521 | S35: 21.819601 | T35: 21.990221 | U35: 22.281153 | V35: 22.423574 | W35: 22.664766 | X35: 22.940054 | Y35: 23.344435 | Z35: 23.717884 | AA35: 24.147013 | AB35: 24.507113 | AC35: 24.87258 | AD35: 25.165535 | AE35: 25.597914 | AF35: 0.042024
A36: REM000:ha_ConventionalH | B36: Conventional Hydroelectric Power | C36: 2.442681 | D36: 2.44755 | E36: 2.491689 | F36: 2.577846 | G36: 2.568922 | H36: 2.546059 | I36: 2.504646 | J36: 2.475489 | K36: 2.446743 | L36: 2.425799 | M36: 2.409033 | N36: 2.411749 | O36: 2.415782 | P36: 2.419376 | Q36: 2.424693 | R36: 2.41289 | S36: 2.399529 | T36: 2.375586 | U36: 2.3708 | V36: 2.35552 | W36: 2.358788 | X36: 2.352015 | Y36: 2.346977 | Z36: 2.343842 | AA36: 2.33262 | AB36: 2.325793 | AC36: 2.323454 | AD36: 2.310321 | AE36: 2.298403 | AF36: -0.002172
A37: REM000:ha_Geothermal | B37: Geothermal | C37: 0.138575 | D37: 0.134139 | E37: 0.138856 | F37: 0.146111 | G37: 0.152066 | H37: 0.156023 | I37: 0.159828 | J37: 0.167233 | K37: 0.174095 | L37: 0.178493 | M37: 0.184554 | N37: 0.187499 | O37: 0.195066 | P37: 0.201046 | Q37: 0.210441 | R37: 0.217342 | S37: 0.223436 | T37: 0.2259 | U37: 0.229147 | V37: 0.234246 | W37: 0.240622 | X37: 0.244772 | Y37: 0.249637 | Z37: 0.25794 | AA37: 0.269467 | AB37: 0.28115 | AC37: 0.288588 | AD37: 0.296086 | AE37: 0.302234 | AF37: 0.028241
A38: REM000:ha_MunicipalSoli | B38: Biogenic Municipal Waste 7/ | C38: 0.22191 | D38: 0.228224 | E38: 0.233892 | F38: 0.239109 | G38: 0.244032 | H38: 0.251669 | I38: 0.255155 | J38: 0.262267 | K38: 0.270317 | L38: 0.278272 | M38: 0.285579 | N38: 0.29683 | O38: 0.303756 | P38: 0.312192 | Q38: 0.321445 | R38: 0.330951 | S38: 0.342231 | T38: 0.35276 | U38: 0.36073 | V38: 0.369139 | W38: 0.377914 | X38: 0.386538 | Y38: 0.395555 | Z38: 0.404655 | AA38: 0.410119 | AB38: 0.416926 | AC38: 0.422851 | AD38: 0.42875 | AE38: 0.43555 | AF38: 0.024376
A39: REM000:ha_Biomass | B39: Biomass | C39: 0.180331 | D39: 0.192473 | E39: 0.180116 | F39: 0.181063 | G39: 0.177749 | H39: 0.175131 | I39: 0.165623 | J39: 0.161346 | K39: 0.161241 | L39: 0.162494 | M39: 0.162658 | N39: 0.163868 | O39: 0.163854 | P39: 0.164149 | Q39: 0.163862 | R39: 0.164537 | S39: 0.165233 | T39: 0.165279 | U39: 0.16548 | V39: 0.165659 | W39: 0.164763 | X39: 0.164765 | Y39: 0.164578 | Z39: 0.1647 | AA39: 0.170629 | AB39: 0.170972 | AC39: 0.171464 | AD39: 0.176981 | AE39: 0.177752 | AF39: -0.000514
A40: REM000:ha_DedicatedPlan | B40: Dedicated Plants | C40: 0.146924 | D40: 0.157217 | E40: 0.148088 | F40: 0.149106 | G40: 0.145807 | H40: 0.143338 | I40: 0.13548 | J40: 0.131939 | K40: 0.131949 | L40: 0.133298 | M40: 0.133607 | N40: 0.134069 | O40: 0.134178 | P40: 0.134068 | Q40: 0.133866 | R40: 0.134474 | S40: 0.135283 | T40: 0.135296 | U40: 0.13552 | V40: 0.135503 | W40: 0.134629 | X40: 0.1346 | Y40: 0.134432 | Z40: 0.134527 | AA40: 0.140319 | AB40: 0.140614 | AC40: 0.14099 | AD40: 0.146394 | AE40: 0.147057 | AF40: 3.2e-05
A41: REM000:ha_Cofiring | B41: Cofiring | C41: 0.033407 | D41: 0.035255 | E41: 0.032028 | F41: 0.031957 | G41: 0.031942 | H41: 0.031793 | I41: 0.030144 | J41: 0.029407 | K41: 0.029292 | L41: 0.029196 | M41: 0.029051 | N41: 0.029799 | O41: 0.029675 | P41: 0.030081 | Q41: 0.029995 | R41: 0.030063 | S41: 0.029951 | T41: 0.029983 | U41: 0.02996 | V41: 0.030157 | W41: 0.030133 | X41: 0.030165 | Y41: 0.030146 | Z41: 0.030173 | AA41: 0.03031 | AB41: 0.030358 | AC41: 0.030474 | AD41: 0.030587 | AE41: 0.030695 | AF41: -0.003019
A42: REM000:ha_SolarThermal | B42: Solar Thermal | C42: 0.026097 | D42: 0.026142 | E42: 0.02559 | F42: 0.025612 | G42: 0.025363 | H42: 0.025058 | I42: 0.024745 | J42: 0.024274 | K42: 0.024036 | L42: 0.02384 | M42: 0.022007 | N42: 0.021626 | O42: 0.020728 | P42: 0.020644 | Q42: 0.019789 | R42: 0.019886 | S42: 0.020183 | T42: 0.020373 | U42: 0.019944 | V42: 0.019694 | W42: 0.019015 | X42: 0.018082 | Y42: 0.017749 | Z42: 0.01733 | AA42: 0.017052 | AB42: 0.016774 | AC42: 0.016619 | AD42: 0.016455 | AE42: 0.016648 | AF42: -0.015926
A43: REM000:ha_SolarPhotovol | B43: Solar Photovoltaic 8/ | C43: 1.177112 | D43: 1.520191 | E43: 2.136887 | F43: 3.17957 | G43: 4.325841 | H43: 5.352685 | I43: 5.958737 | J43: 6.275979 | K43: 6.478005 | L43: 6.825141 | M43: 7.316296 | N43: 7.667536 | O43: 7.998652 | P43: 8.191917 | Q43: 8.540236 | R43: 8.880701 | S43: 9.202519 | T43: 9.377172 | U43: 9.679772 | V43: 9.812637 | W43: 10.01744 | X43: 10.248034 | Y43: 10.580895 | Z43: 10.882163 | AA43: 11.308514 | AB43: 11.581096 | AC43: 11.847967 | AD43: 12.144065 | AE43: 12.509926 | AF43: 0.088074
A44: REM000:ha_Wind | B44: Wind | C44: 3.897385 | D44: 4.056876 | E44: 4.046569 | F44: 4.420499 | G44: 4.995658 | H44: 5.701052 | I44: 6.588266 | J44: 7.313008 | K44: 8.015505 | L44: 8.317482 | M44: 8.468944 | N44: 8.852024 | O44: 9.109915 | P44: 9.374693 | Q44: 9.493549 | R44: 9.501213 | S44: 9.46647 | T44: 9.473149 | U44: 9.45528 | V44: 9.466681 | W44: 9.486225 | X44: 9.525846 | Y44: 9.589043 | Z44: 9.647252 | AA44: 9.63861 | AB44: 9.714403 | AC44: 9.801635 | AD44: 9.792878 | AE44: 9.857403 | AF44: 0.033695
A46: REM000:ia_TotalMarketed | B46: Total Marketed Renewable Energy | C46: 12.806632 | D46: 13.546563 | E46: 14.092015 | F46: 15.552782 | G46: 17.248375 | H46: 18.956732 | I46: 20.29533 | J46: 21.314304 | K46: 22.197727 | L46: 22.835978 | M46: 23.473591 | N46: 24.228859 | O46: 24.840157 | P46: 25.325615 | Q46: 25.811092 | R46: 26.165939 | S46: 26.458969 | T46: 26.633888 | U46: 26.933115 | V46: 27.093468 | W46: 27.34576 | X46: 27.631161 | Y46: 28.036123 | Z46: 28.413322 | AA46: 28.869314 | AB46: 29.271667 | AC46: 29.704914 | AD46: 30.040731 | AE46: 30.511297 | AF46: 0.03149
B48: Sources of Ethanol
A49: REM000:ja_FromCorn | B49: From Corn and Other Starch | C49: 1.263154 | D49: 1.23928 | E49: 1.324231 | F49: 1.318407 | G49: 1.315272 | H49: 1.313495 | I49: 1.317761 | J49: 1.313384 | K49: 1.305957 | L49: 1.300309 | M49: 1.295035 | N49: 1.293353 | O49: 1.293118 | P49: 1.302341 | Q49: 1.301225 | R49: 1.302217 | S49: 1.304563 | T49: 1.307725 | U49: 1.313264 | V49: 1.330781 | W49: 1.33853 | X49: 1.347896 | Y49: 1.349838 | Z49: 1.359517 | AA49: 1.375432 | AB49: 1.392505 | AC49: 1.423452 | AD49: 1.43737 | AE49: 1.447323 | AF49: 0.004873
A50: REM000:ja_FromCellulose | B50: From Cellulose | C50: 0.001455 | D50: 0.001397 | E50: 0.001468 | F50: 0.001468 | G50: 0.001468 | H50: 0.001468 | I50: 0.001468 | J50: 0.000463 | K50: 0.001031 | L50: 0.000851 | M50: 0.00082 | N50: 0.000463 | O50: 0.000463 | P50: 0.000463 | Q50: 0.000463 | R50: 0.000463 | S50: 0.000463 | T50: 0.000463 | U50: 0.000463 | V50: 3.9e-05 | W50: 0.000463 | X50: 0.000463 | Y50: 0.000715 | Z50: 0.001468 | AA50: 0.000463 | AB50: 0.000463 | AC50: 0.000463 | AD50: 0.000424 | AE50: 0.000823 | AF50: -0.020154
A51: REM000:ja_Imports | B51: Net Imports | C51: -0.117203 | D51: -0.09538 | E51: -0.152586 | F51: -0.156399 | G51: -0.160302 | H51: -0.164311 | I51: -0.176445 | J51: -0.18085 | K51: -0.185365 | L51: -0.190007 | M51: -0.194759 | N51: -0.199622 | O51: -0.204611 | P51: -0.219259 | Q51: -0.224739 | R51: -0.230367 | S51: -0.236128 | T51: -0.24202 | U51: -0.248078 | V51: -0.26534 | W51: -0.271971 | X51: -0.278774 | Y51: -0.276443 | Z51: -0.280831 | AA51: -0.287691 | AB51: -0.294887 | AC51: -0.31539 | AD51: -0.317511 | AE51: -0.313985 | AF51: 0.035821
A52: REM000:ja_Total | B52: Total U.S. Supply of Ethanol | C52: 1.147406 | D52: 1.145297 | E52: 1.173112 | F52: 1.163476 | G52: 1.156438 | H52: 1.150652 | I52: 1.142784 | J52: 1.132997 | K52: 1.121622 | L52: 1.111153 | M52: 1.101096 | N52: 1.094194 | O52: 1.088969 | P52: 1.083545 | Q52: 1.076948 | R52: 1.072313 | S52: 1.068897 | T52: 1.066168 | U52: 1.065649 | V52: 1.065481 | W52: 1.067022 | X52: 1.069585 | Y52: 1.074109 | Z52: 1.080154 | AA52: 1.088203 | AB52: 1.09808 | AC52: 1.108525 | AD52: 1.120282 | AE52: 1.134161 | AF52: -0.000415
...

Sheet AEO 2022 Table 17
A1: Table 17. Renewable Energy Consumption by Sector and Source
A2: https://www.eia.gov/outlooks/aeo/data/browser/#/?id=24-AEO2022&sourcekey=0
A3: Mon Apr 17 2023 13:54:10 GMT-0400 (Eastern Daylight Time)
A4: Source: U.S. Energy Information Administration
B5: full name | C5: api key | D5: units | E5: 2020 | F5: 2021 | G5: 2022 | H5: 2023 | I5: 2024 | J5: 2025 | K5: 2026 | L5: 2027 | M5: 2028 | N5: 2029 | O5: 2030 | P5: 2031 | Q5: 2032 | R5: 2033 | S5: 2034 | T5: 2035 | U5: 2036 | V5: 2037 | W5: 2038 | X5: 2039 | Y5: 2040 | Z5: 2041 | AA5: 2042 | AB5: 2043 | AC5: 2044 | AD5: 2045 | AE5: 2046 | AF5: 2047 | AG5: 2048 | AH5: 2049 | AI5: 2050 | AJ5: Growth (2021-2050)
A6: Marketed Renewable Energy
A7: Residential (wood) | B7: Renewable Energy: Marketed Use: Residential: Wood: Reference case | C7: AEO.2022.REF2022.CNSM_NA_RESD_NA_BMS_NA_NA_QBTU.A | D7: quads | F7: 0.463778 | G7: 0.483735 | H7: 0.453515 | I7: 0.450879 | J7: 0.44873 | K7: 0.446162 | L7: 0.442512 | M7: 0.43797 | N7: 0.432095 | O7: 0.424601 | P7: 0.417937 | Q7: 0.411333 | R7: 0.404265 | S7: 0.396807 | T7: 0.389404 | U7: 0.382276 | V7: 0.37601 | W7: 0.370007 | X7: 0.363737 | Y7: 0.357937 | Z7: 0.352367 | AA7: 0.346852 | AB7: 0.342168 | AC7: 0.338413 | AD7: 0.334752 | AE7: 0.331473 | AF7: 0.327686 | AG7: 0.32328 | AH7: 0.318664 | AI7: 0.313908 | AJ7: -0.013
A8: Commercial (biomass) | B8: Renewable Energy: Marketed Use: Commercial: Biomass: Reference case | C8: AEO.2022.REF2022.CNSM_NA_COMM_NA_BMS_NA_NA_QBTU.A | D8: quads | F8: 0.124386 | G8: 0.124386 | H8: 0.124386 | I8: 0.124386 | J8: 0.124386 | K8: 0.124386 | L8: 0.124386 | M8: 0.124386 | N8: 0.124386 | O8: 0.124386 | P8: 0.124386 | Q8: 0.124386 | R8: 0.124386 | S8: 0.124386 | T8: 0.124386 | U8: 0.124386 | V8: 0.124386 | W8: 0.124386 | X8: 0.124386 | Y8: 0.124386 | Z8: 0.124386 | AA8: 0.124386 | AB8: 0.124386 | AC8: 0.124386 | AD8: 0.124386 | AE8: 0.124386 | AF8: 0.124386 | AG8: 0.124386 | AH8: 0.124386 | AI8: 0.124386 | AJ8: 0
A9: Industrial | B9: Renewable Energy: Marketed Use: Industrial: Reference case | C9: AEO.2022.REF2022.CNSM_NA_IDAL_NA_MRE_NA_NA_QBTU.A | D9: quads | F9: 2.496644 | G9: 2.530462 | H9: 2.497888 | I9: 2.523535 | J9: 2.555713 | K9: 2.571653 | L9: 2.580374 | M9: 2.593268 | N9: 2.609464 | O9: 2.629252 | P9: 2.64608 | Q9: 2.659712 | R9: 2.672037 | S9: 2.682685 | T9: 2.693303 | U9: 2.704962 | V9: 2.719073 | W9: 2.735342 | X9: 2.751694 | Y9: 2.776412 | Z9: 2.798453 | AA9: 2.822463 | AB9: 2.846729 | AC9: 2.867383 | AD9: 2.887165 | AE9: 2.912558 | AF9: 2.934979 | AG9: 2.962943 | AH9: 2.988084 | AI9: 3.020718 | AJ9: 0.007
A10: Conventional Hydroelectric Power | B10: Renewable Energy: Marketed Use: Industrial: Hydropower: Reference case | C10: AEO.2022.REF2022.CNSM_NA_IDAL_NA_HYD_CNV_NA_QBTU.A | D10: quads | F10: 0.010519 | G10: 0.010658 | H10: 0.010818 | I10: 0.010976 | J10: 0.011128 | K10: 0.011272 | L10: 0.011405 | M10: 0.011526 | N10: 0.011632 | O10: 0.011721 | P10: 0.011792 | Q10: 0.011844 | R10: 0.011875 | S10: 0.011886 | T10: 0.011886 | U10: 0.011886 | V10: 0.011886 | W10: 0.011886 | X10: 0.011886 | Y10: 0.011886 | Z10: 0.011886 | AA10: 0.011886 | AB10: 0.011886 | AC10: 0.011886 | AD10: 0.011886 | AE10: 0.011886 | AF10: 0.011886 | AG10: 0.011886 | AH10: 0.011886 | AI10: 0.011886 | AJ10: 0.004
A11: Municipal Waste | B11: Renewable Energy: Marketed Use: Industrial: Municipal Waste: Reference case | C11: AEO.2022.REF2022.CNSM_NA_IDAL_NA_MUNWST_NA_NA_QBTU.A | D11: quads | F11: 0.156335 | G11: 0.154814 | H11: 0.15681 | I11: 0.159629 | J11: 0.16169 | K11: 0.163167 | L11: 0.164418 | M11: 0.164777 | N11: 0.165245 | O11: 0.16607 | P11: 0.166877 | Q11: 0.167135 | R11: 0.167544 | S11: 0.167953 | T11: 0.168182 | U11: 0.168222 | V11: 0.168175 | W11: 0.168405 | X11: 0.168585 | Y11: 0.169585 | Z11: 0.170501 | AA11: 0.171359 | AB11: 0.172656 | AC11: 0.173904 | AD11: 0.175097 | AE11: 0.176401 | AF11: 0.177634 | AG11: 0.178918 | AH11: 0.180221 | AI11: 0.181737 | AJ11: 0.005
A12: Biomass | B12: Renewable Energy: Marketed Use: Industrial: Biomass: Reference case | C12: AEO.2022.REF2022.CNSM_NA_IDAL_NA_BMS_NA_NA_QBTU.A | D12: quads | F12: 1.3896 | G12: 1.410222 | H12: 1.414995 | I12: 1.435591 | J12: 1.454187 | K12: 1.464957 | L12: 1.469858 | M12: 1.480521 | N12: 1.496045 | O12: 1.508449 | P12: 1.520013 | Q12: 1.528893 | R12: 1.534837 | S12: 1.539657 | T12: 1.544073 | U12: 1.549468 | V12: 1.556269 | W12: 1.564724 | X12: 1.572327 | Y12: 1.579641 | Z12: 1.59223 | AA12: 1.606303 | AB12: 1.619699 | AC12: 1.628914 | AD12: 1.636636 | AE12: 1.648889 | AF12: 1.658079 | AG12: 1.664214 | AH12: 1.674716 | AI12: 1.691527 | AJ12: 0.007
A13: Biofuels Heat and Coproducts | B13: Renewable Energy: Marketed Use: Industrial: Biofuels Heat and Coproducts: Reference case | C13: AEO.2022.REF2022.CNSM_NA_IDAL_NA_BFH_NA_NA_QBTU.A | D13: quads | F13: 0.94019 | G13: 0.954767 | H13: 0.915264 | I13: 0.917338 | J13: 0.928709 | K13: 0.932258 | L13: 0.934692 | M13: 0.936444 | N13: 0.936543 | O13: 0.943012 | P13: 0.947397 | Q13: 0.951841 | R13: 0.957781 | S13: 0.963188 | T13: 0.969162 | U13: 0.975386 | V13: 0.982744 | W13: 0.990327 | X13: 0.998896 | Y13: 1.015301 | Z13: 1.023836 | AA13: 1.032915 | AB13: 1.042488 | AC13: 1.05268 | AD13: 1.063547 | AE13: 1.075383 | AF13: 1.087381 | AG13: 1.107926 | AH13: 1.121262 | AI13: 1.135569 | AJ13: 0.007
A14: Transportation | B14: Renewable Energy: Marketed Use: Transportation: Reference case | C14: AEO.2022.REF2022.CNSM_NA_TRN_NA_NA_NA_NA_QBTU.A | D14: quads | F14: 1.481083 | G14: 1.595972 | H14: 1.570117 | I14: 1.569048 | J14: 1.567658 | K14: 1.566599 | L14: 1.565629 | M14: 1.564616 | N14: 1.563762 | O14: 1.562576 | P14: 1.561213 | Q14: 1.559942 | R14: 1.55878 | S14: 1.557684 | T14: 1.573331 | U14: 1.568047 | V14: 1.576267 | W14: 1.61363 | X14: 1.618422 | Y14: 1.619595 | Z14: 1.640474 | AA14: 1.654707 | AB14: 1.685681 | AC14: 1.715283 | AD14: 1.729491 | AE14: 1.751297 | AF14: 1.765245 | AG14: 1.788393 | AH14: 1.811662 | AI14: 1.829423 | AJ14: 0.007
A15: Ethanol used in E85 | B15: Renewable Energy: Marketed Use: Transportation: Ethanol used in E85: Reference case | C15: AEO.2022.REF2022.CNSM_NA_TRN_NA_ETE_NA_NA_QBTU.A | D15: quads | F15: 0.02388 | G15: 0.024522 | H15: 0.022864 | I15: 0.022616 | J15: 0.022372 | K15: 0.021777 | L15: 0.021071 | M15: 0.020277 | N15: 0.019567 | O15: 0.018792 | P15: 0.017954 | Q15: 0.01722 | R15: 0.016794 | S15: 0.015887 | T15: 0.015386 | U15: 0.015355 | V15: 0.015245 | W15: 0.015007 | X15: 0.015038 | Y15: 0.015083 | Z15: 0.01512 | AA15: 0.015291 | AB15: 0.015418 | AC15: 0.015548 | AD15: 0.015729 | AE15: 0.015907 | AF15: 0.016133 | AG15: 0.01639 | AH15: 0.016655 | AI15: 0.016946 | AJ15: -0.012
A16: Ethanol used in Gasoline Blending | B16: Renewable Energy: Marketed Use: Transportation: Ethanol used in Gasoline Blending: Reference case | C16: AEO.2022.REF2022.CNSM_NA_TRN_NA_EBL_NA_NA_QBTU.A | D16: quads | F16: 1.096564 | G16: 1.130419 | H16: 1.169692 | I16: 1.169188 | J16: 1.173701 | K16: 1.17659 | L16: 1.17704 | M16: 1.176579 | N16: 1.177181 | O16: 1.179507 | P16: 1.182875 | Q16: 1.185697 | R16: 1.190464 | S16: 1.195611 | T16: 1.200457 | U16: 1.204376 | V16: 1.209625 | W16: 1.21545 | X16: 1.222369 | Y16: 1.229884 | Z16: 1.237184 | AA16: 1.245143 | AB16: 1.25352 | AC16: 1.262774 | AD16: 1.273024 | AE16: 1.284625 | AF16: 1.296338 | AG16: 1.307989 | AH16: 1.321071 | AI16: 1.335503 | AJ16: 0.007
A17: Biodiesel used in Distillate Blending | B17: Renewable Energy: Marketed Use: Transportation: Biodiesel used in Distillate Blending: Reference case | C17: AEO.2022.REF2022.CNSM_NA_TRN_NA_BUD_NA_NA_QBTU.A | D17: quads | F17: 0.214324 | G17: 0.240857 | H17: 0.165567 | I17: 0.165352 | J17: 0.159718 | K17: 0.158429 | L17: 0.160165 | M17: 0.161367 | N17: 0.164184 | O17: 0.163796 | P17: 0.156588 | Q17: 0.15267 | R17: 0.150928 | S17: 0.151302 | T17: 0.156429 | U17: 0.157215 | V17: 0.160409 | W17: 0.176145 | X17: 0.177494 | Y17: 0.179785 | Z17: 0.183994 | AA17: 0.18618 | AB17: 0.200011 | AC17: 0.213223 | AD17: 0.216842 | AE17: 0.224952 | AF17: 0.229112 | AG17: 0.236551 | AH17: 0.243485 | AI17: 0.247466 | AJ17: 0.005
A18: Biobutanol | B18: Renewable Energy: Marketed Use: Transportation: Biobutanol: Reference case | C18: AEO.2022.REF2022.CNSM_NA_TRN_NA_BIOB_NA_NA_NA.A | D18: quads | F18: 0 | G18: 0 | H18: 0 | I18: 0 | J18: 0 | K18: 0 | L18: 0 | M18: 0 | N18: 0 | O18: 0 | P18: 0 | Q18: 0 | R18: 0 | S18: 0 | T18: 0 | U18: 0 | V18: 0 | W18: 0 | X18: 0 | Y18: 0 | Z18: 0 | AA18: 0 | AB18: 0 | AC18: 0 | AD18: 0 | AE18: 0 | AF18: 0 | AG18: 0 | AH18: 0 | AI18: 0 | AJ18: - -
A19: Liquids from Biomass | B19: Renewable Energy: Marketed Use: Transportation: Liquids from Biomass: Reference case | C19: AEO.2022.REF2022.CNSM_NA_TRN_NA_LFB_NA_NA_QBTU.A | D19: quads | F19: 1.3e-05 | G19: 0 | H19: 0.000247 | I19: 0 | J19: 0.000218 | K19: 0 | L19: 0 | M19: 0 | N19: 0 | O19: 0 | P19: 0.000253 | Q19: 0 | R19: 0 | S19: 0 | T19: 0 | U19: 0 | V19: 0 | W19: 0 | X19: 0 | Y19: 0 | Z19: 0 | AA19: 0 | AB19: 0 | AC19: 0.000253 | AD19: 0 | AE19: 0.000253 | AF19: 0.000248 | AG19: 0.000253 | AH19: 0.000253 | AI19: 0.000253 | AJ19: 0.109
A20: Renewable Diesel and Gasoline | B20: Renewable Energy: Marketed Use: Transportation: Green Liquids: Reference case | C20: AEO.2022.REF2022.CNSM_NA_TRN_NA_GLQ_NA_NA_QBTU.A | D20: quads | F20: 0.146303 | G20: 0.200174 | H20: 0.211747 | I20: 0.211891 | J20: 0.211649 | K20: 0.209803 | L20: 0.207353 | M20: 0.206393 | N20: 0.202829 | O20: 0.200481 | P20: 0.203543 | Q20: 0.204356 | R20: 0.200594 | S20: 0.194884 | T20: 0.201059 | U20: 0.191101 | V20: 0.190988 | W20: 0.207028 | X20: 0.203521 | Y20: 0.194843 | Z20: 0.204176 | AA20: 0.208094 | AB20: 0.216732 | AC20: 0.223486 | AD20: 0.223896 | AE20: 0.225561 | AF20: 0.223414 | AG20: 0.22721 | AH20: 0.230199 | AI20: 0.229255 | AJ20: 0.016
A21: Electric Power | B21: Renewable Energy: Marketed Use: Electric Power: Reference case | C21: AEO.2022.REF2022.CNSM_NA_ELEP_NA_NA_NA_NA_QBTU.A | D21: quads | F21: 7.164837 | G21: 7.95489 | H21: 8.60901 | I21: 9.667582 | J21: 10.268406 | K21: 10.528873 | L21: 10.6873 | M21: 10.936319 | N21: 11.463621 | O21: 11.873926 | P21: 12.113972 | Q21: 12.317896 | R21: 12.656253 | S21: 13.125913 | T21: 13.512785 | U21: 13.861454 | V21: 14.081444 | W21: 14.214426 | X21: 14.396395 | Y21: 14.565773 | Z21: 14.657819 | AA21: 14.808374 | AB21: 15.045956 | AC21: 15.162731 | AD21: 15.315306 | AE21: 15.491807 | AF21: 15.70385 | AG21: 15.925936 | AH21: 16.170849 | AI21: 16.416498 | AJ21: 0.029
A22: Conventional Hydroelectric Power | B22: Renewable Energy: Marketed Use: Electric Power: Hydropower: Reference case | C22: AEO.2022.REF2022.CNSM_NA_ELEP_NA_HYD_CNV_NA_QBTU.A | D22: quads | F22: 2.278509 | G22: 2.386126 | H22: 2.506349 | I22: 2.597265 | J22: 2.547893 | K22: 2.521233 | L22: 2.505932 | M22: 2.481081 | N22: 2.470032 | O22: 2.448954 | P22: 2.437599 | Q22: 2.429201 | R22: 2.416351 | S22: 2.407975 | T22: 2.390304 | U22: 2.377386 | V22: 2.363961 | W22: 2.350256 | X22: 2.336961 | Y22: 2.336046 | Z22: 2.331888 | AA22: 2.31647 | AB22: 2.302012 | AC22: 2.299827 | AD22: 2.290988 | AE22: 2.284513 | AF22: 2.278644 | AG22: 2.245361 | AH22: 2.230556 | AI22: 2.227889 | AJ22: -0.001
A23: Geothermal | B23: Renewable Energy: Marketed Use: Electric Power: Geothermal: Reference case | C23: AEO.2022.REF2022.CNSM_NA_ELEP_NA_GEOTHM_NA_NA_QBTU.A | D23: quads | F23: 0.139767 | G23: 0.140145 | H23: 0.139517 | I23: 0.13769 | J23: 0.144374 | K23: 0.152013 | L23: 0.161825 | M23: 0.171325 | N23: 0.182837 | O23: 0.192774 | P23: 0.202227 | Q23: 0.215724 | R23: 0.226798 | S23: 0.240608 | T23: 0.252648 | U23: 0.265345 | V23: 0.276736 | W23: 0.28721 | X23: 0.297147 | Y23: 0.307823 | Z23: 0.316766 | AA23: 0.322668 | AB23: 0.328969 | AC23: 0.337832 | AD23: 0.345586 | AE23: 0.351624 | AF23: 0.355346 | AG23: 0.358731 | AH23: 0.362486 | AI23: 0.365868 | AJ23: 0.034
A24: Biogenic Municipal Waste | B24: Renewable Energy: Marketed Use: Electric Power: Biogenic Municipal Waste: Reference case | C24: AEO.2022.REF2022.CNSM_NA_ELEP_NA_BGM_NA_NA_QBTU.A | D24: quads | F24: 0.281054 | G24: 0.281471 | H24: 0.297916 | I24: 0.309257 | J24: 0.318267 | K24: 0.32755 | L24: 0.340255 | M24: 0.345118 | N24: 0.35495 | O24: 0.363817 | P24: 0.373888 | Q24: 0.387101 | R24: 0.40103 | S24: 0.408984 | T24: 0.422672 | U24: 0.43479 | V24: 0.445378 | W24: 0.460285 | X24: 0.46768 | Y24: 0.475504 | Z24: 0.485565 | AA24: 0.494466 | AB24: 0.50627 | AC24: 0.514772 | AD24: 0.521608 | AE24: 0.527975 | AF24: 0.54013 | AG24: 0.54455 | AH24: 0.557815 | AI24: 0.565178 | AJ24: 0.024
A25: Biomass | B25: Renewable Energy: Marketed Use: Electric Power: Biomass: Reference case | C25: AEO.2022.REF2022.CNSM_NA_ELEP_NA_BMS_NA_NA_QBTU.A | D25: quads | F25: 0.205146 | G25: 0.192008 | H25: 0.188325 | I25: 0.181888 | J25: 0.186007 | K25: 0.18369 | L25: 0.180898 | M25: 0.172945 | N25: 0.173301 | O25: 0.171745 | P25: 0.175047 | Q25: 0.174542 | R25: 0.177776 | S25: 0.177446 | T25: 0.175941 | U25: 0.17483 | V25: 0.17528 | W25: 0.175844 | X25: 0.175573 | Y25: 0.175385 | Z25: 0.175217 | AA25: 0.174436 | AB25: 0.1746 | AC25: 0.174804 | AD25: 0.174806 | AE25: 0.174621 | AF25: 0.174744 | AG25: 0.174755 | AH25: 0.17454 | AI25: 0.174565 | AJ25: -0.006
A26: Dedicated Plants | B26: Renewable Energy: Marketed Use: Electric Power: Biomass: Dedicated Plants: Reference case | C26: AEO.2022.REF2022.CNSM_NA_ELEP_NA_DPE_NA_NA_QBTU.A | D26: quads | F26: 0.169064 | G26: 0.158647 | H26: 0.156547 | I26: 0.15044 | J26: 0.149862 | K26: 0.149761 | L26: 0.149678 | M26: 0.14295 | N26: 0.142392 | O26: 0.142117 | P26: 0.144788 | Q26: 0.143838 | R26: 0.146949 | S26: 0.146946 | T26: 0.145868 | U26: 0.145283 | V26: 0.145349 | W26: 0.145438 | X26: 0.145131 | Y26: 0.145375 | Z26: 0.145376 | AA26: 0.144652 | AB26: 0.144549 | AC26: 0.144369 | AD26: 0.144376 | AE26: 0.144205 | AF26: 0.144311 | AG26: 0.144322 | AH26: 0.144137 | AI26: 0.144156 | AJ26: -0.005
A27: Cofiring | B27: Renewable Energy: Marketed Use: Electric Power: Biomass: Cofiring: Reference case | C27: AEO.2022.REF2022.CNSM_NA_ELEP_NA_CFR_NA_NA_QBTU.A | D27: quads | F27: 0.036083 | G27: 0.033361 | H27: 0.031778 | I27: 0.031448 | J27: 0.036145 | K27: 0.033929 | L27: 0.03122 | M27: 0.029995 | N27: 0.030909 | O27: 0.029628 | P27: 0.030259 | Q27: 0.030703 | R27: 0.030826 | S27: 0.0305 | T27: 0.030073 | U27: 0.029548 | V27: 0.029931 | W27: 0.030406 | X27: 0.030442 | Y27: 0.030011 | Z27: 0.029841 | AA27: 0.029784 | AB27: 0.030051 | AC27: 0.030434 | AD27: 0.03043 | AE27: 0.030416 | AF27: 0.030432 | AG27: 0.030433 | AH27: 0.030403 | AI27: 0.030409 | AJ27: -0.006
A28: Solar Thermal | B28: Renewable Energy: Marketed Use: Electric Power: Solar Thermal: Reference case | C28: AEO.2022.REF2022.CNSM_NA_ELEP_NA_SLR_THERM_NA_QBTU.A | D28: quads | F28: 0.028909 | G28: 0.027994 | H28: 0.026036 | I28: 0.025486 | J28: 0.025027 | K28: 0.024038 | L28: 0.023782 | M28: 0.024011 | N28: 0.023512 | O28: 0.023401 | P28: 0.022885 | Q28: 0.023164 | R28: 0.023164 | S28: 0.023089 | T28: 0.023039 | U28: 0.023255 | V28: 0.022916 | W28: 0.02235 | X28: 0.022423 | Y28: 0.021824 | Z28: 0.022436 | AA28: 0.020022 | AB28: 0.022952 | AC28: 0.020869 | AD28: 0.020237 | AE28: 0.020551 | AF28: 0.020455 | AG28: 0.020353 | AH28: 0.019676 | AI28: 0.022031 | AJ28: -0.009
A29: Solar Photovoltaic | B29: Renewable Energy: Marketed Use: Electric Power: Solar Photovoltaic: Reference case | C29: AEO.2022.REF2022.CNSM_NA_ELEP_NA_SLR_PHTVL_NA_QBTU.A | D29: quads | F29: 0.910082 | G29: 1.204032 | H29: 1.599433 | I29: 2.396997 | J29: 2.642442 | K29: 2.773188 | L29: 2.90058 | M29: 3.140108 | N29: 3.591925 | O29: 3.819357 | P29: 4.001662 | Q29: 4.18863 | R29: 4.519379 | S29: 4.849735 | T29: 5.046693 | U29: 5.304826 | V29: 5.476848 | W29: 5.59964 | X29: 5.779035 | Y29: 5.906889 | Z29: 5.969163 | AA29: 6.080739 | AB29: 6.234192 | AC29: 6.350657 | AD29: 6.492189 | AE29: 6.600983 | AF29: 6.766973 | AG29: 6.998704 | AH29: 7.205952 | AI29: 7.372166 | AJ29: 0.075
A30: Wind | B30: Renewable Energy: Marketed Use: Electric Power: Wind: Reference case | C30: AEO.2022.REF2022.CNSM_NA_ELEP_NA_WND_NA_NA_QBTU.A | D30: quads | F30: 3.321371 | G30: 3.723115 | H30: 3.851433 | I30: 4.018998 | J30: 4.404397 | K30: 4.54716 | L30: 4.574028 | M30: 4.601732 | N30: 4.667064 | O30: 4.853878 | P30: 4.900664 | Q30: 4.899534 | R30: 4.891755 | S30: 5.018075 | T30: 5.201488 | U30: 5.281021 | V30: 5.320325 | W30: 5.318841 | X30: 5.317576 | Y30: 5.342301 | Z30: 5.356784 | AA30: 5.399573 | AB30: 5.476961 | AC30: 5.463971 | AD30: 5.469892 | AE30: 5.53154 | AF30: 5.567556 | AG30: 5.583482 | AH30: 5.619822 | AI30: 5.6888 | AJ30: 0.019
A31: Total Marketed Renewable Energy | B31: Renewable Energy: Total Marketed Renewable Energy Use: Reference case | C31: AEO.2022.REF2022.CNSM_NA_NA_NA_NA_NA_NA_QBTU.A | D31: quads | F31: 11.730729 | G31: 12.689444 | H31: 13.254916 | I31: 14.335429 | J31: 14.964892 | K31: 15.237675 | L31: 15.4002 | M31: 15.65656 | N31: 16.193329 | O31: 16.614742 | P31: 16.863588 | Q31: 17.073269 | R31: 17.41572 | S31: 17.887474 | T31: 18.293209 | U31: 18.641125 | V31: 18.87718 | W31: 19.057791 | X31: 19.254635 | Y31: 19.444103 | Z31: 19.5735 | AA31: 19.756783 | AB31: 20.04492 | AC31: 20.208197 | AD31: 20.3911 | AE31: 20.611523 | AF31: 20.856146 | AG31: 21.124939 | AH31: 21.413647 | AI31: 21.704933 | AJ31: 0.021
A32: Sources of Ethanol
A33: From Corn and Other Starch | B33: Renewable Energy: Sources of Ethanol: From Corn: Reference case | C33: AEO.2022.REF2022.SUP_PRD_FCO_NA_ETH_NA_NA_QBTU.A | D33: quads | F33: 1.21785 | G33: 1.260142 | H33: 1.333862 | I33: 1.336415 | J33: 1.351975 | K33: 1.357633 | L33: 1.361493 | M33: 1.364473 | N33: 1.364559 | O33: 1.374466 | P33: 1.381244 | Q33: 1.388113 | R33: 1.397095 | S33: 1.406098 | T33: 1.415326 | U33: 1.424217 | V33: 1.434494 | W33: 1.445341 | X33: 1.457672 | Y33: 1.481548 | Z33: 1.494822 | AA33: 1.50903 | AB33: 1.52377 | AC33: 1.53978 | AD33: 1.556515 | AE33: 1.575252 | AF33: 1.59407 | AG33: 1.62578 | AH33: 1.64666 | AI33: 1.669157 | AJ33: 0.011
A34: From Cellulose | B34: Renewable Energy: Sources of Ethanol: From Cellulose: Reference case | C34: AEO.2022.REF2022.SUP_PRD_FCE_NA_ETH_NA_NA_QBTU.A | D34: quads | F34: 0.001414 | G34: 0.000689 | H34: 0.000468 | I34: 0.00071 | J34: 0.000496 | K34: 0.00071 | L34: 0.00071 | M34: 0.00071 | N34: 0.00071 | O34: 0.00071 | P34: 0.000463 | Q34: 0.00071 | R34: 0.00071 | S34: 0.00071 | T34: 0.00071 | U34: 0.00071 | V34: 0.00071 | W34: 0.00071 | X34: 0.00071 | Y34: 0.00071 | Z34: 0.00071 | AA34: 0.00071 | AB34: 0.00071 | AC34: 0.000463 | AD34: 0.00071 | AE34: 0.000463 | AF34: 0.000467 | AG34: 0.000463 | AH34: 0.000463 | AI34: 0.000463 | AJ34: -0.038
A35: Net Imports | B35: Renewable Energy: Sources of Ethanol: Net Imports: Reference case | C35: AEO.2022.REF2022.SUP_NETIMP_NA_NA_ETH_NA_NA_QBTU.A | D35: quads | F35: -0.09882 | G35: -0.10589 | H35: -0.141775 | I35: -0.14532 | J35: -0.156399 | K35: -0.159976 | L35: -0.164093 | M35: -0.168328 | N35: -0.168521 | O35: -0.176878 | P35: -0.180877 | Q35: -0.185906 | R35: -0.190548 | S35: -0.19531 | T35: -0.200193 | U35: -0.205196 | V35: -0.210335 | W35: -0.215595 | X35: -0.220975 | Y35: -0.237292 | Z35: -0.243228 | AA35: -0.249306 | AB35: -0.255543 | AC35: -0.261921 | AD35: -0.268473 | AE35: -0.275183 | AF35: -0.282066 | AG35: -0.301864 | AH35: -0.309397 | AI35: -0.317171 | AJ35: 0.041
A36: Total U.S. Supply of Ethanol | B36: Renewable Energy: Total U.S. Supply of Ethanol: Reference case | C36: AEO.2022.REF2022.SUP_NA_NA_NA_ETH_NA_NA_QBTU.A | D36: quads | F36: 1.120444 | G36: 1.15494 | H36: 1.192555 | I36: 1.191805 | J36: 1.196072 | K36: 1.198367 | L36: 1.198111 | M36: 1.196856 | N36: 1.196748 | O36: 1.198299 | P36: 1.200829 | Q36: 1.202916 | R36: 1.207257 | S36: 1.211498 | T36: 1.215843 | U36: 1.219731 | V36: 1.224869 | W36: 1.230456 | X36: 1.237407 | Y36: 1.244966 | Z36: 1.252304 | AA36: 1.260433 | AB36: 1.268938 | AC36: 1.278322 | AD36: 1.288753 | AE36: 1.300532 | AF36: 1.312471 | AG36: 1.324379 | AH36: 1.337726 | AI36: 1.352449 | AJ36: 0.007
A37: Nonmarketed Renewable Energy
A38: Selected Consumption
A39: Residential | B39: Renewable Energy: Nonmarketed Selected Use: Residential: Reference case | C39: AEO.2022.REF2022.CNSM_NA_RESD_NA_NA_NA_NA_QBTU.A | D39: quads | F39: 0.340788 | G39: 0.381309 | H39: 0.419325 | I39: 0.442722 | J39: 0.467823 | K39: 0.490065 | L39: 0.516998 | M39: 0.544956 | N39: 0.572551 | O39: 0.60084 | P39: 0.633196 | Q39: 0.664056 | R39: 0.697855 | S39: 0.731961 | T39: 0.767872 | U39: 0.80532 | V39: 0.846867 | W39: 0.890039 | X39: 0.937502 | Y39: 0.986676 | Z39: 1.035265 | AA39: 1.089061 | AB39: 1.148234 | AC39: 1.205276 | AD39: 1.26791 | AE39: 1.331056 | AF39: 1.398572 | AG39: 1.474351 | AH39: 1.555907 | AI39: 1.63301 | AJ39: 0.056
A40: Solar Hot Water Heating | B40: Renewable Energy: Nonmarketed Selected Use: Residential: Solar Hot Water Heating: Reference case | C40: AEO.2022.REF2022.CNSM_NA_RESD_NA_SHW_NA_NA_QBTU.A | D40: quads | F40: 0.048449 | G40: 0.054094 | H40: 0.057747 | I40: 0.05701 | J40: 0.056903 | K40: 0.056573 | L40: 0.056635 | M40: 0.056603 | N40: 0.056563 | O40: 0.056604 | P40: 0.0569 | Q40: 0.057071 | R40: 0.057255 | S40: 0.057186 | T40: 0.057152 | U40: 0.057105 | V40: 0.057269 | W40: 0.057571 | X40: 0.057897 | Y40: 0.058241 | Z40: 0.05843 | AA40: 0.058646 | AB40: 0.058917 | AC40: 0.05919 | AD40: 0.059469 | AE40: 0.059692 | AF40: 0.060043 | AG40: 0.060541 | AH40: 0.061066 | AI40: 0.06133 | AJ40: 0.008
...

Sheet AEO 2023 Table 36 Raw
