Workbook

Sheet About
A1: BHRaSYC BAU Heat Rates and Start Year Capacities
A3: Source: | B3: National Energy Control Center (Cenace) | D3: Generation data for 2022 and 2023
B4: Accessed 2024
B5: Public area of ​​the market information system
B6: https://www.cenace.gob.mx/APSIM.aspx
B7: Obtained through the Energy Transition Observatory in Mexico (Obtrenmx.org)
B8: https://obtrenmx.org/
B10: Energy Secretary (Sener) | D10: Capacity data for 2022 and 2023
B11: 2024
B12: National Electric System Development Program
B13: https://www.gob.mx/sener/articulos/programa-de-desarrollo-del-sistema-electrico-nacional-2024-2038
B14: Programa de Desarrollo del Sistema Eléctrico Nacional
B16: FUEL CONSUMPTION FOR ELECTRICAL GENERATION | D16: Data for 2022 and 2023
B17: Energy Ministry (SENER)
B18: 2024
B19: National Energy Balance 2023
B20: https://www.gob.mx/cms/uploads/attachment/file/947752/BALANCE_NACIONAL_DE_ENERG_A_PRELIMINAR_2023.pdf
B21: CUADRO A.17 CONSUMO DE COMBUSTIBLES PARA GENERACIÓN ELÉCTRICA
B23: National council of humanities, sciences and technologies | D23: Data for 2012 to 2021
B24: 2024
B25: Energy futures for Mexico by 2050 The path to a just and sustainable energy transition
B26: https://conahcyt.mx/wp-content/uploads/pronaces/micrositios/energia_y_cambio_climatico/energia/cuadernos_tematicos/Cuaderno_9.pdf
A29: Notes
B30: Gen2022-2023: Preprocessed information in BAU Trans and Distr Loss Perc.xlsx
B31: The specific uses of each generation technology are included in the heat rate so that this element represents the entire conversion of fuel to net energy injected into the grid.
B32: We use natural gas combustion turbines as a proxy for hydrogen combustion turbines, since we would expect most hydrogen plants to be retrofits of gas plants.
A34: Unit conversion
A35: BTU/PJ | B35: =5414093.87/0.00000571187/1000000 -> 947867.14
B36: 1 | C36: BEP | D36: 5414093.9 | E36: BTU
B37: 1 | C37: BEP | D37: 5.71187e-06 | E37: PJ
A38: Source: https://dof.gob.mx/nota_detalle.php?codigo=5278970&fecha=23/11/2012#gsc.tab=0
B41: hard coal | C41: Carboeléctrica
B42: natural gas steam turbine | C42: Combustión Interna
B43: natural gas combined cycle | C43: Ciclo combinado
B44: nuclear | C44: Nuclear
B45: hydro | C45: Hidroeléctrica
B46: onshore wind | C46: Eólica
B47: solar PV | C47: Solar
B48: solar thermal
B49: biomass | C49: Biomasa
...

Sheet Gen2022-2023
C1: 2022 | D1: 2023
B2: Eolica | C2: 20302337 | D2: 20699882
B3: Fotovoltaica | C3: 16287206 | D3: 18209101
B4: Biomasa | C4: 95359 | D4: 96959
B5: Carboelectrica | C5: 14191640 | D5: 14237878
B6: Ciclo Combinado | C6: 193994868 | D6: 203605022
B7: Combustion Interna | C7: 1843740 | D7: 3636195
B8: Geotermoelectrica | C8: 4368545 | D8: 4113284
B9: Hidroelectrica | C9: 35551309 | D9: 20595830
B10: Nucleoelectrica | C10: 10538743 | D10: 12043391
B11: Termica Convencional | C11: 21116986 | D11: 31182145
B12: Turbo Gas | C12: 15486778 | D12: 17849573

Sheet Cap2020-2023
A1: Cuadro A1.4 Capacidad instalada interconectada de la CFE y del resto de los permisionarios (MW), se excluyen centrales en pruebas
A2: Tecnología | B2: 2020 | C2: 2021 | D2: 2022 | E2: 2023
A3: Hidroeléctrica | B3: 12612 | C3: 12614 | D3: 12613 | E3: 12612
A4: Geotermoeléctrica | B4: 951 | C4: 976 | D4: 976 | E4: 976
A5: Eoloeléctrica | B5: 6504 | C5: 6977 | D5: 6921 | E5: 7055
A6: Fotovoltaica | B6: 5149 | C6: 5955 | D6: 6535 | E6: 7469
A7: Bioenergía | B7: 378 | C7: 378 | D7: 408 | E7: 407
A8: Suma limpia renovable | B8: =SUM(B3:B7) -> 25594 | C8: =SUM(C3:C7) -> 26900 | D8: =SUM(D3:D7) -> 27453 | E8: =SUM(E3:E7) -> 28519
A9: Nucleoelectrica | B9: 1608 | C9: 1608 | D9: 1608 | E9: 1608
A10: Cogeneración eficiente | B10: 2305 | C10: 2305 | D10: 2308 | E10: 2322
A11: Suma limpia no renovable | B11: =SUM(B9:B10) -> 3913 | C11: =SUM(C9:C10) -> 3913 | D11: =SUM(D9:D10) -> 3916 | E11: =SUM(E9:E10) -> 3930
A12: Total capacidad de energía limpia | B12: =B11+B8 -> 29507 | C12: =C11+C8 -> 30813 | D12: =D11+D8 -> 31369 | E12: =E11+E8 -> 32449
A13: Porcentaje | B13: =B12/B19 -> 0.35498424 | C13: =C12/C19 -> 0.35765025 | D13: =D12/D19 -> 0.36002112 | E13: =E12/E19 -> 0.36456683
A14: Ciclo combinado | B14: 31948 | C14: 33640 | D14: 34413 | E14: 35178
A15: Termica convencional | B15: 11809 | C15: 11793 | D15: 11343 | E15: 11300
A16: Turbogas | B16: 3545 | C16: 3744 | D16: 3815 | E16: 3888
A17: Combsutión interna | B17: 850 | C17: 701 | D17: 728 | E17: 729
A18: Carboeléctrica | B18: 5463 | C18: 5463 | D18: 5463 | E18: 5463
A19: Total | B19: =SUM(B14:B18,B12) -> 83122 | C19: =SUM(C14:C18,C12) -> 86154 | D19: =SUM(D14:D18,D12) -> 87131 | E19: =SUM(E14:E18,E12) -> 89007

Sheet 2012-2021
A1: CAP(t,ā) | B1: Capacidad instalada por tecnología y año histórico
B2: 2012 | C2: 2013 | D2: 2014 | E2: 2015 | F2: 2016 | G2: 2017 | H2: 2018 | I2: 2019 | J2: 2020 | K2: 2021
A3: Ciclo combinado | B3: 18029 | C3: 22830 | D3: 23309 | E3: 24043 | F3: 27274 | G3: 28084 | H3: 34860 | I3: 38265 | J3: 40763 | K3: 41613
A4: Termoeléctrica convencional | B4: 13765 | C4: 15246 | D4: 14614 | E4: 13881 | F4: 14217 | G4: 14383 | H4: 12503 | I4: 12584 | J4: 12399 | K4: 12399
A5: Carboeléctrica | B5: 5378 | C5: 5378 | D5: 5378 | E5: 5378 | F5: 5378 | G5: 5378 | H5: 5498 | I5: 5498 | J5: 5498 | K5: 5498
A6: Turbogás | B6: 2658 | C6: 3418 | D6: 3419 | E6: 4904 | F6: 5052 | G6: 5136 | H6: 5087 | I6: 5308 | J6: 6078 | K6: 6078
A7: Combustión Interna | B7: 1052 | C7: 1146 | D7: 1312 | E7: 1163 | F7: 1453 | G7: 1634 | H7: 2045 | I7: 2118 | J7: 2189 | K7: 2190
A8: Nuclear | B8: 1610 | C8: 1400 | D8: 1400 | E8: 1510 | F8: 1608 | G8: 1608 | H8: 1634 | I8: 1634 | J8: 1634 | K8: 1634
A9: Hidroeléctrica | B9: 11498 | C9: 11679 | D9: 12429 | E9: 12489 | F9: 12589 | G9: 12642 | H9: 12641 | I9: 12641 | J9: 12641 | K9: 12643
A10: Eólica | B10: 1158 | C10: 1611 | D10: 2036 | E10: 2805 | F10: 3735 | G10: 4199 | H10: 4855 | I10: 6040 | J10: 6454 | K10: 6454
A11: Geotérmica | B11: 812 | C11: 823 | D11: 813 | E11: 926 | F11: 909 | G11: 926 | H11: 997 | I11: 997 | J11: 997 | K11: 997
A12: Solar | B12: 6 | C12: 46 | D12: 56 | E12: 56 | F12: 145 | G12: 214 | H12: 1946 | I12: 4598 | J12: 5630 | K12: 6830
A13: Biomasa | B13: 492 | C13: 554 | D13: 685 | E13: 760 | F13: 889 | G13: 1007 | H13: 1082 | I13: 1016 | J13: 1201 | K13: 1201
A14: Generación distribuida | B14: 15 | C14: 29 | D14: 62 | E14: 118 | F14: 248 | G14: 459 | H14: 693 | I14: 1083 | J14: 1551 | K14: 2031
... A18: Concentración solar | B18: 0 | C18: 0 | D18: 0 | E18: 0 | F18: 0 | G18: 0 | H18: 0 | I18: 0 | J18: 0 | K18: 0
A21: GEN.N(t,ā) | B21: Generación neta por tecnología y año histórico
B22: 2012 | C22: 2013 | D22: 2014 | E22: 2015 | F22: 2016 | G22: 2017 | H22: 2018 | I22: 2019 | J22: 2020 | K22: 2021
A23: Ciclo combinado | B23: 129331590 | C23: 139162757 | D23: 145335722 | E23: 151463563 | F23: 152587411 | G23: 154128126 | H23: 159082959 | I23: 171368943 | J23: 181382154 | K23: 184444135
A24: Termoeléctrica convencional | B24: 59561147 | C24: 55036664 | D24: 40410894 | E24: 42474410 | F24: 42023428 | G24: 43947148 | H24: 40010763 | I24: 38661529 | J24: 23095298 | K24: 23495780
A25: Carboeléctrica | B25: 35018872 | C25: 34641891 | D25: 34066857 | E25: 34056857 | F25: 34532398 | G25: 28663360 | H25: 27344983 | I25: 21609445 | J25: 12500718 | K25: 8703941
A26: Turbogás | B26: 7624532 | C26: 7088706 | D26: 9249223 | E26: 11806728 | F26: 12719487 | G26: 14687034 | H26: 14392288 | I26: 16352558 | J26: 14087648 | K26: 15875312
A27: Combustión Interna | B27: 2000855 | C27: 2152886 | D27: 2339164 | E27: 2687125 | F27: 3169777 | G27: 2333057 | H27: 2565641 | I27: 3170220 | J27: 2871416 | K27: 2057546
A28: Nuclear | B28: 8192869 | C28: 11389115 | D28: 9807663 | E28: 11734761 | F28: 10667410 | G28: 10571136 | H28: 13198780 | I28: 10879189 | J28: 10844159 | K28: 11604710
A29: Hidroeléctrica | B29: 32834971 | C29: 28869215 | D29: 39418150 | E29: 31312968 | F29: 31202113 | G29: 31660121 | H29: 32205816 | I29: 23601751 | J29: 26764499 | K29: 34692471
A30: Eólica | B30: 3688311 | C30: 4243237 | D30: 6512767 | E30: 8864169 | F30: 10562222 | G30: 10454444 | H30: 12432938 | I30: 16724388 | J30: 19611291 | K30: 21046312
A31: Geotérmica | B31: 5886681 | C31: 6152271 | D31: 6081015 | E31: 6417273 | F31: 6206302 | G31: 5706169 | H31: 5024663 | I31: 5004941 | J31: 4507430 | K31: 4198496
A32: Solar | B32: 2811 | C32: 19709 | D32: 86148 | E32: 79063 | F32: 161517 | G32: 346947 | H32: 2174389 | I32: 8391865 | J32: 13480212 | K32: 17070210
A33: Biomasa | B33: 1231312 | C33: 1086854 | D33: 1406020 | E33: 1388420 | F33: 1485058 | G33: 1884844 | H33: 1989116 | I33: 1861586 | J33: 2216007 | K33: 1531996
A34: Generación distribuida | B34: 26047 | C34: 51139 | D34: 108602 | E34: 206329 | F34: 432876 | G34: 795392 | H34: 1199886 | I34: 1876363 | J34: 2686390 | K34: 3517980
... A38: Concentración solar | B38: 0 | C38: 0 | D38: 0 | E38: 0 | F38: 0 | G38: 0 | H38: 0 | I38: 0 | J38: 0 | K38: 0
A39: GEN.B(t,ā) | B39: Generación bruta por tecnología y año histórico
B40: 2012 | C40: 2013 | D40: 2014 | E40: 2015 | F40: 2016 | G40: 2017 | H40: 2018 | I40: 2019 | J40: 2020 | K40: 2021
A41: Ciclo combinado | B41: 132704169 | C41: 142791703 | D41: 149125640 | E41: 155413277 | F41: 156566431 | G41: 158147324 | H41: 163231364 | I41: 175837729 | J41: 186112055 | K41: 189253883
A42: Termoeléctrica convencional | B42: 63432622 | C42: 58614048 | D42: 43037603 | E42: 45235248 | F42: 44754951 | G42: 46803713 | H42: 42611463 | I42: 41174529 | J42: 24596493 | K42: 25023006
A43: Carboeléctrica | B43: 37575247 | C43: 37170747 | D43: 36553735 | E43: 36543005 | F43: 37053261 | G43: 30755783 | H43: 29341165 | I43: 23186933 | J43: 13413269 | K43: 9339328
A44: Turbogás | B44: 7827104 | C44: 7277041 | D44: 9494960 | E44: 12120414 | F44: 13057423 | G44: 15077244 | H44: 14774667 | I44: 16787019 | J44: 14461934 | K44: 16297093
A45: Combustión Interna | B45: 2060881 | C45: 2217472 | D45: 2409338 | E45: 2767739 | F45: 3264870 | G45: 2403048 | H45: 2642610 | I45: 3265326 | J45: 2957558 | K45: 2119272
A46: Nuclear | B46: 8479620 | C46: 11787734 | D46: 10150931 | E46: 12145478 | F46: 11040769 | G46: 10941126 | H46: 13660737 | I46: 11259961 | J46: 11223705 | K46: 12010875
A47: Hidroeléctrica | B47: 33166638 | C47: 29160823 | D47: 39816313 | E47: 31629261 | F47: 31517286 | G47: 31979920 | H47: 32531127 | I47: 23840153 | J47: 27034847 | K47: 35042900
A48: Eólica | B48: 3725567 | C48: 4286098 | D48: 6578552 | E48: 8953706 | F48: 10668911 | G48: 10560044 | H48: 12558523 | I48: 16893321 | J48: 19809385 | K48: 21258901
...

Sheet BNE23
I2: 2022 | J2: 2023
H3: Carbón | I3: 111.31 | J3: 145.12
H4: Uranio | I4: 152.77 | J4: 175.7
H5: Biogas | I5: 2.4 | J5: 2.15
H6: Coque de petroleo | I6: 37.78 | J6: 32.61
H7: Diesel | I7: 60 | J7: 38.76
H8: Combustoleo | I8: 228.96 | J8: 233.27
H9: Gas seco | I9: 2216.41 | J9: 2242.49
H10: Bagazo de caña | I10: 48.13 | J10: 46.37
H11: Gas licuado | I11: 0 | J11: 0
H12: Otros | I12: 33.75 | J12: 24
B18: Ciclo combinado
B19: Gas seco | C19: 1531.81
B20: Termoeléctrica convencional
B21: Coque de petróleo | C21: 34.62
B22: Combustóleo | C22: 193.22
B23: Gas seco | C23: 103.72
B24: Turbogás
B25: GLP | C25: 0
B26: Diésel | C26: 29.2
B27: Gas seco | C27: 137.15
B28: Combustión Interna
B29: Biogás | C29: 2.71
B30: Diésel | C30: 3.07 | D30: =I7 -> 60 | E30: =J7 -> 38.76
B31: Gas seco | C31: 23.01

Sheet Calculations
A1: Evolución de la capacidad (MW)
B2: ='2012-2021'!B2 -> 2012 | C2: ='2012-2021'!C2 -> 2013 | D2: ='2012-2021'!D2 -> 2014 | E2: ='2012-2021'!E2 -> 2015 | F2: ='2012-2021'!F2 -> 2016 | G2: ='2012-2021'!G2 -> 2017 | H2: ='2012-2021'!H2 -> 2018 | I2: ='2012-2021'!I2 -> 2019 | ... K2: ='2012-2021'!K2 -> 2021 | L2: 2022 | M2: 2023
A3: Ciclo combinado | B3: ='2012-2021'!B3 -> 18029 | C3: ='2012-2021'!C3 -> 22830 | D3: ='2012-2021'!D3 -> 23309 | E3: ='2012-2021'!E3 -> 24043 | F3: ='2012-2021'!F3 -> 27274 | G3: ='2012-2021'!G3 -> 28084 | H3: =AVERAGE(G3,J3) -> 30016 | I3: =AVERAGE(H3,K3) -> 31828 | J3: ='Cap2020-2023'!B14 -> 31948 | K3: ='Cap2020-2023'!C14 -> 33640 | L3: ='Cap2020-2023'!D14 -> 34413 | M3: ='Cap2020-2023'!E14 -> 35178
A4: Termoeléctrica convencional | B4: ='2012-2021'!B4 -> 13765 | C4: ='2012-2021'!C4 -> 15246 | D4: ='2012-2021'!D4 -> 14614 | E4: ='2012-2021'!E4 -> 13881 | F4: ='2012-2021'!F4 -> 14217 | G4: ='2012-2021'!G4 -> 14383 | H4: ='2012-2021'!H4 -> 12503 | I4: ='2012-2021'!I4 -> 12584 | ... K4: ='2012-2021'!K4 -> 12399 | L4: ='Cap2020-2023'!D15 -> 11343 | M4: ='Cap2020-2023'!E15 -> 11300
A5: Carboeléctrica | B5: ='2012-2021'!B5 -> 5378 | C5: ='2012-2021'!C5 -> 5378 | D5: ='2012-2021'!D5 -> 5378 | E5: ='2012-2021'!E5 -> 5378 | F5: ='2012-2021'!F5 -> 5378 | G5: ='2012-2021'!G5 -> 5378 | H5: ='2012-2021'!H5 -> 5498 | I5: ='2012-2021'!I5 -> 5498 | ... K5: ='2012-2021'!K5 -> 5498 | L5: ='Cap2020-2023'!D18 -> 5463 | M5: ='Cap2020-2023'!E18 -> 5463
A6: Turbogás | B6: ='2012-2021'!B6 -> 2658 | C6: ='2012-2021'!C6 -> 3418 | D6: ='2012-2021'!D6 -> 3419 | E6: ='2012-2021'!E6 -> 4904 | F6: ='2012-2021'!F6 -> 5052 | G6: ='2012-2021'!G6 -> 5136 | H6: ='2012-2021'!H6 -> 5087 | I6: ='2012-2021'!I6 -> 5308 | J6: ='Cap2020-2023'!B16+'Cap2020-2023'!B10*0.5 -> 4697.5 | K6: ='Cap2020-2023'!C16+'Cap2020-2023'!C10*0.5 -> 4896.5 | L6: ='Cap2020-2023'!D16+'Cap2020-2023'!D10*0.5 -> 4969 | M6: ='Cap2020-2023'!E16+'Cap2020-2023'!E10*0.5 -> 5049
A7: Combustión Interna | B7: ='2012-2021'!B7 -> 1052 | C7: ='2012-2021'!C7 -> 1146 | D7: ='2012-2021'!D7 -> 1312 | E7: ='2012-2021'!E7 -> 1163 | F7: ='2012-2021'!F7 -> 1453 | G7: ='2012-2021'!G7 -> 1634 | H7: ='2012-2021'!H7 -> 2045 | I7: ='2012-2021'!I7 -> 2118 | J7: ='Cap2020-2023'!B17+'Cap2020-2023'!B10*0.25 -> 1426.25 | K7: ='Cap2020-2023'!C17+'Cap2020-2023'!C10*0.25 -> 1277.25 | L7: ='Cap2020-2023'!D17+'Cap2020-2023'!D10*0.25 -> 1305 | M7: ='Cap2020-2023'!E17+'Cap2020-2023'!E10*0.25 -> 1309.5
A8: Nuclear | B8: ='2012-2021'!B8 -> 1610 | C8: ='2012-2021'!C8 -> 1400 | D8: ='2012-2021'!D8 -> 1400 | E8: ='2012-2021'!E8 -> 1510 | F8: ='2012-2021'!F8 -> 1608 | G8: ='2012-2021'!G8 -> 1608 | H8: ='2012-2021'!H8 -> 1634 | I8: ='2012-2021'!I8 -> 1634 | ... K8: ='2012-2021'!K8 -> 1634 | L8: ='Cap2020-2023'!D9 -> 1608 | M8: ='Cap2020-2023'!E9 -> 1608
A9: Hidroeléctrica | B9: ='2012-2021'!B9 -> 11498 | C9: ='2012-2021'!C9 -> 11679 | D9: ='2012-2021'!D9 -> 12429 | E9: ='2012-2021'!E9 -> 12489 | F9: ='2012-2021'!F9 -> 12589 | G9: ='2012-2021'!G9 -> 12642 | H9: ='2012-2021'!H9 -> 12641 | I9: ='2012-2021'!I9 -> 12641 | ... K9: ='2012-2021'!K9 -> 12643 | L9: ='Cap2020-2023'!D3 -> 12613 | M9: ='Cap2020-2023'!E3 -> 12612
A10: Eólica | B10: ='2012-2021'!B10 -> 1158 | C10: ='2012-2021'!C10 -> 1611 | D10: ='2012-2021'!D10 -> 2036 | E10: ='2012-2021'!E10 -> 2805 | F10: ='2012-2021'!F10 -> 3735 | G10: ='2012-2021'!G10 -> 4199 | H10: ='2012-2021'!H10 -> 4855 | I10: ='2012-2021'!I10 -> 6040 | ... K10: ='2012-2021'!K10 -> 6454 | L10: ='Cap2020-2023'!D5 -> 6921 | M10: ='Cap2020-2023'!E5 -> 7055
A11: Geotérmica | B11: ='2012-2021'!B11 -> 812 | C11: ='2012-2021'!C11 -> 823 | D11: ='2012-2021'!D11 -> 813 | E11: ='2012-2021'!E11 -> 926 | F11: ='2012-2021'!F11 -> 909 | G11: ='2012-2021'!G11 -> 926 | H11: =G11 -> 926 | I11: =J11 -> 951 | J11: ='Cap2020-2023'!B4 -> 951 | K11: ='Cap2020-2023'!C4 -> 976 | L11: ='Cap2020-2023'!D4 -> 976 | M11: ='Cap2020-2023'!E4 -> 976
A12: Solar | B12: ='2012-2021'!B12 -> 6 | C12: ='2012-2021'!C12 -> 46 | D12: ='2012-2021'!D12 -> 56 | E12: ='2012-2021'!E12 -> 56 | F12: ='2012-2021'!F12 -> 145 | G12: ='2012-2021'!G12 -> 214 | H12: ='2012-2021'!H12 -> 1946 | I12: ='2012-2021'!I12 -> 4598 | J12: ='2012-2021'!J12 -> 5630 | K12: ='Cap2020-2023'!C6 -> 5955 | L12: ='Cap2020-2023'!D6 -> 6535 | M12: ='Cap2020-2023'!E6 -> 7469
A13: Biomasa | B13: ='2012-2021'!B13 -> 492 | C13: ='2012-2021'!C13 -> 554 | D13: ='2012-2021'!D13 -> 685 | E13: ='2012-2021'!E13 -> 760 | F13: ='2012-2021'!F13 -> 889 | G13: ='2012-2021'!G13 -> 1007 | H13: ='2012-2021'!H13 -> 1082 | I13: ='2012-2021'!I13 -> 1016 | J13: ='Cap2020-2023'!B7+'Cap2020-2023'!B10*0.25 -> 954.25 | K13: ='Cap2020-2023'!C7+'Cap2020-2023'!C10*0.277 -> 1016.485 | L13: ='Cap2020-2023'!D7+'Cap2020-2023'!D10*0.277 -> 1047.316 | M13: ='Cap2020-2023'!E7+'Cap2020-2023'!E10*0.277 -> 1050.194
B14: =SUM(B3:B13) -> 56458 | C14: =SUM(C3:C13) -> 64131 | D14: =SUM(D3:D13) -> 65451 | E14: =SUM(E3:E13) -> 67915 | F14: =SUM(F3:F13) -> 73249 | G14: =SUM(G3:G13) -> 75211 | H14: =SUM(H3:H13) -> 78233 | I14: =SUM(I3:I13) -> 84216 | ... M14: =SUM(M3:M13) -> 89069.694
A16: Evolución de la generación (MWh)
B17: 2012 | C17: 2013 | D17: 2014 | E17: 2015 | F17: 2016 | G17: 2017 | H17: 2018 | I17: 2019 | J17: 2020 | K17: 2021 | L17: 2022 | M17: 2023
A18: Ciclo combinado | B18: ='2012-2021'!B23 -> 129331590 | C18: ='2012-2021'!C23 -> 139162757 | D18: ='2012-2021'!D23 -> 145335722 | E18: ='2012-2021'!E23 -> 151463563 | F18: ='2012-2021'!F23 -> 152587411 | G18: ='2012-2021'!G23 -> 154128126 | H18: ='2012-2021'!H23 -> 159082959 | I18: ='2012-2021'!I23 -> 171368943 | ... K18: ='2012-2021'!K23 -> 184444135 | L18: ='Gen2022-2023'!C6 -> 193994868 | M18: ='Gen2022-2023'!D6 -> 203605022
A19: Termoeléctrica convencional | B19: ='2012-2021'!B24 -> 59561147 | C19: ='2012-2021'!C24 -> 55036664 | D19: ='2012-2021'!D24 -> 40410894 | E19: ='2012-2021'!E24 -> 42474410 | F19: ='2012-2021'!F24 -> 42023428 | G19: ='2012-2021'!G24 -> 43947148 | H19: ='2012-2021'!H24 -> 40010763 | I19: ='2012-2021'!I24 -> 38661529 | ... K19: ='2012-2021'!K24 -> 23495780 | L19: ='Gen2022-2023'!C11 -> 21116986 | M19: ='Gen2022-2023'!D11 -> 31182145
A20: Carboeléctrica | B20: ='2012-2021'!B25 -> 35018872 | C20: ='2012-2021'!C25 -> 34641891 | D20: ='2012-2021'!D25 -> 34066857 | E20: ='2012-2021'!E25 -> 34056857 | F20: ='2012-2021'!F25 -> 34532398 | G20: ='2012-2021'!G25 -> 28663360 | H20: ='2012-2021'!H25 -> 27344983 | I20: ='2012-2021'!I25 -> 21609445 | ... K20: ='2012-2021'!K25 -> 8703941 | L20: ='Gen2022-2023'!C5 -> 14191640 | M20: ='Gen2022-2023'!D5 -> 14237878
A21: Turbogás | B21: ='2012-2021'!B26 -> 7624532 | C21: ='2012-2021'!C26 -> 7088706 | D21: ='2012-2021'!D26 -> 9249223 | E21: ='2012-2021'!E26 -> 11806728 | F21: ='2012-2021'!F26 -> 12719487 | G21: ='2012-2021'!G26 -> 14687034 | H21: ='2012-2021'!H26 -> 14392288 | I21: ='2012-2021'!I26 -> 16352558 | ... K21: ='2012-2021'!K26 -> 15875312 | L21: ='Gen2022-2023'!C12 -> 15486778 | M21: ='Gen2022-2023'!D12 -> 17849573
A22: Combustión Interna | B22: ='2012-2021'!B27 -> 2000855 | C22: ='2012-2021'!C27 -> 2152886 | D22: ='2012-2021'!D27 -> 2339164 | E22: ='2012-2021'!E27 -> 2687125 | F22: ='2012-2021'!F27 -> 3169777 | G22: ='2012-2021'!G27 -> 2333057 | H22: ='2012-2021'!H27 -> 2565641 | I22: ='2012-2021'!I27 -> 3170220 | ... K22: ='2012-2021'!K27 -> 2057546 | L22: ='Gen2022-2023'!C7 -> 1843740 | M22: ='Gen2022-2023'!D7 -> 3636195
A23: Nuclear | B23: ='2012-2021'!B28 -> 8192869 | C23: ='2012-2021'!C28 -> 11389115 | D23: ='2012-2021'!D28 -> 9807663 | E23: ='2012-2021'!E28 -> 11734761 | F23: ='2012-2021'!F28 -> 10667410 | G23: ='2012-2021'!G28 -> 10571136 | H23: ='2012-2021'!H28 -> 13198780 | I23: ='2012-2021'!I28 -> 10879189 | ... K23: ='2012-2021'!K28 -> 11604710 | L23: ='Gen2022-2023'!C10 -> 10538743 | M23: ='Gen2022-2023'!D10 -> 12043391
A24: Biomasa | B24: ='2012-2021'!B33 -> 1231312 | C24: ='2012-2021'!C33 -> 1086854 | D24: ='2012-2021'!D33 -> 1406020 | E24: ='2012-2021'!E33 -> 1388420 | F24: ='2012-2021'!F33 -> 1485058 | G24: ='2012-2021'!G33 -> 1884844 | H24: ='2012-2021'!H33 -> 1989116 | I24: ='2012-2021'!I33 -> 1861586 | ... K24: ='2012-2021'!K33 -> 1531996 | L24: ='Gen2022-2023'!C4+$K24 -> 1627355 | M24: ='Gen2022-2023'!D4+$K24 -> 1628955
A26: Consumo de combustibles (PJ)
B27: 2012 | C27: 2013 | D27: 2014 | E27: 2015 | F27: 2016 | G27: 2017 | H27: 2018 | I27: 2019 | J27: 2020 | K27: 2021 | L27: 2022 | M27: 2023
A28: Ciclo combinado | B28: ='2012-2021'!B104 -> 1009.23 | C28: ='2012-2021'!C104 -> 1108.1 | D28: ='2012-2021'!D104 -> 1131.19 | E28: ='2012-2021'!E104 -> 1275.2 | F28: ='2012-2021'!F104 -> 1416.37 | G28: ='2012-2021'!G104 -> 1383.12 | H28: ='2012-2021'!H104 -> 1488.74 | I28: ='2012-2021'!I104 -> 1445.94 | ... K28: ='2012-2021'!K104 -> 1531.81 | L28: ='BNE23'!I9*0.85 -> 1883.9485 | M28: ='BNE23'!J9*0.9 -> 2018.241
A29: Termoeléctrica convencional | B29: =SUM('2012-2021'!B106:B108) -> 641.85 | C29: =SUM('2012-2021'!C106:C108) -> 581.14 | D29: =SUM('2012-2021'!D106:D108) -> 416.81 | E29: =SUM('2012-2021'!E106:E108) -> 425.87 | F29: =SUM('2012-2021'!F106:F108) -> 475.39 | G29: =SUM('2012-2021'!G106:G108) -> 507.01 | H29: =SUM('2012-2021'!H106:H108) -> 472.16 | I29: =SUM('2012-2021'!I106:I108) -> 439.98 | ... K29: =SUM('2012-2021'!K106:K108) -> 331.56 | L29: ='BNE23'!I6+'BNE23'!I8+'BNE23'!I9*0.025 -> 322.15025 | M29: ='BNE23'!J6+'BNE23'!J8+'BNE23'!J9*0.075 -> 434.06675
A30: Carboeléctrica | B30: ='2012-2021'!B110 -> 351.49 | C30: ='2012-2021'!C110 -> 332.87 | D30: ='2012-2021'!D110 -> 353.1 | E30: ='2012-2021'!E110 -> 356.11 | F30: ='2012-2021'!F110 -> 372.85 | G30: ='2012-2021'!G110 -> 316.59 | H30: ='2012-2021'!H110 -> 315.71 | I30: ='2012-2021'!I110 -> 306.73 | ... K30: ='2012-2021'!K110 -> 99.04 | L30: ='BNE23'!I3+'BNE23'!I12 -> 145.06 | M30: ='BNE23'!J3+'BNE23'!J12 -> 169.12
A31: Turbogás | B31: =SUM('2012-2021'!B112:B114) -> 79.26 | C31: =SUM('2012-2021'!C112:C114) -> 73.64 | D31: =SUM('2012-2021'!D112:D114) -> 89.95 | E31: =SUM('2012-2021'!E112:E114) -> 106.35 | F31: =SUM('2012-2021'!F112:F114) -> 143.81 | G31: =SUM('2012-2021'!G112:G114) -> 170.28 | H31: =SUM('2012-2021'!H112:H114) -> 170.51 | I31: =SUM('2012-2021'!I112:I114) -> 179.14 | ... K31: =SUM('2012-2021'!K112:K114) -> 166.35 | L31: ='BNE23'!I11+'BNE23'!I7*0.9+'BNE23'!I9*0.05 -> 164.8205 | M31: ='BNE23'!J11+'BNE23'!J7*0.9+'BNE23'!J9*0.075 -> 203.07075
A32: Combustión Interna | B32: =SUM('2012-2021'!B116:B118) -> 24.18 | C32: =SUM('2012-2021'!C116:C118) -> 26.05 | D32: =SUM('2012-2021'!D116:D118) -> 26.53 | E32: =SUM('2012-2021'!E116:E118) -> 27.98 | F32: =SUM('2012-2021'!F116:F118) -> 41.47 | G32: =SUM('2012-2021'!G116:G118) -> 31.36 | H32: =SUM('2012-2021'!H116:H118) -> 35.24 | I32: =SUM('2012-2021'!I116:I118) -> 40.4 | ... K32: =SUM('2012-2021'!K116:K118) -> 28.79 | L32: ='BNE23'!I5+'BNE23'!I7*0.1+'BNE23'!I9*0.01 -> 30.5641 | M32: ='BNE23'!J5+'BNE23'!J7*0.1+'BNE23'!J9*0.02 -> 50.8758
A33: Nuclear | B33: ='2012-2021'!B120 -> 91.32 | C33: ='2012-2021'!C120 -> 122.6 | D33: ='2012-2021'!D120 -> 100.6 | E33: ='2012-2021'!E120 -> 120.41 | F33: ='2012-2021'!F120 -> 109.95 | G33: ='2012-2021'!G120 -> 113.22 | H33: ='2012-2021'!H120 -> 156 | I33: ='2012-2021'!I120 -> 124.82 | ... K33: ='2012-2021'!K120 -> 124.99 | L33: ='BNE23'!I4 -> 152.77 | M33: ='BNE23'!J4 -> 175.7
A34: Biomasa | B34: ='2012-2021'!B122 -> 52.97 | C34: ='2012-2021'!C122 -> 58.57 | D34: ='2012-2021'!D122 -> 68.15 | E34: ='2012-2021'!E122 -> 68.41 | F34: ='2012-2021'!F122 -> 70.41 | G34: ='2012-2021'!G122 -> 65.46 | H34: ='2012-2021'!H122 -> 64.61 | I34: ='2012-2021'!I122 -> 75.57 | ... K34: ='2012-2021'!K122 -> 55.56 | L34: ='BNE23'!I10 -> 48.13 | M34: ='BNE23'!J10 -> 46.37
A36: Regimen térmico, incluye usos propios (GJ/MWh)
B37: 2012 | C37: 2013 | D37: 2014 | E37: 2015 | F37: 2016 | G37: 2017 | H37: 2018 | I37: 2019 | J37: 2020 | K37: 2021 | L37: 2022 | M37: 2023
A38: Ciclo combinado | B38: =B28/B18*1000000 -> 7.8034299 | C38: =C28/C18*1000000 -> 7.9626189 | D38: =D28/D18*1000000 -> 7.7832895 | E38: =E28/E18*1000000 -> 8.4191866 | F38: =F28/F18*1000000 -> 9.2823516 | G38: =G28/G18*1000000 -> 8.9738326 | H38: =H28/H18*1000000 -> 9.3582619 | I38: =I28/I18*1000000 -> 8.4375849 | ... M38: =M28/M18*1000000 -> 9.9125305
A39: Termoeléctrica convencional | B39: =B29/B19*1000000 -> 10.77632 | C39: =C29/C19*1000000 -> 10.559143 | D39: =D29/D19*1000000 -> 10.314298 | E39: =E29/E19*1000000 -> 10.026508 | F39: =F29/F19*1000000 -> 11.312499 | G39: =G29/G19*1000000 -> 11.536812 | H39: =H29/H19*1000000 -> 11.800825 | I39: =I29/I19*1000000 -> 11.380305 | ... M39: =M29/M19*1000000 -> 13.920362
A40: Carboeléctrica | B40: =B30/B20*1000000 -> 10.037159 | C40: =C30/C20*1000000 -> 9.6088865 | D40: =D30/D20*1000000 -> 10.364913 | E40: =E30/E20*1000000 -> 10.456338 | F40: =F30/F20*1000000 -> 10.797107 | G40: =G30/G20*1000000 -> 11.045111 | H40: =H30/H20*1000000 -> 11.545445 | I40: =I30/I20*1000000 -> 14.194256 | ... M40: =M30/M20*1000000 -> 11.878175
A41: Turbogás | B41: =B31/B21*1000000 -> 10.395392 | C41: =C31/C21*1000000 -> 10.388356 | D41: =D31/D21*1000000 -> 9.7251412 | E41: =E31/E21*1000000 -> 9.007576 | F41: =F31/F21*1000000 -> 11.306274 | G41: =G31/G21*1000000 -> 11.5939 | H41: =H31/H21*1000000 -> 11.847317 | I41: =I31/I21*1000000 -> 10.954861 | ... M41: =M31/M21*1000000 -> 11.376785
A42: Combustión Interna | B42: =B32/B22*1000000 -> 12.084834 | C42: =C32/C22*1000000 -> 12.100037 | D42: =D32/D22*1000000 -> 11.341659 | E42: =E32/E22*1000000 -> 10.412616 | F42: =F32/F22*1000000 -> 13.082939 | G42: =G32/G22*1000000 -> 13.441592 | H42: =H32/H22*1000000 -> 13.735359 | I42: =I32/I22*1000000 -> 12.743595 | ... M42: =M32/M22*1000000 -> 13.991494
A43: Nuclear | B43: =B33/B23*1000000 -> 11.146279 | C43: =C33/C23*1000000 -> 10.764664 | D43: =D33/D23*1000000 -> 10.257286 | E43: =E33/E23*1000000 -> 10.260967 | F43: =F33/F23*1000000 -> 10.307094 | G43: =G33/G23*1000000 -> 10.710296 | H43: =H33/H23*1000000 -> 11.819274 | I43: =I33/I23*1000000 -> 11.473282 | ... M43: =M33/M23*1000000 -> 14.588914
...

Sheet BHRaSYC-HeatRates
A1: Heat Rates (BTU/(MW*hour)) | B1: Vintage1891 | C1: Vintage1892 | D1: Vintage1893 | E1: Vintage1894 | F1: Vintage1895 | G1: Vintage1896 | H1: Vintage1897 | I1: Vintage1898 | J1: Vintage1899 | K1: Vintage1900 | L1: Vintage1901 | M1: Vintage1902 | N1: Vintage1903 | O1: Vintage1904 | P1: Vintage1905 | Q1: Vintage1906 | R1: Vintage1907 | S1: Vintage1908 | T1: Vintage1909 | U1: Vintage1910 | V1: Vintage1911 | W1: Vintage1912 | X1: Vintage1913 | Y1: Vintage1914 | Z1: Vintage1915 | AA1: Vintage1916 | AB1: Vintage1917 | AC1: Vintage1918 | AD1: Vintage1919 | AE1: Vintage1920 | AF1: Vintage1921 | AG1: Vintage1922 | AH1: Vintage1923 | AI1: Vintage1924 | AJ1: Vintage1925 | AK1: Vintage1926 | AL1: Vintage1927 | AM1: Vintage1928 | AN1: Vintage1929 | AO1: Vintage1930 | AP1: Vintage1931 | AQ1: Vintage1932 | AR1: Vintage1933 | AS1: Vintage1934 | AT1: Vintage1935 | AU1: Vintage1936 | AV1: Vintage1937 | AW1: Vintage1938 | AX1: Vintage1939 | AY1: Vintage1940 | AZ1: Vintage1941 | BA1: Vintage1942 | BB1: Vintage1943 | BC1: Vintage1944 | BD1: Vintage1945 | BE1: Vintage1946 | BF1: Vintage1947 | BG1: Vintage1948 | BH1: Vintage1949 | BI1: Vintage1950 | BJ1: Vintage1951 | BK1: Vintage1952 | BL1: Vintage1953 | BM1: Vintage1954 | BN1: Vintage1955 | BO1: Vintage1956 | BP1: Vintage1957 | BQ1: Vintage1958 | BR1: Vintage1959 | BS1: Vintage1960 | BT1: Vintage1961 | BU1: Vintage1962 | BV1: Vintage1963 | BW1: Vintage1964 | BX1: Vintage1965 | BY1: Vintage1966 | BZ1: Vintage1967 | CA1: Vintage1968 | CB1: Vintage1969 | CC1: Vintage1970 | CD1: Vintage1971 | CE1: Vintage1972 | CF1: Vintage1973 | CG1: Vintage1974 | CH1: Vintage1975 | CI1: Vintage1976 | CJ1: Vintage1977 | CK1: Vintage1978 | CL1: Vintage1979 | CM1: Vintage1980 | CN1: Vintage1981 | CO1: Vintage1982 | CP1: Vintage1983 | CQ1: Vintage1984 | CR1: Vintage1985 | CS1: Vintage1986 | CT1: Vintage1987 | CU1: Vintage1988 | CV1: Vintage1989 | CW1: Vintage1990 | CX1: Vintage1991 | CY1: Vintage1992 | CZ1: Vintage1993 | DA1: Vintage1994 | DB1: Vintage1995 | DC1: Vintage1996 | DD1: Vintage1997 | DE1: Vintage1998 | DF1: Vintage1999 | DG1: Vintage2000 | DH1: Vintage2001 | DI1: Vintage2002 | DJ1: Vintage2003 | DK1: Vintage2004 | DL1: Vintage2005 | DM1: Vintage2006 | DN1: Vintage2007 | DO1: Vintage2008 | DP1: Vintage2009 | DQ1: Vintage2010 | DR1: Vintage2011 | DS1: Vintage2012 | DT1: Vintage2013 | DU1: Vintage2014 | DV1: Vintage2015 | DW1: Vintage2016 | DX1: Vintage2017 | DY1: Vintage2018 | DZ1: Vintage2019 | EA1: Vintage2020 | EB1: Vintage2021 | EC1: Vintage2022 | ED1: Vintage2023 | EE1: Vintage2024 | EF1: Vintage2025 | EG1: Vintage2026 | EH1: Vintage2027 | EI1: Vintage2028 | EJ1: Vintage2029 | EK1: Vintage2030 | EL1: Vintage2031 | EM1: Vintage2032 | EN1: Vintage2033 | EO1: Vintage2034 | EP1: Vintage2035 | EQ1: Vintage2036 | ER1: Vintage2037 | ES1: Vintage2038 | ET1: Vintage2039 | EU1: Vintage2040 | EV1: Vintage2041 | EW1: Vintage2042 | EX1: Vintage2043 | EY1: Vintage2044 | EZ1: Vintage2045 | FA1: Vintage2046 | FB1: Vintage2047 | FC1: Vintage2048 | FD1: Vintage2049 | FE1: Vintage2050 | FF1: Vintage2051 | FG1: Vintage2052 | FH1: Vintage2053 | FI1: Vintage2054 | FJ1: Vintage2055 | FK1: Vintage2056 | FL1: Vintage2057 | FM1: Vintage2058 | FN1: Vintage2059 | FO1: Vintage2060 | FP1: Vintage2061 | FQ1: Vintage2062 | FR1: Vintage2063 | FS1: Vintage2064 | FT1: Vintage2065 | FU1: Vintage2066 | FV1: Vintage2067 | FW1: Vintage2068 | FX1: Vintage2069 | FY1: Vintage2070 | FZ1: Vintage2071 | GA1: Vintage2072 | GB1: Vintage2073 | GC1: Vintage2074 | GD1: Vintage2075 | GE1: Vintage2076 | GF1: Vintage2077 | GG1: Vintage2078 | GH1: Vintage2079 | GI1: Vintage2080 | GJ1: Vintage2081 | GK1: Vintage2082 | GL1: Vintage2083 | GM1: Vintage2084 | GN1: Vintage2085 | GO1: Vintage2086 | GP1: Vintage2087 | GQ1: Vintage2088 | GR1: Vintage2089 | GS1: Vintage2090 | GT1: Vintage2091 | GU1: Vintage2092 | GV1: Vintage2093 | GW1: Vintage2094 | GX1: Vintage2095 | GY1: Vintage2096 | GZ1: Vintage2097 | HA1: Vintage2098 | HB1: Vintage2099 | HC1: Vintage2100
A2: hard coal | B2: 0 | C2: 0 | D2: 0 | E2: 0 | F2: 0 | G2: 0 | H2: 0 | I2: 0 | J2: 0 | K2: 0 | L2: 0 | M2: 0 | N2: 0 | O2: 0 | P2: 0 | Q2: 0 | R2: 0 | S2: 0 | T2: 0 | U2: 0 | V2: 0 | W2: 0 | X2: 0 | Y2: 0 | Z2: 0 | AA2: 0 | AB2: 0 | AC2: 0 | AD2: 0 | AE2: 0 | AF2: 0 | AG2: 0 | AH2: 0 | AI2: 0 | AJ2: 0 | AK2: 0 | AL2: 0 | AM2: 0 | AN2: 0 | AO2: 0 | AP2: 0 | AQ2: 0 | AR2: 0 | AS2: 0 | AT2: 0 | AU2: 0 | AV2: 0 | AW2: 0 | AX2: 0 | AY2: 0 | AZ2: 0 | BA2: 0 | BB2: 0 | BC2: 0 | BD2: 0 | BE2: 0 | BF2: 0 | BG2: 0 | BH2: 0 | BI2: 0 | BJ2: 0 | BK2: 0 | BL2: 0 | BM2: 0 | BN2: 0 | BO2: 0 | BP2: 0 | BQ2: 0 | BR2: 0 | BS2: =$DS2 -> 9513893.5 | BT2: =$DS2 -> 9513893.5 | BU2: =$DS2 -> 9513893.5 | BV2: =$DS2 -> 9513893.5 | BW2: =$DS2 -> 9513893.5 | BX2: =$DS2 -> 9513893.5 | BY2: =$DS2 -> 9513893.5 | BZ2: =$DS2 -> 9513893.5 | ... DR2: =$DS2 -> 9513893.5 | DS2: =IF(Calculations!B129="",0,Calculations!B129) -> 9513893.5 | DT2: =IF(Calculations!C129="",0,Calculations!C129) -> 9107947.8 | DU2: =IF(Calculations!D129="",0,Calculations!D129) -> 9824560.2 | DV2: =IF(Calculations!E129="",0,Calculations!E129) -> 9911219 | DW2: =IF(Calculations!F129="",0,Calculations!F129) -> 10234223 | DX2: =IF(Calculations!G129="",0,Calculations!G129) -> 10469298 | DY2: =IF(Calculations!H129="",0,Calculations!H129) -> 10943548 | DZ2: =IF(Calculations!I129="",0,Calculations!I129) -> 13454269 | ... ED2: =IF(Calculations!M129="",0,Calculations!M129) -> 11258931 | EE2: =ED2 -> 11258931 | EF2: =EE2 -> 11258931 | EG2: =EF2 -> 11258931 | EH2: =EG2 -> 11258931 | EI2: =EH2 -> 11258931 | EJ2: =EI2 -> 11258931 | EK2: =EJ2 -> 11258931 | EL2: =EK2 -> 11258931 | ... HC2: =HB2 -> 11258931
A3: natural gas steam turbine | B3: 0 | C3: 0 | D3: 0 | E3: 0 | F3: 0 | G3: 0 | H3: 0 | I3: 0 | J3: 0 | K3: 0 | L3: 0 | M3: 0 | N3: 0 | O3: 0 | P3: 0 | Q3: 0 | R3: 0 | S3: 0 | T3: 0 | U3: 0 | V3: 0 | W3: 0 | X3: 0 | Y3: 0 | Z3: 0 | AA3: 0 | AB3: 0 | AC3: 0 | AD3: 0 | AE3: 0 | AF3: 0 | AG3: 0 | AH3: 0 | AI3: 0 | AJ3: 0 | AK3: 0 | AL3: 0 | AM3: 0 | AN3: 0 | AO3: 0 | AP3: 0 | AQ3: 0 | AR3: 0 | AS3: 0 | AT3: 0 | AU3: 0 | AV3: 0 | AW3: 0 | AX3: 0 | AY3: 0 | AZ3: 0 | BA3: 0 | BB3: 0 | BC3: 0 | BD3: 0 | BE3: 0 | BF3: 0 | BG3: 0 | BH3: 0 | BI3: 0 | BJ3: 0 | BK3: 0 | BL3: 0 | BM3: 0 | BN3: 0 | BO3: 0 | BP3: 0 | BQ3: 0 | BR3: 0 | BS3: =$DS3 -> 11454817 | BT3: =$DS3 -> 11454817 | BU3: =$DS3 -> 11454817 | BV3: =$DS3 -> 11454817 | BW3: =$DS3 -> 11454817 | BX3: =$DS3 -> 11454817 | BY3: =$DS3 -> 11454817 | BZ3: =$DS3 -> 11454817 | ... DR3: =$DS3 -> 11454817 | DS3: =IF(Calculations!B130="",0,Calculations!B130) -> 11454817 | DT3: =IF(Calculations!C130="",0,Calculations!C130) -> 11469227 | DU3: =IF(Calculations!D130="",0,Calculations!D130) -> 10750386 | DV3: =IF(Calculations!E130="",0,Calculations!E130) -> 9869776.3 | DW3: =IF(Calculations!F130="",0,Calculations!F130) -> 12400888 | DX3: =IF(Calculations!G130="",0,Calculations!G130) -> 12740843 | DY3: =IF(Calculations!H130="",0,Calculations!H130) -> 13019295 | DZ3: =IF(Calculations!I130="",0,Calculations!I130) -> 12079235 | ... ED3: =IF(Calculations!M130="",0,Calculations!M130) -> 13262077 | EE3: =ED3 -> 13262077 | EF3: =EE3 -> 13262077 | EG3: =EF3 -> 13262077 | EH3: =EG3 -> 13262077 | EI3: =EH3 -> 13262077 | EJ3: =EI3 -> 13262077 | EK3: =EJ3 -> 13262077 | EL3: =EK3 -> 13262077 | ... HC3: =HB3 -> 13262077
A4: natural gas combined cycle | B4: 0 | C4: 0 | D4: 0 | E4: 0 | F4: 0 | G4: 0 | H4: 0 | I4: 0 | J4: 0 | K4: 0 | L4: 0 | M4: 0 | N4: 0 | O4: 0 | P4: 0 | Q4: 0 | R4: 0 | S4: 0 | T4: 0 | U4: 0 | V4: 0 | W4: 0 | X4: 0 | Y4: 0 | Z4: 0 | AA4: 0 | AB4: 0 | AC4: 0 | AD4: 0 | AE4: 0 | AF4: 0 | AG4: 0 | AH4: 0 | AI4: 0 | AJ4: 0 | AK4: 0 | AL4: 0 | AM4: 0 | AN4: 0 | AO4: 0 | AP4: 0 | AQ4: 0 | AR4: 0 | AS4: 0 | AT4: 0 | AU4: 0 | AV4: 0 | AW4: 0 | AX4: 0 | AY4: 0 | AZ4: 0 | BA4: 0 | BB4: 0 | BC4: 0 | BD4: 0 | BE4: 0 | BF4: 0 | BG4: 0 | BH4: 0 | BI4: 0 | BJ4: 0 | BK4: 0 | BL4: 0 | BM4: 0 | BN4: 0 | BO4: 0 | BP4: 0 | BQ4: 0 | BR4: 0 | BS4: =$DS4 -> 7396614.8 | BT4: =$DS4 -> 7396614.8 | BU4: =$DS4 -> 7396614.8 | BV4: =$DS4 -> 7396614.8 | BW4: =$DS4 -> 7396614.8 | BX4: =$DS4 -> 7396614.8 | BY4: =$DS4 -> 7396614.8 | BZ4: =$DS4 -> 7396614.8 | ... DR4: =$DS4 -> 7396614.8 | DS4: =IF(Calculations!B131="",0,Calculations!B131) -> 7396614.8 | DT4: =IF(Calculations!C131="",0,Calculations!C131) -> 7547504.8 | DU4: =IF(Calculations!D131="",0,Calculations!D131) -> 7377524.3 | DV4: =IF(Calculations!E131="",0,Calculations!E131) -> 7980270.3 | DW4: =IF(Calculations!F131="",0,Calculations!F131) -> 8798436.1 | DX4: =IF(Calculations!G131="",0,Calculations!G131) -> 8506001 | DY4: =IF(Calculations!H131="",0,Calculations!H131) -> 8870389 | DZ4: =IF(Calculations!I131="",0,Calculations!I131) -> 7997709.4 | ... ED4: =IF(Calculations!M131="",0,Calculations!M131) -> 9395762 | EE4: =ED4 -> 9395762 | EF4: =EE4 -> 9395762 | EG4: =EF4 -> 9395762 | EH4: =EG4 -> 9395762 | EI4: =EH4 -> 9395762 | EJ4: =EI4 -> 9395762 | EK4: =EJ4 -> 9395762 | EL4: =EK4 -> 9395762 | ... HC4: =HB4 -> 9395762
A5: nuclear | B5: 0 | C5: 0 | D5: 0 | E5: 0 | F5: 0 | G5: 0 | H5: 0 | I5: 0 | J5: 0 | K5: 0 | L5: 0 | M5: 0 | N5: 0 | O5: 0 | P5: 0 | Q5: 0 | R5: 0 | S5: 0 | T5: 0 | U5: 0 | V5: 0 | W5: 0 | X5: 0 | Y5: 0 | Z5: 0 | AA5: 0 | AB5: 0 | AC5: 0 | AD5: 0 | AE5: 0 | AF5: 0 | AG5: 0 | AH5: 0 | AI5: 0 | AJ5: 0 | AK5: 0 | AL5: 0 | AM5: 0 | AN5: 0 | AO5: 0 | AP5: 0 | AQ5: 0 | AR5: 0 | AS5: 0 | AT5: 0 | AU5: 0 | AV5: 0 | AW5: 0 | AX5: 0 | AY5: 0 | AZ5: 0 | BA5: 0 | BB5: 0 | BC5: 0 | BD5: 0 | BE5: 0 | BF5: 0 | BG5: 0 | BH5: 0 | BI5: 0 | BJ5: 0 | BK5: 0 | BL5: 0 | BM5: 0 | BN5: 0 | BO5: 0 | BP5: 0 | BQ5: 0 | BR5: 0 | BS5: =$DS5 -> 10565191 | BT5: =$DS5 -> 10565191 | BU5: =$DS5 -> 10565191 | BV5: =$DS5 -> 10565191 | BW5: =$DS5 -> 10565191 | BX5: =$DS5 -> 10565191 | BY5: =$DS5 -> 10565191 | BZ5: =$DS5 -> 10565191 | ... DR5: =$DS5 -> 10565191 | DS5: =IF(Calculations!B132="",0,Calculations!B132) -> 10565191 | DT5: =IF(Calculations!C132="",0,Calculations!C132) -> 10203472 | DU5: =IF(Calculations!D132="",0,Calculations!D132) -> 9722543.9 | DV5: =IF(Calculations!E132="",0,Calculations!E132) -> 9726033.8 | DW5: =IF(Calculations!F132="",0,Calculations!F132) -> 9769755.9 | DX5: =IF(Calculations!G132="",0,Calculations!G132) -> 10151938 | DY5: =IF(Calculations!H132="",0,Calculations!H132) -> 11203102 | DZ5: =IF(Calculations!I132="",0,Calculations!I132) -> 10875147 | ... ED5: =IF(Calculations!M132="",0,Calculations!M132) -> 13828353 | EE5: =ED5 -> 13828353 | EF5: =EE5 -> 13828353 | EG5: =EF5 -> 13828353 | EH5: =EG5 -> 13828353 | EI5: =EH5 -> 13828353 | EJ5: =EI5 -> 13828353 | EK5: =EJ5 -> 13828353 | EL5: =EK5 -> 13828353 | ... HC5: =HB5 -> 13828353
A6: hydro | B6: 0 | C6: 0 | D6: 0 | E6: 0 | F6: 0 | G6: 0 | H6: 0 | I6: 0 | J6: 0 | K6: 0 | L6: 0 | M6: 0 | N6: 0 | O6: 0 | P6: 0 | Q6: 0 | R6: 0 | S6: 0 | T6: 0 | U6: 0 | V6: 0 | W6: 0 | X6: 0 | Y6: 0 | Z6: 0 | AA6: 0 | AB6: 0 | AC6: 0 | AD6: 0 | AE6: 0 | AF6: 0 | AG6: 0 | AH6: 0 | AI6: 0 | AJ6: 0 | AK6: 0 | AL6: 0 | AM6: 0 | AN6: 0 | AO6: 0 | AP6: 0 | AQ6: 0 | AR6: 0 | AS6: 0 | AT6: 0 | AU6: 0 | AV6: 0 | AW6: 0 | AX6: 0 | AY6: 0 | AZ6: 0 | BA6: 0 | BB6: 0 | BC6: 0 | BD6: 0 | BE6: 0 | BF6: 0 | BG6: 0 | BH6: 0 | BI6: 0 | BJ6: 0 | BK6: 0 | BL6: 0 | BM6: 0 | BN6: 0 | BO6: 0 | BP6: 0 | BQ6: 0 | BR6: 0 | BS6: =$DS6 -> 0 | BT6: =$DS6 -> 0 | BU6: =$DS6 -> 0 | BV6: =$DS6 -> 0 | BW6: =$DS6 -> 0 | BX6: =$DS6 -> 0 | BY6: =$DS6 -> 0 | BZ6: =$DS6 -> 0 | ... DR6: =$DS6 -> 0 | DS6: =IF(Calculations!B133="",0,Calculations!B133) -> 0 | DT6: =IF(Calculations!C133="",0,Calculations!C133) -> 0 | DU6: =IF(Calculations!D133="",0,Calculations!D133) -> 0 | DV6: =IF(Calculations!E133="",0,Calculations!E133) -> 0 | DW6: =IF(Calculations!F133="",0,Calculations!F133) -> 0 | DX6: =IF(Calculations!G133="",0,Calculations!G133) -> 0 | DY6: =IF(Calculations!H133="",0,Calculations!H133) -> 0 | DZ6: =IF(Calculations!I133="",0,Calculations!I133) -> 0 | ... ED6: =IF(Calculations!M133="",0,Calculations!M133) -> 0 | EE6: =ED6 -> 0 | EF6: =EE6 -> 0 | EG6: =EF6 -> 0 | EH6: =EG6 -> 0 | EI6: =EH6 -> 0 | EJ6: =EI6 -> 0 | EK6: =EJ6 -> 0 | EL6: =EK6 -> 0 | ... HC6: =HB6 -> 0
A7: onshore wind | B7: 0 | C7: 0 | D7: 0 | E7: 0 | F7: 0 | G7: 0 | H7: 0 | I7: 0 | J7: 0 | K7: 0 | L7: 0 | M7: 0 | N7: 0 | O7: 0 | P7: 0 | Q7: 0 | R7: 0 | S7: 0 | T7: 0 | U7: 0 | V7: 0 | W7: 0 | X7: 0 | Y7: 0 | Z7: 0 | AA7: 0 | AB7: 0 | AC7: 0 | AD7: 0 | AE7: 0 | AF7: 0 | AG7: 0 | AH7: 0 | AI7: 0 | AJ7: 0 | AK7: 0 | AL7: 0 | AM7: 0 | AN7: 0 | AO7: 0 | AP7: 0 | AQ7: 0 | AR7: 0 | AS7: 0 | AT7: 0 | AU7: 0 | AV7: 0 | AW7: 0 | AX7: 0 | AY7: 0 | AZ7: 0 | BA7: 0 | BB7: 0 | BC7: 0 | BD7: 0 | BE7: 0 | BF7: 0 | BG7: 0 | BH7: 0 | BI7: 0 | BJ7: 0 | BK7: 0 | BL7: 0 | BM7: 0 | BN7: 0 | BO7: 0 | BP7: 0 | BQ7: 0 | BR7: 0 | BS7: =$DS7 -> 0 | BT7: =$DS7 -> 0 | BU7: =$DS7 -> 0 | BV7: =$DS7 -> 0 | BW7: =$DS7 -> 0 | BX7: =$DS7 -> 0 | BY7: =$DS7 -> 0 | BZ7: =$DS7 -> 0 | ... DR7: =$DS7 -> 0 | DS7: =IF(Calculations!B134="",0,Calculations!B134) -> 0 | DT7: =IF(Calculations!C134="",0,Calculations!C134) -> 0 | DU7: =IF(Calculations!D134="",0,Calculations!D134) -> 0 | DV7: =IF(Calculations!E134="",0,Calculations!E134) -> 0 | DW7: =IF(Calculations!F134="",0,Calculations!F134) -> 0 | DX7: =IF(Calculations!G134="",0,Calculations!G134) -> 0 | DY7: =IF(Calculations!H134="",0,Calculations!H134) -> 0 | DZ7: =IF(Calculations!I134="",0,Calculations!I134) -> 0 | ... ED7: =IF(Calculations!M134="",0,Calculations!M134) -> 0 | EE7: =ED7 -> 0 | EF7: =EE7 -> 0 | EG7: =EF7 -> 0 | EH7: =EG7 -> 0 | EI7: =EH7 -> 0 | EJ7: =EI7 -> 0 | EK7: =EJ7 -> 0 | EL7: =EK7 -> 0 | ... HC7: =HB7 -> 0
A8: solar PV | B8: 0 | C8: 0 | D8: 0 | E8: 0 | F8: 0 | G8: 0 | H8: 0 | I8: 0 | J8: 0 | K8: 0 | L8: 0 | M8: 0 | N8: 0 | O8: 0 | P8: 0 | Q8: 0 | R8: 0 | S8: 0 | T8: 0 | U8: 0 | V8: 0 | W8: 0 | X8: 0 | Y8: 0 | Z8: 0 | AA8: 0 | AB8: 0 | AC8: 0 | AD8: 0 | AE8: 0 | AF8: 0 | AG8: 0 | AH8: 0 | AI8: 0 | AJ8: 0 | AK8: 0 | AL8: 0 | AM8: 0 | AN8: 0 | AO8: 0 | AP8: 0 | AQ8: 0 | AR8: 0 | AS8: 0 | AT8: 0 | AU8: 0 | AV8: 0 | AW8: 0 | AX8: 0 | AY8: 0 | AZ8: 0 | BA8: 0 | BB8: 0 | BC8: 0 | BD8: 0 | BE8: 0 | BF8: 0 | BG8: 0 | BH8: 0 | BI8: 0 | BJ8: 0 | BK8: 0 | BL8: 0 | BM8: 0 | BN8: 0 | BO8: 0 | BP8: 0 | BQ8: 0 | BR8: 0 | BS8: =$DS8 -> 0 | BT8: =$DS8 -> 0 | BU8: =$DS8 -> 0 | BV8: =$DS8 -> 0 | BW8: =$DS8 -> 0 | BX8: =$DS8 -> 0 | BY8: =$DS8 -> 0 | BZ8: =$DS8 -> 0 | ... DR8: =$DS8 -> 0 | DS8: =IF(Calculations!B135="",0,Calculations!B135) -> 0 | DT8: =IF(Calculations!C135="",0,Calculations!C135) -> 0 | DU8: =IF(Calculations!D135="",0,Calculations!D135) -> 0 | DV8: =IF(Calculations!E135="",0,Calculations!E135) -> 0 | DW8: =IF(Calculations!F135="",0,Calculations!F135) -> 0 | DX8: =IF(Calculations!G135="",0,Calculations!G135) -> 0 | DY8: =IF(Calculations!H135="",0,Calculations!H135) -> 0 | DZ8: =IF(Calculations!I135="",0,Calculations!I135) -> 0 | ... ED8: =IF(Calculations!M135="",0,Calculations!M135) -> 0 | EE8: =ED8 -> 0 | EF8: =EE8 -> 0 | EG8: =EF8 -> 0 | EH8: =EG8 -> 0 | EI8: =EH8 -> 0 | EJ8: =EI8 -> 0 | EK8: =EJ8 -> 0 | EL8: =EK8 -> 0 | ... HC8: =HB8 -> 0
A9: solar thermal | B9: 0 | C9: 0 | D9: 0 | E9: 0 | F9: 0 | G9: 0 | H9: 0 | I9: 0 | J9: 0 | K9: 0 | L9: 0 | M9: 0 | N9: 0 | O9: 0 | P9: 0 | Q9: 0 | R9: 0 | S9: 0 | T9: 0 | U9: 0 | V9: 0 | W9: 0 | X9: 0 | Y9: 0 | Z9: 0 | AA9: 0 | AB9: 0 | AC9: 0 | AD9: 0 | AE9: 0 | AF9: 0 | AG9: 0 | AH9: 0 | AI9: 0 | AJ9: 0 | AK9: 0 | AL9: 0 | AM9: 0 | AN9: 0 | AO9: 0 | AP9: 0 | AQ9: 0 | AR9: 0 | AS9: 0 | AT9: 0 | AU9: 0 | AV9: 0 | AW9: 0 | AX9: 0 | AY9: 0 | AZ9: 0 | BA9: 0 | BB9: 0 | BC9: 0 | BD9: 0 | BE9: 0 | BF9: 0 | BG9: 0 | BH9: 0 | BI9: 0 | BJ9: 0 | BK9: 0 | BL9: 0 | BM9: 0 | BN9: 0 | BO9: 0 | BP9: 0 | BQ9: 0 | BR9: 0 | BS9: =$DS9 -> 0 | BT9: =$DS9 -> 0 | BU9: =$DS9 -> 0 | BV9: =$DS9 -> 0 | BW9: =$DS9 -> 0 | BX9: =$DS9 -> 0 | BY9: =$DS9 -> 0 | BZ9: =$DS9 -> 0 | ... DR9: =$DS9 -> 0 | DS9: =IF(Calculations!B136="",0,Calculations!B136) -> 0 | DT9: =IF(Calculations!C136="",0,Calculations!C136) -> 0 | DU9: =IF(Calculations!D136="",0,Calculations!D136) -> 0 | DV9: =IF(Calculations!E136="",0,Calculations!E136) -> 0 | DW9: =IF(Calculations!F136="",0,Calculations!F136) -> 0 | DX9: =IF(Calculations!G136="",0,Calculations!G136) -> 0 | DY9: =IF(Calculations!H136="",0,Calculations!H136) -> 0 | DZ9: =IF(Calculations!I136="",0,Calculations!I136) -> 0 | ... ED9: =IF(Calculations!M136="",0,Calculations!M136) -> 0 | EE9: =ED9 -> 0 | EF9: =EE9 -> 0 | EG9: =EF9 -> 0 | EH9: =EG9 -> 0 | EI9: =EH9 -> 0 | EJ9: =EI9 -> 0 | EK9: =EJ9 -> 0 | EL9: =EK9 -> 0 | ... HC9: =HB9 -> 0
A10: biomass | B10: 0 | C10: 0 | D10: 0 | E10: 0 | F10: 0 | G10: 0 | H10: 0 | I10: 0 | J10: 0 | K10: 0 | L10: 0 | M10: 0 | N10: 0 | O10: 0 | P10: 0 | Q10: 0 | R10: 0 | S10: 0 | T10: 0 | U10: 0 | V10: 0 | W10: 0 | X10: 0 | Y10: 0 | Z10: 0 | AA10: 0 | AB10: 0 | AC10: 0 | AD10: 0 | AE10: 0 | AF10: 0 | AG10: 0 | AH10: 0 | AI10: 0 | AJ10: 0 | AK10: 0 | AL10: 0 | AM10: 0 | AN10: 0 | AO10: 0 | AP10: 0 | AQ10: 0 | AR10: 0 | AS10: 0 | AT10: 0 | AU10: 0 | AV10: 0 | AW10: 0 | AX10: 0 | AY10: 0 | AZ10: 0 | BA10: 0 | BB10: 0 | BC10: 0 | BD10: 0 | BE10: 0 | BF10: 0 | BG10: 0 | BH10: 0 | BI10: 0 | BJ10: 0 | BK10: 0 | BL10: 0 | BM10: 0 | BN10: 0 | BO10: 0 | BP10: 0 | BQ10: 0 | BR10: 0 | BS10: =$DS10 -> 40776442 | BT10: =$DS10 -> 40776442 | BU10: =$DS10 -> 40776442 | BV10: =$DS10 -> 40776442 | BW10: =$DS10 -> 40776442 | BX10: =$DS10 -> 40776442 | BY10: =$DS10 -> 40776442 | BZ10: =$DS10 -> 40776442 | ... DR10: =$DS10 -> 40776442 | DS10: =IF(Calculations!B137="",0,Calculations!B137) -> 40776442 | DT10: =IF(Calculations!C137="",0,Calculations!C137) -> 51080070 | DU10: =IF(Calculations!D137="",0,Calculations!D137) -> 45943262 | DV10: =IF(Calculations!E137="",0,Calculations!E137) -> 46703152 | DW10: =IF(Calculations!F137="",0,Calculations!F137) -> 44940551 | DX10: =IF(Calculations!G137="",0,Calculations!G137) -> 32919108 | DY10: =IF(Calculations!H137="",0,Calculations!H137) -> 30788398 | DZ10: =IF(Calculations!I137="",0,Calculations!I137) -> 38478115 | ... ED10: =IF(Calculations!M137="",0,Calculations!M137) -> 26982083 | EE10: =ED10 -> 26982083 | EF10: =EE10 -> 26982083 | EG10: =EF10 -> 26982083 | EH10: =EG10 -> 26982083 | EI10: =EH10 -> 26982083 | EJ10: =EI10 -> 26982083 | EK10: =EJ10 -> 26982083 | EL10: =EK10 -> 26982083 | ... HC10: =HB10 -> 26982083
A11: geothermal | B11: 0 | C11: 0 | D11: 0 | E11: 0 | F11: 0 | G11: 0 | H11: 0 | I11: 0 | J11: 0 | K11: 0 | L11: 0 | M11: 0 | N11: 0 | O11: 0 | P11: 0 | Q11: 0 | R11: 0 | S11: 0 | T11: 0 | U11: 0 | V11: 0 | W11: 0 | X11: 0 | Y11: 0 | Z11: 0 | AA11: 0 | AB11: 0 | AC11: 0 | AD11: 0 | AE11: 0 | AF11: 0 | AG11: 0 | AH11: 0 | AI11: 0 | AJ11: 0 | AK11: 0 | AL11: 0 | AM11: 0 | AN11: 0 | AO11: 0 | AP11: 0 | AQ11: 0 | AR11: 0 | AS11: 0 | AT11: 0 | AU11: 0 | AV11: 0 | AW11: 0 | AX11: 0 | AY11: 0 | AZ11: 0 | BA11: 0 | BB11: 0 | BC11: 0 | BD11: 0 | BE11: 0 | BF11: 0 | BG11: 0 | BH11: 0 | BI11: 0 | BJ11: 0 | BK11: 0 | BL11: 0 | BM11: 0 | BN11: 0 | BO11: 0 | BP11: 0 | BQ11: 0 | BR11: 0 | BS11: =$DS11 -> 0 | BT11: =$DS11 -> 0 | BU11: =$DS11 -> 0 | BV11: =$DS11 -> 0 | BW11: =$DS11 -> 0 | BX11: =$DS11 -> 0 | BY11: =$DS11 -> 0 | BZ11: =$DS11 -> 0 | ... DR11: =$DS11 -> 0 | DS11: =IF(Calculations!B138="",0,Calculations!B138) -> 0 | DT11: =IF(Calculations!C138="",0,Calculations!C138) -> 0 | DU11: =IF(Calculations!D138="",0,Calculations!D138) -> 0 | DV11: =IF(Calculations!E138="",0,Calculations!E138) -> 0 | DW11: =IF(Calculations!F138="",0,Calculations!F138) -> 0 | DX11: =IF(Calculations!G138="",0,Calculations!G138) -> 0 | DY11: =IF(Calculations!H138="",0,Calculations!H138) -> 0 | DZ11: =IF(Calculations!I138="",0,Calculations!I138) -> 0 | ... ED11: =IF(Calculations!M138="",0,Calculations!M138) -> 0 | EE11: =ED11 -> 0 | EF11: =EE11 -> 0 | EG11: =EF11 -> 0 | EH11: =EG11 -> 0 | EI11: =EH11 -> 0 | EJ11: =EI11 -> 0 | EK11: =EJ11 -> 0 | EL11: =EK11 -> 0 | ... HC11: =HB11 -> 0
A12: petroleum | B12: 0 | C12: 0 | D12: 0 | E12: 0 | F12: 0 | G12: 0 | H12: 0 | I12: 0 | J12: 0 | K12: 0 | L12: 0 | M12: 0 | N12: 0 | O12: 0 | P12: 0 | Q12: 0 | R12: 0 | S12: 0 | T12: 0 | U12: 0 | V12: 0 | W12: 0 | X12: 0 | Y12: 0 | Z12: 0 | AA12: 0 | AB12: 0 | AC12: 0 | AD12: 0 | AE12: 0 | AF12: 0 | AG12: 0 | AH12: 0 | AI12: 0 | AJ12: 0 | AK12: 0 | AL12: 0 | AM12: 0 | AN12: 0 | AO12: 0 | AP12: 0 | AQ12: 0 | AR12: 0 | AS12: 0 | AT12: 0 | AU12: 0 | AV12: 0 | AW12: 0 | AX12: 0 | AY12: 0 | AZ12: 0 | BA12: 0 | BB12: 0 | BC12: 0 | BD12: 0 | BE12: 0 | BF12: 0 | BG12: 0 | BH12: 0 | BI12: 0 | BJ12: 0 | BK12: 0 | BL12: 0 | BM12: 0 | BN12: 0 | BO12: 0 | BP12: 0 | BQ12: 0 | BR12: 0 | BS12: =$DS12 -> 0 | BT12: =$DS12 -> 0 | BU12: =$DS12 -> 0 | BV12: =$DS12 -> 0 | BW12: =$DS12 -> 0 | BX12: =$DS12 -> 0 | BY12: =$DS12 -> 0 | BZ12: =$DS12 -> 0 | ... DR12: =$DS12 -> 0 | DS12: =IF(Calculations!B139="",0,Calculations!B139) -> 0 | DT12: =IF(Calculations!C139="",0,Calculations!C139) -> 0 | DU12: =IF(Calculations!D139="",0,Calculations!D139) -> 0 | DV12: =IF(Calculations!E139="",0,Calculations!E139) -> 0 | DW12: =IF(Calculations!F139="",0,Calculations!F139) -> 0 | DX12: =IF(Calculations!G139="",0,Calculations!G139) -> 0 | DY12: =IF(Calculations!H139="",0,Calculations!H139) -> 0 | DZ12: =IF(Calculations!I139="",0,Calculations!I139) -> 0 | EA12: =IF(Calculations!J139="",0,Calculations!J139) -> 0 | EB12: =INDEX('[1]Heat Rates_post2020'!$C$2:$CD$25,MATCH($A12,'[1]Heat Rates_post2020'!$B$2:$B$25,0),MATCH(EB$1,'[1]Heat Rates_post2020'!$C$1:$CD$1,0)) -> 8663571.9 | EC12: =INDEX('[1]Heat Rates_post2020'!$C$2:$CD$25,MATCH($A12,'[1]Heat Rates_post2020'!$B$2:$B$25,0),MATCH(EC$1,'[1]Heat Rates_post2020'!$C$1:$CD$1,0)) -> 8663571.9 | ED12: =INDEX('[1]Heat Rates_post2020'!$C$2:$CD$25,MATCH($A12,'[1]Heat Rates_post2020'!$B$2:$B$25,0),MATCH(ED$1,'[1]Heat Rates_post2020'!$C$1:$CD$1,0)) -> 8663571.9 | EE12: =INDEX('[1]Heat Rates_post2020'!$C$2:$CD$25,MATCH($A12,'[1]Heat Rates_post2020'!$B$2:$B$25,0),MATCH(EE$1,'[1]Heat Rates_post2020'!$C$1:$CD$1,0)) -> 8663571.9 | EF12: =INDEX('[1]Heat Rates_post2020'!$C$2:$CD$25,MATCH($A12,'[1]Heat Rates_post2020'!$B$2:$B$25,0),MATCH(EF$1,'[1]Heat Rates_post2020'!$C$1:$CD$1,0)) -> 8663571.9 | EG12: =INDEX('[1]Heat Rates_post2020'!$C$2:$CD$25,MATCH($A12,'[1]Heat Rates_post2020'!$B$2:$B$25,0),MATCH(EG$1,'[1]Heat Rates_post2020'!$C$1:$CD$1,0)) -> 8663571.9 | EH12: =INDEX('[1]Heat Rates_post2020'!$C$2:$CD$25,MATCH($A12,'[1]Heat Rates_post2020'!$B$2:$B$25,0),MATCH(EH$1,'[1]Heat Rates_post2020'!$C$1:$CD$1,0)) -> 8663571.9 | EI12: =INDEX('[1]Heat Rates_post2020'!$C$2:$CD$25,MATCH($A12,'[1]Heat Rates_post2020'!$B$2:$B$25,0),MATCH(EI$1,'[1]Heat Rates_post2020'!$C$1:$CD$1,0)) -> 8663571.9 | ... HC12: =INDEX('[1]Heat Rates_post2020'!$C$2:$CD$25,MATCH($A12,'[1]Heat Rates_post2020'!$B$2:$B$25,0),MATCH(HC$1,'[1]Heat Rates_post2020'!$C$1:$CD$1,0)) -> 8663571.9
A13: natural gas peaker | B13: 0 | C13: 0 | D13: 0 | E13: 0 | F13: 0 | G13: 0 | H13: 0 | I13: 0 | J13: 0 | K13: 0 | L13: 0 | M13: 0 | N13: 0 | O13: 0 | P13: 0 | Q13: 0 | R13: 0 | S13: 0 | T13: 0 | U13: 0 | V13: 0 | W13: 0 | X13: 0 | Y13: 0 | Z13: 0 | AA13: 0 | AB13: 0 | AC13: 0 | AD13: 0 | AE13: 0 | AF13: 0 | AG13: 0 | AH13: 0 | AI13: 0 | AJ13: 0 | AK13: 0 | AL13: 0 | AM13: 0 | AN13: 0 | AO13: 0 | AP13: 0 | AQ13: 0 | AR13: 0 | AS13: 0 | AT13: 0 | AU13: 0 | AV13: 0 | AW13: 0 | AX13: 0 | AY13: 0 | AZ13: 0 | BA13: 0 | BB13: 0 | BC13: 0 | BD13: 0 | BE13: 0 | BF13: 0 | BG13: 0 | BH13: 0 | BI13: 0 | BJ13: 0 | BK13: 0 | BL13: 0 | BM13: 0 | BN13: 0 | BO13: 0 | BP13: 0 | BQ13: 0 | BR13: 0 | BS13: =$DS13 -> 9853450.6 | BT13: =$DS13 -> 9853450.6 | BU13: =$DS13 -> 9853450.6 | BV13: =$DS13 -> 9853450.6 | BW13: =$DS13 -> 9853450.6 | BX13: =$DS13 -> 9853450.6 | BY13: =$DS13 -> 9853450.6 | BZ13: =$DS13 -> 9853450.6 | ... DR13: =$DS13 -> 9853450.6 | DS13: =IF(Calculations!B140="",0,Calculations!B140) -> 9853450.6 | DT13: =IF(Calculations!C140="",0,Calculations!C140) -> 9846781.1 | DU13: =IF(Calculations!D140="",0,Calculations!D140) -> 9218141.8 | DV13: =IF(Calculations!E140="",0,Calculations!E140) -> 8537985.3 | DW13: =IF(Calculations!F140="",0,Calculations!F140) -> 10716845 | DX13: =IF(Calculations!G140="",0,Calculations!G140) -> 10989477 | DY13: =IF(Calculations!H140="",0,Calculations!H140) -> 11229683 | DZ13: =IF(Calculations!I140="",0,Calculations!I140) -> 10383753 | ... ED13: =IF(Calculations!M140="",0,Calculations!M140) -> 10783680 | EE13: =ED13 -> 10783680 | EF13: =EE13 -> 10783680 | EG13: =EF13 -> 10783680 | EH13: =EG13 -> 10783680 | EI13: =EH13 -> 10783680 | EJ13: =EI13 -> 10783680 | EK13: =EJ13 -> 10783680 | EL13: =EK13 -> 10783680 | ... HC13: =HB13 -> 10783680
A14: lignite | B14: 0 | C14: 0 | D14: 0 | E14: 0 | F14: 0 | G14: 0 | H14: 0 | I14: 0 | J14: 0 | K14: 0 | L14: 0 | M14: 0 | N14: 0 | O14: 0 | P14: 0 | Q14: 0 | R14: 0 | S14: 0 | T14: 0 | U14: 0 | V14: 0 | W14: 0 | X14: 0 | Y14: 0 | Z14: 0 | AA14: 0 | AB14: 0 | AC14: 0 | AD14: 0 | AE14: 0 | AF14: 0 | AG14: 0 | AH14: 0 | AI14: 0 | AJ14: 0 | AK14: 0 | AL14: 0 | AM14: 0 | AN14: 0 | AO14: 0 | AP14: 0 | AQ14: 0 | AR14: 0 | AS14: 0 | AT14: 0 | AU14: 0 | AV14: 0 | AW14: 0 | AX14: 0 | AY14: 0 | AZ14: 0 | BA14: 0 | BB14: 0 | BC14: 0 | BD14: 0 | BE14: 0 | BF14: 0 | BG14: 0 | BH14: 0 | BI14: 0 | BJ14: 0 | BK14: 0 | BL14: 0 | BM14: 0 | BN14: 0 | BO14: 0 | BP14: 0 | BQ14: 0 | BR14: 0 | BS14: =$DS14 -> 0 | BT14: =$DS14 -> 0 | BU14: =$DS14 -> 0 | BV14: =$DS14 -> 0 | BW14: =$DS14 -> 0 | BX14: =$DS14 -> 0 | BY14: =$DS14 -> 0 | BZ14: =$DS14 -> 0 | ... DR14: =$DS14 -> 0 | DS14: =IF(Calculations!B141="",0,Calculations!B141) -> 0 | DT14: =IF(Calculations!C141="",0,Calculations!C141) -> 0 | DU14: =IF(Calculations!D141="",0,Calculations!D141) -> 0 | DV14: =IF(Calculations!E141="",0,Calculations!E141) -> 0 | DW14: =IF(Calculations!F141="",0,Calculations!F141) -> 0 | DX14: =IF(Calculations!G141="",0,Calculations!G141) -> 0 | DY14: =IF(Calculations!H141="",0,Calculations!H141) -> 0 | DZ14: =IF(Calculations!I141="",0,Calculations!I141) -> 0 | EA14: =IF(Calculations!J141="",0,Calculations!J141) -> 0 | EB14: =INDEX('[1]Heat Rates_post2020'!$C$2:$CD$25,MATCH($A14,'[1]Heat Rates_post2020'!$B$2:$B$25,0),MATCH(EB$1,'[1]Heat Rates_post2020'!$C$1:$CD$1,0)) -> 11911124 | EC14: =INDEX('[1]Heat Rates_post2020'!$C$2:$CD$25,MATCH($A14,'[1]Heat Rates_post2020'!$B$2:$B$25,0),MATCH(EC$1,'[1]Heat Rates_post2020'!$C$1:$CD$1,0)) -> 11911124 | ED14: =INDEX('[1]Heat Rates_post2020'!$C$2:$CD$25,MATCH($A14,'[1]Heat Rates_post2020'!$B$2:$B$25,0),MATCH(ED$1,'[1]Heat Rates_post2020'!$C$1:$CD$1,0)) -> 11911124 | EE14: =INDEX('[1]Heat Rates_post2020'!$C$2:$CD$25,MATCH($A14,'[1]Heat Rates_post2020'!$B$2:$B$25,0),MATCH(EE$1,'[1]Heat Rates_post2020'!$C$1:$CD$1,0)) -> 11911124 | EF14: =INDEX('[1]Heat Rates_post2020'!$C$2:$CD$25,MATCH($A14,'[1]Heat Rates_post2020'!$B$2:$B$25,0),MATCH(EF$1,'[1]Heat Rates_post2020'!$C$1:$CD$1,0)) -> 11911124 | EG14: =INDEX('[1]Heat Rates_post2020'!$C$2:$CD$25,MATCH($A14,'[1]Heat Rates_post2020'!$B$2:$B$25,0),MATCH(EG$1,'[1]Heat Rates_post2020'!$C$1:$CD$1,0)) -> 11911124 | EH14: =INDEX('[1]Heat Rates_post2020'!$C$2:$CD$25,MATCH($A14,'[1]Heat Rates_post2020'!$B$2:$B$25,0),MATCH(EH$1,'[1]Heat Rates_post2020'!$C$1:$CD$1,0)) -> 11911124 | EI14: =INDEX('[1]Heat Rates_post2020'!$C$2:$CD$25,MATCH($A14,'[1]Heat Rates_post2020'!$B$2:$B$25,0),MATCH(EI$1,'[1]Heat Rates_post2020'!$C$1:$CD$1,0)) -> 11911124 | ... HC14: =INDEX('[1]Heat Rates_post2020'!$C$2:$CD$25,MATCH($A14,'[1]Heat Rates_post2020'!$B$2:$B$25,0),MATCH(HC$1,'[1]Heat Rates_post2020'!$C$1:$CD$1,0)) -> 11911124
A15: offshore wind | B15: 0 | C15: 0 | D15: 0 | E15: 0 | F15: 0 | G15: 0 | H15: 0 | I15: 0 | J15: 0 | K15: 0 | L15: 0 | M15: 0 | N15: 0 | O15: 0 | P15: 0 | Q15: 0 | R15: 0 | S15: 0 | T15: 0 | U15: 0 | V15: 0 | W15: 0 | X15: 0 | Y15: 0 | Z15: 0 | AA15: 0 | AB15: 0 | AC15: 0 | AD15: 0 | AE15: 0 | AF15: 0 | AG15: 0 | AH15: 0 | AI15: 0 | AJ15: 0 | AK15: 0 | AL15: 0 | AM15: 0 | AN15: 0 | AO15: 0 | AP15: 0 | AQ15: 0 | AR15: 0 | AS15: 0 | AT15: 0 | AU15: 0 | AV15: 0 | AW15: 0 | AX15: 0 | AY15: 0 | AZ15: 0 | BA15: 0 | BB15: 0 | BC15: 0 | BD15: 0 | BE15: 0 | BF15: 0 | BG15: 0 | BH15: 0 | BI15: 0 | BJ15: 0 | BK15: 0 | BL15: 0 | BM15: 0 | BN15: 0 | BO15: 0 | BP15: 0 | BQ15: 0 | BR15: 0 | BS15: =$DS15 -> 0 | BT15: =$DS15 -> 0 | BU15: =$DS15 -> 0 | BV15: =$DS15 -> 0 | BW15: =$DS15 -> 0 | BX15: =$DS15 -> 0 | BY15: =$DS15 -> 0 | BZ15: =$DS15 -> 0 | ... DR15: =$DS15 -> 0 | DS15: =IF(Calculations!B142="",0,Calculations!B142) -> 0 | DT15: =IF(Calculations!C142="",0,Calculations!C142) -> 0 | DU15: =IF(Calculations!D142="",0,Calculations!D142) -> 0 | DV15: =IF(Calculations!E142="",0,Calculations!E142) -> 0 | DW15: =IF(Calculations!F142="",0,Calculations!F142) -> 0 | DX15: =IF(Calculations!G142="",0,Calculations!G142) -> 0 | DY15: =IF(Calculations!H142="",0,Calculations!H142) -> 0 | DZ15: =IF(Calculations!I142="",0,Calculations!I142) -> 0 | ... ED15: =IF(Calculations!M142="",0,Calculations!M142) -> 0 | EE15: =ED15 -> 0 | EF15: =EE15 -> 0 | EG15: =EF15 -> 0 | EH15: =EG15 -> 0 | EI15: =EH15 -> 0 | EJ15: =EI15 -> 0 | EK15: =EJ15 -> 0 | EL15: =EK15 -> 0 | ... HC15: =HB15 -> 0
A16: crude oil | B16: 0 | C16: 0 | D16: 0 | E16: 0 | F16: 0 | G16: 0 | H16: 0 | I16: 0 | J16: 0 | K16: 0 | L16: 0 | M16: 0 | N16: 0 | O16: 0 | P16: 0 | Q16: 0 | R16: 0 | S16: 0 | T16: 0 | U16: 0 | V16: 0 | W16: 0 | X16: 0 | Y16: 0 | Z16: 0 | AA16: 0 | AB16: 0 | AC16: 0 | AD16: 0 | AE16: 0 | AF16: 0 | AG16: 0 | AH16: 0 | AI16: 0 | AJ16: 0 | AK16: 0 | AL16: 0 | AM16: 0 | AN16: 0 | AO16: 0 | AP16: 0 | AQ16: 0 | AR16: 0 | AS16: 0 | AT16: 0 | AU16: 0 | AV16: 0 | AW16: 0 | AX16: 0 | AY16: 0 | AZ16: 0 | BA16: 0 | BB16: 0 | BC16: 0 | BD16: 0 | BE16: 0 | BF16: 0 | BG16: 0 | BH16: 0 | BI16: 0 | BJ16: 0 | BK16: 0 | BL16: 0 | BM16: 0 | BN16: 0 | BO16: 0 | BP16: 0 | BQ16: 0 | BR16: 0 | BS16: =$DS16 -> 0 | BT16: =$DS16 -> 0 | BU16: =$DS16 -> 0 | BV16: =$DS16 -> 0 | BW16: =$DS16 -> 0 | BX16: =$DS16 -> 0 | BY16: =$DS16 -> 0 | BZ16: =$DS16 -> 0 | ... DR16: =$DS16 -> 0 | DS16: =IF(Calculations!B143="",0,Calculations!B143) -> 0 | DT16: =IF(Calculations!C143="",0,Calculations!C143) -> 0 | DU16: =IF(Calculations!D143="",0,Calculations!D143) -> 0 | DV16: =IF(Calculations!E143="",0,Calculations!E143) -> 0 | DW16: =IF(Calculations!F143="",0,Calculations!F143) -> 0 | DX16: =IF(Calculations!G143="",0,Calculations!G143) -> 0 | DY16: =IF(Calculations!H143="",0,Calculations!H143) -> 0 | DZ16: =IF(Calculations!I143="",0,Calculations!I143) -> 0 | ... ED16: =IF(Calculations!M143="",0,Calculations!M143) -> 0 | EE16: =ED16 -> 0 | EF16: =EE16 -> 0 | EG16: =EF16 -> 0 | EH16: =EG16 -> 0 | EI16: =EH16 -> 0 | EJ16: =EI16 -> 0 | EK16: =EJ16 -> 0 | EL16: =EK16 -> 0 | ... HC16: =HB16 -> 0
A17: heavy or residual fuel oil | B17: 0 | C17: 0 | D17: 0 | E17: 0 | F17: 0 | G17: 0 | H17: 0 | I17: 0 | J17: 0 | K17: 0 | L17: 0 | M17: 0 | N17: 0 | O17: 0 | P17: 0 | Q17: 0 | R17: 0 | S17: 0 | T17: 0 | U17: 0 | V17: 0 | W17: 0 | X17: 0 | Y17: 0 | Z17: 0 | AA17: 0 | AB17: 0 | AC17: 0 | AD17: 0 | AE17: 0 | AF17: 0 | AG17: 0 | AH17: 0 | AI17: 0 | AJ17: 0 | AK17: 0 | AL17: 0 | AM17: 0 | AN17: 0 | AO17: 0 | AP17: 0 | AQ17: 0 | AR17: 0 | AS17: 0 | AT17: 0 | AU17: 0 | AV17: 0 | AW17: 0 | AX17: 0 | AY17: 0 | AZ17: 0 | BA17: 0 | BB17: 0 | BC17: 0 | BD17: 0 | BE17: 0 | BF17: 0 | BG17: 0 | BH17: 0 | BI17: 0 | BJ17: 0 | BK17: 0 | BL17: 0 | BM17: 0 | BN17: 0 | BO17: 0 | BP17: 0 | BQ17: 0 | BR17: 0 | BS17: =$DS17 -> 10214520 | BT17: =$DS17 -> 10214520 | BU17: =$DS17 -> 10214520 | BV17: =$DS17 -> 10214520 | BW17: =$DS17 -> 10214520 | BX17: =$DS17 -> 10214520 | BY17: =$DS17 -> 10214520 | BZ17: =$DS17 -> 10214520 | ... DR17: =$DS17 -> 10214520 | DS17: =IF(Calculations!B144="",0,Calculations!B144) -> 10214520 | DT17: =IF(Calculations!C144="",0,Calculations!C144) -> 10008665 | DU17: =IF(Calculations!D144="",0,Calculations!D144) -> 9776584.1 | DV17: =IF(Calculations!E144="",0,Calculations!E144) -> 9503797.2 | DW17: =IF(Calculations!F144="",0,Calculations!F144) -> 10722746 | DX17: =IF(Calculations!G144="",0,Calculations!G144) -> 10935365 | DY17: =IF(Calculations!H144="",0,Calculations!H144) -> 11185614 | DZ17: =IF(Calculations!I144="",0,Calculations!I144) -> 10787017 | ... ED17: =IF(Calculations!M144="",0,Calculations!M144) -> 13194654 | EE17: =ED17 -> 13194654 | EF17: =EE17 -> 13194654 | EG17: =EF17 -> 13194654 | EH17: =EG17 -> 13194654 | EI17: =EH17 -> 13194654 | EJ17: =EI17 -> 13194654 | EK17: =EJ17 -> 13194654 | EL17: =EK17 -> 13194654 | ... HC17: =HB17 -> 13194654
