Workbook
Name Fraction_coal: [1]About!#REF!
Name gal_per_barrel: [2]About!$A$63
Name Percent_rural: [1]About!#REF!
Name Percent_urban: [1]About!#REF!
Name quadrillion: [1]About!$B$62
Name Table4: #REF!
Name Table4_1: #REF!
Name Table4_A: #REF!
Name Table5: #REF!
Name Table5_1: #REF!
Name Table5_A: #REF!
Name UrbFrac: '[3]MX urban Rural'!$B$3

Sheet About
A1: SYCEU Start Year Components Energy Use
A3: Sources: | B3: Energy consumption (residential, commercial & public)
B4: Energy Ministry (SENER)
B5: National Energy Balance 2023
B6: https://www.gob.mx/cms/uploads/attachment/file/947752/BALANCE_NACIONAL_DE_ENERG_A_PRELIMINAR_2023.pdf
B7: CUADRO A.11 CONSUMO FINAL TOTAL DE ENERGÍA (Petajoules)
B8: CUADRO A.15 CONSUMO DE ENERGÍA EN LOS SECTORES RESIDENCIAL, COMERCIAL Y PÚBLICO (Petajoules)
B10: Energy consumption by end use (residential, commercial & public)
B11: National Council of Humanities, Sciences and Technologies (Conahcyt)
B12: Energy futures for Mexico by 2050 The path to a just and sustainable energy transition
B13: https://conahcyt.mx/wp-content/uploads/pronaces/micrositios/energia_y_cambio_climatico/energia/cuadernos_tematicos/Cuaderno_9.pdf
B14: CyS.UF1 | C14: Res.UF1 | D14: Pub.UF1
B15: CyS.UF2 | C15: Res.UF2 | D15: Pub.UF2
B16: CyS.UF3 | C16: Res.UF3
B17: CyS.UF4 | C17: Res.UF4
B18: CyS.UF5 | C18: Res.UF5
B19: CyS.UF6 | C19: Res.UF6
B20: CyS.UF7 | C20: Res.UF7
B21: CyS.UF8 | C21: Res.UF8
C22: Res.UF9
C23: Res.UF10
B25: National population commission
B26: 2023
B27: Demographic Reconciliation Databases 1950 to 2019 and Projections of the Population of Mexico 2020 to 2070
B28: https://www.gob.mx/conapo/documentos/bases-de-datos-de-la-conciliacion-demografica-1950-a-2019-y-proyecciones-de-la-poblacion-de-mexico-2020-a-2070?idiom=es
B29: Datasets, 0_Pob_1950_2070
B30: The rows for States of the Republic have been removed to reduce file size.
B32: National Institute of Statistics and Geography (INEGI)
B33: 2020
B34: Private inhabited homes 1950 2020
B35: https://www.inegi.org.mx/temas/vivienda/#tabulados
A38: Notes:
A40: Unit conversion
A41: BTU/PJ | B41: =5414093.87/0.00000571187 -> 9.4786714e+11
B42: 1 | C42: BEP | D42: 5414093.9 | E42: BTU
B43: 1 | C43: BEP | D43: 5.71187e-06 | E43: PJ
A44: Source: https://dof.gob.mx/nota_detalle.php?codigo=5278970&fecha=23/11/2012#gsc.tab=0
A46: Building type
B47: Building type en EPS | D47: Sectores en México
B48: Urban residential | D48: Residencial
...

Sheet Cuadro A.11
A1: S2.2 | B1: CUADRO A.11 CONSUMO FINAL TOTAL DE ENERGÍA (Petajoules)
B2: 2013 | C2: 2014 | D2: 2015 | E2: 2016 | F2: 2017 | G2: 2018 | H2: 2019 | I2: 2020 | J2: 2021 | K2: 2022 | L2: 2023
A3: Consumo final total | B3: 5115.46 | C3: 5125.5 | D3: 5278.13 | E3: 5479.55 | F3: 5498.89 | G3: 5393.45 | H3: 4851.57 | I3: 4432.6 | J3: 5402.34 | K3: 5682.55 | L3: 5313.42
A4: Consumo no energético total | B4: 190.85 | C4: 232.22 | D4: 188.39 | E4: 173.69 | F4: 136.07 | G4: 109.74 | H4: 90.59 | I4: 49.23 | J4: 44.97 | K4: 60.32 | L4: 51.46
A5: PEMEX Petroquímica | B5: 136.53 | C5: 139.17 | D5: 113.22 | E5: 99.21 | F5: 70.53 | G5: 56.53 | H5: 47.93 | I5: 12.05 | J5: 7.81 | K5: 15.99 | L5: 16.22
A6: Otras ramas económicas | B6: 54.32 | C6: 93.05 | D6: 75.17 | E6: 74.48 | F6: 65.54 | G6: 53.22 | H6: 42.66 | I6: 37.17 | J6: 37.16 | K6: 44.33 | L6: 35.24
A7: Consumo energético total | B7: 4924.62 | C7: 4893.28 | D7: 5089.75 | E7: 5305.86 | F7: 5362.82 | G7: 5283.71 | H7: 4760.98 | I7: 4383.37 | J7: 5357.36 | K7: 5622.24 | L7: 5261.96
A8: Transporte | B8: 2261.27 | C8: 2246.4 | D8: 2361.75 | E8: 2484.95 | F8: 2360.16 | G8: 2454.7 | H8: 2027.05 | I8: 1703.68 | J8: 2784.64 | K8: 2670.78 | L8: 2567.72
A9: Industrial | B9: 1599.05 | C9: 1553.22 | D9: 1601.89 | E9: 1680.74 | F9: 1876.65 | G9: 1680.77 | H9: 1589.45 | I9: 1418.05 | J9: 1152.67 | K9: 1476.99 | L9: 1238.96
A10: Residencial, comercial y público | B10: 905.68 | C10: 934.18 | D10: 947.02 | E10: 959.92 | F10: 944.09 | G10: 958.97 | H10: 952.59 | I10: 1075.64 | J10: 940.95 | K10: 990.36 | L10: 972.58
A11: Agropecuario | B11: 158.62 | C11: 159.48 | D11: 179.09 | E11: 180.26 | F11: 181.91 | G11: 189.27 | H11: 191.89 | I11: 186.01 | J11: 178.71 | K11: 188.14 | L11: 183.22
A12: Sin clasificar 1 | B12: - | C12: - | D12: - | E12: - | F12: - | G12: - | H12: - | I12: - | J12: 300.4 | K12: 295.97 | L12: 299.49
A13: FUENTE: Sistema de Información Energética (SIE). SENER. NOTA: La suma de los parciales puede no coincidir con los totales debido al redondeo de las cifras. Las cifras pueden cambiar respecto al SIE, BDI o BDR debido al cierre de cifras. A partir del BNE 2021, se considera el consumo de combustibles nuevos (licor negro, gas residual y aceite residual). PEMEX reporta gasolina Magna, Premium, Naftas (Gasaviones) y gasolina de llenado inicial. PEMEX reporta Diésel automotriz, desulfurado, industrial, marino y pañoles. A partir del BNE 2021, el consumo de diésel, gasolinas y naftas en el sector autotransporte, se consideró a partir de las ventas en estaciones de servicio de expendio al público registradas por la CRE. Información preliminar 1A partir del BNE 2021 se comenzó a contabilizar este rubro., se refiere a suministro calificado, porteo y pérdidas no técnicas de energía eléctrica.

Sheet Cuadro A.15
A1: CUADRO A.15 CONSUMO DE ENERGÍA EN LOS SECTORES RESIDENCIAL, COMERCIAL Y PÚBLICO (Petajoules)
B3: 2013 | C3: 2014 | D3: 2015 | E3: 2016 | F3: 2017 | G3: 2018 | H3: 2019 | I3: 2020 | J3: 2021 | K3: 2022 | L3: 2023
A4: Total, sector residencial, comercial y público | B4: 920.57 | C4: 938.89 | D4: 952.23 | E4: 959.92 | F4: 944.09 | G4: 958.97 | H4: 952.59 | I4: 1075.64 | J4: 940.95 | K4: 990.36 | L4: 972.58
A5: Energía solar | B5: 7.14 | C5: 8.02 | D5: 9.1 | E5: 10.01 | F5: 10.29 | G5: 11.86 | H5: 13.06 | I5: 14.98 | J5: 40.81 | K5: 58.93 | L5: 65.27
A6: Leña | B6: 255.42 | C6: 254.12 | D6: 252.84 | E6: 251.56 | F6: 250.31 | G6: 249.08 | H6: 247.92 | I6: 330.28 | J6: 245.59 | K6: 244.47 | L6: 243.31
A7: Total, de petrolíferos | B7: 327.74 | C7: 326.8 | D7: 324.35 | E7: 316.65 | F7: 310.88 | G7: 309.74 | H7: 292.93 | I7: 365.74 | J7: 300.28 | K7: 310.2 | L7: 283.08
A8: Gas licuado | B8: 321.99 | C8: 320.42 | D8: 316.56 | E8: 312.76 | F8: 310.88 | G8: 309.74 | H8: 292.93 | I8: 365.74 | J8: 300.28 | K8: 310.2 | L8: 283.08
A9: Querosenos | B9: 1.35 | C9: 1.91 | D9: 2.57 | E9: 1.92 | F9: 0 | G9: 0 | H9: 0 | I9: 0 | J9: 0 | K9: 0 | L9: 0
A10: Diésel | B10: 4.4 | C10: 4.46 | D10: 5.22 | E10: 1.97 | F10: 0 | G10: 0 | H10: 0 | I10: 0 | J10: 0 | K10: 0 | L10: 0
A11: Gas seco | B11: 44.9 | C11: 52.99 | D11: 50.77 | E11: 51.83 | F11: 49.25 | G11: 42.38 | H11: 40.9 | I11: 35.45 | J11: 39.49 | K11: 37.2 | L11: 39.18
A12: Energía eléctrica | B12: 285.37 | C12: 296.97 | D12: 315.16 | E12: 329.88 | F12: 323.36 | G12: 345.91 | H12: 357.77 | I12: 329.2 | J12: 314.78 | K12: 339.56 | L12: 341.74
A13: Residencial | B13: 742.84 | C13: 754.33 | D13: 755.41 | E13: 756.85 | F13: 751.61 | G13: 760.6 | H13: 748.94 | I13: 914.88 | J13: 796.59 | K13: 833.62 | L13: 822.15
A14: Energía solar | B14: 4.17 | C14: 4.71 | D14: 5.42 | E14: 6.1 | F14: 6.42 | G14: 7.11 | H14: 7.88 | I14: 9.01 | J14: 34.17 | K14: 52.06 | L14: 56.64
A15: Leña | B15: 255.42 | C15: 254.12 | D15: 252.84 | E15: 251.56 | F15: 250.31 | G15: 249.08 | H15: 247.92 | I15: 330.28 | J15: 245.59 | K15: 244.47 | L15: 243.31
... A30: Energía eléctrica | B30: 33.43 | C30: 32.39 | D30: 32.37 | E30: 31.22 | F30: 28.92 | G30: 30.93 | H30: 32.95 | I30: 15.36 | J30: 13.92 | K30: 15.34 | L30: 13.31
A31: FUENTE: Sistema de Información Energética (SIE). SENER. NOTA: La suma de los parciales puede no coincidir con los totales debido al redondeo de las cifras. Las cifras pueden cambiar respecto al SIE, BDI o BDR debido al cierre de cifras. PEMEX reporta Diésel automotriz, desulfurado, industrial, marino y pañoles. Para la energía solar se consideraron los datos reportados por Asociación Nacional de Energía Solar (ANES) y Fabricantes Mexicanos en las Energías Renovables A.С. (FAMERAC). Se considera la producción del carbón todo uno (incluye impurezas). Información preliminar.

Sheet CyS
A1: CyS.UF1 | B1: Consumo final del sector Comercial y servicios para Iluminación por energético e y año histórico ā (PJ)
B2: 2012 | C2: 2013 | D2: 2014 | E2: 2015 | F2: 2016 | G2: 2017 | H2: 2018 | I2: 2019 | J2: 2020 | K2: 2021
A3: Carbón | B3: 0 | C3: 0 | D3: 0 | E3: 0 | F3: 0 | G3: 0 | H3: 0 | I3: 0 | J3: 0 | K3: 0
A4: Petróleo | B4: 0 | C4: 0 | D4: 0 | E4: 0 | F4: 0 | G4: 0 | H4: 0 | I4: 0 | J4: 0 | K4: 0
A5: Condensados | B5: 0 | C5: 0 | D5: 0 | E5: 0 | F5: 0 | G5: 0 | H5: 0 | I5: 0 | J5: 0 | K5: 0
A6: Gas natural | B6: 0 | C6: 0 | D6: 0 | E6: 0 | F6: 0 | G6: 0 | H6: 0 | I6: 0 | J6: 0 | K6: 0
A7: Nuclear | B7: 0 | C7: 0 | D7: 0 | E7: 0 | F7: 0 | G7: 0 | H7: 0 | I7: 0 | J7: 0 | K7: 0
A8: Hidroenergía | B8: 0 | C8: 0 | D8: 0 | E8: 0 | F8: 0 | G8: 0 | H8: 0 | I8: 0 | J8: 0 | K8: 0
A9: Radiación solar | B9: 0 | C9: 0 | D9: 0 | E9: 0 | F9: 0 | G9: 0 | H9: 0 | I9: 0 | J9: 0 | K9: 0
A10: Energía eólica | B10: 0 | C10: 0 | D10: 0 | E10: 0 | F10: 0 | G10: 0 | H10: 0 | I10: 0 | J10: 0 | K10: 0
A11: Geoenergía | B11: 0 | C11: 0 | D11: 0 | E11: 0 | F11: 0 | G11: 0 | H11: 0 | I11: 0 | J11: 0 | K11: 0
A12: Bagazos | B12: 0 | C12: 0 | D12: 0 | E12: 0 | F12: 0 | G12: 0 | H12: 0 | I12: 0 | J12: 0 | K12: 0
A13: Leña | B13: 0 | C13: 0 | D13: 0 | E13: 0 | F13: 0 | G13: 0 | H13: 0 | I13: 0 | J13: 0 | K13: 0
A14: Biogás | B14: 0 | C14: 0 | D14: 0 | E14: 0 | F14: 0 | G14: 0 | H14: 0 | I14: 0 | J14: 0 | K14: 0
... A29: Hidrogeno | B29: 0 | C29: 0 | D29: 0 | E29: 0 | F29: 0 | G29: 0 | H29: 0 | I29: 0 | J29: 0 | K29: 0
A33: CyS.UF2 | B33: Consumo final del sector Comercial y servicios para Climatización por energético e y año histórico ā (PJ)
B34: 2012 | C34: 2013 | D34: 2014 | E34: 2015 | F34: 2016 | G34: 2017 | H34: 2018 | I34: 2019 | J34: 2020 | K34: 2021
A35: Carbón | B35: 0 | C35: 0 | D35: 0 | E35: 0 | F35: 0 | G35: 0 | H35: 0 | I35: 0 | J35: 0 | K35: 0
A36: Petróleo | B36: 0 | C36: 0 | D36: 0 | E36: 0 | F36: 0 | G36: 0 | H36: 0 | I36: 0 | J36: 0 | K36: 0
A37: Condensados | B37: 0 | C37: 0 | D37: 0 | E37: 0 | F37: 0 | G37: 0 | H37: 0 | I37: 0 | J37: 0 | K37: 0
A38: Gas natural | B38: 0 | C38: 0 | D38: 0 | E38: 0 | F38: 0 | G38: 0 | H38: 0 | I38: 0 | J38: 0 | K38: 0
A39: Nuclear | B39: 0 | C39: 0 | D39: 0 | E39: 0 | F39: 0 | G39: 0 | H39: 0 | I39: 0 | J39: 0 | K39: 0
A40: Hidroenergía | B40: 0 | C40: 0 | D40: 0 | E40: 0 | F40: 0 | G40: 0 | H40: 0 | I40: 0 | J40: 0 | K40: 0
A41: Radiación solar | B41: 0 | C41: 0 | D41: 0 | E41: 0 | F41: 0 | G41: 0 | H41: 0 | I41: 0 | J41: 0 | K41: 0
A42: Energía eólica | B42: 0 | C42: 0 | D42: 0 | E42: 0 | F42: 0 | G42: 0 | H42: 0 | I42: 0 | J42: 0 | K42: 0
A43: Geoenergía | B43: 0 | C43: 0 | D43: 0 | E43: 0 | F43: 0 | G43: 0 | H43: 0 | I43: 0 | J43: 0 | K43: 0
A44: Bagazos | B44: 0 | C44: 0 | D44: 0 | E44: 0 | F44: 0 | G44: 0 | H44: 0 | I44: 0 | J44: 0 | K44: 0
A45: Leña | B45: 0 | C45: 0 | D45: 0 | E45: 0 | F45: 0 | G45: 0 | H45: 0 | I45: 0 | J45: 0 | K45: 0
A46: Biogás | B46: 0 | C46: 0 | D46: 0 | E46: 0 | F46: 0 | G46: 0 | H46: 0 | I46: 0 | J46: 0 | K46: 0
... A61: Hidrogeno | B61: 0 | C61: 0 | D61: 0 | E61: 0 | F61: 0 | G61: 0 | H61: 0 | I61: 0 | J61: 0 | K61: 0
A65: CyS.UF3 | B65: Consumo final del sector Comercial y servicios para Refrigeración por energético e y año histórico ā (PJ)
B66: 2012 | C66: 2013 | D66: 2014 | E66: 2015 | F66: 2016 | G66: 2017 | H66: 2018 | I66: 2019 | J66: 2020 | K66: 2021
A67: Carbón | B67: 0 | C67: 0 | D67: 0 | E67: 0 | F67: 0 | G67: 0 | H67: 0 | I67: 0 | J67: 0 | K67: 0
A68: Petróleo | B68: 0 | C68: 0 | D68: 0 | E68: 0 | F68: 0 | G68: 0 | H68: 0 | I68: 0 | J68: 0 | K68: 0
A69: Condensados | B69: 0 | C69: 0 | D69: 0 | E69: 0 | F69: 0 | G69: 0 | H69: 0 | I69: 0 | J69: 0 | K69: 0
A70: Gas natural | B70: 0 | C70: 0 | D70: 0 | E70: 0 | F70: 0 | G70: 0 | H70: 0 | I70: 0 | J70: 0 | K70: 0
A71: Nuclear | B71: 0 | C71: 0 | D71: 0 | E71: 0 | F71: 0 | G71: 0 | H71: 0 | I71: 0 | J71: 0 | K71: 0
A72: Hidroenergía | B72: 0 | C72: 0 | D72: 0 | E72: 0 | F72: 0 | G72: 0 | H72: 0 | I72: 0 | J72: 0 | K72: 0
A73: Radiación solar | B73: 0 | C73: 0 | D73: 0 | E73: 0 | F73: 0 | G73: 0 | H73: 0 | I73: 0 | J73: 0 | K73: 0
A74: Energía eólica | B74: 0 | C74: 0 | D74: 0 | E74: 0 | F74: 0 | G74: 0 | H74: 0 | I74: 0 | J74: 0 | K74: 0
...

Sheet Res
A1: Res.UF1 | B1: Consumo final del sector Residencial para Iluminación por energético e y año histórico ā (PJ)
B2: 2012 | C2: 2013 | D2: 2014 | E2: 2015 | F2: 2016 | G2: 2017 | H2: 2018 | I2: 2019 | J2: 2020 | K2: 2021
A3: Carbón | B3: 0 | C3: 0 | D3: 0 | E3: 0 | F3: 0 | G3: 0 | H3: 0 | I3: 0 | J3: 0 | K3: 0
A4: Petróleo | B4: 0 | C4: 0 | D4: 0 | E4: 0 | F4: 0 | G4: 0 | H4: 0 | I4: 0 | J4: 0 | K4: 0
A5: Condensados | B5: 0 | C5: 0 | D5: 0 | E5: 0 | F5: 0 | G5: 0 | H5: 0 | I5: 0 | J5: 0 | K5: 0
A6: Gas natural | B6: 0 | C6: 0 | D6: 0 | E6: 0 | F6: 0 | G6: 0 | H6: 0 | I6: 0 | J6: 0 | K6: 0
A7: Nuclear | B7: 0 | C7: 0 | D7: 0 | E7: 0 | F7: 0 | G7: 0 | H7: 0 | I7: 0 | J7: 0 | K7: 0
A8: Hidroenergía | B8: 0 | C8: 0 | D8: 0 | E8: 0 | F8: 0 | G8: 0 | H8: 0 | I8: 0 | J8: 0 | K8: 0
A9: Radiación solar | B9: 0 | C9: 0 | D9: 0 | E9: 0 | F9: 0 | G9: 0 | H9: 0 | I9: 0 | J9: 0 | K9: 0
A10: Energía eólica | B10: 0 | C10: 0 | D10: 0 | E10: 0 | F10: 0 | G10: 0 | H10: 0 | I10: 0 | J10: 0 | K10: 0
A11: Geoenergía | B11: 0 | C11: 0 | D11: 0 | E11: 0 | F11: 0 | G11: 0 | H11: 0 | I11: 0 | J11: 0 | K11: 0
A12: Bagazos | B12: 0 | C12: 0 | D12: 0 | E12: 0 | F12: 0 | G12: 0 | H12: 0 | I12: 0 | J12: 0 | K12: 0
A13: Leña | B13: 0 | C13: 0 | D13: 0 | E13: 0 | F13: 0 | G13: 0 | H13: 0 | I13: 0 | J13: 0 | K13: 0
A14: Biogás | B14: 0 | C14: 0 | D14: 0 | E14: 0 | F14: 0 | G14: 0 | H14: 0 | I14: 0 | J14: 0 | K14: 0
... A29: Hidrogeno | B29: 0 | C29: 0 | D29: 0 | E29: 0 | F29: 0 | G29: 0 | H29: 0 | I29: 0 | J29: 0 | K29: 0
A33: Res.UF2 | B33: Consumo final del sector Residencial para Climatización por energético e y año histórico ā (PJ)
B34: 2012 | C34: 2013 | D34: 2014 | E34: 2015 | F34: 2016 | G34: 2017 | H34: 2018 | I34: 2019 | J34: 2020 | K34: 2021
A35: Carbón | B35: 0 | C35: 0 | D35: 0 | E35: 0 | F35: 0 | G35: 0 | H35: 0 | I35: 0 | J35: 0 | K35: 0
A36: Petróleo | B36: 0 | C36: 0 | D36: 0 | E36: 0 | F36: 0 | G36: 0 | H36: 0 | I36: 0 | J36: 0 | K36: 0
A37: Condensados | B37: 0 | C37: 0 | D37: 0 | E37: 0 | F37: 0 | G37: 0 | H37: 0 | I37: 0 | J37: 0 | K37: 0
A38: Gas natural | B38: 0 | C38: 0 | D38: 0 | E38: 0 | F38: 0 | G38: 0 | H38: 0 | I38: 0 | J38: 0 | K38: 0
A39: Nuclear | B39: 0 | C39: 0 | D39: 0 | E39: 0 | F39: 0 | G39: 0 | H39: 0 | I39: 0 | J39: 0 | K39: 0
A40: Hidroenergía | B40: 0 | C40: 0 | D40: 0 | E40: 0 | F40: 0 | G40: 0 | H40: 0 | I40: 0 | J40: 0 | K40: 0
A41: Radiación solar | B41: 0 | C41: 0 | D41: 0 | E41: 0 | F41: 0 | G41: 0 | H41: 0 | I41: 0 | J41: 0 | K41: 0
A42: Energía eólica | B42: 0 | C42: 0 | D42: 0 | E42: 0 | F42: 0 | G42: 0 | H42: 0 | I42: 0 | J42: 0 | K42: 0
A43: Geoenergía | B43: 0 | C43: 0 | D43: 0 | E43: 0 | F43: 0 | G43: 0 | H43: 0 | I43: 0 | J43: 0 | K43: 0
A44: Bagazos | B44: 0 | C44: 0 | D44: 0 | E44: 0 | F44: 0 | G44: 0 | H44: 0 | I44: 0 | J44: 0 | K44: 0
A45: Leña | B45: 0 | C45: 0 | D45: 0 | E45: 0 | F45: 0 | G45: 0 | H45: 0 | I45: 0 | J45: 0 | K45: 0
A46: Biogás | B46: 0 | C46: 0 | D46: 0 | E46: 0 | F46: 0 | G46: 0 | H46: 0 | I46: 0 | J46: 0 | K46: 0
... A61: Hidrogeno | B61: 0 | C61: 0 | D61: 0 | E61: 0 | F61: 0 | G61: 0 | H61: 0 | I61: 0 | J61: 0 | K61: 0
A65: Res.UF3 | B65: Consumo final del sector Residencial para Refrigeración por energético e y año histórico ā (PJ)
B66: 2012 | C66: 2013 | D66: 2014 | E66: 2015 | F66: 2016 | G66: 2017 | H66: 2018 | I66: 2019 | J66: 2020 | K66: 2021
A67: Carbón | B67: 0 | C67: 0 | D67: 0 | E67: 0 | F67: 0 | G67: 0 | H67: 0 | I67: 0 | J67: 0 | K67: 0
A68: Petróleo | B68: 0 | C68: 0 | D68: 0 | E68: 0 | F68: 0 | G68: 0 | H68: 0 | I68: 0 | J68: 0 | K68: 0
A69: Condensados | B69: 0 | C69: 0 | D69: 0 | E69: 0 | F69: 0 | G69: 0 | H69: 0 | I69: 0 | J69: 0 | K69: 0
A70: Gas natural | B70: 0 | C70: 0 | D70: 0 | E70: 0 | F70: 0 | G70: 0 | H70: 0 | I70: 0 | J70: 0 | K70: 0
A71: Nuclear | B71: 0 | C71: 0 | D71: 0 | E71: 0 | F71: 0 | G71: 0 | H71: 0 | I71: 0 | J71: 0 | K71: 0
A72: Hidroenergía | B72: 0 | C72: 0 | D72: 0 | E72: 0 | F72: 0 | G72: 0 | H72: 0 | I72: 0 | J72: 0 | K72: 0
A73: Radiación solar | B73: 0 | C73: 0 | D73: 0 | E73: 0 | F73: 0 | G73: 0 | H73: 0 | I73: 0 | J73: 0 | K73: 0
A74: Energía eólica | B74: 0 | C74: 0 | D74: 0 | E74: 0 | F74: 0 | G74: 0 | H74: 0 | I74: 0 | J74: 0 | K74: 0
...

Sheet Pub
A1: Pub.UF1 | B1: Consumo final del sector Público para Alumbrado público por energético e y año histórico ā (PJ)
B2: 2012 | C2: 2013 | D2: 2014 | E2: 2015 | F2: 2016 | G2: 2017 | H2: 2018 | I2: 2019 | J2: 2020 | K2: 2021
A3: Carbón | B3: 0 | C3: 0 | D3: 0 | E3: 0 | F3: 0 | G3: 0 | H3: 0 | I3: 0 | J3: 0 | K3: 0
A4: Petróleo | B4: 0 | C4: 0 | D4: 0 | E4: 0 | F4: 0 | G4: 0 | H4: 0 | I4: 0 | J4: 0 | K4: 0
A5: Condensados | B5: 0 | C5: 0 | D5: 0 | E5: 0 | F5: 0 | G5: 0 | H5: 0 | I5: 0 | J5: 0 | K5: 0
A6: Gas natural | B6: 0 | C6: 0 | D6: 0 | E6: 0 | F6: 0 | G6: 0 | H6: 0 | I6: 0 | J6: 0 | K6: 0
A7: Nuclear | B7: 0 | C7: 0 | D7: 0 | E7: 0 | F7: 0 | G7: 0 | H7: 0 | I7: 0 | J7: 0 | K7: 0
A8: Hidroenergía | B8: 0 | C8: 0 | D8: 0 | E8: 0 | F8: 0 | G8: 0 | H8: 0 | I8: 0 | J8: 0 | K8: 0
A9: Radiación solar | B9: 0 | C9: 0 | D9: 0 | E9: 0 | F9: 0 | G9: 0 | H9: 0 | I9: 0 | J9: 0 | K9: 0
A10: Energía eólica | B10: 0 | C10: 0 | D10: 0 | E10: 0 | F10: 0 | G10: 0 | H10: 0 | I10: 0 | J10: 0 | K10: 0
A11: Geoenergía | B11: 0 | C11: 0 | D11: 0 | E11: 0 | F11: 0 | G11: 0 | H11: 0 | I11: 0 | J11: 0 | K11: 0
A12: Bagazos | B12: 0 | C12: 0 | D12: 0 | E12: 0 | F12: 0 | G12: 0 | H12: 0 | I12: 0 | J12: 0 | K12: 0
A13: Leña | B13: 0 | C13: 0 | D13: 0 | E13: 0 | F13: 0 | G13: 0 | H13: 0 | I13: 0 | J13: 0 | K13: 0
A14: Biogás | B14: 0 | C14: 0 | D14: 0 | E14: 0 | F14: 0 | G14: 0 | H14: 0 | I14: 0 | J14: 0 | K14: 0
... A29: Hidrogeno | B29: 0 | C29: 0 | D29: 0 | E29: 0 | F29: 0 | G29: 0 | H29: 0 | I29: 0 | J29: 0 | K29: 0
A33: Pub.UF2 | B33: Consumo final del sector Público para Bombeo de agua por energético e y año histórico ā (PJ)
B34: 2012 | C34: 2013 | D34: 2014 | E34: 2015 | F34: 2016 | G34: 2017 | H34: 2018 | I34: 2019 | J34: 2020 | K34: 2021
A35: Carbón | B35: 0 | C35: 0 | D35: 0 | E35: 0 | F35: 0 | G35: 0 | H35: 0 | I35: 0 | J35: 0 | K35: 0
A36: Petróleo | B36: 0 | C36: 0 | D36: 0 | E36: 0 | F36: 0 | G36: 0 | H36: 0 | I36: 0 | J36: 0 | K36: 0
A37: Condensados | B37: 0 | C37: 0 | D37: 0 | E37: 0 | F37: 0 | G37: 0 | H37: 0 | I37: 0 | J37: 0 | K37: 0
A38: Gas natural | B38: 0 | C38: 0 | D38: 0 | E38: 0 | F38: 0 | G38: 0 | H38: 0 | I38: 0 | J38: 0 | K38: 0
A39: Nuclear | B39: 0 | C39: 0 | D39: 0 | E39: 0 | F39: 0 | G39: 0 | H39: 0 | I39: 0 | J39: 0 | K39: 0
A40: Hidroenergía | B40: 0 | C40: 0 | D40: 0 | E40: 0 | F40: 0 | G40: 0 | H40: 0 | I40: 0 | J40: 0 | K40: 0
A41: Radiación solar | B41: 0 | C41: 0 | D41: 0 | E41: 0 | F41: 0 | G41: 0 | H41: 0 | I41: 0 | J41: 0 | K41: 0
A42: Energía eólica | B42: 0 | C42: 0 | D42: 0 | E42: 0 | F42: 0 | G42: 0 | H42: 0 | I42: 0 | J42: 0 | K42: 0
A43: Geoenergía | B43: 0 | C43: 0 | D43: 0 | E43: 0 | F43: 0 | G43: 0 | H43: 0 | I43: 0 | J43: 0 | K43: 0
A44: Bagazos | B44: 0 | C44: 0 | D44: 0 | E44: 0 | F44: 0 | G44: 0 | H44: 0 | I44: 0 | J44: 0 | K44: 0
A45: Leña | B45: 0 | C45: 0 | D45: 0 | E45: 0 | F45: 0 | G45: 0 | H45: 0 | I45: 0 | J45: 0 | K45: 0
A46: Biogás | B46: 0 | C46: 0 | D46: 0 | E46: 0 | F46: 0 | G46: 0 | H46: 0 | I46: 0 | J46: 0 | K46: 0
... A61: Hidrogeno | B61: 0 | C61: 0 | D61: 0 | E61: 0 | F61: 0 | G61: 0 | H61: 0 | I61: 0 | J61: 0 | K61: 0

Sheet Pob
B1: Población
A2: 1950 | B2: 26655054
A3: 1951 | B3: 27397996
A4: 1952 | B4: 28162168
A5: 1953 | B5: 28995019
A6: 1954 | B6: 29842856
A7: 1955 | B7: 30780789
A8: 1956 | B8: 31764383
A9: 1957 | B9: 32798480
A10: 1958 | B10: 33875705
A11: 1959 | B11: 35003402
A12: 1960 | B12: 36178954
A13: 1961 | B13: 37394012
... A122: 2070 | B122: 141440479

Sheet Viv
B1: Viviendas
A2: 1950 | B2: 5259208
A3: 1951 | B3: 5374197
A4: 1952 | B4: 5489186
A5: 1953 | B5: 5604174
A6: 1954 | B6: 5719163
A7: 1955 | B7: 5834152
A8: 1956 | B8: 5949141
A9: 1957 | B9: 6064130
A10: 1958 | B10: 6179118
A11: 1959 | B11: 6294107
A12: 1960 | B12: 6409096
A13: 1961 | B13: 6596823
... A72: 2020 | B72: 35233462

Sheet Pob&Viv
B1: Población | C1: Viviendas | D1: Per/Viv
A2: 1950 | B2: =Pob!B2 -> 26655054 | C2: =Viv!B2 -> 5259208 | D2: =B2/C2 -> 5.0682639
A3: 1951 | B3: =Pob!B3 -> 27397996 | C3: =Viv!B3 -> 5374197 | D3: =B3/C3 -> 5.0980632
A4: 1952 | B4: =Pob!B4 -> 28162168 | C4: =Viv!B4 -> 5489186 | D4: =B4/C4 -> 5.1304816
A5: 1953 | B5: =Pob!B5 -> 28995019 | C5: =Viv!B5 -> 5604174 | D5: =B5/C5 -> 5.1738256
A6: 1954 | B6: =Pob!B6 -> 29842856 | C6: =Viv!B6 -> 5719163 | D6: =B6/C6 -> 5.2180461
A7: 1955 | B7: =Pob!B7 -> 30780789 | C7: =Viv!B7 -> 5834152 | D7: =B7/C7 -> 5.2759662
A8: 1956 | B8: =Pob!B8 -> 31764383 | C8: =Viv!B8 -> 5949141 | D8: =B8/C8 -> 5.3393226
A9: 1957 | B9: =Pob!B9 -> 32798480 | C9: =Viv!B9 -> 6064130 | D9: =B9/C9 -> 5.4086044
A10: 1958 | B10: =Pob!B10 -> 33875705 | C10: =Viv!B10 -> 6179118 | D10: =B10/C10 -> 5.4822881
A11: 1959 | B11: =Pob!B11 -> 35003402 | C11: =Viv!B11 -> 6294107 | D11: =B11/C11 -> 5.5612976
A12: 1960 | B12: =Pob!B12 -> 36178954 | C12: =Viv!B12 -> 6409096 | D12: =B12/C12 -> 5.6449387
A13: 1961 | B13: =Pob!B13 -> 37394012 | C13: =Viv!B13 -> 6596823 | D13: =B13/C13 -> 5.668488
... A72: 2020 | B72: =Pob!B72 -> 127191826 | C72: =Viv!B72 -> 35233462 | D72: =B72/C72 -> 3.6099724
A73: 2021 | B73: =Pob!B73 -> 128389290 | C73: =B73/D73 -> 36065403 | D73: =((103.75-0.049575*A73)-(103.75-0.049575*A72))*(1-((A73-A$74)/100))+D72 -> 3.5599017
A74: 2022 | B74: =Pob!B74 -> 129960600 | C74: =B74/D74 -> 37022366 | D74: =((103.75-0.049575*A74)-(103.75-0.049575*A73))*(1-((A74-A$74)/100))+D73 -> 3.5103267
A75: 2023 | B75: =Pob!B75 -> 131135337 | C75: =B75/D75 -> 37886727 | D75: =((103.75-0.049575*A75)-(103.75-0.049575*A74))*(1-((A75-A$74)/100))+D74 -> 3.4612474
A76: 2024 | B76: =Pob!B76 -> 132274416 | C76: =B76/D76 -> 38759872 | D76: =((103.75-0.049575*A76)-(103.75-0.049575*A75))*(1-((A76-A$74)/100))+D75 -> 3.4126639
A77: 2025 | B77: =Pob!B77 -> 133367428 | C77: =B77/D77 -> 39638701 | D77: =((103.75-0.049575*A77)-(103.75-0.049575*A76))*(1-((A77-A$74)/100))+D76 -> 3.3645762
A78: 2026 | B78: =Pob!B78 -> 134407258 | C78: =B78/D78 -> 40520922 | D78: =((103.75-0.049575*A78)-(103.75-0.049575*A77))*(1-((A78-A$74)/100))+D77 -> 3.3169842
A79: 2027 | B79: =Pob!B79 -> 135391662 | C79: =B79/D79 -> 41405597 | D79: =((103.75-0.049575*A79)-(103.75-0.049575*A78))*(1-((A79-A$74)/100))+D78 -> 3.2698879
A80: 2028 | B80: =Pob!B80 -> 136321595 | C80: =B80/D80 -> 42292721 | D80: =((103.75-0.049575*A80)-(103.75-0.049575*A79))*(1-((A80-A$74)/100))+D79 -> 3.2232874
A81: 2029 | B81: =Pob!B81 -> 137200808 | C81: =B81/D81 -> 43183166 | D81: =((103.75-0.049575*A81)-(103.75-0.049575*A80))*(1-((A81-A$74)/100))+D80 -> 3.1771827
A82: 2030 | B82: =Pob!B82 -> 138033990 | C82: =B82/D82 -> 44078155 | D82: =((103.75-0.049575*A82)-(103.75-0.049575*A81))*(1-((A82-A$74)/100))+D81 -> 3.1315737
A83: 2031 | B83: =Pob!B83 -> 138825843 | C83: =B83/D83 -> 44978981 | D83: =((103.75-0.049575*A83)-(103.75-0.049575*A82))*(1-((A83-A$74)/100))+D82 -> 3.0864604
A84: 2032 | B84: =Pob!B84 -> 139580548 | C84: =B84/D84 -> 45886836 | D84: =((103.75-0.049575*A84)-(103.75-0.049575*A83))*(1-((A84-A$74)/100))+D83 -> 3.0418429
... A122: 2070 | B122: =Pob!B122 -> 141440479 | C122: =B122/D122 -> 82533765 | D122: =((103.75-0.049575*A122)-(103.75-0.049575*A121))*(1-((A122-A$74)/100))+D121 -> 1.7137287

Sheet P.Res
A2: Residencial
A3: Energético | D3: 2013 | E3: 2014 | F3: 2015 | G3: 2016 | H3: 2017 | I3: 2018 | J3: 2019 | K3: 2020 | L3: 2021 | M3: 2022 | N3: 2023 | O3: 2024 | P3: 2025 | Q3: 2026 | R3: 2027 | S3: 2028 | T3: 2029 | U3: 2030 | V3: 2031 | W3: 2032 | X3: 2033 | Y3: 2034 | Z3: 2035 | AA3: 2036 | AB3: 2037 | AC3: 2038 | AD3: 2039 | AE3: 2040 | AF3: 2041 | AG3: 2042 | AH3: 2043 | AI3: 2044 | AJ3: 2045 | AK3: 2046 | AL3: 2047 | AM3: 2048 | AN3: 2049 | AO3: 2050 | AP3: 2051 | AQ3: 2052 | AR3: 2053 | AS3: 2054 | AT3: 2055 | AU3: 2056 | AV3: 2057 | AW3: 2058 | AX3: 2059 | AY3: 2060 | AZ3: 2061 | BA3: 2062 | BB3: 2063 | BC3: 2064 | BD3: 2065 | BE3: 2066 | BF3: 2067 | BG3: 2068 | BH3: 2069 | BI3: 2070
C4: Radiación solar | D4: =Res!C9+Res!C41+Res!C73+Res!C105+Res!C137+Res!C169+Res!C201+Res!C233+Res!C265+Res!C297 -> 4.04 | E4: =Res!D9+Res!D41+Res!D73+Res!D105+Res!D137+Res!D169+Res!D201+Res!D233+Res!D265+Res!D297 -> 4.53 | F4: =Res!E9+Res!E41+Res!E73+Res!E105+Res!E137+Res!E169+Res!E201+Res!E233+Res!E265+Res!E297 -> 5.29 | G4: =Res!F9+Res!F41+Res!F73+Res!F105+Res!F137+Res!F169+Res!F201+Res!F233+Res!F265+Res!F297 -> 6.1 | H4: =Res!G9+Res!G41+Res!G73+Res!G105+Res!G137+Res!G169+Res!G201+Res!G233+Res!G265+Res!G297 -> 6.42 | I4: =Res!H9+Res!H41+Res!H73+Res!H105+Res!H137+Res!H169+Res!H201+Res!H233+Res!H265+Res!H297 -> 7.11 | J4: =Res!I9+Res!I41+Res!I73+Res!I105+Res!I137+Res!I169+Res!I201+Res!I233+Res!I265+Res!I297 -> 7.89 | K4: =Res!J9+Res!J41+Res!J73+Res!J105+Res!J137+Res!J169+Res!J201+Res!J233+Res!J265+Res!J297 -> 9.01 | L4: =Res!K9+Res!K41+Res!K73+Res!K105+Res!K137+Res!K169+Res!K201+Res!K233+Res!K265+Res!K297 -> 10.69 | M4: =L4+L4-K4 -> 12.37 | N4: =M4+M4-L4 -> 14.05
C5: Leña | D5: =Res!C13+Res!C45+Res!C77+Res!C109+Res!C141+Res!C173+Res!C205+Res!C237+Res!C269+Res!C301 -> 331.84 | E5: =Res!D13+Res!D45+Res!D77+Res!D109+Res!D141+Res!D173+Res!D205+Res!D237+Res!D269+Res!D301 -> 330.21 | F5: =Res!E13+Res!E45+Res!E77+Res!E109+Res!E141+Res!E173+Res!E205+Res!E237+Res!E269+Res!E301 -> 328.57 | G5: =Res!F13+Res!F45+Res!F77+Res!F109+Res!F141+Res!F173+Res!F205+Res!F237+Res!F269+Res!F301 -> 326.93 | H5: =Res!G13+Res!G45+Res!G77+Res!G109+Res!G141+Res!G173+Res!G205+Res!G237+Res!G269+Res!G301 -> 325.29 | I5: =Res!H13+Res!H45+Res!H77+Res!H109+Res!H141+Res!H173+Res!H205+Res!H237+Res!H269+Res!H301 -> 323.68 | J5: =Res!I13+Res!I45+Res!I77+Res!I109+Res!I141+Res!I173+Res!I205+Res!I237+Res!I269+Res!I301 -> 322.04 | K5: =Res!J13+Res!J45+Res!J77+Res!J109+Res!J141+Res!J173+Res!J205+Res!J237+Res!J269+Res!J301 -> 320.4 | L5: =Res!K13+Res!K45+Res!K77+Res!K109+Res!K141+Res!K173+Res!K205+Res!K237+Res!K269+Res!K301 -> 319.07 | M5: =L5+L5-K5 -> 317.74 | N5: =M5+M5-L5 -> 316.41
C6: Carbón vegetal | D6: =Res!C17+Res!C49+Res!C81+Res!C113+Res!C145+Res!C177+Res!C209+Res!C241+Res!C273+Res!C305 -> 71.16 | E6: =Res!D17+Res!D49+Res!D81+Res!D113+Res!D145+Res!D177+Res!D209+Res!D241+Res!D273+Res!D305 -> 71.89 | F6: =Res!E17+Res!E49+Res!E81+Res!E113+Res!E145+Res!E177+Res!E209+Res!E241+Res!E273+Res!E305 -> 72.63 | G6: =Res!F17+Res!F49+Res!F81+Res!F113+Res!F145+Res!F177+Res!F209+Res!F241+Res!F273+Res!F305 -> 73.36 | H6: =Res!G17+Res!G49+Res!G81+Res!G113+Res!G145+Res!G177+Res!G209+Res!G241+Res!G273+Res!G305 -> 74.09 | I6: =Res!H17+Res!H49+Res!H81+Res!H113+Res!H145+Res!H177+Res!H209+Res!H241+Res!H273+Res!H305 -> 74.83 | J6: =Res!I17+Res!I49+Res!I81+Res!I113+Res!I145+Res!I177+Res!I209+Res!I241+Res!I273+Res!I305 -> 75.56 | K6: =Res!J17+Res!J49+Res!J81+Res!J113+Res!J145+Res!J177+Res!J209+Res!J241+Res!J273+Res!J305 -> 76.31 | L6: =Res!K17+Res!K49+Res!K81+Res!K113+Res!K145+Res!K177+Res!K209+Res!K241+Res!K273+Res!K305 -> 77.04 | M6: =L6+L6-K6 -> 77.77 | N6: =M6+M6-L6 -> 78.5
C7: BCS Procesados | D7: =Res!C18+Res!C50+Res!C82+Res!C114+Res!C146+Res!C178+Res!C210+Res!C242+Res!C274+Res!C306 -> 20.51 | E7: =Res!D18+Res!D50+Res!D82+Res!D114+Res!D146+Res!D178+Res!D210+Res!D242+Res!D274+Res!D306 -> 20.4 | F7: =Res!E18+Res!E50+Res!E82+Res!E114+Res!E146+Res!E178+Res!E210+Res!E242+Res!E274+Res!E306 -> 20.31 | G7: =Res!F18+Res!F50+Res!F82+Res!F114+Res!F146+Res!F178+Res!F210+Res!F242+Res!F274+Res!F306 -> 20.2 | H7: =Res!G18+Res!G50+Res!G82+Res!G114+Res!G146+Res!G178+Res!G210+Res!G242+Res!G274+Res!G306 -> 20.11 | I7: =Res!H18+Res!H50+Res!H82+Res!H114+Res!H146+Res!H178+Res!H210+Res!H242+Res!H274+Res!H306 -> 20 | J7: =Res!I18+Res!I50+Res!I82+Res!I114+Res!I146+Res!I178+Res!I210+Res!I242+Res!I274+Res!I306 -> 19.91 | K7: =Res!J18+Res!J50+Res!J82+Res!J114+Res!J146+Res!J178+Res!J210+Res!J242+Res!J274+Res!J306 -> 19.8 | L7: =Res!K18+Res!K50+Res!K82+Res!K114+Res!K146+Res!K178+Res!K210+Res!K242+Res!K274+Res!K306 -> 19.72 | M7: =L7+L7-K7 -> 19.64 | N7: =M7+M7-L7 -> 19.56
C8: Gas licuado de petróleo | D8: ='Cuadro A.15'!B17 -> 256.96 | E8: ='Cuadro A.15'!C17 -> 257.11 | F8: ='Cuadro A.15'!D17 -> 253.39 | G8: ='Cuadro A.15'!E17 -> 247.54 | H8: ='Cuadro A.15'!F17 -> 246.45 | I8: ='Cuadro A.15'!G17 -> 246.45 | J8: ='Cuadro A.15'!H17 -> 231.04 | K8: ='Cuadro A.15'!I17 -> 289.54 | ... N8: ='Cuadro A.15'!L17 -> 224.57
C9: Gas seco | D9: ='Cuadro A.15'!B19 -> 33.8 | E9: ='Cuadro A.15'!C19 -> 39.86 | F9: ='Cuadro A.15'!D19 -> 37.43 | G9: ='Cuadro A.15'!E19 -> 37.45 | H9: ='Cuadro A.15'!F19 -> 35.48 | I9: ='Cuadro A.15'!G19 -> 30.16 | J9: ='Cuadro A.15'!H19 -> 29.94 | K9: ='Cuadro A.15'!I19 -> 25.95 | ... N9: ='Cuadro A.15'!L19 -> 26
C10: Electricidad | D10: ='Cuadro A.15'!B20 -> 191.14 | E10: ='Cuadro A.15'!C20 -> 196.62 | F10: ='Cuadro A.15'!D20 -> 203.75 | G10: ='Cuadro A.15'!E20 -> 212.28 | H10: ='Cuadro A.15'!F20 -> 212.95 | I10: ='Cuadro A.15'!G20 -> 227.8 | J10: ='Cuadro A.15'!H20 -> 232.15 | K10: ='Cuadro A.15'!I20 -> 260.1 | ... N10: ='Cuadro A.15'!L20 -> 271.63
D11: =SUM(D4:D10) -> 909.45 | E11: =SUM(E4:E10) -> 920.62 | F11: =SUM(F4:F10) -> 921.37 | G11: =SUM(G4:G10) -> 923.86 | H11: =SUM(H4:H10) -> 920.79 | I11: =SUM(I4:I10) -> 930.03 | J11: =SUM(J4:J10) -> 918.53 | K11: =SUM(K4:K10) -> 1001.11 | ... N11: =SUM(N4:N10) -> 950.72
A13: Usos finales | D13: 2013 | E13: 2014 | F13: 2015 | G13: 2016 | H13: 2017 | I13: 2018 | J13: 2019 | K13: 2020 | L13: 2021 | M13: 2022 | N13: 2023
C14: Iluminación | D14: =D28 -> 20.862711 | E14: =E28 -> 21.460299 | F14: =F28 -> 22.232638 | G14: =G28 -> 23.166443 | H14: =H28 -> 23.235293 | I14: =I28 -> 24.857739 | J14: =J28 -> 25.330589 | K14: =K28 -> 28.385165 | ... N14: =N28 -> 29.644898
C15: Otros | D15: =D30 -> 0 | E15: =E30 -> 0 | F15: =F30 -> 0 | G15: =G30 -> 0 | H15: =H30 -> 0 | I15: =I30 -> 0 | J15: =J30 -> 0 | K15: =K30 -> 0 | ... N15: =N30 -> 0
C16: Stand by | D16: =D32 -> 13.578529 | E16: =E32 -> 13.972673 | F16: =F32 -> 14.483928 | G16: =G32 -> 15.089598 | H16: =H32 -> 15.139107 | I16: =I32 -> 16.191857 | J16: =J32 -> 16.502332 | K16: =K32 -> 18.482156 | ... N16: =N32 -> 19.303655
C17: Climatización | D17: =D34 -> 51.420746 | E17: =E34 -> 52.895641 | F17: =F34 -> 54.818269 | G17: =G34 -> 57.114833 | H17: =H34 -> 57.295111 | I17: =I34 -> 61.282941 | J17: =J34 -> 62.448559 | K17: =K34 -> 69.982994 | ... N17: =N34 -> 73.078122
C18: Lavadoras | D18: =D36 -> 14.796789 | E18: =E36 -> 15.21638 | F18: =F36 -> 15.766827 | G18: =G36 -> 16.435739 | H18: =H36 -> 16.484241 | I18: =I36 -> 17.629694 | J18: =J36 -> 17.975755 | K18: =K36 -> 20.130494 | ... N18: =N36 -> 21.027195
C19: Microondas | D19: =D38 -> 4.3654335 | E19: =E38 -> 4.492576 | F19: =F38 -> 4.6569229 | G19: =G38 -> 4.846107 | H19: =H38 -> 4.8602497 | I19: =I38 -> 5.2073013 | J19: =J38 -> 5.3043212 | K19: =K38 -> 5.9444012 | ... N19: =N38 -> 6.2047462
C20: Televisión | D20: =D40 -> 44.390368 | E20: =E40 -> 45.661832 | F20: =F40 -> 47.313311 | G20: =G40 -> 49.294395 | H20: =H40 -> 49.452723 | I20: =I40 -> 52.902036 | J20: =J40 -> 53.914987 | K20: =K40 -> 60.404461 | ... N20: =N40 -> 63.081586
C21: Refrigeración | D21: =D42 -> 41.725423 | E21: =E42 -> 42.920599 | F21: =F42 -> 44.478104 | G21: =G42 -> 46.332886 | H21: =H42 -> 46.483276 | I21: =I42 -> 49.728432 | J21: =J42 -> 50.673457 | K21: =K42 -> 56.770329 | ... N21: =N42 -> 59.289797
C22: Calentamiento de agua | D22: =SUM(D44:D49) -> 182.61 | E22: =SUM(E44:E49) -> 184.39745 | F22: =SUM(F44:F49) -> 183.44829 | G22: =SUM(G44:G49) -> 182.47234 | H22: =SUM(H44:H49) -> 181.78172 | I22: =SUM(I44:I49) -> 180.89318 | J22: =SUM(J44:J49) -> 177.38009 | K22: =SUM(K44:K49) -> 192.5006 | ... N22: =SUM(N44:N49) -> 177.63302
C23: Cocción de alimentos | D23: =SUM(D52:D56) -> 535.7 | E23: =SUM(E52:E56) -> 539.60255 | F23: =SUM(F52:F56) -> 534.17171 | G23: =SUM(G52:G56) -> 529.10766 | H23: =SUM(H52:H56) -> 526.05828 | I23: =SUM(I52:I56) -> 521.33682 | J23: =SUM(J52:J56) -> 508.99991 | K23: =SUM(K52:K56) -> 548.5094 | ... N23: =SUM(N52:N56) -> 501.45698
D24: =SUM(D14:D23) -> 909.45 | E24: =SUM(E14:E23) -> 920.62 | F24: =SUM(F14:F23) -> 921.37 | G24: =SUM(G14:G23) -> 923.86 | H24: =SUM(H14:H23) -> 920.79 | I24: =SUM(I14:I23) -> 930.03 | J24: =SUM(J14:J23) -> 918.53 | K24: =SUM(K14:K23) -> 1001.11 | ... N24: =SUM(N14:N23) -> 950.72
A26: Usos finales y energético | D26: 2013 | E26: 2014 | F26: 2015 | G26: 2016 | H26: 2017 | I26: 2018 | J26: 2019 | K26: 2020 | L26: 2021 | M26: 2022 | N26: 2023
B27: Iluminación
C28: Electricidad | D28: =D$10*Res!C28/(Res!C$28+Res!C$60+Res!C$92+Res!C$124+Res!C$156+Res!C$188+Res!C$220+Res!C$252+Res!C$284+Res!C$316) -> 20.862711 | E28: =E$10*Res!D28/(Res!D$28+Res!D$60+Res!D$92+Res!D$124+Res!D$156+Res!D$188+Res!D$220+Res!D$252+Res!D$284+Res!D$316) -> 21.460299 | F28: =F$10*Res!E28/(Res!E$28+Res!E$60+Res!E$92+Res!E$124+Res!E$156+Res!E$188+Res!E$220+Res!E$252+Res!E$284+Res!E$316) -> 22.232638 | G28: =G$10*Res!F28/(Res!F$28+Res!F$60+Res!F$92+Res!F$124+Res!F$156+Res!F$188+Res!F$220+Res!F$252+Res!F$284+Res!F$316) -> 23.166443 | H28: =H$10*Res!G28/(Res!G$28+Res!G$60+Res!G$92+Res!G$124+Res!G$156+Res!G$188+Res!G$220+Res!G$252+Res!G$284+Res!G$316) -> 23.235293 | I28: =I$10*Res!H28/(Res!H$28+Res!H$60+Res!H$92+Res!H$124+Res!H$156+Res!H$188+Res!H$220+Res!H$252+Res!H$284+Res!H$316) -> 24.857739 | J28: =J$10*Res!I28/(Res!I$28+Res!I$60+Res!I$92+Res!I$124+Res!I$156+Res!I$188+Res!I$220+Res!I$252+Res!I$284+Res!I$316) -> 25.330589 | K28: =K$10*Res!J28/(Res!J$28+Res!J$60+Res!J$92+Res!J$124+Res!J$156+Res!J$188+Res!J$220+Res!J$252+Res!J$284+Res!J$316) -> 28.385165 | L28: =L$10*Res!K28/(Res!K$28+Res!K$60+Res!K$92+Res!K$124+Res!K$156+Res!K$188+Res!K$220+Res!K$252+Res!K$284+Res!K$316) -> 27.290812 | M28: =L28/L$10*M$10 -> 28.911497 | N28: =M28/M$10*N$10 -> 29.644898
B29: Otros
C30: Electricidad | D30: =D$10*Res!C316/(Res!C$28+Res!C$60+Res!C$92+Res!C$124+Res!C$156+Res!C$188+Res!C$220+Res!C$252+Res!C$284+Res!C$316) -> 0 | E30: =E$10*Res!D316/(Res!D$28+Res!D$60+Res!D$92+Res!D$124+Res!D$156+Res!D$188+Res!D$220+Res!D$252+Res!D$284+Res!D$316) -> 0 | F30: =F$10*Res!E316/(Res!E$28+Res!E$60+Res!E$92+Res!E$124+Res!E$156+Res!E$188+Res!E$220+Res!E$252+Res!E$284+Res!E$316) -> 0 | G30: =G$10*Res!F316/(Res!F$28+Res!F$60+Res!F$92+Res!F$124+Res!F$156+Res!F$188+Res!F$220+Res!F$252+Res!F$284+Res!F$316) -> 0 | H30: =H$10*Res!G316/(Res!G$28+Res!G$60+Res!G$92+Res!G$124+Res!G$156+Res!G$188+Res!G$220+Res!G$252+Res!G$284+Res!G$316) -> 0 | I30: =I$10*Res!H316/(Res!H$28+Res!H$60+Res!H$92+Res!H$124+Res!H$156+Res!H$188+Res!H$220+Res!H$252+Res!H$284+Res!H$316) -> 0 | J30: =J$10*Res!I316/(Res!I$28+Res!I$60+Res!I$92+Res!I$124+Res!I$156+Res!I$188+Res!I$220+Res!I$252+Res!I$284+Res!I$316) -> 0 | K30: =K$10*Res!J316/(Res!J$28+Res!J$60+Res!J$92+Res!J$124+Res!J$156+Res!J$188+Res!J$220+Res!J$252+Res!J$284+Res!J$316) -> 0 | L30: =L$10*Res!K316/(Res!K$28+Res!K$60+Res!K$92+Res!K$124+Res!K$156+Res!K$188+Res!K$220+Res!K$252+Res!K$284+Res!K$316) -> 0 | M30: =L30/L$10*M$10 -> 0 | N30: =M30/M$10*N$10 -> 0
B31: Stand by
C32: Electricidad | D32: =D$10*Res!C188/(Res!C$28+Res!C$60+Res!C$92+Res!C$124+Res!C$156+Res!C$188+Res!C$220+Res!C$252+Res!C$284+Res!C$316) -> 13.578529 | E32: =E$10*Res!D188/(Res!D$28+Res!D$60+Res!D$92+Res!D$124+Res!D$156+Res!D$188+Res!D$220+Res!D$252+Res!D$284+Res!D$316) -> 13.972673 | F32: =F$10*Res!E188/(Res!E$28+Res!E$60+Res!E$92+Res!E$124+Res!E$156+Res!E$188+Res!E$220+Res!E$252+Res!E$284+Res!E$316) -> 14.483928 | G32: =G$10*Res!F188/(Res!F$28+Res!F$60+Res!F$92+Res!F$124+Res!F$156+Res!F$188+Res!F$220+Res!F$252+Res!F$284+Res!F$316) -> 15.089598 | H32: =H$10*Res!G188/(Res!G$28+Res!G$60+Res!G$92+Res!G$124+Res!G$156+Res!G$188+Res!G$220+Res!G$252+Res!G$284+Res!G$316) -> 15.139107 | I32: =I$10*Res!H188/(Res!H$28+Res!H$60+Res!H$92+Res!H$124+Res!H$156+Res!H$188+Res!H$220+Res!H$252+Res!H$284+Res!H$316) -> 16.191857 | J32: =J$10*Res!I188/(Res!I$28+Res!I$60+Res!I$92+Res!I$124+Res!I$156+Res!I$188+Res!I$220+Res!I$252+Res!I$284+Res!I$316) -> 16.502332 | K32: =K$10*Res!J188/(Res!J$28+Res!J$60+Res!J$92+Res!J$124+Res!J$156+Res!J$188+Res!J$220+Res!J$252+Res!J$284+Res!J$316) -> 18.482156 | L32: =L$10*Res!K188/(Res!K$28+Res!K$60+Res!K$92+Res!K$124+Res!K$156+Res!K$188+Res!K$220+Res!K$252+Res!K$284+Res!K$316) -> 17.770761 | M32: =L32/L$10*M$10 -> 18.826091 | N32: =M32/M$10*N$10 -> 19.303655
B33: Climatización
C34: Electricidad | D34: =D$10*Res!C60/(Res!C$28+Res!C$60+Res!C$92+Res!C$124+Res!C$156+Res!C$188+Res!C$220+Res!C$252+Res!C$284+Res!C$316) -> 51.420746 | E34: =E$10*Res!D60/(Res!D$28+Res!D$60+Res!D$92+Res!D$124+Res!D$156+Res!D$188+Res!D$220+Res!D$252+Res!D$284+Res!D$316) -> 52.895641 | F34: =F$10*Res!E60/(Res!E$28+Res!E$60+Res!E$92+Res!E$124+Res!E$156+Res!E$188+Res!E$220+Res!E$252+Res!E$284+Res!E$316) -> 54.818269 | G34: =G$10*Res!F60/(Res!F$28+Res!F$60+Res!F$92+Res!F$124+Res!F$156+Res!F$188+Res!F$220+Res!F$252+Res!F$284+Res!F$316) -> 57.114833 | H34: =H$10*Res!G60/(Res!G$28+Res!G$60+Res!G$92+Res!G$124+Res!G$156+Res!G$188+Res!G$220+Res!G$252+Res!G$284+Res!G$316) -> 57.295111 | I34: =I$10*Res!H60/(Res!H$28+Res!H$60+Res!H$92+Res!H$124+Res!H$156+Res!H$188+Res!H$220+Res!H$252+Res!H$284+Res!H$316) -> 61.282941 | J34: =J$10*Res!I60/(Res!I$28+Res!I$60+Res!I$92+Res!I$124+Res!I$156+Res!I$188+Res!I$220+Res!I$252+Res!I$284+Res!I$316) -> 62.448559 | K34: =K$10*Res!J60/(Res!J$28+Res!J$60+Res!J$92+Res!J$124+Res!J$156+Res!J$188+Res!J$220+Res!J$252+Res!J$284+Res!J$316) -> 69.982994 | L34: =L$10*Res!K60/(Res!K$28+Res!K$60+Res!K$92+Res!K$124+Res!K$156+Res!K$188+Res!K$220+Res!K$252+Res!K$284+Res!K$316) -> 67.275025 | M34: =L34/L$10*M$10 -> 71.270203 | N34: =M34/M$10*N$10 -> 73.078122
B35: Lavadoras
C36: Electricidad | D36: =D$10*Res!C220/(Res!C$28+Res!C$60+Res!C$92+Res!C$124+Res!C$156+Res!C$188+Res!C$220+Res!C$252+Res!C$284+Res!C$316) -> 14.796789 | E36: =E$10*Res!D220/(Res!D$28+Res!D$60+Res!D$92+Res!D$124+Res!D$156+Res!D$188+Res!D$220+Res!D$252+Res!D$284+Res!D$316) -> 15.21638 | F36: =F$10*Res!E220/(Res!E$28+Res!E$60+Res!E$92+Res!E$124+Res!E$156+Res!E$188+Res!E$220+Res!E$252+Res!E$284+Res!E$316) -> 15.766827 | G36: =G$10*Res!F220/(Res!F$28+Res!F$60+Res!F$92+Res!F$124+Res!F$156+Res!F$188+Res!F$220+Res!F$252+Res!F$284+Res!F$316) -> 16.435739 | H36: =H$10*Res!G220/(Res!G$28+Res!G$60+Res!G$92+Res!G$124+Res!G$156+Res!G$188+Res!G$220+Res!G$252+Res!G$284+Res!G$316) -> 16.484241 | I36: =I$10*Res!H220/(Res!H$28+Res!H$60+Res!H$92+Res!H$124+Res!H$156+Res!H$188+Res!H$220+Res!H$252+Res!H$284+Res!H$316) -> 17.629694 | J36: =J$10*Res!I220/(Res!I$28+Res!I$60+Res!I$92+Res!I$124+Res!I$156+Res!I$188+Res!I$220+Res!I$252+Res!I$284+Res!I$316) -> 17.975755 | K36: =K$10*Res!J220/(Res!J$28+Res!J$60+Res!J$92+Res!J$124+Res!J$156+Res!J$188+Res!J$220+Res!J$252+Res!J$284+Res!J$316) -> 20.130494 | L36: =L$10*Res!K220/(Res!K$28+Res!K$60+Res!K$92+Res!K$124+Res!K$156+Res!K$188+Res!K$220+Res!K$252+Res!K$284+Res!K$316) -> 19.357437 | M36: =L36/L$10*M$10 -> 20.506992 | N36: =M36/M$10*N$10 -> 21.027195
B37: Microondas
C38: Electricidad | D38: =D$10*Res!C252/(Res!C$28+Res!C$60+Res!C$92+Res!C$124+Res!C$156+Res!C$188+Res!C$220+Res!C$252+Res!C$284+Res!C$316) -> 4.3654335 | E38: =E$10*Res!D252/(Res!D$28+Res!D$60+Res!D$92+Res!D$124+Res!D$156+Res!D$188+Res!D$220+Res!D$252+Res!D$284+Res!D$316) -> 4.492576 | F38: =F$10*Res!E252/(Res!E$28+Res!E$60+Res!E$92+Res!E$124+Res!E$156+Res!E$188+Res!E$220+Res!E$252+Res!E$284+Res!E$316) -> 4.6569229 | G38: =G$10*Res!F252/(Res!F$28+Res!F$60+Res!F$92+Res!F$124+Res!F$156+Res!F$188+Res!F$220+Res!F$252+Res!F$284+Res!F$316) -> 4.846107 | H38: =H$10*Res!G252/(Res!G$28+Res!G$60+Res!G$92+Res!G$124+Res!G$156+Res!G$188+Res!G$220+Res!G$252+Res!G$284+Res!G$316) -> 4.8602497 | I38: =I$10*Res!H252/(Res!H$28+Res!H$60+Res!H$92+Res!H$124+Res!H$156+Res!H$188+Res!H$220+Res!H$252+Res!H$284+Res!H$316) -> 5.2073013 | J38: =J$10*Res!I252/(Res!I$28+Res!I$60+Res!I$92+Res!I$124+Res!I$156+Res!I$188+Res!I$220+Res!I$252+Res!I$284+Res!I$316) -> 5.3043212 | K38: =K$10*Res!J252/(Res!J$28+Res!J$60+Res!J$92+Res!J$124+Res!J$156+Res!J$188+Res!J$220+Res!J$252+Res!J$284+Res!J$316) -> 5.9444012 | L38: =L$10*Res!K252/(Res!K$28+Res!K$60+Res!K$92+Res!K$124+Res!K$156+Res!K$188+Res!K$220+Res!K$252+Res!K$284+Res!K$316) -> 5.7120305 | M38: =L38/L$10*M$10 -> 6.0512437 | N38: =M38/M$10*N$10 -> 6.2047462
B39: Televisión
C40: Electricidad | D40: =D$10*Res!C284/(Res!C$28+Res!C$60+Res!C$92+Res!C$124+Res!C$156+Res!C$188+Res!C$220+Res!C$252+Res!C$284+Res!C$316) -> 44.390368 | E40: =E$10*Res!D284/(Res!D$28+Res!D$60+Res!D$92+Res!D$124+Res!D$156+Res!D$188+Res!D$220+Res!D$252+Res!D$284+Res!D$316) -> 45.661832 | F40: =F$10*Res!E284/(Res!E$28+Res!E$60+Res!E$92+Res!E$124+Res!E$156+Res!E$188+Res!E$220+Res!E$252+Res!E$284+Res!E$316) -> 47.313311 | G40: =G$10*Res!F284/(Res!F$28+Res!F$60+Res!F$92+Res!F$124+Res!F$156+Res!F$188+Res!F$220+Res!F$252+Res!F$284+Res!F$316) -> 49.294395 | H40: =H$10*Res!G284/(Res!G$28+Res!G$60+Res!G$92+Res!G$124+Res!G$156+Res!G$188+Res!G$220+Res!G$252+Res!G$284+Res!G$316) -> 49.452723 | I40: =I$10*Res!H284/(Res!H$28+Res!H$60+Res!H$92+Res!H$124+Res!H$156+Res!H$188+Res!H$220+Res!H$252+Res!H$284+Res!H$316) -> 52.902036 | J40: =J$10*Res!I284/(Res!I$28+Res!I$60+Res!I$92+Res!I$124+Res!I$156+Res!I$188+Res!I$220+Res!I$252+Res!I$284+Res!I$316) -> 53.914987 | K40: =K$10*Res!J284/(Res!J$28+Res!J$60+Res!J$92+Res!J$124+Res!J$156+Res!J$188+Res!J$220+Res!J$252+Res!J$284+Res!J$316) -> 60.404461 | L40: =L$10*Res!K284/(Res!K$28+Res!K$60+Res!K$92+Res!K$124+Res!K$156+Res!K$188+Res!K$220+Res!K$252+Res!K$284+Res!K$316) -> 58.07231 | M40: =L40/L$10*M$10 -> 61.520977 | N40: =M40/M$10*N$10 -> 63.081586
B41: Refrigeración
C42: Electricidad | D42: =D$10*Res!C92/(Res!C$28+Res!C$60+Res!C$92+Res!C$124+Res!C$156+Res!C$188+Res!C$220+Res!C$252+Res!C$284+Res!C$316) -> 41.725423 | E42: =E$10*Res!D92/(Res!D$28+Res!D$60+Res!D$92+Res!D$124+Res!D$156+Res!D$188+Res!D$220+Res!D$252+Res!D$284+Res!D$316) -> 42.920599 | F42: =F$10*Res!E92/(Res!E$28+Res!E$60+Res!E$92+Res!E$124+Res!E$156+Res!E$188+Res!E$220+Res!E$252+Res!E$284+Res!E$316) -> 44.478104 | G42: =G$10*Res!F92/(Res!F$28+Res!F$60+Res!F$92+Res!F$124+Res!F$156+Res!F$188+Res!F$220+Res!F$252+Res!F$284+Res!F$316) -> 46.332886 | H42: =H$10*Res!G92/(Res!G$28+Res!G$60+Res!G$92+Res!G$124+Res!G$156+Res!G$188+Res!G$220+Res!G$252+Res!G$284+Res!G$316) -> 46.483276 | I42: =I$10*Res!H92/(Res!H$28+Res!H$60+Res!H$92+Res!H$124+Res!H$156+Res!H$188+Res!H$220+Res!H$252+Res!H$284+Res!H$316) -> 49.728432 | J42: =J$10*Res!I92/(Res!I$28+Res!I$60+Res!I$92+Res!I$124+Res!I$156+Res!I$188+Res!I$220+Res!I$252+Res!I$284+Res!I$316) -> 50.673457 | K42: =K$10*Res!J92/(Res!J$28+Res!J$60+Res!J$92+Res!J$124+Res!J$156+Res!J$188+Res!J$220+Res!J$252+Res!J$284+Res!J$316) -> 56.770329 | L42: =L$10*Res!K92/(Res!K$28+Res!K$60+Res!K$92+Res!K$124+Res!K$156+Res!K$188+Res!K$220+Res!K$252+Res!K$284+Res!K$316) -> 54.581624 | M42: =L42/L$10*M$10 -> 57.822995 | N42: =M42/M$10*N$10 -> 59.289797
B43: Calentamiento de agua
...

Sheet P.Com
A2: Comercial y servicios | D2: 2013 | E2: 2014 | F2: 2015 | G2: 2016 | H2: 2017 | I2: 2018 | J2: 2019 | K2: 2020 | L2: 2021 | M2: 2022 | N2: 2023
A3: Energético
C4: Radiación solar | D4: ='Cuadro A.15'!B22 -> 2.98 | E4: ='Cuadro A.15'!C22 -> 3.3 | F4: ='Cuadro A.15'!D22 -> 3.68 | G4: ='Cuadro A.15'!E22 -> 3.91 | H4: ='Cuadro A.15'!F22 -> 3.87 | I4: ='Cuadro A.15'!G22 -> 4.75 | J4: ='Cuadro A.15'!H22 -> 5.17 | K4: ='Cuadro A.15'!I22 -> 5.96 | ... N4: ='Cuadro A.15'!L22 -> 8.47
C5: Leña | D5: =CyS!C13+CyS!C45+CyS!C77+CyS!C109+CyS!C141+CyS!C173+CyS!C205+CyS!C237 -> 13.46 | E5: =CyS!D13+CyS!D45+CyS!D77+CyS!D109+CyS!D141+CyS!D173+CyS!D205+CyS!D237 -> 13.4 | F5: =CyS!E13+CyS!E45+CyS!E77+CyS!E109+CyS!E141+CyS!E173+CyS!E205+CyS!E237 -> 13.33 | G5: =CyS!F13+CyS!F45+CyS!F77+CyS!F109+CyS!F141+CyS!F173+CyS!F205+CyS!F237 -> 13.27 | H5: =CyS!G13+CyS!G45+CyS!G77+CyS!G109+CyS!G141+CyS!G173+CyS!G205+CyS!G237 -> 13.2 | I5: =CyS!H13+CyS!H45+CyS!H77+CyS!H109+CyS!H141+CyS!H173+CyS!H205+CyS!H237 -> 13.13 | J5: =CyS!I13+CyS!I45+CyS!I77+CyS!I109+CyS!I141+CyS!I173+CyS!I205+CyS!I237 -> 13.07 | K5: =CyS!J13+CyS!J45+CyS!J77+CyS!J109+CyS!J141+CyS!J173+CyS!J205+CyS!J237 -> 13 | L5: =CyS!K13+CyS!K45+CyS!K77+CyS!K109+CyS!K141+CyS!K173+CyS!K205+CyS!K237 -> 12.95 | M5: =L5+L5-K5 -> 12.9 | N5: =M5+M5-L5 -> 12.85
C6: Carbón vegetal | D6: =CyS!C17+CyS!C49+CyS!C81+CyS!C113+CyS!C145+CyS!C177+CyS!C209+CyS!C241 -> 5.77 | E6: =CyS!D17+CyS!D49+CyS!D81+CyS!D113+CyS!D145+CyS!D177+CyS!D209+CyS!D241 -> 5.85 | F6: =CyS!E17+CyS!E49+CyS!E81+CyS!E113+CyS!E145+CyS!E177+CyS!E209+CyS!E241 -> 5.92 | G6: =CyS!F17+CyS!F49+CyS!F81+CyS!F113+CyS!F145+CyS!F177+CyS!F209+CyS!F241 -> 6 | H6: =CyS!G17+CyS!G49+CyS!G81+CyS!G113+CyS!G145+CyS!G177+CyS!G209+CyS!G241 -> 6.07 | I6: =CyS!H17+CyS!H49+CyS!H81+CyS!H113+CyS!H145+CyS!H177+CyS!H209+CyS!H241 -> 6.15 | J6: =CyS!I17+CyS!I49+CyS!I81+CyS!I113+CyS!I145+CyS!I177+CyS!I209+CyS!I241 -> 6.22 | K6: =CyS!J17+CyS!J49+CyS!J81+CyS!J113+CyS!J145+CyS!J177+CyS!J209+CyS!J241 -> 6.3 | L6: =CyS!K17+CyS!K49+CyS!K81+CyS!K113+CyS!K145+CyS!K177+CyS!K209+CyS!K241 -> 6.38 | M6: =L6+L6-K6 -> 6.46 | N6: =M6+M6-L6 -> 6.54
C7: Gas licuado de petróleo | D7: ='Cuadro A.15'!B24 -> 65.03 | E7: ='Cuadro A.15'!C24 -> 63.32 | F7: ='Cuadro A.15'!D24 -> 63.17 | G7: ='Cuadro A.15'!E24 -> 65.21 | H7: ='Cuadro A.15'!F24 -> 64.43 | I7: ='Cuadro A.15'!G24 -> 63.29 | J7: ='Cuadro A.15'!H24 -> 61.89 | K7: ='Cuadro A.15'!I24 -> 76.2 | ... N7: ='Cuadro A.15'!L24 -> 58.51
C8: Diésel | D8: ='Cuadro A.15'!B25 -> 4.4 | E8: ='Cuadro A.15'!C25 -> 4.46 | F8: ='Cuadro A.15'!D25 -> 5.22 | G8: ='Cuadro A.15'!E25 -> 1.97 | H8: ='Cuadro A.15'!F25 -> 0 | I8: ='Cuadro A.15'!G25 -> 0 | J8: ='Cuadro A.15'!H25 -> 0 | K8: ='Cuadro A.15'!I25 -> 0 | ... N8: ='Cuadro A.15'!L25 -> 0
C9: Gas seco | D9: ='Cuadro A.15'!B26 -> 11.1 | E9: ='Cuadro A.15'!C26 -> 13.13 | F9: ='Cuadro A.15'!D26 -> 13.34 | G9: ='Cuadro A.15'!E26 -> 14.38 | H9: ='Cuadro A.15'!F26 -> 13.77 | I9: ='Cuadro A.15'!G26 -> 12.22 | J9: ='Cuadro A.15'!H26 -> 10.96 | K9: ='Cuadro A.15'!I26 -> 9.5 | ... N9: ='Cuadro A.15'!L26 -> 13.18
C10: Electricidad | D10: =CyS!C28+CyS!C60+CyS!C92+CyS!C124+CyS!C156+CyS!C188+CyS!C220+CyS!C252 -> 61.22 | E10: =CyS!D28+CyS!D60+CyS!D92+CyS!D124+CyS!D156+CyS!D188+CyS!D220+CyS!D252 -> 63.57 | F10: =CyS!E28+CyS!E60+CyS!E92+CyS!E124+CyS!E156+CyS!E188+CyS!E220+CyS!E252 -> 65.21 | G10: =CyS!F28+CyS!F60+CyS!F92+CyS!F124+CyS!F156+CyS!F188+CyS!F220+CyS!F252 -> 66.69 | H10: =CyS!G28+CyS!G60+CyS!G92+CyS!G124+CyS!G156+CyS!G188+CyS!G220+CyS!G252 -> 68.13 | I10: =CyS!H28+CyS!H60+CyS!H92+CyS!H124+CyS!H156+CyS!H188+CyS!H220+CyS!H252 -> 66.17 | J10: =CyS!I28+CyS!I60+CyS!I92+CyS!I124+CyS!I156+CyS!I188+CyS!I220+CyS!I252 -> 68.1 | K10: =CyS!J28+CyS!J60+CyS!J92+CyS!J124+CyS!J156+CyS!J188+CyS!J220+CyS!J252 -> 65.8 | L10: =CyS!K28+CyS!K60+CyS!K92+CyS!K124+CyS!K156+CyS!K188+CyS!K220+CyS!K252 -> 71.99 | M10: =M12+M14 -> 80.177511 | N10: =N12+N14 -> 77.915809
D11: =SUM(D4:D10) -> 163.96 | E11: =SUM(E4:E10) -> 167.03 | F11: =SUM(F4:F10) -> 169.87 | G11: =SUM(G4:G10) -> 171.43 | H11: =SUM(H4:H10) -> 169.47 | I11: =SUM(I4:I10) -> 165.71 | J11: =SUM(J4:J10) -> 165.41 | K11: =SUM(K4:K10) -> 176.76 | ... N11: =SUM(N4:N10) -> 177.46581
C12: Base | L12: ='Cuadro A.15'!J27 -> 50.8 | M12: ='Cuadro A.15'!K27 -> 59.3 | N12: ='Cuadro A.15'!L27 -> 56.79
C13: Sin clasificar | L13: ='Cuadro A.11'!J12 -> 300.4 | M13: ='Cuadro A.11'!K12 -> 295.97 | N13: ='Cuadro A.11'!L12 -> 299.49
L14: =(L10-L12)/L13 -> 0.070539281 | M14: =$L14*M13 -> 20.877511 | N14: =$L14*N13 -> 21.125809
A15: Usos finales
C16: Iluminación | D16: =D11*(SUM(CyS!C3:C29)/SUM(CyS!C3:C29,CyS!C35:C61,CyS!C67:C93,CyS!C99:C125,CyS!C131:C157,CyS!C163:C189,CyS!C195:C221,CyS!C227:C253)) -> 18.057621 | E16: =E11*(SUM(CyS!D3:D29)/SUM(CyS!D3:D29,CyS!D35:D61,CyS!D67:D93,CyS!D99:D125,CyS!D131:D157,CyS!D163:D189,CyS!D195:D221,CyS!D227:D253)) -> 18.750206 | F16: =F11*(SUM(CyS!E3:E29)/SUM(CyS!E3:E29,CyS!E35:E61,CyS!E67:E93,CyS!E99:E125,CyS!E131:E157,CyS!E163:E189,CyS!E195:E221,CyS!E227:E253)) -> 19.305465 | G16: =G11*(SUM(CyS!F3:F29)/SUM(CyS!F3:F29,CyS!F35:F61,CyS!F67:F93,CyS!F99:F125,CyS!F131:F157,CyS!F163:F189,CyS!F195:F221,CyS!F227:F253)) -> 20.229399 | H16: =H11*(SUM(CyS!G3:G29)/SUM(CyS!G3:G29,CyS!G35:G61,CyS!G67:G93,CyS!G99:G125,CyS!G131:G157,CyS!G163:G189,CyS!G195:G221,CyS!G227:G253)) -> 20.10678 | I16: =I11*(SUM(CyS!H3:H29)/SUM(CyS!H3:H29,CyS!H35:H61,CyS!H67:H93,CyS!H99:H125,CyS!H131:H157,CyS!H163:H189,CyS!H195:H221,CyS!H227:H253)) -> 19.41735 | J16: =J11*(SUM(CyS!I3:I29)/SUM(CyS!I3:I29,CyS!I35:I61,CyS!I67:I93,CyS!I99:I125,CyS!I131:I157,CyS!I163:I189,CyS!I195:I221,CyS!I227:I253)) -> 19.955043 | K16: =K11*(SUM(CyS!J3:J29)/SUM(CyS!J3:J29,CyS!J35:J61,CyS!J67:J93,CyS!J99:J125,CyS!J131:J157,CyS!J163:J189,CyS!J195:J221,CyS!J227:J253)) -> 21.198074 | L16: =L11*(SUM(CyS!K3:K29)/SUM(CyS!K3:K29,CyS!K35:K61,CyS!K67:K93,CyS!K99:K125,CyS!K131:K157,CyS!K163:K189,CyS!K195:K221,CyS!K227:K253)) -> 21.21 | M16: =M11*(SUM(CyS!K3:K29)/SUM(CyS!K3:K29,CyS!K35:K61,CyS!K67:K93,CyS!K99:K125,CyS!K131:K157,CyS!K163:K189,CyS!K195:K221,CyS!K227:K253)) -> 22.530738 | N16: =N11*(SUM(CyS!K3:K29)/SUM(CyS!K3:K29,CyS!K35:K61,CyS!K67:K93,CyS!K99:K125,CyS!K131:K157,CyS!K163:K189,CyS!K195:K221,CyS!K227:K253)) -> 22.033892
C17: Climatización | D17: =D11*(SUM(CyS!C35:C61)/SUM(CyS!C3:C29,CyS!C35:C61,CyS!C67:C93,CyS!C99:C125,CyS!C131:C157,CyS!C163:C189,CyS!C195:C221,CyS!C227:C253)) -> 29.729011 | E17: =E11*(SUM(CyS!D35:D61)/SUM(CyS!D3:D29,CyS!D35:D61,CyS!D67:D93,CyS!D99:D125,CyS!D131:D157,CyS!D163:D189,CyS!D195:D221,CyS!D227:D253)) -> 30.893292 | F17: =F11*(SUM(CyS!E35:E61)/SUM(CyS!E3:E29,CyS!E35:E61,CyS!E67:E93,CyS!E99:E125,CyS!E131:E157,CyS!E163:E189,CyS!E195:E221,CyS!E227:E253)) -> 31.807286 | G17: =G11*(SUM(CyS!F35:F61)/SUM(CyS!F3:F29,CyS!F35:F61,CyS!F67:F93,CyS!F99:F125,CyS!F131:F157,CyS!F163:F189,CyS!F195:F221,CyS!F227:F253)) -> 33.30387 | H17: =H11*(SUM(CyS!G35:G61)/SUM(CyS!G3:G29,CyS!G35:G61,CyS!G67:G93,CyS!G99:G125,CyS!G131:G157,CyS!G163:G189,CyS!G195:G221,CyS!G227:G253)) -> 33.120585 | I17: =I11*(SUM(CyS!H35:H61)/SUM(CyS!H3:H29,CyS!H35:H61,CyS!H67:H93,CyS!H99:H125,CyS!H131:H157,CyS!H163:H189,CyS!H195:H221,CyS!H227:H253)) -> 31.990309 | J17: =J11*(SUM(CyS!I35:I61)/SUM(CyS!I3:I29,CyS!I35:I61,CyS!I67:I93,CyS!I99:I125,CyS!I131:I157,CyS!I163:I189,CyS!I195:I221,CyS!I227:I253)) -> 32.877078 | K17: =K11*(SUM(CyS!J35:J61)/SUM(CyS!J3:J29,CyS!J35:J61,CyS!J67:J93,CyS!J99:J125,CyS!J131:J157,CyS!J163:J189,CyS!J195:J221,CyS!J227:J253)) -> 34.925413 | L17: =L11*(SUM(CyS!K35:K61)/SUM(CyS!K3:K29,CyS!K35:K61,CyS!K67:K93,CyS!K99:K125,CyS!K131:K157,CyS!K163:K189,CyS!K195:K221,CyS!K227:K253)) -> 34.94 | M17: =M11*(SUM(CyS!K35:K61)/SUM(CyS!K3:K29,CyS!K35:K61,CyS!K67:K93,CyS!K99:K125,CyS!K131:K157,CyS!K163:K189,CyS!K195:K221,CyS!K227:K253)) -> 37.115699 | N17: =N11*(SUM(CyS!K35:K61)/SUM(CyS!K3:K29,CyS!K35:K61,CyS!K67:K93,CyS!K99:K125,CyS!K131:K157,CyS!K163:K189,CyS!K195:K221,CyS!K227:K253)) -> 36.297228
C18: Refrigeración | D18: =D11*(SUM(CyS!C67:C93)/SUM(CyS!C3:C29,CyS!C35:C61,CyS!C67:C93,CyS!C99:C125,CyS!C131:C157,CyS!C163:C189,CyS!C195:C221,CyS!C227:C253)) -> 5.5253919 | E18: =E11*(SUM(CyS!D67:D93)/SUM(CyS!D3:D29,CyS!D35:D61,CyS!D67:D93,CyS!D99:D125,CyS!D131:D157,CyS!D163:D189,CyS!D195:D221,CyS!D227:D253)) -> 5.7361816 | F18: =F11*(SUM(CyS!E67:E93)/SUM(CyS!E3:E29,CyS!E35:E61,CyS!E67:E93,CyS!E99:E125,CyS!E131:E157,CyS!E163:E189,CyS!E195:E221,CyS!E227:E253)) -> 5.9092208 | G18: =G11*(SUM(CyS!F67:F93)/SUM(CyS!F3:F29,CyS!F35:F61,CyS!F67:F93,CyS!F99:F125,CyS!F131:F157,CyS!F163:F189,CyS!F195:F221,CyS!F227:F253)) -> 6.1975054 | H18: =H11*(SUM(CyS!G67:G93)/SUM(CyS!G3:G29,CyS!G35:G61,CyS!G67:G93,CyS!G99:G125,CyS!G131:G157,CyS!G163:G189,CyS!G195:G221,CyS!G227:G253)) -> 6.1612704 | I18: =I11*(SUM(CyS!H67:H93)/SUM(CyS!H3:H29,CyS!H35:H61,CyS!H67:H93,CyS!H99:H125,CyS!H131:H157,CyS!H163:H189,CyS!H195:H221,CyS!H227:H253)) -> 5.9477466 | J18: =J11*(SUM(CyS!I67:I93)/SUM(CyS!I3:I29,CyS!I35:I61,CyS!I67:I93,CyS!I99:I125,CyS!I131:I157,CyS!I163:I189,CyS!I195:I221,CyS!I227:I253)) -> 6.1078747 | K18: =K11*(SUM(CyS!J67:J93)/SUM(CyS!J3:J29,CyS!J35:J61,CyS!J67:J93,CyS!J99:J125,CyS!J131:J157,CyS!J163:J189,CyS!J195:J221,CyS!J227:J253)) -> 6.4972426 | L18: =L11*(SUM(CyS!K67:K93)/SUM(CyS!K3:K29,CyS!K35:K61,CyS!K67:K93,CyS!K99:K125,CyS!K131:K157,CyS!K163:K189,CyS!K195:K221,CyS!K227:K253)) -> 6.49 | M18: =M11*(SUM(CyS!K67:K93)/SUM(CyS!K3:K29,CyS!K35:K61,CyS!K67:K93,CyS!K99:K125,CyS!K131:K157,CyS!K163:K189,CyS!K195:K221,CyS!K227:K253)) -> 6.8941295 | N18: =N11*(SUM(CyS!K67:K93)/SUM(CyS!K3:K29,CyS!K35:K61,CyS!K67:K93,CyS!K99:K125,CyS!K131:K157,CyS!K163:K189,CyS!K195:K221,CyS!K227:K253)) -> 6.7421009
C19: Motores | D19: =D11*(SUM(CyS!C99:C125)/SUM(CyS!C3:C29,CyS!C35:C61,CyS!C67:C93,CyS!C99:C125,CyS!C131:C157,CyS!C163:C189,CyS!C195:C221,CyS!C227:C253)) -> 13.38306 | E19: =E11*(SUM(CyS!D99:D125)/SUM(CyS!D3:D29,CyS!D35:D61,CyS!D67:D93,CyS!D99:D125,CyS!D131:D157,CyS!D163:D189,CyS!D195:D221,CyS!D227:D253)) -> 14.595729 | F19: =F11*(SUM(CyS!E99:E125)/SUM(CyS!E3:E29,CyS!E35:E61,CyS!E67:E93,CyS!E99:E125,CyS!E131:E157,CyS!E163:E189,CyS!E195:E221,CyS!E227:E253)) -> 15.617227 | G19: =G11*(SUM(CyS!F99:F125)/SUM(CyS!F3:F29,CyS!F35:F61,CyS!F67:F93,CyS!F99:F125,CyS!F131:F157,CyS!F163:F189,CyS!F195:F221,CyS!F227:F253)) -> 13.259779 | H19: =H11*(SUM(CyS!G99:G125)/SUM(CyS!G3:G29,CyS!G35:G61,CyS!G67:G93,CyS!G99:G125,CyS!G131:G157,CyS!G163:G189,CyS!G195:G221,CyS!G227:G253)) -> 12.873549 | I19: =I11*(SUM(CyS!H99:H125)/SUM(CyS!H3:H29,CyS!H35:H61,CyS!H67:H93,CyS!H99:H125,CyS!H131:H157,CyS!H163:H189,CyS!H195:H221,CyS!H227:H253)) -> 10.919146 | J19: =J11*(SUM(CyS!I99:I125)/SUM(CyS!I3:I29,CyS!I35:I61,CyS!I67:I93,CyS!I99:I125,CyS!I131:I157,CyS!I163:I189,CyS!I195:I221,CyS!I227:I253)) -> 9.8680972 | K19: =K11*(SUM(CyS!J99:J125)/SUM(CyS!J3:J29,CyS!J35:J61,CyS!J67:J93,CyS!J99:J125,CyS!J131:J157,CyS!J163:J189,CyS!J195:J221,CyS!J227:J253)) -> 9.2208342 | L19: =L11*(SUM(CyS!K99:K125)/SUM(CyS!K3:K29,CyS!K35:K61,CyS!K67:K93,CyS!K99:K125,CyS!K131:K157,CyS!K163:K189,CyS!K195:K221,CyS!K227:K253)) -> 9.94 | M19: =M11*(SUM(CyS!K99:K125)/SUM(CyS!K3:K29,CyS!K35:K61,CyS!K67:K93,CyS!K99:K125,CyS!K131:K157,CyS!K163:K189,CyS!K195:K221,CyS!K227:K253)) -> 10.55896 | N19: =N11*(SUM(CyS!K99:K125)/SUM(CyS!K3:K29,CyS!K35:K61,CyS!K67:K93,CyS!K99:K125,CyS!K131:K157,CyS!K163:K189,CyS!K195:K221,CyS!K227:K253)) -> 10.326115
C20: Misceláneos | D20: =D11*(SUM(CyS!C131:C157)/SUM(CyS!C3:C29,CyS!C35:C61,CyS!C67:C93,CyS!C99:C125,CyS!C131:C157,CyS!C163:C189,CyS!C195:C221,CyS!C227:C253)) -> 1.7617192 | E20: =E11*(SUM(CyS!D131:D157)/SUM(CyS!D3:D29,CyS!D35:D61,CyS!D67:D93,CyS!D99:D125,CyS!D131:D157,CyS!D163:D189,CyS!D195:D221,CyS!D227:D253)) -> 1.8219634 | F20: =F11*(SUM(CyS!E131:E157)/SUM(CyS!E3:E29,CyS!E35:E61,CyS!E67:E93,CyS!E99:E125,CyS!E131:E157,CyS!E163:E189,CyS!E195:E221,CyS!E227:E253)) -> 1.879293 | G20: =G11*(SUM(CyS!F131:F157)/SUM(CyS!F3:F29,CyS!F35:F61,CyS!F67:F93,CyS!F99:F125,CyS!F131:F157,CyS!F163:F189,CyS!F195:F221,CyS!F227:F253)) -> 1.9663182 | H20: =H11*(SUM(CyS!G131:G157)/SUM(CyS!G3:G29,CyS!G35:G61,CyS!G67:G93,CyS!G99:G125,CyS!G131:G157,CyS!G163:G189,CyS!G195:G221,CyS!G227:G253)) -> 1.9435552 | I20: =I11*(SUM(CyS!H131:H157)/SUM(CyS!H3:H29,CyS!H35:H61,CyS!H67:H93,CyS!H99:H125,CyS!H131:H157,CyS!H163:H189,CyS!H195:H221,CyS!H227:H253)) -> 1.882955 | J20: =J11*(SUM(CyS!I131:I157)/SUM(CyS!I3:I29,CyS!I35:I61,CyS!I67:I93,CyS!I99:I125,CyS!I131:I157,CyS!I163:I189,CyS!I195:I221,CyS!I227:I253)) -> 1.9298497 | K20: =K11*(SUM(CyS!J131:J157)/SUM(CyS!J3:J29,CyS!J35:J61,CyS!J67:J93,CyS!J99:J125,CyS!J131:J157,CyS!J163:J189,CyS!J195:J221,CyS!J227:J253)) -> 2.0563663 | L20: =L11*(SUM(CyS!K131:K157)/SUM(CyS!K3:K29,CyS!K35:K61,CyS!K67:K93,CyS!K99:K125,CyS!K131:K157,CyS!K163:K189,CyS!K195:K221,CyS!K227:K253)) -> 2.06 | M20: =M11*(SUM(CyS!K131:K157)/SUM(CyS!K3:K29,CyS!K35:K61,CyS!K67:K93,CyS!K99:K125,CyS!K131:K157,CyS!K163:K189,CyS!K195:K221,CyS!K227:K253)) -> 2.1882753 | N20: =N11*(SUM(CyS!K131:K157)/SUM(CyS!K3:K29,CyS!K35:K61,CyS!K67:K93,CyS!K99:K125,CyS!K131:K157,CyS!K163:K189,CyS!K195:K221,CyS!K227:K253)) -> 2.1400197
C21: Otros | D21: =D11*(SUM(CyS!C163:C189)/SUM(CyS!C3:C29,CyS!C35:C61,CyS!C67:C93,CyS!C99:C125,CyS!C131:C157,CyS!C163:C189,CyS!C195:C221,CyS!C227:C253)) -> 2.7827155 | E21: =E11*(SUM(CyS!D163:D189)/SUM(CyS!D3:D29,CyS!D35:D61,CyS!D67:D93,CyS!D99:D125,CyS!D131:D157,CyS!D163:D189,CyS!D195:D221,CyS!D227:D253)) -> 2.883107 | F21: =F11*(SUM(CyS!E163:E189)/SUM(CyS!E3:E29,CyS!E35:E61,CyS!E67:E93,CyS!E99:E125,CyS!E131:E157,CyS!E163:E189,CyS!E195:E221,CyS!E227:E253)) -> 2.9747098 | G21: =G11*(SUM(CyS!F163:F189)/SUM(CyS!F3:F29,CyS!F35:F61,CyS!F67:F93,CyS!F99:F125,CyS!F131:F157,CyS!F163:F189,CyS!F195:F221,CyS!F227:F253)) -> 3.1193424 | H21: =H11*(SUM(CyS!G163:G189)/SUM(CyS!G3:G29,CyS!G35:G61,CyS!G67:G93,CyS!G99:G125,CyS!G131:G157,CyS!G163:G189,CyS!G195:G221,CyS!G227:G253)) -> 3.0956627 | I21: =I11*(SUM(CyS!H163:H189)/SUM(CyS!H3:H29,CyS!H35:H61,CyS!H67:H93,CyS!H99:H125,CyS!H131:H157,CyS!H163:H189,CyS!H195:H221,CyS!H227:H253)) -> 2.9987801 | J21: =J11*(SUM(CyS!I163:I189)/SUM(CyS!I3:I29,CyS!I35:I61,CyS!I67:I93,CyS!I99:I125,CyS!I131:I157,CyS!I163:I189,CyS!I195:I221,CyS!I227:I253)) -> 3.0738327 | K21: =K11*(SUM(CyS!J163:J189)/SUM(CyS!J3:J29,CyS!J35:J61,CyS!J67:J93,CyS!J99:J125,CyS!J131:J157,CyS!J163:J189,CyS!J195:J221,CyS!J227:J253)) -> 3.2704975 | L21: =L11*(SUM(CyS!K163:K189)/SUM(CyS!K3:K29,CyS!K35:K61,CyS!K67:K93,CyS!K99:K125,CyS!K131:K157,CyS!K163:K189,CyS!K195:K221,CyS!K227:K253)) -> 3.27 | M21: =M11*(SUM(CyS!K163:K189)/SUM(CyS!K3:K29,CyS!K35:K61,CyS!K67:K93,CyS!K99:K125,CyS!K131:K157,CyS!K163:K189,CyS!K195:K221,CyS!K227:K253)) -> 3.4736215 | N21: =N11*(SUM(CyS!K163:K189)/SUM(CyS!K3:K29,CyS!K35:K61,CyS!K67:K93,CyS!K99:K125,CyS!K131:K157,CyS!K163:K189,CyS!K195:K221,CyS!K227:K253)) -> 3.3970216
C22: Calentamiento de agua | D22: =D11*(SUM(CyS!C195:C221)/SUM(CyS!C3:C29,CyS!C35:C61,CyS!C67:C93,CyS!C99:C125,CyS!C131:C157,CyS!C163:C189,CyS!C195:C221,CyS!C227:C253)) -> 32.241463 | E22: =E11*(SUM(CyS!D195:D221)/SUM(CyS!D3:D29,CyS!D35:D61,CyS!D67:D93,CyS!D99:D125,CyS!D131:D157,CyS!D163:D189,CyS!D195:D221,CyS!D227:D253)) -> 32.444964 | F22: =F11*(SUM(CyS!E195:E221)/SUM(CyS!E3:E29,CyS!E35:E61,CyS!E67:E93,CyS!E99:E125,CyS!E131:E157,CyS!E163:E189,CyS!E195:E221,CyS!E227:E253)) -> 32.812255 | G22: =G11*(SUM(CyS!F195:F221)/SUM(CyS!F3:F29,CyS!F35:F61,CyS!F67:F93,CyS!F99:F125,CyS!F131:F157,CyS!F163:F189,CyS!F195:F221,CyS!F227:F253)) -> 33.427409 | H22: =H11*(SUM(CyS!G195:G221)/SUM(CyS!G3:G29,CyS!G35:G61,CyS!G67:G93,CyS!G99:G125,CyS!G131:G157,CyS!G163:G189,CyS!G195:G221,CyS!G227:G253)) -> 32.920219 | I22: =I11*(SUM(CyS!H195:H221)/SUM(CyS!H3:H29,CyS!H35:H61,CyS!H67:H93,CyS!H99:H125,CyS!H131:H157,CyS!H163:H189,CyS!H195:H221,CyS!H227:H253)) -> 33.504643 | J22: =J11*(SUM(CyS!I195:I221)/SUM(CyS!I3:I29,CyS!I35:I61,CyS!I67:I93,CyS!I99:I125,CyS!I131:I157,CyS!I163:I189,CyS!I195:I221,CyS!I227:I253)) -> 33.344619 | K22: =K11*(SUM(CyS!J195:J221)/SUM(CyS!J3:J29,CyS!J35:J61,CyS!J67:J93,CyS!J99:J125,CyS!J131:J157,CyS!J163:J189,CyS!J195:J221,CyS!J227:J253)) -> 36.719265 | L22: =L11*(SUM(CyS!K195:K221)/SUM(CyS!K3:K29,CyS!K35:K61,CyS!K67:K93,CyS!K99:K125,CyS!K131:K157,CyS!K163:K189,CyS!K195:K221,CyS!K227:K253)) -> 34.74 | M22: =M11*(SUM(CyS!K195:K221)/SUM(CyS!K3:K29,CyS!K35:K61,CyS!K67:K93,CyS!K99:K125,CyS!K131:K157,CyS!K163:K189,CyS!K195:K221,CyS!K227:K253)) -> 36.903245 | N22: =N11*(SUM(CyS!K195:K221)/SUM(CyS!K3:K29,CyS!K35:K61,CyS!K67:K93,CyS!K99:K125,CyS!K131:K157,CyS!K163:K189,CyS!K195:K221,CyS!K227:K253)) -> 36.089459
