Workbook

Sheet About
A1: SoEDtICoS Share of Electricity Demand that Is Cost of Service
A3: Using 1 for all values for MX
A7: Source: | B7: Load by IPM Region
B8: https://www.epa.gov/sites/default/files/2018-05/documents/epa_platform_v6_documentation_-_chapter_3.pdf
B9: EPA
B10: 2018
B11: Power System Operation Assumptions
B12: Table 3-3
B14: Load by NEMS Region
B15: https://www.eia.gov/outlooks/aeo/tables_ref.php
B16: EIA
B17: 2025
B18: Annual Energy Outlook 2025
B19: Tables 54.1-54.25, Total Net Energy for Load entries
B21: Mapping of NEMS Regions with IPM Regions
B22: https://www.epa.gov/system/files/documents/2021-09/chapter-3-power-system-operation-assumptions.pdf
B23: EPA
B24: 2021
B25: Power System Operation Assumptions
B26: Table 3-1
B28: Deregulation and Cost-of-Service Shares by Region
B29: ICF
B30: 2019
B31: Documentation of the Retail Price Model
B32: https://www.epa.gov/sites/default/files/2019-06/documents/rpm_documentation_june2019.pdf
B33: Attachment 1
A36: Notes:
A37: This EPS calculates both cost of service (costs of generation, construction costs, T&D, etc.)
A38: and capacity market costs. This variable serves as a multiplier so that the total electricity
A39: rates are the sum of costs of service * the share of demand that is cost of service and
A40: capacity market costs * (1 - the share of demand that is cost of service).

Sheet NEMS Net Load
A1: abbreviation | B1: region | C1: 2024 | D1: 2025 | E1: 2026 | F1: 2027 | G1: 2028 | H1: 2029 | I1: 2030 | J1: 2031 | K1: 2032 | L1: 2033 | M1: 2034 | N1: 2035 | O1: 2036 | P1: 2037 | Q1: 2038 | R1: 2039 | S1: 2040 | T1: 2041 | U1: 2042 | V1: 2043 | W1: 2044 | X1: 2045 | Y1: 2046 | Z1: 2047 | AA1: 2048 | AB1: 2049 | AC1: 2050
A2: TRE | B2: Texas Reliability Entity | C2: 421.218 | D2: 431.137 | E2: 434.171 | F2: 439.011 | G2: 442.993 | H2: 447.452 | I2: 451.612 | J2: 456.288 | K2: 463.356 | L2: 471.046 | M2: 480.03 | N2: 490.3 | O2: 501.54 | P2: 513.328 | Q2: 523.674 | R2: 533.448 | S2: 541.92 | T2: 549.592 | U2: 557.095 | V2: 564.723 | W2: 571.442 | X2: 577.883 | Y2: 583.343 | Z2: 589.175 | AA2: 595.586 | AB2: 602.505 | AC2: 610.927
A3: FRCC | B3: Florida Reliability Coordinating Council | C3: 260.716 | D3: 261.831 | E3: 263.087 | F3: 266.489 | G3: 269.2 | H3: 272.809 | I3: 276.093 | J3: 279.488 | K3: 283.539 | L3: 287.547 | M3: 291.732 | N3: 296.332 | O3: 303.691 | P3: 309.353 | Q3: 315.111 | R3: 321.12 | S3: 326.774 | T3: 332.151 | U3: 336.716 | V3: 341.193 | W3: 345.307 | X3: 349.492 | Y3: 352.298 | Z3: 356.419 | AA3: 360.825 | AB3: 364.631 | AC3: 369.357
A4: MISW | B4: Midcontinent ISO / West | C4: 220.864 | D4: 225.18 | E4: 223.97 | F4: 225.653 | G4: 226.792 | H4: 228.823 | I4: 231.084 | J4: 233.588 | K4: 237.315 | L4: 241.395 | M4: 246.657 | N4: 252.136 | O4: 257.436 | P4: 262.219 | Q4: 266.893 | R4: 271.53 | S4: 275.977 | T4: 280.074 | U4: 284.079 | V4: 287.871 | W4: 291.454 | X4: 294.723 | Y4: 297.928 | Z4: 301.419 | AA4: 304.936 | AB4: 308.487 | AC4: 311.768
A5: MISC | B5: Midcontinent ISO / Central | C5: 200.588 | D5: 204.438 | E5: 205.6 | F5: 207.476 | G5: 208.797 | H5: 210.602 | I5: 212.544 | J5: 214.731 | K5: 218.045 | L5: 221.587 | M5: 226.062 | N5: 230.805 | O5: 235.558 | P5: 239.901 | Q5: 244.14 | R5: 248.413 | S5: 252.538 | T5: 256.291 | U5: 259.885 | V5: 263.283 | W5: 266.464 | X5: 269.346 | Y5: 272.14 | Z5: 275.136 | AA5: 278.133 | AB5: 281.119 | AC5: 284.084
A6: MISE | B6: Midcontinent ISO / East | C6: 100.369 | D6: 102.401 | E6: 103.152 | F6: 104.353 | G6: 105.279 | H6: 106.338 | I6: 107.38 | J6: 108.512 | K6: 110.297 | L6: 112.108 | M6: 114.368 | N6: 116.768 | O6: 119.261 | P6: 121.521 | Q6: 123.747 | R6: 126.056 | S6: 128.285 | T6: 130.319 | U6: 132.215 | V6: 134.008 | W6: 135.705 | X6: 137.273 | Y6: 138.809 | Z6: 140.398 | AA6: 141.927 | AB6: 143.416 | AC6: 144.916
A7: MISS | B7: Midcontinent ISO / South | C7: 192.521 | D7: 196.597 | E7: 198.738 | F7: 200.869 | G7: 202.601 | H7: 204.421 | I7: 206.191 | J7: 208.275 | K7: 211.326 | L7: 214.67 | M7: 218.694 | N7: 223.165 | O7: 227.935 | P7: 232.846 | Q7: 237.146 | R7: 241.293 | S7: 244.916 | T7: 248.139 | U7: 251.291 | V7: 254.477 | W7: 257.096 | X7: 259.636 | Y7: 261.752 | Z7: 264.142 | AA7: 266.9 | AB7: 269.842 | AC7: 273.374
A8: ISNE | B8: Northeast Power Coordinating Council / New England | C8: 118.18 | D8: 117.346 | E8: 115.727 | F8: 117.669 | G8: 119.566 | H8: 121.781 | I8: 123.665 | J8: 125.618 | K8: 127.579 | L8: 129.349 | M8: 131.415 | N8: 134.165 | O8: 137.124 | P8: 139.922 | Q8: 142.742 | R8: 145.586 | S8: 148.301 | T8: 150.788 | U8: 153.031 | V8: 155.197 | W8: 157.321 | X8: 158.919 | Y8: 160.591 | Z8: 162.265 | AA8: 163.941 | AB8: 165.597 | AC8: 167.262
A9: NYCW | B9: Northeast Power Coordinating Council / NYC & Long Island | C9: 71.104 | D9: 72.099 | E9: 71.933 | F9: 73.206 | G9: 74.32 | H9: 75.701 | I9: 76.854 | J9: 78.017 | K9: 79.582 | L9: 81.026 | M9: 82.727 | N9: 84.572 | O9: 86.538 | P9: 88.48 | Q9: 90.439 | R9: 92.487 | S9: 94.403 | T9: 96.144 | U9: 97.777 | V9: 99.349 | W9: 100.936 | X9: 102.451 | Y9: 103.976 | Z9: 105.484 | AA9: 107.004 | AB9: 108.504 | AC9: 110.102
A10: NYUP | B10: Northeast Power Coordinating Council / Upstate New York | C10: 80.086 | D10: 81.22 | E10: 81.264 | F10: 82.392 | G10: 83.243 | H10: 84.403 | I10: 85.503 | J10: 86.607 | K10: 88.11 | L10: 89.519 | M10: 91.236 | N10: 93.098 | O10: 95.082 | P10: 96.953 | Q10: 98.836 | R10: 100.824 | S10: 102.641 | T10: 104.269 | U10: 105.73 | V10: 107.089 | W10: 108.41 | X10: 109.711 | Y10: 110.96 | Z10: 112.261 | AA10: 113.595 | AB10: 114.911 | AC10: 116.28
A11: PJME | B11: PJM / East | C11: 275.612 | D11: 278.865 | E11: 279.127 | F11: 282.772 | G11: 285.51 | H11: 289.381 | I11: 293.038 | J11: 296.77 | K11: 301.637 | L11: 306.254 | M11: 311.674 | N11: 317.54 | O11: 323.953 | P11: 330.121 | Q11: 336.48 | R11: 343.062 | S11: 349.116 | T11: 354.616 | U11: 359.547 | V11: 364.12 | W11: 368.52 | X11: 372.806 | Y11: 376.901 | Z11: 381.25 | AA11: 385.788 | AB11: 390.346 | AC11: 395.113
A12: PJMW | B12: PJM / West | C12: 317.012 | D12: 322.44 | E12: 325.076 | F12: 328.551 | G12: 331.018 | H12: 334.097 | I12: 337.351 | J12: 340.916 | K12: 346.118 | L12: 351.446 | M12: 358.009 | N12: 364.932 | O12: 372.069 | P12: 378.734 | Q12: 385.298 | R12: 392.024 | S12: 398.415 | T12: 404.152 | U12: 409.473 | V12: 414.411 | W12: 418.916 | X12: 423.124 | Y12: 427.159 | Z12: 431.495 | AA12: 435.97 | AB12: 440.472 | AC12: 445.132
... A26: BASN | B26: Western Electricity Coordinating Council / Basin | C26: 115.935 | D26: 116.947 | E26: 118.036 | F26: 119.814 | G26: 121.434 | H26: 123.778 | I26: 126.404 | J26: 129.382 | K26: 133.094 | L26: 137.339 | M26: 142.315 | N26: 147.394 | O26: 152.051 | P26: 156.399 | Q26: 160.779 | R26: 165.017 | S26: 169.331 | T26: 173.496 | U26: 177.385 | V26: 180.986 | W26: 184.351 | X26: 187.855 | Y26: 191.234 | Z26: 194.725 | AA26: 198.264 | AB26: 202.046 | AC26: 205.856

Sheet IPM Load
A1: IPM | B1: Region
A2: Net | B2: Energy | C2: for | D2: Load | E2: (Billions | F2: of | G2: kWh)
B3: 2021 | C3: 2023 | D3: 2025 | E3: 2030 | F3: 2035 | G3: 2040 | H3: 2045 | I3: 2050
A4: ERC_FRNT | B4: 0 | C4: 0 | D4: 0 | E4: 0 | F4: 0 | G4: 0 | H4: 0 | I4: 0
A5: ERC_GWAY | B5: 0 | C5: 0 | D5: 0 | E5: 0 | F5: 0 | G5: 0 | H5: 0 | I5: 0
A6: ERC_PHDL | B6: 0 | C6: 0 | D6: 0 | E6: 0 | F6: 0 | G6: 0 | H6: 0 | I6: 0
A7: ERC_REST | B7: 347 | C7: 357 | D7: 367 | E7: 386 | F7: 403 | G7: 424 | H7: 444 | I7: 461
A8: ERC_WEST | B8: 28 | C8: 28 | D8: 29 | E8: 31 | F8: 32 | G8: 34 | H8: 35 | I8: 37
A9: FRCC | B9: 231 | C9: 236 | D9: 242 | E9: 254 | F9: 265 | G9: 278 | H9: 290 | I9: 304
A10: MIS_AMSO | B10: 31 | C10: 32 | D10: 33 | E10: 34 | F10: 36 | G10: 37 | H10: 39 | I10: 40
A11: MIS_AR | B11: 36 | C11: 38 | D11: 39 | E11: 40 | F11: 42 | G11: 44 | H11: 46 | I11: 48
A12: MIS_D_MS | B12: 22 | C12: 23 | D12: 23 | E12: 24 | F12: 25 | G12: 26 | H12: 27 | I12: 28
A13: MIS_IA | B13: 22 | C13: 22 | D13: 23 | E13: 23 | F13: 24 | G13: 25 | H13: 26 | I13: 27
A14: MIS_IL | B14: 48 | C14: 49 | D14: 49 | E14: 51 | F14: 52 | G14: 54 | H14: 56 | I14: 58
A15: MIS_INKY | B15: 97 | C15: 99 | D15: 100 | E15: 103 | F15: 105 | G15: 108 | H15: 112 | I15: 116
... A70: WECC_WY | B70: 17 | C70: 17 | D70: 18 | E70: 18 | F70: 18 | G70: 19 | H70: 20 | I70: 20

Sheet Cost-of-Service Shares
F1: Load Projections | N1: Cost-of-Service Share Weights | Z1: IPMM Aggregated Load | AJ1: IPPM Aggregated Cost-of-Service Share | AS1: Time Series
A2: IPM Region | B2: NEMS Region | D2: Deregulation Share | E2: Cost-of-Service Share | F2: 2021 | G2: 2023 | H2: 2025 | I2: 2030 | J2: 2035 | K2: 2040 | L2: 2045 | M2: 2050 | N2: 2021 | O2: 2023 | P2: 2025 | Q2: 2030 | R2: 2035 | S2: 2040 | T2: 2045 | U2: 2050 | Z2: 2021 | AA2: 2023 | AB2: 2025 | AC2: 2030 | AD2: 2035 | AE2: 2040 | AF2: 2045 | AG2: 2050 | AJ2: 2021 | AK2: 2023 | AL2: 2025 | AM2: 2030 | AN2: 2035 | AO2: 2040 | AP2: 2045 | AQ2: 2050 | AS2: 2021 | AT2: 2022 | AU2: 2023 | AV2: 2024 | AW2: 2025 | AX2: 2026 | AY2: 2027 | AZ2: 2028 | BA2: 2029 | BB2: 2030 | BC2: 2031 | BD2: 2032 | BE2: 2033 | BF2: 2034 | BG2: 2035 | BH2: 2036 | BI2: 2037 | BJ2: 2038 | BK2: 2039 | BL2: 2040 | BM2: 2041 | BN2: 2042 | BO2: 2043 | BP2: 2044 | BQ2: 2045 | BR2: 2046 | BS2: 2047 | BT2: 2048 | BU2: 2049 | BV2: 2050
A3: ERC_PHDL | B3: TRE | D3: 0.88 | E3: 0.12 | F3: =INDEX('IPM Load'!B:B,MATCH('Cost-of-Service Shares'!$A3,'IPM Load'!$A:$A,0)) -> 0 | G3: =INDEX('IPM Load'!C:C,MATCH('Cost-of-Service Shares'!$A3,'IPM Load'!$A:$A,0)) -> 0 | H3: =INDEX('IPM Load'!D:D,MATCH('Cost-of-Service Shares'!$A3,'IPM Load'!$A:$A,0)) -> 0 | I3: =INDEX('IPM Load'!E:E,MATCH('Cost-of-Service Shares'!$A3,'IPM Load'!$A:$A,0)) -> 0 | J3: =INDEX('IPM Load'!F:F,MATCH('Cost-of-Service Shares'!$A3,'IPM Load'!$A:$A,0)) -> 0 | K3: =INDEX('IPM Load'!G:G,MATCH('Cost-of-Service Shares'!$A3,'IPM Load'!$A:$A,0)) -> 0 | L3: =INDEX('IPM Load'!H:H,MATCH('Cost-of-Service Shares'!$A3,'IPM Load'!$A:$A,0)) -> 0 | M3: =INDEX('IPM Load'!I:I,MATCH('Cost-of-Service Shares'!$A3,'IPM Load'!$A:$A,0)) -> 0 | N3: =$E3*F3/INDEX(Z$3:Z$27,MATCH($B3,$Y$3:$Y$27,0)) -> 0 | O3: =$E3*G3/INDEX(AA$3:AA$27,MATCH($B3,$Y$3:$Y$27,0)) -> 0 | P3: =$E3*H3/INDEX(AB$3:AB$27,MATCH($B3,$Y$3:$Y$27,0)) -> 0 | Q3: =$E3*I3/INDEX(AC$3:AC$27,MATCH($B3,$Y$3:$Y$27,0)) -> 0 | R3: =$E3*J3/INDEX(AD$3:AD$27,MATCH($B3,$Y$3:$Y$27,0)) -> 0 | S3: =$E3*K3/INDEX(AE$3:AE$27,MATCH($B3,$Y$3:$Y$27,0)) -> 0 | T3: =$E3*L3/INDEX(AF$3:AF$27,MATCH($B3,$Y$3:$Y$27,0)) -> 0 | U3: =$E3*M3/INDEX(AG$3:AG$27,MATCH($B3,$Y$3:$Y$27,0)) -> 0 | Y3: TRE | Z3: =SUMIFS(F$3:F$68,$B$3:$B$68,$Y3) -> 375 | AA3: =SUMIFS(G$3:G$68,$B$3:$B$68,$Y3) -> 385 | AB3: =SUMIFS(H$3:H$68,$B$3:$B$68,$Y3) -> 396 | AC3: =SUMIFS(I$3:I$68,$B$3:$B$68,$Y3) -> 417 | AD3: =SUMIFS(J$3:J$68,$B$3:$B$68,$Y3) -> 435 | AE3: =SUMIFS(K$3:K$68,$B$3:$B$68,$Y3) -> 458 | AF3: =SUMIFS(L$3:L$68,$B$3:$B$68,$Y3) -> 479 | AG3: =SUMIFS(M$3:M$68,$B$3:$B$68,$Y3) -> 498 | AI3: TRE | AJ3: =SUMIFS(N$3:N$68,$B$3:$B$68,$AI3) -> 0.12 | AK3: =SUMIFS(O$3:O$68,$B$3:$B$68,$AI3) -> 0.12 | AL3: =SUMIFS(P$3:P$68,$B$3:$B$68,$AI3) -> 0.12 | AM3: =SUMIFS(Q$3:Q$68,$B$3:$B$68,$AI3) -> 0.12 | AN3: =SUMIFS(R$3:R$68,$B$3:$B$68,$AI3) -> 0.12 | AO3: =SUMIFS(S$3:S$68,$B$3:$B$68,$AI3) -> 0.12 | AP3: =SUMIFS(T$3:T$68,$B$3:$B$68,$AI3) -> 0.12 | AQ3: =SUMIFS(U$3:U$68,$B$3:$B$68,$AI3) -> 0.12 | AS3: {=TREND($AJ3:$AQ3,$AJ$2:$AQ$2,AS$2)} -> 0.12 | AT3: {=TREND($AJ3:$AQ3,$AJ$2:$AQ$2,AT$2)} -> 0.12 | AU3: {=TREND($AJ3:$AQ3,$AJ$2:$AQ$2,AU$2)} -> 0.12 | AV3: {=TREND($AJ3:$AQ3,$AJ$2:$AQ$2,AV$2)} -> 0.12 | AW3: {=TREND($AJ3:$AQ3,$AJ$2:$AQ$2,AW$2)} -> 0.12 | AX3: {=TREND($AJ3:$AQ3,$AJ$2:$AQ$2,AX$2)} -> 0.12 | AY3: {=TREND($AJ3:$AQ3,$AJ$2:$AQ$2,AY$2)} -> 0.12 | AZ3: {=TREND($AJ3:$AQ3,$AJ$2:$AQ$2,AZ$2)} -> 0.12 | ... BV3: {=TREND($AJ3:$AQ3,$AJ$2:$AQ$2,BV$2)} -> 0.12
A4: ERC_REST | B4: TRE | D4: 0.88 | E4: 0.12 | F4: =INDEX('IPM Load'!B:B,MATCH('Cost-of-Service Shares'!$A4,'IPM Load'!$A:$A,0)) -> 347 | G4: =INDEX('IPM Load'!C:C,MATCH('Cost-of-Service Shares'!$A4,'IPM Load'!$A:$A,0)) -> 357 | H4: =INDEX('IPM Load'!D:D,MATCH('Cost-of-Service Shares'!$A4,'IPM Load'!$A:$A,0)) -> 367 | I4: =INDEX('IPM Load'!E:E,MATCH('Cost-of-Service Shares'!$A4,'IPM Load'!$A:$A,0)) -> 386 | J4: =INDEX('IPM Load'!F:F,MATCH('Cost-of-Service Shares'!$A4,'IPM Load'!$A:$A,0)) -> 403 | K4: =INDEX('IPM Load'!G:G,MATCH('Cost-of-Service Shares'!$A4,'IPM Load'!$A:$A,0)) -> 424 | L4: =INDEX('IPM Load'!H:H,MATCH('Cost-of-Service Shares'!$A4,'IPM Load'!$A:$A,0)) -> 444 | M4: =INDEX('IPM Load'!I:I,MATCH('Cost-of-Service Shares'!$A4,'IPM Load'!$A:$A,0)) -> 461 | N4: =$E4*F4/INDEX(Z$3:Z$27,MATCH($B4,$Y$3:$Y$27,0)) -> 0.11104 | O4: =$E4*G4/INDEX(AA$3:AA$27,MATCH($B4,$Y$3:$Y$27,0)) -> 0.11127273 | P4: =$E4*H4/INDEX(AB$3:AB$27,MATCH($B4,$Y$3:$Y$27,0)) -> 0.11121212 | Q4: =$E4*I4/INDEX(AC$3:AC$27,MATCH($B4,$Y$3:$Y$27,0)) -> 0.11107914 | R4: =$E4*J4/INDEX(AD$3:AD$27,MATCH($B4,$Y$3:$Y$27,0)) -> 0.11117241 | S4: =$E4*K4/INDEX(AE$3:AE$27,MATCH($B4,$Y$3:$Y$27,0)) -> 0.1110917 | T4: =$E4*L4/INDEX(AF$3:AF$27,MATCH($B4,$Y$3:$Y$27,0)) -> 0.11123173 | U4: =$E4*M4/INDEX(AG$3:AG$27,MATCH($B4,$Y$3:$Y$27,0)) -> 0.11108434 | Y4: FRCC | Z4: =SUMIFS(F$3:F$68,$B$3:$B$68,$Y4) -> 231 | AA4: =SUMIFS(G$3:G$68,$B$3:$B$68,$Y4) -> 236 | AB4: =SUMIFS(H$3:H$68,$B$3:$B$68,$Y4) -> 242 | AC4: =SUMIFS(I$3:I$68,$B$3:$B$68,$Y4) -> 254 | AD4: =SUMIFS(J$3:J$68,$B$3:$B$68,$Y4) -> 265 | AE4: =SUMIFS(K$3:K$68,$B$3:$B$68,$Y4) -> 278 | AF4: =SUMIFS(L$3:L$68,$B$3:$B$68,$Y4) -> 290 | AG4: =SUMIFS(M$3:M$68,$B$3:$B$68,$Y4) -> 304 | AI4: FRCC | AJ4: =SUMIFS(N$3:N$68,$B$3:$B$68,$AI4) -> 1 | AK4: =SUMIFS(O$3:O$68,$B$3:$B$68,$AI4) -> 1 | AL4: =SUMIFS(P$3:P$68,$B$3:$B$68,$AI4) -> 1 | AM4: =SUMIFS(Q$3:Q$68,$B$3:$B$68,$AI4) -> 1 | AN4: =SUMIFS(R$3:R$68,$B$3:$B$68,$AI4) -> 1 | AO4: =SUMIFS(S$3:S$68,$B$3:$B$68,$AI4) -> 1 | AP4: =SUMIFS(T$3:T$68,$B$3:$B$68,$AI4) -> 1 | AQ4: =SUMIFS(U$3:U$68,$B$3:$B$68,$AI4) -> 1 | AS4: {=TREND($AJ4:$AQ4,$AJ$2:$AQ$2,AS$2)} -> 1 | AT4: {=TREND($AJ4:$AQ4,$AJ$2:$AQ$2,AT$2)} -> 1 | AU4: {=TREND($AJ4:$AQ4,$AJ$2:$AQ$2,AU$2)} -> 1 | AV4: {=TREND($AJ4:$AQ4,$AJ$2:$AQ$2,AV$2)} -> 1 | AW4: {=TREND($AJ4:$AQ4,$AJ$2:$AQ$2,AW$2)} -> 1 | AX4: {=TREND($AJ4:$AQ4,$AJ$2:$AQ$2,AX$2)} -> 1 | AY4: {=TREND($AJ4:$AQ4,$AJ$2:$AQ$2,AY$2)} -> 1 | AZ4: {=TREND($AJ4:$AQ4,$AJ$2:$AQ$2,AZ$2)} -> 1 | ... BV4: {=TREND($AJ4:$AQ4,$AJ$2:$AQ$2,BV$2)} -> 1
A5: ERC_WEST | B5: TRE | D5: 0.88 | E5: 0.12 | F5: =INDEX('IPM Load'!B:B,MATCH('Cost-of-Service Shares'!$A5,'IPM Load'!$A:$A,0)) -> 28 | G5: =INDEX('IPM Load'!C:C,MATCH('Cost-of-Service Shares'!$A5,'IPM Load'!$A:$A,0)) -> 28 | H5: =INDEX('IPM Load'!D:D,MATCH('Cost-of-Service Shares'!$A5,'IPM Load'!$A:$A,0)) -> 29 | I5: =INDEX('IPM Load'!E:E,MATCH('Cost-of-Service Shares'!$A5,'IPM Load'!$A:$A,0)) -> 31 | J5: =INDEX('IPM Load'!F:F,MATCH('Cost-of-Service Shares'!$A5,'IPM Load'!$A:$A,0)) -> 32 | K5: =INDEX('IPM Load'!G:G,MATCH('Cost-of-Service Shares'!$A5,'IPM Load'!$A:$A,0)) -> 34 | L5: =INDEX('IPM Load'!H:H,MATCH('Cost-of-Service Shares'!$A5,'IPM Load'!$A:$A,0)) -> 35 | M5: =INDEX('IPM Load'!I:I,MATCH('Cost-of-Service Shares'!$A5,'IPM Load'!$A:$A,0)) -> 37 | N5: =$E5*F5/INDEX(Z$3:Z$27,MATCH($B5,$Y$3:$Y$27,0)) -> 0.00896 | O5: =$E5*G5/INDEX(AA$3:AA$27,MATCH($B5,$Y$3:$Y$27,0)) -> 0.0087272727 | P5: =$E5*H5/INDEX(AB$3:AB$27,MATCH($B5,$Y$3:$Y$27,0)) -> 0.0087878788 | Q5: =$E5*I5/INDEX(AC$3:AC$27,MATCH($B5,$Y$3:$Y$27,0)) -> 0.0089208633 | R5: =$E5*J5/INDEX(AD$3:AD$27,MATCH($B5,$Y$3:$Y$27,0)) -> 0.0088275862 | S5: =$E5*K5/INDEX(AE$3:AE$27,MATCH($B5,$Y$3:$Y$27,0)) -> 0.0089082969 | T5: =$E5*L5/INDEX(AF$3:AF$27,MATCH($B5,$Y$3:$Y$27,0)) -> 0.0087682672 | U5: =$E5*M5/INDEX(AG$3:AG$27,MATCH($B5,$Y$3:$Y$27,0)) -> 0.0089156627 | Y5: MISW | Z5: =SUMIFS(F$3:F$68,$B$3:$B$68,$Y5) -> 203.26707 | AA5: =SUMIFS(G$3:G$68,$B$3:$B$68,$Y5) -> 208.05045 | AB5: =SUMIFS(H$3:H$68,$B$3:$B$68,$Y5) -> 210.05045 | AC5: =SUMIFS(I$3:I$68,$B$3:$B$68,$Y5) -> 216.05045 | AD5: =SUMIFS(J$3:J$68,$B$3:$B$68,$Y5) -> 222.05045 | AE5: =SUMIFS(K$3:K$68,$B$3:$B$68,$Y5) -> 229.83383 | AF5: =SUMIFS(L$3:L$68,$B$3:$B$68,$Y5) -> 237.83383 | AG5: =SUMIFS(M$3:M$68,$B$3:$B$68,$Y5) -> 246.83383 | AI5: MISW | AJ5: =SUMIFS(N$3:N$68,$B$3:$B$68,$AI5) -> 0.83306361 | AK5: =SUMIFS(O$3:O$68,$B$3:$B$68,$AI5) -> 0.83388402 | AL5: =SUMIFS(P$3:P$68,$B$3:$B$68,$AI5) -> 0.83537048 | AM5: =SUMIFS(Q$3:Q$68,$B$3:$B$68,$AI5) -> 0.83429563 | AN5: =SUMIFS(R$3:R$68,$B$3:$B$68,$AI5) -> 0.83589088 | AO5: =SUMIFS(S$3:S$68,$B$3:$B$68,$AI5) -> 0.8360627 | AP5: =SUMIFS(T$3:T$68,$B$3:$B$68,$AI5) -> 0.83636332 | AQ5: =SUMIFS(U$3:U$68,$B$3:$B$68,$AI5) -> 0.83726567 | AS5: {=TREND($AJ5:$AQ5,$AJ$2:$AQ$2,AS$2)} -> 0.83375504 | AT5: {=TREND($AJ5:$AQ5,$AJ$2:$AQ$2,AT$2)} -> 0.8338754 | AU5: {=TREND($AJ5:$AQ5,$AJ$2:$AQ$2,AU$2)} -> 0.83399575 | AV5: {=TREND($AJ5:$AQ5,$AJ$2:$AQ$2,AV$2)} -> 0.83411611 | AW5: {=TREND($AJ5:$AQ5,$AJ$2:$AQ$2,AW$2)} -> 0.83423647 | AX5: {=TREND($AJ5:$AQ5,$AJ$2:$AQ$2,AX$2)} -> 0.83435682 | AY5: {=TREND($AJ5:$AQ5,$AJ$2:$AQ$2,AY$2)} -> 0.83447718 | AZ5: {=TREND($AJ5:$AQ5,$AJ$2:$AQ$2,AZ$2)} -> 0.83459753 | ... BV5: {=TREND($AJ5:$AQ5,$AJ$2:$AQ$2,BV$2)} -> 0.83724537
A6: FRCC | B6: FRCC | D6: 0 | E6: 1 | F6: =INDEX('IPM Load'!B:B,MATCH('Cost-of-Service Shares'!$A6,'IPM Load'!$A:$A,0)) -> 231 | G6: =INDEX('IPM Load'!C:C,MATCH('Cost-of-Service Shares'!$A6,'IPM Load'!$A:$A,0)) -> 236 | H6: =INDEX('IPM Load'!D:D,MATCH('Cost-of-Service Shares'!$A6,'IPM Load'!$A:$A,0)) -> 242 | I6: =INDEX('IPM Load'!E:E,MATCH('Cost-of-Service Shares'!$A6,'IPM Load'!$A:$A,0)) -> 254 | J6: =INDEX('IPM Load'!F:F,MATCH('Cost-of-Service Shares'!$A6,'IPM Load'!$A:$A,0)) -> 265 | K6: =INDEX('IPM Load'!G:G,MATCH('Cost-of-Service Shares'!$A6,'IPM Load'!$A:$A,0)) -> 278 | L6: =INDEX('IPM Load'!H:H,MATCH('Cost-of-Service Shares'!$A6,'IPM Load'!$A:$A,0)) -> 290 | M6: =INDEX('IPM Load'!I:I,MATCH('Cost-of-Service Shares'!$A6,'IPM Load'!$A:$A,0)) -> 304 | N6: =$E6*F6/INDEX(Z$3:Z$27,MATCH($B6,$Y$3:$Y$27,0)) -> 1 | O6: =$E6*G6/INDEX(AA$3:AA$27,MATCH($B6,$Y$3:$Y$27,0)) -> 1 | P6: =$E6*H6/INDEX(AB$3:AB$27,MATCH($B6,$Y$3:$Y$27,0)) -> 1 | Q6: =$E6*I6/INDEX(AC$3:AC$27,MATCH($B6,$Y$3:$Y$27,0)) -> 1 | R6: =$E6*J6/INDEX(AD$3:AD$27,MATCH($B6,$Y$3:$Y$27,0)) -> 1 | S6: =$E6*K6/INDEX(AE$3:AE$27,MATCH($B6,$Y$3:$Y$27,0)) -> 1 | T6: =$E6*L6/INDEX(AF$3:AF$27,MATCH($B6,$Y$3:$Y$27,0)) -> 1 | U6: =$E6*M6/INDEX(AG$3:AG$27,MATCH($B6,$Y$3:$Y$27,0)) -> 1 | Y6: MISC | Z6: =SUMIFS(F$3:F$68,$B$3:$B$68,$Y6) -> 196.42994 | AA6: =SUMIFS(G$3:G$68,$B$3:$B$68,$Y6) -> 200.00938 | AB6: =SUMIFS(H$3:H$68,$B$3:$B$68,$Y6) -> 202.00938 | AC6: =SUMIFS(I$3:I$68,$B$3:$B$68,$Y6) -> 208.00938 | AD6: =SUMIFS(J$3:J$68,$B$3:$B$68,$Y6) -> 212.58882 | AE6: =SUMIFS(K$3:K$68,$B$3:$B$68,$Y6) -> 220.16826 | AF6: =SUMIFS(L$3:L$68,$B$3:$B$68,$Y6) -> 227.16826 | AG6: =SUMIFS(M$3:M$68,$B$3:$B$68,$Y6) -> 235.7477 | AI6: MISC | AJ6: =SUMIFS(N$3:N$68,$B$3:$B$68,$AI6) -> 0.6678714 | AK6: =SUMIFS(O$3:O$68,$B$3:$B$68,$AI6) -> 0.6674656 | AL6: =SUMIFS(P$3:P$68,$B$3:$B$68,$AI6) -> 0.66739168 | AM6: =SUMIFS(Q$3:Q$68,$B$3:$B$68,$AI6) -> 0.66717847 | AN6: =SUMIFS(R$3:R$68,$B$3:$B$68,$AI6) -> 0.66795055 | AO6: =SUMIFS(S$3:S$68,$B$3:$B$68,$AI6) -> 0.66970716 | AP6: =SUMIFS(T$3:T$68,$B$3:$B$68,$AI6) -> 0.66830754 | AQ6: =SUMIFS(U$3:U$68,$B$3:$B$68,$AI6) -> 0.66884089 | AS6: {=TREND($AJ6:$AQ6,$AJ$2:$AQ$2,AS$2)} -> 0.66740084 | AT6: {=TREND($AJ6:$AQ6,$AJ$2:$AQ$2,AT$2)} -> 0.66745536 | AU6: {=TREND($AJ6:$AQ6,$AJ$2:$AQ$2,AU$2)} -> 0.66750988 | AV6: {=TREND($AJ6:$AQ6,$AJ$2:$AQ$2,AV$2)} -> 0.6675644 | AW6: {=TREND($AJ6:$AQ6,$AJ$2:$AQ$2,AW$2)} -> 0.66761892 | AX6: {=TREND($AJ6:$AQ6,$AJ$2:$AQ$2,AX$2)} -> 0.66767345 | AY6: {=TREND($AJ6:$AQ6,$AJ$2:$AQ$2,AY$2)} -> 0.66772797 | AZ6: {=TREND($AJ6:$AQ6,$AJ$2:$AQ$2,AZ$2)} -> 0.66778249 | ... BV6: {=TREND($AJ6:$AQ6,$AJ$2:$AQ$2,BV$2)} -> 0.66898193
A7: MIS_AMSO | B7: MISS | D7: 0 | E7: 1 | F7: =INDEX('IPM Load'!B:B,MATCH('Cost-of-Service Shares'!$A7,'IPM Load'!$A:$A,0)) -> 31 | G7: =INDEX('IPM Load'!C:C,MATCH('Cost-of-Service Shares'!$A7,'IPM Load'!$A:$A,0)) -> 32 | H7: =INDEX('IPM Load'!D:D,MATCH('Cost-of-Service Shares'!$A7,'IPM Load'!$A:$A,0)) -> 33 | I7: =INDEX('IPM Load'!E:E,MATCH('Cost-of-Service Shares'!$A7,'IPM Load'!$A:$A,0)) -> 34 | J7: =INDEX('IPM Load'!F:F,MATCH('Cost-of-Service Shares'!$A7,'IPM Load'!$A:$A,0)) -> 36 | K7: =INDEX('IPM Load'!G:G,MATCH('Cost-of-Service Shares'!$A7,'IPM Load'!$A:$A,0)) -> 37 | L7: =INDEX('IPM Load'!H:H,MATCH('Cost-of-Service Shares'!$A7,'IPM Load'!$A:$A,0)) -> 39 | M7: =INDEX('IPM Load'!I:I,MATCH('Cost-of-Service Shares'!$A7,'IPM Load'!$A:$A,0)) -> 40 | N7: =$E7*F7/INDEX(Z$3:Z$27,MATCH($B7,$Y$3:$Y$27,0)) -> 0.18562874 | O7: =$E7*G7/INDEX(AA$3:AA$27,MATCH($B7,$Y$3:$Y$27,0)) -> 0.1849711 | P7: =$E7*H7/INDEX(AB$3:AB$27,MATCH($B7,$Y$3:$Y$27,0)) -> 0.18644068 | Q7: =$E7*I7/INDEX(AC$3:AC$27,MATCH($B7,$Y$3:$Y$27,0)) -> 0.18378378 | R7: =$E7*J7/INDEX(AD$3:AD$27,MATCH($B7,$Y$3:$Y$27,0)) -> 0.1865285 | S7: =$E7*K7/INDEX(AE$3:AE$27,MATCH($B7,$Y$3:$Y$27,0)) -> 0.1840796 | T7: =$E7*L7/INDEX(AF$3:AF$27,MATCH($B7,$Y$3:$Y$27,0)) -> 0.18483412 | U7: =$E7*M7/INDEX(AG$3:AG$27,MATCH($B7,$Y$3:$Y$27,0)) -> 0.18348624 | Y7: MISE | Z7: =SUMIFS(F$3:F$68,$B$3:$B$68,$Y7) -> 100 | AA7: =SUMIFS(G$3:G$68,$B$3:$B$68,$Y7) -> 102 | AB7: =SUMIFS(H$3:H$68,$B$3:$B$68,$Y7) -> 103 | AC7: =SUMIFS(I$3:I$68,$B$3:$B$68,$Y7) -> 105 | AD7: =SUMIFS(J$3:J$68,$B$3:$B$68,$Y7) -> 108 | AE7: =SUMIFS(K$3:K$68,$B$3:$B$68,$Y7) -> 111 | AF7: =SUMIFS(L$3:L$68,$B$3:$B$68,$Y7) -> 115 | AG7: =SUMIFS(M$3:M$68,$B$3:$B$68,$Y7) -> 119 | AI7: MISE | AJ7: =SUMIFS(N$3:N$68,$B$3:$B$68,$AI7) -> 0.9 | AK7: =SUMIFS(O$3:O$68,$B$3:$B$68,$AI7) -> 0.9 | AL7: =SUMIFS(P$3:P$68,$B$3:$B$68,$AI7) -> 0.9 | AM7: =SUMIFS(Q$3:Q$68,$B$3:$B$68,$AI7) -> 0.9 | AN7: =SUMIFS(R$3:R$68,$B$3:$B$68,$AI7) -> 0.9 | AO7: =SUMIFS(S$3:S$68,$B$3:$B$68,$AI7) -> 0.9 | AP7: =SUMIFS(T$3:T$68,$B$3:$B$68,$AI7) -> 0.9 | AQ7: =SUMIFS(U$3:U$68,$B$3:$B$68,$AI7) -> 0.9 | AS7: {=TREND($AJ7:$AQ7,$AJ$2:$AQ$2,AS$2)} -> 0.9 | AT7: {=TREND($AJ7:$AQ7,$AJ$2:$AQ$2,AT$2)} -> 0.9 | AU7: {=TREND($AJ7:$AQ7,$AJ$2:$AQ$2,AU$2)} -> 0.9 | AV7: {=TREND($AJ7:$AQ7,$AJ$2:$AQ$2,AV$2)} -> 0.9 | AW7: {=TREND($AJ7:$AQ7,$AJ$2:$AQ$2,AW$2)} -> 0.9 | AX7: {=TREND($AJ7:$AQ7,$AJ$2:$AQ$2,AX$2)} -> 0.9 | AY7: {=TREND($AJ7:$AQ7,$AJ$2:$AQ$2,AY$2)} -> 0.9 | AZ7: {=TREND($AJ7:$AQ7,$AJ$2:$AQ$2,AZ$2)} -> 0.9 | ... BV7: {=TREND($AJ7:$AQ7,$AJ$2:$AQ$2,BV$2)} -> 0.9
A8: MIS_AR | B8: MISS | D8: 0 | E8: 1 | F8: =INDEX('IPM Load'!B:B,MATCH('Cost-of-Service Shares'!$A8,'IPM Load'!$A:$A,0)) -> 36 | G8: =INDEX('IPM Load'!C:C,MATCH('Cost-of-Service Shares'!$A8,'IPM Load'!$A:$A,0)) -> 38 | H8: =INDEX('IPM Load'!D:D,MATCH('Cost-of-Service Shares'!$A8,'IPM Load'!$A:$A,0)) -> 39 | I8: =INDEX('IPM Load'!E:E,MATCH('Cost-of-Service Shares'!$A8,'IPM Load'!$A:$A,0)) -> 40 | J8: =INDEX('IPM Load'!F:F,MATCH('Cost-of-Service Shares'!$A8,'IPM Load'!$A:$A,0)) -> 42 | K8: =INDEX('IPM Load'!G:G,MATCH('Cost-of-Service Shares'!$A8,'IPM Load'!$A:$A,0)) -> 44 | L8: =INDEX('IPM Load'!H:H,MATCH('Cost-of-Service Shares'!$A8,'IPM Load'!$A:$A,0)) -> 46 | M8: =INDEX('IPM Load'!I:I,MATCH('Cost-of-Service Shares'!$A8,'IPM Load'!$A:$A,0)) -> 48 | N8: =$E8*F8/INDEX(Z$3:Z$27,MATCH($B8,$Y$3:$Y$27,0)) -> 0.21556886 | O8: =$E8*G8/INDEX(AA$3:AA$27,MATCH($B8,$Y$3:$Y$27,0)) -> 0.21965318 | P8: =$E8*H8/INDEX(AB$3:AB$27,MATCH($B8,$Y$3:$Y$27,0)) -> 0.22033898 | Q8: =$E8*I8/INDEX(AC$3:AC$27,MATCH($B8,$Y$3:$Y$27,0)) -> 0.21621622 | R8: =$E8*J8/INDEX(AD$3:AD$27,MATCH($B8,$Y$3:$Y$27,0)) -> 0.21761658 | S8: =$E8*K8/INDEX(AE$3:AE$27,MATCH($B8,$Y$3:$Y$27,0)) -> 0.21890547 | T8: =$E8*L8/INDEX(AF$3:AF$27,MATCH($B8,$Y$3:$Y$27,0)) -> 0.21800948 | U8: =$E8*M8/INDEX(AG$3:AG$27,MATCH($B8,$Y$3:$Y$27,0)) -> 0.22018349 | Y8: MISS | Z8: =SUMIFS(F$3:F$68,$B$3:$B$68,$Y8) -> 167 | AA8: =SUMIFS(G$3:G$68,$B$3:$B$68,$Y8) -> 173 | AB8: =SUMIFS(H$3:H$68,$B$3:$B$68,$Y8) -> 177 | AC8: =SUMIFS(I$3:I$68,$B$3:$B$68,$Y8) -> 185 | AD8: =SUMIFS(J$3:J$68,$B$3:$B$68,$Y8) -> 193 | AE8: =SUMIFS(K$3:K$68,$B$3:$B$68,$Y8) -> 201 | AF8: =SUMIFS(L$3:L$68,$B$3:$B$68,$Y8) -> 211 | AG8: =SUMIFS(M$3:M$68,$B$3:$B$68,$Y8) -> 218 | AI8: MISS | AJ8: =SUMIFS(N$3:N$68,$B$3:$B$68,$AI8) -> 1 | AK8: =SUMIFS(O$3:O$68,$B$3:$B$68,$AI8) -> 1 | AL8: =SUMIFS(P$3:P$68,$B$3:$B$68,$AI8) -> 1 | AM8: =SUMIFS(Q$3:Q$68,$B$3:$B$68,$AI8) -> 1 | AN8: =SUMIFS(R$3:R$68,$B$3:$B$68,$AI8) -> 1 | AO8: =SUMIFS(S$3:S$68,$B$3:$B$68,$AI8) -> 1 | AP8: =SUMIFS(T$3:T$68,$B$3:$B$68,$AI8) -> 1 | AQ8: =SUMIFS(U$3:U$68,$B$3:$B$68,$AI8) -> 1 | AS8: {=TREND($AJ8:$AQ8,$AJ$2:$AQ$2,AS$2)} -> 1 | AT8: {=TREND($AJ8:$AQ8,$AJ$2:$AQ$2,AT$2)} -> 1 | AU8: {=TREND($AJ8:$AQ8,$AJ$2:$AQ$2,AU$2)} -> 1 | AV8: {=TREND($AJ8:$AQ8,$AJ$2:$AQ$2,AV$2)} -> 1 | AW8: {=TREND($AJ8:$AQ8,$AJ$2:$AQ$2,AW$2)} -> 1 | AX8: {=TREND($AJ8:$AQ8,$AJ$2:$AQ$2,AX$2)} -> 1 | AY8: {=TREND($AJ8:$AQ8,$AJ$2:$AQ$2,AY$2)} -> 1 | AZ8: {=TREND($AJ8:$AQ8,$AJ$2:$AQ$2,AZ$2)} -> 1 | ... BV8: {=TREND($AJ8:$AQ8,$AJ$2:$AQ$2,BV$2)} -> 1
A9: MIS_D_MS | B9: MISS | D9: 0 | E9: 1 | F9: =INDEX('IPM Load'!B:B,MATCH('Cost-of-Service Shares'!$A9,'IPM Load'!$A:$A,0)) -> 22 | G9: =INDEX('IPM Load'!C:C,MATCH('Cost-of-Service Shares'!$A9,'IPM Load'!$A:$A,0)) -> 23 | H9: =INDEX('IPM Load'!D:D,MATCH('Cost-of-Service Shares'!$A9,'IPM Load'!$A:$A,0)) -> 23 | I9: =INDEX('IPM Load'!E:E,MATCH('Cost-of-Service Shares'!$A9,'IPM Load'!$A:$A,0)) -> 24 | J9: =INDEX('IPM Load'!F:F,MATCH('Cost-of-Service Shares'!$A9,'IPM Load'!$A:$A,0)) -> 25 | K9: =INDEX('IPM Load'!G:G,MATCH('Cost-of-Service Shares'!$A9,'IPM Load'!$A:$A,0)) -> 26 | L9: =INDEX('IPM Load'!H:H,MATCH('Cost-of-Service Shares'!$A9,'IPM Load'!$A:$A,0)) -> 27 | M9: =INDEX('IPM Load'!I:I,MATCH('Cost-of-Service Shares'!$A9,'IPM Load'!$A:$A,0)) -> 28 | N9: =$E9*F9/INDEX(Z$3:Z$27,MATCH($B9,$Y$3:$Y$27,0)) -> 0.13173653 | O9: =$E9*G9/INDEX(AA$3:AA$27,MATCH($B9,$Y$3:$Y$27,0)) -> 0.13294798 | P9: =$E9*H9/INDEX(AB$3:AB$27,MATCH($B9,$Y$3:$Y$27,0)) -> 0.1299435 | Q9: =$E9*I9/INDEX(AC$3:AC$27,MATCH($B9,$Y$3:$Y$27,0)) -> 0.12972973 | R9: =$E9*J9/INDEX(AD$3:AD$27,MATCH($B9,$Y$3:$Y$27,0)) -> 0.12953368 | S9: =$E9*K9/INDEX(AE$3:AE$27,MATCH($B9,$Y$3:$Y$27,0)) -> 0.12935323 | T9: =$E9*L9/INDEX(AF$3:AF$27,MATCH($B9,$Y$3:$Y$27,0)) -> 0.12796209 | U9: =$E9*M9/INDEX(AG$3:AG$27,MATCH($B9,$Y$3:$Y$27,0)) -> 0.12844037 | Y9: ISNE | Z9: =SUMIFS(F$3:F$68,$B$3:$B$68,$Y9) -> 119 | AA9: =SUMIFS(G$3:G$68,$B$3:$B$68,$Y9) -> 120 | AB9: =SUMIFS(H$3:H$68,$B$3:$B$68,$Y9) -> 120 | AC9: =SUMIFS(I$3:I$68,$B$3:$B$68,$Y9) -> 121 | AD9: =SUMIFS(J$3:J$68,$B$3:$B$68,$Y9) -> 122 | AE9: =SUMIFS(K$3:K$68,$B$3:$B$68,$Y9) -> 123 | AF9: =SUMIFS(L$3:L$68,$B$3:$B$68,$Y9) -> 123 | AG9: =SUMIFS(M$3:M$68,$B$3:$B$68,$Y9) -> 123 | AI9: ISNE | AJ9: =SUMIFS(N$3:N$68,$B$3:$B$68,$AI9) -> 0.05 | AK9: =SUMIFS(O$3:O$68,$B$3:$B$68,$AI9) -> 0.05 | AL9: =SUMIFS(P$3:P$68,$B$3:$B$68,$AI9) -> 0.05 | AM9: =SUMIFS(Q$3:Q$68,$B$3:$B$68,$AI9) -> 0.05 | AN9: =SUMIFS(R$3:R$68,$B$3:$B$68,$AI9) -> 0.05 | AO9: =SUMIFS(S$3:S$68,$B$3:$B$68,$AI9) -> 0.05 | AP9: =SUMIFS(T$3:T$68,$B$3:$B$68,$AI9) -> 0.05 | AQ9: =SUMIFS(U$3:U$68,$B$3:$B$68,$AI9) -> 0.05 | AS9: {=TREND($AJ9:$AQ9,$AJ$2:$AQ$2,AS$2)} -> 0.05 | AT9: {=TREND($AJ9:$AQ9,$AJ$2:$AQ$2,AT$2)} -> 0.05 | AU9: {=TREND($AJ9:$AQ9,$AJ$2:$AQ$2,AU$2)} -> 0.05 | AV9: {=TREND($AJ9:$AQ9,$AJ$2:$AQ$2,AV$2)} -> 0.05 | AW9: {=TREND($AJ9:$AQ9,$AJ$2:$AQ$2,AW$2)} -> 0.05 | AX9: {=TREND($AJ9:$AQ9,$AJ$2:$AQ$2,AX$2)} -> 0.05 | AY9: {=TREND($AJ9:$AQ9,$AJ$2:$AQ$2,AY$2)} -> 0.05 | AZ9: {=TREND($AJ9:$AQ9,$AJ$2:$AQ$2,AZ$2)} -> 0.05 | ... BV9: {=TREND($AJ9:$AQ9,$AJ$2:$AQ$2,BV$2)} -> 0.05
A10: MIS_IA | B10: MISW | D10: 0.01 | E10: 0.99 | F10: =INDEX('IPM Load'!B:B,MATCH('Cost-of-Service Shares'!$A10,'IPM Load'!$A:$A,0)) -> 22 | G10: =INDEX('IPM Load'!C:C,MATCH('Cost-of-Service Shares'!$A10,'IPM Load'!$A:$A,0)) -> 22 | H10: =INDEX('IPM Load'!D:D,MATCH('Cost-of-Service Shares'!$A10,'IPM Load'!$A:$A,0)) -> 23 | I10: =INDEX('IPM Load'!E:E,MATCH('Cost-of-Service Shares'!$A10,'IPM Load'!$A:$A,0)) -> 23 | J10: =INDEX('IPM Load'!F:F,MATCH('Cost-of-Service Shares'!$A10,'IPM Load'!$A:$A,0)) -> 24 | K10: =INDEX('IPM Load'!G:G,MATCH('Cost-of-Service Shares'!$A10,'IPM Load'!$A:$A,0)) -> 25 | L10: =INDEX('IPM Load'!H:H,MATCH('Cost-of-Service Shares'!$A10,'IPM Load'!$A:$A,0)) -> 26 | M10: =INDEX('IPM Load'!I:I,MATCH('Cost-of-Service Shares'!$A10,'IPM Load'!$A:$A,0)) -> 27 | N10: =$E10*F10/INDEX(Z$3:Z$27,MATCH($B10,$Y$3:$Y$27,0)) -> 0.10714967 | O10: =$E10*G10/INDEX(AA$3:AA$27,MATCH($B10,$Y$3:$Y$27,0)) -> 0.10468615 | P10: =$E10*H10/INDEX(AB$3:AB$27,MATCH($B10,$Y$3:$Y$27,0)) -> 0.10840253 | Q10: =$E10*I10/INDEX(AC$3:AC$27,MATCH($B10,$Y$3:$Y$27,0)) -> 0.10539205 | R10: =$E10*J10/INDEX(AD$3:AD$27,MATCH($B10,$Y$3:$Y$27,0)) -> 0.10700271 | S10: =$E10*K10/INDEX(AE$3:AE$27,MATCH($B10,$Y$3:$Y$27,0)) -> 0.10768649 | T10: =$E10*L10/INDEX(AF$3:AF$27,MATCH($B10,$Y$3:$Y$27,0)) -> 0.10822682 | U10: =$E10*M10/INDEX(AG$3:AG$27,MATCH($B10,$Y$3:$Y$27,0)) -> 0.10829147 | Y10: NYCW | Z10: =SUMIFS(F$3:F$68,$B$3:$B$68,$Y10) -> 73 | AA10: =SUMIFS(G$3:G$68,$B$3:$B$68,$Y10) -> 73 | AB10: =SUMIFS(H$3:H$68,$B$3:$B$68,$Y10) -> 73 | AC10: =SUMIFS(I$3:I$68,$B$3:$B$68,$Y10) -> 72 | AD10: =SUMIFS(J$3:J$68,$B$3:$B$68,$Y10) -> 71 | AE10: =SUMIFS(K$3:K$68,$B$3:$B$68,$Y10) -> 71 | AF10: =SUMIFS(L$3:L$68,$B$3:$B$68,$Y10) -> 71 | AG10: =SUMIFS(M$3:M$68,$B$3:$B$68,$Y10) -> 72 | AI10: NYCW | AJ10: =SUMIFS(N$3:N$68,$B$3:$B$68,$AI10) -> 0 | AK10: =SUMIFS(O$3:O$68,$B$3:$B$68,$AI10) -> 0 | AL10: =SUMIFS(P$3:P$68,$B$3:$B$68,$AI10) -> 0 | AM10: =SUMIFS(Q$3:Q$68,$B$3:$B$68,$AI10) -> 0 | AN10: =SUMIFS(R$3:R$68,$B$3:$B$68,$AI10) -> 0 | AO10: =SUMIFS(S$3:S$68,$B$3:$B$68,$AI10) -> 0 | AP10: =SUMIFS(T$3:T$68,$B$3:$B$68,$AI10) -> 0 | AQ10: =SUMIFS(U$3:U$68,$B$3:$B$68,$AI10) -> 0 | AS10: {=TREND($AJ10:$AQ10,$AJ$2:$AQ$2,AS$2)} -> 0 | AT10: {=TREND($AJ10:$AQ10,$AJ$2:$AQ$2,AT$2)} -> 0 | AU10: {=TREND($AJ10:$AQ10,$AJ$2:$AQ$2,AU$2)} -> 0 | AV10: {=TREND($AJ10:$AQ10,$AJ$2:$AQ$2,AV$2)} -> 0 | AW10: {=TREND($AJ10:$AQ10,$AJ$2:$AQ$2,AW$2)} -> 0 | AX10: {=TREND($AJ10:$AQ10,$AJ$2:$AQ$2,AX$2)} -> 0 | AY10: {=TREND($AJ10:$AQ10,$AJ$2:$AQ$2,AY$2)} -> 0 | AZ10: {=TREND($AJ10:$AQ10,$AJ$2:$AQ$2,AZ$2)} -> 0 | ... BV10: {=TREND($AJ10:$AQ10,$AJ$2:$AQ$2,BV$2)} -> 0
A11: MIS_IL | B11: MISC | D11: 0.09 | E11: 0.91 | F11: =INDEX('IPM Load'!B:B,MATCH('Cost-of-Service Shares'!$A11,'IPM Load'!$A:$A,0)) -> 48 | G11: =INDEX('IPM Load'!C:C,MATCH('Cost-of-Service Shares'!$A11,'IPM Load'!$A:$A,0)) -> 49 | H11: =INDEX('IPM Load'!D:D,MATCH('Cost-of-Service Shares'!$A11,'IPM Load'!$A:$A,0)) -> 49 | I11: =INDEX('IPM Load'!E:E,MATCH('Cost-of-Service Shares'!$A11,'IPM Load'!$A:$A,0)) -> 51 | J11: =INDEX('IPM Load'!F:F,MATCH('Cost-of-Service Shares'!$A11,'IPM Load'!$A:$A,0)) -> 52 | K11: =INDEX('IPM Load'!G:G,MATCH('Cost-of-Service Shares'!$A11,'IPM Load'!$A:$A,0)) -> 54 | L11: =INDEX('IPM Load'!H:H,MATCH('Cost-of-Service Shares'!$A11,'IPM Load'!$A:$A,0)) -> 56 | M11: =INDEX('IPM Load'!I:I,MATCH('Cost-of-Service Shares'!$A11,'IPM Load'!$A:$A,0)) -> 58 | N11: =$E11*F11/INDEX(Z$3:Z$27,MATCH($B11,$Y$3:$Y$27,0)) -> 0.22236936 | O11: =$E11*G11/INDEX(AA$3:AA$27,MATCH($B11,$Y$3:$Y$27,0)) -> 0.22293954 | P11: =$E11*H11/INDEX(AB$3:AB$27,MATCH($B11,$Y$3:$Y$27,0)) -> 0.22073232 | Q11: =$E11*I11/INDEX(AC$3:AC$27,MATCH($B11,$Y$3:$Y$27,0)) -> 0.22311494 | R11: =$E11*J11/INDEX(AD$3:AD$27,MATCH($B11,$Y$3:$Y$27,0)) -> 0.22258932 | S11: =$E11*K11/INDEX(AE$3:AE$27,MATCH($B11,$Y$3:$Y$27,0)) -> 0.22319293 | T11: =$E11*L11/INDEX(AF$3:AF$27,MATCH($B11,$Y$3:$Y$27,0)) -> 0.22432711 | U11: =$E11*M11/INDEX(AG$3:AG$27,MATCH($B11,$Y$3:$Y$27,0)) -> 0.22388341 | Y11: NYUP | Z11: =SUMIFS(F$3:F$68,$B$3:$B$68,$Y11) -> 48 | AA11: =SUMIFS(G$3:G$68,$B$3:$B$68,$Y11) -> 48 | AB11: =SUMIFS(H$3:H$68,$B$3:$B$68,$Y11) -> 50 | AC11: =SUMIFS(I$3:I$68,$B$3:$B$68,$Y11) -> 48 | AD11: =SUMIFS(J$3:J$68,$B$3:$B$68,$Y11) -> 48 | AE11: =SUMIFS(K$3:K$68,$B$3:$B$68,$Y11) -> 48 | AF11: =SUMIFS(L$3:L$68,$B$3:$B$68,$Y11) -> 48 | AG11: =SUMIFS(M$3:M$68,$B$3:$B$68,$Y11) -> 50 | AI11: NYUP | AJ11: =SUMIFS(N$3:N$68,$B$3:$B$68,$AI11) -> 0 | AK11: =SUMIFS(O$3:O$68,$B$3:$B$68,$AI11) -> 0 | AL11: =SUMIFS(P$3:P$68,$B$3:$B$68,$AI11) -> 0 | AM11: =SUMIFS(Q$3:Q$68,$B$3:$B$68,$AI11) -> 0 | AN11: =SUMIFS(R$3:R$68,$B$3:$B$68,$AI11) -> 0 | AO11: =SUMIFS(S$3:S$68,$B$3:$B$68,$AI11) -> 0 | AP11: =SUMIFS(T$3:T$68,$B$3:$B$68,$AI11) -> 0 | AQ11: =SUMIFS(U$3:U$68,$B$3:$B$68,$AI11) -> 0 | AS11: {=TREND($AJ11:$AQ11,$AJ$2:$AQ$2,AS$2)} -> 0 | AT11: {=TREND($AJ11:$AQ11,$AJ$2:$AQ$2,AT$2)} -> 0 | AU11: {=TREND($AJ11:$AQ11,$AJ$2:$AQ$2,AU$2)} -> 0 | AV11: {=TREND($AJ11:$AQ11,$AJ$2:$AQ$2,AV$2)} -> 0 | AW11: {=TREND($AJ11:$AQ11,$AJ$2:$AQ$2,AW$2)} -> 0 | AX11: {=TREND($AJ11:$AQ11,$AJ$2:$AQ$2,AX$2)} -> 0 | AY11: {=TREND($AJ11:$AQ11,$AJ$2:$AQ$2,AY$2)} -> 0 | AZ11: {=TREND($AJ11:$AQ11,$AJ$2:$AQ$2,AZ$2)} -> 0 | ... BV11: {=TREND($AJ11:$AQ11,$AJ$2:$AQ$2,BV$2)} -> 0
A12: MIS_INKY | B12: MISC | D12: 0.59 | E12: 0.41 | F12: =INDEX('IPM Load'!B:B,MATCH('Cost-of-Service Shares'!$A12,'IPM Load'!$A:$A,0)) -> 97 | G12: =INDEX('IPM Load'!C:C,MATCH('Cost-of-Service Shares'!$A12,'IPM Load'!$A:$A,0)) -> 99 | H12: =INDEX('IPM Load'!D:D,MATCH('Cost-of-Service Shares'!$A12,'IPM Load'!$A:$A,0)) -> 100 | I12: =INDEX('IPM Load'!E:E,MATCH('Cost-of-Service Shares'!$A12,'IPM Load'!$A:$A,0)) -> 103 | J12: =INDEX('IPM Load'!F:F,MATCH('Cost-of-Service Shares'!$A12,'IPM Load'!$A:$A,0)) -> 105 | K12: =INDEX('IPM Load'!G:G,MATCH('Cost-of-Service Shares'!$A12,'IPM Load'!$A:$A,0)) -> 108 | L12: =INDEX('IPM Load'!H:H,MATCH('Cost-of-Service Shares'!$A12,'IPM Load'!$A:$A,0)) -> 112 | M12: =INDEX('IPM Load'!I:I,MATCH('Cost-of-Service Shares'!$A12,'IPM Load'!$A:$A,0)) -> 116 | N12: =$E12*F12/INDEX(Z$3:Z$27,MATCH($B12,$Y$3:$Y$27,0)) -> 0.20246405 | O12: =$E12*G12/INDEX(AA$3:AA$27,MATCH($B12,$Y$3:$Y$27,0)) -> 0.20294048 | P12: =$E12*H12/INDEX(AB$3:AB$27,MATCH($B12,$Y$3:$Y$27,0)) -> 0.20296087 | Q12: =$E12*I12/INDEX(AC$3:AC$27,MATCH($B12,$Y$3:$Y$27,0)) -> 0.20301969 | R12: =$E12*J12/INDEX(AD$3:AD$27,MATCH($B12,$Y$3:$Y$27,0)) -> 0.20250359 | S12: =$E12*K12/INDEX(AE$3:AE$27,MATCH($B12,$Y$3:$Y$27,0)) -> 0.20111891 | T12: =$E12*L12/INDEX(AF$3:AF$27,MATCH($B12,$Y$3:$Y$27,0)) -> 0.20214091 | U12: =$E12*M12/INDEX(AG$3:AG$27,MATCH($B12,$Y$3:$Y$27,0)) -> 0.2017411 | Y12: PJME | Z12: =SUMIFS(F$3:F$68,$B$3:$B$68,$Y12) -> 275 | AA12: =SUMIFS(G$3:G$68,$B$3:$B$68,$Y12) -> 277 | AB12: =SUMIFS(H$3:H$68,$B$3:$B$68,$Y12) -> 280 | AC12: =SUMIFS(I$3:I$68,$B$3:$B$68,$Y12) -> 282 | AD12: =SUMIFS(J$3:J$68,$B$3:$B$68,$Y12) -> 287 | AE12: =SUMIFS(K$3:K$68,$B$3:$B$68,$Y12) -> 293 | AF12: =SUMIFS(L$3:L$68,$B$3:$B$68,$Y12) -> 297 | AG12: =SUMIFS(M$3:M$68,$B$3:$B$68,$Y12) -> 306 | AI12: PJME | AJ12: =SUMIFS(N$3:N$68,$B$3:$B$68,$AI12) -> 0 | AK12: =SUMIFS(O$3:O$68,$B$3:$B$68,$AI12) -> 0 | AL12: =SUMIFS(P$3:P$68,$B$3:$B$68,$AI12) -> 0 | AM12: =SUMIFS(Q$3:Q$68,$B$3:$B$68,$AI12) -> 0 | AN12: =SUMIFS(R$3:R$68,$B$3:$B$68,$AI12) -> 0 | AO12: =SUMIFS(S$3:S$68,$B$3:$B$68,$AI12) -> 0 | AP12: =SUMIFS(T$3:T$68,$B$3:$B$68,$AI12) -> 0 | AQ12: =SUMIFS(U$3:U$68,$B$3:$B$68,$AI12) -> 0 | AS12: {=TREND($AJ12:$AQ12,$AJ$2:$AQ$2,AS$2)} -> 0 | AT12: {=TREND($AJ12:$AQ12,$AJ$2:$AQ$2,AT$2)} -> 0 | AU12: {=TREND($AJ12:$AQ12,$AJ$2:$AQ$2,AU$2)} -> 0 | AV12: {=TREND($AJ12:$AQ12,$AJ$2:$AQ$2,AV$2)} -> 0 | AW12: {=TREND($AJ12:$AQ12,$AJ$2:$AQ$2,AW$2)} -> 0 | AX12: {=TREND($AJ12:$AQ12,$AJ$2:$AQ$2,AX$2)} -> 0 | AY12: {=TREND($AJ12:$AQ12,$AJ$2:$AQ$2,AY$2)} -> 0 | AZ12: {=TREND($AJ12:$AQ12,$AJ$2:$AQ$2,AZ$2)} -> 0 | ... BV12: {=TREND($AJ12:$AQ12,$AJ$2:$AQ$2,BV$2)} -> 0
A13: MIS_LA | B13: MISS | D13: 0 | E13: 1 | F13: =INDEX('IPM Load'!B:B,MATCH('Cost-of-Service Shares'!$A13,'IPM Load'!$A:$A,0)) -> 46 | G13: =INDEX('IPM Load'!C:C,MATCH('Cost-of-Service Shares'!$A13,'IPM Load'!$A:$A,0)) -> 47 | H13: =INDEX('IPM Load'!D:D,MATCH('Cost-of-Service Shares'!$A13,'IPM Load'!$A:$A,0)) -> 48 | I13: =INDEX('IPM Load'!E:E,MATCH('Cost-of-Service Shares'!$A13,'IPM Load'!$A:$A,0)) -> 51 | J13: =INDEX('IPM Load'!F:F,MATCH('Cost-of-Service Shares'!$A13,'IPM Load'!$A:$A,0)) -> 53 | K13: =INDEX('IPM Load'!G:G,MATCH('Cost-of-Service Shares'!$A13,'IPM Load'!$A:$A,0)) -> 55 | L13: =INDEX('IPM Load'!H:H,MATCH('Cost-of-Service Shares'!$A13,'IPM Load'!$A:$A,0)) -> 58 | M13: =INDEX('IPM Load'!I:I,MATCH('Cost-of-Service Shares'!$A13,'IPM Load'!$A:$A,0)) -> 60 | N13: =$E13*F13/INDEX(Z$3:Z$27,MATCH($B13,$Y$3:$Y$27,0)) -> 0.2754491 | O13: =$E13*G13/INDEX(AA$3:AA$27,MATCH($B13,$Y$3:$Y$27,0)) -> 0.2716763 | P13: =$E13*H13/INDEX(AB$3:AB$27,MATCH($B13,$Y$3:$Y$27,0)) -> 0.27118644 | Q13: =$E13*I13/INDEX(AC$3:AC$27,MATCH($B13,$Y$3:$Y$27,0)) -> 0.27567568 | R13: =$E13*J13/INDEX(AD$3:AD$27,MATCH($B13,$Y$3:$Y$27,0)) -> 0.2746114 | S13: =$E13*K13/INDEX(AE$3:AE$27,MATCH($B13,$Y$3:$Y$27,0)) -> 0.27363184 | T13: =$E13*L13/INDEX(AF$3:AF$27,MATCH($B13,$Y$3:$Y$27,0)) -> 0.27488152 | U13: =$E13*M13/INDEX(AG$3:AG$27,MATCH($B13,$Y$3:$Y$27,0)) -> 0.27522936 | Y13: PJMW | Z13: =SUMIFS(F$3:F$68,$B$3:$B$68,$Y13) -> 330 | AA13: =SUMIFS(G$3:G$68,$B$3:$B$68,$Y13) -> 337 | AB13: =SUMIFS(H$3:H$68,$B$3:$B$68,$Y13) -> 341 | AC13: =SUMIFS(I$3:I$68,$B$3:$B$68,$Y13) -> 349 | AD13: =SUMIFS(J$3:J$68,$B$3:$B$68,$Y13) -> 356 | AE13: =SUMIFS(K$3:K$68,$B$3:$B$68,$Y13) -> 368 | AF13: =SUMIFS(L$3:L$68,$B$3:$B$68,$Y13) -> 378 | AG13: =SUMIFS(M$3:M$68,$B$3:$B$68,$Y13) -> 392 | AI13: PJMW | AJ13: =SUMIFS(N$3:N$68,$B$3:$B$68,$AI13) -> 0.41 | AK13: =SUMIFS(O$3:O$68,$B$3:$B$68,$AI13) -> 0.41 | AL13: =SUMIFS(P$3:P$68,$B$3:$B$68,$AI13) -> 0.41 | AM13: =SUMIFS(Q$3:Q$68,$B$3:$B$68,$AI13) -> 0.41 | AN13: =SUMIFS(R$3:R$68,$B$3:$B$68,$AI13) -> 0.41 | AO13: =SUMIFS(S$3:S$68,$B$3:$B$68,$AI13) -> 0.41 | AP13: =SUMIFS(T$3:T$68,$B$3:$B$68,$AI13) -> 0.41 | AQ13: =SUMIFS(U$3:U$68,$B$3:$B$68,$AI13) -> 0.41 | AS13: {=TREND($AJ13:$AQ13,$AJ$2:$AQ$2,AS$2)} -> 0.41 | AT13: {=TREND($AJ13:$AQ13,$AJ$2:$AQ$2,AT$2)} -> 0.41 | AU13: {=TREND($AJ13:$AQ13,$AJ$2:$AQ$2,AU$2)} -> 0.41 | AV13: {=TREND($AJ13:$AQ13,$AJ$2:$AQ$2,AV$2)} -> 0.41 | AW13: {=TREND($AJ13:$AQ13,$AJ$2:$AQ$2,AW$2)} -> 0.41 | AX13: {=TREND($AJ13:$AQ13,$AJ$2:$AQ$2,AX$2)} -> 0.41 | AY13: {=TREND($AJ13:$AQ13,$AJ$2:$AQ$2,AY$2)} -> 0.41 | AZ13: {=TREND($AJ13:$AQ13,$AJ$2:$AQ$2,AZ$2)} -> 0.41 | ... BV13: {=TREND($AJ13:$AQ13,$AJ$2:$AQ$2,BV$2)} -> 0.41
A14: MIS_LMI | B14: MISE | D14: 0.1 | E14: 0.9 | F14: =INDEX('IPM Load'!B:B,MATCH('Cost-of-Service Shares'!$A14,'IPM Load'!$A:$A,0)) -> 100 | G14: =INDEX('IPM Load'!C:C,MATCH('Cost-of-Service Shares'!$A14,'IPM Load'!$A:$A,0)) -> 102 | H14: =INDEX('IPM Load'!D:D,MATCH('Cost-of-Service Shares'!$A14,'IPM Load'!$A:$A,0)) -> 103 | I14: =INDEX('IPM Load'!E:E,MATCH('Cost-of-Service Shares'!$A14,'IPM Load'!$A:$A,0)) -> 105 | J14: =INDEX('IPM Load'!F:F,MATCH('Cost-of-Service Shares'!$A14,'IPM Load'!$A:$A,0)) -> 108 | K14: =INDEX('IPM Load'!G:G,MATCH('Cost-of-Service Shares'!$A14,'IPM Load'!$A:$A,0)) -> 111 | L14: =INDEX('IPM Load'!H:H,MATCH('Cost-of-Service Shares'!$A14,'IPM Load'!$A:$A,0)) -> 115 | M14: =INDEX('IPM Load'!I:I,MATCH('Cost-of-Service Shares'!$A14,'IPM Load'!$A:$A,0)) -> 119 | N14: =$E14*F14/INDEX(Z$3:Z$27,MATCH($B14,$Y$3:$Y$27,0)) -> 0.9 | O14: =$E14*G14/INDEX(AA$3:AA$27,MATCH($B14,$Y$3:$Y$27,0)) -> 0.9 | P14: =$E14*H14/INDEX(AB$3:AB$27,MATCH($B14,$Y$3:$Y$27,0)) -> 0.9 | Q14: =$E14*I14/INDEX(AC$3:AC$27,MATCH($B14,$Y$3:$Y$27,0)) -> 0.9 | R14: =$E14*J14/INDEX(AD$3:AD$27,MATCH($B14,$Y$3:$Y$27,0)) -> 0.9 | S14: =$E14*K14/INDEX(AE$3:AE$27,MATCH($B14,$Y$3:$Y$27,0)) -> 0.9 | T14: =$E14*L14/INDEX(AF$3:AF$27,MATCH($B14,$Y$3:$Y$27,0)) -> 0.9 | U14: =$E14*M14/INDEX(AG$3:AG$27,MATCH($B14,$Y$3:$Y$27,0)) -> 0.9 | Y14: PJMC | Z14: =SUMIFS(F$3:F$68,$B$3:$B$68,$Y14) -> 102 | AA14: =SUMIFS(G$3:G$68,$B$3:$B$68,$Y14) -> 104 | AB14: =SUMIFS(H$3:H$68,$B$3:$B$68,$Y14) -> 106 | AC14: =SUMIFS(I$3:I$68,$B$3:$B$68,$Y14) -> 108 | AD14: =SUMIFS(J$3:J$68,$B$3:$B$68,$Y14) -> 110 | AE14: =SUMIFS(K$3:K$68,$B$3:$B$68,$Y14) -> 113 | AF14: =SUMIFS(L$3:L$68,$B$3:$B$68,$Y14) -> 117 | AG14: =SUMIFS(M$3:M$68,$B$3:$B$68,$Y14) -> 121 | AI14: PJMC | AJ14: =SUMIFS(N$3:N$68,$B$3:$B$68,$AI14) -> 0.41 | AK14: =SUMIFS(O$3:O$68,$B$3:$B$68,$AI14) -> 0.41 | AL14: =SUMIFS(P$3:P$68,$B$3:$B$68,$AI14) -> 0.41 | AM14: =SUMIFS(Q$3:Q$68,$B$3:$B$68,$AI14) -> 0.41 | AN14: =SUMIFS(R$3:R$68,$B$3:$B$68,$AI14) -> 0.41 | AO14: =SUMIFS(S$3:S$68,$B$3:$B$68,$AI14) -> 0.41 | AP14: =SUMIFS(T$3:T$68,$B$3:$B$68,$AI14) -> 0.41 | AQ14: =SUMIFS(U$3:U$68,$B$3:$B$68,$AI14) -> 0.41 | AS14: {=TREND($AJ14:$AQ14,$AJ$2:$AQ$2,AS$2)} -> 0.41 | AT14: {=TREND($AJ14:$AQ14,$AJ$2:$AQ$2,AT$2)} -> 0.41 | AU14: {=TREND($AJ14:$AQ14,$AJ$2:$AQ$2,AU$2)} -> 0.41 | AV14: {=TREND($AJ14:$AQ14,$AJ$2:$AQ$2,AV$2)} -> 0.41 | AW14: {=TREND($AJ14:$AQ14,$AJ$2:$AQ$2,AW$2)} -> 0.41 | AX14: {=TREND($AJ14:$AQ14,$AJ$2:$AQ$2,AX$2)} -> 0.41 | AY14: {=TREND($AJ14:$AQ14,$AJ$2:$AQ$2,AY$2)} -> 0.41 | AZ14: {=TREND($AJ14:$AQ14,$AJ$2:$AQ$2,AZ$2)} -> 0.41 | ... BV14: {=TREND($AJ14:$AQ14,$AJ$2:$AQ$2,BV$2)} -> 0.41
A15: MIS_MAPP | B15: MISW | D15: 0.01 | E15: 0.99 | F15: =F$71*('NEMS Net Load'!$C$4/('NEMS Net Load'!$C$4+'NEMS Net Load'!$C$20)) -> 6.2670677 | G15: =G$71*('NEMS Net Load'!$C$4/('NEMS Net Load'!$C$4+'NEMS Net Load'!$C$20)) -> 7.0504512 | H15: =H$71*('NEMS Net Load'!$C$4/('NEMS Net Load'!$C$4+'NEMS Net Load'!$C$20)) -> 7.0504512 | I15: =I$71*('NEMS Net Load'!$C$4/('NEMS Net Load'!$C$4+'NEMS Net Load'!$C$20)) -> 7.0504512 | J15: =J$71*('NEMS Net Load'!$C$4/('NEMS Net Load'!$C$4+'NEMS Net Load'!$C$20)) -> 7.0504512 | K15: =K$71*('NEMS Net Load'!$C$4/('NEMS Net Load'!$C$4+'NEMS Net Load'!$C$20)) -> 7.8338346 | L15: =L$71*('NEMS Net Load'!$C$4/('NEMS Net Load'!$C$4+'NEMS Net Load'!$C$20)) -> 7.8338346 | M15: =M$71*('NEMS Net Load'!$C$4/('NEMS Net Load'!$C$4+'NEMS Net Load'!$C$20)) -> 7.8338346 | N15: =$E15*F15/INDEX(Z$3:Z$27,MATCH($B15,$Y$3:$Y$27,0)) -> 0.030523375 | O15: =$E15*G15/INDEX(AA$3:AA$27,MATCH($B15,$Y$3:$Y$27,0)) -> 0.033549298 | P15: =$E15*H15/INDEX(AB$3:AB$27,MATCH($B15,$Y$3:$Y$27,0)) -> 0.033229858 | Q15: =$E15*I15/INDEX(AC$3:AC$27,MATCH($B15,$Y$3:$Y$27,0)) -> 0.032307022 | R15: =$E15*J15/INDEX(AD$3:AD$27,MATCH($B15,$Y$3:$Y$27,0)) -> 0.031434058 | S15: =$E15*K15/INDEX(AE$3:AE$27,MATCH($B15,$Y$3:$Y$27,0)) -> 0.033743928 | T15: =$E15*L15/INDEX(AF$3:AF$27,MATCH($B15,$Y$3:$Y$27,0)) -> 0.032608886 | U15: =$E15*M15/INDEX(AG$3:AG$27,MATCH($B15,$Y$3:$Y$27,0)) -> 0.031419908 | Y15: PJMD | Z15: =SUMIFS(F$3:F$68,$B$3:$B$68,$Y15) -> 97 | AA15: =SUMIFS(G$3:G$68,$B$3:$B$68,$Y15) -> 100 | AB15: =SUMIFS(H$3:H$68,$B$3:$B$68,$Y15) -> 102 | AC15: =SUMIFS(I$3:I$68,$B$3:$B$68,$Y15) -> 107 | AD15: =SUMIFS(J$3:J$68,$B$3:$B$68,$Y15) -> 111 | AE15: =SUMIFS(K$3:K$68,$B$3:$B$68,$Y15) -> 116 | AF15: =SUMIFS(L$3:L$68,$B$3:$B$68,$Y15) -> 121 | AG15: =SUMIFS(M$3:M$68,$B$3:$B$68,$Y15) -> 126 | AI15: PJMD | AJ15: =SUMIFS(N$3:N$68,$B$3:$B$68,$AI15) -> 1 | AK15: =SUMIFS(O$3:O$68,$B$3:$B$68,$AI15) -> 1 | AL15: =SUMIFS(P$3:P$68,$B$3:$B$68,$AI15) -> 1 | AM15: =SUMIFS(Q$3:Q$68,$B$3:$B$68,$AI15) -> 1 | AN15: =SUMIFS(R$3:R$68,$B$3:$B$68,$AI15) -> 1 | AO15: =SUMIFS(S$3:S$68,$B$3:$B$68,$AI15) -> 1 | AP15: =SUMIFS(T$3:T$68,$B$3:$B$68,$AI15) -> 1 | AQ15: =SUMIFS(U$3:U$68,$B$3:$B$68,$AI15) -> 1 | AS15: {=TREND($AJ15:$AQ15,$AJ$2:$AQ$2,AS$2)} -> 1 | AT15: {=TREND($AJ15:$AQ15,$AJ$2:$AQ$2,AT$2)} -> 1 | AU15: {=TREND($AJ15:$AQ15,$AJ$2:$AQ$2,AU$2)} -> 1 | AV15: {=TREND($AJ15:$AQ15,$AJ$2:$AQ$2,AV$2)} -> 1 | AW15: {=TREND($AJ15:$AQ15,$AJ$2:$AQ$2,AW$2)} -> 1 | AX15: {=TREND($AJ15:$AQ15,$AJ$2:$AQ$2,AX$2)} -> 1 | AY15: {=TREND($AJ15:$AQ15,$AJ$2:$AQ$2,AY$2)} -> 1 | AZ15: {=TREND($AJ15:$AQ15,$AJ$2:$AQ$2,AZ$2)} -> 1 | ... BV15: {=TREND($AJ15:$AQ15,$AJ$2:$AQ$2,BV$2)} -> 1
A16: MIS_MAPP | B16: SPPN | D16: 0.01 | E16: 0.99 | F16: =F$71*('NEMS Net Load'!$C$20/('NEMS Net Load'!$C$4+'NEMS Net Load'!$C$20)) -> 1.7329323 | G16: =G$71*('NEMS Net Load'!$C$20/('NEMS Net Load'!$C$4+'NEMS Net Load'!$C$20)) -> 1.9495488 | H16: =H$71*('NEMS Net Load'!$C$20/('NEMS Net Load'!$C$4+'NEMS Net Load'!$C$20)) -> 1.9495488 | I16: =I$71*('NEMS Net Load'!$C$20/('NEMS Net Load'!$C$4+'NEMS Net Load'!$C$20)) -> 1.9495488 | J16: =J$71*('NEMS Net Load'!$C$20/('NEMS Net Load'!$C$4+'NEMS Net Load'!$C$20)) -> 1.9495488 | K16: =K$71*('NEMS Net Load'!$C$20/('NEMS Net Load'!$C$4+'NEMS Net Load'!$C$20)) -> 2.1661654 | L16: =L$71*('NEMS Net Load'!$C$20/('NEMS Net Load'!$C$4+'NEMS Net Load'!$C$20)) -> 2.1661654 | M16: =M$71*('NEMS Net Load'!$C$20/('NEMS Net Load'!$C$4+'NEMS Net Load'!$C$20)) -> 2.1661654 | N16: =$E16*F16/INDEX(Z$3:Z$27,MATCH($B16,$Y$3:$Y$27,0)) -> 0.029210239 | O16: =$E16*G16/INDEX(AA$3:AA$27,MATCH($B16,$Y$3:$Y$27,0)) -> 0.032740765 | P16: =$E16*H16/INDEX(AB$3:AB$27,MATCH($B16,$Y$3:$Y$27,0)) -> 0.031666409 | Q16: =$E16*I16/INDEX(AC$3:AC$27,MATCH($B16,$Y$3:$Y$27,0)) -> 0.030660321 | R16: =$E16*J16/INDEX(AD$3:AD$27,MATCH($B16,$Y$3:$Y$27,0)) -> 0.030180875 | S16: =$E16*K16/INDEX(AE$3:AE$27,MATCH($B16,$Y$3:$Y$27,0)) -> 0.032410881 | T16: =$E16*L16/INDEX(AF$3:AF$27,MATCH($B16,$Y$3:$Y$27,0)) -> 0.031005098 | U16: =$E16*M16/INDEX(AG$3:AG$27,MATCH($B16,$Y$3:$Y$27,0)) -> 0.030133754 | Y16: SRCA | Z16: =SUMIFS(F$3:F$68,$B$3:$B$68,$Y16) -> 225 | AA16: =SUMIFS(G$3:G$68,$B$3:$B$68,$Y16) -> 231 | AB16: =SUMIFS(H$3:H$68,$B$3:$B$68,$Y16) -> 236 | AC16: =SUMIFS(I$3:I$68,$B$3:$B$68,$Y16) -> 247 | AD16: =SUMIFS(J$3:J$68,$B$3:$B$68,$Y16) -> 256 | AE16: =SUMIFS(K$3:K$68,$B$3:$B$68,$Y16) -> 268 | AF16: =SUMIFS(L$3:L$68,$B$3:$B$68,$Y16) -> 279 | AG16: =SUMIFS(M$3:M$68,$B$3:$B$68,$Y16) -> 292 | AI16: SRCA | AJ16: =SUMIFS(N$3:N$68,$B$3:$B$68,$AI16) -> 1 | AK16: =SUMIFS(O$3:O$68,$B$3:$B$68,$AI16) -> 1 | AL16: =SUMIFS(P$3:P$68,$B$3:$B$68,$AI16) -> 1 | AM16: =SUMIFS(Q$3:Q$68,$B$3:$B$68,$AI16) -> 1 | AN16: =SUMIFS(R$3:R$68,$B$3:$B$68,$AI16) -> 1 | AO16: =SUMIFS(S$3:S$68,$B$3:$B$68,$AI16) -> 1 | AP16: =SUMIFS(T$3:T$68,$B$3:$B$68,$AI16) -> 1 | AQ16: =SUMIFS(U$3:U$68,$B$3:$B$68,$AI16) -> 1 | AS16: {=TREND($AJ16:$AQ16,$AJ$2:$AQ$2,AS$2)} -> 1 | AT16: {=TREND($AJ16:$AQ16,$AJ$2:$AQ$2,AT$2)} -> 1 | AU16: {=TREND($AJ16:$AQ16,$AJ$2:$AQ$2,AU$2)} -> 1 | AV16: {=TREND($AJ16:$AQ16,$AJ$2:$AQ$2,AV$2)} -> 1 | AW16: {=TREND($AJ16:$AQ16,$AJ$2:$AQ$2,AW$2)} -> 1 | AX16: {=TREND($AJ16:$AQ16,$AJ$2:$AQ$2,AX$2)} -> 1 | AY16: {=TREND($AJ16:$AQ16,$AJ$2:$AQ$2,AY$2)} -> 1 | AZ16: {=TREND($AJ16:$AQ16,$AJ$2:$AQ$2,AZ$2)} -> 1 | ... BV16: {=TREND($AJ16:$AQ16,$AJ$2:$AQ$2,BV$2)} -> 1
A17: MIS_MIDA | B17: MISW | D17: 0.01 | E17: 0.99 | F17: =INDEX('IPM Load'!B:B,MATCH('Cost-of-Service Shares'!$A17,'IPM Load'!$A:$A,0)) -> 30 | G17: =INDEX('IPM Load'!C:C,MATCH('Cost-of-Service Shares'!$A17,'IPM Load'!$A:$A,0)) -> 31 | H17: =INDEX('IPM Load'!D:D,MATCH('Cost-of-Service Shares'!$A17,'IPM Load'!$A:$A,0)) -> 31 | I17: =INDEX('IPM Load'!E:E,MATCH('Cost-of-Service Shares'!$A17,'IPM Load'!$A:$A,0)) -> 32 | J17: =INDEX('IPM Load'!F:F,MATCH('Cost-of-Service Shares'!$A17,'IPM Load'!$A:$A,0)) -> 33 | K17: =INDEX('IPM Load'!G:G,MATCH('Cost-of-Service Shares'!$A17,'IPM Load'!$A:$A,0)) -> 34 | L17: =INDEX('IPM Load'!H:H,MATCH('Cost-of-Service Shares'!$A17,'IPM Load'!$A:$A,0)) -> 35 | M17: =INDEX('IPM Load'!I:I,MATCH('Cost-of-Service Shares'!$A17,'IPM Load'!$A:$A,0)) -> 37 | N17: =$E17*F17/INDEX(Z$3:Z$27,MATCH($B17,$Y$3:$Y$27,0)) -> 0.14611319 | O17: =$E17*G17/INDEX(AA$3:AA$27,MATCH($B17,$Y$3:$Y$27,0)) -> 0.1475123 | P17: =$E17*H17/INDEX(AB$3:AB$27,MATCH($B17,$Y$3:$Y$27,0)) -> 0.14610776 | Q17: =$E17*I17/INDEX(AC$3:AC$27,MATCH($B17,$Y$3:$Y$27,0)) -> 0.14663242 | R17: =$E17*J17/INDEX(AD$3:AD$27,MATCH($B17,$Y$3:$Y$27,0)) -> 0.14712873 | S17: =$E17*K17/INDEX(AE$3:AE$27,MATCH($B17,$Y$3:$Y$27,0)) -> 0.14645363 | T17: =$E17*L17/INDEX(AF$3:AF$27,MATCH($B17,$Y$3:$Y$27,0)) -> 0.14568995 | U17: =$E17*M17/INDEX(AG$3:AG$27,MATCH($B17,$Y$3:$Y$27,0)) -> 0.14839943 | Y17: SRSE | Z17: =SUMIFS(F$3:F$68,$B$3:$B$68,$Y17) -> 250 | AA17: =SUMIFS(G$3:G$68,$B$3:$B$68,$Y17) -> 258 | AB17: =SUMIFS(H$3:H$68,$B$3:$B$68,$Y17) -> 263 | AC17: =SUMIFS(I$3:I$68,$B$3:$B$68,$Y17) -> 274 | AD17: =SUMIFS(J$3:J$68,$B$3:$B$68,$Y17) -> 283 | AE17: =SUMIFS(K$3:K$68,$B$3:$B$68,$Y17) -> 295 | AF17: =SUMIFS(L$3:L$68,$B$3:$B$68,$Y17) -> 306 | AG17: =SUMIFS(M$3:M$68,$B$3:$B$68,$Y17) -> 318 | AI17: SRSE | AJ17: =SUMIFS(N$3:N$68,$B$3:$B$68,$AI17) -> 1 | AK17: =SUMIFS(O$3:O$68,$B$3:$B$68,$AI17) -> 1 | AL17: =SUMIFS(P$3:P$68,$B$3:$B$68,$AI17) -> 1 | AM17: =SUMIFS(Q$3:Q$68,$B$3:$B$68,$AI17) -> 1 | AN17: =SUMIFS(R$3:R$68,$B$3:$B$68,$AI17) -> 1 | AO17: =SUMIFS(S$3:S$68,$B$3:$B$68,$AI17) -> 1 | AP17: =SUMIFS(T$3:T$68,$B$3:$B$68,$AI17) -> 1 | AQ17: =SUMIFS(U$3:U$68,$B$3:$B$68,$AI17) -> 1 | AS17: {=TREND($AJ17:$AQ17,$AJ$2:$AQ$2,AS$2)} -> 1 | AT17: {=TREND($AJ17:$AQ17,$AJ$2:$AQ$2,AT$2)} -> 1 | AU17: {=TREND($AJ17:$AQ17,$AJ$2:$AQ$2,AU$2)} -> 1 | AV17: {=TREND($AJ17:$AQ17,$AJ$2:$AQ$2,AV$2)} -> 1 | AW17: {=TREND($AJ17:$AQ17,$AJ$2:$AQ$2,AW$2)} -> 1 | AX17: {=TREND($AJ17:$AQ17,$AJ$2:$AQ$2,AX$2)} -> 1 | AY17: {=TREND($AJ17:$AQ17,$AJ$2:$AQ$2,AY$2)} -> 1 | AZ17: {=TREND($AJ17:$AQ17,$AJ$2:$AQ$2,AZ$2)} -> 1 | ... BV17: {=TREND($AJ17:$AQ17,$AJ$2:$AQ$2,BV$2)} -> 1
A18: MIS_MNWI | B18: MISW | D18: 0.01 | E18: 0.99 | F18: =INDEX('IPM Load'!B:B,MATCH('Cost-of-Service Shares'!$A18,'IPM Load'!$A:$A,0)) -> 90 | G18: =INDEX('IPM Load'!C:C,MATCH('Cost-of-Service Shares'!$A18,'IPM Load'!$A:$A,0)) -> 92 | H18: =INDEX('IPM Load'!D:D,MATCH('Cost-of-Service Shares'!$A18,'IPM Load'!$A:$A,0)) -> 93 | I18: =INDEX('IPM Load'!E:E,MATCH('Cost-of-Service Shares'!$A18,'IPM Load'!$A:$A,0)) -> 96 | J18: =INDEX('IPM Load'!F:F,MATCH('Cost-of-Service Shares'!$A18,'IPM Load'!$A:$A,0)) -> 99 | K18: =INDEX('IPM Load'!G:G,MATCH('Cost-of-Service Shares'!$A18,'IPM Load'!$A:$A,0)) -> 102 | L18: =INDEX('IPM Load'!H:H,MATCH('Cost-of-Service Shares'!$A18,'IPM Load'!$A:$A,0)) -> 106 | M18: =INDEX('IPM Load'!I:I,MATCH('Cost-of-Service Shares'!$A18,'IPM Load'!$A:$A,0)) -> 110 | N18: =$E18*F18/INDEX(Z$3:Z$27,MATCH($B18,$Y$3:$Y$27,0)) -> 0.43833957 | O18: =$E18*G18/INDEX(AA$3:AA$27,MATCH($B18,$Y$3:$Y$27,0)) -> 0.43777843 | P18: =$E18*H18/INDEX(AB$3:AB$27,MATCH($B18,$Y$3:$Y$27,0)) -> 0.43832327 | Q18: =$E18*I18/INDEX(AC$3:AC$27,MATCH($B18,$Y$3:$Y$27,0)) -> 0.43989725 | R18: =$E18*J18/INDEX(AD$3:AD$27,MATCH($B18,$Y$3:$Y$27,0)) -> 0.44138618 | S18: =$E18*K18/INDEX(AE$3:AE$27,MATCH($B18,$Y$3:$Y$27,0)) -> 0.4393609 | T18: =$E18*L18/INDEX(AF$3:AF$27,MATCH($B18,$Y$3:$Y$27,0)) -> 0.44123243 | U18: =$E18*M18/INDEX(AG$3:AG$27,MATCH($B18,$Y$3:$Y$27,0)) -> 0.44118749 | Y18: SRCE | Z18: =SUMIFS(F$3:F$68,$B$3:$B$68,$Y18) -> 211 | AA18: =SUMIFS(G$3:G$68,$B$3:$B$68,$Y18) -> 217 | AB18: =SUMIFS(H$3:H$68,$B$3:$B$68,$Y18) -> 222 | AC18: =SUMIFS(I$3:I$68,$B$3:$B$68,$Y18) -> 229 | AD18: =SUMIFS(J$3:J$68,$B$3:$B$68,$Y18) -> 236 | AE18: =SUMIFS(K$3:K$68,$B$3:$B$68,$Y18) -> 245 | AF18: =SUMIFS(L$3:L$68,$B$3:$B$68,$Y18) -> 253 | AG18: =SUMIFS(M$3:M$68,$B$3:$B$68,$Y18) -> 262 | AI18: SRCE | AJ18: =SUMIFS(N$3:N$68,$B$3:$B$68,$AI18) -> 1 | AK18: =SUMIFS(O$3:O$68,$B$3:$B$68,$AI18) -> 1 | AL18: =SUMIFS(P$3:P$68,$B$3:$B$68,$AI18) -> 1 | AM18: =SUMIFS(Q$3:Q$68,$B$3:$B$68,$AI18) -> 1 | AN18: =SUMIFS(R$3:R$68,$B$3:$B$68,$AI18) -> 1 | AO18: =SUMIFS(S$3:S$68,$B$3:$B$68,$AI18) -> 1 | AP18: =SUMIFS(T$3:T$68,$B$3:$B$68,$AI18) -> 1 | AQ18: =SUMIFS(U$3:U$68,$B$3:$B$68,$AI18) -> 1 | AS18: {=TREND($AJ18:$AQ18,$AJ$2:$AQ$2,AS$2)} -> 1 | AT18: {=TREND($AJ18:$AQ18,$AJ$2:$AQ$2,AT$2)} -> 1 | AU18: {=TREND($AJ18:$AQ18,$AJ$2:$AQ$2,AU$2)} -> 1 | AV18: {=TREND($AJ18:$AQ18,$AJ$2:$AQ$2,AV$2)} -> 1 | AW18: {=TREND($AJ18:$AQ18,$AJ$2:$AQ$2,AW$2)} -> 1 | AX18: {=TREND($AJ18:$AQ18,$AJ$2:$AQ$2,AX$2)} -> 1 | AY18: {=TREND($AJ18:$AQ18,$AJ$2:$AQ$2,AY$2)} -> 1 | AZ18: {=TREND($AJ18:$AQ18,$AJ$2:$AQ$2,AZ$2)} -> 1 | ... BV18: {=TREND($AJ18:$AQ18,$AJ$2:$AQ$2,BV$2)} -> 1
A19: MIS_MO | B19: MISC | D19: 0.09 | E19: 0.91 | F19: =INDEX('IPM Load'!B:B,MATCH('Cost-of-Service Shares'!$A19,'IPM Load'!$A:$A,0)) -> 41 | G19: =INDEX('IPM Load'!C:C,MATCH('Cost-of-Service Shares'!$A19,'IPM Load'!$A:$A,0)) -> 41 | H19: =INDEX('IPM Load'!D:D,MATCH('Cost-of-Service Shares'!$A19,'IPM Load'!$A:$A,0)) -> 42 | I19: =INDEX('IPM Load'!E:E,MATCH('Cost-of-Service Shares'!$A19,'IPM Load'!$A:$A,0)) -> 43 | J19: =INDEX('IPM Load'!F:F,MATCH('Cost-of-Service Shares'!$A19,'IPM Load'!$A:$A,0)) -> 44 | K19: =INDEX('IPM Load'!G:G,MATCH('Cost-of-Service Shares'!$A19,'IPM Load'!$A:$A,0)) -> 46 | L19: =INDEX('IPM Load'!H:H,MATCH('Cost-of-Service Shares'!$A19,'IPM Load'!$A:$A,0)) -> 47 | M19: =INDEX('IPM Load'!I:I,MATCH('Cost-of-Service Shares'!$A19,'IPM Load'!$A:$A,0)) -> 49 | N19: =$E19*F19/INDEX(Z$3:Z$27,MATCH($B19,$Y$3:$Y$27,0)) -> 0.1899405 | O19: =$E19*G19/INDEX(AA$3:AA$27,MATCH($B19,$Y$3:$Y$27,0)) -> 0.18654125 | P19: =$E19*H19/INDEX(AB$3:AB$27,MATCH($B19,$Y$3:$Y$27,0)) -> 0.18919914 | Q19: =$E19*I19/INDEX(AC$3:AC$27,MATCH($B19,$Y$3:$Y$27,0)) -> 0.18811652 | R19: =$E19*J19/INDEX(AD$3:AD$27,MATCH($B19,$Y$3:$Y$27,0)) -> 0.18834481 | S19: =$E19*K19/INDEX(AE$3:AE$27,MATCH($B19,$Y$3:$Y$27,0)) -> 0.19012731 | T19: =$E19*L19/INDEX(AF$3:AF$27,MATCH($B19,$Y$3:$Y$27,0)) -> 0.18827454 | U19: =$E19*M19/INDEX(AG$3:AG$27,MATCH($B19,$Y$3:$Y$27,0)) -> 0.18914288 | Y19: SPPS | Z19: =SUMIFS(F$3:F$68,$B$3:$B$68,$Y19) -> 168.57006 | AA19: =SUMIFS(G$3:G$68,$B$3:$B$68,$Y19) -> 173.99062 | AB19: =SUMIFS(H$3:H$68,$B$3:$B$68,$Y19) -> 178.99062 | AC19: =SUMIFS(I$3:I$68,$B$3:$B$68,$Y19) -> 185.99062 | AD19: =SUMIFS(J$3:J$68,$B$3:$B$68,$Y19) -> 193.41118 | AE19: =SUMIFS(K$3:K$68,$B$3:$B$68,$Y19) -> 203.83174 | AF19: =SUMIFS(L$3:L$68,$B$3:$B$68,$Y19) -> 212.83174 | AG19: =SUMIFS(M$3:M$68,$B$3:$B$68,$Y19) -> 220.2523 | AI19: SPPS | AJ19: =SUMIFS(N$3:N$68,$B$3:$B$68,$AI19) -> 1 | AK19: =SUMIFS(O$3:O$68,$B$3:$B$68,$AI19) -> 1 | AL19: =SUMIFS(P$3:P$68,$B$3:$B$68,$AI19) -> 1 | AM19: =SUMIFS(Q$3:Q$68,$B$3:$B$68,$AI19) -> 1 | AN19: =SUMIFS(R$3:R$68,$B$3:$B$68,$AI19) -> 1 | AO19: =SUMIFS(S$3:S$68,$B$3:$B$68,$AI19) -> 1 | AP19: =SUMIFS(T$3:T$68,$B$3:$B$68,$AI19) -> 1 | AQ19: =SUMIFS(U$3:U$68,$B$3:$B$68,$AI19) -> 1 | AS19: {=TREND($AJ19:$AQ19,$AJ$2:$AQ$2,AS$2)} -> 1 | AT19: {=TREND($AJ19:$AQ19,$AJ$2:$AQ$2,AT$2)} -> 1 | AU19: {=TREND($AJ19:$AQ19,$AJ$2:$AQ$2,AU$2)} -> 1 | AV19: {=TREND($AJ19:$AQ19,$AJ$2:$AQ$2,AV$2)} -> 1 | AW19: {=TREND($AJ19:$AQ19,$AJ$2:$AQ$2,AW$2)} -> 1 | AX19: {=TREND($AJ19:$AQ19,$AJ$2:$AQ$2,AX$2)} -> 1 | AY19: {=TREND($AJ19:$AQ19,$AJ$2:$AQ$2,AY$2)} -> 1 | AZ19: {=TREND($AJ19:$AQ19,$AJ$2:$AQ$2,AZ$2)} -> 1 | ... BV19: {=TREND($AJ19:$AQ19,$AJ$2:$AQ$2,BV$2)} -> 1
A20: MIS_WOTA | B20: MISS | D20: 0 | E20: 1 | F20: =INDEX('IPM Load'!B:B,MATCH('Cost-of-Service Shares'!$A20,'IPM Load'!$A:$A,0)) -> 32 | G20: =INDEX('IPM Load'!C:C,MATCH('Cost-of-Service Shares'!$A20,'IPM Load'!$A:$A,0)) -> 33 | H20: =INDEX('IPM Load'!D:D,MATCH('Cost-of-Service Shares'!$A20,'IPM Load'!$A:$A,0)) -> 34 | I20: =INDEX('IPM Load'!E:E,MATCH('Cost-of-Service Shares'!$A20,'IPM Load'!$A:$A,0)) -> 36 | J20: =INDEX('IPM Load'!F:F,MATCH('Cost-of-Service Shares'!$A20,'IPM Load'!$A:$A,0)) -> 37 | K20: =INDEX('IPM Load'!G:G,MATCH('Cost-of-Service Shares'!$A20,'IPM Load'!$A:$A,0)) -> 39 | L20: =INDEX('IPM Load'!H:H,MATCH('Cost-of-Service Shares'!$A20,'IPM Load'!$A:$A,0)) -> 41 | M20: =INDEX('IPM Load'!I:I,MATCH('Cost-of-Service Shares'!$A20,'IPM Load'!$A:$A,0)) -> 42 | N20: =$E20*F20/INDEX(Z$3:Z$27,MATCH($B20,$Y$3:$Y$27,0)) -> 0.19161677 | O20: =$E20*G20/INDEX(AA$3:AA$27,MATCH($B20,$Y$3:$Y$27,0)) -> 0.19075145 | P20: =$E20*H20/INDEX(AB$3:AB$27,MATCH($B20,$Y$3:$Y$27,0)) -> 0.1920904 | Q20: =$E20*I20/INDEX(AC$3:AC$27,MATCH($B20,$Y$3:$Y$27,0)) -> 0.19459459 | R20: =$E20*J20/INDEX(AD$3:AD$27,MATCH($B20,$Y$3:$Y$27,0)) -> 0.19170984 | S20: =$E20*K20/INDEX(AE$3:AE$27,MATCH($B20,$Y$3:$Y$27,0)) -> 0.19402985 | T20: =$E20*L20/INDEX(AF$3:AF$27,MATCH($B20,$Y$3:$Y$27,0)) -> 0.1943128 | U20: =$E20*M20/INDEX(AG$3:AG$27,MATCH($B20,$Y$3:$Y$27,0)) -> 0.19266055 | Y20: SPPC | Z20: =SUMIFS(F$3:F$68,$B$3:$B$68,$Y20) -> 71 | AA20: =SUMIFS(G$3:G$68,$B$3:$B$68,$Y20) -> 72 | AB20: =SUMIFS(H$3:H$68,$B$3:$B$68,$Y20) -> 74 | AC20: =SUMIFS(I$3:I$68,$B$3:$B$68,$Y20) -> 76 | AD20: =SUMIFS(J$3:J$68,$B$3:$B$68,$Y20) -> 79 | AE20: =SUMIFS(K$3:K$68,$B$3:$B$68,$Y20) -> 82 | AF20: =SUMIFS(L$3:L$68,$B$3:$B$68,$Y20) -> 85 | AG20: =SUMIFS(M$3:M$68,$B$3:$B$68,$Y20) -> 88 | AI20: SPPC | AJ20: =SUMIFS(N$3:N$68,$B$3:$B$68,$AI20) -> 1 | AK20: =SUMIFS(O$3:O$68,$B$3:$B$68,$AI20) -> 1 | AL20: =SUMIFS(P$3:P$68,$B$3:$B$68,$AI20) -> 1 | AM20: =SUMIFS(Q$3:Q$68,$B$3:$B$68,$AI20) -> 1 | AN20: =SUMIFS(R$3:R$68,$B$3:$B$68,$AI20) -> 1 | AO20: =SUMIFS(S$3:S$68,$B$3:$B$68,$AI20) -> 1 | AP20: =SUMIFS(T$3:T$68,$B$3:$B$68,$AI20) -> 1 | AQ20: =SUMIFS(U$3:U$68,$B$3:$B$68,$AI20) -> 1 | AS20: {=TREND($AJ20:$AQ20,$AJ$2:$AQ$2,AS$2)} -> 1 | AT20: {=TREND($AJ20:$AQ20,$AJ$2:$AQ$2,AT$2)} -> 1 | AU20: {=TREND($AJ20:$AQ20,$AJ$2:$AQ$2,AU$2)} -> 1 | AV20: {=TREND($AJ20:$AQ20,$AJ$2:$AQ$2,AV$2)} -> 1 | AW20: {=TREND($AJ20:$AQ20,$AJ$2:$AQ$2,AW$2)} -> 1 | AX20: {=TREND($AJ20:$AQ20,$AJ$2:$AQ$2,AX$2)} -> 1 | AY20: {=TREND($AJ20:$AQ20,$AJ$2:$AQ$2,AY$2)} -> 1 | AZ20: {=TREND($AJ20:$AQ20,$AJ$2:$AQ$2,AZ$2)} -> 1 | ... BV20: {=TREND($AJ20:$AQ20,$AJ$2:$AQ$2,BV$2)} -> 1
A21: MIS_WUMS | B21: MISW | D21: 0.59 | E21: 0.41 | F21: =INDEX('IPM Load'!B:B,MATCH('Cost-of-Service Shares'!$A21,'IPM Load'!$A:$A,0)) -> 55 | G21: =INDEX('IPM Load'!C:C,MATCH('Cost-of-Service Shares'!$A21,'IPM Load'!$A:$A,0)) -> 56 | H21: =INDEX('IPM Load'!D:D,MATCH('Cost-of-Service Shares'!$A21,'IPM Load'!$A:$A,0)) -> 56 | I21: =INDEX('IPM Load'!E:E,MATCH('Cost-of-Service Shares'!$A21,'IPM Load'!$A:$A,0)) -> 58 | J21: =INDEX('IPM Load'!F:F,MATCH('Cost-of-Service Shares'!$A21,'IPM Load'!$A:$A,0)) -> 59 | K21: =INDEX('IPM Load'!G:G,MATCH('Cost-of-Service Shares'!$A21,'IPM Load'!$A:$A,0)) -> 61 | L21: =INDEX('IPM Load'!H:H,MATCH('Cost-of-Service Shares'!$A21,'IPM Load'!$A:$A,0)) -> 63 | M21: =INDEX('IPM Load'!I:I,MATCH('Cost-of-Service Shares'!$A21,'IPM Load'!$A:$A,0)) -> 65 | N21: =$E21*F21/INDEX(Z$3:Z$27,MATCH($B21,$Y$3:$Y$27,0)) -> 0.11093779 | O21: =$E21*G21/INDEX(AA$3:AA$27,MATCH($B21,$Y$3:$Y$27,0)) -> 0.11035785 | P21: =$E21*H21/INDEX(AB$3:AB$27,MATCH($B21,$Y$3:$Y$27,0)) -> 0.10930707 | Q21: =$E21*I21/INDEX(AC$3:AC$27,MATCH($B21,$Y$3:$Y$27,0)) -> 0.11006688 | R21: =$E21*J21/INDEX(AD$3:AD$27,MATCH($B21,$Y$3:$Y$27,0)) -> 0.10893921 | S21: =$E21*K21/INDEX(AE$3:AE$27,MATCH($B21,$Y$3:$Y$27,0)) -> 0.10881775 | T21: =$E21*L21/INDEX(AF$3:AF$27,MATCH($B21,$Y$3:$Y$27,0)) -> 0.10860524 | U21: =$E21*M21/INDEX(AG$3:AG$27,MATCH($B21,$Y$3:$Y$27,0)) -> 0.10796737 | Y21: SPPN | Z21: =SUMIFS(F$3:F$68,$B$3:$B$68,$Y21) -> 58.732932 | AA21: =SUMIFS(G$3:G$68,$B$3:$B$68,$Y21) -> 58.949549 | AB21: =SUMIFS(H$3:H$68,$B$3:$B$68,$Y21) -> 60.949549 | AC21: =SUMIFS(I$3:I$68,$B$3:$B$68,$Y21) -> 62.949549 | AD21: =SUMIFS(J$3:J$68,$B$3:$B$68,$Y21) -> 63.949549 | AE21: =SUMIFS(K$3:K$68,$B$3:$B$68,$Y21) -> 66.166165 | AF21: =SUMIFS(L$3:L$68,$B$3:$B$68,$Y21) -> 69.166165 | AG21: =SUMIFS(M$3:M$68,$B$3:$B$68,$Y21) -> 71.166165 | AI21: SPPN | AJ21: =SUMIFS(N$3:N$68,$B$3:$B$68,$AI21) -> 0.99 | AK21: =SUMIFS(O$3:O$68,$B$3:$B$68,$AI21) -> 0.99 | AL21: =SUMIFS(P$3:P$68,$B$3:$B$68,$AI21) -> 0.99 | AM21: =SUMIFS(Q$3:Q$68,$B$3:$B$68,$AI21) -> 0.99 | AN21: =SUMIFS(R$3:R$68,$B$3:$B$68,$AI21) -> 0.99 | AO21: =SUMIFS(S$3:S$68,$B$3:$B$68,$AI21) -> 0.99 | AP21: =SUMIFS(T$3:T$68,$B$3:$B$68,$AI21) -> 0.99 | AQ21: =SUMIFS(U$3:U$68,$B$3:$B$68,$AI21) -> 0.99 | AS21: {=TREND($AJ21:$AQ21,$AJ$2:$AQ$2,AS$2)} -> 0.99 | AT21: {=TREND($AJ21:$AQ21,$AJ$2:$AQ$2,AT$2)} -> 0.99 | AU21: {=TREND($AJ21:$AQ21,$AJ$2:$AQ$2,AU$2)} -> 0.99 | AV21: {=TREND($AJ21:$AQ21,$AJ$2:$AQ$2,AV$2)} -> 0.99 | AW21: {=TREND($AJ21:$AQ21,$AJ$2:$AQ$2,AW$2)} -> 0.99 | AX21: {=TREND($AJ21:$AQ21,$AJ$2:$AQ$2,AX$2)} -> 0.99 | AY21: {=TREND($AJ21:$AQ21,$AJ$2:$AQ$2,AY$2)} -> 0.99 | AZ21: {=TREND($AJ21:$AQ21,$AJ$2:$AQ$2,AZ$2)} -> 0.99 | ... BV21: {=TREND($AJ21:$AQ21,$AJ$2:$AQ$2,BV$2)} -> 0.99
