Workbook

Sheet About
A1: TTS Transportation Technology Shareweights
A3: Source: | B3: Onroad modes
B4: See supporting Python calibration file and excel/csv files in this folder.
B5: Given logit exponents from the GCAM model, we use a solver to solve
B6: for historical shareweights given recent sales data. We then allow the
B7: shareweights for BEV and PHEV technologies to grow, as explained below.
B9: passenger rail
B10: See data from EPS file trans/SYVbT
A12: Notes
A13: This variable provides the shareweights used in the modified logit equation for vehicle
A14: technology selection. We base them on estimated potential maximum sales shares in each year.
A15: For more on this, see the "Unmodified Logit" equation description at:
A16: https://jgcri.github.io/gcam-doc/choice.html
A18: When adapting the model to a new country or region, it may be helpful
A19: to calibrate this variable after replacing the input data for other variables.
A21: The solver we used is saved as transport_calibration.py in the TTS folder. It is set up
A22: to take in data on the cost per thing*mile for each vehicle type (taken from Vensim),
A23: the observed sales share (from historical data sets), the exponent (trans/TTLE), and
A24: the number of vehicles of that type demanded each year (taken from Vensim).
A25: The file calibration_parameters specifies all those pieces of input data. Sources for the
... A37: such as those from ICCT.
B39: passenger LDVs
B40: The historical data we use for calibration is for states that do not have
B41: their own vehicle standards (ACCI) that put an additional constraint on sales
B42: that is not purely cost-based. This gives us our 2024 and 2025 shareweights.
B44: passenger rail
B45: We use calculated data from SYVbT to calculate the historical sales shares.

Sheet SYVbT-passenger
A1: Number of Vehicles | B1: battery electric vehicle | C1: natural gas vehicle | D1: gasoline vehicle | E1: diesel vehicle | F1: plugin hybrid vehicle | G1: LPG vehicle | H1: hydrogen vehicle
A2: LDVs | B2: 2799214 | C2: 16648 | D2: 256819978 | E2: 1348635 | F2: 1130472 | G2: 16384 | H2: 15809
A3: HDVs | B3: 300 | C3: 123405.86 | D3: 98369.805 | E3: 703911.93 | F3: 0 | G3: 41837.429 | H3: 105.31557
A4: aircraft | B4: 0 | C4: 0 | D4: 0 | E4: 0 | F4: 0 | G4: 0 | H4: 0
A5: rail | B5: 2563.606 | C5: 0 | D5: 0 | E5: 173.39396 | F5: 0 | G5: 0 | H5: 0
A6: ships | B6: 0 | C6: 0 | D6: 10231405 | E6: 2473594.5 | F6: 0 | G6: 0 | H6: 0
A7: motorbikes | B7: 0 | C7: 0 | D7: 9516910 | E7: 0 | F7: 0 | G7: 0 | H7: 0

Sheet Data
A1: We use sigmoidal interpolation for relatively new technologies (battery electric vehicles, natural gas vehicles, and | H1: Sigmoidal Curve Values for Vehicle Technologies (all except battery electric passenger LDVs) | Q1: Sigmoidal Curve Values for battery electric passenger LDV Technologies | T1: Sigmoidal Curve Values for battery electric freight HDV Technologies | W1: Sigmoidal Curve Values for PHEV passenger LDV Technologies | Z1: Sigmoidal Curve Values for battery electric/PHEV passenger HDV and freight LDV Technologies
A2: plugin hybrid vehicles) and linear interpolation for other vehicle technologies. Technologies with constant values | H2: L | I2: 1 | Q2: L | R2: 1 | T2: L | U2: 1 | W2: L | X2: 1 | Z2: L | AA2: 1
A3: do not require interpolation. | H3: k | I3: -0.3 | Q3: k | R3: -0.3 | S3: -0.35 | T3: k | U3: -0.3 | W3: k | X3: -0.4 | Z3: k | AA3: -0.3
A4: The values (to the right) that define the shape of the sigmoidal curve are assumptions, which neatly approach the | H4: Xo | I4: -16 | Q4: Xo | R4: -11 | S4: -10 | T4: Xo | U4: -12 | W4: Xo | X4: -11 | Z4: Xo | AA4: -14
A5: specified 2050 max sales share with a flattening curve. (Of course, linear interpolation is similarly an assumption.)
E6: Max Potential Sales Share | F6: Max Potential Sales Share | G6: Interpolation Method
C7: Psgr LDVs only | E7: 2020 | F7: 2050
D8: 2024 and 2025 shareweights for onroad vehicle types copied/pasted from the Python solver outputs, explained on the About page | G8: *for passenger LDVs only, see Assumptions page
A9: Vehicle Type | B9: Cargo Type | C9: Vehicle Technology | D9: 2021 | E9: 2025 | F9: 2050 | H9: date | I9: =D9 -> 2021 | J9: 2022 | K9: 2023 | L9: 2024 | M9: =E9 -> 2025 | N9: =M9+1 -> 2026 | O9: =N9+1 -> 2027 | P9: =O9+1 -> 2028 | Q9: =P9+1 -> 2029 | R9: =Q9+1 -> 2030 | S9: =R9+1 -> 2031 | T9: =S9+1 -> 2032 | U9: =T9+1 -> 2033 | ... BF9: =BE9+1 -> 2070
A10: LDVs | B10: passenger | C10: battery electric vehicle | D10: 0.01 | E10: 0.05 | F10: 1 | G10: =IF(E10=F10,"n/a",IF(OR(C10="battery electric vehicle",C10="natural gas vehicle",C10="plugin hybrid vehicle"),"s-curve","linear")) -> s-curve | I10: =D10 -> 0.01 | J10: =IFERROR(_xlfn.FORECAST.ETS(J$9,$D10:$E10,$D$9:$E$9,1),0) -> 0.02 | K10: =IFERROR(_xlfn.FORECAST.ETS(K$9,$D10:$E10,$D$9:$E$9,1),0) -> 0.03 | L10: =IFERROR(_xlfn.FORECAST.ETS(L$9,$D10:$E10,$D$9:$E$9,1),0) -> 0.04 | M10: =E10 -> 0.05 | N10: =IF($G10="s-curve",$E10+($F10-$E10)*$R$2/(1+EXP($R$3*(COUNT($N$9:N$9)+$R$4))),TREND($E10:$F10,$E$9:$F$9,N$9)) -> 0.09505458 | O10: =IF($G10="s-curve",$E10+($F10-$E10)*$R$2/(1+EXP($R$3*(COUNT($N$9:O$9)+$R$4))),TREND($E10:$F10,$E$9:$F$9,O$9)) -> 0.10982469 | P10: =IF($G10="s-curve",$E10+($F10-$E10)*$R$2/(1+EXP($R$3*(COUNT($N$9:P$9)+$R$4))),TREND($E10:$F10,$E$9:$F$9,P$9)) -> 0.12901406 | Q10: =IF($G10="s-curve",$E10+($F10-$E10)*$R$2/(1+EXP($R$3*(COUNT($N$9:Q$9)+$R$4))),TREND($E10:$F10,$E$9:$F$9,Q$9)) -> 0.15364198 | R10: =IF($G10="s-curve",$E10+($F10-$E10)*$R$2/(1+EXP($R$3*(COUNT($N$9:R$9)+$R$4))),TREND($E10:$F10,$E$9:$F$9,R$9)) -> 0.18475851 | S10: =IF($G10="s-curve",$E10+($F10-$E10)*$R$2/(1+EXP($R$3*(COUNT($N$9:S$9)+$R$4))),TREND($E10:$F10,$E$9:$F$9,S$9)) -> 0.22330425 | T10: =IF($G10="s-curve",$E10+($F10-$E10)*$R$2/(1+EXP($R$3*(COUNT($N$9:T$9)+$R$4))),TREND($E10:$F10,$E$9:$F$9,T$9)) -> 0.26990146 | U10: =IF($G10="s-curve",$E10+($F10-$E10)*$R$2/(1+EXP($R$3*(COUNT($N$9:U$9)+$R$4))),TREND($E10:$F10,$E$9:$F$9,U$9)) -> 0.32459797 | ... BF10: =IF($G10="s-curve",$E10+($F10-$E10)*$R$2/(1+EXP($R$3*(COUNT($N$9:BF$9)+$R$4))),TREND($E10:$F10,$E$9:$F$9,BF$9)) -> 0.99996469
C11: natural gas vehicle | D11: 0.00010005073 | E11: 9.1114482e-05 | F11: =E11 -> 9.1114482e-05 | G11: =IF(E11=F11,"n/a",IF(OR(C11="battery electric vehicle",C11="natural gas vehicle",C11="plugin hybrid vehicle"),"s-curve","linear")) -> n/a | I11: =E11 -> 9.1114482e-05 | J11: =IFERROR(_xlfn.FORECAST.ETS(J$9,$D11:$E11,$D$9:$E$9,1),0) -> 9.7816668e-05 | K11: =IFERROR(_xlfn.FORECAST.ETS(K$9,$D11:$E11,$D$9:$E$9,1),0) -> 9.5582606e-05 | L11: =IFERROR(_xlfn.FORECAST.ETS(L$9,$D11:$E11,$D$9:$E$9,1),0) -> 9.3348544e-05 | M11: =IF($G11="s-curve",$E11+($F11-$E11)*$I$2/(1+EXP($I$3*(COUNT($I$9:M$9)+$I$4))),TREND($E11:$F11,$E$9:$F$9,M$9)) -> 9.1114482e-05 | N11: =IF($G11="s-curve",$E11+($F11-$E11)*$I$2/(1+EXP($I$3*(COUNT($I$9:N$9)+$I$4))),TREND($E11:$F11,$E$9:$F$9,N$9)) -> 9.1114482e-05 | O11: =IF($G11="s-curve",$E11+($F11-$E11)*$I$2/(1+EXP($I$3*(COUNT($I$9:O$9)+$I$4))),TREND($E11:$F11,$E$9:$F$9,O$9)) -> 9.1114482e-05 | P11: =IF($G11="s-curve",$E11+($F11-$E11)*$I$2/(1+EXP($I$3*(COUNT($I$9:P$9)+$I$4))),TREND($E11:$F11,$E$9:$F$9,P$9)) -> 9.1114482e-05 | Q11: =IF($G11="s-curve",$E11+($F11-$E11)*$I$2/(1+EXP($I$3*(COUNT($I$9:Q$9)+$I$4))),TREND($E11:$F11,$E$9:$F$9,Q$9)) -> 9.1114482e-05 | R11: =IF($G11="s-curve",$E11+($F11-$E11)*$I$2/(1+EXP($I$3*(COUNT($I$9:R$9)+$I$4))),TREND($E11:$F11,$E$9:$F$9,R$9)) -> 9.1114482e-05 | S11: =IF($G11="s-curve",$E11+($F11-$E11)*$I$2/(1+EXP($I$3*(COUNT($I$9:S$9)+$I$4))),TREND($E11:$F11,$E$9:$F$9,S$9)) -> 9.1114482e-05 | T11: =IF($G11="s-curve",$E11+($F11-$E11)*$I$2/(1+EXP($I$3*(COUNT($I$9:T$9)+$I$4))),TREND($E11:$F11,$E$9:$F$9,T$9)) -> 9.1114482e-05 | ... BF11: =IF($G11="s-curve",$E11+($F11-$E11)*$I$2/(1+EXP($I$3*(COUNT($I$9:BF$9)+$I$4))),TREND($E11:$F11,$E$9:$F$9,BF$9)) -> 9.1114482e-05
C12: gasoline vehicle | D12: 1 | E12: 1 | F12: 1 | G12: =IF(E12=F12,"n/a",IF(OR(C12="battery electric vehicle",C12="natural gas vehicle",C12="plugin hybrid vehicle"),"s-curve","linear")) -> n/a | I12: =E12 -> 1 | J12: =IFERROR(_xlfn.FORECAST.ETS(J$9,$D12:$E12,$D$9:$E$9,1),0) -> 1 | K12: =IFERROR(_xlfn.FORECAST.ETS(K$9,$D12:$E12,$D$9:$E$9,1),0) -> 1 | L12: =IFERROR(_xlfn.FORECAST.ETS(L$9,$D12:$E12,$D$9:$E$9,1),0) -> 1 | M12: =IF($G12="s-curve",$E12+($F12-$E12)*$I$2/(1+EXP($I$3*(COUNT($I$9:M$9)+$I$4))),TREND($E12:$F12,$E$9:$F$9,M$9)) -> 1 | N12: =IF($G12="s-curve",$E12+($F12-$E12)*$I$2/(1+EXP($I$3*(COUNT($I$9:N$9)+$I$4))),TREND($E12:$F12,$E$9:$F$9,N$9)) -> 1 | O12: =IF($G12="s-curve",$E12+($F12-$E12)*$I$2/(1+EXP($I$3*(COUNT($I$9:O$9)+$I$4))),TREND($E12:$F12,$E$9:$F$9,O$9)) -> 1 | P12: =IF($G12="s-curve",$E12+($F12-$E12)*$I$2/(1+EXP($I$3*(COUNT($I$9:P$9)+$I$4))),TREND($E12:$F12,$E$9:$F$9,P$9)) -> 1 | Q12: =IF($G12="s-curve",$E12+($F12-$E12)*$I$2/(1+EXP($I$3*(COUNT($I$9:Q$9)+$I$4))),TREND($E12:$F12,$E$9:$F$9,Q$9)) -> 1 | R12: =IF($G12="s-curve",$E12+($F12-$E12)*$I$2/(1+EXP($I$3*(COUNT($I$9:R$9)+$I$4))),TREND($E12:$F12,$E$9:$F$9,R$9)) -> 1 | S12: =IF($G12="s-curve",$E12+($F12-$E12)*$I$2/(1+EXP($I$3*(COUNT($I$9:S$9)+$I$4))),TREND($E12:$F12,$E$9:$F$9,S$9)) -> 1 | T12: =IF($G12="s-curve",$E12+($F12-$E12)*$I$2/(1+EXP($I$3*(COUNT($I$9:T$9)+$I$4))),TREND($E12:$F12,$E$9:$F$9,T$9)) -> 1 | ... BF12: =IF($G12="s-curve",$E12+($F12-$E12)*$I$2/(1+EXP($I$3*(COUNT($I$9:BF$9)+$I$4))),TREND($E12:$F12,$E$9:$F$9,BF$9)) -> 1
C13: diesel vehicle | D13: 0.066777916 | E13: 0.060802312 | F13: =E13 -> 0.060802312 | G13: =IF(E13=F13,"n/a",IF(OR(C13="battery electric vehicle",C13="natural gas vehicle",C13="plugin hybrid vehicle"),"s-curve","linear")) -> n/a | I13: =E13 -> 0.060802312 | J13: =IFERROR(_xlfn.FORECAST.ETS(J$9,$D13:$E13,$D$9:$E$9,1),0) -> 0.065284015 | K13: =IFERROR(_xlfn.FORECAST.ETS(K$9,$D13:$E13,$D$9:$E$9,1),0) -> 0.063790114 | L13: =IFERROR(_xlfn.FORECAST.ETS(L$9,$D13:$E13,$D$9:$E$9,1),0) -> 0.062296213 | M13: =IF($G13="s-curve",$E13+($F13-$E13)*$I$2/(1+EXP($I$3*(COUNT($I$9:M$9)+$I$4))),TREND($E13:$F13,$E$9:$F$9,M$9)) -> 0.060802312 | N13: =IF($G13="s-curve",$E13+($F13-$E13)*$I$2/(1+EXP($I$3*(COUNT($I$9:N$9)+$I$4))),TREND($E13:$F13,$E$9:$F$9,N$9)) -> 0.060802312 | O13: =IF($G13="s-curve",$E13+($F13-$E13)*$I$2/(1+EXP($I$3*(COUNT($I$9:O$9)+$I$4))),TREND($E13:$F13,$E$9:$F$9,O$9)) -> 0.060802312 | P13: =IF($G13="s-curve",$E13+($F13-$E13)*$I$2/(1+EXP($I$3*(COUNT($I$9:P$9)+$I$4))),TREND($E13:$F13,$E$9:$F$9,P$9)) -> 0.060802312 | Q13: =IF($G13="s-curve",$E13+($F13-$E13)*$I$2/(1+EXP($I$3*(COUNT($I$9:Q$9)+$I$4))),TREND($E13:$F13,$E$9:$F$9,Q$9)) -> 0.060802312 | R13: =IF($G13="s-curve",$E13+($F13-$E13)*$I$2/(1+EXP($I$3*(COUNT($I$9:R$9)+$I$4))),TREND($E13:$F13,$E$9:$F$9,R$9)) -> 0.060802312 | S13: =IF($G13="s-curve",$E13+($F13-$E13)*$I$2/(1+EXP($I$3*(COUNT($I$9:S$9)+$I$4))),TREND($E13:$F13,$E$9:$F$9,S$9)) -> 0.060802312 | T13: =IF($G13="s-curve",$E13+($F13-$E13)*$I$2/(1+EXP($I$3*(COUNT($I$9:T$9)+$I$4))),TREND($E13:$F13,$E$9:$F$9,T$9)) -> 0.060802312 | ... BF13: =IF($G13="s-curve",$E13+($F13-$E13)*$I$2/(1+EXP($I$3*(COUNT($I$9:BF$9)+$I$4))),TREND($E13:$F13,$E$9:$F$9,BF$9)) -> 0.060802312
C14: plugin hybrid vehicle | D14: 0.01546374 | E14: 0 | F14: =D14/D10*F10 -> 1.546374 | G14: =IF(E14=F14,"n/a",IF(OR(C14="battery electric vehicle",C14="natural gas vehicle",C14="plugin hybrid vehicle",C14="hydrogen vehicle"),"s-curve","linear")) -> s-curve | I14: =D14 -> 0.01546374 | J14: =IFERROR(_xlfn.FORECAST.ETS(J$9,$D14:$E14,$D$9:$E$9,1),0) -> 0.011597805 | K14: =IFERROR(_xlfn.FORECAST.ETS(K$9,$D14:$E14,$D$9:$E$9,1),0) -> 0.0077318701 | L14: =IFERROR(_xlfn.FORECAST.ETS(L$9,$D14:$E14,$D$9:$E$9,1),0) -> 0.003865935 | M14: =E14 -> 0 | N14: =IF($G14="s-curve",$E14+($F14-$E14)*$X$2/(1+EXP($X$3*(COUNT($I$9:N$9)+$X$4))),TREND($E14:$F14,$E$9:$F$9,N$9)) -> 0.1843323 | O14: =IF($G14="s-curve",$E14+($F14-$E14)*$X$2/(1+EXP($X$3*(COUNT($I$9:O$9)+$X$4))),TREND($E14:$F14,$E$9:$F$9,O$9)) -> 0.25976241 | P14: =IF($G14="s-curve",$E14+($F14-$E14)*$X$2/(1+EXP($X$3*(COUNT($I$9:P$9)+$X$4))),TREND($E14:$F14,$E$9:$F$9,P$9)) -> 0.35794726 | Q14: =IF($G14="s-curve",$E14+($F14-$E14)*$X$2/(1+EXP($X$3*(COUNT($I$9:Q$9)+$X$4))),TREND($E14:$F14,$E$9:$F$9,Q$9)) -> 0.47941541 | R14: =IF($G14="s-curve",$E14+($F14-$E14)*$X$2/(1+EXP($X$3*(COUNT($I$9:R$9)+$X$4))),TREND($E14:$F14,$E$9:$F$9,R$9)) -> 0.62057898 | S14: =IF($G14="s-curve",$E14+($F14-$E14)*$X$2/(1+EXP($X$3*(COUNT($I$9:S$9)+$X$4))),TREND($E14:$F14,$E$9:$F$9,S$9)) -> 0.77318701 | T14: =IF($G14="s-curve",$E14+($F14-$E14)*$X$2/(1+EXP($X$3*(COUNT($I$9:T$9)+$X$4))),TREND($E14:$F14,$E$9:$F$9,T$9)) -> 0.92579504 | U14: =IF($G14="s-curve",$E14+($F14-$E14)*$X$2/(1+EXP($X$3*(COUNT($I$9:U$9)+$X$4))),TREND($E14:$F14,$E$9:$F$9,U$9)) -> 1.0669586 | ... BF14: =IF($G14="s-curve",$E14+($F14-$E14)*$X$2/(1+EXP($X$3*(COUNT($I$9:BF$9)+$X$4))),TREND($E14:$F14,$E$9:$F$9,BF$9)) -> 1.5463738
C15: LPG vehicle | D15: 0 | E15: 0 | F15: =E15 -> 0 | G15: =IF(E15=F15,"n/a",IF(OR(C15="battery electric vehicle",C15="natural gas vehicle",C15="plugin hybrid vehicle",C15="hydrogen vehicle"),"s-curve","linear")) -> n/a | I15: =E15 -> 0 | J15: =IFERROR(_xlfn.FORECAST.ETS(J$9,$D15:$E15,$D$9:$E$9,1),0) -> 0 | K15: =IFERROR(_xlfn.FORECAST.ETS(K$9,$D15:$E15,$D$9:$E$9,1),0) -> 0 | L15: =IFERROR(_xlfn.FORECAST.ETS(L$9,$D15:$E15,$D$9:$E$9,1),0) -> 0 | M15: =IF($G15="s-curve",$E15+($F15-$E15)*$I$2/(1+EXP($I$3*(COUNT($I$9:M$9)+$I$4))),TREND($E15:$F15,$E$9:$F$9,M$9)) -> 0 | N15: =IF($G15="s-curve",$E15+($F15-$E15)*$I$2/(1+EXP($I$3*(COUNT($I$9:N$9)+$I$4))),TREND($E15:$F15,$E$9:$F$9,N$9)) -> 0 | O15: =IF($G15="s-curve",$E15+($F15-$E15)*$I$2/(1+EXP($I$3*(COUNT($I$9:O$9)+$I$4))),TREND($E15:$F15,$E$9:$F$9,O$9)) -> 0 | P15: =IF($G15="s-curve",$E15+($F15-$E15)*$I$2/(1+EXP($I$3*(COUNT($I$9:P$9)+$I$4))),TREND($E15:$F15,$E$9:$F$9,P$9)) -> 0 | Q15: =IF($G15="s-curve",$E15+($F15-$E15)*$I$2/(1+EXP($I$3*(COUNT($I$9:Q$9)+$I$4))),TREND($E15:$F15,$E$9:$F$9,Q$9)) -> 0 | R15: =IF($G15="s-curve",$E15+($F15-$E15)*$I$2/(1+EXP($I$3*(COUNT($I$9:R$9)+$I$4))),TREND($E15:$F15,$E$9:$F$9,R$9)) -> 0 | S15: =IF($G15="s-curve",$E15+($F15-$E15)*$I$2/(1+EXP($I$3*(COUNT($I$9:S$9)+$I$4))),TREND($E15:$F15,$E$9:$F$9,S$9)) -> 0 | T15: =IF($G15="s-curve",$E15+($F15-$E15)*$I$2/(1+EXP($I$3*(COUNT($I$9:T$9)+$I$4))),TREND($E15:$F15,$E$9:$F$9,T$9)) -> 0 | ... BF15: =IF($G15="s-curve",$E15+($F15-$E15)*$I$2/(1+EXP($I$3*(COUNT($I$9:BF$9)+$I$4))),TREND($E15:$F15,$E$9:$F$9,BF$9)) -> 0
C16: hydrogen vehicle | D16: 0 | E16: 0 | F16: =E16 -> 0 | G16: =IF(E16=F16,"n/a",IF(OR(C16="battery electric vehicle",C16="natural gas vehicle",C16="plugin hybrid vehicle",C16="hydrogen vehicle"),"s-curve","linear")) -> n/a | I16: =E16 -> 0 | J16: =IFERROR(_xlfn.FORECAST.ETS(J$9,$D16:$E16,$D$9:$E$9,1),0) -> 0 | K16: =IFERROR(_xlfn.FORECAST.ETS(K$9,$D16:$E16,$D$9:$E$9,1),0) -> 0 | L16: =IFERROR(_xlfn.FORECAST.ETS(L$9,$D16:$E16,$D$9:$E$9,1),0) -> 0 | M16: =IF($G16="s-curve",$E16+($F16-$E16)*$I$2/(1+EXP($I$3*(COUNT($I$9:M$9)+$I$4))),TREND($E16:$F16,$E$9:$F$9,M$9)) -> 0 | N16: =IF($G16="s-curve",$E16+($F16-$E16)*$I$2/(1+EXP($I$3*(COUNT($I$9:N$9)+$I$4))),TREND($E16:$F16,$E$9:$F$9,N$9)) -> 0 | O16: =IF($G16="s-curve",$E16+($F16-$E16)*$I$2/(1+EXP($I$3*(COUNT($I$9:O$9)+$I$4))),TREND($E16:$F16,$E$9:$F$9,O$9)) -> 0 | P16: =IF($G16="s-curve",$E16+($F16-$E16)*$I$2/(1+EXP($I$3*(COUNT($I$9:P$9)+$I$4))),TREND($E16:$F16,$E$9:$F$9,P$9)) -> 0 | Q16: =IF($G16="s-curve",$E16+($F16-$E16)*$I$2/(1+EXP($I$3*(COUNT($I$9:Q$9)+$I$4))),TREND($E16:$F16,$E$9:$F$9,Q$9)) -> 0 | R16: =IF($G16="s-curve",$E16+($F16-$E16)*$I$2/(1+EXP($I$3*(COUNT($I$9:R$9)+$I$4))),TREND($E16:$F16,$E$9:$F$9,R$9)) -> 0 | S16: =IF($G16="s-curve",$E16+($F16-$E16)*$I$2/(1+EXP($I$3*(COUNT($I$9:S$9)+$I$4))),TREND($E16:$F16,$E$9:$F$9,S$9)) -> 0 | T16: =IF($G16="s-curve",$E16+($F16-$E16)*$I$2/(1+EXP($I$3*(COUNT($I$9:T$9)+$I$4))),TREND($E16:$F16,$E$9:$F$9,T$9)) -> 0 | ... BF16: =IF($G16="s-curve",$E16+($F16-$E16)*$I$2/(1+EXP($I$3*(COUNT($I$9:BF$9)+$I$4))),TREND($E16:$F16,$E$9:$F$9,BF$9)) -> 0
A17: LDVs | B17: freight | C17: battery electric vehicle | D17: 0.26000977 | E17: 0.1110976 | F17: 0.3 | G17: =IF(E17=F17,"n/a",IF(OR(C17="battery electric vehicle",C17="natural gas vehicle",C17="plugin hybrid vehicle"),"s-curve","linear")) -> s-curve | I17: =D17 -> 0.26000977 | J17: =IFERROR(_xlfn.FORECAST.ETS(J$9,$D17:$E17,$D$9:$E$9,1),0) -> 0.22278173 | K17: =IFERROR(_xlfn.FORECAST.ETS(K$9,$D17:$E17,$D$9:$E$9,1),0) -> 0.18555368 | L17: =IFERROR(_xlfn.FORECAST.ETS(L$9,$D17:$E17,$D$9:$E$9,1),0) -> 0.14832564 | M17: =IF($G17="s-curve",$E17+($F17-$E17)*$AA$2/(1+EXP($AA$3*(COUNT($I$9:M$9)+$AA$4))),TREND($E17:$F17,$E$9:$F$9,M$9)) -> 0.12299342 | N17: =IF($G17="s-curve",$D17+($F17-$D17)*$AA$2/(1+EXP($AA$3*(COUNT($I$9:N$9)+$AA$4))),TREND($D17:$F17,$E$9:$F$9,N$9)) -> 0.26333586 | O17: =IF($G17="s-curve",$D17+($F17-$D17)*$AA$2/(1+EXP($AA$3*(COUNT($I$9:O$9)+$AA$4))),TREND($D17:$F17,$E$9:$F$9,O$9)) -> 0.26437257 | P17: =IF($G17="s-curve",$D17+($F17-$D17)*$AA$2/(1+EXP($AA$3*(COUNT($I$9:P$9)+$AA$4))),TREND($D17:$F17,$E$9:$F$9,P$9)) -> 0.26568242 | Q17: =IF($G17="s-curve",$D17+($F17-$D17)*$AA$2/(1+EXP($AA$3*(COUNT($I$9:Q$9)+$AA$4))),TREND($D17:$F17,$E$9:$F$9,Q$9)) -> 0.26730501 | R17: =IF($G17="s-curve",$D17+($F17-$D17)*$AA$2/(1+EXP($AA$3*(COUNT($I$9:R$9)+$AA$4))),TREND($D17:$F17,$E$9:$F$9,R$9)) -> 0.26926651 | S17: =IF($G17="s-curve",$D17+($F17-$D17)*$AA$2/(1+EXP($AA$3*(COUNT($I$9:S$9)+$AA$4))),TREND($D17:$F17,$E$9:$F$9,S$9)) -> 0.27156896 | T17: =IF($G17="s-curve",$D17+($F17-$D17)*$AA$2/(1+EXP($AA$3*(COUNT($I$9:T$9)+$AA$4))),TREND($D17:$F17,$E$9:$F$9,T$9)) -> 0.27418005 | U17: =IF($G17="s-curve",$D17+($F17-$D17)*$AA$2/(1+EXP($AA$3*(COUNT($I$9:U$9)+$AA$4))),TREND($D17:$F17,$E$9:$F$9,U$9)) -> 0.27702791 | ... BF17: =IF($G17="s-curve",$D17+($F17-$D17)*$AA$2/(1+EXP($AA$3*(COUNT($I$9:BF$9)+$AA$4))),TREND($D17:$F17,$E$9:$F$9,BF$9)) -> 0.29999918
C18: natural gas vehicle | D18: 0 | E18: 0 | F18: =E18 -> 0 | G18: linear | I18: =D18 -> 0 | J18: =IFERROR(_xlfn.FORECAST.ETS(J$9,$D18:$E18,$D$9:$E$9,1),0) -> 0 | K18: =IFERROR(_xlfn.FORECAST.ETS(K$9,$D18:$E18,$D$9:$E$9,1),0) -> 0 | L18: =IFERROR(_xlfn.FORECAST.ETS(L$9,$D18:$E18,$D$9:$E$9,1),0) -> 0 | M18: =E18 -> 0 | N18: =IF($G18="s-curve",$E18+($F18-$E18)*$I$2/(1+EXP($I$3*(COUNT($I$9:N$9)+$I$4))),TREND($E18:$F18,$E$9:$F$9,N$9)) -> 0 | O18: =IF($G18="s-curve",$E18+($F18-$E18)*$I$2/(1+EXP($I$3*(COUNT($I$9:O$9)+$I$4))),TREND($E18:$F18,$E$9:$F$9,O$9)) -> 0 | P18: =IF($G18="s-curve",$E18+($F18-$E18)*$I$2/(1+EXP($I$3*(COUNT($I$9:P$9)+$I$4))),TREND($E18:$F18,$E$9:$F$9,P$9)) -> 0 | Q18: =IF($G18="s-curve",$E18+($F18-$E18)*$I$2/(1+EXP($I$3*(COUNT($I$9:Q$9)+$I$4))),TREND($E18:$F18,$E$9:$F$9,Q$9)) -> 0 | R18: =IF($G18="s-curve",$E18+($F18-$E18)*$I$2/(1+EXP($I$3*(COUNT($I$9:R$9)+$I$4))),TREND($E18:$F18,$E$9:$F$9,R$9)) -> 0 | S18: =IF($G18="s-curve",$E18+($F18-$E18)*$I$2/(1+EXP($I$3*(COUNT($I$9:S$9)+$I$4))),TREND($E18:$F18,$E$9:$F$9,S$9)) -> 0 | T18: =IF($G18="s-curve",$E18+($F18-$E18)*$I$2/(1+EXP($I$3*(COUNT($I$9:T$9)+$I$4))),TREND($E18:$F18,$E$9:$F$9,T$9)) -> 0 | U18: =IF($G18="s-curve",$E18+($F18-$E18)*$I$2/(1+EXP($I$3*(COUNT($I$9:U$9)+$I$4))),TREND($E18:$F18,$E$9:$F$9,U$9)) -> 0 | ... BF18: =IF($G18="s-curve",$E18+($F18-$E18)*$I$2/(1+EXP($I$3*(COUNT($I$9:BF$9)+$I$4))),TREND($E18:$F18,$E$9:$F$9,BF$9)) -> 0
C19: gasoline vehicle | D19: 0.9008381 | E19: 0.83821627 | F19: =E19 -> 0.83821627 | G19: =IF(E19=F19,"n/a",IF(OR(C19="battery electric vehicle",C19="natural gas vehicle",C19="plugin hybrid vehicle"),"s-curve","linear")) -> n/a | I19: =D19 -> 0.9008381 | J19: =IFERROR(_xlfn.FORECAST.ETS(J$9,$D19:$E19,$D$9:$E$9,1),0) -> 0.88518264 | K19: =IFERROR(_xlfn.FORECAST.ETS(K$9,$D19:$E19,$D$9:$E$9,1),0) -> 0.86952718 | L19: =IFERROR(_xlfn.FORECAST.ETS(L$9,$D19:$E19,$D$9:$E$9,1),0) -> 0.85387172 | M19: =E19 -> 0.83821627 | N19: =IF($G19="s-curve",$E19+($F19-$E19)*$I$2/(1+EXP($I$3*(COUNT($I$9:N$9)+$I$4))),TREND($E19:$F19,$E$9:$F$9,N$9)) -> 0.83821627 | O19: =IF($G19="s-curve",$E19+($F19-$E19)*$I$2/(1+EXP($I$3*(COUNT($I$9:O$9)+$I$4))),TREND($E19:$F19,$E$9:$F$9,O$9)) -> 0.83821627 | P19: =IF($G19="s-curve",$E19+($F19-$E19)*$I$2/(1+EXP($I$3*(COUNT($I$9:P$9)+$I$4))),TREND($E19:$F19,$E$9:$F$9,P$9)) -> 0.83821627 | Q19: =IF($G19="s-curve",$E19+($F19-$E19)*$I$2/(1+EXP($I$3*(COUNT($I$9:Q$9)+$I$4))),TREND($E19:$F19,$E$9:$F$9,Q$9)) -> 0.83821627 | R19: =IF($G19="s-curve",$E19+($F19-$E19)*$I$2/(1+EXP($I$3*(COUNT($I$9:R$9)+$I$4))),TREND($E19:$F19,$E$9:$F$9,R$9)) -> 0.83821627 | S19: =IF($G19="s-curve",$E19+($F19-$E19)*$I$2/(1+EXP($I$3*(COUNT($I$9:S$9)+$I$4))),TREND($E19:$F19,$E$9:$F$9,S$9)) -> 0.83821627 | T19: =IF($G19="s-curve",$E19+($F19-$E19)*$I$2/(1+EXP($I$3*(COUNT($I$9:T$9)+$I$4))),TREND($E19:$F19,$E$9:$F$9,T$9)) -> 0.83821627 | U19: =IF($G19="s-curve",$E19+($F19-$E19)*$I$2/(1+EXP($I$3*(COUNT($I$9:U$9)+$I$4))),TREND($E19:$F19,$E$9:$F$9,U$9)) -> 0.83821627 | ... BF19: =IF($G19="s-curve",$E19+($F19-$E19)*$I$2/(1+EXP($I$3*(COUNT($I$9:BF$9)+$I$4))),TREND($E19:$F19,$E$9:$F$9,BF$9)) -> 0.83821627
C20: diesel vehicle | D20: 1 | E20: 1 | F20: 1 | G20: =IF(E20=F20,"n/a",IF(OR(C20="battery electric vehicle",C20="natural gas vehicle",C20="plugin hybrid vehicle"),"s-curve","linear")) -> n/a | I20: =D20 -> 1 | J20: =IFERROR(_xlfn.FORECAST.ETS(J$9,$D20:$E20,$D$9:$E$9,1),0) -> 1 | K20: =IFERROR(_xlfn.FORECAST.ETS(K$9,$D20:$E20,$D$9:$E$9,1),0) -> 1 | L20: =IFERROR(_xlfn.FORECAST.ETS(L$9,$D20:$E20,$D$9:$E$9,1),0) -> 1 | M20: =E20 -> 1 | N20: =IF($G20="s-curve",$E20+($F20-$E20)*$I$2/(1+EXP($I$3*(COUNT($I$9:N$9)+$I$4))),TREND($E20:$F20,$E$9:$F$9,N$9)) -> 1 | O20: =IF($G20="s-curve",$E20+($F20-$E20)*$I$2/(1+EXP($I$3*(COUNT($I$9:O$9)+$I$4))),TREND($E20:$F20,$E$9:$F$9,O$9)) -> 1 | P20: =IF($G20="s-curve",$E20+($F20-$E20)*$I$2/(1+EXP($I$3*(COUNT($I$9:P$9)+$I$4))),TREND($E20:$F20,$E$9:$F$9,P$9)) -> 1 | Q20: =IF($G20="s-curve",$E20+($F20-$E20)*$I$2/(1+EXP($I$3*(COUNT($I$9:Q$9)+$I$4))),TREND($E20:$F20,$E$9:$F$9,Q$9)) -> 1 | R20: =IF($G20="s-curve",$E20+($F20-$E20)*$I$2/(1+EXP($I$3*(COUNT($I$9:R$9)+$I$4))),TREND($E20:$F20,$E$9:$F$9,R$9)) -> 1 | S20: =IF($G20="s-curve",$E20+($F20-$E20)*$I$2/(1+EXP($I$3*(COUNT($I$9:S$9)+$I$4))),TREND($E20:$F20,$E$9:$F$9,S$9)) -> 1 | T20: =IF($G20="s-curve",$E20+($F20-$E20)*$I$2/(1+EXP($I$3*(COUNT($I$9:T$9)+$I$4))),TREND($E20:$F20,$E$9:$F$9,T$9)) -> 1 | U20: =IF($G20="s-curve",$E20+($F20-$E20)*$I$2/(1+EXP($I$3*(COUNT($I$9:U$9)+$I$4))),TREND($E20:$F20,$E$9:$F$9,U$9)) -> 1 | ... BF20: =IF($G20="s-curve",$E20+($F20-$E20)*$I$2/(1+EXP($I$3*(COUNT($I$9:BF$9)+$I$4))),TREND($E20:$F20,$E$9:$F$9,BF$9)) -> 1
C21: plugin hybrid vehicle | D21: 0 | E21: 0.00067529269 | F21: =E21/E17*F17 -> 0.001823512 | G21: s-curve | I21: =D21 -> 0 | J21: =IFERROR(_xlfn.FORECAST.ETS(J$9,$D21:$E21,$D$9:$E$9,1),0) -> 0.00016882317 | K21: =IFERROR(_xlfn.FORECAST.ETS(K$9,$D21:$E21,$D$9:$E$9,1),0) -> 0.00033764635 | L21: =IFERROR(_xlfn.FORECAST.ETS(L$9,$D21:$E21,$D$9:$E$9,1),0) -> 0.00050646952 | M21: =E21 -> 0.00067529269 | N21: =IF($G21="s-curve",$E21+($F21-$E21)*$AA$2/(1+EXP($AA$3*(COUNT($I$9:N$9)+$AA$4))),TREND($E21:$F21,$E$9:$F$9,N$9)) -> 0.00077079319 | O21: =IF($G21="s-curve",$E21+($F21-$E21)*$AA$2/(1+EXP($AA$3*(COUNT($I$9:O$9)+$AA$4))),TREND($E21:$F21,$E$9:$F$9,O$9)) -> 0.00080055977 | P21: =IF($G21="s-curve",$E21+($F21-$E21)*$AA$2/(1+EXP($AA$3*(COUNT($I$9:P$9)+$AA$4))),TREND($E21:$F21,$E$9:$F$9,P$9)) -> 0.00083816882 | Q21: =IF($G21="s-curve",$E21+($F21-$E21)*$AA$2/(1+EXP($AA$3*(COUNT($I$9:Q$9)+$AA$4))),TREND($E21:$F21,$E$9:$F$9,Q$9)) -> 0.0008847572 | R21: =IF($G21="s-curve",$E21+($F21-$E21)*$AA$2/(1+EXP($AA$3*(COUNT($I$9:R$9)+$AA$4))),TREND($E21:$F21,$E$9:$F$9,R$9)) -> 0.000941077 | S21: =IF($G21="s-curve",$E21+($F21-$E21)*$AA$2/(1+EXP($AA$3*(COUNT($I$9:S$9)+$AA$4))),TREND($E21:$F21,$E$9:$F$9,S$9)) -> 0.0010071861 | T21: =IF($G21="s-curve",$E21+($F21-$E21)*$AA$2/(1+EXP($AA$3*(COUNT($I$9:T$9)+$AA$4))),TREND($E21:$F21,$E$9:$F$9,T$9)) -> 0.001082157 | U21: =IF($G21="s-curve",$E21+($F21-$E21)*$AA$2/(1+EXP($AA$3*(COUNT($I$9:U$9)+$AA$4))),TREND($E21:$F21,$E$9:$F$9,U$9)) -> 0.001163926 | ... BF21: =IF($G21="s-curve",$E21+($F21-$E21)*$AA$2/(1+EXP($AA$3*(COUNT($I$9:BF$9)+$AA$4))),TREND($E21:$F21,$E$9:$F$9,BF$9)) -> 0.0018234886
C22: LPG vehicle | D22: 0 | E22: 0 | F22: =E22 -> 0 | G22: =IF(E22=F22,"n/a",IF(OR(C22="battery electric vehicle",C22="natural gas vehicle",C22="plugin hybrid vehicle",C22="hydrogen vehicle"),"s-curve","linear")) -> n/a | I22: =D22 -> 0 | J22: =IFERROR(_xlfn.FORECAST.ETS(J$9,$D22:$E22,$D$9:$E$9,1),0) -> 0 | K22: =IFERROR(_xlfn.FORECAST.ETS(K$9,$D22:$E22,$D$9:$E$9,1),0) -> 0 | L22: =IFERROR(_xlfn.FORECAST.ETS(L$9,$D22:$E22,$D$9:$E$9,1),0) -> 0 | M22: =E22 -> 0 | N22: =IF($G22="s-curve",$E22+($F22-$E22)*$I$2/(1+EXP($I$3*(COUNT($I$9:N$9)+$I$4))),TREND($E22:$F22,$E$9:$F$9,N$9)) -> 0 | O22: =IF($G22="s-curve",$E22+($F22-$E22)*$I$2/(1+EXP($I$3*(COUNT($I$9:O$9)+$I$4))),TREND($E22:$F22,$E$9:$F$9,O$9)) -> 0 | P22: =IF($G22="s-curve",$E22+($F22-$E22)*$I$2/(1+EXP($I$3*(COUNT($I$9:P$9)+$I$4))),TREND($E22:$F22,$E$9:$F$9,P$9)) -> 0 | Q22: =IF($G22="s-curve",$E22+($F22-$E22)*$I$2/(1+EXP($I$3*(COUNT($I$9:Q$9)+$I$4))),TREND($E22:$F22,$E$9:$F$9,Q$9)) -> 0 | R22: =IF($G22="s-curve",$E22+($F22-$E22)*$I$2/(1+EXP($I$3*(COUNT($I$9:R$9)+$I$4))),TREND($E22:$F22,$E$9:$F$9,R$9)) -> 0 | S22: =IF($G22="s-curve",$E22+($F22-$E22)*$I$2/(1+EXP($I$3*(COUNT($I$9:S$9)+$I$4))),TREND($E22:$F22,$E$9:$F$9,S$9)) -> 0 | T22: =IF($G22="s-curve",$E22+($F22-$E22)*$I$2/(1+EXP($I$3*(COUNT($I$9:T$9)+$I$4))),TREND($E22:$F22,$E$9:$F$9,T$9)) -> 0 | U22: =IF($G22="s-curve",$E22+($F22-$E22)*$I$2/(1+EXP($I$3*(COUNT($I$9:U$9)+$I$4))),TREND($E22:$F22,$E$9:$F$9,U$9)) -> 0 | ... BF22: =IF($G22="s-curve",$E22+($F22-$E22)*$I$2/(1+EXP($I$3*(COUNT($I$9:BF$9)+$I$4))),TREND($E22:$F22,$E$9:$F$9,BF$9)) -> 0
C23: hydrogen vehicle | D23: 0 | E23: 0 | F23: =E23 -> 0 | G23: =IF(E23=F23,"n/a",IF(OR(C23="battery electric vehicle",C23="natural gas vehicle",C23="plugin hybrid vehicle",C23="hydrogen vehicle"),"s-curve","linear")) -> n/a | I23: =D23 -> 0 | J23: =IFERROR(_xlfn.FORECAST.ETS(J$9,$D23:$E23,$D$9:$E$9,1),0) -> 0 | K23: =IFERROR(_xlfn.FORECAST.ETS(K$9,$D23:$E23,$D$9:$E$9,1),0) -> 0 | L23: =IFERROR(_xlfn.FORECAST.ETS(L$9,$D23:$E23,$D$9:$E$9,1),0) -> 0 | M23: =E23 -> 0 | N23: =IF($G23="s-curve",$E23+($F23-$E23)*$I$2/(1+EXP($I$3*(COUNT($I$9:N$9)+$I$4))),TREND($E23:$F23,$E$9:$F$9,N$9)) -> 0 | O23: =IF($G23="s-curve",$E23+($F23-$E23)*$I$2/(1+EXP($I$3*(COUNT($I$9:O$9)+$I$4))),TREND($E23:$F23,$E$9:$F$9,O$9)) -> 0 | P23: =IF($G23="s-curve",$E23+($F23-$E23)*$I$2/(1+EXP($I$3*(COUNT($I$9:P$9)+$I$4))),TREND($E23:$F23,$E$9:$F$9,P$9)) -> 0 | Q23: =IF($G23="s-curve",$E23+($F23-$E23)*$I$2/(1+EXP($I$3*(COUNT($I$9:Q$9)+$I$4))),TREND($E23:$F23,$E$9:$F$9,Q$9)) -> 0 | R23: =IF($G23="s-curve",$E23+($F23-$E23)*$I$2/(1+EXP($I$3*(COUNT($I$9:R$9)+$I$4))),TREND($E23:$F23,$E$9:$F$9,R$9)) -> 0 | S23: =IF($G23="s-curve",$E23+($F23-$E23)*$I$2/(1+EXP($I$3*(COUNT($I$9:S$9)+$I$4))),TREND($E23:$F23,$E$9:$F$9,S$9)) -> 0 | T23: =IF($G23="s-curve",$E23+($F23-$E23)*$I$2/(1+EXP($I$3*(COUNT($I$9:T$9)+$I$4))),TREND($E23:$F23,$E$9:$F$9,T$9)) -> 0 | U23: =IF($G23="s-curve",$E23+($F23-$E23)*$I$2/(1+EXP($I$3*(COUNT($I$9:U$9)+$I$4))),TREND($E23:$F23,$E$9:$F$9,U$9)) -> 0 | ... BF23: =IF($G23="s-curve",$E23+($F23-$E23)*$I$2/(1+EXP($I$3*(COUNT($I$9:BF$9)+$I$4))),TREND($E23:$F23,$E$9:$F$9,BF$9)) -> 0
A24: HDVs | B24: passenger | C24: battery electric vehicle | D24: 0.030938507 | E24: 0.030392777 | F24: 0.75 | G24: =IF(E24=F24,"n/a",IF(OR(C24="battery electric vehicle",C24="natural gas vehicle",C24="plugin hybrid vehicle"),"s-curve","linear")) -> s-curve | I24: =D24 -> 0.030938507 | J24: =IFERROR(_xlfn.FORECAST.ETS(J$9,$D24:$E24,$D$9:$E$9,1),0) -> 0.030802074 | K24: =IFERROR(_xlfn.FORECAST.ETS(K$9,$D24:$E24,$D$9:$E$9,1),0) -> 0.030665642 | L24: =IFERROR(_xlfn.FORECAST.ETS(L$9,$D24:$E24,$D$9:$E$9,1),0) -> 0.03052921 | M24: =E24 -> 0.030392777 | N24: =IF($G24="s-curve",$E24+($F24-$E24)*$AA$2/(1+EXP($AA$3*(COUNT($I$9:N$9)+$AA$4))),TREND($E24:$F24,$E$9:$F$9,N$9)) -> 0.09024445 | O24: =IF($G24="s-curve",$E24+($F24-$E24)*$AA$2/(1+EXP($AA$3*(COUNT($I$9:O$9)+$AA$4))),TREND($E24:$F24,$E$9:$F$9,O$9)) -> 0.10889964 | P24: =IF($G24="s-curve",$E24+($F24-$E24)*$AA$2/(1+EXP($AA$3*(COUNT($I$9:P$9)+$AA$4))),TREND($E24:$F24,$E$9:$F$9,P$9)) -> 0.13246983 | Q24: =IF($G24="s-curve",$E24+($F24-$E24)*$AA$2/(1+EXP($AA$3*(COUNT($I$9:Q$9)+$AA$4))),TREND($E24:$F24,$E$9:$F$9,Q$9)) -> 0.1616675 | R24: =IF($G24="s-curve",$E24+($F24-$E24)*$AA$2/(1+EXP($AA$3*(COUNT($I$9:R$9)+$AA$4))),TREND($E24:$F24,$E$9:$F$9,R$9)) -> 0.19696401 | S24: =IF($G24="s-curve",$E24+($F24-$E24)*$AA$2/(1+EXP($AA$3*(COUNT($I$9:S$9)+$AA$4))),TREND($E24:$F24,$E$9:$F$9,S$9)) -> 0.2383956 | T24: =IF($G24="s-curve",$E24+($F24-$E24)*$AA$2/(1+EXP($AA$3*(COUNT($I$9:T$9)+$AA$4))),TREND($E24:$F24,$E$9:$F$9,T$9)) -> 0.28538106 | U24: =IF($G24="s-curve",$E24+($F24-$E24)*$AA$2/(1+EXP($AA$3*(COUNT($I$9:U$9)+$AA$4))),TREND($E24:$F24,$E$9:$F$9,U$9)) -> 0.33662702 | ... BF24: =IF($G24="s-curve",$E24+($F24-$E24)*$AA$2/(1+EXP($AA$3*(COUNT($I$9:BF$9)+$AA$4))),TREND($E24:$F24,$E$9:$F$9,BF$9)) -> 0.74998532
C25: natural gas vehicle | D25: 0 | E25: 0 | F25: =E25 -> 0 | G25: =IF(E25=F25,"n/a",IF(OR(C25="battery electric vehicle",C25="natural gas vehicle",C25="plugin hybrid vehicle"),"s-curve","linear")) -> n/a | I25: =D25 -> 0 | J25: =IFERROR(_xlfn.FORECAST.ETS(J$9,$D25:$E25,$D$9:$E$9,1),0) -> 0 | K25: =IFERROR(_xlfn.FORECAST.ETS(K$9,$D25:$E25,$D$9:$E$9,1),0) -> 0 | L25: =IFERROR(_xlfn.FORECAST.ETS(L$9,$D25:$E25,$D$9:$E$9,1),0) -> 0 | M25: =E25 -> 0 | N25: =IF($G25="s-curve",$E25+($F25-$E25)*$I$2/(1+EXP($I$3*(COUNT($I$9:N$9)+$I$4))),TREND($E25:$F25,$E$9:$F$9,N$9)) -> 0 | O25: =IF($G25="s-curve",$E25+($F25-$E25)*$I$2/(1+EXP($I$3*(COUNT($I$9:O$9)+$I$4))),TREND($E25:$F25,$E$9:$F$9,O$9)) -> 0 | P25: =IF($G25="s-curve",$E25+($F25-$E25)*$I$2/(1+EXP($I$3*(COUNT($I$9:P$9)+$I$4))),TREND($E25:$F25,$E$9:$F$9,P$9)) -> 0 | Q25: =IF($G25="s-curve",$E25+($F25-$E25)*$I$2/(1+EXP($I$3*(COUNT($I$9:Q$9)+$I$4))),TREND($E25:$F25,$E$9:$F$9,Q$9)) -> 0 | R25: =IF($G25="s-curve",$E25+($F25-$E25)*$I$2/(1+EXP($I$3*(COUNT($I$9:R$9)+$I$4))),TREND($E25:$F25,$E$9:$F$9,R$9)) -> 0 | S25: =IF($G25="s-curve",$E25+($F25-$E25)*$I$2/(1+EXP($I$3*(COUNT($I$9:S$9)+$I$4))),TREND($E25:$F25,$E$9:$F$9,S$9)) -> 0 | T25: =IF($G25="s-curve",$E25+($F25-$E25)*$I$2/(1+EXP($I$3*(COUNT($I$9:T$9)+$I$4))),TREND($E25:$F25,$E$9:$F$9,T$9)) -> 0 | U25: =IF($G25="s-curve",$E25+($F25-$E25)*$I$2/(1+EXP($I$3*(COUNT($I$9:U$9)+$I$4))),TREND($E25:$F25,$E$9:$F$9,U$9)) -> 0 | ... BF25: =IF($G25="s-curve",$E25+($F25-$E25)*$I$2/(1+EXP($I$3*(COUNT($I$9:BF$9)+$I$4))),TREND($E25:$F25,$E$9:$F$9,BF$9)) -> 0
C26: gasoline vehicle | D26: 0 | E26: 0 | F26: =E26 -> 0 | G26: =IF(E26=F26,"n/a",IF(OR(C26="battery electric vehicle",C26="natural gas vehicle",C26="plugin hybrid vehicle"),"s-curve","linear")) -> n/a | I26: =D26 -> 0 | J26: =IFERROR(_xlfn.FORECAST.ETS(J$9,$D26:$E26,$D$9:$E$9,1),0) -> 0 | K26: =IFERROR(_xlfn.FORECAST.ETS(K$9,$D26:$E26,$D$9:$E$9,1),0) -> 0 | L26: =IFERROR(_xlfn.FORECAST.ETS(L$9,$D26:$E26,$D$9:$E$9,1),0) -> 0 | M26: =E26 -> 0 | N26: =IF($G26="s-curve",$E26+($F26-$E26)*$I$2/(1+EXP($I$3*(COUNT($I$9:N$9)+$I$4))),TREND($E26:$F26,$E$9:$F$9,N$9)) -> 0 | O26: =IF($G26="s-curve",$E26+($F26-$E26)*$I$2/(1+EXP($I$3*(COUNT($I$9:O$9)+$I$4))),TREND($E26:$F26,$E$9:$F$9,O$9)) -> 0 | P26: =IF($G26="s-curve",$E26+($F26-$E26)*$I$2/(1+EXP($I$3*(COUNT($I$9:P$9)+$I$4))),TREND($E26:$F26,$E$9:$F$9,P$9)) -> 0 | Q26: =IF($G26="s-curve",$E26+($F26-$E26)*$I$2/(1+EXP($I$3*(COUNT($I$9:Q$9)+$I$4))),TREND($E26:$F26,$E$9:$F$9,Q$9)) -> 0 | R26: =IF($G26="s-curve",$E26+($F26-$E26)*$I$2/(1+EXP($I$3*(COUNT($I$9:R$9)+$I$4))),TREND($E26:$F26,$E$9:$F$9,R$9)) -> 0 | S26: =IF($G26="s-curve",$E26+($F26-$E26)*$I$2/(1+EXP($I$3*(COUNT($I$9:S$9)+$I$4))),TREND($E26:$F26,$E$9:$F$9,S$9)) -> 0 | T26: =IF($G26="s-curve",$E26+($F26-$E26)*$I$2/(1+EXP($I$3*(COUNT($I$9:T$9)+$I$4))),TREND($E26:$F26,$E$9:$F$9,T$9)) -> 0 | U26: =IF($G26="s-curve",$E26+($F26-$E26)*$I$2/(1+EXP($I$3*(COUNT($I$9:U$9)+$I$4))),TREND($E26:$F26,$E$9:$F$9,U$9)) -> 0 | ... BF26: =IF($G26="s-curve",$E26+($F26-$E26)*$I$2/(1+EXP($I$3*(COUNT($I$9:BF$9)+$I$4))),TREND($E26:$F26,$E$9:$F$9,BF$9)) -> 0
C27: diesel vehicle | D27: 1 | E27: 1 | F27: 1 | G27: =IF(E27=F27,"n/a",IF(OR(C27="battery electric vehicle",C27="natural gas vehicle",C27="plugin hybrid vehicle"),"s-curve","linear")) -> n/a | I27: =D27 -> 1 | J27: =IFERROR(_xlfn.FORECAST.ETS(J$9,$D27:$E27,$D$9:$E$9,1),0) -> 1 | K27: =IFERROR(_xlfn.FORECAST.ETS(K$9,$D27:$E27,$D$9:$E$9,1),0) -> 1 | L27: =IFERROR(_xlfn.FORECAST.ETS(L$9,$D27:$E27,$D$9:$E$9,1),0) -> 1 | M27: =E27 -> 1 | N27: =IF($G27="s-curve",$E27+($F27-$E27)*$I$2/(1+EXP($I$3*(COUNT($I$9:N$9)+$I$4))),TREND($E27:$F27,$E$9:$F$9,N$9)) -> 1 | O27: =IF($G27="s-curve",$E27+($F27-$E27)*$I$2/(1+EXP($I$3*(COUNT($I$9:O$9)+$I$4))),TREND($E27:$F27,$E$9:$F$9,O$9)) -> 1 | P27: =IF($G27="s-curve",$E27+($F27-$E27)*$I$2/(1+EXP($I$3*(COUNT($I$9:P$9)+$I$4))),TREND($E27:$F27,$E$9:$F$9,P$9)) -> 1 | Q27: =IF($G27="s-curve",$E27+($F27-$E27)*$I$2/(1+EXP($I$3*(COUNT($I$9:Q$9)+$I$4))),TREND($E27:$F27,$E$9:$F$9,Q$9)) -> 1 | R27: =IF($G27="s-curve",$E27+($F27-$E27)*$I$2/(1+EXP($I$3*(COUNT($I$9:R$9)+$I$4))),TREND($E27:$F27,$E$9:$F$9,R$9)) -> 1 | S27: =IF($G27="s-curve",$E27+($F27-$E27)*$I$2/(1+EXP($I$3*(COUNT($I$9:S$9)+$I$4))),TREND($E27:$F27,$E$9:$F$9,S$9)) -> 1 | T27: =IF($G27="s-curve",$E27+($F27-$E27)*$I$2/(1+EXP($I$3*(COUNT($I$9:T$9)+$I$4))),TREND($E27:$F27,$E$9:$F$9,T$9)) -> 1 | U27: =IF($G27="s-curve",$E27+($F27-$E27)*$I$2/(1+EXP($I$3*(COUNT($I$9:U$9)+$I$4))),TREND($E27:$F27,$E$9:$F$9,U$9)) -> 1 | ... BF27: =IF($G27="s-curve",$E27+($F27-$E27)*$I$2/(1+EXP($I$3*(COUNT($I$9:BF$9)+$I$4))),TREND($E27:$F27,$E$9:$F$9,BF$9)) -> 1
C28: plugin hybrid vehicle | D28: 0 | E28: 0 | F28: =E28 -> 0 | G28: =IF(E28=F28,"n/a",IF(OR(C28="battery electric vehicle",C28="natural gas vehicle",C28="plugin hybrid vehicle"),"s-curve","linear")) -> n/a | I28: =D28 -> 0 | J28: =IFERROR(_xlfn.FORECAST.ETS(J$9,$D28:$E28,$D$9:$E$9,1),0) -> 0 | K28: =IFERROR(_xlfn.FORECAST.ETS(K$9,$D28:$E28,$D$9:$E$9,1),0) -> 0 | L28: =IFERROR(_xlfn.FORECAST.ETS(L$9,$D28:$E28,$D$9:$E$9,1),0) -> 0 | M28: =E28 -> 0 | N28: =IF($G28="s-curve",$E28+($F28-$E28)*$I$2/(1+EXP($I$3*(COUNT($I$9:N$9)+$I$4))),TREND($E28:$F28,$E$9:$F$9,N$9)) -> 0 | O28: =IF($G28="s-curve",$E28+($F28-$E28)*$I$2/(1+EXP($I$3*(COUNT($I$9:O$9)+$I$4))),TREND($E28:$F28,$E$9:$F$9,O$9)) -> 0 | P28: =IF($G28="s-curve",$E28+($F28-$E28)*$I$2/(1+EXP($I$3*(COUNT($I$9:P$9)+$I$4))),TREND($E28:$F28,$E$9:$F$9,P$9)) -> 0 | Q28: =IF($G28="s-curve",$E28+($F28-$E28)*$I$2/(1+EXP($I$3*(COUNT($I$9:Q$9)+$I$4))),TREND($E28:$F28,$E$9:$F$9,Q$9)) -> 0 | R28: =IF($G28="s-curve",$E28+($F28-$E28)*$I$2/(1+EXP($I$3*(COUNT($I$9:R$9)+$I$4))),TREND($E28:$F28,$E$9:$F$9,R$9)) -> 0 | S28: =IF($G28="s-curve",$E28+($F28-$E28)*$I$2/(1+EXP($I$3*(COUNT($I$9:S$9)+$I$4))),TREND($E28:$F28,$E$9:$F$9,S$9)) -> 0 | T28: =IF($G28="s-curve",$E28+($F28-$E28)*$I$2/(1+EXP($I$3*(COUNT($I$9:T$9)+$I$4))),TREND($E28:$F28,$E$9:$F$9,T$9)) -> 0 | U28: =IF($G28="s-curve",$E28+($F28-$E28)*$I$2/(1+EXP($I$3*(COUNT($I$9:U$9)+$I$4))),TREND($E28:$F28,$E$9:$F$9,U$9)) -> 0 | ... BF28: =IF($G28="s-curve",$E28+($F28-$E28)*$I$2/(1+EXP($I$3*(COUNT($I$9:BF$9)+$I$4))),TREND($E28:$F28,$E$9:$F$9,BF$9)) -> 0
C29: LPG vehicle | D29: 0 | E29: 0 | F29: =E29 -> 0 | G29: =IF(E29=F29,"n/a",IF(OR(C29="battery electric vehicle",C29="natural gas vehicle",C29="plugin hybrid vehicle",C29="hydrogen vehicle"),"s-curve","linear")) -> n/a | I29: =D29 -> 0 | J29: =IFERROR(_xlfn.FORECAST.ETS(J$9,$D29:$E29,$D$9:$E$9,1),0) -> 0 | K29: =IFERROR(_xlfn.FORECAST.ETS(K$9,$D29:$E29,$D$9:$E$9,1),0) -> 0 | L29: =IFERROR(_xlfn.FORECAST.ETS(L$9,$D29:$E29,$D$9:$E$9,1),0) -> 0 | M29: =E29 -> 0 | N29: =IF($G29="s-curve",$E29+($F29-$E29)*$I$2/(1+EXP($I$3*(COUNT($I$9:N$9)+$I$4))),TREND($E29:$F29,$E$9:$F$9,N$9)) -> 0 | O29: =IF($G29="s-curve",$E29+($F29-$E29)*$I$2/(1+EXP($I$3*(COUNT($I$9:O$9)+$I$4))),TREND($E29:$F29,$E$9:$F$9,O$9)) -> 0 | P29: =IF($G29="s-curve",$E29+($F29-$E29)*$I$2/(1+EXP($I$3*(COUNT($I$9:P$9)+$I$4))),TREND($E29:$F29,$E$9:$F$9,P$9)) -> 0 | Q29: =IF($G29="s-curve",$E29+($F29-$E29)*$I$2/(1+EXP($I$3*(COUNT($I$9:Q$9)+$I$4))),TREND($E29:$F29,$E$9:$F$9,Q$9)) -> 0 | R29: =IF($G29="s-curve",$E29+($F29-$E29)*$I$2/(1+EXP($I$3*(COUNT($I$9:R$9)+$I$4))),TREND($E29:$F29,$E$9:$F$9,R$9)) -> 0 | S29: =IF($G29="s-curve",$E29+($F29-$E29)*$I$2/(1+EXP($I$3*(COUNT($I$9:S$9)+$I$4))),TREND($E29:$F29,$E$9:$F$9,S$9)) -> 0 | T29: =IF($G29="s-curve",$E29+($F29-$E29)*$I$2/(1+EXP($I$3*(COUNT($I$9:T$9)+$I$4))),TREND($E29:$F29,$E$9:$F$9,T$9)) -> 0 | U29: =IF($G29="s-curve",$E29+($F29-$E29)*$I$2/(1+EXP($I$3*(COUNT($I$9:U$9)+$I$4))),TREND($E29:$F29,$E$9:$F$9,U$9)) -> 0 | ... BF29: =IF($G29="s-curve",$E29+($F29-$E29)*$I$2/(1+EXP($I$3*(COUNT($I$9:BF$9)+$I$4))),TREND($E29:$F29,$E$9:$F$9,BF$9)) -> 0
C30: hydrogen vehicle | D30: 0 | E30: 0 | F30: =E30 -> 0 | G30: =IF(E30=F30,"n/a",IF(OR(C30="battery electric vehicle",C30="natural gas vehicle",C30="plugin hybrid vehicle",C30="hydrogen vehicle"),"s-curve","linear")) -> n/a | I30: =D30 -> 0 | J30: =IFERROR(_xlfn.FORECAST.ETS(J$9,$D30:$E30,$D$9:$E$9,1),0) -> 0 | K30: =IFERROR(_xlfn.FORECAST.ETS(K$9,$D30:$E30,$D$9:$E$9,1),0) -> 0 | L30: =IFERROR(_xlfn.FORECAST.ETS(L$9,$D30:$E30,$D$9:$E$9,1),0) -> 0 | M30: =E30 -> 0 | N30: =IF($G30="s-curve",$E30+($F30-$E30)*$I$2/(1+EXP($I$3*(COUNT($I$9:N$9)+$I$4))),TREND($E30:$F30,$E$9:$F$9,N$9)) -> 0 | O30: =IF($G30="s-curve",$E30+($F30-$E30)*$I$2/(1+EXP($I$3*(COUNT($I$9:O$9)+$I$4))),TREND($E30:$F30,$E$9:$F$9,O$9)) -> 0 | P30: =IF($G30="s-curve",$E30+($F30-$E30)*$I$2/(1+EXP($I$3*(COUNT($I$9:P$9)+$I$4))),TREND($E30:$F30,$E$9:$F$9,P$9)) -> 0 | Q30: =IF($G30="s-curve",$E30+($F30-$E30)*$I$2/(1+EXP($I$3*(COUNT($I$9:Q$9)+$I$4))),TREND($E30:$F30,$E$9:$F$9,Q$9)) -> 0 | R30: =IF($G30="s-curve",$E30+($F30-$E30)*$I$2/(1+EXP($I$3*(COUNT($I$9:R$9)+$I$4))),TREND($E30:$F30,$E$9:$F$9,R$9)) -> 0 | S30: =IF($G30="s-curve",$E30+($F30-$E30)*$I$2/(1+EXP($I$3*(COUNT($I$9:S$9)+$I$4))),TREND($E30:$F30,$E$9:$F$9,S$9)) -> 0 | T30: =IF($G30="s-curve",$E30+($F30-$E30)*$I$2/(1+EXP($I$3*(COUNT($I$9:T$9)+$I$4))),TREND($E30:$F30,$E$9:$F$9,T$9)) -> 0 | U30: =IF($G30="s-curve",$E30+($F30-$E30)*$I$2/(1+EXP($I$3*(COUNT($I$9:U$9)+$I$4))),TREND($E30:$F30,$E$9:$F$9,U$9)) -> 0 | ... BF30: =IF($G30="s-curve",$E30+($F30-$E30)*$I$2/(1+EXP($I$3*(COUNT($I$9:BF$9)+$I$4))),TREND($E30:$F30,$E$9:$F$9,BF$9)) -> 0
A31: HDVs | B31: freight | C31: battery electric vehicle | D31: 0.0040521955 | E31: 0.0051262373 | F31: 0.25 | G31: =IF(E31=F31,"n/a",IF(OR(C31="battery electric vehicle",C31="natural gas vehicle",C31="plugin hybrid vehicle"),"s-curve","linear")) -> s-curve | I31: =D31 -> 0.0040521955 | J31: =IFERROR(_xlfn.FORECAST.ETS(J$9,$D31:$E31,$D$9:$E$9,1),0) -> 0.004320706 | K31: =IFERROR(_xlfn.FORECAST.ETS(K$9,$D31:$E31,$D$9:$E$9,1),0) -> 0.0045892164 | L31: =IFERROR(_xlfn.FORECAST.ETS(L$9,$D31:$E31,$D$9:$E$9,1),0) -> 0.0048577269 | M31: =E31 -> 0.0051262373 | N31: =IF($G31="s-curve",$E31+($F31-$E31)*$U$2/(1+EXP($U$3*(COUNT($N$9:N$9)+$U$4))),TREND($E31:$F31,$E$9:$F$9,N$9)) -> 0.013836688 | O31: =IF($G31="s-curve",$E31+($F31-$E31)*$U$2/(1+EXP($U$3*(COUNT($N$9:O$9)+$U$4))),TREND($E31:$F31,$E$9:$F$9,O$9)) -> 0.016739589 | P31: =IF($G31="s-curve",$E31+($F31-$E31)*$U$2/(1+EXP($U$3*(COUNT($N$9:P$9)+$U$4))),TREND($E31:$F31,$E$9:$F$9,P$9)) -> 0.02054676 | Q31: =IF($G31="s-curve",$E31+($F31-$E31)*$U$2/(1+EXP($U$3*(COUNT($N$9:Q$9)+$U$4))),TREND($E31:$F31,$E$9:$F$9,Q$9)) -> 0.025493048 | R31: =IF($G31="s-curve",$E31+($F31-$E31)*$U$2/(1+EXP($U$3*(COUNT($N$9:R$9)+$U$4))),TREND($E31:$F31,$E$9:$F$9,R$9)) -> 0.031841186 | S31: =IF($G31="s-curve",$E31+($F31-$E31)*$U$2/(1+EXP($U$3*(COUNT($N$9:S$9)+$U$4))),TREND($E31:$F31,$E$9:$F$9,S$9)) -> 0.039861841 | T31: =IF($G31="s-curve",$E31+($F31-$E31)*$U$2/(1+EXP($U$3*(COUNT($N$9:T$9)+$U$4))),TREND($E31:$F31,$E$9:$F$9,T$9)) -> 0.049797462 | U31: =IF($G31="s-curve",$E31+($F31-$E31)*$U$2/(1+EXP($U$3*(COUNT($N$9:U$9)+$U$4))),TREND($E31:$F31,$E$9:$F$9,U$9)) -> 0.061808445 | ... BF31: =IF($G31="s-curve",$E31+($F31-$E31)*$U$2/(1+EXP($U$3*(COUNT($N$9:BF$9)+$U$4))),TREND($E31:$F31,$E$9:$F$9,BF$9)) -> 0.24998771
C32: natural gas vehicle | D32: 0 | E32: 0 | F32: =E32 -> 0 | G32: =IF(E32=F32,"n/a",IF(OR(C32="battery electric vehicle",C32="natural gas vehicle",C32="plugin hybrid vehicle"),"s-curve","linear")) -> n/a | I32: =D32 -> 0 | J32: =IFERROR(_xlfn.FORECAST.ETS(J$9,$D32:$E32,$D$9:$E$9,1),0) -> 0 | K32: =IFERROR(_xlfn.FORECAST.ETS(K$9,$D32:$E32,$D$9:$E$9,1),0) -> 0 | L32: =IFERROR(_xlfn.FORECAST.ETS(L$9,$D32:$E32,$D$9:$E$9,1),0) -> 0 | M32: =E32 -> 0 | N32: =IF($G32="s-curve",$E32+($F32-$E32)*$I$2/(1+EXP($I$3*(COUNT($I$9:N$9)+$I$4))),TREND($E32:$F32,$E$9:$F$9,N$9)) -> 0 | O32: =IF($G32="s-curve",$E32+($F32-$E32)*$I$2/(1+EXP($I$3*(COUNT($I$9:O$9)+$I$4))),TREND($E32:$F32,$E$9:$F$9,O$9)) -> 0 | P32: =IF($G32="s-curve",$E32+($F32-$E32)*$I$2/(1+EXP($I$3*(COUNT($I$9:P$9)+$I$4))),TREND($E32:$F32,$E$9:$F$9,P$9)) -> 0 | Q32: =IF($G32="s-curve",$E32+($F32-$E32)*$I$2/(1+EXP($I$3*(COUNT($I$9:Q$9)+$I$4))),TREND($E32:$F32,$E$9:$F$9,Q$9)) -> 0 | R32: =IF($G32="s-curve",$E32+($F32-$E32)*$I$2/(1+EXP($I$3*(COUNT($I$9:R$9)+$I$4))),TREND($E32:$F32,$E$9:$F$9,R$9)) -> 0 | S32: =IF($G32="s-curve",$E32+($F32-$E32)*$I$2/(1+EXP($I$3*(COUNT($I$9:S$9)+$I$4))),TREND($E32:$F32,$E$9:$F$9,S$9)) -> 0 | T32: =IF($G32="s-curve",$E32+($F32-$E32)*$I$2/(1+EXP($I$3*(COUNT($I$9:T$9)+$I$4))),TREND($E32:$F32,$E$9:$F$9,T$9)) -> 0 | U32: =IF($G32="s-curve",$E32+($F32-$E32)*$I$2/(1+EXP($I$3*(COUNT($I$9:U$9)+$I$4))),TREND($E32:$F32,$E$9:$F$9,U$9)) -> 0 | ... BF32: =IF($G32="s-curve",$E32+($F32-$E32)*$I$2/(1+EXP($I$3*(COUNT($I$9:BF$9)+$I$4))),TREND($E32:$F32,$E$9:$F$9,BF$9)) -> 0
C33: gasoline vehicle | D33: 0 | E33: 0 | F33: =E33 -> 0 | G33: =IF(E33=F33,"n/a",IF(OR(C33="battery electric vehicle",C33="natural gas vehicle",C33="plugin hybrid vehicle"),"s-curve","linear")) -> n/a | I33: =D33 -> 0 | J33: =IFERROR(_xlfn.FORECAST.ETS(J$9,$D33:$E33,$D$9:$E$9,1),0) -> 0 | K33: =IFERROR(_xlfn.FORECAST.ETS(K$9,$D33:$E33,$D$9:$E$9,1),0) -> 0 | L33: =IFERROR(_xlfn.FORECAST.ETS(L$9,$D33:$E33,$D$9:$E$9,1),0) -> 0 | M33: =E33 -> 0 | N33: =IF($G33="s-curve",$E33+($F33-$E33)*$I$2/(1+EXP($I$3*(COUNT($I$9:N$9)+$I$4))),TREND($E33:$F33,$E$9:$F$9,N$9)) -> 0 | O33: =IF($G33="s-curve",$E33+($F33-$E33)*$I$2/(1+EXP($I$3*(COUNT($I$9:O$9)+$I$4))),TREND($E33:$F33,$E$9:$F$9,O$9)) -> 0 | P33: =IF($G33="s-curve",$E33+($F33-$E33)*$I$2/(1+EXP($I$3*(COUNT($I$9:P$9)+$I$4))),TREND($E33:$F33,$E$9:$F$9,P$9)) -> 0 | Q33: =IF($G33="s-curve",$E33+($F33-$E33)*$I$2/(1+EXP($I$3*(COUNT($I$9:Q$9)+$I$4))),TREND($E33:$F33,$E$9:$F$9,Q$9)) -> 0 | R33: =IF($G33="s-curve",$E33+($F33-$E33)*$I$2/(1+EXP($I$3*(COUNT($I$9:R$9)+$I$4))),TREND($E33:$F33,$E$9:$F$9,R$9)) -> 0 | S33: =IF($G33="s-curve",$E33+($F33-$E33)*$I$2/(1+EXP($I$3*(COUNT($I$9:S$9)+$I$4))),TREND($E33:$F33,$E$9:$F$9,S$9)) -> 0 | T33: =IF($G33="s-curve",$E33+($F33-$E33)*$I$2/(1+EXP($I$3*(COUNT($I$9:T$9)+$I$4))),TREND($E33:$F33,$E$9:$F$9,T$9)) -> 0 | U33: =IF($G33="s-curve",$E33+($F33-$E33)*$I$2/(1+EXP($I$3*(COUNT($I$9:U$9)+$I$4))),TREND($E33:$F33,$E$9:$F$9,U$9)) -> 0 | ... BF33: =IF($G33="s-curve",$E33+($F33-$E33)*$I$2/(1+EXP($I$3*(COUNT($I$9:BF$9)+$I$4))),TREND($E33:$F33,$E$9:$F$9,BF$9)) -> 0
C34: diesel vehicle | D34: 1 | E34: 1 | F34: 1 | G34: =IF(E34=F34,"n/a",IF(OR(C34="battery electric vehicle",C34="natural gas vehicle",C34="plugin hybrid vehicle"),"s-curve","linear")) -> n/a | I34: =D34 -> 1 | J34: =IFERROR(_xlfn.FORECAST.ETS(J$9,$D34:$E34,$D$9:$E$9,1),0) -> 1 | K34: =IFERROR(_xlfn.FORECAST.ETS(K$9,$D34:$E34,$D$9:$E$9,1),0) -> 1 | L34: =IFERROR(_xlfn.FORECAST.ETS(L$9,$D34:$E34,$D$9:$E$9,1),0) -> 1 | M34: =E34 -> 1 | N34: =IF($G34="s-curve",$E34+($F34-$E34)*$I$2/(1+EXP($I$3*(COUNT($I$9:N$9)+$I$4))),TREND($E34:$F34,$E$9:$F$9,N$9)) -> 1 | O34: =IF($G34="s-curve",$E34+($F34-$E34)*$I$2/(1+EXP($I$3*(COUNT($I$9:O$9)+$I$4))),TREND($E34:$F34,$E$9:$F$9,O$9)) -> 1 | P34: =IF($G34="s-curve",$E34+($F34-$E34)*$I$2/(1+EXP($I$3*(COUNT($I$9:P$9)+$I$4))),TREND($E34:$F34,$E$9:$F$9,P$9)) -> 1 | Q34: =IF($G34="s-curve",$E34+($F34-$E34)*$I$2/(1+EXP($I$3*(COUNT($I$9:Q$9)+$I$4))),TREND($E34:$F34,$E$9:$F$9,Q$9)) -> 1 | R34: =IF($G34="s-curve",$E34+($F34-$E34)*$I$2/(1+EXP($I$3*(COUNT($I$9:R$9)+$I$4))),TREND($E34:$F34,$E$9:$F$9,R$9)) -> 1 | S34: =IF($G34="s-curve",$E34+($F34-$E34)*$I$2/(1+EXP($I$3*(COUNT($I$9:S$9)+$I$4))),TREND($E34:$F34,$E$9:$F$9,S$9)) -> 1 | T34: =IF($G34="s-curve",$E34+($F34-$E34)*$I$2/(1+EXP($I$3*(COUNT($I$9:T$9)+$I$4))),TREND($E34:$F34,$E$9:$F$9,T$9)) -> 1 | U34: =IF($G34="s-curve",$E34+($F34-$E34)*$I$2/(1+EXP($I$3*(COUNT($I$9:U$9)+$I$4))),TREND($E34:$F34,$E$9:$F$9,U$9)) -> 1 | ... BF34: =IF($G34="s-curve",$E34+($F34-$E34)*$I$2/(1+EXP($I$3*(COUNT($I$9:BF$9)+$I$4))),TREND($E34:$F34,$E$9:$F$9,BF$9)) -> 1
C35: plugin hybrid vehicle | D35: 0 | E35: 0 | F35: =E35 -> 0 | G35: =IF(E35=F35,"n/a",IF(OR(C35="battery electric vehicle",C35="natural gas vehicle",C35="plugin hybrid vehicle"),"s-curve","linear")) -> n/a | I35: =D35 -> 0 | J35: =IFERROR(_xlfn.FORECAST.ETS(J$9,$D35:$E35,$D$9:$E$9,1),0) -> 0 | K35: =IFERROR(_xlfn.FORECAST.ETS(K$9,$D35:$E35,$D$9:$E$9,1),0) -> 0 | L35: =IFERROR(_xlfn.FORECAST.ETS(L$9,$D35:$E35,$D$9:$E$9,1),0) -> 0 | M35: =E35 -> 0 | N35: =IF($G35="s-curve",$E35+($F35-$E35)*$I$2/(1+EXP($I$3*(COUNT($I$9:N$9)+$I$4))),TREND($E35:$F35,$E$9:$F$9,N$9)) -> 0 | O35: =IF($G35="s-curve",$E35+($F35-$E35)*$I$2/(1+EXP($I$3*(COUNT($I$9:O$9)+$I$4))),TREND($E35:$F35,$E$9:$F$9,O$9)) -> 0 | P35: =IF($G35="s-curve",$E35+($F35-$E35)*$I$2/(1+EXP($I$3*(COUNT($I$9:P$9)+$I$4))),TREND($E35:$F35,$E$9:$F$9,P$9)) -> 0 | Q35: =IF($G35="s-curve",$E35+($F35-$E35)*$I$2/(1+EXP($I$3*(COUNT($I$9:Q$9)+$I$4))),TREND($E35:$F35,$E$9:$F$9,Q$9)) -> 0 | R35: =IF($G35="s-curve",$E35+($F35-$E35)*$I$2/(1+EXP($I$3*(COUNT($I$9:R$9)+$I$4))),TREND($E35:$F35,$E$9:$F$9,R$9)) -> 0 | S35: =IF($G35="s-curve",$E35+($F35-$E35)*$I$2/(1+EXP($I$3*(COUNT($I$9:S$9)+$I$4))),TREND($E35:$F35,$E$9:$F$9,S$9)) -> 0 | T35: =IF($G35="s-curve",$E35+($F35-$E35)*$I$2/(1+EXP($I$3*(COUNT($I$9:T$9)+$I$4))),TREND($E35:$F35,$E$9:$F$9,T$9)) -> 0 | U35: =IF($G35="s-curve",$E35+($F35-$E35)*$I$2/(1+EXP($I$3*(COUNT($I$9:U$9)+$I$4))),TREND($E35:$F35,$E$9:$F$9,U$9)) -> 0 | ... BF35: =IF($G35="s-curve",$E35+($F35-$E35)*$I$2/(1+EXP($I$3*(COUNT($I$9:BF$9)+$I$4))),TREND($E35:$F35,$E$9:$F$9,BF$9)) -> 0
C36: LPG vehicle | D36: 0 | E36: 0 | F36: =E36 -> 0 | G36: =IF(E36=F36,"n/a",IF(OR(C36="battery electric vehicle",C36="natural gas vehicle",C36="plugin hybrid vehicle",C36="hydrogen vehicle"),"s-curve","linear")) -> n/a | I36: =D36 -> 0 | J36: =IFERROR(_xlfn.FORECAST.ETS(J$9,$D36:$E36,$D$9:$E$9,1),0) -> 0 | K36: =IFERROR(_xlfn.FORECAST.ETS(K$9,$D36:$E36,$D$9:$E$9,1),0) -> 0 | L36: =IFERROR(_xlfn.FORECAST.ETS(L$9,$D36:$E36,$D$9:$E$9,1),0) -> 0 | M36: =E36 -> 0 | N36: =IF($G36="s-curve",$E36+($F36-$E36)*$I$2/(1+EXP($I$3*(COUNT($I$9:N$9)+$I$4))),TREND($E36:$F36,$E$9:$F$9,N$9)) -> 0 | O36: =IF($G36="s-curve",$E36+($F36-$E36)*$I$2/(1+EXP($I$3*(COUNT($I$9:O$9)+$I$4))),TREND($E36:$F36,$E$9:$F$9,O$9)) -> 0 | P36: =IF($G36="s-curve",$E36+($F36-$E36)*$I$2/(1+EXP($I$3*(COUNT($I$9:P$9)+$I$4))),TREND($E36:$F36,$E$9:$F$9,P$9)) -> 0 | Q36: =IF($G36="s-curve",$E36+($F36-$E36)*$I$2/(1+EXP($I$3*(COUNT($I$9:Q$9)+$I$4))),TREND($E36:$F36,$E$9:$F$9,Q$9)) -> 0 | R36: =IF($G36="s-curve",$E36+($F36-$E36)*$I$2/(1+EXP($I$3*(COUNT($I$9:R$9)+$I$4))),TREND($E36:$F36,$E$9:$F$9,R$9)) -> 0 | S36: =IF($G36="s-curve",$E36+($F36-$E36)*$I$2/(1+EXP($I$3*(COUNT($I$9:S$9)+$I$4))),TREND($E36:$F36,$E$9:$F$9,S$9)) -> 0 | T36: =IF($G36="s-curve",$E36+($F36-$E36)*$I$2/(1+EXP($I$3*(COUNT($I$9:T$9)+$I$4))),TREND($E36:$F36,$E$9:$F$9,T$9)) -> 0 | U36: =IF($G36="s-curve",$E36+($F36-$E36)*$I$2/(1+EXP($I$3*(COUNT($I$9:U$9)+$I$4))),TREND($E36:$F36,$E$9:$F$9,U$9)) -> 0 | ... BF36: =IF($G36="s-curve",$E36+($F36-$E36)*$I$2/(1+EXP($I$3*(COUNT($I$9:BF$9)+$I$4))),TREND($E36:$F36,$E$9:$F$9,BF$9)) -> 0
C37: hydrogen vehicle | D37: 0 | E37: 0 | F37: =E37 -> 0 | G37: =IF(E37=F37,"n/a",IF(OR(C37="battery electric vehicle",C37="natural gas vehicle",C37="plugin hybrid vehicle",C37="hydrogen vehicle"),"s-curve","linear")) -> n/a | I37: =D37 -> 0 | J37: =IFERROR(_xlfn.FORECAST.ETS(J$9,$D37:$E37,$D$9:$E$9,1),0) -> 0 | K37: =IFERROR(_xlfn.FORECAST.ETS(K$9,$D37:$E37,$D$9:$E$9,1),0) -> 0 | L37: =IFERROR(_xlfn.FORECAST.ETS(L$9,$D37:$E37,$D$9:$E$9,1),0) -> 0 | M37: =E37 -> 0 | N37: =IF($G37="s-curve",$E37+($F37-$E37)*$I$2/(1+EXP($I$3*(COUNT($I$9:N$9)+$I$4))),TREND($E37:$F37,$E$9:$F$9,N$9)) -> 0 | O37: =IF($G37="s-curve",$E37+($F37-$E37)*$I$2/(1+EXP($I$3*(COUNT($I$9:O$9)+$I$4))),TREND($E37:$F37,$E$9:$F$9,O$9)) -> 0 | P37: =IF($G37="s-curve",$E37+($F37-$E37)*$I$2/(1+EXP($I$3*(COUNT($I$9:P$9)+$I$4))),TREND($E37:$F37,$E$9:$F$9,P$9)) -> 0 | Q37: =IF($G37="s-curve",$E37+($F37-$E37)*$I$2/(1+EXP($I$3*(COUNT($I$9:Q$9)+$I$4))),TREND($E37:$F37,$E$9:$F$9,Q$9)) -> 0 | R37: =IF($G37="s-curve",$E37+($F37-$E37)*$I$2/(1+EXP($I$3*(COUNT($I$9:R$9)+$I$4))),TREND($E37:$F37,$E$9:$F$9,R$9)) -> 0 | S37: =IF($G37="s-curve",$E37+($F37-$E37)*$I$2/(1+EXP($I$3*(COUNT($I$9:S$9)+$I$4))),TREND($E37:$F37,$E$9:$F$9,S$9)) -> 0 | T37: =IF($G37="s-curve",$E37+($F37-$E37)*$I$2/(1+EXP($I$3*(COUNT($I$9:T$9)+$I$4))),TREND($E37:$F37,$E$9:$F$9,T$9)) -> 0 | U37: =IF($G37="s-curve",$E37+($F37-$E37)*$I$2/(1+EXP($I$3*(COUNT($I$9:U$9)+$I$4))),TREND($E37:$F37,$E$9:$F$9,U$9)) -> 0 | ... BF37: =IF($G37="s-curve",$E37+($F37-$E37)*$I$2/(1+EXP($I$3*(COUNT($I$9:BF$9)+$I$4))),TREND($E37:$F37,$E$9:$F$9,BF$9)) -> 0
A38: aircraft | B38: passenger | C38: battery electric vehicle | D38: =E38 -> 0 | E38: 0 | F38: 0 | G38: =IF(E38=F38,"n/a",IF(OR(C38="battery electric vehicle",C38="natural gas vehicle",C38="plugin hybrid vehicle"),"s-curve","linear")) -> n/a | I38: =E38 -> 0 | J38: =IFERROR(_xlfn.FORECAST.ETS(J$9,$D38:$E38,$D$9:$E$9,1),0) -> 0 | K38: =IFERROR(_xlfn.FORECAST.ETS(K$9,$D38:$E38,$D$9:$E$9,1),0) -> 0 | L38: =IFERROR(_xlfn.FORECAST.ETS(L$9,$D38:$E38,$D$9:$E$9,1),0) -> 0 | M38: =IF($G38="s-curve",$E38+($F38-$E38)*$I$2/(1+EXP($I$3*(COUNT($I$9:M$9)+$I$4))),TREND($E38:$F38,$E$9:$F$9,M$9)) -> 0 | N38: =IF($G38="s-curve",$E38+($F38-$E38)*$I$2/(1+EXP($I$3*(COUNT($I$9:N$9)+$I$4))),TREND($E38:$F38,$E$9:$F$9,N$9)) -> 0 | O38: =IF($G38="s-curve",$E38+($F38-$E38)*$I$2/(1+EXP($I$3*(COUNT($I$9:O$9)+$I$4))),TREND($E38:$F38,$E$9:$F$9,O$9)) -> 0 | P38: =IF($G38="s-curve",$E38+($F38-$E38)*$I$2/(1+EXP($I$3*(COUNT($I$9:P$9)+$I$4))),TREND($E38:$F38,$E$9:$F$9,P$9)) -> 0 | Q38: =IF($G38="s-curve",$E38+($F38-$E38)*$I$2/(1+EXP($I$3*(COUNT($I$9:Q$9)+$I$4))),TREND($E38:$F38,$E$9:$F$9,Q$9)) -> 0 | R38: =IF($G38="s-curve",$E38+($F38-$E38)*$I$2/(1+EXP($I$3*(COUNT($I$9:R$9)+$I$4))),TREND($E38:$F38,$E$9:$F$9,R$9)) -> 0 | S38: =IF($G38="s-curve",$E38+($F38-$E38)*$I$2/(1+EXP($I$3*(COUNT($I$9:S$9)+$I$4))),TREND($E38:$F38,$E$9:$F$9,S$9)) -> 0 | T38: =IF($G38="s-curve",$E38+($F38-$E38)*$I$2/(1+EXP($I$3*(COUNT($I$9:T$9)+$I$4))),TREND($E38:$F38,$E$9:$F$9,T$9)) -> 0 | ... BF38: =IF($G38="s-curve",$E38+($F38-$E38)*$I$2/(1+EXP($I$3*(COUNT($I$9:BF$9)+$I$4))),TREND($E38:$F38,$E$9:$F$9,BF$9)) -> 0
C39: natural gas vehicle | D39: =E39 -> 0 | E39: 0 | F39: 0 | G39: =IF(E39=F39,"n/a",IF(OR(C39="battery electric vehicle",C39="natural gas vehicle",C39="plugin hybrid vehicle"),"s-curve","linear")) -> n/a | I39: =E39 -> 0 | J39: =IFERROR(_xlfn.FORECAST.ETS(J$9,$D39:$E39,$D$9:$E$9,1),0) -> 0 | K39: =IFERROR(_xlfn.FORECAST.ETS(K$9,$D39:$E39,$D$9:$E$9,1),0) -> 0 | L39: =IFERROR(_xlfn.FORECAST.ETS(L$9,$D39:$E39,$D$9:$E$9,1),0) -> 0 | M39: =IF($G39="s-curve",$E39+($F39-$E39)*$I$2/(1+EXP($I$3*(COUNT($I$9:M$9)+$I$4))),TREND($E39:$F39,$E$9:$F$9,M$9)) -> 0 | N39: =IF($G39="s-curve",$E39+($F39-$E39)*$I$2/(1+EXP($I$3*(COUNT($I$9:N$9)+$I$4))),TREND($E39:$F39,$E$9:$F$9,N$9)) -> 0 | O39: =IF($G39="s-curve",$E39+($F39-$E39)*$I$2/(1+EXP($I$3*(COUNT($I$9:O$9)+$I$4))),TREND($E39:$F39,$E$9:$F$9,O$9)) -> 0 | P39: =IF($G39="s-curve",$E39+($F39-$E39)*$I$2/(1+EXP($I$3*(COUNT($I$9:P$9)+$I$4))),TREND($E39:$F39,$E$9:$F$9,P$9)) -> 0 | Q39: =IF($G39="s-curve",$E39+($F39-$E39)*$I$2/(1+EXP($I$3*(COUNT($I$9:Q$9)+$I$4))),TREND($E39:$F39,$E$9:$F$9,Q$9)) -> 0 | R39: =IF($G39="s-curve",$E39+($F39-$E39)*$I$2/(1+EXP($I$3*(COUNT($I$9:R$9)+$I$4))),TREND($E39:$F39,$E$9:$F$9,R$9)) -> 0 | S39: =IF($G39="s-curve",$E39+($F39-$E39)*$I$2/(1+EXP($I$3*(COUNT($I$9:S$9)+$I$4))),TREND($E39:$F39,$E$9:$F$9,S$9)) -> 0 | T39: =IF($G39="s-curve",$E39+($F39-$E39)*$I$2/(1+EXP($I$3*(COUNT($I$9:T$9)+$I$4))),TREND($E39:$F39,$E$9:$F$9,T$9)) -> 0 | ... BF39: =IF($G39="s-curve",$E39+($F39-$E39)*$I$2/(1+EXP($I$3*(COUNT($I$9:BF$9)+$I$4))),TREND($E39:$F39,$E$9:$F$9,BF$9)) -> 0
C40: gasoline vehicle | D40: =E40 -> 0 | E40: 0 | F40: 0 | G40: =IF(E40=F40,"n/a",IF(OR(C40="battery electric vehicle",C40="natural gas vehicle",C40="plugin hybrid vehicle"),"s-curve","linear")) -> n/a | I40: =E40 -> 0 | J40: =IFERROR(_xlfn.FORECAST.ETS(J$9,$D40:$E40,$D$9:$E$9,1),0) -> 0 | K40: =IFERROR(_xlfn.FORECAST.ETS(K$9,$D40:$E40,$D$9:$E$9,1),0) -> 0 | L40: =IFERROR(_xlfn.FORECAST.ETS(L$9,$D40:$E40,$D$9:$E$9,1),0) -> 0 | M40: =IF($G40="s-curve",$E40+($F40-$E40)*$I$2/(1+EXP($I$3*(COUNT($I$9:M$9)+$I$4))),TREND($E40:$F40,$E$9:$F$9,M$9)) -> 0 | N40: =IF($G40="s-curve",$E40+($F40-$E40)*$I$2/(1+EXP($I$3*(COUNT($I$9:N$9)+$I$4))),TREND($E40:$F40,$E$9:$F$9,N$9)) -> 0 | O40: =IF($G40="s-curve",$E40+($F40-$E40)*$I$2/(1+EXP($I$3*(COUNT($I$9:O$9)+$I$4))),TREND($E40:$F40,$E$9:$F$9,O$9)) -> 0 | P40: =IF($G40="s-curve",$E40+($F40-$E40)*$I$2/(1+EXP($I$3*(COUNT($I$9:P$9)+$I$4))),TREND($E40:$F40,$E$9:$F$9,P$9)) -> 0 | Q40: =IF($G40="s-curve",$E40+($F40-$E40)*$I$2/(1+EXP($I$3*(COUNT($I$9:Q$9)+$I$4))),TREND($E40:$F40,$E$9:$F$9,Q$9)) -> 0 | R40: =IF($G40="s-curve",$E40+($F40-$E40)*$I$2/(1+EXP($I$3*(COUNT($I$9:R$9)+$I$4))),TREND($E40:$F40,$E$9:$F$9,R$9)) -> 0 | S40: =IF($G40="s-curve",$E40+($F40-$E40)*$I$2/(1+EXP($I$3*(COUNT($I$9:S$9)+$I$4))),TREND($E40:$F40,$E$9:$F$9,S$9)) -> 0 | T40: =IF($G40="s-curve",$E40+($F40-$E40)*$I$2/(1+EXP($I$3*(COUNT($I$9:T$9)+$I$4))),TREND($E40:$F40,$E$9:$F$9,T$9)) -> 0 | ... BF40: =IF($G40="s-curve",$E40+($F40-$E40)*$I$2/(1+EXP($I$3*(COUNT($I$9:BF$9)+$I$4))),TREND($E40:$F40,$E$9:$F$9,BF$9)) -> 0
...

Sheet TTS-LDVs-psgr
A1: Max Fraction of Production (dimensionless) | B1: 2021 | C1: 2022 | D1: 2023 | E1: 2024 | F1: 2025 | G1: 2026 | H1: 2027 | I1: 2028 | J1: 2029 | K1: 2030 | L1: 2031 | M1: 2032 | N1: 2033 | O1: 2034 | P1: 2035 | Q1: 2036 | R1: 2037 | S1: 2038 | T1: 2039 | U1: 2040 | V1: 2041 | W1: 2042 | X1: 2043 | Y1: 2044 | Z1: 2045 | AA1: 2046 | AB1: 2047 | AC1: 2048 | AD1: 2049 | AE1: 2050 | AF1: 2051 | AG1: 2052 | AH1: 2053 | AI1: 2054 | AJ1: 2055 | AK1: 2056 | AL1: 2057 | AM1: 2058 | AN1: 2059 | AO1: 2060 | AP1: 2061 | AQ1: 2062 | AR1: 2063 | AS1: 2064 | AT1: 2065 | AU1: 2066 | AV1: 2067 | AW1: 2068 | AX1: 2069 | AY1: 2070
A2: battery electric vehicle | B2: =Data!I10 -> 0.01 | C2: =Data!J10 -> 0.02 | D2: =Data!K10 -> 0.03 | E2: =Data!L10 -> 0.04 | F2: =Data!M10 -> 0.05 | G2: =Data!N10 -> 0.09505458 | H2: =Data!O10 -> 0.10982469 | I2: =Data!P10 -> 0.12901406 | ... AY2: =Data!BF10 -> 0.99996469
A3: natural gas vehicle | B3: =Data!I11 -> 9.1114482e-05 | C3: =Data!J11 -> 9.7816668e-05 | D3: =Data!K11 -> 9.5582606e-05 | E3: =Data!L11 -> 9.3348544e-05 | F3: =Data!M11 -> 9.1114482e-05 | G3: =Data!N11 -> 9.1114482e-05 | H3: =Data!O11 -> 9.1114482e-05 | I3: =Data!P11 -> 9.1114482e-05 | ... AY3: =Data!BF11 -> 9.1114482e-05
A4: gasoline vehicle | B4: =Data!I12 -> 1 | C4: =Data!J12 -> 1 | D4: =Data!K12 -> 1 | E4: =Data!L12 -> 1 | F4: =Data!M12 -> 1 | G4: =Data!N12 -> 1 | H4: =Data!O12 -> 1 | I4: =Data!P12 -> 1 | ... AY4: =Data!BF12 -> 1
A5: diesel vehicle | B5: =Data!I13 -> 0.060802312 | C5: =Data!J13 -> 0.065284015 | D5: =Data!K13 -> 0.063790114 | E5: =Data!L13 -> 0.062296213 | F5: =Data!M13 -> 0.060802312 | G5: =Data!N13 -> 0.060802312 | H5: =Data!O13 -> 0.060802312 | I5: =Data!P13 -> 0.060802312 | ... AY5: =Data!BF13 -> 0.060802312
A6: plugin hybrid vehicle | B6: =Data!I14 -> 0.01546374 | C6: =Data!J14 -> 0.011597805 | D6: =Data!K14 -> 0.0077318701 | E6: =Data!L14 -> 0.003865935 | F6: =Data!M14 -> 0 | G6: =Data!N14 -> 0.1843323 | H6: =Data!O14 -> 0.25976241 | I6: =Data!P14 -> 0.35794726 | ... AY6: =Data!BF14 -> 1.5463738
A7: LPG vehicle | B7: =Data!I15 -> 0 | C7: =Data!J15 -> 0 | D7: =Data!K15 -> 0 | E7: =Data!L15 -> 0 | F7: =Data!M15 -> 0 | G7: =Data!N15 -> 0 | H7: =Data!O15 -> 0 | I7: =Data!P15 -> 0 | ... AY7: =Data!BF15 -> 0
A8: hydrogen vehicle | B8: =Data!I16 -> 0 | C8: =Data!J16 -> 0 | D8: =Data!K16 -> 0 | E8: =Data!L16 -> 0 | F8: =Data!M16 -> 0 | G8: =Data!N16 -> 0 | H8: =Data!O16 -> 0 | I8: =Data!P16 -> 0 | ... AY8: =Data!BF16 -> 0

Sheet TTS-LDVs-frgt
A1: Max Fraction of Production (dimensionless) | B1: 2021 | C1: 2022 | D1: 2023 | E1: 2024 | F1: 2025 | G1: 2026 | H1: 2027 | I1: 2028 | J1: 2029 | K1: 2030 | L1: 2031 | M1: 2032 | N1: 2033 | O1: 2034 | P1: 2035 | Q1: 2036 | R1: 2037 | S1: 2038 | T1: 2039 | U1: 2040 | V1: 2041 | W1: 2042 | X1: 2043 | Y1: 2044 | Z1: 2045 | AA1: 2046 | AB1: 2047 | AC1: 2048 | AD1: 2049 | AE1: 2050 | AF1: 2051 | AG1: 2052 | AH1: 2053 | AI1: 2054 | AJ1: 2055 | AK1: 2056 | AL1: 2057 | AM1: 2058 | AN1: 2059 | AO1: 2060 | AP1: 2061 | AQ1: 2062 | AR1: 2063 | AS1: 2064 | AT1: 2065 | AU1: 2066 | AV1: 2067 | AW1: 2068 | AX1: 2069 | AY1: 2070
A2: battery electric vehicle | B2: =Data!I17 -> 0.26000977 | C2: =Data!J17 -> 0.22278173 | D2: =Data!K17 -> 0.18555368 | E2: =Data!L17 -> 0.14832564 | F2: =Data!M17 -> 0.12299342 | G2: =Data!N17 -> 0.26333586 | H2: =Data!O17 -> 0.26437257 | I2: =Data!P17 -> 0.26568242 | ... AY2: =Data!BF17 -> 0.29999918
A3: natural gas vehicle | B3: =Data!I18 -> 0 | C3: =Data!J18 -> 0 | D3: =Data!K18 -> 0 | E3: =Data!L18 -> 0 | F3: =Data!M18 -> 0 | G3: =Data!N18 -> 0 | H3: =Data!O18 -> 0 | I3: =Data!P18 -> 0 | ... AY3: =Data!BF18 -> 0
A4: gasoline vehicle | B4: =Data!I19 -> 0.9008381 | C4: =Data!J19 -> 0.88518264 | D4: =Data!K19 -> 0.86952718 | E4: =Data!L19 -> 0.85387172 | F4: =Data!M19 -> 0.83821627 | G4: =Data!N19 -> 0.83821627 | H4: =Data!O19 -> 0.83821627 | I4: =Data!P19 -> 0.83821627 | ... AY4: =Data!BF19 -> 0.83821627
A5: diesel vehicle | B5: =Data!I20 -> 1 | C5: =Data!J20 -> 1 | D5: =Data!K20 -> 1 | E5: =Data!L20 -> 1 | F5: =Data!M20 -> 1 | G5: =Data!N20 -> 1 | H5: =Data!O20 -> 1 | I5: =Data!P20 -> 1 | ... AY5: =Data!BF20 -> 1
A6: plugin hybrid vehicle | B6: =Data!I21 -> 0 | C6: =Data!J21 -> 0.00016882317 | D6: =Data!K21 -> 0.00033764635 | E6: =Data!L21 -> 0.00050646952 | F6: =Data!M21 -> 0.00067529269 | G6: =Data!N21 -> 0.00077079319 | H6: =Data!O21 -> 0.00080055977 | I6: =Data!P21 -> 0.00083816882 | ... AY6: =Data!BF21 -> 0.0018234886
A7: LPG vehicle | B7: =Data!I22 -> 0 | C7: =Data!J22 -> 0 | D7: =Data!K22 -> 0 | E7: =Data!L22 -> 0 | F7: =Data!M22 -> 0 | G7: =Data!N22 -> 0 | H7: =Data!O22 -> 0 | I7: =Data!P22 -> 0 | ... AY7: =Data!BF22 -> 0
A8: hydrogen vehicle | B8: =Data!I23 -> 0 | C8: =Data!J23 -> 0 | D8: =Data!K23 -> 0 | E8: =Data!L23 -> 0 | F8: =Data!M23 -> 0 | G8: =Data!N23 -> 0 | H8: =Data!O23 -> 0 | I8: =Data!P23 -> 0 | ... AY8: =Data!BF23 -> 0

Sheet TTS-HDVs-psgr
A1: Max Fraction of Production (dimensionless) | B1: 2021 | C1: 2022 | D1: 2023 | E1: 2024 | F1: 2025 | G1: 2026 | H1: 2027 | I1: 2028 | J1: 2029 | K1: 2030 | L1: 2031 | M1: 2032 | N1: 2033 | O1: 2034 | P1: 2035 | Q1: 2036 | R1: 2037 | S1: 2038 | T1: 2039 | U1: 2040 | V1: 2041 | W1: 2042 | X1: 2043 | Y1: 2044 | Z1: 2045 | AA1: 2046 | AB1: 2047 | AC1: 2048 | AD1: 2049 | AE1: 2050 | AF1: 2051 | AG1: 2052 | AH1: 2053 | AI1: 2054 | AJ1: 2055 | AK1: 2056 | AL1: 2057 | AM1: 2058 | AN1: 2059 | AO1: 2060 | AP1: 2061 | AQ1: 2062 | AR1: 2063 | AS1: 2064 | AT1: 2065 | AU1: 2066 | AV1: 2067 | AW1: 2068 | AX1: 2069 | AY1: 2070
A2: battery electric vehicle | B2: =Data!I24 -> 0.030938507 | C2: =Data!J24 -> 0.030802074 | D2: =Data!K24 -> 0.030665642 | E2: =Data!L24 -> 0.03052921 | F2: =Data!M24 -> 0.030392777 | G2: =Data!N24 -> 0.09024445 | H2: =Data!O24 -> 0.10889964 | I2: =Data!P24 -> 0.13246983 | ... AY2: =Data!BF24 -> 0.74998532
