Workbook

Sheet About
A1: Web App Data
A3: This spreadsheet contains data that is used to populate the web application interface
A4: for the Energy Policy Simulator. The data in other tabs in this spreadsheet are used
A5: to establish the policy levers, lever bounds, descriptive text for pop-over
A6: panels, output graphs, and reference scenarios available in the web app.
A8: A live version of the web application interface powered by a copy of this model
A9: can be found at:
A10: https://www.energypolicy.solutions
A12: You are unlikely to need to use or change the contents of this spreadsheet, unless
A13: you are adapting the Energy Policy Simulator to a new country and desire
A14: a web application interface customized for your country-specific model version.
A16: Checks for Policy ID Number Validity
A17: Max policy ID number in use | B17: =MAX(PolicyLevers!H:H) -> 1601
A18: Lowest duplicate ID number | B18: {=IF(MIN(IF(COUNTIF(PolicyLevers!$H$2:$H$1227,PolicyLevers!$H$2:$H$1227)>1,PolicyLevers!$H$2:$H$1227, ""))=0,"No duplicate ID numbers",MIN(IF(COUNTIF(PolicyLevers!$H$2:$H$1227,PolicyLevers!$H$2:$H$1227)>1,PolicyLevers!$H$2:$H$1227, "")))} -> No duplicate ID numbers
A19: Row of first policy missing a valid ID number | B19: {=IF(MIN(IF((NOT(ISNUMBER(PolicyLevers!$H$2:$H$1227)))*(ISTEXT(PolicyLevers!$I$2:$I$1227)),ROW(PolicyLevers!$H$2:$H$1227)))=0,"No missing ID numbers",MIN(IF((NOT(ISNUMBER(PolicyLevers!$H$2:$H$1227)))*(ISTEXT(PolicyLevers!$I$2:$I$1227)),ROW(PolicyLevers!$H$2:$H$1227))))} -> No missing ID numbers
A21: Customizing Policy Levers
A22: Define most policy properties on the "Policy Characteristics" tab.
A23: Specify the subscripted elements of each policy and which are enabled/disabled on the "PolicyLevers" tab.
A24: On the PolicyLevers tab, only manually edit the cells under the green column headers. Simply extend the
A25: existing formulas up or down to fill cells under the red headers on that tab.
A27: Notes on Meaning of Blank Cells on the Policy Characteristics Tab
A28: Leave the "Policy Schedule Subscript" cell blank to deny the ability to edit the implementation
A29: schedule for a lever. This should generally only be done for levers that do not use an
A30: implementation schedule: the toggle to Non-BAU Mandated Capacity Construction
A31: (which has its own schedule built into its input data) and the Nuclear Lifetime Extension
A32: (which simply delays retirements that would occur in the BAU Retirements input data).
A34: Leave the "Policy Group" cell blank to exclude a lever from wedge diagrams and abatement cost curves.
... A53: step size (e.g. 1.5% is not a valid step size, but 1%, 2%, 0.5% and 0.05% are all valid).

Sheet Policy Characteristics
A1: This tab contains information about each policy that does not vary by subscripted element of that policy.
A2: It matches policies to the listing in the "PolicyLevers" tab using the "Vensim Variable Name" column.
A3: Sector | B3: Short Name | C3: Vensim Variable Name | D3: Policy Group | E3: Policy Schedule Subscript | F3: Min Slider Value | G3: Max Slider Value | H3: Slider Step Size | I3: Units | J3: Text for Pop-Over Panel Description | K3: URL for "How the model handles this policy" links | L3: URL for "How to design this policy well" links | M3: Source for Guidance Text (if any) | N3: Source for Max Slider Value (if any)
A4: Transportation | B4: Conventional Pollutant Standards | C4: Percentage Reduction of Separately Regulated Pollutants | D4: Conventional Pollutant Standard | E4: trans reduce regulated pollutants | F4: 0 | G4: 1 | H4: 0.02 | I4: % reduction in emissions | J4: **Description:** This policy represents strengthening standards for the selected pollutant(s) emitted by the selected vehicle type(s). Conventional pollutants' most important, harmful impacts are on human health rather than on climate change. // **Guidance for setting values:** Mexico has multiple regions with serious air quality concerns from fossil fuel combustion. ProAire (local air quality programs) have been deployed in major cities with some strong measures like those deployed for the Mexico City metropolitan area (strengthening air quality standards, re-zoning industrial areas, emissions registry and inventory, semi-annual vehicle inspections and limits to vehicle use). | K4: transportation-sector-main.html#conv-pol-stds | L4: conventional-pollutant-standards.html
A5: Transportation | B5: Electric Vehicle Charger Deployment | C5: EV Charger Deployment | D5: EV Charger Deployment | E5: trans EV charger deployment | F5: 0 | G5: 300 | H5: 5 | I5: chargers / 100k pop | J5: **Description:** This policy represents increasing the deployment of EV charging stations, including DC Fast and Level 2 charging stations. It is set in chargers per 100,000 people (cumulative, not per year), additional to chargers in the Reference case. This policy lever does not have an effect on energy use/emissions/deployment. It is meant to account for the costs of additional charging infrastructure. // **Guidance for setting values:** As of Mar 2019, the U.S. had 63,000 chargers, just under 20 chargers per 100k pop. In 2016, the U.S. had 111,076 gas stations with an average of 8 fuel pumps each, or 275 pumps per 100k pop. Therefore, a lever setting of 255 would cause the population density of EV chargers to equal the 2016 population density of fuel pumps. | L5: ev-charger-deployment.html | M5: Number of EV chargers: https://evadoption.com/ev-charging-stations-statistics/ Number of gas stations: U.S. Census, Statistics of U.S. Businesses, https://www.census.gov/data/tables/2016/econ/susb/2016-susb-annual.html Pumps per station: https://247wallst.com/economy/2014/05/22/why-are-there-115000-or-150000-gas-stations-in-america/
A6: Transportation | B6: Electric Vehicle Range & Charging Time | C6: Reduce EV Range Anxiety and Charging Time | D6: EV Range & Charging Time | E6: trans reduce EV range anxiety and charging time | F6: 0 | G6: 1 | H6: 0.02 | I6: % reduction in concern | J6: **Description:** This policy specifies a percentage reduction in vehicle buyers' aversion to electric vehicles due to concerns over the vehicles' range (how far the EV can travel on a charge) and charging time. A 100% setting implies consumers are no more concerned about EV range and charging time than they are about range and fueling time of gasoline vehicles. It does not imply that range is infinite, nor that charging is instantaneous. This policy only affects passenger LDVs. // **Guidance for setting values:** U.S. model year 2017 all-electric (not hybrid) vehicles had ranges from 58 to 335 miles (median 114 miles), and the typical charging time was 0.5 hours (with a DC Fast charger) or 3.5 hours (with a Level 2 charger). | L6: reduce-range-anxiety-charging-time.html | M6: Ranges: https://www.energy.gov/eere/vehicles/articles/fotw-1010-january-1-2018-all-electric-light-vehicle-ranges-can-exceed-those Charging Times: https://www.chargepoint.com/files/Quick_Guide_to_Fast_Charging.pdf
A7: Transportation | B7: Electric Vehicle Sales Standard | C7: Additional Minimum Required EV Sales Percentage | D7: EV Sales Standard | E7: trans EV minimum | F7: 0 | G7: 1 | H7: 0.01 | I7: % of new vehicles sold | J7: **Description:** This policy requires the specified percentage of newly sold vehicles of the selected type(s) to consist of battery electric vehicles. If that percentage would already be achieved through Reference Case sales plus the effects of other policies, such as an EV subsidy, this policy has no effect. Manufactures may meet a sales standard through techniques such as more heavily marketing electric vehicles, lowering the price of electric vehicles, or raising the price of non-electric vehicles. // **Guidance for setting values:** // **Passenger LDVs:** California's Zero Emission Vehicle (ZEV) program requires automakers to sell ZEVs in California and 10 other states, which will likely require about 7% to 10% new vehicle sales in 2025. California recently passed an executive order to phase out sales of new gas cars by 2035, which would be equivalent to a setting of 100% in 2035. // **Freight Trucks:** Today, the share of electric freight trucks is very low, but electrification is particularly promising for certain types of trucks, such as those used to make deliveries within cities, those involved in port operations, garbage trucks, and others with frequent starts and stops. // **Passenger HDVs:** Electric bus manufacturer Proterra believes all new transit bus sales could be electric as early as 2030, but transit buses make up roughly 15% of the bus fleet. // **Aircraft:** Electricity is commonly used by drones, and small, manned electric aircraft have been developed. However, limited payload and range may complicate the electrification potential of large, long-haul aircraft. Therefore, a low setting of this policy lever may be more realistic than a high setting. // **Passenger Rail:** Today, in the United States, slightly more than half of all energy used for passenger rail consists of electricity, largely for urban metro and commuter rail systems. Electrifying more rail requires installing electric guidewires or an electrified third rail along existing corridors, or the development of new rail corridors. With sufficient investment, most or all passenger rail could potentially be electrified, but many years may be required to complete the associated infrastructure upgrades. // **Freight Rail:** Today, in the United States, little if any freight rail is electrified. However, slightly more than half of all energy used for passenger rail consists of electricity, largely for urban metro and commuter rail systems. It may be possible to use some of the same approaches to electrify freight rail. Electrified rail corridors must have sufficient transformer and other electrical capacity to handle the heavy loads of freight rail. The required infrastructure investments may be substantial and may take many years to complete. // **Passenger Ships:** Although only a small percentage of recreational boats are powered by electricity today, the market for electric recreational boats is growing rapidly and is projected to reach $20 billion / year globally by 2027. Batteries and electric motors are suitable for the typical travel distances and demand cycles of most small pleasure craft, and in some cases, it is possible to retrofit an existing boat with an electric outboard motor and batteries. Accordingly, a high setting of this policy lever may be reasonable. // **Freight Ships:** Today, few freight ships rely solely on electricity for energy. The large loads and long distances traveled by ocean-going vessels (with no opportunity to charge while underway) limit the suitability of electricity for these vessel types. However, there are freight vessels better-suited to electricity, including tug boats (which benefit from the high torque of electric motors) and offshore support vessels (which carry personnel and goods between offshore platforms and the mainland, and perform other support tasks), as these types of vessels travel predictable distances and may easily return to a dock to charge. Accordingly, a modest setting of this policy lever may be reasonable. // **Passenger Motorbikes:** Though electric motorcycles and scooters are popular in Europe and Asia, where motorbikes are commonly used for urban transportation and commuting, electric motorbikes are not yet a significant presence in the U.S., where motorbikes are mostly used for recreation. | K7: transportation-sector-main.html#ev-mandate | L7: ev-mandate.html | M7: https://autoalliance.org/energy-environment/state-electric-vehicle-mandate/ https://www.cnbc.com/2019/08/26/colorado-joins-california-in-requiring-automakers-to-sell-more-evs.html https://www.consumerreports.org/hybrids-evs/california-says-new-cars-sold-in-the-state-must-be-zero-emissions-by-2035/ https://www.greentechmedia.com/articles/read/electric-buses-are-going-to-dominate statistics from FoVObE variable https://www.prnewswire.com/news-releases/electric-boats-and-ships-2017-2027-300561222.html
A8: Transportation | B8: Electric Vehicle Subsidy | C8: Additional EV Subsidy Percentage | D8: EV Subsidy | E8: trans EV subsidy | F8: 0 | G8: 0.5 | H8: 0.01 | I8: % of vehicle cost | J8: **Description:** This policy causes government to pay for the specified percentage of the purchase price of new battery electric passenger LDVs. This is in addition to EV subsidies that exist in the Reference Case case. // **Guidance for setting values:** The U.S. currently offers a federal subsidy for up to $7,500 for qualifying electric vehicles, which represents 20% of the MSRP of a 2017 Chevrolet Bolt EV or 21% of the MSRP of a Tesla Model 3. | K8: transportation-sector-main.html#ev-subsidy | L8: ev-subsidy.html | M8: https://www.fueleconomy.gov/feg/taxevb.shtml plus Chevrolet and Tesla websites
A9: Transportation | B9: Feebate | C9: LDVs Feebate Rate | D9: Feebate | E9: trans LDVs feebate | F9: 0 | G9: 1 | H9: 0.02 | I9: % of global best practice rate | J9: **Description:** This policy implements a fee on sales of inefficient light-duty vehicles (LDVs; namely cars and SUVs) that is rebated to buyers of efficient LDVs. The feebate policy is revenue-neutral, as the pivot point (the efficiency level that incurs neither a rebate nor a fee) is set such that the total of all fees equals the total of all rebates. // **Guidance for setting values:** The feebate is set as a fraction of the global best practice feebate rate. The global best practice feebate rate is $2000 per (hundredth gal/mile), which equates to a $2000 fee on an LDV that gets 20 mpg if the pivot point is 25 mpg. (To see this: 20 mpg is 0.04 gpm. 25 mpg is 0.05 gpm. The difference is -.01 gpm. So in order to levy a $2000 fee on the 20 mpg car when the pivot point is 25 mpg, we need a rate of $2000/.01 gpm.) | K9: transportation-sector-main.html#feebate | L9: feebate.html | M9: Greene et al., 2005, "Feebates, rebates and gas-guzzler taxes: a study of incentives for increased fuel economy", Energy Policy, 33(6), 757-775, http://cta.ornl.gov/cta/Publications/Reports/FeebateEnergyPolicy_FINAL.pdf. | N9: John German and Dan Meszler, 2010, "Best Practices for Feebate Program Design and Implementation", ICCT, http://www.theicct.org/sites/default/files/publications/ICCT_feebates_may2010.pdf, Table 2
A10: Transportation | B10: Fuel Economy Standard | C10: Percentage Additional Improvement of Fuel Economy Std | D10: Vehicle Fuel Economy Standards | E10: trans fuel economy standards | F10: 0 | G10: 1 | H10: 0.01 | I10: % increase in miles/gal | J10: **Description:** This policy specifies a percentage improvement in fuel economy (distance traveled on the same quantity of fuel with the same cargo or passenger loading) due to fuel economy standards for newly sold vehicles of the selected type(s) with fossil fuel-burning engines. // **Guidance for setting values:** // **LDVs:** U.S. combined fuel economy standards for cars and light trucks were 35.5 mpg in 2016 and are scheduled to rise to 54.5 through 2025, then remain constant. The National Research Council has identified a maximum 4.5% annual improvement in LDV fuel economy through 2040, which corresponds to a policy setting of 88%. // **Passenger HDVs:** U.S. fuel economy standards for heavy-duty vehicles vary by vehicle characteristics, but proposed standards for vocational vehicles (the category that includes buses) would reduce GHG emissions by 24% for 2027 model year vehicles relative to the 2018 model year, then remain constant. Extrapolating this trend to 2050 would be an 85% improvement relative to 2018, compared to a 40% improvement relative to 2018 in the Reference Case case. This could be represented by a policy lever setting of 45%. // **Freight HDVs:** U.S. fuel economy standards for heavy-duty vehicles vary by vehicle characteristics, but proposed standards for combination tractor-trailers (which are responsible for roughly 60% of HDV emissions) would reduce GHG emissions by 25% for 2027 model year trucks relative to the 2018 model year, then remain constant. Extrapolating this trend to 2050 would be an 96% improvement relative to 2018, compared to a 40% improvement relative to 2018 in the Reference Case case. This could be represented by a policy lever setting of 56%. // **Passenger Aircraft:** The U.S. currently does not have fuel economy standards for aircraft. In the absence of standards, new passenger aircraft fuel economy is projected to improve roughly 17% from 2018-2050 in the Reference Case case. // **Freight Aircraft:** The U.S. currently does not have fuel economy standards for aircraft. In the absence of standards, new freight aircraft fuel economy is projected to improve roughly 50% from 2018-2050 in the Reference Case case. // **Passenger Rail:** The U.S. currently does not have fuel economy standards for trains. In the absence of standards, new passenger train fuel economy is not projected to change significantly from 2018-2050 in the Reference Case case. // **Freight Rail:** The U.S. currently does not have fuel economy standards for trains. In the absence of standards, new freight train fuel economy is projected to improve roughly 23% from 2018-2050 in the Reference Case case. // **Passenger Ships:** The U.S. currently does not have fuel economy standards for ships. In the absence of standards, new passenger ship fuel economy is not projected to change significantly from 2018-2050 in the Reference Case case. // **Freight Ships:** The U.S. currently does not have fuel economy standards for ships. In the absence of standards, new freight ship fuel economy is projected to improve roughly 21% from 2018-2050 in the Reference Case case. however, the ICCT suggests in-use CO2 intensity of freight ships could fall by roughly 50% by 2040, corresponding to a 100% improvement in fuel economy. // **Passenger Motorbikes:** The U.S. currently does not have fuel economy standards for motorbikes. In the absence of standards, new motorbike fuel economy is not projected to change significantly from 2018-2050 in the Reference Case case. | K10: transportation-sector-main.html#fuel-econ-std | L10: fuel-economy-standard.html | M10: U. S. EPA, 2012, "Fact Sheet: EPA and NHTSA Set Standards to Reduce Greenhouse Gases and Improve Fuel Economy for Model Years 2017-2025 Cars and Light Trucks", https://nepis.epa.gov/Exe/ZyNET.exe/P100EZ7C.txt?ZyActionD=ZyDocument&Client=EPA&Index=2011%20Thru%202015&Docs=&Query=&Time=&EndTime=&SearchMethod=1&TocRestrict=n&Toc=&TocEntry=&QField=&QFieldYear=&QFieldMonth=&QFieldDay=&UseQField=&IntQFieldOp=0&ExtQFieldOp=0&XmlQuery=&File=D%3A%5CZYFILES%5CINDEX%20DATA%5C11THRU15%5CTXT%5C00000005%5CP100EZ7C.txt&User=ANONYMOUS&Password=anonymous&SortMethod=h%7C-&MaximumDocuments=1&FuzzyDegree=0&ImageQuality=r75g8/r75g8/x150y150g16/i425&Display=hpfr&DefSeekPage=x&SearchBack=ZyActionL&Back=ZyActionS&BackDesc=Results%20page&MaximumPages=1&ZyEntry=4, Table 1, Row 4. U.S. EPA, 2015, "EPA and NHTSA Propose Standards to Reduce Greenhouse Gas Emissions and Improve Fuel Efficiency of Medium- and Heavy-Duty Vehicles for Model Year 2018 and Beyond", https://nepis.epa.gov/Exe/ZyNET.exe/P100P7NL.txt?ZyActionD=ZyDocument&Client=EPA&Index=2016%20Thru%202020&Docs=&Query=&Time=&EndTime=&SearchMethod=1&TocRestrict=n&Toc=&TocEntry=&QField=&QFieldYear=&QFieldMonth=&QFieldDay=&UseQField=&IntQFieldOp=0&ExtQFieldOp=0&XmlQuery=&File=D%3A%5CZYFILES%5CINDEX%20DATA%5C16THRU20%5CTXT%5C00000002%5CP100P7NL.txt&User=ANONYMOUS&Password=anonymous&SortMethod=h%7C-&MaximumDocuments=1&FuzzyDegree=0&ImageQuality=r75g8/r75g8/x150y150g16/i425&Display=hpfr&DefSeekPage=x&SearchBack=ZyActionL&Back=ZyActionS&BackDesc=Results%20page&MaximumPages=1&ZyEntry=3, Page 3. https://theicct.org/sites/default/files/publications/ICCT_ShipEfficiency_20130723.pdf Others calculated from model input data. | N10: National Research Council, 2013, "Transitions to Alternative Vehicles and Fuels", https://www.nap.edu/catalog/18264/transitions-to-alternative-vehicles-and-fuels, Table 2.9, Fuel economy test mpg. U.S. DoE, 2013, "Potential for Energy Efficiency Improvement Beyond the Light-Duty-Vehicle Sector," http://www.nrel.gov/docs/fy13osti/55637.pdf, Table 2.2 and Section 3.4.5, Paragraph 1 David McCollum, Gregory Gould, and Davide Greene, 2009, "Greenhouse Gas Emissions from Aviation and Marine Transportation: Mitigation Potential and Policies", Pew Center on Global Climate Change, http://www.c2es.org/docUploads/aviation-and-marine-report-2009.pdf, Table 4 https://theicct.org/sites/default/files/publications/ICCT_ShipEfficiency_20130723.pdf
A11: Transportation | B11: Hydrogen Vehicle Sales Standard | C11: Minimum Required Hydrogen Vehicle Sales Percentage | D11: Hydrogen Veh Sales Standard | E11: trans hydrogen vehicle minimum | F11: 0 | G11: 1 | H11: 0.01 | I11: % of new vehicles sold | J11: **Description:** This policy requires the specified percentage of newly sold vehicles of the selected type(s) to consist of hydrogen vehicles. If that percentage would already be achieved through Reference Case sales plus the effects of other policies, this policy has no effect. Manufactures may meet a sales standard through techniques such as more heavily marketing hydrogen vehicles, lowering the price of hydrogen vehicles, or raising the price of non-hydrogen vehicles. // **Guidance for setting values:** // **Road Vehicles:** No U.S. state has a hydrogen vehicle sales mandate (though hydrogen vehicles are included as a compliance option under zero-emissions vehicle mandates). Only about 5000 hydrogen vehicles are on U.S. roads today (roughly 0.002% of U.S. vehicles). Japan, potentially the country with the greatest commitment to hydrogen vehicles, aims to have 200,000 hydrogen vehicles on its roads by 2025 (which will comprise roughly 0.3% of Japan's vehicles). // **Aircraft:** The use of hydrogen as a fuel for aircraft has been studied, and small prototype aircraft have been built and flown. However, this remains a technology in early stages, and much research and development work would be required to reach commercialization, particularly for large aircraft. // **Rail:** Hydrogen is not commonly used for rail vehicles today, but given trains' ability to carry large fuel tanks, no serious technical barriers exist to more widespread usage. The first hydrogen-powered train, the Coradia iLint, entered service in 2018 (in Germany), and 14 more hydrogen trains are planned for that line. // **Ships:** Hydrogen is not commonly used for ships today, but given ships' ability to carry large fuel tanks, no serious technical barriers exist to more widespread usage. A handful of hydrogen-powered ships have entered service since the mid-2000s, including several passenger ferries. Due to the difficulty of making battery electric, long-haul freight ships, hydrogen is often seen as one of the best options for decarbonizing these types of ships. | L11: hydrogen-vehicle-mandate.html | M11: https://wamu.org/story/19/03/18/japan-is-betting-big-on-the-future-of-hydrogen-cars/
A12: Transportation | B12: Low Carbon Fuel Standard | C12: Additional LCFS Percentage | D12: Low Carbon Fuel Standard | E12: trans LCFS | F12: 0 | G12: 0.2 | H12: 0.01 | I12: % reduction in carbon emissions | J12: **Description:** This policy specifies the percentage reduction in carbon emissions from the transportation sector that must be achieved via fuel switching. This value is in addition to Reference Case requirements. // **Guidance for setting values:** The U.S. National Renewable Fuel Standard equates to a Reference Case LCFS of 2.2% - 4.6% (varying by year). California adopted an LCFS that requires a 10% reduction in carbon intensity of the transportation fuel pool by 2020. | K12: transportation-sector-main.html#lcfs | L12: low-carbon-fuel-standard.html | M12: https://www.arb.ca.gov/fuels/lcfs/background/basics.htm
A13: Transportation | B13: Mode Shifting | C13: Percent of Travel Demand Shifted to Other Modes or Eliminated | D13: Mode Shifting | E13: trans mode shifting | F13: 0 | G13: 0.26 | H13: 0.01 | I13: % of trips shifted | J13: **Description:** This policy represents a set of measures aimed at reducing demand for passenger or freight transportation in the selected vehicle type(s). **Passenger LDV** trips may be shifted to other travel modes, such as buses, rail, walking, biking, or eliminated through technology such as videoconferencing. Example measures include improved public transit systems, more walking and bike paths, zoning for higher density along transit corridors, zoning for mixed-use developments, roadway and congestion pricing, and increased parking fees. **Aircraft** trips may be shifted to inter-city rail or eliminated using technology such as videoconferencing. **Freight Truck** trips can be reduced through improved logistics that avoids backhauls and transporting empty shipping containers. // **Guidance for setting values:** // **Passenger LDVs:** The International Energy Agency's BLUE Shifts scenario (from the 2009 report "Transport, Energy, and CO2: Moving Toward Sustainability") includes a 26% reduction in usage of cars and SUVs in OECD countries by 2050 relative to a Reference Case case. // **Aircraft:** The International Energy Agency's BLUE Shifts scenario (from the 2009 report "Transport, Energy, and CO2: Moving Toward Sustainability") includes a 30% reduction in usage of aircraft in OECD countries by 2050 relative to a Reference Case case. // **Freight Trucks:** The U.S. Federal Highway Administration reports that approximately 25% of mileage for trucks larger than pickups/minivans/other light vans are for empty backhauls and empty shipping containers. | K13: transportation-sector-main.html#tdm | L13: transportation-demand-management.html | M13: International Energy Agency, 2009, "Transport, Energy and CO2: Moving toward Sustainability", http://www.iea.org/publications/freepublications/publication/transport2009.pdf "Freight Facts and Figures", 2013, https://ops.fhwa.dot.gov/freight/freight_analysis/nat_freight_stats/docs/13factsfigures/pdfs/fff2013_highres.pdf
A14: Buildings and Appliances | B14: Building Component Electrification | C14: Fraction of New Bldg Components Shifted to Other Fuels | D14: Building Component Electrification | E14: bldgs new component fuel shifting | F14: 0 | G14: 1 | H14: 0.01 | I14: % of newly sold non-electric building components | J14: **Description:** This policy replaces the specified fraction of newly sold non-electric building components of the selected type(s) in buildings of the selected type(s) with electricity-using components. // **Guidance for setting values: ** // **Mexico:** // In the Reference case for Mexico, the share of electricity among fuels used by urban and rural residential buildings its 28% in Mexico, and in commercial buildings is 50%. // ** ** // **Urban Residential Heating:** // In the Reference Case case, in the United States, the share of electricity among fuels used for heating in urban, residential buildings will fall from 12% to 11% through 2050. // **Urban Residential Appliances:** In the Reference Case case, in the United States, the share of electricity among fuels used by appliances in urban, residential buildings will remain constant at roughly 50% through 2050. // **Urban Residential Other Components:** In the Reference Case case, in the United States, the share of electricity among fuels used by other components in urban, residential buildings will rise from 87% to 88% through 2050. // **Rural Residential Heating:** In the Reference Case case, in the United States, the share of electricity among fuels used for heating in rural, residential buildings will fall from 12% to 11% through 2050. // **Rural Residential Appliances:** In the Reference Case case, in the United States, the share of electricity among fuels used by appliances in rural, residential buildings will remain constant at roughly 50% through 2050. // **Rural Residential Other Components:** In the Reference Case case, in the United States, the share of electricity among fuels used by other components in urban, residential buildings will rise from 87% to 88% through 2050. // **Commercial Heating:** In the Reference Case case, in the United States, the share of electricity among fuels used for heating in commercial buildings will fall from 4% to 3% through 2050. // **Commercial Appliances:** In the Reference Case case, in the United States, the share of electricity among fuels used by appliances in commercial buildings will fall from 45% to 42% through 2050. // **Commercial Other Components:** In the Reference Case case, in the United States, the share of electricity among fuels used by other components in commercial buildings will fall from 68% to 65% through 2050. | K14: buildings-sector-main.html#component-elec | L14: building-component-electrification.html | M14: EIA AEO
A15: Buildings and Appliances | B15: Building Energy Efficiency Standards | C15: Reduction in E Use Allowed by Component Eff Std | D15: Building Energy Efficiency Standards | E15: bldgs efficiency standards | F15: 0 | G15: 0.75 | H15: 0.01 | I15: % reduction in energy use | J15: **Description:** This policy tightens energy efficiency standards for the selected component(s) in the selected building type(s). The policy only applies to newly sold components each year (whether for new buildings or replacement of old components of existing buildings). // **Guidance for setting values:** In "Assessment of Electricity Savings in the U.S. Achievable through New Appliance/Equipment Efficiency Standards and Building Efficiency Codes, 2010-2025" (2011), the Edison Foundation considered a 30% reduction in whole-building energy use (moderate case) and 40-45% (aggressive case) relative to Reference Case from 2010 to 2025. | K15: buildings-sector-main.html#eff-stds | L15: building-energy-efficiency-standards.html | M15: Edison Foundation, 2011, "Assessment of Electricity Savings in the U.S. Achievable through New Appliance/Equipment Efficiency Standards and Building Efficiency Codes (2010 - 2025)", http://www.edisonfoundation.net/iei/Documents/IEE_CodesandStandardsAssessment_2010-2025_UPDATE.pdf, Page B-2, Table B-1. | N15: Itron, 2007, "ASSESSMENT OF LONG-TERM ELECTRIC ENERGY EFFICIENCY POTENTIAL IN CALIFORNIA’S RESIDENTIAL SECTOR," http://www.energy.ca.gov/2007publications/CEC-500-2007-002/CEC-500-2007-002.PDF, p.33, Table 5-1
A16: Buildings and Appliances | B16: Contractor Training | C16: Boolean Improved Contractor Edu and Training | D16: Contractor Training | E16: bldgs contractor training | F16: 0 | G16: 1 | H16: 1 | I16: on/off | J16: **Description:** This policy represents a program to train contractors in energy-efficient products and installation practices. This covers activities such as air sealing, building framing, and choice and application of insulation. This policy affects newly sold building envelope components, which reduce the energy use of heating, cooling, and ventilation systems in buildings by 3.7% (based on a 2006 study from the Energy Center of Wisconsin). | K16: buildings-sector-main.html#contractor-ed | L16: contractor-training.html
A17: Buildings and Appliances | B17: Distributed Solar Carve-Out | C17: Min Fraction of Total Elec Demand to be Met by Distributed Solar PV | D17: Distributed Solar Promotion | E17: bldgs min fraction distributed solar | F17: 0 | G17: 0.24 | H17: 0.005 | I17: minimum % elec from solar | J17: **Description:** This policy requires at least the specified percentage of total retail electricity demand to be generated by residential and commercial buildings' distributed solar systems (typically rooftop PV). // **Guidance for setting values:** Colorado has established a 3% carve-out for 2020 (though it includes non-solar on-site sources). | K17: buildings-sector-main.html#solar-carve-out | L17: solar-carve-out.html | M17: MASSACHUSETTS: http://www.mass.gov/eea/energy-utilities-clean-tech/renewable-energy/solar/rps-solar-carve-out/current-status-of-the-rps-solar-carve-out-program.html COLORADO: http://www.seia.org/research-resources/rps-solar-carve-out-colorado | N17: RMI, 2011, "Reinventing Fire Electricity Sector Methodology," http://www.rmi.org/cms/Download.aspx?id=10765&file=Reinventing+Fire+Electricity+Sector+Methodology.pdf&title=Reinventing+Fire+Electricity+Sector+Methodology, Page 11, 2050 Generation by Case
A18: Buildings and Appliances | B18: Distributed Solar Subsidy | C18: Perc Subsidy for Distributed Solar PV Capacity | D18: Distributed Solar Promotion | E18: bldgs distributed solar subsidy | F18: 0 | G18: 0.5 | H18: 0.01 | I18: % of PV system cost | J18: **Description:** This policy causes the government to reimburse building owners for a percentage of the cost of new distributed solar PV capacity that is installed on or around buildings. // **Guidance for setting values:** The federal Business Energy Investment Tax Credit (ITC) (whose effects are accounted for in the Reference Case case in this simulator) offers a 30% rebate through 2019, with lower values thereafter. Mexico has used similar subsidies in their sustainable housing programs, where efficient components are swapped freely or available at a reduced cost for social-interest housing. | K18: buildings-sector-main.html#distributed-solar-subsidy | L18: distributed-solar-subsidy.html | M18: Department of Energy. Business Energy Investment Tax Credit (ITC). http://energy.gov/savings/business-energy-investment-tax-credit-itc
A19: Buildings and Appliances | B19: Improved Labeling | C19: Boolean Improved Device Labeling | D19: Improved Labeling | E19: bldgs device labeling | F19: 0 | G19: 1 | H19: 1 | I19: on/off | J19: **Description:** This policy represents a program requiring newly sold heating systems, cooling and ventilation systems, and appliances to feature prominent, well-designed labels highlighting their energy efficiencies. The policy reduces energy consumption of newly sold building components of these types by 10%. | K19: buildings-sector-main.html#device-labeling | L19: improved-labeling.html | M19: none
A20: Buildings and Appliances | B20: Retrofit Existing Buildings | C20: Share of Preexisting Buildings Subject to Retrofitting | D20: Increased Retrofitting | E20: bldgs retrofitting | F20: 0 | G20: 0.5 | H20: 0.01 | I20: % of existing buildings | J20: **Description:** Each year, the specified percentage of the selected building type(s) that existed at the start of the model run will be retrofit with more efficient heating, cooling, and envelope components. // **Guidance for setting values:** By 2050, roughly 37% of the preexisting buildings will still survive without major renovations, so a value of 37% will retrofit all such surviving buildings by 2050. Policy settings higher than this will retrofit all eligible buildings sooner than 2050. | K20: buildings-sector-main.html#retrofitting | L20: increased-retrofitting.html | M20: Calculated from model data; see the relevant variable(s) in the InputData folder for source information.
A21: Buildings and Appliances | B21: Rebate for Efficient Products | C21: Boolean Rebate Program for Efficient Components | D21: Rebate for Efficient Products | E21: bldgs rebate | F21: 0 | G21: 1 | H21: 1 | I21: on/off | J21: **Description:** This policy represents a modest rebate paid to customers who purchase energy-efficient building equipment of the selected type(s). Typical rebate amounts represented by this policy are $50-100 for a clothes washer and $25-50 for a dishwasher or refrigerator. Mexico has used similar subsidies in their sustainable housing programs, where old components are swapped freely or at a discount. | K21: buildings-sector-main.html#rebate | L21: rebate-for-efficient-products.html
A22: Electricity Supply | B22: Ban New Power Plants | C22: Boolean Ban New Power Plants | D22: Ban New Power Plants | E22: elec ban new power plants | F22: 0 | G22: 1 | H22: 1 | I22: on/off | J22: **Description:** This policy prevents new capacity of the selected type(s) from being built or deployed. | K22: electricity-sector-main.html#ban | L22: ban-new-capacity.html
A23: Electricity Supply | B23: Carbon Capture and Sequestration | C23: Electricity Sector Fraction of Potential Additional CCS Achieved | D23: Electricity Sector CCS | E23: elec CCS | F23: 0 | G23: 1 | H23: 0.01 | I23: % of CO2 captured | J23: **Description:** This policy specifies the fraction of CO2 emissions from power plants that is captured and stored, above the amount predicted in the business-as-usual scenario. // **Guidance for setting values:** As very few CCS-equipped power plants exist today, a value above 20% or so is likely very optimistic in most policy scenarios. The main exception would be a scenario in which most fossil power plants retire due to other policies, making it feasible to equip a high percentage of the few surviving fossil plants with CCS. | K23: ccs.html#ccs | L23: carbon-capture-and-sequestration.html
A24: Electricity Supply | B24: Clean Electricity Standard | C24: Renewable Portfolio Std Percentage | D24: Clean Electricity Standard | E24: elec renewable portfolio standards | F24: 0 | G24: 1 | H24: 0.01 | I24: % of electricity generation | J24: **Description:** This policy specifies an increase in the fraction of electricity generation that must come from qualifying carbon-free sources (wind, solar, biomass, nuclear, hydro, and geothermal) in 2050. This policy has no effect until the user-set value exceeds the existing fraction of carbon-free electricity and any carbon-free electricity standards which have been enacted at the state level, which in total reaches 51% in 2050 as a generation-weighted national average. In 2020, the value is 36%. To set a carbon-free electricity standard that starts ramping up in 2021, the Customize Implementation Schedule feature below allows users to customize the start year setting. Simply take the 36% value, divide by your chosen policy setting, and enter the resulting value in the "Implementation %" box for 2020. // **Guidance for setting values:** Multiple states have set 100% clean energy or renewable energy laws or goals, including California, Hawaii, New Jersey, New York, Washington, New Mexico, Maine, Wisconsin, Minnesota, Nevada, and Washington DC. The earliest 100% target is Washington DC by 2032, with other states pledging to reach 100% clean or renewable energy by 2040-2050. When setting a high CES with this lever, users should also turn on supporting power sector policies (i.e., Grid-Scale Electricity Storage, Increase Transmission, and Demand Response) to avoid curtailment of renewables. At very high CES values, the associated policy costs are highly uncertain and should be complemented with other modeling. | K24: electricity-sector-main.html#ces | L24: clean-energy-standard.html | M24: White House, 2015, "Fact Sheet: President Obama to Announce Historic Carbon Pollution Standards for Power Plants", https://www.whitehouse.gov/the-press-office/2015/08/03/fact-sheet-president-obama-announce-historic-carbon-pollution-standards.
A25: Electricity Supply | B25: Change Electricity Exports | C25: Percent Change in Electricity Exports | D25: Electricity Imports and Exports | E25: elec change exports | F25: -0.5 | G25: 1 | H25: 0.02 | I25: % change in exports | J25: **Description:** This policy increases or decreases the amount of electricity exported from Mexico to the United States, Belize and Guatemala. It does not cause the construction or removal of transmission lines linking these countries. // **Guidance for setting values:** From 2010 to 2016 electricity exports have grown at 6% p.a. from 22 to 31 PJ. // From 2010-2014, U.S. electricity exports declined by 30%. | K25: electricity-sector-main.html#elec-exports | L25: electricity-imports-exports.html | M25: Energy Information Administation. 2016. Electric Power Annual. Table 2.13.
A26: Electricity Supply | B26: Change Electricity Imports | C26: Percent Change in Electricity Imports | D26: Electricity Imports and Exports | E26: elec change imports | F26: -0.5 | G26: 1 | H26: 0.02 | I26: % change in imports | J26: **Description:** This policy increases or decreases the amount of electricity imported to the United States from Canada and Mexico. It does not cause the construction or removal of transmission lines linking these countries. // **Guidance for setting values:** From 2010 to 2016 electricity imports have grown from what have been a fairly constant 1.5 PJ to 12 PJ by 2016, although electricity imports are still 40% of exports (31 PJ). // From 2010-2014, U.S. electricity imports grew by 48%. | K26: electricity-sector-main.html#elec-imports | L26: electricity-imports-exports.html | M26: Energy Information Administation. 2016. Electric Power Annual. Table 2.13.
A27: Electricity Supply | B27: Non Reference Case Guaranteed Dispatch | C27: Boolean Use Non BAU Guaranteed Dispatch Settings | D27: Non Reference Case Guaranteed Dispatch | E27: elec non BAU guaranteed dispatch | F27: 0 | G27: 1 | H27: 1 | I27: on/off
A28: Electricity Supply | B28: Demand Response | C28: Fraction of Additional Demand Response Potential Achieved | D28: Demand Response | E28: elec demand response | F28: 0 | G28: 1 | H28: 0.01 | I28: % of potential achieved | J28: **Description:** This policy represents regulations that cause more demand response (DR) capacity to be added to the electric grid. Demand response provides flexibility that allows for the integration of more wind and solar PV, if the electricity system is flexibility-constrained. // **Guidance for setting values:** This lever adds additional demand response capacity on top of Reference case values. | K28: electricity-sector-main.html#dr | L28: demand-response.html | M28: Calculated from model data; see the relevant variable(s) in the InputData folder for source information.
A29: Electricity Supply | B29: Early Retirement of Power Plants | C29: Annual Additional Capacity Retired due to Early Retirement Policy | D29: Early Retirement of Power Plants | E29: elec early retirement | F29: 0 | G29: 25000 | H29: 500 | I29: MW/year | J29: **Description:** This policy causes the specified quantity of otherwise non-retiring capacity of the selected type(s) to be retired each year. // **Guidance for setting values:** // **PRODESEN's schedule has 1400 MW of coal capacity retirement in 2029-2030. Additional retirement projects up to 2800 MW retired by 2050 in the reference scenario. An "Accelerated Coal Retirement" policy should not exceed existing coal capacity (5387MW) plus any added by the model. //**Hard Coal:** The EIA Annual Energy Outlook 2015's "Accelerated Coal Retirements" scenario predicts an additional 53.3 GW of coal retirements beyond the reference (Reference Case) scenario by 2030, which is roughly 4,500 MW/year. // **Natural Gas Non-Peaker:** The U.S. has about 255 GW of natural gas non-peaker plants, which is expected to grow somewhat by about 30 GW by 2050. // **Nuclear:** The U.S. has about 100 GW of nuclear reactors, about 20 GW of which are projected to retire by 2050 in the Reference Case case. To retire half of the remainder by 2050 would require about 1200 MW/year of accelerated retirements. // **Natural Gas Peaker:** The U.S. has about 195 GW of natural gas peaker plants, of which 20 GW are projected to retire by 2050. // **Lignite:** The U.S. has about 7,000 MW of lignite power plants, none of which are projected to retire by 2050 in the Reference Case case. | K29: electricity-sector-main.html#early-ret | L29: early-retirement-of-power-plants.html | M29: Energy Information Administration, 2014, "Annual Energy Outlook 2014", http://www.eia.gov/oiaf/aeo/tablebrowser/#release=AEO2014&subject=6-AEO2014&table=9-AEO2014&region=0-0&cases=hccstom-d012314a,ref2014-d102413a, Table Browser. Select Electric Power Sector, Electricity Generating Capacity (and check Reference and Accelerated coal retirements scenarios). | N29: The Brattle Group, 2012, "Potential Coal Plant Retirements: 2012 Update," http://greatlakeslegalfoundation.org/wwcms/wp-content/uploads/documents/regulatory/TrainWreck/12Oct15_BrattleStudy.pdf, Page 8, Table 4
A30: Electricity Supply | B30: Grid-Scale Electricity Storage | C30: Fraction of Additional Grid Battery Storage Potential Achieved | D30: Grid-Scale Electricity Storage | E30: elec storage growth | F30: 0 | G30: 1 | H30: 0.01 | I30: % of potential achieved | J30: **Description:** This policy causes grid-scale electricity storage from chemical batteries to increase above the amount predicted in the Reference Case Scenario. // **Guidance for setting values:** In 2019, the U.S. had about 1,400 MW of grid battery storage. The Reference Case scenario is based on EIA AEO data and sees grid battery capacity reach 17,400 MW by 2050. The additional potential is based on NREL's Renewable Electricity Futures Study (80% RE-ITI (2014) scenario) and suggests the U.S. could reach 120,000 MW of grid battery storage by 2050. | K30: electricity-sector-main.html#storage | L30: grid-scale-electricity-storage.html | M30: National Renewable Energy Laboratory, 2014, Renewable Electricity Futures Scenario Viewer, http://www.nrel.gov/analysis/re_futures/data_viewer/# 80% RE-ITI (2014) scenario
A31: Electricity Supply | B31: Increase Transmission | C31: Percentage Increase in Transmission Capacity vs BAU | D31: Increase Transmission | E31: elec transmission growth | F31: 0 | G31: 1.13 | H31: 0.01 | I31: % increase in transmission capacity | J31: **Description:** This policy causes additional transmission capacity to be built relative to the Reference Case case. Transmission increases the flexibility of the grid, allowing for the integration of more wind and solar PV, if the electricity system is flexibility-constrained. // **Guidance for setting values:** NREL's Renewable Electricity Futures study suggest that the most economical method of achieving 50% renewables penetration involves building roughly 37 million MW-miles of new transmission capacity, an increase of 21% beyond the existing 150-200 million MW-miles. | K31: electricity-sector-main.html#transmission | L31: increase-transmission.html | M31: National Renewable Energy Laboratory, 2014, Renewable Electricity Futures (Vol. 1), http://www.nrel.gov/docs/fy12osti/52409-1.pdf, Page xli, Figure ES-8, 80% RE scenario. | N31: National Renewable Energy Laboratory, 2014, Renewable Electricity Futures (Vol. 1), http://www.nrel.gov/docs/fy12osti/52409-1.pdf, Page 2-10, 90% RE scenario.
A32: Electricity Supply | B32: Non Reference Case Capacity Retirement Schedule | C32: Boolean Use Non BAU Capacity Retirement Schedule | D32: Non Reference Case Capacity Retirement Schedule | F32: 0 | G32: 1 | H32: 1 | I32: on/off | J32: **Description:** This policy uses an alternative retirement schedule for existing capacity of the selected type(s). // **Guidance for setting values:** The Reference Case scenario uses retirements from the Energy Information Administration's Annual Energy Outlook (AEO), which includes some economic retirements. Toggling this policy on will only retire announced, planned retirements and exclude the economic retirements listed in the AEO.
A33: Electricity Supply | B33: Non Reference Case Mandated Capacity Construction | C33: Boolean Use Non BAU Mandated Capacity Construction Schedule | D33: Non Reference Case Mandated Capacity Construction | F33: 0 | G33: 1 | H33: 1 | I33: on/off | J33: **Description:** The business-as-uusal case includes all planned capacity additions (provided by the U.S. Energy Information Administration). This policy blocks all planned additions of the selected type(s) that have not already received regulatory approval. // **Guidance for setting values:** // **Natural Gas Nonpeaker:** This policy levers blocks roughly 15 GW of new natural gas between now and 2025.
A34: Electricity Supply | B34: Non Reference Case RPS Qualifying Resources | C34: Boolean Use Non BAU RPS Qualifying Resource Definitions | D34: Non Reference Case RPS Qualifying Resources | E34: elec non BAU RPS qualifying resources | F34: 0 | G34: 1 | H34: 1 | I34: on/off
A35: Electricity Supply | B35: Nuclear Plant Lifetime Extension | C35: Nuclear Capacity Lifetime Extension | D35: Nuclear Lifetime Extension | F35: 0 | G35: 20 | H35: 1 | I35: year(s) | J35: **Description:** This policy extends the lifetime of all nuclear plants by the specified number of years. Laguna Verde Mexico's only Nuclear Station (1600MW, 2 reactors, 1990) had a 40 year permit, which has already been extended to 60 years (1990-2050). | K35: electricity-sector-main.html#life-ext | L35: nuclear-lifetime-extension.html | M35: El Financiero, 2020, "¿Larga vida a la nuclear Laguna Verde?", https://www.elfinanciero.com.mx/opinion/jonathan-ruiz/2021/09/24/larga-vida-a-la-nuclear-laguna-verde/ U.S. Energy Information Administration, 2014, "Almost all U.S. nuclear plants require life extension past 60 years to operate beyond 2050", http://www.eia.gov/todayinenergy/detail.cfm?id=19091. | N35: El Financiero, 2020, "¿Larga vida a la nuclear Laguna Verde?", https://www.elfinanciero.com.mx/opinion/jonathan-ruiz/2021/09/24/larga-vida-a-la-nuclear-laguna-verde/ U.S. Energy Information Administration, 2014, "Almost all U.S. nuclear plants require life extension past 60 years to operate beyond 2050", http://www.eia.gov/todayinenergy/detail.cfm?id=19091.
A36: Electricity Supply | B36: Reduce Plant Downtime | C36: Percentage Reduction in Plant Downtime | D36: Reduce Plant Downtime | E36: elec reduce plant downtime | F36: 0 | G36: 0.6 | H36: 0.01 | I36: % reduction in downtime | J36: **Description:** This policy specifies the reduction in downtime (time spent not generating power) for plants of the selected type(s) that exist at the start of the model run. This policy increases these plants' target capacity factors, but it does not force them to be dispatched if it would be uneconomical to do so. // **Guidance for setting values:** // **Preexisting Natural Gas Nonpeaker:** Preexisting natural gas nonpeakers have an average capacity factor of 48%. As part of the proposed Clean Power Plan, the EPA assumed that nonpeaking natural gas plants could be reach a 75% capacity factor (ramping up to that value over a number of years). This would represent a 49% reduction in downtime. // **New Wind:** Availability of wind cannot be changed by policy, so the main method of increasing capacity factor is technological improvement of wind turbines. The National Renewable Energy Laboratory estimates that "near-future" wind technology could increase capacity factors by about 10 percentage points in most parts of the country. The average capacity factor of new turbines in the Reference Case case is roughly 47%, so an improvement to 57% might be represented as an 19% setting of this policy lever. // **New Solar PV:** Availability of sunlight cannot be changed by policy, so the main method of improvement is increasing the efficiency of solar cells. Typical crystalline silicon cells today have efficiencies of 20-25%, while today's best multi-junction cells (used primarily in concentrator PV and aerospace applications) have efficiencies of 40-45%. If the typical cells installed in 2050 will have efficiencies similar to today's best multi-junction cells, this might be represented as a 26% setting of this policy lever. | K36: electricity-sector-main.html#red-downtime | L36: reduce-downtime.html | M36: E&E Publishing. The Clean Power Plan - A Summary. http://www.eenews.net/interactive/clean_power_plan/fact_sheets/rule National Renewable Energy Laboratory. United States (48 Contiguous States) Potential Wind Capacity Cumulative Area vs. Gross Capacity Factor. http://apps2.eere.energy.gov/wind/windexchange/pdfs/wind_maps/us_contiguous_wind_potential_chart.pdf See the discussion of multi-junction solar cells on Wikipedia at https://en.wikipedia.org/wiki/Multi-junction_solar_cell. Also NREL has a useful chart at http://www.nrel.gov/ncpv/images/efficiency_chart.jpg.
A37: Electricity Supply | B37: Reduce Soft Costs | C37: Percent Reduction in Soft Costs of Capacity Construction | D37: Reduce Soft Costs | E37: elec reduce soft costs | F37: 0 | G37: 0.9 | H37: 0.01 | I37: % reduction in soft costs | J37: **Description:** This policy specifies a reduction in soft costs (costs for things other than capital equipment) for new plants of the selected type(s), such as the costs of permitting, financing, project management, assembly, etc. // **Guidance for setting values:** Costs of permitting and financing can be reduced by streamlining permitting processes, but some soft costs (such as labor) may be difficult to reduce via policy. A value of 50% would be an aggressive soft cost reduction. | K37: endogenous-learning.html#red-soft-costs | L37: reduce-soft-costs.html
A38: Electricity Supply | B38: Reduce Transmission & Distribution Losses | C38: Percentage TnD Losses Avoided | D38: Reduce T&D Losses | E38: elec avoid TND loss | F38: 0 | G38: 0.4 | H38: 0.01 | I38: % of losses avoided | J38: **Description:** This policy specifies the reduction in transmission and distribution losses that will be achieved by 2050. // **Guidance for setting values:** Mexico's total transmission and distribution losses have fluctuated between 12.5% and 16% according to World Bank. A relevant share of this is due to unenforced illicit use of electricity. As a reference, The U.S. has transmission and distribution losses of about 6%. Germany, Japan, Finland, and the Netherlands have T&D losses of around 4%. Therefore, a 33% policy setting would cause the U.S. to match these countries' current level of T&D losses by 2050. | K38: electricity-sector-main.html#red-tnd-losses | L38: reduce-tnd-losses.html | M38: The World Bank. Electric power transmission and distribution losses (% of output). http://data.worldbank.org/indicator/EG.ELC.LOSS.ZS
A39: Electricity Supply | B39: Subsidy for Capacity Construction | C39: Perc Subsidy for Elec Capacity Construction | D39: Subsidy for Capacity Construction | E39: elec capacity construction subsidy | F39: 0 | G39: 0.95 | H39: 0.01 | I39: % of construction cost | J39: **Description:** This policy is a subsidy paid by the government to electricity suppliers per unit of new capacity constructed. This only applies to utilities, not distributed systems (such as rooftop solar). // **Guidance for setting values:** // **Nuclear:** The U.S. Federal Government has guaranteed billions of dollars of loans for the construction new nuclear plants and has funded billions of dollars of nuclear technology R&D. The construction of two new reactors at the Vogtle power plant, the only advanced nuclear energy project under construction in the U.S., has received $12 billion in loan guarantees as of March 2019. (Loan guarantees are not equivalent to subsidies dollar-for-dollar, but they lower the cost of construction by enabling the plant to access cheaper financing.) // **Onshore Wind:** The U.S. does not have a capacity construction subsidy for onshore wind. However, the Investment Tax Credit, a similar program for solar power, covers 30% of system costs through 2019, with declining amounts thereafter. In the business-as-usual case, we also deduct a third of the ITC value to account for tax credit monetization. // **Solar PV and Solar Thermal:** The U.S. Investment Tax Credit, enacted in 2005, covers 30% of solar system costs through 2019, with declining amounts thereafter. In the business-as-usual case, we also deduct a third of the ITC value to account for tax credit monetization. // **Biomass:** The U.S. Federal Government has collectively guaranteed billions of dollars of loans for the construction new biomass plants. (Loan guarantees are not equivalent to subsidies dollar-for-dollar, but they lower the cost of construction by enabling the plant to access cheaper financing.) // **Offshore Wind:** The Investment Tax Credit covers 30% of system costs through 2025. In the business-as-usual case, we also deduct a third of the ITC value to account for tax credit monetization. | K39: electricity-sector-main.html#subsidies | M39: https://www.energy.gov/articles/secretary-perry-announces-financial-close-additional-loan-guarantees-during-trip-vogtle https://www.energysage.com/solar/cost-benefit/solar-investment-tax-credit/ http://biomassmagazine.com/articles/8185/usda-loan-guarantees-support-3-biomass-power-plants
A40: Electricity Supply | B40: Subsidy for Electricity Production | C40: Subsidy for Elec Production by Fuel | D40: Subsidy for Electricity Production | E40: elec generation subsidy | F40: 0 | G40: 60 | H40: 1 | I40: $/MWh | J40: **Description:** This policy is a subsidy paid by the government to suppliers of electricity per unit of electricity generated from the selected plant type(s). // **Guidance for setting values:** Before its phase-out began, the Renewable Electricity Production Tax Credit (PTC) offered $23/MWh for electricity from wind, geothermal, biomass, and solar systems not claiming the Investment Tax Credit. The current credit level is $25/MWh. State-level tax credits and feed-in tariffs for renewable energy range as high as $54/MWh. Note that while the PTC is currently set to expire in 2022, we assume developers can claim it through 2025 in the business-as-usual case. That is because the model only tracks the year power plants come online, but developers claim the PTC based on when constructions starts rather than when the plant comes online. In the business-as-usual case, we also deduct a third of the PTC value to account for tax credit monetization. // Also note that the Energy Policy Simulator chooses which new power plants to build based on lifetime plant costs, and the PTC is only available for the first 10 years of a project. // **Nuclear:** Because the average lifetime of a nuclear plant is 60 years, a setting of $25/MWh PTC would correspond to a lever setting of approximately $4/MWh. // **Onshore Wind, Solar PV, Solar Thermal, Offshore Wind:** Because the average lifetime of an onshore wind, solar PV, solar thermal, or offshore wind plant is 30 years, a $25/MWh credit would correspond to a lever setting of approximately $8/MWh. Note that where offshore wind developers are eligible for both the PTC and the Investment Tax Credit (ITC) in the business-as-usual case, we assume developers will choose the ITC (see the "Subsidy for Capacity Construction" policy lever). // **Biomass:** Because the average lifetime of a solar thermal plant is 45 years, a setting of $5.50/MWh PTC would correspond to a lever setting of approximately $8/MWh. | K40: electricity-sector-main.html#subsidies | L40: subsidy-for-electricity-production.html | M40: PRODUCTION TAX CREDIT: Database of State Incentives for Renewables & Efficiency, 2013, "Renewable Energy Production Tax Credit (PTC)", http://dsireusa.org/incentives/incentive.cfm?Incentive_Code=US13F. STATE-LEVEL INCENTIVES: Energy Information Administration, 2013, "Feed-In Tariffs and similar programs", http://www.eia.gov/electricity/policies/provider_programs.cfm.
...

Sheet PolicyLevers
A1: Sector | B1: Short Name | C1: Vensim Variable Name | D1: Subscript 1 Value | E1: Subscript 2 Value | F1: Subscript 1 Display Name | G1: Subscript 2 Display Name | H1: Policy ID Number | I1: Include in Web App | J1: Policy Group | K1: Policy Schedule Subscript | L1: Min Slider Value | M1: Max Slider Value | N1: Slider Step Size | O1: Units | P1: Text for Pop-Over Panel Description | Q1: URL for "How the model handles this policy" links | R1: URL for "How to design this policy well" links
