Workbook
Name BARRILES: 6.28982
Name calorcarbonII: 5164.3
Name calordiesel: 9243.22
Name Calorgas: 8967.6
Name calorpeta: 6389.256
Name calorrio: 3900.6
Name calorvacio: 13700
Name corr: 1
Name cpi_2013to2012: [1]About!$A$111
Name cpi_2014to2012: [1]About!$A$110
Name cpi_2016to2012: [1]About!$A$112
Name ft: 35.31466
Name GWP: 21
Name iva: 1.15
Name joules: 4186.8402
Name litros: 158.987
Name tonelada: 907.185

Sheet About
A1: SYVbT Start Year Vehicles by Technology
A3: Sources: | B3: On-road fleet by type of vehicle and technology
B4: Prospectiva del Sector: Petroleo Crudo y Petrolíferos v3.2.3
B5: 2023
B6: https://www.gob.mx/sener/es/articulos/prospectivas-del-sector-energetico-356380?idiom=es
B8: aircraft
B9: Secretaria de comunicaciones y transportes
B10: 2024
B11: Estadísticas de flota
B12: https://www.gob.mx/cms/uploads/attachment/file/970059/flota-reg-2024-4-trim-27012025.pdf
B13: Slide 2
B15: Freight ships fleet
B16: SCT
B17: 2022
B18: https://www.sct.gob.mx/planeacion/estadistica/anuario-estadistico-sct/
B20: Rail fleet
B21: SCT
B22: 2022
B23: Anuario Estadístico Ferroviario
B24: https://www.sct.gob.mx/planeacion/estadistica/anuario-estadistico-sct/
B25: p. 8
B27: Mexico Subway
B28: INEGI
B29: 2022
B30: Transporte Urbano de Pasajeros
B31: http://www.beta.inegi.org.mx/proyectos/registros/economicas/transporteurbano/
B32: http://www.metro.cdmx.gob.mx/operacion/cifras-de-operación
A33: Notes
A34: The start year is the year prior the first simulated year in the model.
A35: EPS Mexico v4.x model set at 2022, so start year 2021
A37: We assumed all hybrids are for passengers, since the information source doesn't include a break down for passenger and freight.
A38: In Mexico there are few natural gas pilot programs for public transport, so we did not included this type of technology.

Sheet RoadTransport
A1: Sistema de Información Energética
A2: Secretaría de Energía | T2: Secretaría de Energía
A3: Dirección General de Planeación e Información Energéticas | T3: Dirección General de Planeación e Información Energéticas
A6: Estimación de parque vehicular por tipo de energético 2023-2037 | T6: Composición regional del parque vehicular por combustible, 2018-2032
A7: (Miles de vehículos) | T7: (numero adimensional)
B9: 2022 | C9: =B9+1 -> 2023 | D9: =C9+1 -> 2024 | E9: =D9+1 -> 2025 | F9: =E9+1 -> 2026 | G9: =F9+1 -> 2027 | H9: =G9+1 -> 2028 | I9: =H9+1 -> 2029 | J9: =I9+1 -> 2030 | ... Q9: =P9+1 -> 2037 | U9: 2004 | V9: 2005 | W9: 2006 | X9: 2007 | Y9: 2008 | Z9: 2009 | AA9: 2010 | AB9: 2011 | AC9: 2012 | AD9: 2013 | AE9: 2014 | AF9: 2015 | AG9: 2016 | AH9: 2017 | AI9: 2018 | AJ9: 2019 | AK9: 2020 | AL9: 2021 | AM9: 2022 | AN9: 2023 | AO9: 2024 | AP9: 2025 | AQ9: 2026 | AR9: 2027 | AS9: 2028 | AT9: 2029 | AU9: 2030
A11: Combustible | T11: Combustible
A12: Total | B12: 43416 | C12: 43791.007 | D12: 44187.552 | E12: 44581.154 | F12: 45009.026 | G12: 45456.252 | H12: 45918.508 | I12: 46405.163 | J12: 46918.296 | K12: 47458.968 | L12: 47947.733 | M12: 48575.206 | N12: 49236.986 | O12: 49949.57 | P12: 50703.521 | Q12: 51521.545 | T12: Total | U12: 17507.465 | V12: 17646.386 | W12: 19414.64 | X12: 21264.606 | Y12: 23039.541 | Z12: 23928.615 | AA12: 25064.501 | AB12: 26492.21 | AC12: 27866.307 | AD12: 29379.433 | AE12: 29587.867 | AF12: 30681.379 | AG12: 31213.637 | AH12: 34702.614 | AI12: 34928.375 | AJ12: 35532.436 | AK12: 36067.038 | AL12: 37140.984 | AM12: 38217.409 | AN12: 39267.574 | AO12: 40047.016 | AP12: 40852.831 | AQ12: 41844.113 | AR12: 42672.969 | AS12: 43209.296 | AT12: 43817.457 | AU12: 44390.401
A13: Gasolina | B13: 42245 | C13: 42764.226 | D13: 43114.43 | E13: 43477.264 | F13: 43853.682 | G13: 44244.754 | H13: 44651.674 | I13: 45075.787 | J13: 45518.606 | K13: 45981.833 | L13: 46390.571 | M13: 46926.436 | N13: 47485.043 | O13: 48085.327 | P13: 48719.385 | Q13: 49390.405 | T13: Gas natural comprimido | U13: 1.863 | V13: 1.922 | W13: 2.924 | X13: 2.745 | Y13: 2.814 | Z13: 1.809 | AA13: 1.47 | AB13: 1.519 | AC13: 1.572 | AD13: 4.295 | AE13: 3.068 | AF13: 3.144 | AG13: 3.62 | AH13: 4.042 | AI13: 4.258 | AJ13: 4.46 | AK13: 4.777 | AL13: 5.068 | AM13: 5.317 | AN13: 5.532 | AO13: 5.711 | AP13: 5.874 | AQ13: 6.017 | AR13: 6.142 | AS13: 6.285 | AT13: 6.711 | AU13: 6.807
A14: Diésel | B14: 787 | C14: 793.644 | D14: 828.344 | E14: 855.704 | F14: 888.067 | G14: 920.041 | H14: 947.437 | I14: 977.446 | J14: 1007.738 | K14: 1038.652 | L14: 1067.411 | M14: 1098.785 | N14: 1130.31 | O14: 1161.393 | P14: 1189.609 | Q14: 1219.424 | T14: Gasolina | U14: 16514.051 | V14: 16667.116 | W14: 18476.315 | X14: 20302.972 | Y14: 22067.136 | Z14: 22961.449 | AA14: 24086.964 | AB14: 25488.435 | AC14: 26787.639 | AD14: 28226.615 | AE14: 28476.736 | AF14: 29594.818 | AG14: 30153.185 | AH14: 33626.713 | AI14: 33846.691 | AJ14: 34422.256 | AK14: 34909.11 | AL14: 35922.942 | AM14: 36938.116 | AN14: 37925.849 | AO14: 38645.135 | AP14: 39396.275 | AQ14: 40317.326 | AR14: 41082.039 | AS14: 41557.607 | AT14: 42105.79 | AU14: 42620.872
A15: Gas LP | B15: 187 | C15: 181.614 | D15: 177.411 | E15: 173.974 | F15: 171.682 | G15: 170.098 | H15: 168.84 | I15: 168.479 | J15: 168.44 | K15: 168.682 | L15: 168.841 | M15: 166.865 | N15: 166.195 | O15: 165.526 | P15: 164.856 | Q15: 164.186 | T15: Gas L.P. | U15: 329.48 | V15: 305.033 | W15: 234.535 | X15: 221.355 | Y15: 196.017 | Z15: 184.912 | AA15: 185.085 | AB15: 203.017 | AC15: 232.235 | AD15: 250.1 | AE15: 253.533 | AF15: 250.275 | AG15: 248.825 | AH15: 242.272 | AI15: 230.479 | AJ15: 223.508 | AK15: 223.505 | AL15: 225.452 | AM15: 228.296 | AN15: 232.023 | AO15: 236.281 | AP15: 240.184 | AQ15: 246.627 | AR15: 252.865 | AS15: 259.309 | AT15: 265.457 | AU15: 265.68
A16: Gas natural | B16: 13 | C16: 12.916 | D16: 13.082 | E16: 13.251 | F16: 13.175 | G16: 13.098 | H16: 13.022 | I16: 12.947 | J16: 12.872 | K16: 13.09 | L16: 13.312 | M16: 13.538 | N16: 13.768 | O16: 14.001 | P16: 14.122 | Q16: 14.243 | T16: Diesel | U16: 662.071 | V16: 672.316 | W16: 700.866 | X16: 737.533 | Y16: 773.574 | Z16: 780.444 | AA16: 790.982 | AB16: 799.239 | AC16: 844.861 | AD16: 898.422 | AE16: 854.529 | AF16: 833.143 | AG16: 808.007 | AH16: 829.587 | AI16: 846.947 | AJ16: 882.213 | AK16: 929.647 | AL16: 987.523 | AM16: 1045.679 | AN16: 1104.171 | AO16: 1159.89 | AP16: 1210.497 | AQ16: 1274.143 | AR16: 1331.923 | AS16: 1386.095 | AT16: 1439.5 | AU16: 1497.042
A17: Electricidad | B17: 23 | C17: 38.607 | D17: 54.285 | E17: 60.961 | F17: 82.42 | G17: 108.262 | H17: 137.535 | I17: 170.503 | J17: 210.64 | K17: 256.711 | L17: 307.598 | M17: 369.582 | N17: 441.671 | O17: 523.322 | P17: 615.549 | Q17: 733.287
A19: Notas: | T19: Nota:
A20: Información de la Prospectiva 2023-2037. | T20: Información de la Prospectiva 2018-2032.
A22: Fuente: Elaborado por IMP con información de AMDA, AMIA, ANPACT, BANXICO, CONUEE, CRE, EIA, EPA, INEGI, PEMEX y SENER. | T22: Referencia:
D23: =SUM(D27:D35)-D24 -> -7880787.1 | E23: =SUM(E27:E35)-E24 -> 717743.65 | F23: =SUM(F27:F35)-F24 -> -33468.658 | G23: =SUM(G27:G35)-G24 -> -2380.2195 | H23: =SUM(H27:H35)-H24 -> -7114.6745 | T23: Fuente: Sistema de Información Energética (SIE) con información de SENER.
A24: Referencia: | D24: 42764226 | E24: 793644 | F24: 181614 | G24: 12916 | H24: 38607
A25: Fuente: Sistema de Información Energética (SIE) con información de la Prospectiva de Petróleo Crudo y Petrolíferos 2023-2037. | D25: Gasolina | E25: Diésel | F25: Gas LP | G25: Gas natural | H25: Electricidad
B26: Vehículos 2022 | C26: 1000 | D26: 0.9765527 | E26: 0.018123447 | F26: 0.0041472899 | G26: 0.0002949464 | H26: 0.00088161937
A27: Camionetas | B27: 13895000 | C27: =B27/$B$36 -> 0.37980046 | D27: =$B27*D$26 -> 13569200 | E27: =$B27*E$26 -> 251825.3 | F27: =$B27*F$26 -> 57626.593 | G27: =$B27*G$26 -> 4098.2803 | H27: =$B27*H$26 -> 12250.101
A28: Compacto | B28: 9107000 | C28: =B28/$B$36 -> 0.24892716 | D28: =$B28*D$26 -> 8893465.4 | E28: =$B28*E$26 -> 165050.23 | F28: =$B28*F$26 -> 37769.369 | G28: =$B28*G$26 -> 2686.0769 | H28: =$B28*H$26 -> 8028.9076
A29: Subcompacto | B29: 7813000 | C29: =B29/$B$36 -> 0.21355747 | D29: =$B29*D$26 -> 7629806.2 | E29: =$B29*E$26 -> 141598.49 | F29: =$B29*F$26 -> 32402.776 | G29: =$B29*G$26 -> 2304.4162 | H29: =$B29*H$26 -> 6888.0921
A30: Lujo y deportivo | B30: 3117000 | C30: =B30/$B$36 -> 0.085198852 | D30: =$B30*D$26 -> 3043914.8 | E30: =$B30*E$26 -> 56490.785 | F30: =$B30*F$26 -> 12927.103 | G30: =$B30*G$26 -> 919.34794 | H30: =$B30*H$26 -> 2748.0076
A31: Camionetas uso intensivo | B31: 1789000 | C31: =B31/$B$36 -> 0.048899822 | D31: =$B31*D$26 -> 1747052.8 | E31: =$B31*E$26 -> 32422.847 | F31: =$B31*F$26 -> 7419.5016 | G31: =$B31*G$26 -> 527.65912 | H31: =$B31*H$26 -> 1577.2171
A32: Camiones pesados | B32: 505000 | C32: =B32/$B$36 -> 0.013803471 | E32: =B32 -> 505000
A33: Autobuses | B33: 241000 | C33: =B33/$B$36 -> 0.0065873992 | E33: =B33 -> 241000
A34: Camiones medianos | B34: 116000 | C34: =B34/$B$36 -> 0.0031706984 | E34: =B34 -> 116000
A35: BRT | B35: 2000 | C35: =B35/$B$36 -> 5.4667213e-05 | E35: 2000
B36: =SUM(B27:B35) -> 36585000
B38: pax
A39: LDVs | B39: =B27+B28+B29+B30 -> 33932000 | C39: =C27+C28+C29+C30 -> 0.92748394
A40: HDVs | B40: =B33+B35 -> 243000 | C40: =C33+C35 -> 0.0066420664
A41: aircraft
A42: rail
A43: ships
A44: motorbikes
B45: cargo
A46: LDVs | B46: =B31 -> 1789000 | C46: =C31 -> 0.048899822
A47: HDVs | B47: =B32+B34 -> 621000 | C47: =C32+C34 -> 0.01697417
...

Sheet Mexico AirFleet
B26: Age of air fleet in 2022 | E26: Comercial aircrafts
B27: 7.7 | E27: 2022 | F27: 358
E28: 2021 | F28: 310
B29: Lifetime estimated at twice the average age
B30: =B27*2 -> 15.4

Sheet AirFleet
D2: Passenger | E2: =E8+E129+E228 -> 188 | F2: =F8+F129+F228 -> 223 | G2: =G8+G129+G228 -> 252 | H2: =H8+H129+H228 -> 261 | I2: =I8+I129+I228 -> 225 | J2: =J8+J129+J228 -> 224 | K2: =K8+K129+K228 -> 239 | L2: =L8+L129+L228 -> 267 | ... AK2: =AK8+AK129+AK228 -> 354
D3: Freight | E3: =E291 -> 0 | F3: =F291 -> 1 | G3: =G291 -> 1 | H3: =H291 -> 9 | I3: =I291 -> 7 | J3: =J291 -> 10 | K3: =K291 -> 10 | L3: =L291 -> 8 | ... AK3: =AK291 -> 128
A5: EQUIPO DE VUELO DE LAS LÍNEAS AÉREAS NACIONALES
C7: LÍNEAS AÉREAS | D7: EQUIPO | E7: 1991 | F7: 1992 | G7: 1993 | H7: 1994 | I7: 1995 | J7: 1996 | K7: 1997 | L7: 1998 | M7: 1999 | N7: 2000 | O7: 2001 | P7: 2002 | Q7: 2003 | R7: 2004 | S7: 2005 | T7: 2006 | U7: 2007 | V7: 2008 | W7: 2009 | X7: 2010 | Y7: 2011 | Z7: 2012 | AA7: 2013 | AB7: 2014 | AC7: 2015 | AD7: 2016 | AE7: 2017 | AF7: 2018 | AG7: 2019 | AH7: 2020 | AI7: 2021 | AJ7: 2022 | AK7: 2023
C8: TRONCALES | E8: =+E9+E14+E23+E18+E40+E42+E62+E75+E79+E82+E95+E102+E119+E121 -> 130 | F8: =+F9+F14+F23+F18+F40+F42+F62+F75+F79+F82+F95+F102+F119+F121 -> 159 | G8: =+G9+G14+G23+G18+G40+G42+G62+G75+G79+G82+G95+G102+G119+G121 -> 164 | H8: =+H9+H14+H23+H18+H40+H42+H62+H75+H79+H82+H95+H102+H119+H121 -> 167 | I8: =+I9+I14+I23+I18+I40+I42+I62+I75+I79+I82+I95+I102+I119+I121 -> 143 | J8: =+J9+J14+J23+J18+J40+J42+J62+J75+J79+J82+J95+J102+J119+J121 -> 141 | K8: =+K9+K14+K23+K18+K40+K42+K62+K75+K79+K82+K95+K102+K119+K121 -> 155 | L8: =+L9+L14+L23+L18+L40+L42+L62+L75+L79+L82+L95+L102+L119+L121 -> 170 | ... AJ8: =+AJ9+AJ14+AJ23+AJ18+AJ40+AJ42+AJ62+AJ75+AJ79+AJ82+AJ95+AJ102+AJ119+AJ121 -> 299 | AK8: =+AK9+AK14+AK23+AK18+AK40+AK42+AK62+AK75+AK79+AK82+AK95+AK102+AK119+AK121+AK93 -> 302
C9: ABC AEROLÍNEAS (INTERJET) | S9: =SUM(S10:S13) -> 3 | T9: =SUM(T10:T13) -> 7 | U9: =SUM(U10:U13) -> 11 | V9: =SUM(V10:V13) -> 15 | W9: =SUM(W10:W13) -> 15 | X9: =SUM(X10:X13) -> 22 | Y9: =SUM(Y10:Y13) -> 33 | Z9: =SUM(Z10:Z13) -> 37 | ... AH9: =SUM(AH10:AH13) -> 3
D10: AIRBUS A-320 | S10: 3 | T10: 7 | U10: 11 | V10: 15 | W10: 15 | X10: 22 | Y10: 33 | Z10: 37 | AA10: 41 | AB10: 42 | AC10: 41 | AD10: 48 | AE10: 56 | AF10: 53 | AG10: 47
D11: AIRBUS A-320 NEO | AF11: 3 | AG11: 8
D12: AIRBUS A-321 NEO | AF12: 8 | AG12: 8
D13: SUKHOI SUPERJET 100 | AA13: 3 | AB13: 10 | AC13: 19 | AD13: 22 | AE13: 22 | AF13: 11 | AG13: 4 | AH13: 3
B14: 5 | C14: AEREO CALAFIA | AB14: =SUM(AB15:AB17) -> 9 | AC14: =SUM(AC15:AC17) -> 9 | AD14: =SUM(AD15:AD17) -> 8 | AE14: =SUM(AE15:AE17) -> 5 | AF14: =SUM(AF15:AF17) -> 5 | AG14: =SUM(AG15:AG17) -> 3 | AH14: =SUM(AH15:AH17) -> 3 | AI14: =SUM(AI15:AI17) -> 2 | ... AK14: =SUM(AK15:AK17) -> 1
D15: CESSNA CARAVAN | AB15: 7 | AC15: 7 | AD15: 3
D16: EMBRAER 120 | AB16: 1 | AC16: 1 | AD16: 2 | AE16: 1 | AF16: 1
D17: EMBRAER 145 | AB17: 1 | AC17: 1 | AD17: 3 | AE17: 4 | AF17: 4 | AG17: 3 | AH17: 3 | AI17: 2 | AJ17: 1 | AK17: 1
C18: AEROCALIFORNIA/a | E18: =SUM(E19:E22) -> 10 | F18: =SUM(F19:F22) -> 10 | G18: =SUM(G19:G22) -> 10 | H18: =SUM(H19:H22) -> 11 | I18: =SUM(I19:I22) -> 15 | J18: =SUM(J19:J22) -> 16 | K18: =SUM(K19:K22) -> 18 | L18: =SUM(L19:L22) -> 18 | ... V18: =SUM(V19:V22) -> 22
D19: DC-9-10 | I19: 1
D20: DC-9-14 | J20: 2 | K20: 2 | L20: 2 | M20: 2 | N20: 1 | O20: 1 | P20: 1 | Q20: 1 | R20: 1 | S20: 1 | T20: 1
D21: DC-9-15 | E21: 10 | F21: 10 | G21: 10 | H21: 11 | I21: 10 | J21: 9 | K21: 9 | L21: 9 | M21: 9 | N21: 10 | O21: 10 | P21: 10 | Q21: 10 | R21: 10 | S21: 10 | T21: 10
D22: DC-9-32 | I22: 4 | J22: 5 | K22: 7 | L22: 7 | M22: 7 | N22: 11 | O22: 11 | P22: 11 | Q22: 11 | R22: 11 | S22: 20 | T22: 21 | U22: 22 | V22: 22
B23: 3 | C23: AEROENLACES NACIONALES (VIVA AEROBUS) | T23: =SUM(T24:T39) -> 2 | U23: =SUM(U24:U39) -> 5 | V23: =SUM(V24:V39) -> 7 | W23: =SUM(W24:W39) -> 7 | X23: =SUM(X24:X39) -> 11 | Y23: =SUM(Y24:Y39) -> 17 | Z23: =SUM(Z24:Z39) -> 19 | AA23: =SUM(AA24:AA39) -> 22 | ... AK23: =SUM(AK24:AK39) -> 80
D24: AIRBUS A320 | AB24: 5 | AC24: 14 | AD24: 21 | AE24: 24 | AF24: 21 | AG24: 17 | AH24: 20 | AI24: 20 | AJ24: 24 | AK24: 26
D25: AIRBUS A320 NEO | AF25: 10 | AG25: 19 | AH25: 20 | AI25: 20 | AJ25: 20 | AK25: 18
D26: AIRBUS A321 NEO | AH26: 3 | AI26: 7 | AJ26: 17 | AK26: 26
D27: AIRBUS A321 | AI27: 7 | AJ27: 9 | AK27: 10
D28: BOEING 737-300 | AC28: 3 | AD28: 1
D29: BOEING 737-301 | T29: 1 | U29: 1 | V29: 1 | W29: 1 | X29: 4 | Y29: 4 | Z29: 4 | AA29: 4 | AB29: 1
D30: BOEING 737-33A | Y30: 4 | Z30: 6 | AA30: 6 | AB30: 6 | AC30: 3 | AD30: 1
D31: BOEING 737-36N | Y31: 1 | Z31: 1 | AA31: 2 | AB31: 1
D32: BOEING 737-36Q | AA32: 1 | AB32: 1 | AC32: 1
D33: BOEING 737-387 | T33: 1 | U33: 4 | V33: 6 | W33: 6 | X33: 5 | AA33: 1
D34: BOEING 737-3B7 | Y34: 5 | Z34: 4 | AA34: 4 | AB34: 3
D35: BOEING 737-3K2 | Z35: 1 | AA35: 1 | AB35: 1 | AC35: 1
D36: BOEING 737-3L9 | X36: 1 | Y36: 1 | AA36: 1 | AB36: 1
D37: BOEING 737-3Q8 | Y37: 1 | Z37: 1 | AA37: 1 | AB37: 1
D38: BOEING 737-3U3 | AA38: 1 | AB38: 1 | AC38: 1
D39: BOEING 737-3Y0 | X39: 1 | Y39: 1 | Z39: 2
C40: AEROLINEAS MESOAMERICANAS (ALMA)/b | T40: =SUM(T41) -> 8 | U40: =SUM(U41) -> 18 | V40: =SUM(V41) -> 15
D41: BOMBARDIER | T41: 8 | U41: 18 | V41: 15
B42: 2 | C42: AEROVIAS DE MÉXICO (AEROMÉXICO) | E42: =SUM(E43:E61) -> 45 | F42: =SUM(F43:F61) -> 54 | G42: =SUM(G43:G61) -> 57 | H42: =SUM(H43:H61) -> 56 | I42: =SUM(I43:I61) -> 51 | J42: =SUM(J43:J61) -> 53 | K42: =SUM(K43:K61) -> 59 | L42: =SUM(L43:L61) -> 63 | ... AK42: =SUM(AK43:AK61) -> 105
D43: BOEING 737-700 | Q43: 4 | R43: 16 | S43: 23 | T43: 29 | U43: 33 | V43: 33 | W43: 29 | X43: 28 | Y43: 30 | Z43: 30 | AA43: 28 | AB43: 25 | AC43: 19 | AD43: 19 | AE43: 17 | AF43: 13 | AG43: 11 | AH43: 3 | AI43: 1 | AJ43: 2
...

Sheet Rail
A26: Transporte ferroviario
A29: Longitud de vías y equipo del transporte ferroviario Serie anual 2006 ,2012 y de 2017 a 2023 | K29: Cuadro 20
A30: Concepto | B30: 2006 | C30: 2012 | D30: 2017 | E30: 2018 | F30: 2019 | G30: 2020 | H30: 2021 | I30: 2022 | J30: 2023
A32: Longitud de vias (Kilómetros) | B32: 26662 | C32: 26727 | D32: 26914 | E32: 26914 | F32: 26914 | G32: 26914 | H32: 26914 | I32: 26914 | J32: 27732
A33: Principales | B33: 20687 | C33: 20722 | D33: 20826 | E33: 20826 | F33: 20826 | G33: 20826 | H33: 20826 | I33: 20826 | J33: 22037
A34: Secundarias | B34: 4420 | C34: 4450 | D34: 4533 | E34: 4533 | F34: 4533 | G34: 4533 | H34: 4533 | I34: 4533 | J34: 2759
A35: Particulares | B35: 1555 | C35: 1555 | D35: 1555 | E35: 1555 | F35: 1555 | G35: 1555 | H35: 1555 | I35: 1555 | J35: 2937
A36: Equipo ferroviario | B36: 0 | C36: 0 | D36: 0 | E36: 0 | F36: 0 | G36: 0 | H36: 0 | I36: 0 | J36: 0
A37: Carros de carga a | B37: 32013 | C37: 30958 | D37: 33149 | E37: 32876 | F37: 31909 | G37: 32034 | H37: 30237 | I37: 30310 | J37: 30586
A38: Coches de pasajeros D | B38: 60 | C38: 129 | D38: 137 | E38: 148 | F38: 148 | G38: 148 | H38: 148 | I38: 148 | J38: 165
A39: Locomotoras c | B39: 1245 | C39: 1231 | D39: 1295 | E39: 1278 | F39: 1217 | G39: 1196 | H39: 1999 | I39: 1998 | J39: 1209
A40: 8 A partir de 2012 se refiere a los carros de carga total (incluye los carros operables y os carros que se encuentran en mantenimiento). b Incluye os coches en servicio activo y fuera de servicio. Incluye el equipo en servicio activo y fuera de servicio y no se incluyen las ocomotoras eléctricas [Cholula-PuebIa). Fuente: ARTE Agencia Reguladora del Transporte Ferroviario.

Sheet Rail Pssgr
A1: CDMX Metro | I1: CDMX Tren ligero
A3: Principales características del sistema de transporte colectivo metro de la Ciudad de México | I3: Principales características de los sistemas de transportes eléctricos en la Ciudad de México
A5: Periodo | C5: Longitud en servicio (km) a | D5: Trenes en servicio b | E5: Kilómetros recorridos | F5: Pasajeros transportados | G5: Energía eléctrica consumida | I5: Periodo | K5: Tren ligero
E6: (Miles de kilómetros) c | F6: (Miles de pasajeros) d | G6: (Miles de KWH) e | K6: Longitud en servicio (km) a | L6: Unidades en operación b | M6: Kilómetros recorridos | N6: Pasajeros transportados | O6: Ingresos por pasaje
A7: 2016 | C7: =MAX(C8:C19) -> 226 | D7: =MAX(D8:D19) -> 280 | E7: =SUM(E8:E19)*1000 -> 42620362 | F7: =SUM(F8:F19)*1000 -> 52674876 | G7: =SUM(G8:G19)*1000 -> 1169544759 | M7: (Miles de Kilómetros) | N7: (Miles de pasajeros) | O7: (Miles de pesos)
A8: Enero | C8: 226 | D8: 275 | E8: 3531.2649 | F8: 4134.2138 | G8: 97830.216 | I8: 2016 | K8: =MAX(K9:K20) -> 25 | L8: =MAX(L9:L20) -> 20 | M8: =SUM(M9:M20)*1000 -> 2105375 | N8: =SUM(N9:N20)*1000 -> 35062394 | O8: =SUM(O9:O20)*1000 -> 64480687
A9: Febrero | C9: 226 | D9: 273 | E9: 3584.4799 | F9: 4471.7183 | G9: 92449.615 | I9: Enero | K9: 25 | L9: 20 | M9: 167.204 | N9: 2395.229 | O9: 9388
A10: Marzo | C10: 226 | D10: 277 | E10: 3496.2561 | F10: 3857.0302 | G10: 97345.935 | I10: Febrero | K10: 25 | L10: 20 | M10: 170.349 | N10: 2790.126 | O10: 6374.4
A11: Abril | C11: 226 | D11: 278 | E11: 3576.9758 | F11: 4582.4189 | G11: 96357.848 | I11: Marzo | K11: 25 | L11: 20 | M11: 178.303 | N11: 2581.103 | O11: 7469.6
A12: Mayo | C12: 226 | D12: 280 | E12: 3559.7155 | F12: 4423.6272 | G12: 99297.52 | I12: Abril | K12: 25 | L12: 20 | M12: 175.038 | N12: 3738.986 | O12: 0
A13: Junio | C13: 226 | D13: 280 | E13: 3592.4546 | F13: 4513.787 | G13: 96849.359 | I13: Mayo | K13: 25 | L13: 20 | M13: 182.131 | N13: 3773.313 | O13: 0
A14: Julio | C14: 226 | D14: 279 | E14: 3544.7119 | F14: 4097.9018 | G14: 98806.009 | I14: Junio | K14: 25 | L14: 20 | M14: 178.062 | N14: 3660.346 | O14: 0
A15: Agosto | C15: 226 | D15: 277 | E15: 3563.9532 | F15: 4574.2797 | G15: 100273.31 | I15: Julio | K15: 25 | L15: 20 | M15: 187.256 | N15: 2551.433 | O15: 4393.187
A16: Septiembre | C16: 226 | D16: 278 | E16: 3526.0896 | F16: 4480.6018 | G16: 95873.568 | I16: Agosto | K16: 25 | L16: 20 | M16: 183.27 | N16: 2949.136 | O16: 6842.4
A17: Octubre | C17: 226 | D17: 278 | E17: 3532.7445 | F17: 4600.7489 | G17: 98806.008 | I17: Septiembre | K17: 25 | L17: 20 | M17: 166.989 | N17: 2493.44 | O17: 7901.9
A18: Noviembre | C18: 226 | D18: 276 | E18: 3524.0098 | F18: 4552.7586 | G18: 95873.568 | I18: Octubre | K18: 25 | L18: 20 | M18: 179.796 | N18: 2946.698 | O18: 6728.2
A19: Diciembre | C19: 226 | D19: 276 | E19: 3587.7064 | F19: 4385.7898 | G19: 99781.801 | I19: Noviembre | K19: 25 | L19: 20 | M19: 170.646 | N19: 2819.245 | O19: 7813.2
A20: Nota: | B20: A partir del 29 de noviembre de 2015, se regularizó el servicio de la línea 12. | I20: Diciembre | K20: 25 | L20: 20 | M20: 166.331 | N20: 2363.339 | O20: 7569.8
A21: a | B21: Dato no acumulable. | I21: Nota: | J21: La información de pasajeros transportados e ingresos por pasaje se encuentra en proceso de verificación de ventas de tarjetas, total de pasajeros y recargas.
A22: b | B22: Cifra relativa al número de trenes en operación en día laborable y horario de máxima demanda. | J22: Del 5 de abril y hasta el 30 de junio los sistemas de transporte de pasajeros de Trolebús, Tren Ligero y la Red de Transporte de Pasajeros (RTP), realizarán el servicio de transporte de pasajeros de manera gratiuta, lo anterior como parte de las medidas que se han tomado para reducir los niveles de contaminación en la Ciudad.
A23: c | B23: Promedio diario de kilómetros recorridos | I23: a | J23: Dato no acumulable.
A24: d | B24: Promedio diario de pasajeros transportados. Incluye a los pasajeros con boleto pagado y usuarios de acceso gratuito (personas de la tercera edad, Discapacitados, menores de 5 años y derechohabientes del Sistema de Transporte Colectivo, principalmente). | I24: b | J24: El dato anual se refiere al promedio mensual.
A25: e | B25: Cifras estimadas para tracción, alumbrado y fuerza, por parte de la Coodinación de Control y Operaciones Eléctricas del SCT.
A26: Fecha de actualización: Miércoles, 20 de Junio de 2018 | I26: Fecha de actualización: Miércoles, 20 de Junio de 2018
A28: Guadalajara Tren eléctrico | I28: Monterrey Sistema de transporte colectivo (metro)
A30: Principales características de los sistemas de transportes eléctricos en la Ciudad de Guadalajara | I30: Principales características del sistema de transporte colectivo metrorrey
A32: Periodo | C32: Tren eléctrico | I32: Periodo | K32: Longitud en servicio | L32: Trenes en servicio a | M32: Kilómetros recorridos | N32: Pasajeros transportados | O32: Ingresos por pasaje | P32: Energia eléctrica consumida
C33: Longitud en servicio (km) a | D33: Unidades en operación b | E33: Kilómetros recorridos | F33: Pasajeros transportados | G33: Ingresos por pasaje | K33: (km) a | M33: (Miles de kilómetros) | N33: (Miles de pasajeros) | O33: (Miles de pesos) | P33: (Miles de KWH)b
E34: (Miles de kilómetros) | F34: (Miles de pasajeros) | G34: (Miles de pesos) | I34: 2016 | K34: =MAX(K35:K46) -> 32 | L34: =MAX(L35:L46) -> 40 | M34: =SUM(M35:M46)*1000 -> 10267964 | N34: =SUM(N35:N46)*1000 -> 1.8044475e+08 | O34: =SUM(O35:O46)*1000 -> 445470692 | P34: =SUM(P35:P46)*1000 -> 42463236
A35: 2016 | C35: =MAX(C36:C47) -> 48 | D35: =MAX(D36:D47) -> 44 | E35: =SUM(E36:E47)*1000 -> 5714391 | F35: =SUM(F36:F47)*1000 -> 98268017 | G35: =SUM(G36:G47)*1000 -> 4.7550966e+08 | I35: Enero | K35: 32 | L35: 40 | M35: 839.876 | N35: 13925.906 | O35: 34347.638 | P35: 3243.78
A36: Enero | C36: 48 | D36: 44 | E36: 476.492 | F36: 7758.313 | G36: 36978.737 | I36: Febrero | K36: 32 | L36: 40 | M36: 812.904 | N36: 14723.523 | O36: 36975.303 | P36: 3148.274
A37: Febrero | C37: 48 | D37: 44 | E37: 446.248 | F37: 7813.208 | G37: 37239.541 | I37: Marzo | K37: 32 | L37: 40 | M37: 851.225 | N37: 14536.004 | O37: 36382.83 | P37: 3366.218
A38: Marzo | C38: 48 | D38: 44 | E38: 461.545 | F38: 7709.211 | G38: 36746.7 | I38: Abril | K38: 32 | L38: 40 | M38: 841.871 | N38: 15387.757 | O38: 38383 | P38: 3360.004
A39: Abril | C39: 48 | D39: 44 | E39: 468.466 | F39: 8101.776 | G39: 38619.072 | I39: Mayo | K39: 32 | L39: 40 | M39: 886.94 | N39: 15360.752 | O39: 38366.664 | P39: 3618.439
A40: Mayo | C40: 48 | D40: 44 | E40: 474.792 | F40: 8256.762 | G40: 39357.823 | I40: Junio | K40: 32 | L40: 40 | M40: 853.567 | N40: 14295.487 | O40: 37369.377 | P40: 3740.571
A41: Junio | C41: 48 | D41: 44 | E41: 474.938 | F41: 7852.953 | G41: 37431.334 | I41: Julio | K41: 32 | L41: 40 | M41: 855.061 | N41: 14557.776 | O41: 33382.5 | P41: 3980.578
A42: Julio | C42: 48 | D42: 38 | E42: 478.672 | F42: 7831.065 | G42: 37326.471 | I42: Agosto | K42: 32 | L42: 40 | M42: 887.901 | N42: 16182.244 | O42: 40139.449 | P42: 3941.569
A43: Agosto | C43: 48 | D43: 38 | E43: 491.813 | F43: 8447.533 | G43: 40265.176 | I43: Septiembre | K43: 32 | L43: 40 | M43: 852.11 | N43: 15470.381 | O43: 37092.028 | P43: 3739.151
A44: Septiembre | C44: 48 | D44: 44 | E44: 471.819 | F44: 8315.585 | G44: 39636.254 | I44: Octubre | K44: 32 | L44: 40 | M44: 873.706 | N44: 15995.545 | O44: 39659.572 | P44: 3621.455
A45: Octubre | C45: 48 | D45: 38 | E45: 510.547 | F45: 8987.09 | G45: 42836.975 | I45: Noviembre | K45: 32 | L45: 40 | M45: 839.722 | N45: 15339.581 | O45: 36999.857 | P45: 3324.452
...

Sheet Ships
B2: Type of ship | C2: Fleet (2015)
B3: Freight ships (height) | C3: 11945
B4: Freight ships (cabotage) | C4: 7201
B6: Total>Buques>Cabotaje+Altura
B7: http://www.sct.gob.mx/fileadmin/CGPMM/U_DGP/estadisticas/2016/Anuario/Anuario_2016.html
B9: This is too high, estimated ships are 2% of this
C10: =SUM(C3:C4)*0.02 -> 382.92
A13: Instituto Nacional de Estadística y Geografía (INEGI)
A14: Banco de Información Económica (BIE)
A15: Fecha de consulta: 03/12/2024 23:47:36
A17: Periodos | B17: Comunicaciones y transportes > Secretaría de Comunicaciones y Transportes > Arribo de barcos y pasajeros por tipo de tráfico > Total > Arribos /p2 /l /f3 (Número de embarcaciones) Mensual | C17: Comunicaciones y transportes > Secretaría de Comunicaciones y Transportes > Arribo de barcos y pasajeros por tipo de tráfico > Total > Pasajeros /p2 /l /f3 (Número de pasajeros) Mensual | D17: Comunicaciones y transportes > Secretaría de Comunicaciones y Transportes > Arribo de barcos y pasajeros por tipo de tráfico > Internacional > Cruceros > Arribos /p2 /l /f3 (Número de embarcaciones) Mensual | E17: Comunicaciones y transportes > Secretaría de Comunicaciones y Transportes > Arribo de barcos y pasajeros por tipo de tráfico > Internacional > Cruceros > Pasajeros /p2 /l /f3 (Número de pasajeros) Mensual | F17: Comunicaciones y transportes > Secretaría de Comunicaciones y Transportes > Arribo de barcos y pasajeros por tipo de tráfico > Cabotaje > Total > Arribos /p2 /l /f3 (Número de embarcaciones) Mensual | G17: Comunicaciones y transportes > Secretaría de Comunicaciones y Transportes > Arribo de barcos y pasajeros por tipo de tráfico > Cabotaje > Total > Pasajeros /p2 /l /f3 (Número de pasajeros) Mensual | H17: Comunicaciones y transportes > Secretaría de Comunicaciones y Transportes > Arribo de barcos y pasajeros por tipo de tráfico > Cabotaje > Transbordadores > Arribos /p2 /l /f3 (Número de embarcaciones) Mensual | I17: Comunicaciones y transportes > Secretaría de Comunicaciones y Transportes > Arribo de barcos y pasajeros por tipo de tráfico > Cabotaje > Transbordadores > Pasajeros /p2 /l /f3 (Número de pasajeros) Mensual | J17: Comunicaciones y transportes > Secretaría de Comunicaciones y Transportes > Arribo de barcos y pasajeros por tipo de tráfico > Cabotaje > Movimiento costero > Arribos /p2 /l /f3 (Número de embarcaciones) Mensual | K17: Comunicaciones y transportes > Secretaría de Comunicaciones y Transportes > Arribo de barcos y pasajeros por tipo de tráfico > Cabotaje > Movimiento costero > Pasajeros /p2 /l /f3 (Número de pasajeros) Mensual | L17: Comunicaciones y transportes > Secretaría de Comunicaciones y Transportes > Movimiento portuario de carga por tipo de tráfico > Total nacional /p2 /f3 /m (Miles de toneladas) Mensual | M17: Comunicaciones y transportes > Secretaría de Comunicaciones y Transportes > Movimiento portuario de carga por tipo de tráfico > Altura > Total /p2 /f3 /m (Miles de toneladas) Mensual | N17: Comunicaciones y transportes > Secretaría de Comunicaciones y Transportes > Movimiento portuario de carga por tipo de tráfico > Altura > Importación /p2 /f3 /m (Miles de toneladas) Mensual | O17: Comunicaciones y transportes > Secretaría de Comunicaciones y Transportes > Movimiento portuario de carga por tipo de tráfico > Altura > Exportación /p2 /f3 /m (Miles de toneladas) Mensual | P17: Comunicaciones y transportes > Secretaría de Comunicaciones y Transportes > Movimiento portuario de carga por tipo de tráfico > Cabotaje > Total /p2 /f3 /m (Miles de toneladas) Mensual | Q17: Comunicaciones y transportes > Secretaría de Comunicaciones y Transportes > Movimiento portuario de carga por tipo de tráfico > Cabotaje > Entradas /p2 /f3 /m (Miles de toneladas) Mensual | R17: Comunicaciones y transportes > Secretaría de Comunicaciones y Transportes > Movimiento portuario de carga por tipo de tráfico > Cabotaje > Salidas /p2 /f3 /m (Miles de toneladas) Mensual
A18: 2000/01 | B18: 5033 | C18: 677455 | D18: 269 | E18: 321252 | F18: 4764 | G18: 356203 | H18: 664 | I18: 51716 | J18: 4100 | K18: 304487 | L18: 19298 | M18: 13867 | N18: 3882 | O18: 9985 | P18: 5431 | Q18: 2913 | R18: 2518
A19: 2000/02 | B19: 4659 | C19: 665512 | D19: 264 | E19: 328833 | F19: 4395 | G19: 336679 | H19: 612 | I19: 39822 | J19: 3783 | K19: 296857 | L19: 18435 | M19: 13539 | N19: 3685 | O19: 9854 | P19: 4896 | Q19: 2484 | R19: 2412
A20: 2000/03 | B20: 4817 | C20: 729314 | D20: 279 | E20: 353053 | F20: 4538 | G20: 376261 | H20: 691 | I20: 46284 | J20: 3847 | K20: 329977 | L20: 20461 | M20: 14707 | N20: 4322 | O20: 10385 | P20: 5754 | Q20: 2829 | R20: 2925
A21: 2000/04 | B21: 5216 | C21: 702251 | D21: 239 | E21: 292185 | F21: 4977 | G21: 410066 | H21: 684 | I21: 73197 | J21: 4293 | K21: 336869 | L21: 19998 | M21: 14480 | N21: 3929 | O21: 10551 | P21: 5518 | Q21: 2750 | R21: 2768
A22: 2000/05 | B22: 4965 | C22: 577154 | D22: 209 | E22: 241757 | F22: 4756 | G22: 335397 | H22: 657 | I22: 47571 | J22: 4099 | K22: 287826 | L22: 20658 | M22: 14962 | N22: 4395 | O22: 10567 | P22: 5696 | Q22: 2873 | R22: 2823
A23: 2000/06 | B23: 4706 | C23: 462513 | D23: 141 | E23: 184791 | F23: 4565 | G23: 277722 | H23: 655 | I23: 43992 | J23: 3910 | K23: 233730 | L23: 21193 | M23: 15313 | N23: 4293 | O23: 11020 | P23: 5880 | Q23: 3011 | R23: 2869
A24: 2000/07 | B24: 5248 | C24: 669312 | D24: 140 | E24: 193693 | F24: 5108 | G24: 475619 | H24: 703 | I24: 80980 | J24: 4405 | K24: 394639 | L24: 20790 | M24: 14553 | N24: 4194 | O24: 10359 | P24: 6237 | Q24: 3215 | R24: 3022
A25: 2000/08 | B25: 5177 | C25: 647573 | D25: 164 | E25: 211714 | F25: 5013 | G25: 435859 | H25: 703 | I25: 68622 | J25: 4310 | K25: 367237 | L25: 21826 | M25: 15851 | N25: 4765 | O25: 11086 | P25: 5975 | Q25: 3041 | R25: 2934
A26: 2000/09 | B26: 4689 | C26: 461899 | D26: 138 | E26: 189982 | F26: 4551 | G26: 271917 | H26: 673 | I26: 33980 | J26: 3878 | K26: 237937 | L26: 19960 | M26: 14480 | N26: 4484 | O26: 9996 | P26: 5480 | Q26: 2736 | R26: 2744
A27: 2000/10 | B27: 5134 | C27: 537305 | D27: 187 | E27: 274947 | F27: 4947 | G27: 262358 | H27: 763 | I27: 34087 | J27: 4184 | K27: 228271 | L27: 21488 | M27: 16040 | N27: 5041 | O27: 10999 | P27: 5448 | Q27: 2947 | R27: 2501
A28: 2000/11 | B28: 4703 | C28: 595288 | D28: 221 | E28: 300584 | F28: 4482 | G28: 294704 | H28: 744 | I28: 37047 | J28: 3738 | K28: 257657 | L28: 19094 | M28: 13682 | N28: 4552 | O28: 9130 | P28: 5412 | Q28: 2746 | R28: 2666
A29: 2000/12 | B29: 4815 | C29: 674441 | D29: 220 | E29: 296574 | F29: 4595 | G29: 377867 | H29: 708 | I29: 54892 | J29: 3887 | K29: 322975 | L29: 21052 | M29: 15221 | N29: 4272 | O29: 10949 | P29: 5831 | Q29: 2990 | R29: 2841
... A314: 2024/09 | B314: 5414 | C314: 1122979 | D314: 133 | E314: 491823 | F314: 5281 | G314: 631156 | H314: 691 | I314: 47780 | J314: 4590 | K314: 583376 | L314: 21087.043 | M314: 17216.872 | N314: 10055.946 | O314: 7160.926 | P314: 3870.171 | Q314: 1744.632 | R314: 2125.539
A315: 2024/10
A317: Notas:
A318: /a La Estadística Mensual de Vehículos de Motor Registrados en Circulación se actualiza a partir del padrón vehicular registrado por los gobiernos de las 32 entidades federativas, al 31 de diciembre del año inmediato anterior. Posteriormente, en los meses del año en curso se realiza una estimación del parque vehicular mensual en circulación, incorporando las ventas de vehículos al público reportadas en el Registro Administrativo de la Industria Automotriz de Vehículos Ligeros (RAIAVL) y el Registro Administrativo de la Industria Automotriz de Vehículos Pesados (RAIAVP). En este sentido, los datos publicados mensualmente se actualizan hasta la publicación de cifras anuales de Vehículos de Motor Registrados en Circulación. Asimismo, la Estadística Mensual de Vehículos de Motor Registrados en Circulación excluye los datos de Motocicletas y del servicio Oficial.
A319: /b Nota al usuario: Se refiere a la producción nacional de vehículos destinados al mercado interno y de exportación. A partir de enero de 2015, los datos se actualizan conforme a lo reportado mensualmente en el Registro Administrativo de la Industria Automotriz de Vehículos Ligeros (RAIAVL) y, hasta 2020, se complementó la información con los resultados de la Encuesta Mensual de la Industria Manufacturera (EMIM). Posteriormente, en junio del 2020 se incluyeron los resultados mensuales del Registro Administrativo de la Industria Automotriz de Vehículos Pesados (RAIAVP), con cifras a partir de enero de 2018 para la producción de Camiones, Tractocamiones y Autobuses integrales.
A320: /c Los datos se actualizan conforme el último resultado mensual de ventas de automóviles, publicado en el Registro Administrativo de la Industria Automotriz de Vehículos Ligeros (RAIAVL).
A321: /d Los vehículos Importados incluyen las categorías de Subcompactos, Compactos, De Lujo y Deportivos.
A322: /e El Total se actualiza con base en los resultados mensuales de los camiones de Uso Múltiple (SUV y Minivan) y camiones Pick Up reportados en el Registro Administrativo de la Industria Automotriz de Vehículos Ligeros (RAIAVL). Así como, con las clases Carga Resto, Carga Tractocamiones, Pasajeros Autobuses - Resto y, Pasajeros Autobuses - Foráneos reportadas en el Registro Administrativo de la Industria Automotriz de Vehículos Pesados (RAIAVP).
A323: /f Son las unidades que parten de una plataforma de camión ligero y por sus características pueden ser usadas para el transporte de pasajeros o carga (SUV, Minivan).
A324: /g Se refiere a los vehículos ligeros de carga PICK UP con Peso Bruto Vehicular de hasta 2,721 Kgs.
A325: /h Se refiere a los vehículos ligeros de carga PICK UP con Peso Bruto Vehicular de 2,722 a 4,536 Kgs.
A326: /i Se refiere a los vehículos ligeros de carga PICK UP con Peso Bruto Vehicular de 4,537 a 6,350 Kgs.
A327: /j Se refiere a los vehículos pesados de carga clasificados en el Registro Administrativo de Vehículos Pesados como Carga-Resto, con un Peso Bruto Vehicular de 6,351 KGS en adelante.
... A337: /f3 SICT. Secretaría de Comunicaciones y Transportes (SCT); SEMAR. Coordinación General de Puertos y Marina Mercante (CGPYMM).

Sheet SYVbT-passenger
A1: Number of Vehicles | B1: battery electric vehicle | C1: natural gas vehicle | D1: gasoline vehicle | E1: diesel vehicle | F1: plugin hybrid vehicle | G1: LPG vehicle | H1: hydrogen vehicle
A2: LDVs | B2: =RoadTransport!B62 -> 7478.7771 | C2: =RoadTransport!C62 -> 10008.121 | D2: =RoadTransport!D62 -> 33136386 | E2: =RoadTransport!E62 -> 614964.81 | F2: =RoadTransport!F62 -> 22436.331 | G2: =RoadTransport!G62 -> 140725.84 | H2: =RoadTransport!H62 -> 0
A3: HDVs | B3: =RoadTransport!B63 -> 53.558377 | C3: =RoadTransport!C63 -> 71.671976 | D3: =RoadTransport!D63 -> 237302.31 | E3: =RoadTransport!E63 -> 4403.9977 | F3: =RoadTransport!F63 -> 160.67513 | G3: =RoadTransport!G63 -> 1007.7914 | H3: =RoadTransport!H63 -> 0
A4: aircraft | B4: 0 | C4: 0 | D4: 0 | E4: =AirFleet!AJ2 -> 358 | F4: 0 | G4: 0 | H4: 0
A5: rail | B5: ='Rail Pssgr'!D59 -> 384 | C5: 0 | D5: 0 | E5: 0 | F5: 0 | G5: 0 | H5: 0
A6: ships | B6: 0 | C6: 0 | D6: 0 | E6: 0 | F6: 0 | G6: 0 | H6: 0
A7: motorbikes | B7: =RoadTransport!B67 -> 29198.158 | C7: =RoadTransport!C67 -> 0 | D7: =RoadTransport!D67 -> 5810433.5 | E7: =RoadTransport!E67 -> 0 | F7: =RoadTransport!F67 -> 0 | G7: =RoadTransport!G67 -> 0 | H7: =RoadTransport!H67 -> 0

Sheet SYVbT-freight
A1: Number of Vehicles | B1: battery electric vehicle | C1: natural gas vehicle | D1: gasoline vehicle | E1: diesel vehicle | F1: plugin hybrid vehicle | G1: LPG vehicle | H1: hydrogen vehicle
A2: LDVs | B2: =RoadTransport!B71 -> 1577.2171 | C2: =RoadTransport!C71 -> 527.65912 | D2: =RoadTransport!D71 -> 26255.622 | E2: =RoadTransport!E71 -> 1753220 | F2: =RoadTransport!F71 -> 0 | G2: =RoadTransport!G71 -> 7419.5016 | H2: =RoadTransport!H71 -> 0
A3: HDVs | B3: =RoadTransport!B72 -> 547.48563 | C3: =RoadTransport!C72 -> 183.16172 | D3: =RoadTransport!D72 -> 9113.8856 | E3: =RoadTransport!E72 -> 608580 | F3: =RoadTransport!F72 -> 0 | G3: =RoadTransport!G72 -> 2575.467 | H3: =RoadTransport!H72 -> 0
A4: aircraft | B4: 0 | C4: 0 | D4: 0 | E4: =AirFleet!AJ3 -> 82 | F4: 0 | G4: 0 | H4: 0
A5: rail | B5: 0 | C5: 0 | D5: 0 | E5: =Rail!I39 -> 1998 | F5: 0 | G5: 0 | H5: 0
A6: ships | B6: 0 | C6: 0 | D6: 0 | E6: =Ships!C10 -> 382.92 | F6: 0 | G6: 0 | H6: 0
A7: motorbikes | B7: 0 | C7: 0 | D7: 0 | E7: 0 | F7: 0 | G7: 0 | H7: 0
