Workbook
Name a: [1]ISICrev3.1!$E:$F
Name Calculated_Relationship_HS12___HS07: '[2]Correlation HS2012-HS2007'!#REF!
Name CAP_CT: #REF!
Name CAP_CT: #REF!
Name CAP_CT: #REF!
Name CAP_CT: #REF!
Name CAP_GFCF: #REF!
Name CAP_GFCF: #REF!
Name CAP_GFCF: #REF!
Name CAP_GFCF: #REF!
Name CAP_IT: #REF!
Name CAP_IT: #REF!
Name CAP_IT: #REF!
Name CAP_IT: #REF!
Name CAP_OCon: #REF!
Name CAP_OCon: #REF!
Name CAP_OCon: #REF!
Name CAP_OCon: #REF!
Name CAP_OMach: #REF!
Name CAP_OMach: #REF!
Name CAP_OMach: #REF!
Name CAP_OMach: #REF!
Name CAP_Other: #REF!
Name CAP_Other: #REF!
Name CAP_Other: #REF!
Name CAP_Other: #REF!
Name CAP_QI: #REF!
Name CAP_QI: #REF!
Name CAP_QI: #REF!
Name CAP_QI: #REF!
Name CAP_RStruc: #REF!
Name CAP_RStruc: #REF!
Name CAP_RStruc: #REF!
Name CAP_RStruc: #REF!
Name CAP_Soft: #REF!
Name CAP_Soft: #REF!
Name CAP_Soft: #REF!
Name CAP_Soft: #REF!
Name CAP_TraEq: #REF!
Name CAP_TraEq: #REF!
Name CAP_TraEq: #REF!
Name CAP_TraEq: #REF!
Name CAPIT: #REF!
Name CAPIT: #REF!
Name CAPIT: #REF!
Name CAPIT: #REF!
Name CAPIT_QI: #REF!
Name CAPIT_QI: #REF!
Name CAPIT_QI: #REF!
Name CAPIT_QI: #REF!
Name capit_qph: #REF!
Name capit_qph: #REF!
Name capit_qph: #REF!
Name capit_qph: #REF!
Name CAPNIT: #REF!
Name CAPNIT: #REF!
Name CAPNIT: #REF!
Name CAPNIT: #REF!
Name CAPNIT_QI: #REF!
Name CAPNIT_QI: #REF!

Sheet About
A1: FoGPbEaIC Fraction of Goods Purchased by Entity and ISIC Code
A3: Source: | B3: All Industries
B4: see variable io-model/DLIM
B5: see variable io-model/BOibC
B6: see variable io-model/GAaHEbIC-government
B7: see variable io-model/GaHEbIC-household
B9: Split for Chemicals/Pharmaceuticals
B10: World Input-Output Database
B11: 2016
B12: National IO Tables
B13: http://www.wiod.org/database/niots16
B14: Mexico NIOT, 2014
B16: Split for All Other ISIC Codes
B17: Exiobase
B18: 2019
B19: Exiobase 3rx, 2016
B20: https://zenodo.org/record/2654460#.YEFjHmhKg2w
B21: MEX, exports
A23: Notes
A25: Data Source
A26: The OECD input-output tables use ISIC codes that do not map well onto EPS industry categories.
A27: The following industry categories are particularly problematic for mapping onto OECD:
B28: chemicals (OECD doesn't split out pharmaceuticals)
B29: natural gas and petroleum systems
B30: coal mining
B31: waste management (water + waste)
A33: Also, even the industries that are mappable to OECD (such as iron and steel) can be improved by
A34: using a more disaggregated data source that (for example) breaks out iron and steel from other metals.
A36: Accordingly, we use the variables DLIM and BOIbC to break out the OECD data in several places. See the file io-model/DLIM
A37: for more information on the steps to transform a DLIM table into a standard input-output matrix. Ideally, we would use
A38: a Total Leontief Inverse matrix rather than a Domestic Leontief Inverse matrix for this step, but our source data does not provide
A39: that information.
A41: Procedure
A42: We calculate the share of each industry's output purchased by each ISIC code, disregarding
A43: the cash flow entities that are not assigned ISIC codes, such that the shares assigned to all
A44: ISIC codes sum to 100%. Note that this requires dividing by the total output from each industry
A45: to all ISIC codes in the denominator ourselves, since using the "Total Intermediate" column (col OS)
A46: from the BEA table introduces too much rounding error, and this is visible in EPS outputs.
... A66: the five energy supplier entities, does not introduce error.

Sheet ISIC Crosswalk
I1: OECD Version | J1: OECD ISIC
A2: ISIC 05 | B2: 05 | C2: Mining of coal and lignite | I2: 2021 | J2: CONS_ABR: Direct purchases abroad by residents (imports)
B3: 051 | C3: Mining of hard coal | I3: 2021 | J3: CONS_NONRES: Direct purchases by non-residents (exports)
B4: 052 | C4: Mining of lignite | I4: 2021 | J4: D01T02: Agriculture, hunting, forestry
A5: ISIC 06 | B5: 06 | C5: Extraction of crude petroleum & natural gas | I5: 2018 | J5: D01T03: Agriculture, forestry and fishing | K5: ISIC 01T03
B6: 061 | C6: Extraction of crude petroleum | I6: 2021 | J6: D03: Fishing and aquaculture
B7: 062 | C7: Extraction of natural gas | I7: 2018 | J7: D05T06: Mining and extraction of energy producing products
A8: ISIC 07T08 | B8: 07 | C8: Mining of metal ores | I8: 2021 | J8: D05T06: Mining and quarrying, energy producing products
B9: 071 | C9: Mining of iron ores | I9: 2018 | J9: D07T08: Mining and quarrying of non-energy producing products
B10: 072 | C10: Mining of non-ferrous metal ores | I10: 2021 | J10: D07T08: Mining and quarrying, non-energy producing products | K10: ISIC 07T08
A11: ISIC 07T08 | B11: 08 | C11: Other mining and quarrying | I11: 2021 | J11: D09: Mining support service activities | K11: ISIC 09
B12: 081 | C12: Quarrying of stone, sand and clay | I12: 2021 | J12: D10T12: Food products, beverages and tobacco | K12: ISIC 10T12
B13: 089 | C13: Mining and quarrying n.e.c. | I13: 2021 | J13: D13T15: Textiles, textile products, leather and footwear | K13: ISIC 13T15
A14: ISIC 09 | B14: 09 | C14: Mining support service activities | I14: 2018 | J14: D13T15: Textiles, wearing apparel, leather and related products
B15: 091 | C15: Support activities for petroleum | I15: 2021 | J15: D16: Wood and products of wood and cork | K15: ISIC 16
B16: 099 | C16: Support activities for other mining, quarrying | I16: 2021 | J16: D17T18: Paper products and printing | K16: ISIC 17T18
B17: 0B | C17: Mining and quarrying | I17: 2021 | J17: D19: Coke and refined petroleum products | K17: ISIC 19
B18: 35 | C18: Electricity, gas, steam & air conditioning | I18: 2021 | J18: D20: Chemical and chemical products | K18: ISIC 20
A19: ISIC 351 | B19: 351 | C19: Electric power generation, transmission | I19: 2018 | J19: D20T21: Chemicals and pharmaceutical products
A20: ISIC 352T353 | B20: 352 | C20: Manufacture of gas | I20: 2021 | J20: D21: Pharmaceuticals, medicinal chemical and botanical products | K20: ISIC 21
A21: ISIC 352T353 | B21: 353 | C21: Steam and air conditioning supply | I21: 2018 | J21: D22: Rubber and plastic products | K21: ISIC 22
B22: 35D | C22: Electricity, gas, steam & air conditioning | I22: 2021 | J22: D22: Rubber and plastics products
A23: ISIC 36T39 | B23: 36 | C23: Water collection, treatment and supply | I23: 2021 | J23: D23: Other non-metallic mineral products
B24: 360 | C24: Water collection, treatment and supply | I24: 2021 | J24: D24: Basic metals
A25: ISIC 36T39 | B25: 37 | C25: Sewerage | I25: 2021 | J25: D25: Fabricated metal products | K25: ISIC 25
B26: 370 | C26: Sewerage | I26: 2021 | J26: D26: Computer, electronic and optical equipment | K26: ISIC 26
A27: ISIC 36T39 | B27: 38 | C27: Waste collection,treatment,disposal activities | I27: 2018 | J27: D26: Computer, electronic and optical products
B28: 381 | C28: Waste collection | I28: 2021 | J28: D27: Electrical equipment | K28: ISIC 27
B29: 382 | C29: Waste treatment and disposal | I29: 2021 | J29: D28: Machinery and equipment, nec | K29: ISIC 28
B30: 383 | C30: Materials recovery | I30: 2021 | J30: D29: Motor vehicles, trailers and semi-trailers | K30: ISIC 29
A31: ISIC 36T39 | B31: 39 | C31: Remediation activities | I31: 2021 | J31: D30: Other transport equipment | K31: ISIC 30
B32: 390 | C32: Remediation activities | I32: 2021 | J32: D31T33: Manufacturing nec; repair and installation of machinery and equipment | K32: ISIC 31T33
A33: ISIC 36T39 | B33: 39E | C33: Water supply;sewerage,waste management | I33: 2018 | J33: D31T33: Other manufacturing; repair and installation of machinery and equipment
A34: ISIC 10T12 | B34: 1010 | C34: Processing/preserving of meat | I34: 2021 | J34: D35: Electricity, gas, steam and air conditioning supply
A35: ISIC 10T12 | B35: 1020 | C35: Processing/preserving of fish, etc. | I35: 2018 | J35: D35T39: Electricity, gas, water supply, sewerage, waste and remediation services
A36: ISIC 10T12 | B36: 1030 | C36: Processing/preserving of fruit,vegetables | I36: 2021 | J36: D36T39: Water supply; sewerage, waste management and remediation activities | K36: ISIC 36T39
A37: ISIC 10T12 | B37: 1040 | C37: Vegetable and animal oils and fats | I37: 2021 | J37: D41T43: Construction | K37: ISIC 41T43
A38: ISIC 10T12 | B38: 1050 | C38: Dairy products | I38: 2021 | J38: D45T47: Wholesale and retail trade; repair of motor vehicles | K38: ISIC 45T47
A39: ISIC 10T12 | B39: 106 | C39: Grain mill products,starches and starch products | I39: 2021 | J39: D49: Land transport and transport via pipelines
B40: 1061 | C40: Grain mill products | I40: 2018 | J40: D49T53: Transportation and storage | K40: ISIC 49T53
...

Sheet Pre ISIC Split DLIM
B1: ISIC 01T03 | C1: ISIC 05 | D1: ISIC 06 | E1: ISIC 07T08 | F1: ISIC 09 | G1: ISIC 10T12 | H1: ISIC 13T15 | I1: ISIC 16 | J1: ISIC 17T18 | K1: ISIC 19 | L1: ISIC 20 | M1: ISIC 21 | N1: ISIC 22 | O1: ISIC 231 | P1: ISIC 239 | Q1: ISIC 241 | R1: ISIC 242 | S1: ISIC 25 | T1: ISIC 26 | U1: ISIC 27 | V1: ISIC 28 | W1: ISIC 29 | X1: ISIC 30 | Y1: ISIC 31T33 | Z1: ISIC 351 | AA1: ISIC 352T353 | AB1: ISIC 36T39 | AC1: ISIC 41T43 | AD1: ISIC 45T47 | AE1: ISIC 49T53 | AF1: ISIC 55T56 | AG1: ISIC 58T60 | AH1: ISIC 61 | AI1: ISIC 62T63 | AJ1: ISIC 64T66 | AK1: ISIC 68 | AL1: ISIC 69T82 | AM1: ISIC 84 | AN1: ISIC 85 | AO1: ISIC 86T88 | AP1: ISIC 90T96 | AQ1: ISIC 97T98
A2: ISIC 01T03 | B2: 1.093 | C2: 8.3969505e-05 | D2: 2.6080841e-06 | E2: 0.003 | F2: 0.002 | G2: 0.233 | H2: 0.026 | I2: 0.132 | J2: 0.03 | K2: 0.003 | L2: 0.0060866294 | M2: 0.0064984597 | N2: 0.011 | O2: 0.00015007949 | P2: 4.4392202e-05 | Q2: 0.00017323838 | R2: 4.6852676e-05 | S2: 0.002 | T2: 0.001 | U2: 0.002 | V2: 0.002 | W2: 0.002 | X2: 0.002 | Y2: 0.015 | Z2: 0.00014546665 | AA2: 0.00013813121 | AB2: 0.00011991853 | AC2: 0.004 | AD2: 0.004 | AE2: 0.002 | AF2: 0.046 | AG2: 0.005 | AH2: 0.001 | AI2: 0.002 | AJ2: 0.002 | AK2: 0.001 | AL2: 0.003 | AM2: 0.008 | AN2: 0.003 | AO2: 0.007 | AP2: 0.006 | AQ2: 0
A3: ISIC 05 | B3: 0.00013876065 | C3: 1.0001866 | D3: 9.9524146e-06 | E3: 9.274934e-07 | F3: 0 | G3: 8.356304e-05 | H3: 2.6823783e-05 | I3: 2.0067892e-05 | J3: 9.6552656e-05 | K3: 4.4514085e-05 | L3: 0.16235409 | M3: 0.017733337 | N3: 0.0019951756 | O3: 3.9354235e-05 | P3: 2.681869e-07 | Q3: 0.00026688022 | R3: 2.6281428e-05 | S3: 0.0001372281 | T3: 0.00014480334 | U3: 8.2811004e-05 | V3: 8.9411695e-05 | W3: 7.2987642e-05 | X3: 3.2362951e-05 | Y3: 0.0023669661 | Z3: 0.0016261951 | AA3: 5.4910283e-05 | AB3: 2.7983939e-05 | AC3: 7.8745665e-06 | AD3: 4.9253684e-07 | AE3: 9.489812e-08 | AF3: 2.110407e-06 | AG3: 0 | AH3: 3.2483714e-06 | AI3: 2.2372152e-06 | AJ3: 2.2660878e-05 | AK3: 2.295248e-05 | AL3: 8.262152e-06 | AM3: 0.00016150026 | AN3: 8.2770245e-05 | AO3: 5.6143825e-05 | AP3: 3.9919059e-05 | AQ3: 0.00014562739
A4: ISIC 06 | B4: 9.7181737e-05 | C4: 8.6218445e-07 | D4: 1.0000043 | E4: 4.7772262e-06 | F4: 0 | G4: 0.00010328004 | H4: 0.00013743446 | I4: 0.00016208523 | J4: 0.00012270031 | K4: 0.57343054 | L4: 0.16235409 | M4: 0.017733337 | N4: 0.0020914809 | O4: 1.3941107e-05 | P4: 3.2291581e-07 | Q4: 4.7753979e-05 | R4: 2.4145145e-05 | S4: 0.00018970189 | T4: 0.0001798993 | U4: 7.4577449e-05 | V4: 0.0001581329 | W4: 0.00012252767 | X4: 2.8041447e-05 | Y4: 0.00045073823 | Z4: 0.0024276532 | AA4: 2.8745616e-06 | AB4: 3.1688793e-05 | AC4: 3.8214303e-06 | AD4: 3.3766234e-07 | AE4: 1.9226182e-08 | AF4: 3.9450503e-07 | AG4: 0 | AH4: 4.7460969e-07 | AI4: 3.4867421e-07 | AJ4: 0.00031605219 | AK4: 0.0025064542 | AL4: 2.2830113e-06 | AM4: 0.0077373031 | AN4: 0.00053065108 | AO4: 5.4136947e-05 | AP4: 0.00012200624 | AQ4: 7.8228207e-09
A5: ISIC 07T08 | B5: 0.003 | C5: 0.0025483117 | D5: 6.083748e-05 | E5: 1.016 | F5: 0.005 | G5: 0.005 | H5: 0.002 | I5: 0.002 | J5: 0.003 | K5: 0.001 | L5: 0.02 | M5: 0.003 | N5: 0.006 | O5: 0.0021423114 | P5: 0.16026496 | Q5: 0.0029841508 | R5: 0.33477604 | S5: 0.035 | T5: 0.003 | U5: 0.02 | V5: 0.017 | W5: 0.013 | X5: 0.012 | Y5: 0.007 | Z5: 0.00048920078 | AA5: 0.00097120228 | AB5: 0.004 | AC5: 0.023 | AD5: 0.001 | AE5: 0.004 | AF5: 0.002 | AG5: 0.001 | AH5: 0 | AI5: 0.002 | AJ5: 0 | AK5: 0 | AL5: 0.001 | AM5: 0.001 | AN5: 0 | AO5: 0.001 | AP5: 0.002 | AQ5: 0
A6: ISIC 09 | B6: 0.017 | C6: 0 | D6: 0 | E6: 0.003 | F6: 1.018 | G6: 0 | H6: 0 | I6: 0 | J6: 0 | K6: 0.007 | L6: 0.003 | M6: 0.002 | N6: 0.007 | O6: 0 | P6: 0 | Q6: 0 | R6: 0 | S6: 0 | T6: 0 | U6: 0 | V6: 0 | W6: 0 | X6: 0 | Y6: 0 | Z6: 0 | AA6: 0 | AB6: 0 | AC6: 0 | AD6: 0 | AE6: 0.006 | AF6: 0 | AG6: 0.001 | AH6: 0 | AI6: 0.001 | AJ6: 0 | AK6: 0 | AL6: 0.001 | AM6: 0 | AN6: 0 | AO6: 0 | AP6: 0.001 | AQ6: 0
A7: ISIC 10T12 | B7: 0.062 | C7: 7.6404479e-05 | D7: 2.5099902e-06 | E7: 0.001 | F7: 0.001 | G7: 1.084 | H7: 0.014 | I7: 0.014 | J7: 0.007 | K7: 0.001 | L7: 0.005 | M7: 0.01 | N7: 0.006 | O7: 0.00022668919 | P7: 3.516024e-05 | Q7: 0.00019165883 | R7: 4.8621767e-05 | S7: 0.002 | T7: 0.001 | U7: 0.001 | V7: 0.001 | W7: 0.001 | X7: 0.001 | Y7: 0.002 | Z7: 0.00016695917 | AA7: 0.00020572359 | AB7: 0.001 | AC7: 0.001 | AD7: 0.001 | AE7: 0.002 | AF7: 0.063 | AG7: 0.002 | AH7: 0.001 | AI7: 0.002 | AJ7: 0.001 | AK7: 0 | AL7: 0.002 | AM7: 0.009 | AN7: 0.002 | AO7: 0.004 | AP7: 0.009 | AQ7: 0
A8: ISIC 13T15 | B8: 0.002 | C8: 8.9127488e-05 | D8: 2.7077664e-06 | E8: 0.005 | F8: 0.01 | G8: 0.002 | H8: 0.007 | I8: 0.004 | J8: 0.005 | K8: 0.001 | L8: 0.002 | M8: 0.002 | N8: 0.009 | O8: 0.00039265603 | P8: 7.5778652e-05 | Q8: 0.00029333523 | R8: 0.00011363244 | S8: 0.005 | T8: 0.006 | U8: 0.005 | V8: 0.004 | W8: 0.004 | X8: 0.004 | Y8: 1.013 | Z8: 0.00082703972 | AA8: 0.00016655856 | AB8: 0.002 | AC8: 0.003 | AD8: 0.001 | AE8: 0.002 | AF8: 0.002 | AG8: 0.006 | AH8: 0.002 | AI8: 0.002 | AJ8: 0.002 | AK8: 0 | AL8: 0.002 | AM8: 0.003 | AN8: 0.002 | AO8: 0.007 | AP8: 0.005 | AQ8: 0
A9: ISIC 16 | B9: 0.001 | C9: 0.00084144085 | D9: 1.1794331e-06 | E9: 0.005 | F9: 0.01 | G9: 0.002 | H9: 0.007 | I9: 0.004 | J9: 0.005 | K9: 0.001 | L9: 0.002 | M9: 0.002 | N9: 0.002 | O9: 0.0043697259 | P9: 0.001016003 | Q9: 0.0010514986 | R9: 0.00040414828 | S9: 0.005 | T9: 0.006 | U9: 0.005 | V9: 0.004 | W9: 0.004 | X9: 0.004 | Y9: 1.013 | Z9: 0.0001101571 | AA9: 0.00023239194 | AB9: 0.002 | AC9: 0.003 | AD9: 0.001 | AE9: 0.001 | AF9: 0.002 | AG9: 0.006 | AH9: 0.002 | AI9: 0.002 | AJ9: 0.002 | AK9: 0 | AL9: 0.001 | AM9: 0.003 | AN9: 0.002 | AO9: 0.007 | AP9: 0.002 | AQ9: 0
A10: ISIC 17T18 | B10: 0.003 | C10: 7.0831409e-05 | D10: 1.0593472e-05 | E10: 0.002 | F10: 0.016 | G10: 0.01 | H10: 0.016 | I10: 0.011 | J10: 1.19 | K10: 0.002 | L10: 0.006 | M10: 0.012 | N10: 0.012 | O10: 0.0071278247 | P10: 3.7463566e-05 | Q10: 0.00033613438 | R10: 0.00010902981 | S10: 0.01 | T10: 0.007 | U10: 0.008 | V10: 0.005 | W10: 0.005 | X10: 0.003 | Y10: 0.021 | Z10: 0.00057549979 | AA10: 0.0015836685 | AB10: 0.004 | AC10: 0.002 | AD10: 0.007 | AE10: 0.004 | AF10: 0.01 | AG10: 0.004 | AH10: 0.002 | AI10: 0.008 | AJ10: 0.009 | AK10: 0.003 | AL10: 0.008 | AM10: 0.012 | AN10: 0.007 | AO10: 0.006 | AP10: 0.011 | AQ10: 0
A11: ISIC 19 | B11: 0.027 | C11: 5.3489112e-08 | D11: 5.1685294e-09 | E11: 0.035 | F11: 0.06 | G11: 0.016 | H11: 0.012 | I11: 0.027 | J11: 0.018 | K11: 1.155 | L11: 0.045 | M11: 0.014 | N11: 0.021 | O11: 2.1211268e-06 | P11: 1.5000553e-08 | Q11: 2.3819679e-05 | R11: 6.3670694e-06 | S11: 0.02 | T11: 0.006 | U11: 0.013 | V11: 0.01 | W11: 0.009 | X11: 0.01 | Y11: 0.014 | Z11: 0.00052951316 | AA11: 3.3758267e-07 | AB11: 0.026 | AC11: 0.015 | AD11: 0.008 | AE11: 0.11 | AF11: 0.008 | AG11: 0.009 | AH11: 0.003 | AI11: 0.006 | AJ11: 0.004 | AK11: 0.002 | AL11: 0.008 | AM11: 0.017 | AN11: 0.004 | AO11: 0.01 | AP11: 0.012 | AQ11: 0
A12: ISIC 20 | B12: 0.040781031 | C12: 0.024202007 | D12: 0.024202007 | E12: 0.017 | F12: 0.01 | G12: 0.02 | H12: 0.028 | I12: 0.022 | J12: 0.041 | K12: 0.032 | L12: 1.118 | M12: 0.076 | N12: 0.23670861 | O12: 0.048965334 | P12: 0.048965334 | Q12: 0.023497274 | R12: 0.023497274 | S12: 0.015 | T12: 0.007 | U12: 0.02 | V12: 0.009 | W12: 0.015 | X12: 0.005 | Y12: 0.027 | Z12: 0.092141332 | AA12: 0.069288717 | AB12: 0.015 | AC12: 0.006 | AD12: 0.003 | AE12: 0.017465322 | AF12: 0.011 | AG12: 0.011 | AH12: 0.002 | AI12: 0.004 | AJ12: 0.002 | AK12: 0.002 | AL12: 0.0073353336 | AM12: 0.007 | AN12: 0.003 | AO12: 0.017 | AP12: 0 | AQ12: 0
A13: ISIC 21 | B13: 0.00076978746 | C13: 1.4632139e-05 | D13: 1.4632139e-05 | E13: 0 | F13: 0 | G13: 0.001 | H13: 0 | I13: 0.001 | J13: 0 | K13: 0 | L13: 0.001 | M13: 1.083 | N13: 0.00017271509 | O13: 6.8304542e-05 | P13: 6.8304542e-05 | Q13: 3.2743993e-05 | R13: 3.2743993e-05 | S13: 0 | T13: 0 | U13: 0 | V13: 0 | W13: 0 | X13: 0 | Y13: 0.004 | Z13: 4.7870518e-05 | AA13: 4.0663545e-05 | AB13: 0 | AC13: 0 | AD13: 0 | AE13: 4.8955228e-05 | AF13: 0 | AG13: 0 | AH13: 0 | AI13: 0 | AJ13: 0 | AK13: 0 | AL13: 0.0050553872 | AM13: 0.002 | AN13: 0 | AO13: 0.046 | AP13: 0 | AQ13: 0
... A43: ISIC 97T98 | B43: 0 | C43: 0 | D43: 0 | E43: 0 | F43: 0 | G43: 0 | H43: 0 | I43: 0 | J43: 0 | K43: 0 | L43: 0 | M43: 0 | N43: 0 | O43: 0 | P43: 0 | Q43: 0 | R43: 0 | S43: 0 | T43: 0 | U43: 0 | V43: 0 | W43: 0 | X43: 0 | Y43: 0 | Z43: 0 | AA43: 0 | AB43: 0 | AC43: 0 | AD43: 0 | AE43: 0 | AF43: 0 | AG43: 0 | AH43: 0 | AI43: 0 | AJ43: 0 | AK43: 0 | AL43: 0 | AM43: 0 | AN43: 0 | AO43: 0 | AP43: 0 | AQ43: 1

Sheet DLIM ISIC alignment
A1: ='Pre ISIC Split DLIM'!A1 -> 0 | B1: ='Pre ISIC Split DLIM'!B1 -> ISIC 01T03 | C1: ='Pre ISIC Split DLIM'!C1 -> ISIC 05 | D1: ='Pre ISIC Split DLIM'!D1 -> ISIC 06 | E1: ='Pre ISIC Split DLIM'!E1 -> ISIC 07T08 | F1: ='Pre ISIC Split DLIM'!F1 -> ISIC 09 | G1: ='Pre ISIC Split DLIM'!G1 -> ISIC 10T12 | H1: ='Pre ISIC Split DLIM'!H1 -> ISIC 13T15 | ... AQ1: ='Pre ISIC Split DLIM'!AQ1 -> ISIC 97T98
A2: ='Pre ISIC Split DLIM'!A2 -> ISIC 01T03 | B2: ='Pre ISIC Split DLIM'!B2 -> 1.093 | C2: ='Pre ISIC Split DLIM'!C2 -> 8.3969505e-05 | D2: ='Pre ISIC Split DLIM'!D2 -> 2.6080841e-06 | E2: ='Pre ISIC Split DLIM'!E2 -> 0.003 | F2: ='Pre ISIC Split DLIM'!F2 -> 0.002 | G2: ='Pre ISIC Split DLIM'!G2 -> 0.233 | H2: ='Pre ISIC Split DLIM'!H2 -> 0.026 | ... AQ2: ='Pre ISIC Split DLIM'!AQ2 -> 0
A3: ='Pre ISIC Split DLIM'!A3 -> ISIC 05 | B3: ='Pre ISIC Split DLIM'!B3 -> 0.00013876065 | C3: ='Pre ISIC Split DLIM'!C3 -> 1.0001866 | D3: ='Pre ISIC Split DLIM'!D3 -> 9.9524146e-06 | E3: ='Pre ISIC Split DLIM'!E3 -> 9.274934e-07 | F3: ='Pre ISIC Split DLIM'!F3 -> 0 | G3: ='Pre ISIC Split DLIM'!G3 -> 8.356304e-05 | H3: ='Pre ISIC Split DLIM'!H3 -> 2.6823783e-05 | ... AQ3: ='Pre ISIC Split DLIM'!AQ3 -> 0.00014562739
A4: ='Pre ISIC Split DLIM'!A4 -> ISIC 06 | B4: ='Pre ISIC Split DLIM'!B4 -> 9.7181737e-05 | C4: ='Pre ISIC Split DLIM'!C4 -> 8.6218445e-07 | D4: ='Pre ISIC Split DLIM'!D4 -> 1.0000043 | E4: ='Pre ISIC Split DLIM'!E4 -> 4.7772262e-06 | F4: ='Pre ISIC Split DLIM'!F4 -> 0 | G4: ='Pre ISIC Split DLIM'!G4 -> 0.00010328004 | H4: ='Pre ISIC Split DLIM'!H4 -> 0.00013743446 | ... AQ4: ='Pre ISIC Split DLIM'!AQ4 -> 7.8228207e-09
A5: ='Pre ISIC Split DLIM'!A5 -> ISIC 07T08 | B5: ='Pre ISIC Split DLIM'!B5 -> 0.003 | C5: ='Pre ISIC Split DLIM'!C5 -> 0.0025483117 | D5: ='Pre ISIC Split DLIM'!D5 -> 6.083748e-05 | E5: ='Pre ISIC Split DLIM'!E5 -> 1.016 | F5: ='Pre ISIC Split DLIM'!F5 -> 0.005 | G5: ='Pre ISIC Split DLIM'!G5 -> 0.005 | H5: ='Pre ISIC Split DLIM'!H5 -> 0.002 | ... AQ5: ='Pre ISIC Split DLIM'!AQ5 -> 0
A6: ='Pre ISIC Split DLIM'!A6 -> ISIC 09 | B6: ='Pre ISIC Split DLIM'!B6 -> 0.017 | C6: ='Pre ISIC Split DLIM'!C6 -> 0 | D6: ='Pre ISIC Split DLIM'!D6 -> 0 | E6: ='Pre ISIC Split DLIM'!E6 -> 0.003 | F6: ='Pre ISIC Split DLIM'!F6 -> 1.018 | G6: ='Pre ISIC Split DLIM'!G6 -> 0 | H6: ='Pre ISIC Split DLIM'!H6 -> 0 | ... AQ6: ='Pre ISIC Split DLIM'!AQ6 -> 0
A7: ='Pre ISIC Split DLIM'!A7 -> ISIC 10T12 | B7: ='Pre ISIC Split DLIM'!B7 -> 0.062 | C7: ='Pre ISIC Split DLIM'!C7 -> 7.6404479e-05 | D7: ='Pre ISIC Split DLIM'!D7 -> 2.5099902e-06 | E7: ='Pre ISIC Split DLIM'!E7 -> 0.001 | F7: ='Pre ISIC Split DLIM'!F7 -> 0.001 | G7: ='Pre ISIC Split DLIM'!G7 -> 1.084 | H7: ='Pre ISIC Split DLIM'!H7 -> 0.014 | ... AQ7: ='Pre ISIC Split DLIM'!AQ7 -> 0
A8: ='Pre ISIC Split DLIM'!A8 -> ISIC 13T15 | B8: ='Pre ISIC Split DLIM'!B8 -> 0.002 | C8: ='Pre ISIC Split DLIM'!C8 -> 8.9127488e-05 | D8: ='Pre ISIC Split DLIM'!D8 -> 2.7077664e-06 | E8: ='Pre ISIC Split DLIM'!E8 -> 0.005 | F8: ='Pre ISIC Split DLIM'!F8 -> 0.01 | G8: ='Pre ISIC Split DLIM'!G8 -> 0.002 | H8: ='Pre ISIC Split DLIM'!H8 -> 0.007 | ... AQ8: ='Pre ISIC Split DLIM'!AQ8 -> 0
A9: ='Pre ISIC Split DLIM'!A9 -> ISIC 16 | B9: ='Pre ISIC Split DLIM'!B9 -> 0.001 | C9: ='Pre ISIC Split DLIM'!C9 -> 0.00084144085 | D9: ='Pre ISIC Split DLIM'!D9 -> 1.1794331e-06 | E9: ='Pre ISIC Split DLIM'!E9 -> 0.005 | F9: ='Pre ISIC Split DLIM'!F9 -> 0.01 | G9: ='Pre ISIC Split DLIM'!G9 -> 0.002 | H9: ='Pre ISIC Split DLIM'!H9 -> 0.007 | ... AQ9: ='Pre ISIC Split DLIM'!AQ9 -> 0
A10: ='Pre ISIC Split DLIM'!A10 -> ISIC 17T18 | B10: ='Pre ISIC Split DLIM'!B10 -> 0.003 | C10: ='Pre ISIC Split DLIM'!C10 -> 7.0831409e-05 | D10: ='Pre ISIC Split DLIM'!D10 -> 1.0593472e-05 | E10: ='Pre ISIC Split DLIM'!E10 -> 0.002 | F10: ='Pre ISIC Split DLIM'!F10 -> 0.016 | G10: ='Pre ISIC Split DLIM'!G10 -> 0.01 | H10: ='Pre ISIC Split DLIM'!H10 -> 0.016 | ... AQ10: ='Pre ISIC Split DLIM'!AQ10 -> 0
A11: ='Pre ISIC Split DLIM'!A11 -> ISIC 19 | B11: ='Pre ISIC Split DLIM'!B11 -> 0.027 | C11: ='Pre ISIC Split DLIM'!C11 -> 5.3489112e-08 | D11: ='Pre ISIC Split DLIM'!D11 -> 5.1685294e-09 | E11: ='Pre ISIC Split DLIM'!E11 -> 0.035 | F11: ='Pre ISIC Split DLIM'!F11 -> 0.06 | G11: ='Pre ISIC Split DLIM'!G11 -> 0.016 | H11: ='Pre ISIC Split DLIM'!H11 -> 0.012 | ... AQ11: ='Pre ISIC Split DLIM'!AQ11 -> 0
A12: ='Pre ISIC Split DLIM'!A12 -> ISIC 20 | B12: ='Pre ISIC Split DLIM'!B12 -> 0.040781031 | C12: ='Pre ISIC Split DLIM'!C12 -> 0.024202007 | D12: ='Pre ISIC Split DLIM'!D12 -> 0.024202007 | E12: ='Pre ISIC Split DLIM'!E12 -> 0.017 | F12: ='Pre ISIC Split DLIM'!F12 -> 0.01 | G12: ='Pre ISIC Split DLIM'!G12 -> 0.02 | H12: ='Pre ISIC Split DLIM'!H12 -> 0.028 | ... AQ12: ='Pre ISIC Split DLIM'!AQ12 -> 0
... A43: ='Pre ISIC Split DLIM'!A43 -> ISIC 97T98 | B43: ='Pre ISIC Split DLIM'!B43 -> 0 | C43: ='Pre ISIC Split DLIM'!C43 -> 0 | D43: ='Pre ISIC Split DLIM'!D43 -> 0 | E43: ='Pre ISIC Split DLIM'!E43 -> 0 | F43: ='Pre ISIC Split DLIM'!F43 -> 0 | G43: ='Pre ISIC Split DLIM'!G43 -> 0 | H43: ='Pre ISIC Split DLIM'!H43 -> 0 | ... AQ43: ='Pre ISIC Split DLIM'!AQ43 -> 1

Sheet Pre ISIC Split BObIC
A1: Unit: USD | B1: ISIC 01T03 | C1: ISIC 05 | D1: ISIC 06 | E1: ISIC 07T08 | F1: ISIC 09 | G1: ISIC 10T12 | H1: ISIC 13T15 | I1: ISIC 16 | J1: ISIC 17T18 | K1: ISIC 19 | L1: ISIC 20 | M1: ISIC 21 | N1: ISIC 22 | O1: ISIC 231 | P1: ISIC 239 | Q1: ISIC 241 | R1: ISIC 242 | S1: ISIC 25 | T1: ISIC 26 | U1: ISIC 27 | V1: ISIC 28 | W1: ISIC 29 | X1: ISIC 30 | Y1: ISIC 31T33 | Z1: ISIC 351 | AA1: ISIC 352T353 | AB1: ISIC 36T39 | AC1: ISIC 41T43 | AD1: ISIC 45T47 | AE1: ISIC 49T53 | AF1: ISIC 55T56 | AG1: ISIC 58T60 | AH1: ISIC 61 | AI1: ISIC 62T63 | AJ1: ISIC 64T66 | AK1: ISIC 68 | AL1: ISIC 69T82 | AM1: ISIC 84 | AN1: ISIC 85 | AO1: ISIC 86T88 | AP1: ISIC 90T96 | AQ1: ISIC 97T98
A2: Output | B2: 52329376000 | C2: 4.8858285e+08 | D2: 4.2147738e+10 | E2: 16974139000 | F2: 7200739000 | G2: 129043369000 | H2: 19568731000 | I2: 3939845000 | J2: 16184623000 | K2: 45756620000 | L2: 39707304000 | M2: 12745551000 | N2: 18376336000 | O2: 6.5339221e+09 | P2: 1.1263403e+10 | Q2: 1.3105774e+10 | R2: 2.6453837e+10 | S2: 24117730000 | T2: 78553930000 | U2: 25144483000 | V2: 23016903000 | W2: 161627466000 | X2: 9838556000 | Y2: 20414667000 | Z2: 2.6767267e+10 | AA2: 8.2743506e+08 | AB2: 6815263000 | AC2: 139088313000 | AD2: 261044875000 | AE2: 110265848000 | AF2: 37828973000 | AG2: 8906261000 | AH2: 21265426000 | AI2: 2554643000 | AJ2: 68018132000 | AK2: 115551527000 | AL2: 82725720000 | AM2: 63878360000 | AN2: 46365228000 | AO2: 38002328000 | AP2: 19889936000 | AQ2: 4731727000

Sheet SIOM from DLIM
A1: Inverse of DLIM
B3: ISIC 01T03 | C3: ISIC 05 | D3: ISIC 06 | E3: ISIC 07T08 | F3: ISIC 09 | G3: ISIC 10T12 | H3: ISIC 13T15 | I3: ISIC 16 | J3: ISIC 17T18 | K3: ISIC 19 | L3: ISIC 20 | M3: ISIC 21 | N3: ISIC 22 | O3: ISIC 231 | P3: ISIC 239 | Q3: ISIC 241 | R3: ISIC 242 | S3: ISIC 25 | T3: ISIC 26 | U3: ISIC 27 | V3: ISIC 28 | W3: ISIC 29 | X3: ISIC 30 | Y3: ISIC 31T33 | Z3: ISIC 351 | AA3: ISIC 352T353 | AB3: ISIC 36T39 | AC3: ISIC 41T43 | AD3: ISIC 45T47 | AE3: ISIC 49T53 | AF3: ISIC 55T56 | AG3: ISIC 58T60 | AH3: ISIC 61 | AI3: ISIC 62T63 | AJ3: ISIC 64T66 | AK3: ISIC 68 | AL3: ISIC 69T82 | AM3: ISIC 84 | AN3: ISIC 85 | AO3: ISIC 86T88 | AP3: ISIC 90T96 | AQ3: ISIC 97T98
A4: ISIC 01T03 | B4: {=MINVERSE('Pre ISIC Split DLIM'!B2:AQ43)} -> 2.9432153 | C4: -25.977206 | D4: 8.4242198 | E4: 0.14111685 | F4: 0.2231858 | G4: 0.23918731 | H4: -690215.88 | I4: 76433.089 | J4: -1.7668661 | K4: -4.2530586 | L4: -7.6898321 | M4: -4.0770411 | N4: 12.216443 | O4: -86.322387 | P4: -24.735576 | Q4: -10.37495 | R4: 11.416637 | S4: -1729.6564 | T4: 1011240.3 | U4: -112657.88 | V4: -4511.554 | W4: -0.082069038 | X4: -692122.67 | Y4: 413564.26 | Z4: 653.0532 | AA4: 96.772714 | AB4: 0.18481286 | AC4: 0.30676107 | AD4: 0.036298251 | AE4: 1.9605806 | AF4: -0.1629405 | AG4: -0.1516697 | AH4: 0.032354226 | AI4: 0.072915896 | AJ4: -1.354409 | AK4: -1.7652872 | AL4: -0.25156157 | AM4: -3.8857408 | AN4: -5.6219522 | AO4: -2.2855595 | AP4: 83.268144 | AQ4: 0.0037622831
A5: ISIC 05 | B5: -3.095982 | C5: 29.566052 | D5: -9.4289327 | E5: -0.14864601 | F5: -0.24412955 | G5: -0.25780952 | H5: 781502.98 | I5: -85587.253 | J5: 1.9802566 | K5: 4.7943148 | L5: 8.5863108 | M5: 4.5852259 | N5: -10.012217 | O5: 95.294416 | P5: 27.088243 | Q5: 12.324758 | R5: -13.026493 | S5: 2833.7576 | T5: -1150740.2 | U5: 126132.49 | V5: 741.58509 | W5: 0.050267688 | X5: 784502.46 | Y5: -459385.92 | Z5: -734.89936 | AA5: -109.67379 | AB5: -0.22269845 | AC5: -0.32960477 | AD5: -0.051547298 | AE5: -3.1117579 | AF5: 0.16537728 | AG5: 0.14074002 | AH5: -0.038835608 | AI5: -0.086607588 | AJ5: 1.5279922 | AK5: 1.992866 | AL5: 0.24361484 | AM5: 4.3746834 | AN5: 6.3329056 | AO5: 2.5544745 | AP5: -83.279211 | AQ5: -0.0042813162
A6: ISIC 06 | B6: -4.8276352 | C6: 45.062724 | D6: -13.836501 | E6: -0.22046797 | F6: -0.35778411 | G6: -0.42348027 | H6: 1229525.2 | I6: -134808.89 | J6: 3.1161512 | K6: 7.0406753 | L6: 13.59324 | M6: 7.2195442 | N6: -15.915634 | O6: 150.42652 | P6: 42.762966 | Q6: 19.416445 | R6: -20.517695 | S6: 4416.7736 | T6: -1810237.9 | U6: 198436.46 | V6: 1443.7047 | W6: 0.077406708 | X6: 1234205.2 | Y6: -722980.68 | Z6: -1156.1901 | AA6: -172.52643 | AB6: -0.33895159 | AC6: -0.51674326 | AD6: -0.077635303 | AE6: -4.8022267 | AF6: 0.26096929 | AG6: 0.22325042 | AH6: -0.060643381 | AI6: -0.13527157 | AJ6: 2.4037282 | AK6: 3.1325902 | AL6: 0.38806164 | AM6: 6.8809198 | AN6: 9.9637876 | AO6: 4.0207959 | AP6: -131.21463 | AQ6: -0.0065243613
A7: ISIC 07T08 | B7: 6.7837163 | C7: -61.900136 | D7: 20.598079 | E7: 1.3168467 | F7: 0.53523704 | G7: 0.51544062 | H7: -1707451.1 | I7: 186315.25 | J7: -4.3232438 | K7: -10.460138 | L7: -19.172924 | M7: -10.043944 | N7: 23.508433 | O7: -206.14978 | P7: -58.653279 | Q7: -27.382913 | R7: 27.83657 | S7: -6440.1185 | T7: 2514018.2 | U7: -275414.24 | V7: 134.13307 | W7: -0.13253056 | X7: -1714478.8 | Y7: 1003317 | Z7: 1605.1681 | AA7: 239.76525 | AB7: 0.48272337 | AC7: 0.69561697 | AD7: 0.10991443 | AE7: 6.8227253 | AF7: -0.35563696 | AG7: -0.28700918 | AH7: 0.095309057 | AI7: 0.21806493 | AJ7: -3.3196862 | AK7: -4.3505616 | AL7: -0.74009502 | AM7: -9.546017 | AN7: -13.826308 | AO7: -5.5676896 | AP7: 182.79846 | AQ7: 0.0089605983
A8: ISIC 09 | B8: -0.24970382 | C8: 2.2863379 | D8: -0.7547337 | E8: -0.014827919 | F8: 0.96297156 | G8: -0.020297226 | H8: 62410.952 | I8: -6839.2495 | J8: 0.15839842 | K8: 0.37714778 | L8: 0.69580867 | M8: 0.3656662 | N8: -0.87147535 | O8: 7.617196 | P8: 2.1672665 | Q8: 0.97983398 | R8: -1.0333814 | S8: 217.56439 | T8: -91817.829 | U8: 10093.261 | V8: 95.008057 | W8: 0.0049395532 | X8: 62647.41 | Y8: -36807.124 | Z8: -58.754511 | AA8: -8.7592919 | AB8: -0.017499739 | AC8: -0.026325414 | AD8: -0.0039305484 | AE8: -0.23963676 | AF8: 0.01334374 | AG8: 0.010390198 | AH8: -0.003239351 | AI8: -0.0083596167 | AJ8: 0.1218211 | AK8: 0.1592096 | AL8: 0.023917074 | AM8: 0.34967382 | AN8: 0.50614658 | AO8: 0.20433582 | AP8: -6.8133319 | AQ8: -0.00033101252
A9: ISIC 10T12 | B9: 12.347012 | C9: -113.92568 | D9: 37.668823 | E9: 0.60265601 | F9: 0.97984486 | G9: 1.9494023 | H9: -3122107.7 | I9: 341691.25 | J9: -7.8984427 | K9: -19.137511 | L9: -34.911068 | M9: -18.352487 | N9: 40.576432 | O9: -379.92206 | P9: -107.96499 | Q9: -49.233258 | R9: 52.085413 | S9: -11404.136 | T9: 4597206.5 | U9: -503690.24 | V9: -2533.8916 | W9: -0.20796272 | X9: -3134238.9 | Y9: 1835077.4 | Z9: 2935.292 | AA9: 438.23316 | AB9: 0.89457296 | AC9: 1.3129442 | AD9: 0.20521354 | AE9: 12.455072 | AF9: -0.71161119 | AG9: -0.55197958 | AH9: 0.15829329 | AI9: 0.35497341 | AJ9: -6.0982685 | AK9: -7.95854 | AL9: -1.0314207 | AM9: -17.475949 | AN9: -25.29373 | AO9: -10.194046 | AP9: 332.74513 | AQ9: 0.016493225
A10: ISIC 13T15 | B10: -1320.624 | C10: 12093.935 | D10: -4002.6535 | E10: -64.070627 | F10: -104.17606 | G10: -106.17066 | H10: 3.317302e+08 | I10: -36290703 | J10: 839.06826 | K10: 2033.5461 | L10: 3711.0228 | M10: 1949.539 | N10: -4327.7727 | O10: 40326.029 | P10: 11457.12 | Q10: 5232.1526 | R10: -5525.9828 | S10: 1218388.4 | T10: -4.884739e+08 | U10: 53522292 | V10: 222087.21 | W10: 22.520962 | X10: 3.330288e+08 | Y10: -1.949572e+08 | Z10: -311896.06 | AA10: -46565.535 | AB10: -95.086667 | AC10: -139.29211 | AD10: -21.821664 | AE10: -1327.1706 | AF10: 69.674322 | AG10: 58.345231 | AH10: -16.971567 | AI10: -38.186644 | AJ10: 647.75401 | AK10: 845.68063 | AL10: 112.18622 | AM10: 1856.1387 | AN10: 2687.4387 | AO10: 1082.8413 | AP10: -35355.307 | AQ10: -1.7508317
A11: ISIC 16 | B11: 225.66685 | C11: -2002.28 | D11: 664.55301 | E11: 10.572838 | F11: 17.266746 | G11: 15.727699 | H11: -55137115 | I11: 6022676.7 | J11: -139.48864 | K11: -337.85184 | L11: -617.34843 | M11: -323.9364 | N11: 696.11204 | O11: -6678.2387 | P11: -1895.3158 | Q11: -873.96391 | R11: 917.97036 | S11: -209853.7 | T11: 81231690 | U11: -8886170.9 | V11: 1854.8652 | W11: -3.5207823 | X11: -55360740 | Y11: 32337664 | Z11: 51809.7 | AA11: 7740.9118 | AB11: 15.909774 | AC11: 22.969369 | AD11: 3.6727436 | AE11: 227.36746 | AF11: -11.667473 | AG11: -9.4346673 | AH11: 2.866926 | AI11: 6.4661364 | AJ11: -107.58362 | AK11: -140.52505 | AL11: -18.99816 | AM11: -308.35104 | AN11: -446.46204 | AO11: -179.74529 | AP11: 5799.033 | AQ11: 0.28985269
A12: ISIC 17T18 | B12: -5.9621381 | C12: 53.620326 | D12: -17.986784 | E12: -0.29101749 | F12: -0.48489238 | G12: -0.4137812 | H12: 1487155.4 | I12: -161813.6 | J12: 4.6279813 | K12: 9.1312242 | L12: 16.780781 | M12: 8.7672399 | N12: -22.822373 | O12: 178.47492 | P12: 50.498585 | Q12: 23.364007 | R12: -23.996334 | S12: 5906.1687 | T12: -2189118.3 | U12: 240561.84 | V12: -2402.6785 | W12: 0.16322542 | X12: 1493802.4 | Y12: -874091.41 | Z12: -1400.4028 | AA12: -208.89442 | AB12: -0.41880214 | AC12: -0.61051055 | AD12: -0.096210799 | AE12: -6.011878 | AF12: 0.30366573 | AG12: 0.23598896 | AH12: -0.092191851 | AI12: -0.22427121 | AJ12: 2.8741663 | AK12: 3.7911157 | AL12: 0.85310666 | AM12: 8.3127536 | AN12: 12.051554 | AO12: 4.8517815 | AP12: -161.50431 | AQ12: -0.0077608907
A13: ISIC 19 | B13: 2.6144883 | C13: -25.082377 | D13: 8.2098226 | E13: 0.10569536 | F13: 0.16635108 | G13: 0.25719064 | H13: -680203.09 | I13: 74779.357 | J13: -1.7245833 | K13: -3.2973315 | L13: -7.5996625 | M13: -3.9993549 | N13: 8.9082085 | O13: -83.842693 | P13: -23.84545 | Q13: -10.776849 | R13: 11.394046 | S13: -2378.2399 | T13: 1001223.6 | U13: -109769.86 | V13: -1228.8803 | W13: -0.039309483 | X13: -682718.94 | Y13: 400296.15 | Z13: 639.59691 | AA13: 95.417663 | AB13: 0.17395284 | AC13: 0.28403242 | AD13: 0.039080986 | AE13: 2.5405438 | AF13: -0.14531163 | AG13: -0.12643316 | AH13: 0.03274371 | AI13: 0.072514032 | AJ13: -1.3306334 | AK13: -1.7340614 | AL13: -0.21029588 | AM13: -3.8180502 | AN13: -5.5134713 | AO13: -2.2270829 | AP13: 72.805063 | AQ13: 0.003631945
A14: ISIC 20 | B14: 15.433423 | C14: -142.729 | D14: 47.05198 | E14: 0.73878956 | F14: 1.2161894 | G14: 1.3024782 | H14: -3900606.7 | I14: 427388.3 | J14: -9.8838976 | K14: -23.930546 | L14: -42.652363 | M14: -22.971797 | N14: 49.144982 | O14: -476.20157 | P14: -135.41462 | Q14: -61.536505 | R14: 65.15879 | S14: -14037.326 | T14: 5743666 | U14: -629474.11 | V14: -4462.1464 | W14: -0.23691105 | X14: -3915383 | Y14: 2292909.5 | Z14: 3667.7077 | AA14: 547.35312 | AB14: 1.1117183 | AC14: 1.648601 | AD14: 0.2588141 | AE14: 15.511747 | AF14: -0.82684491 | AG14: -0.7098026 | AH14: 0.19007411 | AI14: 0.42070062 | AJ14: -7.6325416 | AK14: -9.9471312 | AL14: -1.1343003 | AM14: -21.837133 | AN14: -31.6089 | AO14: -12.748798 | AP14: 415.08682 | AQ14: 0.020664201
A15: ISIC 21 | B15: -0.099735843 | C15: 0.85773994 | D15: -0.28429274 | E15: -0.0044725948 | F15: -0.0073174605 | G15: -0.0070119827 | H15: 23672.115 | I15: -2584.5437 | J15: 0.059691063 | K15: 0.14470644 | L15: 0.26349232 | M15: 1.06213 | N15: -0.26030777 | O15: 2.8655362 | P15: 0.81260956 | Q15: 0.37773712 | R15: -0.39927611 | S15: 94.096825 | T15: -34911.93 | U15: 3801.1709 | V15: -13.749256 | W15: 0.00092641854 | X15: 23773.605 | Y15: -13830.772 | Z15: -22.19773 | AA15: -3.3232304 | AB15: -0.0069380329 | AC15: -0.009828069 | AD15: -0.0016435113 | AE15: -0.10001162 | AF15: 0.0051096995 | AG15: 0.0040576131 | AH15: -0.001131404 | AI15: -0.0024494941 | AJ15: 0.0463225 | AK15: 0.06027153 | AL15: 0.0052627068 | AM15: 0.13038747 | AN15: 0.19140071 | AO15: 0.034744738 | AP15: -2.4064462 | AQ15: -0.00012416729
A16: ISIC 22 | B16: -3.513646 | C16: 32.121051 | D16: -10.64784 | E16: -0.17019431 | F16: -0.27748898 | G16: -0.27748652 | H16: 882275.74 | I16: -96432.093 | J16: 2.235509 | K16: 5.4081914 | L16: 9.8820571 | M16: 5.1885642 | N16: -12.111256 | O16: 107.08464 | P16: 30.385914 | Q16: 13.884685 | R16: -14.574427 | S16: 3319.6496 | T16: -1298567.4 | U16: 142379.22 | V16: 30.901812 | W16: 0.070070302 | X16: 885885.06 | Y16: -518891.17 | Z16: -829.65763 | AA16: -123.85598 | AB16: -0.25102328 | AC16: -0.36932214 | AD16: -0.057048747 | AE16: -3.5316465 | AF16: 0.18552989 | AG16: 0.1536891 | AH16: -0.047648102 | AI16: -0.10992747 | AJ16: 1.7177629 | AK16: 2.2483905 | AL16: 0.37016618 | AM16: 4.9353815 | AN16: 7.1467938 | AO16: 2.8803404 | AP16: -95.321404 | AQ16: -0.0046500229
... A45: ISIC 97T98 | B45: 0 | C45: 0 | D45: 0 | E45: 0 | F45: 0 | G45: 0 | H45: 0 | I45: 0 | J45: 0 | K45: 0 | L45: 0 | M45: 0 | N45: 0 | O45: 0 | P45: 0 | Q45: 0 | R45: 0 | S45: 0 | T45: 0 | U45: 0 | V45: 0 | W45: 0 | X45: 0 | Y45: 0 | Z45: 0 | AA45: 0 | AB45: 0 | AC45: 0 | AD45: 0 | AE45: 0 | AF45: 0 | AG45: 0 | AH45: 0 | AI45: 0 | AJ45: 0 | AK45: 0 | AL45: 0 | AM45: 0 | AN45: 0 | AO45: 0 | AP45: 0 | AQ45: 1
A47: I Matrix
B49: ISIC 01T03 | C49: ISIC 05 | D49: ISIC 06 | E49: ISIC 07T08 | F49: ISIC 09 | G49: ISIC 10T12 | H49: ISIC 13T15 | I49: ISIC 16 | J49: ISIC 17T18 | K49: ISIC 19 | L49: ISIC 20 | M49: ISIC 21 | N49: ISIC 22 | O49: ISIC 231 | P49: ISIC 239 | Q49: ISIC 241 | R49: ISIC 242 | S49: ISIC 25 | T49: ISIC 26 | U49: ISIC 27 | V49: ISIC 28 | W49: ISIC 29 | X49: ISIC 30 | Y49: ISIC 31T33 | Z49: ISIC 351 | AA49: ISIC 352T353 | AB49: ISIC 36T39 | AC49: ISIC 41T43 | AD49: ISIC 45T47 | AE49: ISIC 49T53 | AF49: ISIC 55T56 | AG49: ISIC 58T60 | AH49: ISIC 61 | AI49: ISIC 62T63 | AJ49: ISIC 64T66 | AK49: ISIC 68 | AL49: ISIC 69T82 | AM49: ISIC 84 | AN49: ISIC 85 | AO49: ISIC 86T88 | AP49: ISIC 90T96 | AQ49: ISIC 97T98
A50: ISIC 01T03 | B50: 1 | C50: 0 | D50: 0 | E50: 0 | F50: 0 | G50: 0 | H50: 0 | I50: 0 | J50: 0 | K50: 0 | L50: 0 | M50: 0 | N50: 0 | O50: 0 | P50: 0 | Q50: 0 | R50: 0 | S50: 0 | T50: 0 | U50: 0 | V50: 0 | W50: 0 | X50: 0 | Y50: 0 | Z50: 0 | AA50: 0 | AB50: 0 | AC50: 0 | AD50: 0 | AE50: 0 | AF50: 0 | AG50: 0 | AH50: 0 | AI50: 0 | AJ50: 0 | AK50: 0 | AL50: 0 | AM50: 0 | AN50: 0 | AO50: 0 | AP50: 0 | AQ50: 0
A51: ISIC 05 | B51: 0 | C51: 1 | D51: 0 | E51: 0 | F51: 0 | G51: 0 | H51: 0 | I51: 0 | J51: 0 | K51: 0 | L51: 0 | M51: 0 | N51: 0 | O51: 0 | P51: 0 | Q51: 0 | R51: 0 | S51: 0 | T51: 0 | U51: 0 | V51: 0 | W51: 0 | X51: 0 | Y51: 0 | Z51: 0 | AA51: 0 | AB51: 0 | AC51: 0 | AD51: 0 | AE51: 0 | AF51: 0 | AG51: 0 | AH51: 0 | AI51: 0 | AJ51: 0 | AK51: 0 | AL51: 0 | AM51: 0 | AN51: 0 | AO51: 0 | AP51: 0 | AQ51: 0
A52: ISIC 06 | B52: 0 | C52: 0 | D52: 1 | E52: 0 | F52: 0 | G52: 0 | H52: 0 | I52: 0 | J52: 0 | K52: 0 | L52: 0 | M52: 0 | N52: 0 | O52: 0 | P52: 0 | Q52: 0 | R52: 0 | S52: 0 | T52: 0 | U52: 0 | V52: 0 | W52: 0 | X52: 0 | Y52: 0 | Z52: 0 | AA52: 0 | AB52: 0 | AC52: 0 | AD52: 0 | AE52: 0 | AF52: 0 | AG52: 0 | AH52: 0 | AI52: 0 | AJ52: 0 | AK52: 0 | AL52: 0 | AM52: 0 | AN52: 0 | AO52: 0 | AP52: 0 | AQ52: 0
A53: ISIC 07T08 | B53: 0 | C53: 0 | D53: 0 | E53: 1 | F53: 0 | G53: 0 | H53: 0 | I53: 0 | J53: 0 | K53: 0 | L53: 0 | M53: 0 | N53: 0 | O53: 0 | P53: 0 | Q53: 0 | R53: 0 | S53: 0 | T53: 0 | U53: 0 | V53: 0 | W53: 0 | X53: 0 | Y53: 0 | Z53: 0 | AA53: 0 | AB53: 0 | AC53: 0 | AD53: 0 | AE53: 0 | AF53: 0 | AG53: 0 | AH53: 0 | AI53: 0 | AJ53: 0 | AK53: 0 | AL53: 0 | AM53: 0 | AN53: 0 | AO53: 0 | AP53: 0 | AQ53: 0
A54: ISIC 09 | B54: 0 | C54: 0 | D54: 0 | E54: 0 | F54: 1 | G54: 0 | H54: 0 | I54: 0 | J54: 0 | K54: 0 | L54: 0 | M54: 0 | N54: 0 | O54: 0 | P54: 0 | Q54: 0 | R54: 0 | S54: 0 | T54: 0 | U54: 0 | V54: 0 | W54: 0 | X54: 0 | Y54: 0 | Z54: 0 | AA54: 0 | AB54: 0 | AC54: 0 | AD54: 0 | AE54: 0 | AF54: 0 | AG54: 0 | AH54: 0 | AI54: 0 | AJ54: 0 | AK54: 0 | AL54: 0 | AM54: 0 | AN54: 0 | AO54: 0 | AP54: 0 | AQ54: 0
A55: ISIC 10T12 | B55: 0 | C55: 0 | D55: 0 | E55: 0 | F55: 0 | G55: 1 | H55: 0 | I55: 0 | J55: 0 | K55: 0 | L55: 0 | M55: 0 | N55: 0 | O55: 0 | P55: 0 | Q55: 0 | R55: 0 | S55: 0 | T55: 0 | U55: 0 | V55: 0 | W55: 0 | X55: 0 | Y55: 0 | Z55: 0 | AA55: 0 | AB55: 0 | AC55: 0 | AD55: 0 | AE55: 0 | AF55: 0 | AG55: 0 | AH55: 0 | AI55: 0 | AJ55: 0 | AK55: 0 | AL55: 0 | AM55: 0 | AN55: 0 | AO55: 0 | AP55: 0 | AQ55: 0
A56: ISIC 13T15 | B56: 0 | C56: 0 | D56: 0 | E56: 0 | F56: 0 | G56: 0 | H56: 1 | I56: 0 | J56: 0 | K56: 0 | L56: 0 | M56: 0 | N56: 0 | O56: 0 | P56: 0 | Q56: 0 | R56: 0 | S56: 0 | T56: 0 | U56: 0 | V56: 0 | W56: 0 | X56: 0 | Y56: 0 | Z56: 0 | AA56: 0 | AB56: 0 | AC56: 0 | AD56: 0 | AE56: 0 | AF56: 0 | AG56: 0 | AH56: 0 | AI56: 0 | AJ56: 0 | AK56: 0 | AL56: 0 | AM56: 0 | AN56: 0 | AO56: 0 | AP56: 0 | AQ56: 0
A57: ISIC 16 | B57: 0 | C57: 0 | D57: 0 | E57: 0 | F57: 0 | G57: 0 | H57: 0 | I57: 1 | J57: 0 | K57: 0 | L57: 0 | M57: 0 | N57: 0 | O57: 0 | P57: 0 | Q57: 0 | R57: 0 | S57: 0 | T57: 0 | U57: 0 | V57: 0 | W57: 0 | X57: 0 | Y57: 0 | Z57: 0 | AA57: 0 | AB57: 0 | AC57: 0 | AD57: 0 | AE57: 0 | AF57: 0 | AG57: 0 | AH57: 0 | AI57: 0 | AJ57: 0 | AK57: 0 | AL57: 0 | AM57: 0 | AN57: 0 | AO57: 0 | AP57: 0 | AQ57: 0
A58: ISIC 17T18 | B58: 0 | C58: 0 | D58: 0 | E58: 0 | F58: 0 | G58: 0 | H58: 0 | I58: 0 | J58: 1 | K58: 0 | L58: 0 | M58: 0 | N58: 0 | O58: 0 | P58: 0 | Q58: 0 | R58: 0 | S58: 0 | T58: 0 | U58: 0 | V58: 0 | W58: 0 | X58: 0 | Y58: 0 | Z58: 0 | AA58: 0 | AB58: 0 | AC58: 0 | AD58: 0 | AE58: 0 | AF58: 0 | AG58: 0 | AH58: 0 | AI58: 0 | AJ58: 0 | AK58: 0 | AL58: 0 | AM58: 0 | AN58: 0 | AO58: 0 | AP58: 0 | AQ58: 0
A59: ISIC 19 | B59: 0 | C59: 0 | D59: 0 | E59: 0 | F59: 0 | G59: 0 | H59: 0 | I59: 0 | J59: 0 | K59: 1 | L59: 0 | M59: 0 | N59: 0 | O59: 0 | P59: 0 | Q59: 0 | R59: 0 | S59: 0 | T59: 0 | U59: 0 | V59: 0 | W59: 0 | X59: 0 | Y59: 0 | Z59: 0 | AA59: 0 | AB59: 0 | AC59: 0 | AD59: 0 | AE59: 0 | AF59: 0 | AG59: 0 | AH59: 0 | AI59: 0 | AJ59: 0 | AK59: 0 | AL59: 0 | AM59: 0 | AN59: 0 | AO59: 0 | AP59: 0 | AQ59: 0
A60: ISIC 20 | B60: 0 | C60: 0 | D60: 0 | E60: 0 | F60: 0 | G60: 0 | H60: 0 | I60: 0 | J60: 0 | K60: 0 | L60: 1 | M60: 0 | N60: 0 | O60: 0 | P60: 0 | Q60: 0 | R60: 0 | S60: 0 | T60: 0 | U60: 0 | V60: 0 | W60: 0 | X60: 0 | Y60: 0 | Z60: 0 | AA60: 0 | AB60: 0 | AC60: 0 | AD60: 0 | AE60: 0 | AF60: 0 | AG60: 0 | AH60: 0 | AI60: 0 | AJ60: 0 | AK60: 0 | AL60: 0 | AM60: 0 | AN60: 0 | AO60: 0 | AP60: 0 | AQ60: 0
A61: ISIC 21 | B61: 0 | C61: 0 | D61: 0 | E61: 0 | F61: 0 | G61: 0 | H61: 0 | I61: 0 | J61: 0 | K61: 0 | L61: 0 | M61: 1 | N61: 0 | O61: 0 | P61: 0 | Q61: 0 | R61: 0 | S61: 0 | T61: 0 | U61: 0 | V61: 0 | W61: 0 | X61: 0 | Y61: 0 | Z61: 0 | AA61: 0 | AB61: 0 | AC61: 0 | AD61: 0 | AE61: 0 | AF61: 0 | AG61: 0 | AH61: 0 | AI61: 0 | AJ61: 0 | AK61: 0 | AL61: 0 | AM61: 0 | AN61: 0 | AO61: 0 | AP61: 0 | AQ61: 0
... A91: ISIC 97T98 | B91: 0 | C91: 0 | D91: 0 | E91: 0 | F91: 0 | G91: 0 | H91: 0 | I91: 0 | J91: 0 | K91: 0 | L91: 0 | M91: 0 | N91: 0 | O91: 0 | P91: 0 | Q91: 0 | R91: 0 | S91: 0 | T91: 0 | U91: 0 | V91: 0 | W91: 0 | X91: 0 | Y91: 0 | Z91: 0 | AA91: 0 | AB91: 0 | AC91: 0 | AD91: 0 | AE91: 0 | AF91: 0 | AG91: 0 | AH91: 0 | AI91: 0 | AJ91: 0 | AK91: 0 | AL91: 0 | AM91: 0 | AN91: 0 | AO91: 0 | AP91: 0 | AQ91: 1
A93: A Matrix
B95: ISIC 01T03 | C95: ISIC 05 | D95: ISIC 06 | E95: ISIC 07T08 | F95: ISIC 09 | G95: ISIC 10T12 | H95: ISIC 13T15 | I95: ISIC 16 | J95: ISIC 17T18 | K95: ISIC 19 | L95: ISIC 20 | M95: ISIC 21 | N95: ISIC 22 | O95: ISIC 231 | P95: ISIC 239 | Q95: ISIC 241 | R95: ISIC 242 | S95: ISIC 25 | T95: ISIC 26 | U95: ISIC 27 | V95: ISIC 28 | W95: ISIC 29 | X95: ISIC 30 | Y95: ISIC 31T33 | Z95: ISIC 351 | AA95: ISIC 352T353 | AB95: ISIC 36T39 | AC95: ISIC 41T43 | AD95: ISIC 45T47 | AE95: ISIC 49T53 | AF95: ISIC 55T56 | AG95: ISIC 58T60 | AH95: ISIC 61 | AI95: ISIC 62T63 | AJ95: ISIC 64T66 | AK95: ISIC 68 | AL95: ISIC 69T82 | AM95: ISIC 84 | AN95: ISIC 85 | AO95: ISIC 86T88 | AP95: ISIC 90T96 | AQ95: ISIC 97T98
A96: ISIC 01T03 | B96: =B50-B4 -> -1.9432153 | C96: =C50-C4 -> 25.977206 | D96: =D50-D4 -> -8.4242198 | E96: =E50-E4 -> -0.14111685 | F96: =F50-F4 -> -0.2231858 | G96: =G50-G4 -> -0.23918731 | H96: =H50-H4 -> 690215.88 | I96: =I50-I4 -> -76433.089 | ... AQ96: =AQ50-AQ4 -> -0.0037622831
A97: ISIC 05 | B97: =B51-B5 -> 3.095982 | C97: =C51-C5 -> -28.566052 | D97: =D51-D5 -> 9.4289327 | E97: =E51-E5 -> 0.14864601 | F97: =F51-F5 -> 0.24412955 | G97: =G51-G5 -> 0.25780952 | H97: =H51-H5 -> -781502.98 | I97: =I51-I5 -> 85587.253 | ... AQ97: =AQ51-AQ5 -> 0.0042813162
A98: ISIC 06 | B98: =B52-B6 -> 4.8276352 | C98: =C52-C6 -> -45.062724 | D98: =D52-D6 -> 14.836501 | E98: =E52-E6 -> 0.22046797 | F98: =F52-F6 -> 0.35778411 | G98: =G52-G6 -> 0.42348027 | H98: =H52-H6 -> -1229525.2 | I98: =I52-I6 -> 134808.89 | ... AQ98: =AQ52-AQ6 -> 0.0065243613
A99: ISIC 07T08 | B99: =B53-B7 -> -6.7837163 | C99: =C53-C7 -> 61.900136 | D99: =D53-D7 -> -20.598079 | E99: =E53-E7 -> -0.31684674 | F99: =F53-F7 -> -0.53523704 | G99: =G53-G7 -> -0.51544062 | H99: =H53-H7 -> 1707451.1 | I99: =I53-I7 -> -186315.25 | ... AQ99: =AQ53-AQ7 -> -0.0089605983
A100: ISIC 09 | B100: =B54-B8 -> 0.24970382 | C100: =C54-C8 -> -2.2863379 | D100: =D54-D8 -> 0.7547337 | E100: =E54-E8 -> 0.014827919 | F100: =F54-F8 -> 0.037028436 | G100: =G54-G8 -> 0.020297226 | H100: =H54-H8 -> -62410.952 | I100: =I54-I8 -> 6839.2495 | ... AQ100: =AQ54-AQ8 -> 0.00033101252
A101: ISIC 10T12 | B101: =B55-B9 -> -12.347012 | C101: =C55-C9 -> 113.92568 | D101: =D55-D9 -> -37.668823 | E101: =E55-E9 -> -0.60265601 | F101: =F55-F9 -> -0.97984486 | G101: =G55-G9 -> -0.94940228 | H101: =H55-H9 -> 3122107.7 | I101: =I55-I9 -> -341691.25 | ... AQ101: =AQ55-AQ9 -> -0.016493225
A102: ISIC 13T15 | B102: =B56-B10 -> 1320.624 | C102: =C56-C10 -> -12093.935 | D102: =D56-D10 -> 4002.6535 | E102: =E56-E10 -> 64.070627 | F102: =F56-F10 -> 104.17606 | G102: =G56-G10 -> 106.17066 | H102: =H56-H10 -> -3.317302e+08 | I102: =I56-I10 -> 36290703 | ... AQ102: =AQ56-AQ10 -> 1.7508317
...

Sheet SIOM
A1: *Note for CEA: This table is mostly complete, but is just missing values for some of the orange highlighted boxes. You can copy the method used in the first orange box (cells D4:E5) to fill out the others. Once you've done that, the FoGPbEaIC-isic tab will correctly reflect the share by entity.
B2: Matching EPS Industry | C2: D01T03: Agriculture, forestry and fishing | D2: coal mining 05 | E2: oil and gas extraction 06 | F2: D07T08: Mining and quarrying of non-energy producing products | G2: D09: Mining support service activities | H2: D10T12: Food products, beverages and tobacco | I2: D13T15: Textiles, wearing apparel, leather and related products | J2: D16: Wood and products of wood and cork | K2: D17T18: Paper products and printing | L2: D19: Coke and refined petroleum products | M2: chemicals 20 | N2: pharmaceuticals | O2: D22: Rubber and plastic products | P2: glass and glass products 231 | Q2: cement and other nonmetallic minerals 239 | R2: iron and steel 241 | S2: other metals 242 | T2: D25: Fabricated metal products | U2: D26: Computer, electronic and optical products | V2: D27: Electrical equipment | W2: D28: Machinery and equipment, nec | X2: D29: Motor vehicles, trailers and semi-trailers | Y2: D30: Other transport equipment | Z2: D31T33: Other manufacturing; repair and installation of machinery and equipment | AA2: electricity | AB2: energy pipelines and gas processing 352T353 | AC2: water and waste 36T39 | AD2: D41T43: Construction | AE2: D45T47: Wholesale and retail trade; repair of motor vehicles | AF2: D49T53: Transportation and storage | AG2: D55T56: Accomodation and food services | AH2: D58T60: Publishing, audiovisual and broadcasting activities | AI2: D61: Telecommunications | AJ2: D62T63: IT and other information services | AK2: D64T66: Financial and insurance activities | AL2: D68: Real estate activities | AM2: D69T82: Other business sector services | AN2: D84: Public admin. and defence; compulsory social security | AO2: D85: Education | AP2: D86T88: Human health and social work | AQ2: D90T96: Arts, entertainment, recreation and other service activities | AR2: D97T98: Private households with employed persons
A3: D01T03: Agriculture, forestry and fishing | B3: agriculture and forestry 01T03 | C3: ='OECD TTL - 2018'!C9 -> 5034.6 | D3: ='OECD TTL - 2018'!$D9*'SIOM from DLIM'!C142/SUM('SIOM from DLIM'!$C142:$D142) -> 8.1 | E3: ='OECD TTL - 2018'!$D9*'SIOM from DLIM'!D142/SUM('SIOM from DLIM'!$C142:$D142) -> 0 | F3: ='OECD TTL - 2018'!E9 -> 22.4 | G3: ='OECD TTL - 2018'!F9 -> 8.2 | H3: ='OECD TTL - 2018'!G9 -> 30244.9 | I3: ='OECD TTL - 2018'!H9 -> 425.8 | J3: ='OECD TTL - 2018'!I9 -> 494.3 | K3: ='OECD TTL - 2018'!J9 -> 325.3 | L3: ='OECD TTL - 2018'!K9 -> 39.8 | M3: ='OECD TTL - 2018'!$L9*'SIOM from DLIM'!L142/SUM('SIOM from DLIM'!$L142:$M142) -> 461.12441 | N3: ='OECD TTL - 2018'!$L9*'SIOM from DLIM'!M142/SUM('SIOM from DLIM'!$L142:$M142) -> 78.475586 | O3: ='OECD TTL - 2018'!M9 -> 153.5 | P3: ='OECD TTL - 2018'!$N9*'SIOM from DLIM'!O142/SUM('SIOM from DLIM'!$O142:$P142) -> 5.8903742 | Q3: ='OECD TTL - 2018'!$N9*'SIOM from DLIM'!P142/SUM('SIOM from DLIM'!$O142:$P142) -> 2.9096258 | R3: ='OECD TTL - 2018'!$O9*'SIOM from DLIM'!Q142/SUM('SIOM from DLIM'!$Q142:$R142) -> 19.5 | S3: ='OECD TTL - 2018'!$O9*'SIOM from DLIM'!R142/SUM('SIOM from DLIM'!$Q142:$R142) -> 0 | T3: ='OECD TTL - 2018'!P9 -> 9.7 | U3: ='OECD TTL - 2018'!Q9 -> 7.4 | V3: ='OECD TTL - 2018'!R9 -> 6.9 | W3: ='OECD TTL - 2018'!S9 -> 6.8 | X3: ='OECD TTL - 2018'!T9 -> 25.1 | Y3: ='OECD TTL - 2018'!U9 -> 0.5 | Z3: ='OECD TTL - 2018'!V9 -> 132.5 | AA3: ='OECD TTL - 2018'!$W9*'SIOM from DLIM'!Z142/SUM('SIOM from DLIM'!$Z142:$AB142) -> #DIV/0! | AB3: ='OECD TTL - 2018'!$W9*'SIOM from DLIM'!AA142/SUM('SIOM from DLIM'!$Z142:$AB142) -> #DIV/0! | AC3: ='OECD TTL - 2018'!$W9*'SIOM from DLIM'!AB142/SUM('SIOM from DLIM'!$Z142:$AB142) -> #DIV/0! | AD3: ='OECD TTL - 2018'!X9 -> 177.3 | AE3: ='OECD TTL - 2018'!Y9 -> 643.1 | AF3: ='OECD TTL - 2018'!Z9 -> 45 | AG3: ='OECD TTL - 2018'!AA9 -> 1104.2 | AH3: ='OECD TTL - 2018'!AB9 -> 11.6 | AI3: ='OECD TTL - 2018'!AC9 -> 0.9 | AJ3: ='OECD TTL - 2018'!AD9 -> 0.9 | AK3: ='OECD TTL - 2018'!AE9 -> 12.9 | ... AR3: ='OECD TTL - 2018'!AL9 -> 0
A4: coal mining 05 | B4: coal mining 05 | C4: ='OECD TTL - 2018'!C$10*'SIOM from DLIM'!B143/SUM('SIOM from DLIM'!B$143:B$144) -> 18.87218 | D4: ='OECD TTL - 2018'!$D$10*'SIOM from DLIM'!C143/SUM('SIOM from DLIM'!$C$143:$D$144) -> 0 | E4: ='OECD TTL - 2018'!$D$10*'SIOM from DLIM'!D143/SUM('SIOM from DLIM'!$C$143:$D$144) -> 110.86035 | F4: ='OECD TTL - 2018'!E$10*'SIOM from DLIM'!D143/SUM('SIOM from DLIM'!D$143:D$144) -> 7.1109162 | G4: ='OECD TTL - 2018'!F$10*'SIOM from DLIM'!E143/SUM('SIOM from DLIM'!E$143:E$144) -> 89.603048 | H4: ='OECD TTL - 2018'!G$10*'SIOM from DLIM'!F143/SUM('SIOM from DLIM'!F$143:F$144) -> 41.694548 | I4: ='OECD TTL - 2018'!H$10*'SIOM from DLIM'!G143/SUM('SIOM from DLIM'!G$143:G$144) -> 3.1029939 | J4: ='OECD TTL - 2018'!I$10*'SIOM from DLIM'!H143/SUM('SIOM from DLIM'!H$143:H$144) -> #DIV/0! | K4: ='OECD TTL - 2018'!J$10*'SIOM from DLIM'!I143/SUM('SIOM from DLIM'!I$143:I$144) -> 14.174181 | L4: ='OECD TTL - 2018'!K$10*'SIOM from DLIM'!J143/SUM('SIOM from DLIM'!J$143:J$144) -> #DIV/0! | M4: ='OECD TTL - 2018'!$L$10*'SIOM from DLIM'!L143/SUM('SIOM from DLIM'!$L$143:$M$144) -> #DIV/0! | N4: ='OECD TTL - 2018'!$L$10*'SIOM from DLIM'!M143/SUM('SIOM from DLIM'!$L$143:$M$144) -> #DIV/0! | O4: ='OECD TTL - 2018'!M$10*'SIOM from DLIM'!L143/SUM('SIOM from DLIM'!L$143:L$144) -> #DIV/0! | P4: ='OECD TTL - 2018'!$N$10*'SIOM from DLIM'!O143/SUM('SIOM from DLIM'!$O$143:$P$144) -> #DIV/0! | Q4: ='OECD TTL - 2018'!$N$10*'SIOM from DLIM'!P143/SUM('SIOM from DLIM'!$O$143:$P$144) -> #DIV/0! | R4: ='OECD TTL - 2018'!$O$10*'SIOM from DLIM'!Q143/SUM('SIOM from DLIM'!$Q$143:$R$144) -> 0 | S4: ='OECD TTL - 2018'!$O$10*'SIOM from DLIM'!R143/SUM('SIOM from DLIM'!$Q$143:$R$144) -> 153.97614 | T4: ='OECD TTL - 2018'!P$10*'SIOM from DLIM'!O143/SUM('SIOM from DLIM'!O$143:O$144) -> #DIV/0! | U4: ='OECD TTL - 2018'!Q$10*'SIOM from DLIM'!P143/SUM('SIOM from DLIM'!P$143:P$144) -> #DIV/0! | V4: ='OECD TTL - 2018'!R$10*'SIOM from DLIM'!Q143/SUM('SIOM from DLIM'!Q$143:Q$144) -> #DIV/0! | W4: ='OECD TTL - 2018'!S$10*'SIOM from DLIM'!R143/SUM('SIOM from DLIM'!R$143:R$144) -> 5.1260655 | X4: ='OECD TTL - 2018'!T$10*'SIOM from DLIM'!S143/SUM('SIOM from DLIM'!S$143:S$144) -> #DIV/0! | Y4: ='OECD TTL - 2018'!U$10*'SIOM from DLIM'!T143/SUM('SIOM from DLIM'!T$143:T$144) -> 1.9043123 | Z4: ='OECD TTL - 2018'!V$10*'SIOM from DLIM'!U143/SUM('SIOM from DLIM'!U$143:U$144) -> #DIV/0! | AA4: ='OECD TTL - 2018'!$W$10*'SIOM from DLIM'!Z143/SUM('SIOM from DLIM'!$Z$143:$AB$144) -> 627.03844 | AB4: ='OECD TTL - 2018'!$W$10*'SIOM from DLIM'!AA143/SUM('SIOM from DLIM'!$Z$143:$AB$144) -> 2.892671 | AC4: ='OECD TTL - 2018'!$W$10*'SIOM from DLIM'!AB143/SUM('SIOM from DLIM'!$Z$143:$AB$144) -> 0.048379579 | AD4: ='OECD TTL - 2018'!X$10*'SIOM from DLIM'!W143/SUM('SIOM from DLIM'!W$143:W$144) -> #DIV/0! | AE4: ='OECD TTL - 2018'!Y$10*'SIOM from DLIM'!X143/SUM('SIOM from DLIM'!X$143:X$144) -> #DIV/0! | AF4: ='OECD TTL - 2018'!Z$10*'SIOM from DLIM'!Y143/SUM('SIOM from DLIM'!Y$143:Y$144) -> 104.04857 | AG4: ='OECD TTL - 2018'!AA$10*'SIOM from DLIM'!Z143/SUM('SIOM from DLIM'!Z$143:Z$144) -> 22.69492 | AH4: ='OECD TTL - 2018'!AB$10*'SIOM from DLIM'!AA143/SUM('SIOM from DLIM'!AA$143:AA$144) -> 1.4379614 | AI4: ='OECD TTL - 2018'!AC$10*'SIOM from DLIM'!AB143/SUM('SIOM from DLIM'!AB$143:AB$144) -> 2.1807912 | AJ4: ='OECD TTL - 2018'!AD$10*'SIOM from DLIM'!AC143/SUM('SIOM from DLIM'!AC$143:AC$144) -> 0.11683306 | AK4: ='OECD TTL - 2018'!AE$10*'SIOM from DLIM'!AD143/SUM('SIOM from DLIM'!AD$143:AD$144) -> 6.1450101 | ... AR4: ='OECD TTL - 2018'!AL$10*'SIOM from DLIM'!AK143/SUM('SIOM from DLIM'!AK$143:AK$144) -> #DIV/0!
A5: oil and gas extraction 06 | B5: oil and gas extraction 06 | C5: ='OECD TTL - 2018'!C$10*'SIOM from DLIM'!B144/SUM('SIOM from DLIM'!B$143:B$144) -> 29.42782 | D5: ='OECD TTL - 2018'!$D$10*'SIOM from DLIM'!C144/SUM('SIOM from DLIM'!$C$143:$D$144) -> 0 | E5: ='OECD TTL - 2018'!$D$10*'SIOM from DLIM'!D144/SUM('SIOM from DLIM'!$C$143:$D$144) -> 174.43965 | F5: ='OECD TTL - 2018'!E$10*'SIOM from DLIM'!D144/SUM('SIOM from DLIM'!D$143:D$144) -> 11.189084 | G5: ='OECD TTL - 2018'!F$10*'SIOM from DLIM'!E144/SUM('SIOM from DLIM'!E$143:E$144) -> 132.89695 | H5: ='OECD TTL - 2018'!G$10*'SIOM from DLIM'!F144/SUM('SIOM from DLIM'!F$143:F$144) -> 61.105452 | I5: ='OECD TTL - 2018'!H$10*'SIOM from DLIM'!G144/SUM('SIOM from DLIM'!G$143:G$144) -> 5.0970061 | J5: ='OECD TTL - 2018'!I$10*'SIOM from DLIM'!H144/SUM('SIOM from DLIM'!H$143:H$144) -> #DIV/0! | K5: ='OECD TTL - 2018'!J$10*'SIOM from DLIM'!I144/SUM('SIOM from DLIM'!I$143:I$144) -> 22.325819 | L5: ='OECD TTL - 2018'!K$10*'SIOM from DLIM'!J144/SUM('SIOM from DLIM'!J$143:J$144) -> #DIV/0! | M5: ='OECD TTL - 2018'!$L$10*'SIOM from DLIM'!L144/SUM('SIOM from DLIM'!$L$143:$M$144) -> #DIV/0! | N5: ='OECD TTL - 2018'!$L$10*'SIOM from DLIM'!M144/SUM('SIOM from DLIM'!$L$143:$M$144) -> #DIV/0! | O5: ='OECD TTL - 2018'!M$10*'SIOM from DLIM'!L144/SUM('SIOM from DLIM'!L$143:L$144) -> #DIV/0! | P5: ='OECD TTL - 2018'!$N$10*'SIOM from DLIM'!O144/SUM('SIOM from DLIM'!$O$143:$P$144) -> #DIV/0! | Q5: ='OECD TTL - 2018'!$N$10*'SIOM from DLIM'!P144/SUM('SIOM from DLIM'!$O$143:$P$144) -> #DIV/0! | R5: ='OECD TTL - 2018'!$O$10*'SIOM from DLIM'!Q144/SUM('SIOM from DLIM'!$Q$143:$R$144) -> 0 | S5: ='OECD TTL - 2018'!$O$10*'SIOM from DLIM'!R144/SUM('SIOM from DLIM'!$Q$143:$R$144) -> 242.52386 | T5: ='OECD TTL - 2018'!P$10*'SIOM from DLIM'!O144/SUM('SIOM from DLIM'!O$143:O$144) -> #DIV/0! | U5: ='OECD TTL - 2018'!Q$10*'SIOM from DLIM'!P144/SUM('SIOM from DLIM'!P$143:P$144) -> #DIV/0! | V5: ='OECD TTL - 2018'!R$10*'SIOM from DLIM'!Q144/SUM('SIOM from DLIM'!Q$143:Q$144) -> #DIV/0! | W5: ='OECD TTL - 2018'!S$10*'SIOM from DLIM'!R144/SUM('SIOM from DLIM'!R$143:R$144) -> 8.0739345 | X5: ='OECD TTL - 2018'!T$10*'SIOM from DLIM'!S144/SUM('SIOM from DLIM'!S$143:S$144) -> #DIV/0! | Y5: ='OECD TTL - 2018'!U$10*'SIOM from DLIM'!T144/SUM('SIOM from DLIM'!T$143:T$144) -> 2.9956877 | Z5: ='OECD TTL - 2018'!V$10*'SIOM from DLIM'!U144/SUM('SIOM from DLIM'!U$143:U$144) -> #DIV/0! | AA5: ='OECD TTL - 2018'!$W$10*'SIOM from DLIM'!Z144/SUM('SIOM from DLIM'!$Z$143:$AB$144) -> 986.49646 | AB5: ='OECD TTL - 2018'!$W$10*'SIOM from DLIM'!AA144/SUM('SIOM from DLIM'!$Z$143:$AB$144) -> 4.5504234 | AC5: ='OECD TTL - 2018'!$W$10*'SIOM from DLIM'!AB144/SUM('SIOM from DLIM'!$Z$143:$AB$144) -> 0.073634706 | AD5: ='OECD TTL - 2018'!X$10*'SIOM from DLIM'!W144/SUM('SIOM from DLIM'!W$143:W$144) -> #DIV/0! | AE5: ='OECD TTL - 2018'!Y$10*'SIOM from DLIM'!X144/SUM('SIOM from DLIM'!X$143:X$144) -> #DIV/0! | AF5: ='OECD TTL - 2018'!Z$10*'SIOM from DLIM'!Y144/SUM('SIOM from DLIM'!Y$143:Y$144) -> 163.75143 | AG5: ='OECD TTL - 2018'!AA$10*'SIOM from DLIM'!Z144/SUM('SIOM from DLIM'!Z$143:Z$144) -> 35.70508 | AH5: ='OECD TTL - 2018'!AB$10*'SIOM from DLIM'!AA144/SUM('SIOM from DLIM'!AA$143:AA$144) -> 2.2620386 | AI5: ='OECD TTL - 2018'!AC$10*'SIOM from DLIM'!AB144/SUM('SIOM from DLIM'!AB$143:AB$144) -> 3.3192088 | AJ5: ='OECD TTL - 2018'!AD$10*'SIOM from DLIM'!AC144/SUM('SIOM from DLIM'!AC$143:AC$144) -> 0.18316694 | AK5: ='OECD TTL - 2018'!AE$10*'SIOM from DLIM'!AD144/SUM('SIOM from DLIM'!AD$143:AD$144) -> 9.2549899 | ... AR5: ='OECD TTL - 2018'!AL$10*'SIOM from DLIM'!AK144/SUM('SIOM from DLIM'!AK$143:AK$144) -> #DIV/0!
A6: D07T08: Mining and quarrying of non-energy producing products | B6: other mining and quarrying 07T08 | C6: ='OECD TTL - 2018'!C11 -> 56.1 | D6: ='OECD TTL - 2018'!$D11*'SIOM from DLIM'!C145/SUM('SIOM from DLIM'!$C145:$D145) -> 19.8 | E6: ='OECD TTL - 2018'!$D11*'SIOM from DLIM'!D145/SUM('SIOM from DLIM'!$C145:$D145) -> 0 | F6: ='OECD TTL - 2018'!E11 -> 613.3 | G6: ='OECD TTL - 2018'!F11 -> 59.5 | H6: ='OECD TTL - 2018'!G11 -> 40.7 | I6: ='OECD TTL - 2018'!H11 -> 6.9 | J6: ='OECD TTL - 2018'!I11 -> 2.6 | K6: ='OECD TTL - 2018'!J11 -> 46.4 | L6: ='OECD TTL - 2018'!K11 -> 970.2 | M6: ='OECD TTL - 2018'!$L11*'SIOM from DLIM'!L145/SUM('SIOM from DLIM'!$L145:$M145) -> 655.99294 | N6: ='OECD TTL - 2018'!$L11*'SIOM from DLIM'!M145/SUM('SIOM from DLIM'!$L145:$M145) -> 110.30706 | O6: ='OECD TTL - 2018'!M11 -> 13.4 | P6: ='OECD TTL - 2018'!$N11*'SIOM from DLIM'!O145/SUM('SIOM from DLIM'!$O145:$P145) -> 1143.8738 | Q6: ='OECD TTL - 2018'!$N11*'SIOM from DLIM'!P145/SUM('SIOM from DLIM'!$O145:$P145) -> 561.02624 | R6: ='OECD TTL - 2018'!$O11*'SIOM from DLIM'!Q145/SUM('SIOM from DLIM'!$Q145:$R145) -> 6761.2 | S6: ='OECD TTL - 2018'!$O11*'SIOM from DLIM'!R145/SUM('SIOM from DLIM'!$Q145:$R145) -> 0 | T6: ='OECD TTL - 2018'!P11 -> 235.1 | U6: ='OECD TTL - 2018'!Q11 -> 38.7 | V6: ='OECD TTL - 2018'!R11 -> 64 | W6: ='OECD TTL - 2018'!S11 -> 45.8 | X6: ='OECD TTL - 2018'!T11 -> 55.1 | Y6: ='OECD TTL - 2018'!U11 -> 3.4 | Z6: ='OECD TTL - 2018'!V11 -> 145.9 | AA6: ='OECD TTL - 2018'!$W11*'SIOM from DLIM'!Z145/SUM('SIOM from DLIM'!$Z145:$AB145) -> #DIV/0! | AB6: ='OECD TTL - 2018'!$W11*'SIOM from DLIM'!AA145/SUM('SIOM from DLIM'!$Z145:$AB145) -> #DIV/0! | AC6: ='OECD TTL - 2018'!$W11*'SIOM from DLIM'!AB145/SUM('SIOM from DLIM'!$Z145:$AB145) -> #DIV/0! | AD6: ='OECD TTL - 2018'!X11 -> 1805.4 | AE6: ='OECD TTL - 2018'!Y11 -> 47.5 | AF6: ='OECD TTL - 2018'!Z11 -> 62.5 | AG6: ='OECD TTL - 2018'!AA11 -> 4.6 | AH6: ='OECD TTL - 2018'!AB11 -> 0.5 | AI6: ='OECD TTL - 2018'!AC11 -> 0.5 | AJ6: ='OECD TTL - 2018'!AD11 -> 0.1 | AK6: ='OECD TTL - 2018'!AE11 -> 3 | ... AR6: ='OECD TTL - 2018'!AL11 -> 0
A7: D09: Mining support service activities | C7: ='OECD TTL - 2018'!C12 -> 665.7 | D7: ='OECD TTL - 2018'!$D12*'SIOM from DLIM'!C146/SUM('SIOM from DLIM'!$C146:$D146) -> 0 | E7: ='OECD TTL - 2018'!$D12*'SIOM from DLIM'!D146/SUM('SIOM from DLIM'!$C146:$D146) -> 3004.1 | F7: ='OECD TTL - 2018'!E12 -> 870.4 | G7: ='OECD TTL - 2018'!F12 -> 2312.7 | H7: ='OECD TTL - 2018'!G12 -> 171.5 | I7: ='OECD TTL - 2018'!H12 -> 0.4 | J7: ='OECD TTL - 2018'!I12 -> 7.1 | K7: ='OECD TTL - 2018'!J12 -> 55.1 | L7: ='OECD TTL - 2018'!K12 -> 162.9 | M7: ='OECD TTL - 2018'!$L12*'SIOM from DLIM'!L146/SUM('SIOM from DLIM'!$L146:$M146) -> #DIV/0! | N7: ='OECD TTL - 2018'!$L12*'SIOM from DLIM'!M146/SUM('SIOM from DLIM'!$L146:$M146) -> #DIV/0! | O7: ='OECD TTL - 2018'!M12 -> 74.2 | P7: ='OECD TTL - 2018'!$N12*'SIOM from DLIM'!O146/SUM('SIOM from DLIM'!$O146:$P146) -> #DIV/0! | Q7: ='OECD TTL - 2018'!$N12*'SIOM from DLIM'!P146/SUM('SIOM from DLIM'!$O146:$P146) -> #DIV/0! | R7: ='OECD TTL - 2018'!$O12*'SIOM from DLIM'!Q146/SUM('SIOM from DLIM'!$Q146:$R146) -> 0 | S7: ='OECD TTL - 2018'!$O12*'SIOM from DLIM'!R146/SUM('SIOM from DLIM'!$Q146:$R146) -> 26.3 | T7: ='OECD TTL - 2018'!P12 -> 3.9 | U7: ='OECD TTL - 2018'!Q12 -> 1.1 | V7: ='OECD TTL - 2018'!R12 -> 0.6 | W7: ='OECD TTL - 2018'!S12 -> 37.9 | X7: ='OECD TTL - 2018'!T12 -> 7.6 | Y7: ='OECD TTL - 2018'!U12 -> 1 | Z7: ='OECD TTL - 2018'!V12 -> 34 | AA7: ='OECD TTL - 2018'!$W12*'SIOM from DLIM'!Z146/SUM('SIOM from DLIM'!$Z146:$AB146) -> 399.82708 | AB7: ='OECD TTL - 2018'!$W12*'SIOM from DLIM'!AA146/SUM('SIOM from DLIM'!$Z146:$AB146) -> 1.842595 | AC7: ='OECD TTL - 2018'!$W12*'SIOM from DLIM'!AB146/SUM('SIOM from DLIM'!$Z146:$AB146) -> 0.030320835 | AD7: ='OECD TTL - 2018'!X12 -> 1271 | AE7: ='OECD TTL - 2018'!Y12 -> 8.8 | AF7: ='OECD TTL - 2018'!Z12 -> 54.6 | AG7: ='OECD TTL - 2018'!AA12 -> 1.9 | AH7: ='OECD TTL - 2018'!AB12 -> 0.4 | AI7: ='OECD TTL - 2018'!AC12 -> 0.7 | AJ7: ='OECD TTL - 2018'!AD12 -> 0.1 | AK7: ='OECD TTL - 2018'!AE12 -> 5.3 | ... AR7: ='OECD TTL - 2018'!AL12 -> 0
