Workbook
Name asdf: #REF!
Name cpi_2010to2012: #REF!
Name cpi_2014to2012: #REF!
Name cpi_2019to2012: #REF!
Name cpi_2020to2012: #REF!
Name H2_kg_to_MMBtu: #REF!
Name kWh_to_Btu: #REF!

Sheet About
A1: BPPM Battery Pack Price Multiplier
A3: Sources: | B3: NLR
B4: 2024
B5: Transportation Annual Technology Baseline
B6: https://atb.nrel.gov/transportation/2024/index
B7: Data download
A9: Notes:
A10: We use data from NREL's ATB to apply a multiplier to freight LDV, HDV, and nonroad battery pack prices.

Sheet Transportation ATB
A1: Class Mapping | B1: Technology Mapping | C1: right | D1: scenario | E1: fuel_category | F1: fuel2_category | G1: vehicle_weight_category | H1: vehicle_class | I1: vehicle_powertrain | J1: vehicle_detail | K1: CS(mi/gge) | L1: CD(Wh/mi) | M1: ARB_contribution | N1: EPA55_contribution | O1: EPA65_contribution | P1: ARB_CS(mpgde) | Q1: EPA55_CS(mpgde) | R1: EPA65_CS(mpgde) | S1: ARB_CD(Wh/mi) | T1: EPA55_CD(Wh/mi) | U1: EPA65_CD(Wh/mi) | V1: range(mi) | W1: battery_cost($) | X1: pack_energy(kWh) | Y1: pack price in $/kWh | Z1: usable_energy(kWh) | AA1: fuel_cell_cost($/kW) | AB1: h2_storage_tank_cost($/kgh2) | AC1: vehicle_cost($) | AD1: non-battery cost | AE1: dollar_year | AF1: reference
A2: AEO car | B2: 100-mile electric vehicle | C2: 2023 | D2: Constant | E2: Electricity | G2: Light Duty | H2: Compact | I2: Battery Electric | J2: Battery Electric Vehicle (150-mile range) | K2: 139.9246611826366 | L2: 240.84389 | V2: 150 | W2: 4643.886309310859 | X2: 34.93552896000001 | AC2: 21900.725789825254 | AD2: 14934.896 | AE2: 2022 | AF2: ANL, Autonomie (2023)
A3: AEO car | B3: 100-mile electric vehicle | C3: 2025 | D3: Constant | E3: Electricity | G3: Light Duty | H3: Compact | I3: Battery Electric | J3: Battery Electric Vehicle (150-mile range) | K3: 139.9246611826366 | L3: 240.84389 | V3: 150 | W3: 4643.886309310859 | X3: 34.93552896000001 | AC3: 21900.725789825254 | AD3: 14934.896 | AE3: 2022 | AF3: ANL, Autonomie (2023)
A4: AEO car | B4: 100-mile electric vehicle | C4: 2030 | D4: Constant | E4: Electricity | G4: Light Duty | H4: Compact | I4: Battery Electric | J4: Battery Electric Vehicle (150-mile range) | K4: 139.9246611826366 | L4: 240.84389 | V4: 150 | W4: 4643.886309310859 | X4: 34.93552896000001 | AC4: 21900.725789825254 | AD4: 14934.896 | AE4: 2022 | AF4: ANL, Autonomie (2023)
A5: AEO car | B5: 100-mile electric vehicle | C5: 2035 | D5: Constant | E5: Electricity | G5: Light Duty | H5: Compact | I5: Battery Electric | J5: Battery Electric Vehicle (150-mile range) | K5: 139.9246611826366 | L5: 240.84389 | V5: 150 | W5: 4643.886309310859 | X5: 34.93552896000001 | AC5: 21900.725789825254 | AD5: 14934.896 | AE5: 2022 | AF5: ANL, Autonomie (2023)
A6: AEO car | B6: 100-mile electric vehicle | C6: 2040 | D6: Constant | E6: Electricity | G6: Light Duty | H6: Compact | I6: Battery Electric | J6: Battery Electric Vehicle (150-mile range) | K6: 139.9246611826366 | L6: 240.84389 | V6: 150 | W6: 4643.886309310859 | X6: 34.93552896000001 | AC6: 21900.725789825254 | AD6: 14934.896 | AE6: 2022 | AF6: ANL, Autonomie (2023)
A7: AEO car | B7: 100-mile electric vehicle | C7: 2045 | D7: Constant | E7: Electricity | G7: Light Duty | H7: Compact | I7: Battery Electric | J7: Battery Electric Vehicle (150-mile range) | K7: 139.9246611826366 | L7: 240.84389 | V7: 150 | W7: 4643.886309310859 | X7: 34.93552896000001 | AC7: 21900.725789825254 | AD7: 14934.896 | AE7: 2022 | AF7: ANL, Autonomie (2023)
A8: AEO car | B8: 100-mile electric vehicle | C8: 2050 | D8: Constant | E8: Electricity | G8: Light Duty | H8: Compact | I8: Battery Electric | J8: Battery Electric Vehicle (150-mile range) | K8: 139.9246611826366 | L8: 240.84389 | V8: 150 | W8: 4643.886309310859 | X8: 34.93552896000001 | AC8: 21900.725789825254 | AD8: 14934.896 | AE8: 2022 | AF8: ANL, Autonomie (2023)
A9: AEO car | B9: 100-mile electric vehicle | C9: 2023 | D9: Mid | E9: Electricity | G9: Light Duty | H9: Compact | I9: Battery Electric | J9: Battery Electric Vehicle (150-mile range) | K9: 139.9246611826366 | L9: 240.84389 | V9: 150 | W9: 4643.886309310859 | X9: 34.93552896000001 | AC9: 21900.725789825254 | AD9: 14934.896 | AE9: 2022 | AF9: ANL, Autonomie (2023)
A10: AEO car | B10: 100-mile electric vehicle | C10: 2025 | D10: Mid | E10: Electricity | G10: Light Duty | H10: Compact | I10: Battery Electric | J10: Battery Electric Vehicle (150-mile range) | K10: 151.2676191473047 | L10: 222.78397 | V10: 150 | W10: 3829.0716609024075 | X10: 31.754374 | Y10: =W10/X10 -> 120.58407 | AC10: 20172.67060307931 | AD10: 14429.063 | AE10: 2022 | AF10: ANL, Autonomie (2023)
A11: AEO car | B11: 100-mile electric vehicle | C11: 2030 | D11: Mid | E11: Electricity | G11: Light Duty | H11: Compact | I11: Battery Electric | J11: Battery Electric Vehicle (150-mile range) | K11: 151.2097401324258 | L11: 222.86924 | V11: 150 | W11: 3393.742978032179 | X11: 32.493766 | AC11: 19035.19251861687 | AD11: 13944.578 | AE11: 2022 | AF11: ANL, Autonomie (2023)
A12: AEO car | B12: 100-mile electric vehicle | C12: 2035 | D12: Mid | E12: Electricity | G12: Light Duty | H12: Compact | I12: Battery Electric | J12: Battery Electric Vehicle (150-mile range) | K12: 166.28705 | L12: 202.6616 | V12: 150 | W12: 2741.6400545586794 | X12: 28.875148 | AC12: 17762.88815035337 | AD12: 13650.428 | AE12: 2022 | AF12: ANL, Autonomie (2023)
A13: AEO car | B13: 100-mile electric vehicle | C13: 2040 | D13: Mid | E13: Electricity | G13: Light Duty | H13: Compact | I13: Battery Electric | J13: Battery Electric Vehicle (150-mile range) | K13: 171.65808 | L13: 196.69394523333332 | V13: 150 | W13: 2545.075877318017 | X13: 27.644345 | AC13: 17262.51173089452 | AD13: 13444.898 | AE13: 2022 | AF13: ANL, Autonomie (2023)
A14: AEO car | B14: 100-mile electric vehicle | C14: 2045 | D14: Mid | E14: Electricity | G14: Light Duty | H14: Compact | I14: Battery Electric | J14: Battery Electric Vehicle (150-mile range) | K14: 177.02911 | L14: 190.72628566666666 | V14: 150 | W14: 2348.511700077354 | X14: 26.413541 | AC14: 16762.135311435664 | AD14: 13239.368 | AE14: 2022 | AF14: ANL, Autonomie (2023)
A15: AEO car | B15: 100-mile electric vehicle | C15: 2050 | D15: Mid | E15: Electricity | G15: Light Duty | H15: Compact | I15: Battery Electric | J15: Battery Electric Vehicle (150-mile range) | K15: 182.40014 | L15: 184.75863 | V15: 150 | W15: 2151.9475228366914 | X15: 25.182738 | AC15: 16261.758891976811 | AD15: 13033.838 | AE15: 2022 | AF15: ANL, Autonomie (2023)
A16: AEO car | B16: 100-mile electric vehicle | C16: 2023 | D16: Advanced | E16: Electricity | G16: Light Duty | H16: Compact | I16: Battery Electric | J16: Battery Electric Vehicle (150-mile range) | K16: 151.6302803607349 | L16: 222.25112 | V16: 150 | W16: 3950.974919764476 | X16: 32.009191 | AC16: 20531.574372634237 | AD16: 14605.112 | AE16: 2022 | AF16: ANL, Autonomie (2023)
A17: AEO car | B17: 100-mile electric vehicle | C17: 2025 | D17: Advanced | E17: Electricity | G17: Light Duty | H17: Compact | I17: Battery Electric | J17: Battery Electric Vehicle (150-mile range) | K17: 159.3356596030735 | L17: 211.50319 | V17: 150 | W17: 2714.873154986781 | X17: 30.098144 | AC17: 18090.45905113763 | AD17: 14018.149 | AE17: 2022 | AF17: ANL, Autonomie (2023)
A18: AEO car | B18: 100-mile electric vehicle | C18: 2030 | D18: Advanced | E18: Electricity | G18: Light Duty | H18: Compact | I18: Battery Electric | J18: Battery Electric Vehicle (150-mile range) | K18: 166.4743813463727 | L18: 202.43355 | V18: 150 | W18: 2106.0387060578423 | X18: 29.574599 | AC18: 17487.538697520227 | AD18: 14328.481 | AE18: 2022 | AF18: ANL, Autonomie (2023)
A19: AEO car | B19: 100-mile electric vehicle | C19: 2035 | D19: Advanced | E19: Electricity | G19: Light Duty | H19: Compact | I19: Battery Electric | J19: Battery Electric Vehicle (150-mile range) | K19: 182.0623633491291 | L19: 185.10141 | V19: 150 | W19: 1805.9994615551582 | X19: 27.172735 | AC19: 16900.759518724077 | AD19: 14191.76 | AE19: 2022 | AF19: ANL, Autonomie (2023)
A20: AEO car | B20: 100-mile electric vehicle | C20: 2040 | D20: Advanced | E20: Electricity | G20: Light Duty | H20: Compact | I20: Battery Electric | J20: Battery Electric Vehicle (150-mile range) | K20: 191.21035872909945 | L20: 177.01904386666666 | V20: 150 | W20: 1626.0720327011654 | X20: 25.523984 | AC20: 16602.62252496681 | AD20: 14163.514 | AE20: 2022 | AF20: ANL, Autonomie (2023)
A21: AEO car | B21: 100-mile electric vehicle | C21: 2045 | D21: Advanced | E21: Electricity | G21: Light Duty | H21: Compact | I21: Battery Electric | J21: Battery Electric Vehicle (150-mile range) | K21: 200.35835410906984 | L21: 168.93667863333334 | V21: 150 | W21: 1446.144603847173 | X21: 23.875233 | AC21: 16304.48553120954 | AD21: 14135.269 | AE21: 2022 | AF21: ANL, Autonomie (2023)
A22: AEO car | B22: 100-mile electric vehicle | C22: 2050 | D22: Advanced | E22: Electricity | G22: Light Duty | H22: Compact | I22: Battery Electric | J22: Battery Electric Vehicle (150-mile range) | K22: 209.5063494890402 | L22: 160.85431 | V22: 150 | W22: 1266.2171749931802 | X22: 22.226482 | AC22: 16006.348537452273 | AD22: 14107.023 | AE22: 2022 | AF22: ANL, Autonomie (2023)
A23: AEO car | B23: 200-mile electric vehicle | C23: 2023 | D23: Constant | E23: Electricity | G23: Light Duty | H23: Compact | I23: Battery Electric | J23: Battery Electric Vehicle (200-mile range) | K23: 139.5219198613624 | L23: 241.53911 | V23: 200 | W23: 6136.6730352825725 | X23: 46.165626 | AC23: 24197.52001880242 | AD23: 14992.51 | AE23: 2022 | AF23: ANL, Autonomie (2023)
A24: AEO car | B24: 200-mile electric vehicle | C24: 2025 | D24: Constant | E24: Electricity | G24: Light Duty | H24: Compact | I24: Battery Electric | J24: Battery Electric Vehicle (200-mile range) | K24: 139.5219198613624 | L24: 241.53911 | V24: 200 | W24: 6136.6730352825725 | X24: 46.165626 | AC24: 24197.52001880242 | AD24: 14992.51 | AE24: 2022 | AF24: ANL, Autonomie (2023)
A25: AEO car | B25: 200-mile electric vehicle | C25: 2030 | D25: Constant | E25: Electricity | G25: Light Duty | H25: Compact | I25: Battery Electric | J25: Battery Electric Vehicle (200-mile range) | K25: 139.5219198613624 | L25: 241.53911 | V25: 200 | W25: 6136.6730352825725 | X25: 46.165626 | AC25: 24197.52001880242 | AD25: 14992.51 | AE25: 2022 | AF25: ANL, Autonomie (2023)
A26: AEO car | B26: 200-mile electric vehicle | C26: 2035 | D26: Constant | E26: Electricity | G26: Light Duty | H26: Compact | I26: Battery Electric | J26: Battery Electric Vehicle (200-mile range) | K26: 139.5219198613624 | L26: 241.53911 | V26: 200 | W26: 6136.6730352825725 | X26: 46.165626 | AC26: 24197.52001880242 | AD26: 14992.51 | AE26: 2022 | AF26: ANL, Autonomie (2023)
A27: AEO car | B27: 200-mile electric vehicle | C27: 2040 | D27: Constant | E27: Electricity | G27: Light Duty | H27: Compact | I27: Battery Electric | J27: Battery Electric Vehicle (200-mile range) | K27: 139.5219198613624 | L27: 241.53911 | V27: 200 | W27: 6136.6730352825725 | X27: 46.165626 | AC27: 24197.52001880242 | AD27: 14992.51 | AE27: 2022 | AF27: ANL, Autonomie (2023)
A28: AEO car | B28: 200-mile electric vehicle | C28: 2045 | D28: Constant | E28: Electricity | G28: Light Duty | H28: Compact | I28: Battery Electric | J28: Battery Electric Vehicle (200-mile range) | K28: 139.5219198613624 | L28: 241.53911 | V28: 200 | W28: 6136.6730352825725 | X28: 46.165626 | AC28: 24197.52001880242 | AD28: 14992.51 | AE28: 2022 | AF28: ANL, Autonomie (2023)
A29: AEO car | B29: 200-mile electric vehicle | C29: 2050 | D29: Constant | E29: Electricity | G29: Light Duty | H29: Compact | I29: Battery Electric | J29: Battery Electric Vehicle (200-mile range) | K29: 139.5219198613624 | L29: 241.53911 | V29: 200 | W29: 6136.6730352825725 | X29: 46.165626 | AC29: 24197.52001880242 | AD29: 14992.51 | AE29: 2022 | AF29: ANL, Autonomie (2023)
A30: AEO car | B30: 200-mile electric vehicle | C30: 2023 | D30: Mid | E30: Electricity | G30: Light Duty | H30: Compact | I30: Battery Electric | J30: Battery Electric Vehicle (200-mile range) | K30: 139.5219198613624 | L30: 241.53911 | V30: 200 | W30: 6136.6730352825725 | X30: 46.165626 | AC30: 24197.52001880242 | AD30: 14992.51 | AE30: 2022 | AF30: ANL, Autonomie (2023)
A31: AEO car | B31: 200-mile electric vehicle | C31: 2025 | D31: Mid | E31: Electricity | G31: Light Duty | H31: Compact | I31: Battery Electric | J31: Battery Electric Vehicle (200-mile range) | K31: 145.0081111147534 | L31: 232.40079 | V31: 200 | W31: 5355.004915799065 | X31: 44.408892 | Y31: =W31/X31 -> 120.58407 | AC31: 22519.787318263912 | AD31: 14487.28 | AE31: 2022 | AF31: ANL, Autonomie (2023)
A32: AEO car | B32: 200-mile electric vehicle | C32: 2030 | D32: Mid | E32: Electricity | G32: Light Duty | H32: Compact | I32: Battery Electric | J32: Battery Electric Vehicle (200-mile range) | K32: 150.8922451661433 | L32: 223.33818 | V32: 200 | W32: 4350.265125576863 | X32: 41.652092 | AC32: 20497.393061248054 | AD32: 13971.995 | AE32: 2022 | AF32: ANL, Autonomie (2023)
A33: AEO car | B33: 200-mile electric vehicle | C33: 2035 | D33: Mid | E33: Electricity | G33: Light Duty | H33: Compact | I33: Battery Electric | J33: Battery Electric Vehicle (200-mile range) | K33: 165.8409386458156 | L33: 203.20676 | V33: 200 | W33: 3742.2079801776335 | X33: 39.4132 | AC33: 19287.754430525893 | AD33: 13674.442 | AE33: 2022 | AF33: ANL, Autonomie (2023)
A34: AEO car | B34: 200-mile electric vehicle | C34: 2040 | D34: Mid | E34: Electricity | G34: Light Duty | H34: Compact | I34: Battery Electric | J34: Battery Electric Vehicle (200-mile range) | K34: 170.98321645766393 | L34: 197.44210913333333 | V34: 200 | W34: 3478.8479626071367 | X34: 37.79103 | AC34: 18680.086672549296 | AD34: 13461.815 | AE34: 2022 | AF34: ANL, Autonomie (2023)
A35: AEO car | B35: 200-mile electric vehicle | C35: 2045 | D35: Mid | E35: Electricity | G35: Light Duty | H35: Compact | I35: Battery Electric | J35: Battery Electric Vehicle (200-mile range) | K35: 176.12549426951227 | L35: 191.67745716666667 | V35: 200 | W35: 3215.4879450366398 | X35: 36.16886 | AC35: 18072.419 | AD35: 13249.187 | AE35: 2022 | AF35: ANL, Autonomie (2023)
A36: AEO car | B36: 200-mile electric vehicle | C36: 2050 | D36: Mid | E36: Electricity | G36: Light Duty | H36: Compact | I36: Battery Electric | J36: Battery Electric Vehicle (200-mile range) | K36: 181.2677720813606 | L36: 185.91281 | V36: 200 | W36: 2952.1279274661433 | X36: 34.54669 | AC36: 17464.751156596103 | AD36: 13036.559 | AE36: 2022 | AF36: ANL, Autonomie (2023)
A37: AEO car | B37: 200-mile electric vehicle | C37: 2023 | D37: Advanced | E37: Electricity | G37: Light Duty | H37: Compact | I37: Battery Electric | J37: Battery Electric Vehicle (200-mile range) | K37: 144.3224551683149 | L37: 233.5049 | V37: 200 | W37: 5482.283874288221 | X37: 44.415233 | AC37: 22888.185896537223 | AD37: 14664.76 | AE37: 2022 | AF37: ANL, Autonomie (2023)
A38: AEO car | B38: 200-mile electric vehicle | C38: 2025 | D38: Advanced | E38: Electricity | G38: Light Duty | H38: Compact | I38: Battery Electric | J38: Battery Electric Vehicle (200-mile range) | K38: 158.8143439466045 | L38: 212.19746 | V38: 200 | W38: 3689.405647424976 | X38: 40.902192 | AC38: 19570.699730333745 | AD38: 14036.591 | AE38: 2022 | AF38: ANL, Autonomie (2023)
A39: AEO car | B39: 200-mile electric vehicle | C39: 2030 | D39: Advanced | E39: Electricity | G39: Light Duty | H39: Compact | I39: Battery Electric | J39: Battery Electric Vehicle (200-mile range) | K39: 167.3073860227084 | L39: 201.42566 | V39: 200 | W39: 2768.6862222808654 | X39: 38.88 | AC39: 18493.988421668964 | AD39: 14340.959 | AE39: 2022 | AF39: ANL, Autonomie (2023)
A40: AEO car | B40: 200-mile electric vehicle | C40: 2035 | D40: Advanced | E40: Electricity | G40: Light Duty | H40: Compact | I40: Battery Electric | J40: Battery Electric Vehicle (200-mile range) | K40: 181.453 | L40: 185.72302 | V40: 200 | W40: 2342.030567952895 | X40: 35.23776 | AC40: 17711.616183274095 | AD40: 14198.57 | AE40: 2022 | AF40: ANL, Autonomie (2023)
...

Sheet HDV multiplier
A1: ATB data appear to use constant battery pack prices across the light-duty segment, and separately across the MDV/HDV segment.
A2: We find the ratio between midsize LDV $/kWh pack prices and class 7 $/kWh pack prices.
B4: 2023 | C4: 2025 | D4: 2030 | E4: 2035 | F4: 2040 | G4: 2045 | H4: 2050
A5: LDV | B5: ='Transportation ATB'!Y408 -> 132.92732 | C5: ='Transportation ATB'!Y409 -> 120.58407 | D5: ='Transportation ATB'!Y410 -> 104.4429 | E5: ='Transportation ATB'!Y411 -> 94.948087 | F5: ='Transportation ATB'!Y412 -> 92.12954 | G5: ='Transportation ATB'!Y413 -> 88.984656 | H5: ='Transportation ATB'!Y414 -> 85.453278
A6: MDV/HDV | B6: ='Transportation ATB'!Y3565 -> 332.31831 | C6: ='Transportation ATB'!Y3566 -> 265.85464 | D6: ='Transportation ATB'!Y3567 -> 189.89617 | E6: ='Transportation ATB'!Y3568 -> 151.91694 | F6: ='Transportation ATB'!Y3569 -> 131.21183 | G6: ='Transportation ATB'!Y3570 -> 109.10629 | H6: ='Transportation ATB'!Y3571 -> 85.453278
A7: Ratio | B7: =B6/B5 -> 2.5 | C7: =C6/C5 -> 2.2047244 | D7: =D6/D5 -> 1.8181818 | E7: =E6/E5 -> 1.6 | F7: =F6/F5 -> 1.4242102 | G7: =G6/G5 -> 1.2261248 | H7: =H6/H5 -> 1
B9: 2023 | C9: 2024 | D9: 2025 | E9: 2026 | F9: 2027 | G9: 2028 | H9: 2029 | I9: 2030 | J9: 2031 | K9: 2032 | L9: 2033 | M9: 2034 | N9: 2035 | O9: 2036 | P9: 2037 | Q9: 2038 | R9: 2039 | S9: 2040 | T9: 2041 | U9: 2042 | V9: 2043 | W9: 2044 | X9: 2045 | Y9: 2046 | Z9: 2047 | AA9: 2048 | AB9: 2049 | AC9: 2050
A10: Ratio Interpolated | B10: {=TREND($B$7:$C$7,$B$4:$C$4,B9)} -> 2.5 | C10: {=TREND($B$7:$C$7,$B$4:$C$4,C9)} -> 2.3523622 | D10: {=TREND($B$7:$C$7,$B$4:$C$4,D9)} -> 2.2047244 | E10: {=TREND($C$7:$D$7,$C$4:$D$4,E9)} -> 2.1274159 | F10: {=TREND($C$7:$D$7,$C$4:$D$4,F9)} -> 2.0501074 | G10: {=TREND($C$7:$D$7,$C$4:$D$4,G9)} -> 1.9727989 | H10: {=TREND($C$7:$D$7,$C$4:$D$4,H9)} -> 1.8954903 | I10: {=TREND($C$7:$D$7,$C$4:$D$4,I9)} -> 1.8181818 | J10: {=TREND($D$7:$E$7,$D$4:$E$4,J9)} -> 1.7745455 | K10: {=TREND($D$7:$E$7,$D$4:$E$4,K9)} -> 1.7309091 | L10: {=TREND($D$7:$E$7,$D$4:$E$4,L9)} -> 1.6872727 | M10: {=TREND($D$7:$E$7,$D$4:$E$4,M9)} -> 1.6436364 | N10: {=TREND($D$7:$E$7,$D$4:$E$4,N9)} -> 1.6 | O10: {=TREND($E$7:$F$7,$E$4:$F$4,O9)} -> 1.564842 | P10: {=TREND($E$7:$F$7,$E$4:$F$4,P9)} -> 1.5296841 | Q10: {=TREND($E$7:$F$7,$E$4:$F$4,Q9)} -> 1.4945261 | R10: {=TREND($E$7:$F$7,$E$4:$F$4,R9)} -> 1.4593681 | S10: {=TREND($E$7:$F$7,$E$4:$F$4,S9)} -> 1.4242102 | T10: {=TREND($F$7:$G$7,$F$4:$G$4,T9)} -> 1.3845931 | U10: {=TREND($F$7:$G$7,$F$4:$G$4,U9)} -> 1.344976 | V10: {=TREND($F$7:$G$7,$F$4:$G$4,V9)} -> 1.3053589 | W10: {=TREND($F$7:$G$7,$F$4:$G$4,W9)} -> 1.2657419 | X10: {=TREND($F$7:$G$7,$F$4:$G$4,X9)} -> 1.2261248 | Y10: {=TREND($G$7:$H$7,$G$4:$H$4,Y9)} -> 1.1808998 | Z10: {=TREND($G$7:$H$7,$G$4:$H$4,Z9)} -> 1.1356749 | AA10: {=TREND($G$7:$H$7,$G$4:$H$4,AA9)} -> 1.0904499 | AB10: {=TREND($G$7:$H$7,$G$4:$H$4,AB9)} -> 1.045225 | AC10: {=TREND($G$7:$H$7,$G$4:$H$4,AC9)} -> 1

Sheet BPPM-psgr
A1: $/kWh | B1: 2021 | C1: 2022 | D1: 2023 | E1: 2024 | F1: 2025 | G1: 2026 | H1: 2027 | I1: 2028 | J1: 2029 | K1: 2030 | L1: 2031 | M1: 2032 | N1: 2033 | O1: 2034 | P1: 2035 | Q1: 2036 | R1: 2037 | S1: 2038 | T1: 2039 | U1: 2040 | V1: 2041 | W1: 2042 | X1: 2043 | Y1: 2044 | Z1: 2045 | AA1: 2046 | AB1: 2047 | AC1: 2048 | AD1: 2049 | AE1: 2050 | AF1: 2051 | AG1: 2052 | AH1: 2053 | AI1: 2054 | AJ1: 2055 | AK1: 2056 | AL1: 2057 | AM1: 2058 | AN1: 2059 | AO1: 2060 | AP1: 2061 | AQ1: 2062 | AR1: 2063 | AS1: 2064 | AT1: 2065 | AU1: 2066 | AV1: 2067 | AW1: 2068 | AX1: 2069 | AY1: 2070
A2: LDVs | B2: =C2 -> 1 | C2: =D2 -> 1 | D2: =E2 -> 1 | E2: 1 | F2: 1 | G2: 1 | H2: 1 | I2: 1 | J2: 1 | K2: 1 | L2: 1 | M2: 1 | N2: 1 | O2: 1 | P2: 1 | Q2: 1 | R2: 1 | S2: 1 | T2: 1 | U2: 1 | V2: 1 | W2: 1 | X2: 1 | Y2: 1 | Z2: 1 | AA2: 1 | AB2: 1 | AC2: 1 | AD2: 1 | AE2: 1 | AF2: =AE2 -> 1 | AG2: =AF2 -> 1 | AH2: =AG2 -> 1 | AI2: =AH2 -> 1 | AJ2: =AI2 -> 1 | AK2: =AJ2 -> 1 | AL2: =AK2 -> 1 | AM2: =AL2 -> 1 | ... AY2: =AX2 -> 1
A3: HDVs | B3: =C3 -> 2.3523622 | C3: =D3 -> 2.3523622 | D3: =E3 -> 2.3523622 | E3: ='HDV multiplier'!C10 -> 2.3523622 | F3: ='HDV multiplier'!D10 -> 2.2047244 | G3: ='HDV multiplier'!E10 -> 2.1274159 | H3: ='HDV multiplier'!F10 -> 2.0501074 | I3: ='HDV multiplier'!G10 -> 1.9727989 | J3: ='HDV multiplier'!H10 -> 1.8954903 | K3: ='HDV multiplier'!I10 -> 1.8181818 | L3: ='HDV multiplier'!J10 -> 1.7745455 | ... AE3: ='HDV multiplier'!AC10 -> 1 | AF3: =AE3 -> 1 | AG3: =AF3 -> 1 | AH3: =AG3 -> 1 | AI3: =AH3 -> 1 | AJ3: =AI3 -> 1 | AK3: =AJ3 -> 1 | AL3: =AK3 -> 1 | AM3: =AL3 -> 1 | ... AY3: =AX3 -> 1
A4: aircraft | B4: =C4 -> 2.3523622 | C4: =D4 -> 2.3523622 | D4: =E4 -> 2.3523622 | E4: =E3 -> 2.3523622 | F4: =F3 -> 2.2047244 | G4: =G3 -> 2.1274159 | H4: =H3 -> 2.0501074 | I4: =I3 -> 1.9727989 | J4: =J3 -> 1.8954903 | K4: =K3 -> 1.8181818 | L4: =L3 -> 1.7745455 | ... AE4: =AE3 -> 1 | AF4: =AE4 -> 1 | AG4: =AF4 -> 1 | AH4: =AG4 -> 1 | AI4: =AH4 -> 1 | AJ4: =AI4 -> 1 | AK4: =AJ4 -> 1 | AL4: =AK4 -> 1 | AM4: =AL4 -> 1 | ... AY4: =AX4 -> 1
A5: rail | B5: =C5 -> 2.3523622 | C5: =D5 -> 2.3523622 | D5: =E5 -> 2.3523622 | E5: =E4 -> 2.3523622 | F5: =F4 -> 2.2047244 | G5: =G4 -> 2.1274159 | H5: =H4 -> 2.0501074 | I5: =I4 -> 1.9727989 | J5: =J4 -> 1.8954903 | K5: =K4 -> 1.8181818 | L5: =L4 -> 1.7745455 | ... AE5: =AE4 -> 1 | AF5: =AE5 -> 1 | AG5: =AF5 -> 1 | AH5: =AG5 -> 1 | AI5: =AH5 -> 1 | AJ5: =AI5 -> 1 | AK5: =AJ5 -> 1 | AL5: =AK5 -> 1 | AM5: =AL5 -> 1 | ... AY5: =AX5 -> 1
A6: ships | B6: =C6 -> 2.3523622 | C6: =D6 -> 2.3523622 | D6: =E6 -> 2.3523622 | E6: =E5 -> 2.3523622 | F6: =F5 -> 2.2047244 | G6: =G5 -> 2.1274159 | H6: =H5 -> 2.0501074 | I6: =I5 -> 1.9727989 | J6: =J5 -> 1.8954903 | K6: =K5 -> 1.8181818 | L6: =L5 -> 1.7745455 | ... AE6: =AE5 -> 1 | AF6: =AE6 -> 1 | AG6: =AF6 -> 1 | AH6: =AG6 -> 1 | AI6: =AH6 -> 1 | AJ6: =AI6 -> 1 | AK6: =AJ6 -> 1 | AL6: =AK6 -> 1 | AM6: =AL6 -> 1 | ... AY6: =AX6 -> 1
A7: motorbikes | B7: =C7 -> 1 | C7: =D7 -> 1 | D7: =E7 -> 1 | E7: =E2 -> 1 | F7: =F2 -> 1 | G7: =G2 -> 1 | H7: =H2 -> 1 | I7: =I2 -> 1 | J7: =J2 -> 1 | K7: =K2 -> 1 | L7: =L2 -> 1 | ... AE7: =AE2 -> 1 | AF7: =AE7 -> 1 | AG7: =AF7 -> 1 | AH7: =AG7 -> 1 | AI7: =AH7 -> 1 | AJ7: =AI7 -> 1 | AK7: =AJ7 -> 1 | AL7: =AK7 -> 1 | AM7: =AL7 -> 1 | ... AY7: =AX7 -> 1

Sheet BPPM-frgt
A1: $/kWh | B1: 2021 | C1: 2022 | D1: 2023 | E1: 2024 | F1: 2025 | G1: 2026 | H1: 2027 | I1: 2028 | J1: 2029 | K1: 2030 | L1: 2031 | M1: 2032 | N1: 2033 | O1: 2034 | P1: 2035 | Q1: 2036 | R1: 2037 | S1: 2038 | T1: 2039 | U1: 2040 | V1: 2041 | W1: 2042 | X1: 2043 | Y1: 2044 | Z1: 2045 | AA1: 2046 | AB1: 2047 | AC1: 2048 | AD1: 2049 | AE1: 2050 | AF1: 2051 | AG1: 2052 | AH1: 2053 | AI1: 2054 | AJ1: 2055 | AK1: 2056 | AL1: 2057 | AM1: 2058 | AN1: 2059 | AO1: 2060 | AP1: 2061 | AQ1: 2062 | AR1: 2063 | AS1: 2064 | AT1: 2065 | AU1: 2066 | AV1: 2067 | AW1: 2068 | AX1: 2069 | AY1: 2070
A2: LDVs | B2: =C2 -> 2.3523622 | C2: =D2 -> 2.3523622 | D2: =E2 -> 2.3523622 | E2: =E3 -> 2.3523622 | F2: =F3 -> 2.2047244 | G2: =G3 -> 2.1274159 | H2: =H3 -> 2.0501074 | I2: =I3 -> 1.9727989 | J2: =J3 -> 1.8954903 | K2: =K3 -> 1.8181818 | L2: =L3 -> 1.7745455 | ... AE2: =AE3 -> 1 | AF2: =AE2 -> 1 | AG2: =AF2 -> 1 | AH2: =AG2 -> 1 | AI2: =AH2 -> 1 | AJ2: =AI2 -> 1 | AK2: =AJ2 -> 1 | AL2: =AK2 -> 1 | AM2: =AL2 -> 1 | ... AY2: =AX2 -> 1
A3: HDVs | B3: =C3 -> 2.3523622 | C3: =D3 -> 2.3523622 | D3: =E3 -> 2.3523622 | E3: ='HDV multiplier'!C10 -> 2.3523622 | F3: ='HDV multiplier'!D10 -> 2.2047244 | G3: ='HDV multiplier'!E10 -> 2.1274159 | H3: ='HDV multiplier'!F10 -> 2.0501074 | I3: ='HDV multiplier'!G10 -> 1.9727989 | J3: ='HDV multiplier'!H10 -> 1.8954903 | K3: ='HDV multiplier'!I10 -> 1.8181818 | L3: ='HDV multiplier'!J10 -> 1.7745455 | ... AE3: ='HDV multiplier'!AC10 -> 1 | AF3: =AE3 -> 1 | AG3: =AF3 -> 1 | AH3: =AG3 -> 1 | AI3: =AH3 -> 1 | AJ3: =AI3 -> 1 | AK3: =AJ3 -> 1 | AL3: =AK3 -> 1 | AM3: =AL3 -> 1 | ... AY3: =AX3 -> 1
A4: aircraft | B4: =C4 -> 2.3523622 | C4: =D4 -> 2.3523622 | D4: =E4 -> 2.3523622 | E4: =E3 -> 2.3523622 | F4: =F3 -> 2.2047244 | G4: =G3 -> 2.1274159 | H4: =H3 -> 2.0501074 | I4: =I3 -> 1.9727989 | J4: =J3 -> 1.8954903 | K4: =K3 -> 1.8181818 | L4: =L3 -> 1.7745455 | ... AE4: =AE3 -> 1 | AF4: =AE4 -> 1 | AG4: =AF4 -> 1 | AH4: =AG4 -> 1 | AI4: =AH4 -> 1 | AJ4: =AI4 -> 1 | AK4: =AJ4 -> 1 | AL4: =AK4 -> 1 | AM4: =AL4 -> 1 | ... AY4: =AX4 -> 1
A5: rail | B5: =C5 -> 2.3523622 | C5: =D5 -> 2.3523622 | D5: =E5 -> 2.3523622 | E5: =E4 -> 2.3523622 | F5: =F4 -> 2.2047244 | G5: =G4 -> 2.1274159 | H5: =H4 -> 2.0501074 | I5: =I4 -> 1.9727989 | J5: =J4 -> 1.8954903 | K5: =K4 -> 1.8181818 | L5: =L4 -> 1.7745455 | ... AE5: =AE4 -> 1 | AF5: =AE5 -> 1 | AG5: =AF5 -> 1 | AH5: =AG5 -> 1 | AI5: =AH5 -> 1 | AJ5: =AI5 -> 1 | AK5: =AJ5 -> 1 | AL5: =AK5 -> 1 | AM5: =AL5 -> 1 | ... AY5: =AX5 -> 1
A6: ships | B6: =C6 -> 2.3523622 | C6: =D6 -> 2.3523622 | D6: =E6 -> 2.3523622 | E6: =E5 -> 2.3523622 | F6: =F5 -> 2.2047244 | G6: =G5 -> 2.1274159 | H6: =H5 -> 2.0501074 | I6: =I5 -> 1.9727989 | J6: =J5 -> 1.8954903 | K6: =K5 -> 1.8181818 | L6: =L5 -> 1.7745455 | ... AE6: =AE5 -> 1 | AF6: =AE6 -> 1 | AG6: =AF6 -> 1 | AH6: =AG6 -> 1 | AI6: =AH6 -> 1 | AJ6: =AI6 -> 1 | AK6: =AJ6 -> 1 | AL6: =AK6 -> 1 | AM6: =AL6 -> 1 | ... AY6: =AX6 -> 1
A7: motorbikes | B7: =C7 -> 2.3523622 | C7: =D7 -> 2.3523622 | D7: =E7 -> 2.3523622 | E7: =E2 -> 2.3523622 | F7: =F2 -> 2.2047244 | G7: =G2 -> 2.1274159 | H7: =H2 -> 2.0501074 | I7: =I2 -> 1.9727989 | J7: =J2 -> 1.8954903 | K7: =K2 -> 1.8181818 | L7: =L2 -> 1.7745455 | ... AE7: =AE2 -> 1 | AF7: =AE7 -> 1 | AG7: =AF7 -> 1 | AH7: =AG7 -> 1 | AI7: =AH7 -> 1 | AJ7: =AI7 -> 1 | AK7: =AJ7 -> 1 | AL7: =AK7 -> 1 | AM7: =AL7 -> 1 | ... AY7: =AX7 -> 1
