Workbook
Name Fraction_coal: [1]About!#REF!
Name gal_per_barrel: [2]About!$A$63
Name Percent_rural: [1]About!#REF!
Name Percent_urban: [1]About!#REF!
Name quadrillion: [1]About!$B$62
Name Table4: #REF!
Name Table4_1: #REF!
Name Table4_A: #REF!
Name Table5: #REF!
Name Table5_1: #REF!
Name Table5_A: #REF!
Name UrbFrac: '[3]MX urban Rural'!$B$3

Sheet About
A1: BFPIaE BAU Fuel Production
A2: BFPIaE BAU Fuel Imports
A3: BFPIaE BAU Fuel Exports
A5: Source: | B5: Petroleum-based fuels, biofuels | F5: National Energy Balance
B6: U.S. Energy Information Administration | F6: Sistema de Información Energética
B7: 2019 | F7: Secretaría de Energía
B8: Petroleum & Other Liquids: Supply and Disposition | F8: Dirección General de Planeación e Información Energéticas
B9: https://www.eia.gov/dnav/pet/pet_sum_snd_d_nus_mbbl_a_cur.htm | F9: Balance Nacional de Energía: Origen y destino de la energía
B10: Area: US, Period: Annual 2017 | F10: (petajoules)
F11: REALES 2019
B12: Nuclear Fuel (Uranium) | F12: https://www.gob.mx/sener/articulos/balance-nacional-de-energia-296106
B13: U.S. Energy Information Administration
B14: 2018
B15: U.S. uranium imports continue as domestic production remains at historical lows
B16: https://www.eia.gov/todayinenergy/detail.php?id=37192
B17: Paragraph 1
B19: Hard Coal, Lignite
B20: U.S. Energy Information Administration
B21: 2019
B22: Coal Explained: Where Our Coal Comes From
B23: https://www.eia.gov/energyexplained/index.php?page=coal_where
B24: https://www.eia.gov/energyexplained/index.php?page=coal_imports
B25: https://www.eia.gov/energyexplained/index.php?page=coal_prices
B27: Biomass Production and Exports
B28: U.S. Energy Information Administration
B29: 2017
B30: Monthly Densified Biomass Fuel Report
B31: https://www.eia.gov/biofuels/biomass/?year=2016&month=13#table_data
B32: Tables 4 and 8
B34: Biomass Imports and Exports (for Import to Export Ratio)
B35: U.S. International Trade Administration
B36: 2017
B37: 2016 Top Markets Report Renewable Fuels Sector Snapshot: Biomass Wood Pellets
B38: https://www.trade.gov/topmarkets/pdf/Renewable_Fuels_Biomass_Wood_Pellets.pdf
B39: Tables 2 and 3a
B41: Natural Gas, Time Series Scaling Factors
B42: U.S. Energy Information Administration
B43: 2019
B44: Annual Energy Outlook 2019
B45: https://www.eia.gov/outlooks/aeo/tables_ref.php
...

Sheet Petroleum and Biofuel Data
A1: Area: US | B1: Period: 2017 (Annual) | D1: Unit: Thousand Barrels
B2: Supply | H2: Disposition | L2: Ending Stocks
B3: Field Production | C3: Renewable Fuels & Oxygenate Plant Net Production | D3: Refinery & Blender Net Production | E3: Imports | F3: Net Receipts | G3: Adjust- ments | H3: Stock Change | I3: Refinery & Blender Net Inputs | J3: Exports | K3: Products Supplied
A4: Crude Oil & Petroleum Products | B4: 4794078 | C4: 437131 | D4: 7408771 | E4: 3702640 | G4: 137262 | H4: -135002 | I4: 7003159 | J4: 2327156 | K4: 7284569 | L4: 1894570
A5: Crude Oil | B5: 3413376 | C5: - - | D5: - - | E5: 2908670 | G5: 60486 | H5: -95227 | I5: 6055241 | J5: 422518 | K5: 0 | L5: 1084477
A6: Hydrocarbon Gas Liquids | B6: 1380702 | C6: -7942 | D6: 229391 | E6: 71427 | G6: - - | H6: -10191 | I6: 206629 | J6: 512495 | K6: 964645 | L6: 190004
A7: Natural Gas Liquids | B7: 1380702 | C7: -7942 | D7: 127270 | E7: 60585 | G7: - - | H7: -6640 | I7: 206629 | J7: 512495 | K7: 848131 | L7: 184131
A8: Ethane | B8: 520504 | C8: - - | D8: 1958 | E8: - | G8: - - | H8: 4925 | J8: 64822 | K8: 452715 | L8: 55616
A9: Propane | B9: 451133 | C9: - - | D9: 111964 | E9: 48606 | G9: - - | H9: -14864 | J9: 333544 | K9: 293023 | L9: 62183
A10: Normal Butane | B10: 115086 | C10: - - | D10: 15710 | E10: 5504 | G10: - - | H10: 7939 | I10: 64779 | J10: 49568 | K10: 14014 | L10: 37821
A11: Isobutane | B11: 128589 | C11: - - | D11: -2362 | E11: 3735 | G11: - - | H11: 292 | I11: 77360 | J11: 1321 | K11: 50989 | L11: 8398
A12: Natural Gasoline | B12: 165390 | C12: -7942 | E12: 2740 | G12: - - | H12: -4932 | I12: 64490 | J12: 63240 | K12: 37390 | L12: 20113
A13: Refinery Olefins | B13: - - | C13: - - | D13: 102121 | E13: 10842 | G13: - - | H13: -3551 | I13: - - | J13: - - | K13: 116514 | L13: 5873
A14: Ethylene | B14: - - | C14: - - | D14: 270 | E14: - | G14: - - | H14: 0 | I14: - - | J14: - - | K14: 270 | L14: 0
A15: Propylene | B15: - - | C15: - - | D15: 103962 | E15: 8409 | G15: - - | H15: -2392 | I15: - - | J15: - - | K15: 114763 | L15: 4639
A16: Normal Butylene | B16: - - | C16: - - | D16: -2397 | E16: 2433 | G16: - - | H16: -1165 | I16: - - | J16: - - | K16: 1201 | L16: 1204
A17: Isobutylene | B17: - - | C17: - - | D17: 286 | E17: - | G17: - - | H17: 6 | I17: - - | J17: - - | K17: 280 | L17: 30
A18: Other Liquids | B18: - - | C18: 443737 | D18: - - | E18: 471784 | G18: 19117 | H18: 8685 | I18: 741289 | J18: 171592 | K18: 13072 | L18: 328230
A19: Hydrogen/Oxygenates/Renewables/Other Hydrocarbons | B19: - - | C19: 443788 | D19: - - | E19: 19778 | G19: 36824 | H19: 577 | I19: 439078 | J19: 60735 | K19: 0 | L19: 29585
A20: Hydrogen | B20: - - | C20: - - | D20: - - | G20: 81091 | H20: - - | I20: 81091 | K20: 0 | L20: - -
A21: Oxygenates (excl. Fuel Ethanol) | B21: - - | C21: 26360 | D21: - - | E21: 3835 | G21: -4811 | H21: -31 | I21: - | J21: 25415 | K21: 0 | L21: 1446
A22: Renewable Fuels (incl. Fuel Ethanol) | B22: - - | C22: 417428 | D22: - - | E22: 15707 | G22: -39640 | H22: 578 | I22: 357597 | J22: 35320 | K22: 0 | L22: 28092
A23: Fuel Ethanol | B23: - - | C23: 379435 | D23: - - | E23: 1824 | G23: -9859 | H23: 3285 | I23: 335023 | J23: 33092 | K23: 0 | L23: 23043
A24: Renewable Fuels Except Fuel Ethanol | B24: - - | C24: 37993 | D24: - - | E24: 13883 | G24: -29781 | H24: -2707 | I24: 22574 | J24: 2228 | K24: 0 | L24: 5049
A25: Other Hydrocarbons | B25: - - | C25: - - | D25: - - | E25: 236 | G25: 184 | H25: 30 | I25: 390 | K25: 0 | L25: 47
A26: Unfinished Oils | B26: - - | C26: - - | D26: - - | E26: 231478 | G26: - - | H26: 6013 | I26: 129406 | J26: 82949 | K26: 13110 | L26: 86337
A27: Motor Gasoline Blend. Comp. | B27: - - | C27: -51 | D27: - - | E27: 220528 | G27: -17707 | H27: 2089 | I27: 172773 | J27: 27908 | K27: 0 | L27: 212293
A28: Reformulated | B28: - - | C28: -3 | D28: - - | E28: 76948 | G28: 65150 | H28: 1299 | I28: 140697 | J28: 99 | K28: 0 | L28: 53447
A29: Conventional | B29: - - | C29: -48 | D29: - - | E29: 143580 | G29: -82856 | H29: 790 | I29: 32076 | J29: 27810 | K29: 0 | L29: 158846
A30: Aviation Gasoline Blend. Comp. | B30: - - | C30: - - | D30: - - | E30: - | G30: - - | H30: 6 | I30: 32 | J30: - | K30: -38 | L30: 15
A31: Finished Petroleum Products | B31: - - | C31: 1336 | D31: 7179380 | E31: 250759 | G31: 57659 | H31: -38269 | I31: - - | J31: 1220551 | K31: 6306852 | L31: 291859
A32: Finished Motor Gasoline | B32: - - | C32: 1336 | D32: 3633123 | E32: 11784 | G32: 27566 | H32: -3860 | I32: - - | J32: 273483 | K32: 3404186 | L32: 24523
A33: Reformulated | B33: - - | D33: 1187104 | E33: - | G33: -59342 | H33: -7 | I33: - - | J33: - | K33: 1127769 | L33: 40
A34: Conventional | B34: - - | C34: 1336 | D34: 2446019 | E34: 11784 | G34: 86908 | H34: -3853 | I34: - - | J34: 273483 | K34: 2276417 | L34: 24483
A35: Finished Aviation Gasoline | B35: - - | C35: - - | D35: 4032 | E35: 165 | G35: - - | H35: 47 | I35: - - | J35: - | K35: 4150 | L35: 1041
A36: Kerosene-Type Jet Fuel | B36: - - | C36: - - | D36: 621176 | E36: 58273 | G36: - - | H36: -1706 | I36: - - | J36: 67161 | K36: 613994 | L36: 41304
A37: Kerosene | B37: - - | C37: - - | D37: 2738 | E37: 1429 | G37: - - | H37: 10 | I37: - - | J37: 2267 | K37: 1890 | L37: 2138
A38: Distillate Fuel Oil | B38: - - | C38: - - | D38: 1833879 | E38: 54975 | G38: 30093 | H38: -20457 | I38: - - | J38: 504155 | K38: 1435249 | L38: 145638
A39: 15 ppm Sulfur and Under | B39: - - | C39: - - | D39: 1713652 | E39: 37012 | G39: 30093 | H39: -16256 | I39: - - | J39: 423862 | K39: 1373151 | L39: 128016
A40: Greater than 15 to 500 ppm Sulfur | B40: - - | C40: - - | D40: 42167 | E40: 759 | G40: - | H40: -929 | I40: - - | J40: 41645 | K40: 2210 | L40: 7480
...

Sheet Biomass Data
A1: Table 4. Production of densified biomass fuel, 2016 (tons)
A2: Region | B2: Month | C2: Wood Pellets, PFI Certified | D2: Wood Pellets, Not Certified | E2: Wood Pellets Utility | F2: Compressed Bricks/Logs
A3: U.S. Total
B4: 1 | C4: 95844 | D4: 79371 | E4: 421133 | F4: 1659
B5: 2 | C5: 65410 | D5: 63962 | E5: 388199 | F5: 1748
B6: 3 | C6: 60828 | D6: 49392 | E6: 413882 | F6: 1705
B7: 4 | C7: 63815 | D7: 45622 | E7: 419029 | F7: 1660
B8: 5 | C8: 72872 | D8: 62962 | E8: 447352 | F8: 1371
B9: 6 | C9: 63971 | D9: 69622 | E9: 425459 | F9: 2299
B10: 7 | C10: 66862 | D10: 56530 | E10: 473065 | F10: 2052
B11: 8 | C11: 81078 | D11: 77052 | E11: 427549 | F11: 2080
B12: 9 | C12: 78422 | D12: 77769 | E12: 425587 | F12: 1552
B13: 10 | C13: 78390 | D13: 70137 | E13: 445045 | F13: 1484
B14: 11 | C14: 59704 | D14: 69068 | E14: 470151 | F14: 992
B15: 12 | C15: 58607 | D15: 58819 | E15: 509468 | F15: 1208
A17: Table 8. Export sales and average price of densified biomass fuel, 2016
A18: Month | B18: Quantity (tons) | C18: Average Price (USD per ton)
A19: 1 | B19: 318480 | C19: 151.07
A20: 2 | B20: 432018 | C20: 145.75
A21: 3 | B21: 459937 | C21: 148.58
A22: 4 | B22: 317594 | C22: 155.75
A23: 5 | B23: 417765 | C23: 148.33
A24: 6 | B24: 538584 | C24: 147.9
A25: 7 | B25: 257482 | C25: 166.17
A26: 8 | B26: 391653 | C26: 149.42
A27: 9 | B27: 457496 | C27: 153.16
A28: 10 | B28: 400054 | C28: 129.94
A29: 11 | B29: 340954 | C29: 144.92
A30: 12 | B30: 495630 | C30: 144.99
A32: Total wood pellet production
A33: =SUM(C4:E15) -> 6892028 | B33: tons
A35: Total wood pellet exports
A36: =SUM(B19:B30) -> 4827647 | B36: tons
A38: We don't have biomass import data from EIA, but we do have some from the International Trade Administration (trade.gov).
A39: It uses different units and shows much higher wood pellet quantities than the EIA data, and it lacks production data.
A40: Accordingly, we only use it to establish a ratio of exports to imports, and apply that ratio to the EIA export data to
A41: estimate wood pellet imports (which are small compared to exports).
B43: Imports | C43: Exports | D43: Unit
A44: 2015 | B44: 207171527 | C44: 4668774792 | D44: kg
A46: Import to Export Ratio
...

Sheet Uranium, Coal, MSW, Hydrogen
A1: Uranium
B2: Production | C2: Imports | D2: Exports | E2: Unit
A3: 2017 | B3: 3 | C3: 40 | D3: 0 | E3: million pounds U3O8
A5: Hard Coal and Lignite
A6: 0.09 | B6: of U.S. coal production was lignite in 2017
A7: 775 | B7: million short tons of coal produced (of all types) in 2017
A8: 97 | B8: million short tons of coal exported in 2017
A9: 6 | B9: million short tons of coal imported in 2017
A10: We assume that all imported and exported coal was hard coal, while all lignite produced was used domestically.
B12: Production | C12: Imports | D12: Exports | E12: Unit
A13: Hard Coal | B13: =A7*(1-A6) -> 705.25 | C13: =A9 -> 6 | D13: =A8 -> 97 | E13: million short tons
A14: Lignite | B14: =A6*A7 -> 69.75 | C14: 0 | D14: 0 | E14: million short tons
A16: Municipal Solid Waste
A17: MSW Tonnage Data for Year 2015
A18: 262.4 | B18: U.S. MSW generated (million tons)
A19: 33.57 | B19: U.S. MSW burned with energy recovery (million tons)
A20: 67.8 | B20: U.S. MSW recycled (million tons)
A21: 23.4 | B21: U.S. MSW composted (million tons)
A22: 137.7 | B22: U.S. MSW landfilled (million tons)
A24: Although the U.S. exports waste to other countries,
A25: it is difficult to find statistics for waste exports other than plastic waste.
A26: (Plastic waste exports to other countries in 2018 were
A27: 1.07 million metric tons in 2018.) | D27: https://www.plasticpollutioncoalition.org/pft/2019/3/6/157000-shipping-containers-of-us-plastic-waste-exported-to-countries-with-poor-waste-management-in-2018
A30: In this model, we are only concerned about MSW that is burned as a
A31: fuel. We will assume that a negligible amount of exported waste
A32: is used as a fuel.
A34: Hydrogen
A35: 10 | B35: million metric tons
A36: produced in 2018
A38: We assume none was imported or exported.

Sheet AEO Table 1
B1: highogs.d112619a | C1: 2019 | D1: 2020 | E1: 2021 | F1: 2022 | G1: 2023 | H1: 2024 | I1: 2025 | J1: 2026 | K1: 2027 | L1: 2028 | M1: 2029 | N1: 2030 | O1: 2031 | P1: 2032 | Q1: 2033 | R1: 2034 | S1: 2035 | T1: 2036 | U1: 2037 | V1: 2038 | W1: 2039 | X1: 2040 | Y1: 2041 | Z1: 2042 | AA1: 2043 | AB1: 2044 | AC1: 2045 | AD1: 2046 | AE1: 2047 | AF1: 2048 | AG1: 2049 | AH1: 2050
C3: Report | D3: Annual Energy Outlook 2020
C4: Scenario | D4: highogs | G4: High oil and gas supply
C5: Datekey | D5: d112619a
C6: Release Date | E6: January 2020
A10: SUP000 | B10: 1. Total Energy Supply, Disposition, and Price Summary
B11: (quadrillion Btu, unless otherwise noted)
AI12: 2019-
B13: Supply, Disposition, and Prices | C13: 2019 | D13: 2020 | E13: 2021 | F13: 2022 | G13: 2023 | H13: 2024 | I13: 2025 | J13: 2026 | K13: 2027 | L13: 2028 | M13: 2029 | N13: 2030 | O13: 2031 | P13: 2032 | Q13: 2033 | R13: 2034 | S13: 2035 | T13: 2036 | U13: 2037 | V13: 2038 | W13: 2039 | X13: 2040 | Y13: 2041 | Z13: 2042 | AA13: 2043 | AB13: 2044 | AC13: 2045 | AD13: 2046 | AE13: 2047 | AF13: 2048 | AG13: 2049 | AH13: 2050 | AI13: 2050
B15: Production
A16: SUP000:ba_CrudeOilLease | B16: Crude Oil and Lease Condensate | C16: 25.609802 | D16: 29.02322 | E16: 32.153172 | F16: 34.069309 | G16: 34.946575 | H16: 35.786289 | I16: 36.260719 | J16: 36.787514 | K16: 37.048611 | L16: 37.295334 | M16: 37.478222 | N16: 37.728161 | O16: 38.161762 | P16: 38.435223 | Q16: 38.808941 | R16: 38.440941 | S16: 38.606178 | T16: 38.570507 | U16: 38.509876 | V16: 38.289101 | W16: 38.237984 | X16: 38.24062 | Y16: 38.236805 | Z16: 38.273491 | AA16: 38.000069 | AB16: 37.980083 | AC16: 38.048946 | AD16: 38.124599 | AE16: 38.372814 | AF16: 38.755627 | AG16: 39.242901 | AH16: 39.56263 | AI16: 0.014128
A17: SUP000:ba_NaturalGasPla | B17: Natural Gas Plant Liquids | C17: 6.601902 | D17: 7.687216 | E17: 8.268795 | F17: 9.085635 | G17: 9.154001 | H17: 9.280481 | I17: 9.382998 | J17: 9.632951 | K17: 9.888704 | L17: 10.018386 | M17: 10.108791 | N17: 10.070297 | O17: 10.089097 | P17: 10.12474 | Q17: 10.179479 | R17: 10.167198 | S17: 10.201029 | T17: 10.205934 | U17: 10.177264 | V17: 10.230554 | W17: 10.229934 | X17: 10.224058 | Y17: 10.182619 | Z17: 10.205435 | AA17: 10.201748 | AB17: 10.166046 | AC17: 10.195329 | AD17: 10.23309 | AE17: 10.288787 | AF17: 10.369956 | AG17: 10.475321 | AH17: 10.553595 | AI17: 0.015248
A18: SUP000:ba_DryNaturalGas | B18: Dry Natural Gas | C18: 35.698853 | D18: 36.461613 | E18: 38.399319 | F18: 39.064152 | G18: 39.540783 | H18: 40.186932 | I18: 41.594856 | J18: 42.991825 | K18: 43.837154 | L18: 44.673092 | M18: 45.265652 | N18: 45.577869 | O18: 46.066223 | P18: 46.707607 | Q18: 47.376926 | R18: 47.925549 | S18: 48.427116 | T18: 49.248726 | U18: 49.617588 | V18: 50.274464 | W18: 50.788734 | X18: 51.329384 | Y18: 51.800266 | Z18: 52.29541 | AA18: 52.754333 | AB18: 53.282814 | AC18: 53.71896 | AD18: 54.344379 | AE18: 54.812981 | AF18: 55.301308 | AG18: 55.799816 | AH18: 56.345497 | AI18: 0.014831
A19: SUP000:ba_Coal | B19: Coal 1/ | C19: 13.570377 | D19: 12.323533 | E19: 11.59661 | F19: 11.398017 | G19: 10.785779 | H19: 10.465207 | I19: 9.428184 | J19: 9.61118 | K19: 9.565367 | L19: 9.448417 | M19: 9.282607 | N19: 9.118553 | O19: 9.030849 | P19: 9.008224 | Q19: 8.995221 | R19: 8.990909 | S19: 8.880076 | T19: 8.872306 | U19: 8.865554 | V19: 8.824455 | W19: 8.782435 | X19: 8.69428 | Y19: 8.630263 | Z19: 8.598111 | AA19: 8.579282 | AB19: 8.54311 | AC19: 8.502932 | AD19: 8.50601 | AE19: 8.48208 | AF19: 8.45368 | AG19: 8.459153 | AH19: 8.432384 | AI19: -0.015231
A20: SUP000:ba_NuclearPower | B20: Nuclear / Uranium 2/ | C20: 8.444346 | D20: 8.293446 | E20: 8.156399 | F20: 8.00432 | G20: 8.028068 | H20: 8.059065 | I20: 7.91081 | J20: 6.578477 | K20: 6.110461 | L20: 6.114827 | M20: 6.119108 | N20: 5.934624 | O20: 5.842663 | P20: 5.775915 | Q20: 5.617176 | R20: 5.362936 | S20: 5.377634 | T20: 4.883077 | U20: 4.885286 | V20: 4.510839 | W20: 4.330963 | X20: 4.33457 | Y20: 4.347668 | Z20: 4.273965 | AA20: 4.200269 | AB20: 4.048344 | AC20: 3.984968 | AD20: 3.918423 | AE20: 3.922881 | AF20: 3.925656 | AG20: 3.929009 | AH20: 3.933857 | AI20: -0.02434
A21: SUP000:ba_Hydropower | B21: Conventional Hydroelectric Power | C21: 2.62724 | D21: 2.630024 | E21: 2.608772 | F21: 2.555373 | G21: 2.500631 | H21: 2.447045 | I21: 2.414509 | J21: 2.335763 | K21: 2.301766 | L21: 2.286823 | M21: 2.274183 | N21: 2.265188 | O21: 2.258272 | P21: 2.247759 | Q21: 2.242433 | R21: 2.237327 | S21: 2.234227 | T21: 2.225456 | U21: 2.210283 | V21: 2.210092 | W21: 2.194727 | X21: 2.188682 | Y21: 2.171035 | Z21: 2.163268 | AA21: 2.149309 | AB21: 2.155904 | AC21: 2.147812 | AD21: 2.14894 | AE21: 2.147149 | AF21: 2.149729 | AG21: 2.138394 | AH21: 2.13362 | AI21: -0.006691
A22: SUP000:ba_Biomass | B22: Biomass 3/ | C22: 4.82518 | D22: 4.766847 | E22: 4.82663 | F22: 4.891224 | G22: 4.918721 | H22: 4.950122 | I22: 4.980151 | J22: 5.007463 | K22: 5.044035 | L22: 5.080586 | M22: 5.106367 | N22: 5.128502 | O22: 5.144773 | P22: 5.152127 | Q22: 5.16701 | R22: 5.174049 | S22: 5.189386 | T22: 5.204069 | U22: 5.213857 | V22: 5.227988 | W22: 5.239909 | X22: 5.257756 | Y22: 5.283101 | Z22: 5.29576 | AA22: 5.319311 | AB22: 5.350887 | AC22: 5.378565 | AD22: 5.424164 | AE22: 5.462148 | AF22: 5.500999 | AG22: 5.546075 | AH22: 5.598709 | AI22: 0.004808
A23: SUP000:ba_RenewableEner | B23: Other Renewable Energy 4/ | C23: 3.98661 | D23: 4.494395 | E23: 5.065486 | F23: 5.872777 | G23: 6.29326 | H23: 6.385596 | I23: 6.742633 | J23: 6.775188 | K23: 6.839761 | L23: 6.913706 | M23: 7.030445 | N23: 7.305614 | O23: 7.369681 | P23: 7.379068 | Q23: 7.407632 | R23: 7.451074 | S23: 7.710938 | T23: 7.802966 | U23: 7.833769 | V23: 7.879764 | W23: 7.930049 | X23: 7.981818 | Y23: 8.045572 | Z23: 8.143557 | AA23: 8.303351 | AB23: 8.493343 | AC23: 8.690237 | AD23: 8.881924 | AE23: 9.096939 | AF23: 9.320292 | AG23: 9.595012 | AH23: 9.894312 | AI23: 0.029757
A24: SUP000:ba_Other | B24: Other 5/ | C24: 1.418818 | D24: 0.77089 | E24: 0.736356 | F24: 0.77303 | G24: 0.854863 | H24: 0.881459 | I24: 0.815687 | J24: 0.66516 | K24: 0.622542 | L24: 0.637312 | M24: 0.628271 | N24: 0.584811 | O24: 0.578334 | P24: 0.588707 | Q24: 0.567073 | R24: 0.580399 | S24: 0.578376 | T24: 0.572439 | U24: 0.595171 | V24: 0.595104 | W24: 0.595701 | X24: 0.590376 | Y24: 0.600907 | Z24: 0.597535 | AA24: 0.601193 | AB24: 0.603373 | AC24: 0.607764 | AD24: 0.608229 | AE24: 0.612571 | AF24: 0.614231 | AG24: 0.617509 | AH24: 0.612761 | AI24: -0.026721
A25: SUP000:ba_Total | B25: Total | C25: 102.78312 | D25: 106.45117 | E25: 111.81154 | F25: 115.71384 | G25: 117.02268 | H25: 118.44222 | I25: 119.53055 | J25: 120.38552 | K25: 121.25841 | L25: 122.46849 | M25: 123.29364 | N25: 123.71362 | O25: 124.54166 | P25: 125.41937 | Q25: 126.36188 | R25: 126.33038 | S25: 127.20496 | T25: 127.58548 | U25: 127.90865 | V25: 128.04236 | W25: 128.33043 | X25: 128.84155 | Y25: 129.29825 | Z25: 129.84653 | AA25: 130.10887 | AB25: 130.6239 | AC25: 131.27551 | AD25: 132.18977 | AE25: 133.19835 | AF25: 134.39149 | AG25: 135.80318 | AH25: 137.06737 | AI25: 0.009329
B27: Imports
A28: SUP000:ca_CrudeOil | B28: Crude Oil | C28: 15.557913 | D28: 14.53161 | E28: 10.839822 | F28: 9.283045 | G28: 9.711083 | H28: 9.396487 | I28: 8.376527 | J28: 8.779516 | K28: 8.26525 | L28: 7.740358 | M28: 7.331103 | N28: 5.658647 | O28: 5.515424 | P28: 5.242305 | Q28: 4.703898 | R28: 5.036331 | S28: 5.039837 | T28: 4.886359 | U28: 5.357675 | V28: 5.245924 | W28: 5.107249 | X28: 5.233577 | Y28: 5.783911 | Z28: 5.680748 | AA28: 5.922231 | AB28: 5.976051 | AC28: 5.866432 | AD28: 5.936519 | AE28: 5.963267 | AF28: 5.832415 | AG28: 6.03104 | AH28: 5.868403 | AI28: -0.030962
A29: SUP000:ca_PetroleumProd | B29: Petroleum and Other Liquids 6/ | C29: 4.818967 | D29: 4.202692 | E29: 4.255038 | F29: 4.344409 | G29: 4.310221 | H29: 4.204672 | I29: 4.051309 | J29: 3.73584 | K29: 3.758186 | L29: 3.626599 | M29: 3.472314 | N29: 3.533805 | O29: 3.499255 | P29: 3.403134 | Q29: 3.427885 | R29: 3.436105 | S29: 3.391357 | T29: 3.327733 | U29: 3.427994 | V29: 3.385025 | W29: 3.394435 | X29: 3.420483 | Y29: 3.419091 | Z29: 3.424332 | AA29: 3.42945 | AB29: 3.433667 | AC29: 3.463475 | AD29: 3.521511 | AE29: 3.534636 | AF29: 3.576368 | AG29: 3.644244 | AH29: 3.693158 | AI29: -0.008546
A30: SUP000:ca_NaturalGas | B30: Natural Gas | C30: 2.79107 | D30: 2.72174 | E30: 2.397942 | F30: 2.310857 | G30: 2.205464 | H30: 2.171041 | I30: 2.251062 | J30: 2.344378 | K30: 2.18932 | L30: 1.897442 | M30: 1.81331 | N30: 1.769985 | O30: 1.839804 | P30: 1.766449 | Q30: 1.596209 | R30: 1.557857 | S30: 1.522343 | T30: 1.501905 | U30: 1.505041 | V30: 1.486304 | W30: 1.46496 | X30: 1.443362 | Y30: 1.435708 | Z30: 1.394784 | AA30: 1.341333 | AB30: 1.28926 | AC30: 1.263642 | AD30: 1.222849 | AE30: 1.183778 | AF30: 1.151181 | AG30: 1.138505 | AH30: 1.106201 | AI30: -0.029413
A31: SUP000:ca_OtherImports | B31: Other 7/ | C31: 0.291597 | D31: 0.311465 | E31: 0.198491 | F31: 0.188917 | G31: 0.184921 | H31: 0.188236 | I31: 0.177557 | J31: 0.183053 | K31: 0.197399 | L31: 0.203696 | M31: 0.201345 | N31: 0.209987 | O31: 0.201656 | P31: 0.210156 | Q31: 0.210358 | R31: 0.21874 | S31: 0.21698 | T31: 0.212136 | U31: 0.210972 | V31: 0.209018 | W31: 0.209871 | X31: 0.208984 | Y31: 0.210388 | Z31: 0.208157 | AA31: 0.206515 | AB31: 0.203912 | AC31: 0.201447 | AD31: 0.199199 | AE31: 0.19695 | AF31: 0.196395 | AG31: 0.194942 | AH31: 0.191452 | AI31: -0.01348
A32: SUP000:ca_Total | B32: Total | C32: 23.459549 | D32: 21.767506 | E32: 17.691294 | F32: 16.127226 | G32: 16.41169 | H32: 15.960435 | I32: 14.856455 | J32: 15.042787 | K32: 14.410155 | L32: 13.468095 | M32: 12.818072 | N32: 11.172423 | O32: 11.056138 | P32: 10.622044 | Q32: 9.938349 | R32: 10.249033 | S32: 10.170517 | T32: 9.928134 | U32: 10.501682 | V32: 10.326272 | W32: 10.176515 | X32: 10.306406 | Y32: 10.849097 | Z32: 10.70802 | AA32: 10.899529 | AB32: 10.902891 | AC32: 10.794995 | AD32: 10.880077 | AE32: 10.878632 | AF32: 10.756359 | AG32: 11.00873 | AH32: 10.859214 | AI32: -0.024541
B34: Exports
A35: SUP000:da_Petroleum | B35: Petroleum and Other Liquids 8/ | C35: 16.699137 | D35: 19.67774 | E35: 19.813248 | F35: 21.186703 | G35: 22.677301 | H35: 23.574001 | I35: 23.217295 | J35: 24.092285 | K35: 24.293886 | L35: 24.191198 | M35: 24.077267 | N35: 22.821302 | O35: 23.160934 | P35: 23.184769 | Q35: 23.166058 | R35: 23.190947 | S35: 23.408087 | T35: 23.194202 | U35: 23.611103 | V35: 23.30299 | W35: 23.079035 | X35: 23.200663 | Y35: 23.616289 | Z35: 23.485144 | AA35: 23.346128 | AB35: 23.194836 | AC35: 23.039408 | AD35: 22.963045 | AE35: 23.076998 | AF35: 23.139055 | AG35: 23.632502 | AH35: 23.532877 | AI35: 0.011127
A36: SUP000:da_NaturalGas | B36: Natural Gas | C36: 4.483331 | D36: 5.390441 | E36: 6.29525 | F36: 6.659064 | G36: 6.864997 | H36: 7.378416 | I36: 8.329083 | J36: 9.202188 | K36: 9.561375 | L36: 9.921309 | M36: 10.159161 | N36: 10.409156 | O36: 10.643183 | P36: 10.902959 | Q36: 11.031044 | R36: 11.16286 | S36: 11.386827 | T36: 11.532694 | U36: 11.53221 | V36: 11.555552 | W36: 11.577884 | X36: 11.721876 | Y36: 11.812589 | Z36: 11.835786 | AA36: 11.857625 | AB36: 11.900509 | AC36: 11.898772 | AD36: 11.921367 | AE36: 11.949547 | AF36: 12.009178 | AG36: 12.025288 | AH36: 12.043931 | AI36: 0.032391
A37: SUP000:da_Coal | B37: Coal | C37: 2.384845 | D37: 2.087335 | E37: 2.21891 | F37: 2.73313 | G37: 2.749026 | H37: 2.765525 | I37: 2.784021 | J37: 2.799102 | K37: 2.796579 | L37: 2.754004 | M37: 2.701591 | N37: 2.662022 | O37: 2.659713 | P37: 2.660605 | Q37: 2.658387 | R37: 2.657806 | S37: 2.707269 | T37: 2.700574 | U37: 2.700053 | V37: 2.699575 | W37: 2.699134 | X37: 2.69873 | Y37: 2.698362 | Z37: 2.698028 | AA37: 2.697726 | AB37: 2.705911 | AC37: 2.705754 | AD37: 2.705624 | AE37: 2.705523 | AF37: 2.696648 | AG37: 2.705398 | AH37: 2.705374 | AI37: 0.004076
A38: SUP000:da_Total | B38: Total | C38: 23.567314 | D38: 27.155516 | E38: 28.327408 | F38: 30.578896 | G38: 32.291325 | H38: 33.717941 | I38: 34.330399 | J38: 36.093575 | K38: 36.65184 | L38: 36.866508 | M38: 36.938019 | N38: 35.892479 | O38: 36.463829 | P38: 36.748333 | Q38: 36.855488 | R38: 37.011612 | S38: 37.502182 | T38: 37.427471 | U38: 37.843369 | V38: 37.558117 | W38: 37.356052 | X38: 37.621269 | Y38: 38.127239 | Z38: 38.018959 | AA38: 37.901482 | AB38: 37.801254 | AC38: 37.643932 | AD38: 37.590034 | AE38: 37.732067 | AF38: 37.844879 | AG38: 38.36319 | AH38: 38.282185 | AI38: 0.015772
A40: SUP000:ea_Discrepancy | B40: Discrepancy 9/ | C40: 2.669487 | D40: 0.957136 | E40: 0.29143 | F40: 0.221487 | G40: 0.189823 | H40: 0.076195 | I40: 0.048325 | J40: 0.102432 | K40: 0.048897 | L40: 0.081345 | M40: 0.069302 | N40: 0.093658 | O40: 0.043777 | P40: 0.034935 | Q40: 0.018368 | R40: 0.023247 | S40: 0.037964 | T40: 0.013191 | U40: 0.09399 | V40: 0.109951 | W40: 0.113277 | X40: 0.077209 | Y40: 0.088421 | Z40: 0.078701 | AA40: 0.11026 | AB40: 0.098335 | AC40: 0.067657 | AD40: 0.048908 | AE40: 0.092388 | AF40: 0.042515 | AG40: 0.015648 | AH40: -0.014767 | AI40: - -
B42: Consumption
A43: SUP000:fa_PetroleumProd | B43: Petroleum and Other Liquids 10/ | C43: 38.036598 | D43: 38.249081 | E43: 38.338688 | F43: 38.386181 | G43: 38.289234 | H43: 38.002949 | I43: 37.750813 | J43: 37.561947 | K43: 37.416737 | L43: 37.273754 | M43: 37.124798 | N43: 36.995697 | O43: 36.933586 | P43: 36.857891 | Q43: 36.808525 | R43: 36.746334 | S43: 36.693485 | T43: 36.683826 | U43: 36.740818 | V43: 36.744766 | W43: 36.804943 | X43: 36.866257 | Y43: 36.954792 | Z43: 37.06773 | AA43: 37.188457 | AB43: 37.365673 | AC43: 37.576744 | AD43: 37.924442 | AE43: 38.174854 | AF43: 38.506775 | AG43: 38.902462 | AH43: 39.312489 | AI43: 0.001065
A44: SUP000:fa_NaturalGas | B44: Natural Gas | C44: 32.145264 | D44: 32.737129 | E44: 33.949142 | F44: 34.150421 | G44: 34.379078 | H44: 34.568253 | I44: 35.093334 | J44: 35.69463 | K44: 36.01915 | L44: 36.170952 | M44: 36.428425 | N44: 36.37265 | O44: 36.745525 | P44: 37.066868 | Q44: 37.421097 | R44: 37.808136 | S44: 38.033005 | T44: 38.68364 | U44: 39.013336 | V44: 39.599762 | W44: 40.054459 | X44: 40.432426 | Y44: 40.813301 | Z44: 41.232796 | AA44: 41.579891 | AB44: 42.008537 | AC44: 42.425045 | AD44: 42.982323 | AE44: 43.330105 | AF44: 43.763386 | AG44: 44.238911 | AH44: 44.742081 | AI44: 0.010723
A45: SUP000:fa_Coal | B45: Coal 11/ | C45: 11.259031 | D45: 10.280395 | E45: 9.333065 | F45: 8.622534 | G45: 8.002261 | H45: 7.662528 | I45: 6.605392 | J45: 6.773781 | K45: 6.734324 | L45: 6.658014 | M45: 6.544596 | N45: 6.423348 | O45: 6.334036 | P45: 6.312187 | Q45: 6.300232 | R45: 6.297875 | S45: 6.135948 | T45: 6.138631 | U45: 6.129973 | V45: 6.088452 | W45: 6.047576 | X45: 5.958601 | Y45: 5.893947 | Z45: 5.861347 | AA45: 5.84467 | AB45: 5.801578 | AC45: 5.760871 | AD45: 5.764395 | AE45: 5.739917 | AF45: 5.721745 | AG45: 5.718521 | AH45: 5.689028 | AI45: -0.02178
A46: SUP000:fa_NuclearPower | B46: Nuclear / Uranium 2/ | C46: 8.444346 | D46: 8.293446 | E46: 8.156399 | F46: 8.00432 | G46: 8.028068 | H46: 8.059065 | I46: 7.91081 | J46: 6.578477 | K46: 6.110461 | L46: 6.114827 | M46: 6.119108 | N46: 5.934624 | O46: 5.842663 | P46: 5.775915 | Q46: 5.617176 | R46: 5.362936 | S46: 5.377634 | T46: 4.883077 | U46: 4.885286 | V46: 4.510839 | W46: 4.330963 | X46: 4.33457 | Y46: 4.347668 | Z46: 4.273965 | AA46: 4.200269 | AB46: 4.048344 | AC46: 3.984968 | AD46: 3.918423 | AE46: 3.922881 | AF46: 3.925656 | AG46: 3.929009 | AH46: 3.933857 | AI46: -0.02434
A47: SUP000:fa_Hydropower | B47: Conventional Hydroelectric Power | C47: 2.62724 | D47: 2.630024 | E47: 2.608772 | F47: 2.555373 | G47: 2.500631 | H47: 2.447045 | I47: 2.414509 | J47: 2.335763 | K47: 2.301766 | L47: 2.286823 | M47: 2.274183 | N47: 2.265188 | O47: 2.258272 | P47: 2.247759 | Q47: 2.242433 | R47: 2.237327 | S47: 2.234227 | T47: 2.225456 | U47: 2.210283 | V47: 2.210092 | W47: 2.194727 | X47: 2.188682 | Y47: 2.171035 | Z47: 2.163268 | AA47: 2.149309 | AB47: 2.155904 | AC47: 2.147812 | AD47: 2.14894 | AE47: 2.147149 | AF47: 2.149729 | AG47: 2.138394 | AH47: 2.13362 | AI47: -0.006691
A48: SUP000:fa_Biomass | B48: Biomass 12/ | C48: 3.225383 | D48: 3.098976 | E48: 3.124981 | F48: 3.156809 | G48: 3.174736 | H48: 3.189423 | I48: 3.20948 | J48: 3.226856 | K48: 3.24636 | L48: 3.264666 | M48: 3.279681 | N48: 3.290752 | O48: 3.303107 | P48: 3.306364 | Q48: 3.317096 | R48: 3.319901 | S48: 3.330778 | T48: 3.340802 | U48: 3.345825 | V48: 3.355098 | W48: 3.362056 | X48: 3.374875 | Y48: 3.39137 | Z48: 3.402288 | AA48: 3.420014 | AB48: 3.445644 | AC48: 3.467393 | AD48: 3.507087 | AE48: 3.538946 | AF48: 3.571927 | AG48: 3.61107 | AH48: 3.65761 | AI48: 0.004065
A49: SUP000:fa_RenewableEner | B49: Other Renewable Energy 4/ | C49: 3.98661 | D49: 4.494395 | E49: 5.065486 | F49: 5.872777 | G49: 6.29326 | H49: 6.385596 | I49: 6.742633 | J49: 6.775188 | K49: 6.839761 | L49: 6.913706 | M49: 7.030445 | N49: 7.305614 | O49: 7.369681 | P49: 7.379068 | Q49: 7.407632 | R49: 7.451074 | S49: 7.710938 | T49: 7.802966 | U49: 7.833769 | V49: 7.879764 | W49: 7.930049 | X49: 7.981818 | Y49: 8.045572 | Z49: 8.143557 | AA49: 8.303351 | AB49: 8.493343 | AC49: 8.690237 | AD49: 8.881924 | AE49: 9.096939 | AF49: 9.320292 | AG49: 9.595012 | AH49: 9.894312 | AI49: 0.029757
...

Sheet AEO Table 73
B1: ref2021.d113020a | C1: 2020 | D1: 2021 | E1: 2022 | F1: 2023 | G1: 2024 | H1: 2025 | I1: 2026 | J1: 2027 | K1: 2028 | L1: 2029 | M1: 2030 | N1: 2031 | O1: 2032 | P1: 2033 | Q1: 2034 | R1: 2035 | S1: 2036 | T1: 2037 | U1: 2038 | V1: 2039 | W1: 2040 | X1: 2041 | Y1: 2042 | Z1: 2043 | AA1: 2044 | AB1: 2045 | AC1: 2046 | AD1: 2047 | AE1: 2048 | AF1: 2049 | AG1: 2050
C3: Report | D3: Annual Energy Outlook 2021
C4: Scenario | D4: ref2021 | G4: Reference case
C5: Datekey | D5: d113020a
C6: Release Date | E6: January 2021
A10: CNV000 | B10: 71. Conversion Factors | AH10: Compound
B11: (from physical units to million Btu) | AH11: Growth
AH12: 2020-2050
C13: 2020 | D13: 2021 | E13: 2022 | F13: 2023 | G13: 2024 | H13: 2025 | I13: 2026 | J13: 2027 | K13: 2028 | L13: 2029 | M13: 2030 | N13: 2031 | O13: 2032 | P13: 2033 | Q13: 2034 | R13: 2035 | S13: 2036 | T13: 2037 | U13: 2038 | V13: 2039 | W13: 2040 | X13: 2041 | Y13: 2042 | Z13: 2043 | AA13: 2044 | AB13: 2045 | AC13: 2046 | AD13: 2047 | AE13: 2048 | AF13: 2049 | AG13: 2050 | AH13: (percent)
B14: Petroleum and Other Liquids
B15: (million Btu per barrel)
A16: CNV000:aa_AsphaltandRoa | B16: Asphalt and Road Oil | C16: 6.636 | D16: 6.636 | E16: 6.636 | F16: 6.636 | G16: 6.636 | H16: 6.636 | I16: 6.636 | J16: 6.636 | K16: 6.636 | L16: 6.636 | M16: 6.636 | N16: 6.636 | O16: 6.636 | P16: 6.636 | Q16: 6.636 | R16: 6.636 | S16: 6.636 | T16: 6.636 | U16: 6.636 | V16: 6.636 | W16: 6.636 | X16: 6.636 | Y16: 6.636 | Z16: 6.636 | AA16: 6.636 | AB16: 6.636 | AC16: 6.636 | AD16: 6.636 | AE16: 6.636 | AF16: 6.636 | AG16: 6.636 | AH16: 0
A17: CNV000:aa_AviationGasol | B17: Aviation Gasoline | C17: 5.048 | D17: 5.048 | E17: 5.048 | F17: 5.048 | G17: 5.048 | H17: 5.048 | I17: 5.048 | J17: 5.048 | K17: 5.048 | L17: 5.048 | M17: 5.048 | N17: 5.048 | O17: 5.048 | P17: 5.048 | Q17: 5.048 | R17: 5.048 | S17: 5.048 | T17: 5.048 | U17: 5.048 | V17: 5.048 | W17: 5.048 | X17: 5.048 | Y17: 5.048 | Z17: 5.048 | AA17: 5.048 | AB17: 5.048 | AC17: 5.048 | AD17: 5.048 | AE17: 5.048 | AF17: 5.048 | AG17: 5.048 | AH17: 0
A18: CNV000:ea_Biodiesel | B18: Biodiesel | C18: 5.359 | D18: 5.359 | E18: 5.359 | F18: 5.359 | G18: 5.359 | H18: 5.359 | I18: 5.359 | J18: 5.359 | K18: 5.359 | L18: 5.359 | M18: 5.359 | N18: 5.359 | O18: 5.359 | P18: 5.359 | Q18: 5.359 | R18: 5.359 | S18: 5.359 | T18: 5.359 | U18: 5.359 | V18: 5.359 | W18: 5.359 | X18: 5.359 | Y18: 5.359 | Z18: 5.359 | AA18: 5.359 | AB18: 5.359 | AC18: 5.359 | AD18: 5.359 | AE18: 5.359 | AF18: 5.359 | AG18: 5.359 | AH18: 0
A19: CNV000:aa_Distillate | B19: Distillate Fuel Oil | C19: 5.825 | D19: 5.825 | E19: 5.825 | F19: 5.825 | G19: 5.825 | H19: 5.825 | I19: 5.825 | J19: 5.825 | K19: 5.825 | L19: 5.825 | M19: 5.825 | N19: 5.825 | O19: 5.825 | P19: 5.825 | Q19: 5.825 | R19: 5.825 | S19: 5.825 | T19: 5.825 | U19: 5.825 | V19: 5.825 | W19: 5.825 | X19: 5.825 | Y19: 5.825 | Z19: 5.825 | AA19: 5.825 | AB19: 5.825 | AC19: 5.825 | AD19: 5.825 | AE19: 5.825 | AF19: 5.825 | AG19: 5.825 | AH19: 0
A20: CNV000:aa_Residential | B20: Residential | C20: 5.772225 | D20: 5.770434 | E20: 5.769468 | F20: 5.769597 | G20: 5.770083 | H20: 5.769742 | I20: 5.769996 | J20: 5.770608 | K20: 5.769846 | L20: 5.770197 | M20: 5.76971 | N20: 5.7698 | O20: 5.769487 | P20: 5.769598 | Q20: 5.769436 | R20: 5.769614 | S20: 5.770103 | T20: 5.769971 | U20: 5.770141 | V20: 5.769869 | W20: 5.770143 | X20: 5.770298 | Y20: 5.770511 | Z20: 5.770051 | AA20: 5.769538 | AB20: 5.769256 | AC20: 5.770041 | AD20: 5.769023 | AE20: 5.768785 | AF20: 5.768611 | AG20: 5.768018 | AH20: -2.4e-05
A21: CNV000:aa_Commercial | B21: Commercial | C21: 5.772225 | D21: 5.770434 | E21: 5.769468 | F21: 5.769597 | G21: 5.770083 | H21: 5.769742 | I21: 5.769996 | J21: 5.770608 | K21: 5.769846 | L21: 5.770197 | M21: 5.76971 | N21: 5.7698 | O21: 5.769487 | P21: 5.769598 | Q21: 5.769436 | R21: 5.769614 | S21: 5.770103 | T21: 5.769971 | U21: 5.770141 | V21: 5.769869 | W21: 5.770143 | X21: 5.770298 | Y21: 5.770511 | Z21: 5.770051 | AA21: 5.769538 | AB21: 5.769256 | AC21: 5.770041 | AD21: 5.769023 | AE21: 5.768785 | AF21: 5.768611 | AG21: 5.768018 | AH21: -2.4e-05
A22: CNV000:aa_Transportatio | B22: Transportation | C22: 5.772225 | D22: 5.770434 | E22: 5.769468 | F22: 5.769597 | G22: 5.770083 | H22: 5.769742 | I22: 5.769996 | J22: 5.770608 | K22: 5.769846 | L22: 5.770197 | M22: 5.76971 | N22: 5.7698 | O22: 5.769487 | P22: 5.769598 | Q22: 5.769436 | R22: 5.769614 | S22: 5.770103 | T22: 5.769971 | U22: 5.770141 | V22: 5.769869 | W22: 5.770143 | X22: 5.770298 | Y22: 5.770511 | Z22: 5.770051 | AA22: 5.769538 | AB22: 5.769256 | AC22: 5.770041 | AD22: 5.769023 | AE22: 5.768785 | AF22: 5.768611 | AG22: 5.768018 | AH22: -2.4e-05
A23: CNV000:aa_Industrial | B23: Industrial | C23: 5.772225 | D23: 5.770434 | E23: 5.769468 | F23: 5.769597 | G23: 5.770083 | H23: 5.769742 | I23: 5.769996 | J23: 5.770608 | K23: 5.769846 | L23: 5.770197 | M23: 5.76971 | N23: 5.7698 | O23: 5.769487 | P23: 5.769598 | Q23: 5.769436 | R23: 5.769614 | S23: 5.770103 | T23: 5.769971 | U23: 5.770141 | V23: 5.769869 | W23: 5.770143 | X23: 5.770298 | Y23: 5.770511 | Z23: 5.770051 | AA23: 5.769538 | AB23: 5.769256 | AC23: 5.770041 | AD23: 5.769023 | AE23: 5.768785 | AF23: 5.768611 | AG23: 5.768018 | AH23: -2.4e-05
A24: CNV000:aa_ElectricPower | B24: Electric Power | C24: 5.772225 | D24: 5.770434 | E24: 5.769468 | F24: 5.769597 | G24: 5.770083 | H24: 5.769742 | I24: 5.769996 | J24: 5.770608 | K24: 5.769846 | L24: 5.770197 | M24: 5.76971 | N24: 5.7698 | O24: 5.769487 | P24: 5.769598 | Q24: 5.769436 | R24: 5.769614 | S24: 5.770103 | T24: 5.769971 | U24: 5.770141 | V24: 5.769869 | W24: 5.770143 | X24: 5.770298 | Y24: 5.770511 | Z24: 5.770051 | AA24: 5.769538 | AB24: 5.769256 | AC24: 5.770041 | AD24: 5.769023 | AE24: 5.768785 | AF24: 5.768611 | AG24: 5.768018 | AH24: -2.4e-05
A25: CNV000:aa_TotalDistilla | B25: Total Distillate | C25: 5.772226 | D25: 5.770434 | E25: 5.769468 | F25: 5.769597 | G25: 5.770083 | H25: 5.769742 | I25: 5.769997 | J25: 5.770607 | K25: 5.769845 | L25: 5.770196 | M25: 5.76971 | N25: 5.7698 | O25: 5.769487 | P25: 5.769598 | Q25: 5.769436 | R25: 5.769614 | S25: 5.770103 | T25: 5.769971 | U25: 5.770141 | V25: 5.769869 | W25: 5.770143 | X25: 5.770298 | Y25: 5.770511 | Z25: 5.770051 | AA25: 5.769537 | AB25: 5.769256 | AC25: 5.770042 | AD25: 5.769023 | AE25: 5.768785 | AF25: 5.768611 | AG25: 5.768018 | AH25: -2.4e-05
A26: CNV000:aa_DistLowSulf | B26: Distillate Fuel Oil - Low Sulfur Diesel | C26: 5.817 | D26: 5.817 | E26: 5.817 | F26: 5.817 | G26: 5.817 | H26: 5.817 | I26: 5.817 | J26: 5.817 | K26: 5.817 | L26: 5.817 | M26: 5.817 | N26: 5.817 | O26: 5.817 | P26: 5.817 | Q26: 5.817 | R26: 5.817 | S26: 5.817 | T26: 5.817 | U26: 5.817 | V26: 5.817 | W26: 5.817 | X26: 5.817 | Y26: 5.817 | Z26: 5.817 | AA26: 5.817 | AB26: 5.817 | AC26: 5.817 | AD26: 5.817 | AE26: 5.817 | AF26: 5.817 | AG26: 5.817 | AH26: 0
A27: CNV000:aa_DistUltraLow | B27: Distillate Fuel Oil - Ultra Low Sulfur Diesel | C27: 5.77 | D27: 5.77 | E27: 5.77 | F27: 5.77 | G27: 5.77 | H27: 5.77 | I27: 5.77 | J27: 5.77 | K27: 5.77 | L27: 5.77 | M27: 5.77 | N27: 5.77 | O27: 5.77 | P27: 5.77 | Q27: 5.77 | R27: 5.77 | S27: 5.77 | T27: 5.77 | U27: 5.77 | V27: 5.77 | W27: 5.77 | X27: 5.77 | Y27: 5.77 | Z27: 5.77 | AA27: 5.77 | AB27: 5.77 | AC27: 5.77 | AD27: 5.77 | AE27: 5.77 | AF27: 5.77 | AG27: 5.77 | AH27: 0
... A46: CNV000:aa_Exports | B46: Petroleum Product Exports | C46: 5.208902 | D46: 5.233259 | E46: 5.248022 | F46: 5.255337 | G46: 5.284336 | H46: 5.284585 | I46: 5.293683 | J46: 5.295779 | K46: 5.304686 | L46: 5.305382 | M46: 5.288252 | N46: 5.307133 | O46: 5.317582 | P46: 5.324971 | Q46: 5.329218 | R46: 5.340077 | S46: 5.341102 | T46: 5.350363 | U46: 5.351419 | V46: 5.347663 | W46: 5.341086 | X46: 5.342655 | Y46: 5.341298 | Z46: 5.333441 | AA46: 5.32583 | AB46: 5.325848 | AC46: 5.324336 | AD46: 5.331812 | AE46: 5.337536 | AF46: 5.337165 | AG46: 5.341957 | AH46: 0.000841
B47: Crude Oil
A48: CNV000:aa_CrudeOilProdu | B48: Production | C48: 5.701258 | D48: 5.705287 | E48: 5.698242 | F48: 5.690741 | G48: 5.686217 | H48: 5.680397 | I48: 5.679482 | J48: 5.680235 | K48: 5.682467 | L48: 5.683152 | M48: 5.685532 | N48: 5.686835 | O48: 5.686281 | P48: 5.688497 | Q48: 5.689099 | R48: 5.687949 | S48: 5.684894 | T48: 5.68398 | U48: 5.68161 | V48: 5.680455 | W48: 5.678696 | X48: 5.677988 | Y48: 5.678402 | Z48: 5.678963 | AA48: 5.678901 | AB48: 5.675479 | AC48: 5.677872 | AD48: 5.678594 | AE48: 5.676446 | AF48: 5.673857 | AG48: 5.669861 | AH48: -0.000184
A49: CNV000:aa_CrudeOilImpor | B49: Imports | C49: 6.085091 | D49: 6.066456 | E49: 6.068346 | F49: 6.068904 | G49: 6.068149 | H49: 6.070602 | I49: 6.087798 | J49: 6.087098 | K49: 6.09395 | L49: 6.091728 | M49: 6.087254 | N49: 6.093457 | O49: 6.103011 | P49: 6.10403 | Q49: 6.110426 | R49: 6.110364 | S49: 6.113935 | T49: 6.127923 | U49: 6.126749 | V49: 6.126231 | W49: 6.121337 | X49: 6.12137 | Y49: 6.118534 | Z49: 6.108738 | AA49: 6.108547 | AB49: 6.110272 | AC49: 6.10705 | AD49: 6.107703 | AE49: 6.109305 | AF49: 6.10804 | AG49: 6.116878 | AH49: 0.000174
A50: CNV000:aa_CrudeOilExpor | B50: Exports | C50: 5.586683 | D50: 5.596693 | E50: 5.596242 | F50: 5.595907 | G50: 5.595245 | H50: 5.595181 | I50: 5.584603 | J50: 5.587386 | K50: 5.595116 | L50: 5.586189 | M50: 5.59499 | N50: 5.585876 | O50: 5.594877 | P50: 5.59394 | Q50: 5.590277 | R50: 5.591412 | S50: 5.590872 | T50: 5.594198 | U50: 5.594143 | V50: 5.588477 | W50: 5.593933 | X50: 5.593874 | Y50: 5.593719 | Z50: 5.593579 | AA50: 5.597045 | AB50: 5.59432 | AC50: 5.593446 | AD50: 5.593292 | AE50: 5.593154 | AF50: 5.593037 | AG50: 5.592913 | AH50: 3.7e-05
A51: CNV000:aa_NaturalGasPla | B51: Natural Gas Plant Liquids | C51: 3.588495 | D51: 3.53136 | E51: 3.523382 | F51: 3.549014 | G51: 3.544739 | H51: 3.540329 | I51: 3.539303 | J51: 3.538394 | K51: 3.537459 | L51: 3.535216 | M51: 3.533556 | N51: 3.532846 | O51: 3.532958 | P51: 3.533101 | Q51: 3.532566 | R51: 3.531256 | S51: 3.530272 | T51: 3.529652 | U51: 3.528985 | V51: 3.52799 | W51: 3.527618 | X51: 3.528339 | Y51: 3.528407 | Z51: 3.529173 | AA51: 3.529438 | AB51: 3.528521 | AC51: 3.529552 | AD51: 3.529862 | AE51: 3.52899 | AF51: 3.527624 | AG51: 3.525624 | AH51: -0.000589
B53: Natural Gas (thousand Btu per cubic foot)
A54: CNV000:ba_Consumption | B54: Consumption | C54: 1.037 | D54: 1.037 | E54: 1.037 | F54: 1.037 | G54: 1.037 | H54: 1.037 | I54: 1.037 | J54: 1.037 | K54: 1.037 | L54: 1.037 | M54: 1.037 | N54: 1.037 | O54: 1.037 | P54: 1.037 | Q54: 1.037 | R54: 1.037 | S54: 1.037 | T54: 1.037 | U54: 1.037 | V54: 1.037 | W54: 1.037 | X54: 1.037 | Y54: 1.037 | Z54: 1.037 | AA54: 1.037 | AB54: 1.037 | AC54: 1.037 | AD54: 1.037 | AE54: 1.037 | AF54: 1.037 | AG54: 1.037 | AH54: 0
A55: CNV000:ba_Utility | B55: Electric Power Sector 2/ | C55: 1.034 | D55: 1.034 | E55: 1.034 | F55: 1.034 | G55: 1.034 | H55: 1.034 | I55: 1.034 | J55: 1.034 | K55: 1.034 | L55: 1.034 | M55: 1.034 | N55: 1.034 | O55: 1.034 | P55: 1.034 | Q55: 1.034 | R55: 1.034 | S55: 1.034 | T55: 1.034 | U55: 1.034 | V55: 1.034 | W55: 1.034 | X55: 1.034 | Y55: 1.034 | Z55: 1.034 | AA55: 1.034 | AB55: 1.034 | AC55: 1.034 | AD55: 1.034 | AE55: 1.034 | AF55: 1.034 | AG55: 1.034 | AH55: 0
A56: CNV000:ba_Nonutility | B56: End-use Sector | C56: 1.039 | D56: 1.039 | E56: 1.039 | F56: 1.039 | G56: 1.039 | H56: 1.039 | I56: 1.039 | J56: 1.039 | K56: 1.039 | L56: 1.039 | M56: 1.039 | N56: 1.039 | O56: 1.039 | P56: 1.039 | Q56: 1.039 | R56: 1.039 | S56: 1.039 | T56: 1.039 | U56: 1.039 | V56: 1.039 | W56: 1.039 | X56: 1.039 | Y56: 1.039 | Z56: 1.039 | AA56: 1.039 | AB56: 1.039 | AC56: 1.039 | AD56: 1.039 | AE56: 1.039 | AF56: 1.039 | AG56: 1.039 | AH56: 0
A57: CNV000:ba_Production | B57: Production | C57: 1.037 | D57: 1.037 | E57: 1.037 | F57: 1.037 | G57: 1.037 | H57: 1.037 | I57: 1.037 | J57: 1.037 | K57: 1.037 | L57: 1.037 | M57: 1.037 | N57: 1.037 | O57: 1.037 | P57: 1.037 | Q57: 1.037 | R57: 1.037 | S57: 1.037 | T57: 1.037 | U57: 1.037 | V57: 1.037 | W57: 1.037 | X57: 1.037 | Y57: 1.037 | Z57: 1.037 | AA57: 1.037 | AB57: 1.037 | AC57: 1.037 | AD57: 1.037 | AE57: 1.037 | AF57: 1.037 | AG57: 1.037 | AH57: 0
A58: CNV000:ba_Imports | B58: Imports | C58: 1.025 | D58: 1.025 | E58: 1.025 | F58: 1.025 | G58: 1.025 | H58: 1.025 | I58: 1.025 | J58: 1.025 | K58: 1.025 | L58: 1.025 | M58: 1.025 | N58: 1.025 | O58: 1.025 | P58: 1.025 | Q58: 1.025 | R58: 1.025 | S58: 1.025 | T58: 1.025 | U58: 1.025 | V58: 1.025 | W58: 1.025 | X58: 1.025 | Y58: 1.025 | Z58: 1.025 | AA58: 1.025 | AB58: 1.025 | AC58: 1.025 | AD58: 1.025 | AE58: 1.025 | AF58: 1.025 | AG58: 1.025 | AH58: 0
A59: CNV000:ba_Exports | B59: Exports | C59: 1.009 | D59: 1.009 | E59: 1.009 | F59: 1.009 | G59: 1.009 | H59: 1.009 | I59: 1.009 | J59: 1.009 | K59: 1.009 | L59: 1.009 | M59: 1.009 | N59: 1.009 | O59: 1.009 | P59: 1.009 | Q59: 1.009 | R59: 1.009 | S59: 1.009 | T59: 1.009 | U59: 1.009 | V59: 1.009 | W59: 1.009 | X59: 1.009 | Y59: 1.009 | Z59: 1.009 | AA59: 1.009 | AB59: 1.009 | AC59: 1.009 | AD59: 1.009 | AE59: 1.009 | AF59: 1.009 | AG59: 1.009 | AH59: 0
A60: CNV000:ba_CompressedNat | B60: Compressed/Liquefied Natural Gas | C60: 0.96 | D60: 0.96 | E60: 0.96 | F60: 0.96 | G60: 0.96 | H60: 0.96 | I60: 0.96 | J60: 0.96 | K60: 0.96 | L60: 0.96 | M60: 0.96 | N60: 0.96 | O60: 0.96 | P60: 0.96 | Q60: 0.96 | R60: 0.96 | S60: 0.96 | T60: 0.96 | U60: 0.96 | V60: 0.96 | W60: 0.96 | X60: 0.96 | Y60: 0.96 | Z60: 0.96 | AA60: 0.96 | AB60: 0.96 | AC60: 0.96 | AD60: 0.96 | AE60: 0.96 | AF60: 0.96 | AG60: 0.96 | AH60: 0
B62: Coal (million Btu per short ton)
A63: CNV000:ca_Production | B63: Production | C63: 20.313612 | D63: 20.251499 | E63: 20.463696 | F63: 20.630898 | G63: 20.58532 | H63: 20.620371 | I63: 20.558367 | J63: 20.551445 | K63: 20.452055 | L63: 20.355701 | M63: 20.289701 | N63: 20.316072 | O63: 20.341093 | P63: 20.369787 | Q63: 20.349621 | R63: 20.382479 | S63: 20.405159 | T63: 20.455118 | U63: 20.57431 | V63: 20.58498 | W63: 20.617809 | X63: 20.606735 | Y63: 20.642296 | Z63: 20.684587 | AA63: 20.690783 | AB63: 20.781717 | AC63: 20.824453 | AD63: 20.813873 | AE63: 20.786306 | AF63: 20.831282 | AG63: 20.832466 | AH63: 0.000841
A64: CNV000:ca_EastoftheMiss | B64: East of the Mississippi | C64: 25.162447 | D64: 25.061907 | E64: 24.844831 | F64: 25.003353 | G64: 25.014917 | H64: 25.161196 | I64: 25.144636 | J64: 25.18247 | K64: 25.190441 | L64: 25.210474 | M64: 25.271479 | N64: 25.263571 | O64: 25.235905 | P64: 25.426609 | Q64: 25.42605 | R64: 25.406256 | S64: 25.35174 | T64: 25.317278 | U64: 25.262371 | V64: 25.204082 | W64: 25.170408 | X64: 25.136366 | Y64: 25.124195 | Z64: 25.10177 | AA64: 25.08288 | AB64: 25.03639 | AC64: 25.004837 | AD64: 24.996422 | AE64: 24.994413 | AF64: 25.032789 | AG64: 25.018826 | AH64: -0.000191
...

Sheet GREET1 Fuel_Specs
A1: Specifications of Fuels, Global Warming Potentials of Greenhouse Gases, and Carbon and Sulfur Ratios of Pollutants
A2: 1) Specifications of Fuels
A3: Fuel | B3: Heating Value | E3: Density | F3: C ratio | G3: S ratio | H3: S ratio
B4: Calculation: LHV | C4: LHV | D4: HHV | F4: (% by wt) | G4: (ppm by wt) | H4: Actual ratio by wt | I4: LHV/HHV
A5: Use LHV or HHV in calculations? | B5: 1 | C5: 1 -- LHV; 2 -- HHV
A6: Liquid Fuels: | B6: Btu/gal | C6: Btu/gal | D6: Btu/gal | E6: grams/gal
A7: Crude oil | B7: 129670 | C7: 129670 | D7: 138350 | E7: 3205 | F7: 0.853 | G7: 16000 | H7: 0.016 | I7: 0.93726057
A8: Synthetic crude oil (SCO) | B8: 135084.91 | C8: 135084.91 | D8: 144475.84 | E8: 3266 | F8: 0.85562069 | G8: 1800 | H8: 0.0018 | I8: 0.935
A9: Bitumen | B9: 152370.9 | C9: 152370.9 | D9: 162963.53 | E9: 3839.6821 | F9: 0.83 | G9: 48000 | H9: 0.048 | I9: 0.935
A10: Dilbit (After Recovery) | B10: 152370.9 | C10: 152370.9 | D10: 162963.53 | E10: 3839.6821 | F10: 0.83 | G10: 48000 | H10: 0.048 | I10: 0.935
A11: Dilbit (Before Recovery) | B11: 145194.19 | C11: 145194.19 | D11: 155287.9 | E11: 3500.4775 | F11: 0.83245886 | G11: 37227.39 | H11: 0.03722739 | I11: 0.935
A12: Diluent | B12: 128448.53 | C12: 128448.53 | D12: 137378.1 | E12: 2709 | F12: 0.84059084 | G12: 1600 | H12: 0.0016 | I12: 0.935
A13: Shale Oil (Bakken) | B13: 125600.91 | C13: 125600.91 | D13: 134008.53 | E13: 3087.2372 | F13: 0.853 | G13: 16000 | H13: 0.016 | I13: 0.93726057
A14: Shale Oil (Eagle Ford) | B14: 122492.61 | C14: 122492.61 | D14: 130692.16 | E14: 2984.0427 | F14: 0.853 | G14: 16000 | H14: 0.016 | I14: 0.93726057
A15: Gasoline blendstock | B15: 116090 | C15: 116090 | D15: 124340 | E15: 2819 | F15: 0.863 | G15: 10 | H15: 1e-05 | I15: 0.93364967
A16: Gasoline | B16: 112193.52 | C16: 112193.52 | D16: 120438.62 | E16: 2835.562 | F16: 0.82778547 | G16: 9.0261788 | H16: 9.0261788e-06 | I16: 0.93154106
A17: CA gasoline | B17: 112193.52 | C17: 112193.52 | D17: 120438.62 | E17: 2835.562 | F17: 0.82778547 | G17: 9.0261788 | H17: 9.0261788e-06 | I17: 0.93154106
A18: High Octane Fuel (E25) | B18: 106150 | C18: 106150 | D18: 114387.5 | E18: 2861.25 | F18: 0.77775 | G18: 7.6425 | H18: 7.6425e-06 | I18: 0.92798601
... A20: U.S. conventional diesel | B20: 128450 | C20: 128450 | D20: 137380 | E20: 3167 | F20: 0.865 | G20: 200 | H20: 0.0002 | I20: 0.93499782
A21: CA diesel | B21: 129487.85 | C21: 129487.85 | D21: 138490 | E21: 3206 | F21: 0.871 | G21: 11 | H21: 1.1e-05
A22: Diesel for non-road engines | B22: 128450 | C22: 128450 | D22: 137380 | E22: 3167 | F22: 0.865 | G22: 11 | H22: 1.1e-05 | I22: 0.93499782
A23: Low-sulfur diesel | B23: 129487.85 | C23: 129487.85 | D23: 138490 | E23: 3206 | F23: 0.871 | G23: 11 | H23: 1.1e-05 | I23: 0.93499782
A24: Petroleum naphtha | B24: 116920 | C24: 116920 | D24: 125080 | E24: 2745 | F24: 0.85 | G24: 1 | H24: 1e-06 | I24: 0.93476175
A25: Low Octane Gasoline-Like Fuel (LOF) | B25: 118237.43 | C25: 118237.43 | D25: 126586.16 | E25: 2833.857 | F25: 0.85315639 | G25: 10 | H25: 1e-05 | I25: 0.93404711
A26: Conventional Jet Fuel | B26: 124307.03 | C26: 124307.03 | D26: 132948.69 | E26: 3035.8996 | F26: 0.862 | G26: 700 | H26: 0.0007 | I26: 0.93500004
A27: ULS Jet Fuel | B27: 123041.23 | C27: 123041.23 | D27: 131594.89 | E27: 2998.0455 | F27: 0.86 | G27: 11 | H27: 1.1e-05 | I27: 0.93500004
A28: NG-based FT naphtha | B28: 111520 | C28: 111520 | D28: 119740 | E28: 2651 | F28: 0.842 | G28: 0 | H28: 0 | I28: 0.93135126
A29: Residual oil | B29: 140352.52 | C29: 140352.52 | D29: 150110 | E29: 3752 | F29: 0.868 | G29: 5000 | H29: 0.005 | I29: 0.93499782
A30: Bunker fuel for ocean tanker | B30: 140352.52 | C30: 140352.52 | D30: 150110 | E30: 3752 | F30: 0.868 | G30: 27000 | H30: 0.027 | I30: 0.93499782
A31: Methanol | B31: 57250 | C31: 57250 | D31: 65200 | E31: 3006 | F31: 0.375 | G31: 0 | H31: 0 | I31: 0.87806748
A32: Ethanol | B32: 76330 | C32: 76330 | D32: 84530 | E32: 2988 | F32: 0.522 | G32: 0.57000011 | H32: 5.7000011e-07 | I32: 0.90299302
A33: Butanol | B33: 99837 | C33: 99837 | D33: 108458 | E33: 3065 | F33: 0.6486 | G33: 0 | H33: 0 | I33: 0.92051301
... A56: Propane | B56: 84250 | C56: 84250 | D56: 91420 | E56: 1920 | F56: 0.818 | G56: 0 | H56: 0 | I56: 0.92157077
A57: Natural gas liquids | B57: 83686.112 | C57: 83686.112 | D57: 90050 | E57: 2532 | G57: 0 | H57: 0 | I57: 0.9293294
A58: n-Hexane | B58: 105124.8 | C58: 105124.8 | D58: 112166.3 | E58: 2478.7 | F58: 0.836251 | G58: 0 | H58: 0 | I58: 0.93722268
A59: Gaseous Fuels (at 32F and 1atm): | B59: Btu/ft3 | C59: Btu/ft3 | D59: Btu/ft3 | E59: gms/ft3 | I59: LHV/HHV
A60: Natural gas | B60: 983 | C60: 983 | D60: 1089 | E60: 22 | F60: 0.724 | G60: 6 | H60: 6e-06 | I60: 0.90266299
A61: Pure Methane | B61: 962.18505 | C61: 962.18505 | D61: 1068.0254 | E61: 20.303179 | F61: 0.75 | G61: 0 | H61: 0 | I61: 0.9009009
A62: Gaseous hydrogen | B62: 290 | C62: 290 | D62: 343 | E62: 2.55 | F62: 0 | G62: 0 | H62: 0 | I62: 0.84548105
A63: Carbon Dioxide | E63: 55.97783 | F63: 0.27272727 | G63: 0 | H63: 0
...

Sheet energeticos
A1: Sistema de Información Energética
A2: Secretaría de Energía
A3: Dirección General de Planeación e Información Energéticas
A4: Balance Nacional de Energía: Oferta interna bruta total por energético
A5: (petajoules)
B7: REALES
A8: PRODUCCION | B8: 2005 | C8: 2006 | D8: 2007 | E8: 2008 | F8: 2009 | G8: 2010 | H8: 2011 | I8: 2012 | J8: 2013 | K8: 2014 | L8: 2015 | M8: 2016 | N8: 2017 | O8: 2018 | P8: 2019
A10: Total | B10: 7957.4425 | C10: 8056.0255 | D10: 8092.2401 | E10: 8337.7937 | F10: 8315.1592 | G10: 8271.0447 | H10: 8638.2634 | I10: 8814.8054 | J10: 8988.4304 | K10: 8650.6894 | L10: 8528.8669 | M10: 9140.096 | N10: 9249.7458 | O10: 9236.858 | P10: 8811.0536
A11: Carbón y coque de carbón | B11: 480.34629 | C11: 515.51383 | D11: 473.7015 | E11: 423.16308 | F11: 431.08722 | G11: 533.22752 | H11: 616.77734 | I11: 537.35764 | J11: 533.6158 | K11: 532.57986 | L11: 531.54163 | M11: 520.67992 | N11: 636.31004 | O11: 567.16367 | P11: 541.49341
A12: Crudo y petrolíferos | B12: 3810.5241 | C12: 3668.0553 | D12: 3814.1232 | E12: 4016.4307 | F12: 3807.6383 | G12: 3662.0643 | H12: 3755.621 | I12: 3954.8035 | J12: 3905.5825 | K12: 3505.8766 | L12: 3462.1818 | M12: 3592.9419 | N12: 3520.6184 | O12: 3508.2583 | P12: 3261.1419
A13: Gas natural y condensados | B13: 2936.5748 | C13: 3154.6768 | D13: 3084.0401 | E13: 3154.1639 | F13: 3385.3809 | G13: 3390.0961 | H13: 3538.5164 | I13: 3626.0582 | J13: 3812.4531 | K13: 3870.5824 | L13: 3791.0102 | M13: 4281.1098 | N13: 4335.6791 | O13: 4344.1563 | P13: 4227.1734
A14: Nuclear | B14: 117.88 | C14: 119.419 | D14: 114.486 | E14: 106.635 | F14: 112.745 | G14: 63.942774 | H14: 106.39494 | I14: 91.317 | J14: 122.598 | K14: 100.596 | L14: 120.407 | M14: 109.95428 | N14: 113.21871 | O14: 156.00289 | P14: 124.82
A15: Renovables | B15: 638.20057 | C15: 625.8113 | D15: 632.25558 | E15: 666.21994 | F15: 605.14064 | G15: 641.96217 | H15: 640.84781 | I15: 620.53108 | J15: 634.71908 | K15: 665.76647 | L15: 647.90824 | M15: 653.95183 | N15: 663.87645 | O15: 673.74244 | P15: 661.12485
A16: Biogás | B16: 0.688518 | C16: 0.675775 | D16: 0.651122 | E16: 0.808913 | F16: 1.067139 | G16: 1.298023 | H16: 1.507667 | I16: 1.823098 | J16: 1.972003 | K16: 1.925703 | L16: 1.867721 | M16: 1.912172 | N16: 2.51994 | O16: 2.843916 | P16: 2.799
A17: Hidro | B17: 99.754004 | C17: 109.60731 | D17: 98.422827 | E17: 141.20607 | F17: 96.19922 | G17: 133.76877 | H17: 130.57351 | I17: 114.87848 | J17: 100.87676 | K17: 140.01397 | L17: 111.20955 | M17: 110.51047 | N17: 114.65156 | O17: 116.9475 | P17: 84.99
A18: Geo, eólica, solar | B18: 167.54291 | C18: 153.96991 | D18: 171.46978 | E18: 164.11173 | F18: 158.93915 | G18: 159.35707 | H18: 161.03846 | I18: 153.05186 | J18: 153.97625 | K18: 161.74767 | L18: 176.16514 | M18: 181.04483 | N18: 180.81332 | O18: 184.28175 | P18: 213.42
A19: Biomasa | B19: 370.21514 | C19: 361.55831 | D19: 361.71185 | E19: 360.09323 | F19: 348.93514 | G19: 347.53832 | H19: 347.72818 | I19: 350.77764 | J19: 377.89407 | K19: 362.07913 | L19: 358.66583 | M19: 360.48435 | N19: 365.89163 | O19: 369.66927 | P19: 359.92
A20: Comercio neto de electricidad | B20: -26.083201 | C20: -27.450698 | D20: -26.366262 | E20: -28.81887 | F20: -26.832849 | G20: -20.248171 | H20: -19.894091 | I20: -15.262 | J20: -20.538 | K20: -24.712 | L20: -24.182 | M20: -18.541693 | N20: -19.956901 | O20: -12.465634 | P20: -4.7
A22: Nota:
A23: La suma de los parciales puede no coincidir con los totales, debido al redondeo de las cifras.
A24: Los datos del a&ntilde;o 2018 son preliminares y están sujetos a cambios sin previo aviso.
A26: Fuente: Sistema de Información Energética, SENER.
A28: Sistema de Información Energética
A29: Secretaría de Energía
A30: Dirección General de Planeación e Información Energéticas
A31: Balance Nacional de Energía: Importación de energía
A32: (petajoules)
B34: REALES
A35: IMPORTACION | B35: 2005 | C35: 2006 | D35: 2007 | E35: 2008 | F35: 2009 | G35: 2010 | H35: 2011 | I35: 2012 | J35: 2013 | K35: 2014 | L35: 2015 | M35: 2016 | N35: 2017 | O35: 2018 | P35: 2019
A37: Total | B37: 1175.0891 | C37: 1312.3561 | D37: 1563.285 | E37: 1780.0249 | F37: 1690.4806 | G37: 2063.1866 | H37: 2307.5298 | I37: 2449.6146 | J37: 2401.159 | K37: 2560.9862 | L37: 2904.2855 | M37: 3994.254 | N37: 4417.6104 | O37: 5032.193 | P37: 4803.342
A39: Energía primaria | B39: 214.63649 | C39: 225.28817 | D39: 157.07036 | E39: 131.82857 | F39: 173.82363 | G39: 222.89887 | H39: 219.49365 | I39: 215.30875 | J39: 216.96667 | K39: 210.82794 | L39: 223.23036 | M39: 239.84802 | N39: 301.22066 | O39: 277.237 | P39: 275.146
A40: Carbón | B40: 214.63649 | C40: 225.28817 | D40: 157.07036 | E40: 131.82857 | F40: 173.82363 | G40: 222.89887 | H40: 219.49365 | I40: 215.30875 | J40: 216.96667 | K40: 210.82794 | L40: 223.23036 | M40: 239.84802 | N40: 301.22066 | O40: 268.665 | P40: 275.146
A41: Petróleo crudo | B41: 0 | C41: 0 | D41: 0 | E41: 0 | F41: 0 | G41: 0 | H41: 0 | I41: 0 | J41: 0 | K41: 0 | L41: 0 | M41: 0 | N41: 0 | O41: 8.572 | P41: 0
A43: Energía secundaria | B43: 960.45259 | C43: 1087.0679 | D43: 1406.2146 | E43: 1648.1963 | F43: 1516.6569 | G43: 1840.2877 | H43: 2088.0361 | I43: 2234.3058 | J43: 2184.1923 | K43: 2350.1583 | L43: 2681.0551 | M43: 3754.4059 | N43: 4116.3898 | O43: 4754.956 | P43: 4528.196
A44: Coque | B44: 80.811661 | C44: 105.59073 | D44: 119.66027 | E44: 117.76023 | F44: 75.729024 | G44: 93.548424 | H44: 103.09529 | I44: 113.58223 | J44: 95.548637 | K44: 89.063171 | L44: 104.41035 | M44: 139.8685 | N44: 171.72484 | O44: 170.734 | P44: 149.518
A45: Coque de carbón | B45: 10.34776 | C45: 8.569837 | D45: 7.217706 | E45: 9.237363 | F45: 5.517239 | G45: 10.366608 | H45: 8.90816 | I45: 10.366377 | J45: 9.894612 | K45: 13.286949 | L45: 13.869203 | M45: 29.413607 | N45: 31.52665 | O45: 19.178 | P45: 32.333
A46: Coque de petróleo | B46: 70.4639 | C46: 97.020891 | D46: 112.44256 | E46: 108.52287 | F46: 70.211785 | G46: 83.181816 | H46: 94.187132 | I46: 103.21585 | J46: 85.654025 | K46: 75.776222 | L46: 90.541153 | M46: 110.45489 | N46: 140.19819 | O46: 151.556 | P46: 117.185
A47: Gas licuado | B47: 100.22508 | C47: 103.91974 | D47: 126.37883 | E47: 138.04281 | F47: 124.11815 | G47: 122.37296 | H47: 126.42366 | I47: 130.83708 | J47: 119.61333 | K47: 127.88249 | L47: 158.39708 | M47: 206.48342 | N47: 224.86509 | O47: 248.94 | P47: 233.628
A48: Gasolinas y naftas | B48: 354.59955 | C48: 399.0066 | D48: 587.25496 | E48: 645.37498 | F48: 624.14022 | G48: 761.69667 | H48: 815.73267 | I48: 755.48205 | J48: 713.79389 | K48: 711.47402 | L48: 810.81735 | M48: 978.83989 | N48: 1061.0026 | O48: 1262.578 | P48: 1128.085
A49: Querosenos | B49: 0 | C49: 0.260609 | D49: 6.815569 | E49: 9.697214 | F49: 2.168061 | G49: 8.053136 | H49: 1.839684 | I49: 6.614373 | J49: 6.557259 | K49: 24.126674 | L49: 50.347961 | M49: 72.325782 | N49: 91.191092 | O49: 121.7 | P49: 114.693
...

Sheet OrigenDestino_2019
A1: Sistema de Información Energética
A2: Secretaría de Energía
A3: Dirección General de Planeación e Información Energéticas
A4: Balance Nacional de Energía: Origen y destino de la energía
A5: (petajoules)
A6: REALES 2019
B9: Carbón | C9: Petróleo crudo | D9: Condensados | E9: Gas natural | F9: Nucleoenergía | G9: Hidroenergía | H9: Geoenergía | I9: Energía solar | J9: Energía eólica | K9: Bagazo de ca&ntilde;a | L9: Le&ntilde;a | M9: Biogás | N9: Total de energía primaria | O9: Coque de carbón | P9: Coque de petróleo | Q9: Gas LP | R9: Gasolinas y naftas | S9: Querosenos | T9: Diesel | U9: Combustóleo | V9: Productos no energéticos | W9: Gas seco | X9: Otros autogeneración | Y9: Electricidad | Z9: Total de energía secundaria | AA9: Total
A11: Producción | B11: 230.461 | C11: 3788.641 | D11: 60.487 | E11: 1466.036 | F11: 124.817 | G11: 84.989 | H11: 112.883 | I11: 40.315 | J11: 60.216 | K11: 113.249 | L11: 247.919 | M11: 2.799 | N11: 6332.812 | O11: 0 | P11: 0 | Q11: 0 | R11: 0 | S11: 0 | T11: 0 | U11: 0 | V11: 0 | W11: 0 | X11: 0 | Y11: 0 | Z11: 0 | AA11: 6332.812
A12: De otras fuentes | E12: 684.327 | N12: 684.327 | O12: 0 | P12: 0 | Q12: 0 | R12: 0 | S12: 0 | T12: 0 | U12: 0 | V12: 0 | W12: 0 | X12: 0 | Y12: 0 | Z12: 0 | AA12: 684.327
A13: Importación | B13: 275.146 | C13: 0 | N13: 275.146 | O13: 32.333 | P13: 117.185 | Q13: 233.628 | R13: 1128.085 | S13: 114.693 | T13: 572.06 | U13: 103.143 | V13: 0 | W13: 2213.002 | X13: 0 | Y13: 14.067 | Z13: 4528.196 | AA13: 4803.342
A14: Variación de inventarios | B14: 3.693 | C14: 41.625 | D14: 5.886 | E14: 21.153 | N14: 72.357 | O14: 0 | P14: -6.525 | Q14: -0.691 | R14: -91.919 | S14: 16.157 | T14: -41.723 | U14: 15.889 | V14: -1.096 | W14: -0.29 | X14: 0 | Z14: -110.196 | AA14: -37.838
A15: Oferta total | B15: 509.3 | C15: 3830.266 | D15: 66.373 | E15: 2171.516 | F15: 124.817 | G15: 84.989 | H15: 112.883 | I15: 40.315 | J15: 60.216 | K15: 113.249 | L15: 247.919 | M15: 2.799 | N15: 7364.642 | O15: 32.333 | P15: 110.66 | Q15: 232.937 | R15: 1036.166 | S15: 130.85 | T15: 530.337 | U15: 119.032 | V15: -1.096 | W15: 2212.712 | X15: 0 | Y15: 14.067 | Z15: 4417.998 | AA15: 11782.641
A16: Exportación | B16: -0.135 | C16: -2465.319 | D16: 0 | N16: -2465.454 | O16: -0.006 | P16: -0.092 | Q16: -1.396 | R16: -64.678 | S16: 0 | T16: -27.128 | U16: -168.521 | V16: 0 | W16: -1.403 | X16: 0 | Y16: -18.762 | Z16: -281.986 | AA16: -2747.44
A17: No aprovechada | C17: -0.878 | E17: -222.025 | K17: -1.246 | N17: -224.149 | X17: 0 | Y17: 0 | Z17: 0 | AA17: -224.148
A18: Maquila-intercambio neto | C18: 0 | N18: 0 | Q18: 0 | R18: 0 | S18: 0 | T18: 0 | U18: 0 | V18: 0 | X18: 0 | Y18: 0 | Z18: 0 | AA18: 0
A19: Oferta interna bruta | B19: 509.165 | C19: 1364.069 | D19: 66.373 | E19: 1949.491 | F19: 124.817 | G19: 84.989 | H19: 112.883 | I19: 40.315 | J19: 60.216 | K19: 112.003 | L19: 247.919 | M19: 2.799 | N19: 4675.039 | O19: 32.327 | P19: 110.568 | Q19: 231.541 | R19: 971.488 | S19: 130.85 | T19: 503.209 | U19: -49.489 | V19: -1.096 | W19: 2211.309 | X19: 0 | Y19: -4.695 | Z19: 4136.012 | AA19: 8811.053
A20: Total transformación | B20: -387.477 | C20: -1287.501 | D20: -66.372 | E20: -1311.252 | F20: -124.817 | G20: -84.989 | H20: -112.883 | I20: -26.519018 | J20: -60.216 | K20: -75.569 | L20: 0 | M20: -2.799136 | N20: -3540.3942 | O20: 26.282 | P20: 6.199 | Q20: 162.217 | R20: 475.974 | S20: 60.903 | T20: 169.406 | U20: 102.172 | V20: 118.697 | W20: -758.513 | X20: 0 | Y20: 1240.487 | Z20: 1603.824 | AA20: -1936.5702
A21: Coquizadoras | B21: -37.048 | N21: -37.048 | O21: 26.282 | X21: 1.555 | Y21: 0 | Z21: 27.837 | AA21: -9.211
A22: Refinerías y despuntadoras | C22: -1287.501 | D22: -33.369 | N22: -1320.87 | P22: 40.529 | Q22: 10.509 | R22: 391.414 | S22: 60.903 | T22: 219.889 | U22: 354.177 | V22: 36.172 | W22: 92.064 | X22: 0 | Y22: 0 | Z22: 1205.657 | AA22: -115.213
