Workbook
Name gal_per_barrel: [1]About!$A$63

Sheet About
A1: BFPIaE BAU Fuel Production
A2: BFPIaE BAU Fuel Imports
A3: BFPIaE BAU Fuel Exports
A5: Source: | B5: Petroleum-based fuels, biofuels
B6: U.S. Energy Information Administration
B7: 2019
B8: Petroleum & Other Liquids: Supply and Disposition
B9: https://www.eia.gov/dnav/pet/pet_sum_snd_d_nus_mbbl_a_cur.htm
B10: Area: US, Period: Annual 2017
B12: Nuclear Fuel (Uranium)
B13: U.S. Energy Information Administration
B14: 2018
B15: U.S. uranium imports continue as domestic production remains at historical lows
B16: https://www.eia.gov/todayinenergy/detail.php?id=37192
B17: Paragraph 1
B19: Hard Coal, Lignite
B20: U.S. Energy Information Administration
B21: 2019
B22: Coal Explained: Where Our Coal Comes From
B23: https://www.eia.gov/energyexplained/index.php?page=coal_where
B24: https://www.eia.gov/energyexplained/index.php?page=coal_imports
B25: https://www.eia.gov/energyexplained/index.php?page=coal_prices
B27: Biomass Production and Exports
B28: U.S. Energy Information Administration
B29: 2020
B30: Monthly Densified Biomass Fuel Report
B31: https://www.eia.gov/biofuels/biomass/?year=2020&month=12#table_data
B32: Tables 4 and 8
B34: Biomass Imports and Exports (for Import to Export Ratio)
B35: U.S. International Trade Administration
B36: 2017
B37: 2016 Top Markets Report Renewable Fuels Sector Snapshot: Biomass Wood Pellets
B38: https://www.trade.gov/topmarkets/pdf/Renewable_Fuels_Biomass_Wood_Pellets.pdf
B39: Tables 2 and 3a
B41: Natural Gas, Time Series Scaling Factors
B42: U.S. Energy Information Administration
B43: 2020, 2022
B44: Annual Energy Outlook 2020, Annual Energy Outlook 2022
B45: https://www.eia.gov/outlooks/aeo/tables_ref.php
B46: Table 1
...

Sheet Petroleum and Biofuel Data
B1: Area: US | C1: Period: 2017 (Annual) | E1: Unit: Thousand Barrels
C2: Supply | I2: Disposition | M2: Ending Stocks
C3: Field Production | D3: Renewable Fuels & Oxygenate Plant Net Production | E3: Refinery & Blender Net Production | F3: Imports | G3: Net Receipts | H3: Adjust- ments | I3: Stock Change | J3: Refinery & Blender Net Inputs | K3: Exports | L3: Products Supplied
A4: =TRIM(B4) -> Crude Oil & Petroleum Products | B4: Crude Oil & Petroleum Products | C4: 4794078 | D4: 437131 | E4: 7408771 | F4: 3702640 | H4: 137262 | I4: -135002 | J4: 7003159 | K4: 2327156 | L4: 7284569 | M4: 1894570
A5: =TRIM(B5) -> Crude Oil | B5: Crude Oil | C5: 4083494 | D5: - - | E5: - - | F5: 2230000 | H5: 194916 | I5: -108241 | J5: 5529012 | K5: 1087638 | L5: 0 | M5: 1015102
A6: =TRIM(B6) -> Hydrocarbon Gas Liquids | B6: Hydrocarbon Gas Liquids | C6: 1970031 | D6: -7941 | E6: 225172 | F6: 63125 | H6: - - | I6: -40797 | J6: 198527 | K6: 848015 | L6: 1244642 | M6: 188360
A7: =TRIM(B7) -> Natural Gas Liquids | B7: Natural Gas Liquids | C7: 1970031 | D7: -7941 | E7: 120757 | F7: 57128 | H7: - - | I7: -40636 | J7: 198527 | K7: 848015 | L7: 1134069 | M7: 186272
A8: =TRIM(B8) -> Ethane | B8: Ethane | C8: 781560 | D8: - - | E8: 1505 | F8: - | H8: - - | I8: -9779 | K8: 147584 | L8: 645260 | M8: 59821
A9: =TRIM(B9) -> Propane | B9: Propane | C9: 632906 | D9: - - | E9: 101344 | F9: 41465 | H9: - - | I9: -8358 | K9: 477616 | L9: 306457 | M9: 62077
A10: =TRIM(B10) -> Normal Butane | B10: Normal Butane | C10: 180543 | D10: - | E10: 20998 | F10: 13237 | H10: - - | I10: -7626 | J10: 66056 | K10: 149693 | L10: 6655 | M10: 34017
A11: =TRIM(B11) -> Isobutane | B11: Isobutane | C11: 153863 | D11: - | E11: -3090 | F11: 2358 | H11: - - | I11: -2667 | J11: 71652 | K11: 1181 | L11: 82965 | M11: 9674
A12: =TRIM(B12) -> Natural Gasoline | B12: Natural Gasoline | C12: 221159 | D12: -7941 | F12: 68 | H12: - - | I12: -12206 | J12: 60819 | K12: 71941 | L12: 92732 | M12: 20683
A13: =TRIM(B13) -> Refinery Olefins | B13: Refinery Olefins | C13: - - | D13: - - | E13: 104415 | F13: 5997 | H13: - - | I13: -161 | J13: - - | K13: - - | L13: 110573 | M13: 2088
A14: =TRIM(B14) -> Ethylene | B14: Ethylene | C14: - - | D14: - - | E14: 277 | F14: - | H14: - - | I14: 0 | J14: - - | K14: - - | L14: 277 | M14: 0
A15: =TRIM(B15) -> Propylene | B15: Propylene | C15: - - | D15: - - | E15: 106126 | F15: 5243 | H15: - - | I15: -90 | J15: - - | K15: - - | L15: 111459 | M15: 1397
A16: =TRIM(B16) -> Normal Butylene | B16: Normal Butylene | C16: - - | D16: - - | E16: -2397 | F16: 2433 | H16: - - | I16: -1165 | J16: - - | K16: - - | L16: 1201 | M16: 1204
A17: =TRIM(B17) -> Isobutylene | B17: Isobutylene | C17: - - | D17: - - | E17: 286 | F17: - | H17: - - | I17: 6 | J17: - - | K17: - - | L17: 280 | M17: 30
A18: =TRIM(B18) -> Other Liquids | B18: Other Liquids | C18: - - | D18: 443737 | E18: - - | F18: 471784 | H18: 19117 | I18: 8685 | J18: 741289 | K18: 171592 | L18: 13072 | M18: 328230
A19: =TRIM(B19) -> Hydrogen/Oxygenates/Renewables/Other Hydrocarbons | B19: Hydrogen/Oxygenates/Renewables/Other Hydrocarbons | C19: - - | D19: 443788 | E19: - - | F19: 19778 | H19: 36824 | I19: 577 | J19: 439078 | K19: 60735 | L19: 0 | M19: 29585
A20: =TRIM(B20) -> Hydrogen | B20: Hydrogen | C20: - - | D20: - - | E20: - - | H20: 81091 | I20: - - | J20: 81091 | L20: 0 | M20: - -
A21: =TRIM(B21) -> Oxygenates (excl. Fuel Ethanol) | B21: Oxygenates (excl. Fuel Ethanol) | C21: - - | D21: 26360 | E21: - - | F21: 3835 | H21: -4811 | I21: -31 | J21: - | K21: 25415 | L21: 0 | M21: 1446
A22: =TRIM(B22) -> Renewable Fuels (incl. Fuel Ethanol) | B22: Renewable Fuels (incl. Fuel Ethanol) | C22: - - | D22: 417428 | E22: - - | F22: 15707 | H22: -39640 | I22: 578 | J22: 357597 | K22: 35320 | L22: 0 | M22: 28092
A23: =TRIM(B23) -> Fuel Ethanol | B23: Fuel Ethanol | C23: - - | D23: 379435 | E23: - - | F23: 1824 | H23: -9859 | I23: 3285 | J23: 335023 | K23: 33092 | L23: 0 | M23: 23043
A24: =TRIM(B24) -> Renewable Fuels Except Fuel Ethanol | B24: Renewable Fuels Except Fuel Ethanol | C24: - - | D24: 37993 | E24: - - | F24: 13883 | H24: -29781 | I24: -2707 | J24: 22574 | K24: 2228 | L24: 0 | M24: 5049
A25: =TRIM(B25) -> Other Hydrocarbons | B25: Other Hydrocarbons | C25: - - | D25: - - | E25: - - | F25: 236 | H25: 184 | I25: 30 | J25: 390 | L25: 0 | M25: 47
A26: =TRIM(B26) -> Unfinished Oils | B26: Unfinished Oils | C26: - - | D26: - - | E26: - - | F26: 231478 | H26: - - | I26: 6013 | J26: 129406 | K26: 82949 | L26: 13110 | M26: 86337
A27: =TRIM(B27) -> Motor Gasoline Blend. Comp. | B27: Motor Gasoline Blend. Comp. | C27: - - | D27: -51 | E27: - - | F27: 220528 | H27: -17707 | I27: 2089 | J27: 172773 | K27: 27908 | L27: 0 | M27: 212293
A28: =TRIM(B28) -> Reformulated | B28: Reformulated | C28: - - | D28: -3 | E28: - - | F28: 76948 | H28: 65150 | I28: 1299 | J28: 140697 | K28: 99 | L28: 0 | M28: 53447
A29: =TRIM(B29) -> Conventional | B29: Conventional | C29: - - | D29: -48 | E29: - - | F29: 143580 | H29: -82856 | I29: 790 | J29: 32076 | K29: 27810 | L29: 0 | M29: 158846
A30: =TRIM(B30) -> Aviation Gasoline Blend. Comp. | B30: Aviation Gasoline Blend. Comp. | C30: - - | D30: - - | E30: - - | F30: - | H30: - - | I30: 6 | J30: 32 | K30: - | L30: -38 | M30: 15
A31: =TRIM(B31) -> Finished Petroleum Products | B31: Finished Petroleum Products | C31: - - | D31: 1336 | E31: 7179380 | F31: 250759 | H31: 57659 | I31: -38269 | J31: - - | K31: 1220551 | L31: 6306852 | M31: 291859
A32: =TRIM(B32) -> Finished Motor Gasoline | B32: Finished Motor Gasoline | C32: - - | D32: 1336 | E32: 3633123 | F32: 11784 | H32: 27566 | I32: -3860 | J32: - - | K32: 273483 | L32: 3404186 | M32: 24523
A33: =TRIM(B33) -> Reformulated | B33: Reformulated | C33: - - | E33: 1187104 | F33: - | H33: -59342 | I33: -7 | J33: - - | K33: - | L33: 1127769 | M33: 40
A34: =TRIM(B34) -> Conventional | B34: Conventional | C34: - - | D34: 1336 | E34: 2446019 | F34: 11784 | H34: 86908 | I34: -3853 | J34: - - | K34: 273483 | L34: 2276417 | M34: 24483
A35: =TRIM(B35) -> Finished Aviation Gasoline | B35: Finished Aviation Gasoline | C35: - - | D35: - - | E35: 4032 | F35: 165 | H35: - - | I35: 47 | J35: - - | K35: - | L35: 4150 | M35: 1041
A36: =TRIM(B36) -> Kerosene-Type Jet Fuel | B36: Kerosene-Type Jet Fuel | C36: - - | D36: - - | E36: 621176 | F36: 58273 | H36: - - | I36: -1706 | J36: - - | K36: 67161 | L36: 613994 | M36: 41304
A37: =TRIM(B37) -> Kerosene | B37: Kerosene | C37: - - | D37: - - | E37: 2738 | F37: 1429 | H37: - - | I37: 10 | J37: - - | K37: 2267 | L37: 1890 | M37: 2138
A38: =TRIM(B38) -> Distillate Fuel Oil | B38: Distillate Fuel Oil | C38: - - | D38: - - | E38: 1833879 | F38: 54975 | H38: 30093 | I38: -20457 | J38: - - | K38: 504155 | L38: 1435249 | M38: 145638
A39: =TRIM(B39) -> 15 ppm Sulfur and Under | B39: 15 ppm Sulfur and Under | C39: - - | D39: - - | E39: 1713652 | F39: 37012 | H39: 30093 | I39: -16256 | J39: - - | K39: 423862 | L39: 1373151 | M39: 128016
A40: =TRIM(B40) -> Greater than 15 to 500 ppm Sulfur | B40: Greater than 15 to 500 ppm Sulfur | C40: - - | D40: - - | E40: 42167 | F40: 759 | H40: - | I40: -929 | J40: - - | K40: 41645 | L40: 2210 | M40: 7480
...

Sheet Biomass Data
A1: Table 4. Production of densified biomass fuel, 2020 (tons)
A2: Region | B2: Month | C2: Wood Pellets, premium/standard | D2: Wood Pellets Utility
A3: U.S. Total
B4: 1 | C4: 184451 | D4: 589367
B5: 2 | C5: 168559 | D5: 535088
B6: 3 | C6: 158633 | D6: 613798
B7: 4 | C7: 122820 | D7: 592364
B8: 5 | C8: 143019 | D8: 608837
B9: 6 | C9: 157357 | D9: 575481
B10: 7 | C10: 174016 | D10: 581260
B11: 8 | C11: 178391 | D11: 664441
B12: 9 | C12: 173333 | D12: 629927
B13: 10 | C13: 193711 | D13: 658237
B14: 11 | C14: 172601 | D14: 635793
B15: 12 | C15: 161979 | D15: 599576
A17: Table 8. Export sales and average price of densified biomass fuel, 2020
A18: Month | B18: Quantity (tons) | C18: Average Price (USD per ton)
A19: 1 | B19: 465014 | C19: 167.75
A20: 2 | B20: 532014 | C20: 163.39
A21: 3 | B21: 655441 | C21: 167.92
A22: 4 | B22: 548340 | C22: 164.43
A23: 5 | B23: 525716 | C23: 166.38
A24: 6 | B24: 627529 | C24: 159.44
A25: 7 | B25: 466871 | C25: 159.27
A26: 8 | B26: 557048 | C26: 169.81
A27: 9 | B27: 658081 | C27: 165.88
A28: 10 | B28: 572569 | C28: 166.42
A29: 11 | B29: 579346 | C29: 171.17
A30: 12 | B30: 761935 | C30: 172.44
A32: Total wood pellet production
A33: =SUM(C4:D15) -> 9273039 | B33: tons
A35: Total wood pellet exports
A36: =SUM(B19:B30) -> 6949904 | B36: tons
A38: We don't have biomass import data from EIA, but we do have some from the International Trade Administration (trade.gov).
A39: It uses different units and shows much higher wood pellet quantities than the EIA data, and it lacks production data.
A40: Accordingly, we only use it to establish a ratio of exports to imports, and apply that ratio to the EIA export data to
A41: estimate wood pellet imports (which are small compared to exports).
B43: Imports | C43: Exports | D43: Unit
A44: 2015 | B44: 207171527 | C44: 4668774792 | D44: kg
A46: Import to Export Ratio
...

Sheet Uranium, Coal, MSW, Hydrogen
A1: Uranium
B2: Production | C2: Imports | D2: Exports | E2: Unit
A3: 2017 | B3: 3 | C3: 40 | D3: 0 | E3: million pounds U3O8
A5: Hard Coal and Lignite
A6: 0.09 | B6: of U.S. coal production was lignite in 2017
A7: 775 | B7: million short tons of coal produced (of all types) in 2017
A8: 97 | B8: million short tons of coal exported in 2017
A9: 6 | B9: million short tons of coal imported in 2017
A10: We assume that all imported and exported coal was hard coal, while all lignite produced was used domestically.
B12: Production | C12: Imports | D12: Exports | E12: Unit
A13: Hard Coal | B13: =A7*(1-A6) -> 705.25 | C13: =A9 -> 6 | D13: =A8 -> 97 | E13: million short tons
A14: Lignite | B14: =A6*A7 -> 69.75 | C14: 0 | D14: 0 | E14: million short tons
A16: Municipal Solid Waste
A17: MSW Tonnage Data for Year 2015
A18: 262.4 | B18: U.S. MSW generated (million tons)
A19: 33.57 | B19: U.S. MSW burned with energy recovery (million tons)
A20: 67.8 | B20: U.S. MSW recycled (million tons)
A21: 23.4 | B21: U.S. MSW composted (million tons)
A22: 137.7 | B22: U.S. MSW landfilled (million tons)
A24: Although the U.S. exports waste to other countries,
A25: it is difficult to find statistics for waste exports other than plastic waste.
A26: (Plastic waste exports to other countries in 2018 were
A27: 1.07 million metric tons in 2018.) | D27: https://www.plasticpollutioncoalition.org/pft/2019/3/6/157000-shipping-containers-of-us-plastic-waste-exported-to-countries-with-poor-waste-management-in-2018
A30: In this model, we are only concerned about MSW that is burned as a
A31: fuel. We will assume that a negligible amount of exported waste
A32: is used as a fuel.
A34: Hydrogen
A35: 10 | B35: million metric tons
A36: produced in 2018
A38: We assume none was imported or exported.

Sheet AEO 2022 Table 1
B1: ref2022.d011222a | C1: 2021 | D1: 2022 | E1: 2023 | F1: 2024 | G1: 2025 | H1: 2026 | I1: 2027 | J1: 2028 | K1: 2029 | L1: 2030 | M1: 2031 | N1: 2032 | O1: 2033 | P1: 2034 | Q1: 2035 | R1: 2036 | S1: 2037 | T1: 2038 | U1: 2039 | V1: 2040 | W1: 2041 | X1: 2042 | Y1: 2043 | Z1: 2044 | AA1: 2045 | AB1: 2046 | AC1: 2047 | AD1: 2048 | AE1: 2049 | AF1: 2050
C3: Report | D3: Annual Energy Outlook 2022
C4: Scenario | D4: ref2022 | G4: Reference
C5: Datekey | D5: d011222a
C6: Release Date | E6: March 2022
A10: SUP000 | B10: 1. Total Energy Supply, Disposition, and Price Summary | AG10: Average
B11: (quadrillion Btu, unless otherwise noted) | AG11: Annual
AG12: Change
B13: Supply, Disposition, and Prices | C13: 2021 | D13: 2022 | E13: 2023 | F13: 2024 | G13: 2025 | H13: 2026 | I13: 2027 | J13: 2028 | K13: 2029 | L13: 2030 | M13: 2031 | N13: 2032 | O13: 2033 | P13: 2034 | Q13: 2035 | R13: 2036 | S13: 2037 | T13: 2038 | U13: 2039 | V13: 2040 | W13: 2041 | X13: 2042 | Y13: 2043 | Z13: 2044 | AA13: 2045 | AB13: 2046 | AC13: 2047 | AD13: 2048 | AE13: 2049 | AF13: 2050 | AG13: 2021–2050
B15: Production
A16: SUP000:ba_CrudeOilLease | B16: Crude Oil and Lease Condensate | C16: 23.173487 | D16: 24.717472 | E16: 25.494104 | F16: 26.154642 | G16: 27.054277 | H16: 27.435596 | I16: 27.342155 | J16: 27.686852 | K16: 27.633852 | L16: 27.555265 | M16: 27.280258 | N16: 27.009712 | O16: 27.003248 | P16: 26.646475 | Q16: 26.47743 | R16: 26.305445 | S16: 26.016472 | T16: 25.819599 | U16: 25.821352 | V16: 25.902487 | W16: 25.722721 | X16: 25.635948 | Y16: 25.63641 | Z16: 25.47831 | AA16: 25.779816 | AB16: 25.951448 | AC16: 25.981897 | AD16: 25.859144 | AE16: 25.553583 | AF16: 26.234585 | AG16: 0.004287
A17: SUP000:ba_NaturalGasPla | B17: Natural Gas Plant Liquids | C17: 7.006215 | D17: 7.552815 | E17: 7.883783 | F17: 8.023396 | G17: 8.163991 | H17: 8.108202 | I17: 8.041482 | J17: 8.029618 | K17: 8.082181 | L17: 8.155948 | M17: 8.184832 | N17: 8.259987 | O17: 8.235239 | P17: 8.250072 | Q17: 8.27844 | R17: 8.210117 | S17: 8.17472 | T17: 8.172275 | U17: 8.222511 | V17: 8.267702 | W17: 8.281703 | X17: 8.384741 | Y17: 8.490253 | Z17: 8.476263 | AA17: 8.579662 | AB17: 8.612893 | AC17: 8.634458 | AD17: 8.644827 | AE17: 8.650251 | AF17: 8.701235 | AG17: 0.007499
A18: SUP000:ba_DryNaturalGas | B18: Dry Natural Gas | C18: 35.682777 | D18: 36.629646 | E18: 36.922058 | F18: 37.131554 | G18: 37.233967 | H18: 37.210548 | I18: 37.134987 | J18: 37.74691 | K18: 38.012238 | L18: 38.079895 | M18: 38.334229 | N18: 38.609394 | O18: 38.861305 | P18: 38.688675 | Q18: 38.547447 | R18: 38.495739 | S18: 38.611137 | T18: 38.832619 | U18: 39.095234 | V18: 39.377579 | W18: 39.502232 | X18: 39.69487 | Y18: 40.037334 | Z18: 40.361305 | AA18: 40.596077 | AB18: 40.848938 | AC18: 41.134644 | AD18: 41.335979 | AE18: 41.513866 | AF18: 41.894924 | AG18: 0.00555
A19: SUP000:ba_Coal | B19: Coal 1/ | C19: 13.089978 | D19: 12.741252 | E19: 12.812081 | F19: 11.346849 | G19: 10.919338 | H19: 10.890395 | I19: 10.594276 | J19: 10.517385 | K19: 10.477952 | L19: 10.320335 | M19: 10.278054 | N19: 10.186623 | O19: 10.161192 | P19: 9.840708 | Q19: 9.568752 | R19: 9.414873 | S19: 9.287329 | T19: 9.301336 | U19: 9.227633 | V19: 9.145965 | W19: 9.122682 | X19: 9.086012 | Y19: 8.961373 | Z19: 8.89466 | AA19: 8.785145 | AB19: 8.720604 | AC19: 8.623024 | AD19: 8.544412 | AE19: 8.507181 | AF19: 8.572097 | AG19: -0.014492
A20: SUP000:ba_NuclearPower | B20: Nuclear / Uranium 2/ | C20: 8.12115 | D20: 8.183111 | E20: 8.202579 | F20: 8.239058 | G20: 8.163899 | H20: 8.075755 | I20: 7.930267 | J20: 7.368946 | K20: 7.299504 | L20: 7.307006 | M20: 7.318423 | N20: 7.326343 | O20: 6.808416 | P20: 6.815667 | Q20: 6.747447 | R20: 6.758354 | S20: 6.760554 | T20: 6.762659 | U20: 6.762759 | V20: 6.766273 | W20: 6.77936 | X20: 6.788805 | Y20: 6.797936 | Z20: 6.805902 | AA20: 6.814445 | AB20: 6.818903 | AC20: 6.823349 | AD20: 6.826119 | AE20: 6.829472 | AF20: 6.834313 | AG20: -0.005931
A21: SUP000:ba_Hydropower | B21: Conventional Hydroelectric Power | C21: 2.288529 | D21: 2.39653 | E21: 2.520376 | F21: 2.607582 | G21: 2.562303 | H21: 2.533515 | I21: 2.5148 | J21: 2.494481 | K21: 2.48263 | L21: 2.471396 | M21: 2.456771 | N21: 2.450083 | O21: 2.436512 | P21: 2.4271 | Q21: 2.410605 | R21: 2.397023 | S21: 2.392663 | T21: 2.381657 | U21: 2.376802 | V21: 2.37014 | W21: 2.362096 | X21: 2.354189 | Y21: 2.3427 | Z21: 2.33699 | AA21: 2.32513 | AB21: 2.318443 | AC21: 2.309026 | AD21: 2.304834 | AE21: 2.295233 | AF21: 2.274688 | AG21: -0.000209
A22: SUP000:ba_Biomass | B22: Biomass 3/ | C22: 4.70119 | D22: 4.833665 | E22: 4.736951 | F22: 4.731843 | G22: 4.751482 | H22: 4.740038 | I22: 4.728146 | J22: 4.706775 | K22: 4.708263 | L22: 4.6997 | M22: 4.688527 | N22: 4.681827 | O22: 4.666749 | P22: 4.654086 | Q22: 4.648972 | R22: 4.641438 | S22: 4.63418 | T22: 4.638316 | U22: 4.647457 | V22: 4.683486 | W22: 4.705445 | X22: 4.722157 | Y22: 4.748343 | Z22: 4.791994 | AA22: 4.814004 | AB22: 4.843565 | AC22: 4.876688 | AD22: 4.909999 | AE22: 4.942437 | AF22: 4.984637 | AG22: 0.002021
A23: SUP000:ba_RenewableEner | B23: Other Renewable Energy 4/ | C23: 4.839005 | D23: 5.544484 | E23: 6.085557 | F23: 6.989227 | G23: 7.561359 | H23: 7.846316 | I23: 8.347466 | J23: 8.5777 | K23: 8.787159 | L23: 9.155986 | M23: 9.41178 | N23: 9.649215 | O23: 9.910384 | P23: 10.464489 | Q23: 11.17978 | R23: 11.560812 | S23: 11.709242 | T23: 11.735645 | U23: 11.787336 | V23: 11.864063 | W23: 11.965893 | X23: 12.084974 | Y23: 12.202391 | Z23: 12.369851 | AA23: 12.586577 | AB23: 12.70438 | AC23: 12.871214 | AD23: 13.03612 | AE23: 13.182046 | AF23: 13.273847 | AG23: 0.035408
A24: SUP000:ba_Other | B24: Other 5/ | C24: 2.133576 | D24: 1.012973 | E24: 0.879855 | F24: 0.894946 | G24: 0.774271 | H24: 0.88321 | I24: 0.8699 | J24: 0.796129 | K24: 0.770551 | L24: 0.770231 | M24: 0.768565 | N24: 0.632673 | O24: 0.631935 | P24: 0.640565 | Q24: 0.637551 | R24: 0.647367 | S24: 0.651814 | T24: 0.653633 | U24: 0.651491 | V24: 0.642037 | W24: 0.639621 | X24: 0.634056 | Y24: 0.627797 | Z24: 0.632698 | AA24: 0.626717 | AB24: 0.618566 | AC24: 0.61455 | AD24: 0.621078 | AE24: 0.628376 | AF24: 0.623335 | AG24: -0.041542
A25: SUP000:ba_Total | B25: Total | C25: 101.0359 | D25: 103.61195 | E25: 105.53733 | F25: 106.1191 | G25: 107.18489 | H25: 107.72357 | I25: 107.50348 | J25: 107.9248 | K25: 108.25434 | L25: 108.51576 | M25: 108.72144 | N25: 108.80585 | O25: 108.71499 | P25: 108.42783 | Q25: 108.49642 | R25: 108.43117 | S25: 108.23811 | T25: 108.29774 | U25: 108.59257 | V25: 109.01973 | W25: 109.08175 | X25: 109.38576 | Y25: 109.84454 | Z25: 110.14797 | AA25: 110.90757 | AB25: 111.43774 | AC25: 111.86885 | AD25: 112.08251 | AE25: 112.10244 | AF25: 113.39367 | AG25: 0.003987
B27: Imports
A28: SUP000:ca_CrudeOil | B28: Crude Oil | C28: 13.849983 | D28: 16.37085 | E28: 16.629141 | F28: 15.971055 | G28: 15.230758 | H28: 14.679036 | I28: 14.643375 | J28: 14.357627 | K28: 14.264916 | L28: 14.200821 | M28: 14.399286 | N28: 14.778255 | O28: 14.611301 | P28: 14.955673 | Q28: 15.036996 | R28: 15.363056 | S28: 15.527345 | T28: 15.740888 | U28: 15.813135 | V28: 15.458242 | W28: 15.443821 | X28: 15.243117 | Y28: 14.882616 | Z28: 15.204732 | AA28: 14.507174 | AB28: 14.091373 | AC28: 13.903984 | AD28: 14.131474 | AE28: 14.48548 | AF28: 13.759513 | AG28: -0.000226
A29: SUP000:ca_PetroleumProd | B29: Petroleum and Other Liquids 6/ | C29: 4.715964 | D29: 4.470991 | E29: 3.845002 | F29: 3.923882 | G29: 4.01288 | H29: 3.965475 | I29: 3.914824 | J29: 3.83206 | K29: 3.720322 | L29: 3.693734 | M29: 3.634232 | N29: 3.635437 | O29: 3.59495 | P29: 3.562899 | Q29: 3.543973 | R29: 3.497625 | S29: 3.494834 | T29: 3.505317 | U29: 3.501205 | V29: 3.483078 | W29: 3.503401 | X29: 3.506699 | Y29: 3.514882 | Z29: 3.52966 | AA29: 3.55301 | AB29: 3.566257 | AC29: 3.599412 | AD29: 3.686488 | AE29: 3.677653 | AF29: 3.64243 | AG29: -0.008867
A30: SUP000:ca_NaturalGas | B30: Natural Gas | C30: 2.798295 | D30: 2.540921 | E30: 2.459869 | F30: 2.356853 | G30: 2.282891 | H30: 2.256741 | I30: 2.221225 | J30: 2.170627 | K30: 2.036805 | L30: 1.983411 | M30: 1.890747 | N30: 1.878801 | O30: 1.924771 | P30: 1.886512 | Q30: 1.844462 | R30: 1.839028 | S30: 1.873339 | T30: 1.870136 | U30: 1.839986 | V30: 1.805083 | W30: 1.780095 | X30: 1.772161 | Y30: 1.710783 | Z30: 1.587325 | AA30: 1.509457 | AB30: 1.489166 | AC30: 1.460802 | AD30: 1.464388 | AE30: 1.431648 | AF30: 1.387205 | AG30: -0.023907
A31: SUP000:ca_OtherImports | B31: Other 7/ | C31: 0.290388 | D31: 0.22012 | E31: 0.1165 | F31: 0.120814 | G31: 0.110212 | H31: 0.115351 | I31: 0.128298 | J31: 0.136961 | K31: 0.138309 | L31: 0.145788 | M31: 0.137366 | N31: 0.141914 | O31: 0.134995 | P31: 0.140072 | Q31: 0.137182 | R31: 0.136788 | S31: 0.131592 | T31: 0.13375 | U31: 0.134478 | V31: 0.136204 | W31: 0.131303 | X31: 0.131657 | Y31: 0.139108 | Z31: 0.138671 | AA31: 0.134569 | AB31: 0.134666 | AC31: 0.134403 | AD31: 0.13461 | AE31: 0.13483 | AF31: 0.135472 | AG31: -0.025949
A32: SUP000:ca_Total | B32: Total | C32: 21.654629 | D32: 23.602882 | E32: 23.05051 | F32: 22.372604 | G32: 21.63674 | H32: 21.016602 | I32: 20.907722 | J32: 20.497274 | K32: 20.160353 | L32: 20.023756 | M32: 20.06163 | N32: 20.434408 | O32: 20.266016 | P32: 20.545156 | Q32: 20.562613 | R32: 20.836498 | S32: 21.027109 | T32: 21.250092 | U32: 21.288803 | V32: 20.882607 | W32: 20.85862 | X32: 20.653633 | Y32: 20.247391 | Z32: 20.460388 | AA32: 19.70421 | AB32: 19.281464 | AC32: 19.098602 | AD32: 19.41696 | AE32: 19.729612 | AF32: 18.92462 | AG32: -0.004636
B34: Exports
A35: SUP000:da_Petroleum | B35: Petroleum and Other Liquids 8/ | C35: 16.73385 | D35: 18.356298 | E35: 19.182388 | F35: 19.602926 | G35: 19.941938 | H35: 19.903315 | I35: 19.849981 | J35: 19.863663 | K35: 19.811287 | L35: 19.834377 | M35: 19.808157 | N35: 19.842936 | O35: 19.662491 | P35: 19.775711 | Q35: 19.81488 | R35: 19.950239 | S35: 19.816631 | T35: 19.884661 | U35: 19.983006 | V35: 19.83169 | W35: 19.682125 | X35: 19.486174 | Y35: 19.221823 | Z35: 19.413261 | AA35: 19.138691 | AB35: 18.841377 | AC35: 18.655954 | AD35: 18.810968 | AE35: 18.771133 | AF35: 18.527115 | AG35: 0.003517
A36: SUP000:da_NaturalGas | B36: Natural Gas | C36: 6.809672 | D36: 7.579476 | E36: 7.788739 | F36: 7.875538 | G36: 8.095082 | H36: 8.109738 | I36: 8.24765 | J36: 8.540207 | K36: 8.791788 | L36: 9.023255 | M36: 9.300149 | N36: 9.552501 | O36: 9.670875 | P36: 9.714972 | Q36: 9.777483 | R36: 9.799871 | S36: 9.798469 | T36: 9.820782 | U36: 9.84569 | V36: 9.881186 | W36: 9.868215 | X36: 9.885421 | Y36: 9.895191 | Z36: 9.93121 | AA36: 9.928005 | AB36: 9.911631 | AC36: 9.899729 | AD36: 9.904961 | AE36: 9.876596 | AF36: 9.8705 | AG36: 0.012882
A37: SUP000:da_Coal | B37: Coal | C37: 2.253399 | D37: 2.300418 | E37: 2.924233 | F37: 2.806449 | G37: 2.745555 | H37: 2.878079 | I37: 2.822221 | J37: 2.814723 | K37: 2.789355 | L37: 2.781176 | M37: 2.809537 | N37: 2.864769 | O37: 2.790718 | P37: 2.767172 | Q37: 2.793478 | R37: 2.759903 | S37: 2.751223 | T37: 2.785581 | U37: 2.726024 | V37: 2.735147 | W37: 2.71931 | X37: 2.734332 | Y37: 2.698877 | Z37: 2.698676 | AA37: 2.712163 | AB37: 2.696237 | AC37: 2.690248 | AD37: 2.71199 | AE37: 2.722844 | AF37: 2.737185 | AG37: 0.006729
A38: SUP000:da_Total | B38: Total | C38: 25.796921 | D38: 28.236191 | E38: 29.895359 | F38: 30.284914 | G38: 30.782578 | H38: 30.891132 | I38: 30.919853 | J38: 31.218594 | K38: 31.392429 | L38: 31.638807 | M38: 31.917843 | N38: 32.260204 | O38: 32.124084 | P38: 32.257858 | Q38: 32.385841 | R38: 32.510014 | S38: 32.366325 | T38: 32.491024 | U38: 32.554718 | V38: 32.448021 | W38: 32.26965 | X38: 32.105927 | Y38: 31.815891 | Z38: 32.043148 | AA38: 31.778858 | AB38: 31.449245 | AC38: 31.245932 | AD38: 31.427919 | AE38: 31.370575 | AF38: 31.1348 | AG38: 0.006506
A40: SUP000:ea_Discrepancy | B40: Discrepancy 9/ | C40: -0.09956 | D40: 1.014343 | E40: 0.351906 | F40: 0.371489 | G40: 0.341177 | H40: 0.382046 | I40: 0.381279 | J40: 0.35734 | K40: 0.386271 | L40: 0.381487 | M40: 0.400639 | N40: 0.433743 | O40: 0.415009 | P40: 0.413139 | Q40: 0.417732 | R40: 0.407967 | S40: 0.411499 | T40: 0.408596 | U40: 0.402512 | V40: 0.377655 | W40: 0.373608 | X40: 0.358025 | Y40: 0.344402 | Z40: 0.348759 | AA40: 0.320744 | AB40: 0.279781 | AC40: 0.300562 | AD40: 0.304501 | AE40: 0.307432 | AF40: 0.309587 | AG40: --
B42: Consumption
A43: SUP000:fa_PetroleumProd | B43: Petroleum and Other Liquids 10/ | C43: 36.03891 | D43: 36.753876 | E43: 37.164867 | F43: 37.008743 | G43: 36.993271 | H43: 36.890812 | I43: 36.698307 | J43: 36.579685 | K43: 36.420643 | L43: 36.309967 | M43: 36.218292 | N43: 36.215271 | O43: 36.163837 | P43: 36.030983 | Q43: 35.914291 | R43: 35.832382 | S43: 35.810936 | T43: 35.784924 | U43: 35.813648 | V43: 35.779423 | W43: 35.801689 | X43: 35.841454 | Y43: 35.887527 | Z43: 35.903362 | AA43: 35.944035 | AB43: 36.088379 | AC43: 36.201035 | AD43: 36.273766 | AE43: 36.392872 | AF43: 36.628178 | AG43: 0.000559
A44: SUP000:fa_NaturalGas | B44: Natural Gas | C44: 31.361422 | D44: 31.199945 | E44: 31.177605 | F44: 31.16921 | G44: 30.965534 | H44: 30.880772 | I44: 30.613737 | J44: 30.871202 | K44: 30.754141 | L44: 30.537725 | M44: 30.416206 | N44: 30.414434 | O44: 30.607912 | P44: 30.353966 | Q44: 30.106274 | R44: 30.03334 | S44: 30.184532 | T44: 30.381096 | U44: 30.592625 | V44: 30.803253 | W44: 30.909266 | X44: 31.077223 | Y44: 31.346886 | Z44: 31.509253 | AA44: 31.678867 | AB44: 31.934574 | AC44: 32.173542 | AD44: 32.373512 | AE44: 32.546021 | AF44: 32.886066 | AG44: 0.001638
A45: SUP000:fa_Coal | B45: Coal 11/ | C45: 10.883375 | D45: 10.484755 | E45: 9.873912 | F45: 8.510278 | G45: 8.140191 | H45: 7.937951 | I45: 7.705096 | J45: 7.669232 | K45: 7.61521 | L45: 7.464706 | M45: 7.393437 | N45: 7.246166 | O45: 7.293676 | P45: 6.99925 | Q45: 6.700851 | R45: 6.583507 | S45: 6.461794 | T45: 6.44173 | U45: 6.426641 | V45: 6.337152 | W45: 6.326757 | X45: 6.277361 | Y45: 6.194617 | Z45: 6.127982 | AA45: 6.00381 | AB45: 5.957881 | AC45: 5.866497 | AD45: 5.765072 | AE45: 5.717658 | AF45: 5.766378 | AG45: -0.021665
A46: SUP000:fa_NuclearPower | B46: Nuclear / Uranium 2/ | C46: 8.12115 | D46: 8.183111 | E46: 8.202579 | F46: 8.239058 | G46: 8.163899 | H46: 8.075755 | I46: 7.930267 | J46: 7.368946 | K46: 7.299504 | L46: 7.307006 | M46: 7.318423 | N46: 7.326343 | O46: 6.808416 | P46: 6.815667 | Q46: 6.747447 | R46: 6.758354 | S46: 6.760554 | T46: 6.762659 | U46: 6.762759 | V46: 6.766273 | W46: 6.77936 | X46: 6.788805 | Y46: 6.797936 | Z46: 6.805902 | AA46: 6.814445 | AB46: 6.818903 | AC46: 6.823349 | AD46: 6.826119 | AE46: 6.829472 | AF46: 6.834313 | AG46: -0.005931
A47: SUP000:fa_Hydropower | B47: Conventional Hydroelectric Power | C47: 2.288529 | D47: 2.39653 | E47: 2.520376 | F47: 2.607582 | G47: 2.562303 | H47: 2.533515 | I47: 2.5148 | J47: 2.494481 | K47: 2.48263 | L47: 2.471396 | M47: 2.456771 | N47: 2.450083 | O47: 2.436512 | P47: 2.4271 | Q47: 2.410605 | R47: 2.397023 | S47: 2.392663 | T47: 2.381657 | U47: 2.376802 | V47: 2.37014 | W47: 2.362096 | X47: 2.354189 | Y47: 2.3427 | Z47: 2.33699 | AA47: 2.32513 | AB47: 2.318443 | AC47: 2.309026 | AD47: 2.304834 | AE47: 2.295233 | AF47: 2.274688 | AG47: -0.000209
A48: SUP000:fa_Biomass | B48: Biomass 12/ | C48: 3.124412 | D48: 3.124567 | E48: 3.05355 | F48: 3.045954 | G48: 3.05583 | H48: 3.041447 | I48: 3.026574 | J48: 3.002259 | K48: 2.992482 | L48: 2.980528 | M48: 2.965883 | N48: 2.956268 | O48: 2.939253 | P48: 2.923384 | Q48: 2.911871 | R48: 2.900167 | S48: 2.888609 | T48: 2.879169 | U48: 2.882052 | V48: 2.872139 | W48: 2.872755 | X48: 2.872178 | Y48: 2.879459 | Z48: 2.883198 | AA48: 2.883371 | AB48: 2.891699 | AC48: 2.900502 | AD48: 2.911157 | AE48: 2.913831 | AF48: 2.933004 | AG48: -0.002178
A49: SUP000:fa_RenewableEner | B49: Other Renewable Energy 4/ | C49: 4.839005 | D49: 5.544484 | E49: 6.085557 | F49: 6.989227 | G49: 7.561359 | H49: 7.846316 | I49: 8.347466 | J49: 8.5777 | K49: 8.787159 | L49: 9.155986 | M49: 9.41178 | N49: 9.649215 | O49: 9.910384 | P49: 10.464489 | Q49: 11.17978 | R49: 11.560812 | S49: 11.709242 | T49: 11.735645 | U49: 11.787336 | V49: 11.864063 | W49: 11.965893 | X49: 12.084974 | Y49: 12.202391 | Z49: 12.369851 | AA49: 12.586577 | AB49: 12.70438 | AC49: 12.871214 | AD49: 13.03612 | AE49: 13.182046 | AF49: 13.273847 | AG49: 0.035408
...

Sheet AEO 2023 Table 1
B1: ref2023.d020623a | C1: 2022 | D1: 2023 | E1: 2024 | F1: 2025 | G1: 2026 | H1: 2027 | I1: 2028 | J1: 2029 | K1: 2030 | L1: 2031 | M1: 2032 | N1: 2033 | O1: 2034 | P1: 2035 | Q1: 2036 | R1: 2037 | S1: 2038 | T1: 2039 | U1: 2040 | V1: 2041 | W1: 2042 | X1: 2043 | Y1: 2044 | Z1: 2045 | AA1: 2046 | AB1: 2047 | AC1: 2048 | AD1: 2049 | AE1: 2050
C3: Report | D3: Annual Energy Outlook 2023
C4: Scenario | D4: ref2023 | G4: Reference
C5: Datekey | D5: d020623a
C6: Release Date | E6: March 2023
A10: SUP000 | B10: 1. Total Energy Supply, Disposition, and Price Summary | AF10: Average
B11: (quadrillion Btu, unless otherwise noted) | AF11: Annual
AF12: Change
B13: Supply, Disposition, and Prices | C13: 2022 | D13: 2023 | E13: 2024 | F13: 2025 | G13: 2026 | H13: 2027 | I13: 2028 | J13: 2029 | K13: 2030 | L13: 2031 | M13: 2032 | N13: 2033 | O13: 2034 | P13: 2035 | Q13: 2036 | R13: 2037 | S13: 2038 | T13: 2039 | U13: 2040 | V13: 2041 | W13: 2042 | X13: 2043 | Y13: 2044 | Z13: 2045 | AA13: 2046 | AB13: 2047 | AC13: 2048 | AD13: 2049 | AE13: 2050 | AF13: 2022–2050
B15: Production
A16: SUP000:ba_CrudeOilLease | B16: Crude Oil and Lease Condensate | C16: 24.586992 | D16: 25.571161 | E16: 26.28504 | F16: 26.689157 | G16: 27.061613 | H16: 27.276854 | I16: 27.645002 | J16: 27.607613 | K16: 27.657637 | L16: 27.504726 | M16: 27.566185 | N16: 27.626516 | O16: 27.525274 | P16: 27.454479 | Q16: 27.324806 | R16: 27.286285 | S16: 27.180134 | T16: 27.06955 | U16: 26.857201 | V16: 26.565493 | W16: 26.618496 | X16: 26.76222 | Y16: 27.042204 | Z16: 27.108969 | AA16: 27.167717 | AB16: 26.948446 | AC16: 27.031092 | AD16: 27.320032 | AE16: 27.390823 | AF16: 0.003864
A17: SUP000:ba_NaturalGasPla | B17: Natural Gas Plant Liquids | C17: 7.768493 | D17: 8.169656 | E17: 8.33212 | F17: 8.311151 | G17: 8.472385 | H17: 8.339916 | I17: 8.228629 | J17: 8.126106 | K17: 8.05903 | L17: 8.040661 | M17: 8.113167 | N17: 8.167894 | O17: 8.280707 | P17: 8.339736 | Q17: 8.463762 | R17: 8.517173 | S17: 8.518053 | T17: 8.645661 | U17: 8.632603 | V17: 8.691146 | W17: 8.843096 | X17: 8.967008 | Y17: 9.032116 | Z17: 9.079972 | AA17: 9.143809 | AB17: 9.19521 | AC17: 9.236042 | AD17: 9.282736 | AE17: 9.310446 | AF17: 0.006487
A18: SUP000:ba_DryNaturalGas | B18: Dry Natural Gas | C18: 37.814274 | D18: 37.835823 | E18: 36.882996 | F18: 37.047318 | G18: 37.522251 | H18: 37.473186 | I18: 37.786018 | J18: 38.036835 | K18: 38.406055 | L18: 38.853168 | M18: 39.378105 | N18: 39.977421 | O18: 40.490608 | P18: 40.958794 | Q18: 41.332081 | R18: 41.707432 | S18: 41.989216 | T18: 42.240601 | U18: 42.38311 | V18: 42.506451 | W18: 42.687958 | X18: 42.804451 | Y18: 42.884609 | Z18: 43.041492 | AA18: 42.870251 | AB18: 43.082157 | AC18: 43.152935 | AD18: 43.235588 | AE18: 43.621796 | AF18: 0.005116
A19: SUP000:ba_Coal | B19: Coal 1/ | C19: 11.789563 | D19: 11.071955 | E19: 12.067057 | F19: 11.332017 | G19: 10.370732 | H19: 9.303524 | I19: 8.355421 | J19: 7.463985 | K19: 7.094864 | L19: 7.063365 | M19: 7.113411 | N19: 7.082268 | O19: 7.01697 | P19: 7.068785 | Q19: 6.985933 | R19: 6.801968 | S19: 6.692012 | T19: 6.533113 | U19: 6.437759 | V19: 6.442639 | W19: 6.454122 | X19: 6.36397 | Y19: 6.262532 | Z19: 6.188755 | AA19: 6.119871 | AB19: 6.087613 | AC19: 6.069883 | AD19: 6.032045 | AE19: 5.945596 | AF19: -0.024152
A20: SUP000:ba_NuclearPower | B20: Nuclear / Uranium 2/ | C20: 8.064654 | D20: 8.187211 | E20: 8.246629 | F20: 8.171966 | G20: 8.092857 | H20: 8.092719 | I20: 7.997469 | J20: 7.99734 | K20: 7.918744 | L20: 7.918797 | M20: 7.918885 | N20: 7.47281 | O20: 7.403218 | P20: 7.313933 | Q20: 7.145817 | R20: 7.031636 | S20: 6.837198 | T20: 6.734248 | U20: 6.533641 | V20: 6.535408 | W20: 6.538529 | X20: 6.541202 | Y20: 6.544166 | Z20: 6.544192 | AA20: 6.541663 | AB20: 6.539629 | AC20: 6.530636 | AD20: 6.531871 | AE20: 6.527707 | AF20: -0.007523
A21: SUP000:ba_Hydropower | B21: Conventional Hydroelectric Power | C21: 2.453454 | D21: 2.458462 | E21: 2.502563 | F21: 2.588684 | G21: 2.579723 | H21: 2.556826 | I21: 2.515381 | J21: 2.486196 | K21: 2.457424 | L21: 2.43646 | M21: 2.419676 | N21: 2.422381 | O21: 2.426406 | P21: 2.429998 | Q21: 2.435315 | R21: 2.423512 | S21: 2.41015 | T21: 2.386208 | U21: 2.381421 | V21: 2.366141 | W21: 2.369409 | X21: 2.362637 | Y21: 2.357599 | Z21: 2.354464 | AA21: 2.343242 | AB21: 2.336414 | AC21: 2.334075 | AD21: 2.320942 | AE21: 2.309024 | AF21: -0.002164
A22: SUP000:ba_Biomass | B22: Biomass 3/ | C22: 4.838805 | D22: 5.032741 | E22: 4.964215 | F22: 4.912142 | G22: 4.886052 | H22: 4.875721 | I22: 4.769737 | J22: 4.767001 | K22: 4.765035 | L22: 4.767915 | M22: 4.773014 | N22: 4.782948 | O22: 4.793034 | P22: 4.817472 | Q22: 4.818559 | R22: 4.826615 | S22: 4.834418 | T22: 4.844079 | U22: 4.857975 | V22: 4.892778 | W22: 4.909179 | X22: 4.92593 | Y22: 4.924026 | Z22: 4.93202 | AA22: 4.970815 | AB22: 5.019265 | AC22: 5.10552 | AD22: 5.154455 | AE22: 5.188916 | AF22: 0.002498
A23: SUP000:ba_RenewableEner | B23: Other Renewable Energy 4/ | C23: 5.622848 | D23: 6.12555 | E23: 6.742159 | F23: 8.173244 | G23: 9.907674 | H23: 11.653165 | I23: 13.154488 | J23: 14.209772 | K23: 15.128234 | L23: 15.78889 | M23: 16.442295 | N23: 17.189573 | O23: 17.791294 | P23: 18.262888 | Q23: 18.746868 | R23: 19.110622 | S23: 19.414564 | T23: 19.60931 | U23: 19.90523 | V23: 20.063116 | W23: 20.302187 | X23: 20.584305 | Y23: 20.993839 | Z23: 21.370592 | AA23: 21.805227 | AB23: 22.17202 | AC23: 22.539532 | AD23: 22.84026 | AE23: 23.283979 | AF23: 0.052057
A24: SUP000:ba_Other | B24: Other 5/ | C24: 1.82513 | D24: 1.234037 | E24: 0.928669 | F24: 0.803857 | G24: 0.909898 | H24: 0.90237 | I24: 0.841003 | J24: 0.828401 | K24: 0.836635 | L24: 0.837526 | M24: 0.71289 | N24: 0.708538 | O24: 0.71509 | P24: 0.709654 | Q24: 0.706237 | R24: 0.703952 | S24: 0.704838 | T24: 0.704036 | U24: 0.700627 | V24: 0.702727 | W24: 0.700445 | X24: 0.699926 | Y24: 0.700781 | Z24: 0.700645 | AA24: 0.677574 | AB24: 0.674621 | AC24: 0.677692 | AD24: 0.678272 | AE24: 0.675773 | AF24: -0.034862
A25: SUP000:ba_Total | B25: Total | C25: 104.76421 | D25: 105.6866 | E25: 106.95145 | F25: 108.02953 | G25: 109.80318 | H25: 110.47428 | I25: 111.29315 | J25: 111.52324 | K25: 112.32366 | L25: 113.21151 | M25: 114.43762 | N25: 115.43036 | O25: 116.4426 | P25: 117.35574 | Q25: 117.95938 | R25: 118.4092 | S25: 118.58059 | T25: 118.76679 | U25: 118.68956 | V25: 118.76591 | W25: 119.42342 | X25: 120.01164 | Y25: 120.74187 | Z25: 121.3211 | AA25: 121.64017 | AB25: 122.05538 | AC25: 122.67742 | AD25: 123.39619 | AE25: 124.25407 | AF25: 0.006112
B27: Imports
A28: SUP000:ca_CrudeOil | B28: Crude Oil | C28: 13.824968 | D28: 14.777425 | E28: 15.446031 | F28: 15.30518 | G28: 15.0045 | H28: 15.261106 | I28: 15.230433 | J28: 15.49168 | K28: 15.589063 | L28: 15.686406 | M28: 15.720078 | N28: 15.538974 | O28: 15.709466 | P28: 15.851457 | Q28: 15.843707 | R28: 15.807153 | S28: 15.874156 | T28: 15.984639 | U28: 16.045517 | V28: 16.390509 | W28: 16.327881 | X28: 16.155361 | Y28: 15.890744 | Z28: 15.766374 | AA28: 15.490686 | AB28: 15.523278 | AC28: 15.392778 | AD28: 15.059613 | AE28: 14.806977 | AF28: 0.002454
A29: SUP000:ca_PetroleumProd | B29: Petroleum and Other Liquids 6/ | C29: 4.758858 | D29: 4.839342 | E29: 4.030089 | F29: 4.034095 | G29: 4.035874 | H29: 3.992856 | I29: 3.913863 | J29: 3.837766 | K29: 3.804423 | L29: 3.806296 | M29: 3.740932 | N29: 3.718116 | O29: 3.68477 | P29: 3.681871 | Q29: 3.670537 | R29: 3.681304 | S29: 3.685072 | T29: 3.692872 | U29: 3.702409 | V29: 3.723368 | W29: 3.718675 | X29: 3.725362 | Y29: 3.717126 | Z29: 3.747543 | AA29: 3.722438 | AB29: 3.744125 | AC29: 3.816768 | AD29: 3.836668 | AE29: 3.767644 | AF29: -0.008307
A30: SUP000:ca_NaturalGas | B30: Natural Gas | C30: 2.981649 | D30: 2.808482 | E30: 2.461069 | F30: 2.35087 | G30: 2.25211 | H30: 2.184048 | I30: 2.073739 | J30: 2.040553 | K30: 2.072865 | L30: 2.06794 | M30: 2.11868 | N30: 2.137902 | O30: 2.141702 | P30: 2.125696 | Q30: 2.080384 | R30: 2.079351 | S30: 2.136969 | T30: 2.11006 | U30: 2.231398 | V30: 2.256781 | W30: 2.269709 | X30: 2.318002 | Y30: 2.40196 | Z30: 2.477401 | AA30: 2.508059 | AB30: 2.53545 | AC30: 2.582582 | AD30: 2.599269 | AE30: 2.627204 | AF30: -0.00451
A31: SUP000:ca_OtherImports | B31: Other 7/ | C31: 0.25367 | D31: 0.337121 | E31: 0.14549 | F31: 0.130841 | G31: 0.141319 | H31: 0.155275 | I31: 0.177303 | J31: 0.169148 | K31: 0.176284 | L31: 0.166932 | M31: 0.170314 | N31: 0.169336 | O31: 0.170398 | P31: 0.165942 | Q31: 0.164005 | R31: 0.163859 | S31: 0.167017 | T31: 0.16908 | U31: 0.170614 | V31: 0.166044 | W31: 0.165721 | X31: 0.163252 | Y31: 0.161465 | Z31: 0.158517 | AA31: 0.155057 | AB31: 0.154695 | AC31: 0.157649 | AD31: 0.15918 | AE31: 0.157261 | AF31: -0.016931
A32: SUP000:ca_Total | B32: Total | C32: 21.819145 | D32: 22.762371 | E32: 22.08268 | F32: 21.820986 | G32: 21.433804 | H32: 21.593285 | I32: 21.395336 | J32: 21.539146 | K32: 21.642633 | L32: 21.727573 | M32: 21.750002 | N32: 21.564329 | O32: 21.706337 | P32: 21.824965 | Q32: 21.758633 | R32: 21.731667 | S32: 21.863213 | T32: 21.956652 | U32: 22.149939 | V32: 22.536701 | W32: 22.481985 | X32: 22.361977 | Y32: 22.171295 | Z32: 22.149836 | AA32: 21.876242 | AB32: 21.957548 | AC32: 21.949778 | AD32: 21.654732 | AE32: 21.359085 | AF32: -0.000761
B34: Exports
A35: SUP000:da_Petroleum | B35: Petroleum and Other Liquids 8/ | C35: 18.53616 | D35: 19.04047 | E35: 20.328047 | F35: 20.57988 | G35: 21.071783 | H35: 21.489708 | I35: 21.636562 | J35: 21.880472 | K35: 22.202881 | L35: 22.327625 | M35: 22.464676 | N35: 22.515352 | O35: 22.756023 | P35: 22.978777 | Q35: 23.076605 | R35: 23.112068 | S35: 23.121672 | T35: 23.267797 | U35: 23.053844 | V35: 23.139196 | W35: 23.210157 | X35: 23.236942 | Y35: 23.218386 | Z35: 23.136253 | AA35: 22.799206 | AB35: 22.53091 | AC35: 22.513948 | AD35: 22.402639 | AE35: 21.931286 | AF35: 0.006025
A36: SUP000:da_NaturalGas | B36: Natural Gas | C36: 7.157014 | D36: 7.945881 | E36: 7.943815 | F36: 8.33703 | G36: 8.842743 | H36: 9.263846 | I36: 9.664758 | J36: 10.022476 | K36: 10.671082 | L36: 11.372363 | M36: 12.069704 | N36: 12.747917 | O36: 13.325287 | P36: 13.720263 | Q36: 13.973807 | R36: 14.186524 | S36: 14.301539 | T36: 14.335634 | U36: 14.360343 | V36: 14.349729 | W36: 14.358644 | X36: 14.365799 | Y36: 14.408306 | Z36: 14.392715 | AA36: 14.375298 | AB36: 14.355018 | AC36: 14.358721 | AD36: 14.323404 | AE36: 14.304577 | AF36: 0.02504
A37: SUP000:da_Coal | B37: Coal | C37: 2.154573 | D37: 2.143556 | E37: 2.779966 | F37: 2.715976 | G37: 2.848135 | H37: 2.810707 | I37: 2.822736 | J37: 2.808787 | K37: 2.810107 | L37: 2.838428 | M37: 2.89129 | N37: 2.819009 | O37: 2.79456 | P37: 2.821391 | Q37: 2.784587 | R37: 2.726998 | S37: 2.770777 | T37: 2.712615 | U37: 2.722989 | V37: 2.708216 | W37: 2.723382 | X37: 2.690624 | Y37: 2.694831 | Z37: 2.703859 | AA37: 2.688675 | AB37: 2.682404 | AC37: 2.70565 | AD37: 2.707865 | AE37: 2.723995 | AF37: 0.00841
A38: SUP000:da_Total | B38: Total | C38: 27.847746 | D38: 29.129908 | E38: 31.051828 | F38: 31.632887 | G38: 32.762661 | H38: 33.564262 | I38: 34.124054 | J38: 34.711735 | K38: 35.684071 | L38: 36.538418 | M38: 37.425667 | N38: 38.082275 | O38: 38.87587 | P38: 39.520432 | Q38: 39.834999 | R38: 40.025589 | S38: 40.193985 | T38: 40.316048 | U38: 40.137177 | V38: 40.197144 | W38: 40.292183 | X38: 40.293365 | Y38: 40.321526 | Z38: 40.232826 | AA38: 39.863178 | AB38: 39.568333 | AC38: 39.57832 | AD38: 39.43391 | AE38: 38.959858 | AF38: 0.012064
A40: SUP000:ea_Discrepancy | B40: Discrepancy 9/ | C40: -0.457861 | D40: 0.97529 | E40: 0.423643 | F40: 0.464403 | G40: 0.459312 | H40: 0.424484 | I40: 0.430447 | J40: 0.294971 | K40: 0.325535 | L40: 0.400856 | M40: 0.449509 | N40: 0.447327 | O40: 0.453705 | P40: 0.532143 | Q40: 0.48624 | R40: 0.46405 | S40: 0.455482 | T40: 0.450829 | U40: 0.450035 | V40: 0.45557 | W40: 0.44809 | X40: 0.438515 | Y40: 0.440971 | Z40: 0.547066 | AA40: 0.476925 | AB40: 0.612675 | AC40: 0.563404 | AD40: 0.513699 | AE40: 0.713924 | AF40: --
B42: Consumption
A43: SUP000:fa_PetroleumProd | B43: Petroleum and Other Liquids 10/ | C43: 36.816776 | D43: 36.981636 | E43: 36.540516 | F43: 36.38258 | G43: 36.236435 | H43: 36.093872 | I43: 35.925087 | J43: 35.71246 | K43: 35.460438 | L43: 35.244152 | M43: 35.085304 | N43: 34.948364 | O43: 34.86829 | P43: 34.774864 | Q43: 34.660748 | R43: 34.614304 | S43: 34.581387 | T43: 34.574551 | U43: 34.635841 | V43: 34.700855 | W43: 34.772816 | X43: 34.84396 | Y43: 34.938004 | Z43: 35.050571 | AA43: 35.202904 | AB43: 35.394215 | AC43: 35.548607 | AD43: 35.727844 | AE43: 35.995079 | AF43: -0.000806
A44: SUP000:fa_NaturalGas | B44: Natural Gas | C44: 33.183849 | D44: 31.975372 | E44: 30.744192 | F44: 30.454859 | G44: 30.362862 | H44: 29.860353 | I44: 29.690903 | J44: 29.540802 | K44: 29.285072 | L44: 29.002975 | M44: 28.86751 | N44: 28.778568 | O44: 28.707445 | P44: 28.712893 | Q44: 28.819685 | R44: 28.978542 | S44: 29.210226 | T44: 29.397072 | U44: 29.632147 | V44: 29.788446 | W44: 29.983868 | X44: 30.153929 | Y44: 30.279633 | Z44: 30.429348 | AA44: 30.410452 | AB44: 30.539183 | AC44: 30.747511 | AD44: 30.902693 | AE44: 31.130543 | AF44: -0.002279
A45: SUP000:fa_Coal | B45: Coal 11/ | C45: 9.694483 | D45: 9.040522 | E45: 9.411029 | F45: 8.647058 | G45: 7.516863 | H45: 6.501535 | I45: 5.529372 | J45: 4.801684 | K45: 4.396944 | L45: 4.30778 | M45: 4.272085 | N45: 4.338585 | O45: 4.299617 | P45: 4.302522 | Q45: 4.260971 | R45: 4.161004 | S45: 4.002717 | T45: 3.909357 | U45: 3.806856 | V45: 3.824085 | W45: 3.815112 | X45: 3.763251 | Y45: 3.645989 | Z45: 3.548136 | AA45: 3.463649 | AB45: 3.422932 | AC45: 3.33322 | AD45: 3.31122 | AE45: 3.208326 | AF45: -0.038723
A46: SUP000:fa_NuclearPower | B46: Nuclear / Uranium 2/ | C46: 8.064654 | D46: 8.187211 | E46: 8.246629 | F46: 8.171966 | G46: 8.092857 | H46: 8.092719 | I46: 7.997469 | J46: 7.99734 | K46: 7.918744 | L46: 7.918797 | M46: 7.918885 | N46: 7.47281 | O46: 7.403218 | P46: 7.313933 | Q46: 7.145817 | R46: 7.031636 | S46: 6.837198 | T46: 6.734248 | U46: 6.533641 | V46: 6.535408 | W46: 6.538529 | X46: 6.541202 | Y46: 6.544166 | Z46: 6.544192 | AA46: 6.541663 | AB46: 6.539629 | AC46: 6.530636 | AD46: 6.531871 | AE46: 6.527707 | AF46: -0.007523
A47: SUP000:fa_Hydropower | B47: Conventional Hydroelectric Power | C47: 2.453454 | D47: 2.458462 | E47: 2.502563 | F47: 2.588684 | G47: 2.579723 | H47: 2.556826 | I47: 2.515381 | J47: 2.486196 | K47: 2.457424 | L47: 2.43646 | M47: 2.419676 | N47: 2.422381 | O47: 2.426406 | P47: 2.429998 | Q47: 2.435315 | R47: 2.423512 | S47: 2.41015 | T47: 2.386208 | U47: 2.381421 | V47: 2.366141 | W47: 2.369409 | X47: 2.362637 | Y47: 2.357599 | Z47: 2.354464 | AA47: 2.343242 | AB47: 2.336414 | AC47: 2.334075 | AD47: 2.320942 | AE47: 2.309024 | AF47: -0.002164
A48: SUP000:fa_Biomass | B48: Biomass 12/ | C48: 3.086376 | D48: 3.275092 | E48: 3.097149 | F48: 3.077337 | G48: 3.057139 | H48: 3.045216 | I48: 3.037763 | J48: 3.031368 | K48: 3.025933 | L48: 3.025459 | M48: 3.027686 | N48: 3.034011 | O48: 3.040862 | P48: 3.052712 | Q48: 3.050264 | R48: 3.054543 | S48: 3.058388 | T48: 3.063898 | U48: 3.073415 | V48: 3.092868 | W48: 3.104291 | X48: 3.115824 | Y48: 3.11755 | Z48: 3.122586 | AA48: 3.141141 | AB48: 3.159971 | AC48: 3.182918 | AD48: 3.200994 | AE48: 3.21923 | AF48: 0.001506
A49: SUP000:fa_RenewableEner | B49: Other Renewable Energy 4/ | C49: 5.622848 | D49: 6.12555 | E49: 6.742159 | F49: 8.173244 | G49: 9.907674 | H49: 11.653165 | I49: 13.154488 | J49: 14.209772 | K49: 15.128234 | L49: 15.78889 | M49: 16.442295 | N49: 17.189573 | O49: 17.791294 | P49: 18.262888 | Q49: 18.746868 | R49: 19.110622 | S49: 19.414564 | T49: 19.60931 | U49: 19.90523 | V49: 20.063116 | W49: 20.302187 | X49: 20.584305 | Y49: 20.993839 | Z49: 21.370592 | AA49: 21.805227 | AB49: 22.17202 | AC49: 22.539532 | AD49: 22.84026 | AE49: 23.283979 | AF49: 0.052057
...

Sheet AEO 2023 Table 71
B1: ref2023.d020623a | C1: 2022 | D1: 2023 | E1: 2024 | F1: 2025 | G1: 2026 | H1: 2027 | I1: 2028 | J1: 2029 | K1: 2030 | L1: 2031 | M1: 2032 | N1: 2033 | O1: 2034 | P1: 2035 | Q1: 2036 | R1: 2037 | S1: 2038 | T1: 2039 | U1: 2040 | V1: 2041 | W1: 2042 | X1: 2043 | Y1: 2044 | Z1: 2045 | AA1: 2046 | AB1: 2047 | AC1: 2048 | AD1: 2049 | AE1: 2050
C3: Report | D3: Annual Energy Outlook 2023
C4: Scenario | D4: ref2023 | G4: Reference
C5: Datekey | D5: d020623a
C6: Release Date | E6: March 2023
A10: CNV000:convert_cbob | B10: 68. Conversion Factors | AF10: Annual
A11: CNV000:convert_rbob | B11: (from physical units to million Btu) | AF11: Change
A12: CNV000:aa_PentanesPlus | AF12: 2022–2050
A13: CNV000:aa_OtherPetroleu | C13: 2022 | D13: 2023 | E13: 2024 | F13: 2025 | G13: 2026 | H13: 2027 | I13: 2028 | J13: 2029 | K13: 2030 | L13: 2031 | M13: 2032 | N13: 2033 | O13: 2034 | P13: 2035 | Q13: 2036 | R13: 2037 | S13: 2038 | T13: 2039 | U13: 2040 | V13: 2041 | W13: 2042 | X13: 2043 | Y13: 2044 | Z13: 2045 | AA13: 2046 | AB13: 2047 | AC13: 2048 | AD13: 2049 | AE13: 2050 | AF13: 2050
A14: CNV000:aa_PetrochemFeed | B14: Petroleum and Other Liquids
A15: CNV000:aa_PetroleumCoke | B15: (million Btu per barrel)
A16: CNV000:aa_ResidualFuel | B16: Asphalt and Road Oil | C16: 6.636 | D16: 6.636 | E16: 6.636 | F16: 6.636 | G16: 6.636 | H16: 6.636 | I16: 6.636 | J16: 6.636 | K16: 6.636 | L16: 6.636 | M16: 6.636 | N16: 6.636 | O16: 6.636 | P16: 6.636 | Q16: 6.636 | R16: 6.636 | S16: 6.636 | T16: 6.636 | U16: 6.636 | V16: 6.636 | W16: 6.636 | X16: 6.636 | Y16: 6.636 | Z16: 6.636 | AA16: 6.636 | AB16: 6.636 | AC16: 6.636 | AD16: 6.636 | AE16: 6.636 | AF16: 0
A17: CNV000:aa_StillGas | B17: Aviation Gasoline | C17: 5.048 | D17: 5.048 | E17: 5.048 | F17: 5.048 | G17: 5.048 | H17: 5.048 | I17: 5.048 | J17: 5.048 | K17: 5.048 | L17: 5.048 | M17: 5.048 | N17: 5.048 | O17: 5.048 | P17: 5.048 | Q17: 5.048 | R17: 5.048 | S17: 5.048 | T17: 5.048 | U17: 5.048 | V17: 5.048 | W17: 5.048 | X17: 5.048 | Y17: 5.048 | Z17: 5.048 | AA17: 5.048 | AB17: 5.048 | AC17: 5.048 | AD17: 5.048 | AE17: 5.048 | AF17: 0
A18: CNV000:aa_UnfinishOilIm | B18: Biodiesel | C18: 5.359 | D18: 5.359 | E18: 5.359 | F18: 5.359 | G18: 5.359 | H18: 5.359 | I18: 5.359 | J18: 5.359 | K18: 5.359 | L18: 5.359 | M18: 5.359 | N18: 5.359 | O18: 5.359 | P18: 5.359 | Q18: 5.359 | R18: 5.359 | S18: 5.359 | T18: 5.359 | U18: 5.359 | V18: 5.359 | W18: 5.359 | X18: 5.359 | Y18: 5.359 | Z18: 5.359 | AA18: 5.359 | AB18: 5.359 | AC18: 5.359 | AD18: 5.359 | AE18: 5.359 | AF18: 0
A19: CNV000:aa_TotalPetroleu | B19: Distillate Fuel Oil | C19: 5.825 | D19: 5.825 | E19: 5.825 | F19: 5.825 | G19: 5.825 | H19: 5.825 | I19: 5.825 | J19: 5.825 | K19: 5.825 | L19: 5.825 | M19: 5.825 | N19: 5.825 | O19: 5.825 | P19: 5.825 | Q19: 5.825 | R19: 5.825 | S19: 5.825 | T19: 5.825 | U19: 5.825 | V19: 5.825 | W19: 5.825 | X19: 5.825 | Y19: 5.825 | Z19: 5.825 | AA19: 5.825 | AB19: 5.825 | AC19: 5.825 | AD19: 5.825 | AE19: 5.825 | AF19: 0
A20: CNV000:aa_Imports | B20: Residential | C20: 5.775621 | D20: 5.775648 | E20: 5.776083 | F20: 5.776062 | G20: 5.776467 | H20: 5.777218 | I20: 5.776948 | J20: 5.776953 | K20: 5.776798 | L20: 5.776974 | M20: 5.776898 | N20: 5.77701 | O20: 5.776805 | P20: 5.776956 | Q20: 5.776839 | R20: 5.776862 | S20: 5.776748 | T20: 5.776711 | U20: 5.776654 | V20: 5.776614 | W20: 5.776632 | X20: 5.776631 | Y20: 5.776552 | Z20: 5.776594 | AA20: 5.776409 | AB20: 5.776283 | AC20: 5.77638 | AD20: 5.776386 | AE20: 5.776234 | AF20: 4e-06
A21: CNV000:aa_Exports | B21: Commercial | C21: 5.775621 | D21: 5.775648 | E21: 5.776083 | F21: 5.776062 | G21: 5.776467 | H21: 5.777218 | I21: 5.776948 | J21: 5.776953 | K21: 5.776798 | L21: 5.776974 | M21: 5.776898 | N21: 5.77701 | O21: 5.776805 | P21: 5.776956 | Q21: 5.776839 | R21: 5.776862 | S21: 5.776748 | T21: 5.776711 | U21: 5.776654 | V21: 5.776614 | W21: 5.776632 | X21: 5.776631 | Y21: 5.776552 | Z21: 5.776594 | AA21: 5.776409 | AB21: 5.776283 | AC21: 5.77638 | AD21: 5.776386 | AE21: 5.776234 | AF21: 4e-06
B22: Transportation | C22: 5.775621 | D22: 5.775648 | E22: 5.776083 | F22: 5.776062 | G22: 5.776467 | H22: 5.777218 | I22: 5.776948 | J22: 5.776953 | K22: 5.776798 | L22: 5.776974 | M22: 5.776898 | N22: 5.77701 | O22: 5.776805 | P22: 5.776956 | Q22: 5.776839 | R22: 5.776862 | S22: 5.776748 | T22: 5.776711 | U22: 5.776654 | V22: 5.776614 | W22: 5.776632 | X22: 5.776631 | Y22: 5.776552 | Z22: 5.776594 | AA22: 5.776409 | AB22: 5.776283 | AC22: 5.77638 | AD22: 5.776386 | AE22: 5.776234 | AF22: 4e-06
A23: CNV000:aa_CrudeOilProdu | B23: Industrial | C23: 5.775621 | D23: 5.775648 | E23: 5.776083 | F23: 5.776062 | G23: 5.776467 | H23: 5.777218 | I23: 5.776948 | J23: 5.776953 | K23: 5.776798 | L23: 5.776974 | M23: 5.776898 | N23: 5.77701 | O23: 5.776805 | P23: 5.776956 | Q23: 5.776839 | R23: 5.776862 | S23: 5.776748 | T23: 5.776711 | U23: 5.776654 | V23: 5.776614 | W23: 5.776632 | X23: 5.776631 | Y23: 5.776552 | Z23: 5.776594 | AA23: 5.776409 | AB23: 5.776283 | AC23: 5.77638 | AD23: 5.776386 | AE23: 5.776234 | AF23: 4e-06
A24: CNV000:aa_CrudeOilImpor | B24: Electric Power | C24: 5.775621 | D24: 5.775648 | E24: 5.776083 | F24: 5.776062 | G24: 5.776467 | H24: 5.777218 | I24: 5.776948 | J24: 5.776953 | K24: 5.776798 | L24: 5.776974 | M24: 5.776898 | N24: 5.77701 | O24: 5.776805 | P24: 5.776956 | Q24: 5.776839 | R24: 5.776862 | S24: 5.776748 | T24: 5.776711 | U24: 5.776654 | V24: 5.776614 | W24: 5.776632 | X24: 5.776631 | Y24: 5.776552 | Z24: 5.776594 | AA24: 5.776409 | AB24: 5.776283 | AC24: 5.77638 | AD24: 5.776386 | AE24: 5.776234 | AF24: 4e-06
A25: CNV000:aa_CrudeOilExpor | B25: Total Distillate | C25: 5.775621 | D25: 5.775648 | E25: 5.776083 | F25: 5.776062 | G25: 5.776467 | H25: 5.777218 | I25: 5.776948 | J25: 5.776953 | K25: 5.776799 | L25: 5.776974 | M25: 5.776899 | N25: 5.77701 | O25: 5.776805 | P25: 5.776956 | Q25: 5.776838 | R25: 5.776862 | S25: 5.776748 | T25: 5.776711 | U25: 5.776654 | V25: 5.776614 | W25: 5.776632 | X25: 5.776631 | Y25: 5.776552 | Z25: 5.776594 | AA25: 5.776409 | AB25: 5.776284 | AC25: 5.77638 | AD25: 5.776386 | AE25: 5.776234 | AF25: 4e-06
A26: CNV000:aa_NaturalGasPla | B26: Distillate Fuel Oil - Low Sulfur Diesel | C26: 5.817 | D26: 5.817 | E26: 5.817 | F26: 5.817 | G26: 5.817 | H26: 5.817 | I26: 5.817 | J26: 5.817 | K26: 5.817 | L26: 5.817 | M26: 5.817 | N26: 5.817 | O26: 5.817 | P26: 5.817 | Q26: 5.817 | R26: 5.817 | S26: 5.817 | T26: 5.817 | U26: 5.817 | V26: 5.817 | W26: 5.817 | X26: 5.817 | Y26: 5.817 | Z26: 5.817 | AA26: 5.817 | AB26: 5.817 | AC26: 5.817 | AD26: 5.817 | AE26: 5.817 | AF26: 0
B27: Distillate Fuel Oil - Ultra Low Sulfur Diesel | C27: 5.77 | D27: 5.77 | E27: 5.77 | F27: 5.77 | G27: 5.77 | H27: 5.77 | I27: 5.77 | J27: 5.77 | K27: 5.77 | L27: 5.77 | M27: 5.77 | N27: 5.77 | O27: 5.77 | P27: 5.77 | Q27: 5.77 | R27: 5.77 | S27: 5.77 | T27: 5.77 | U27: 5.77 | V27: 5.77 | W27: 5.77 | X27: 5.77 | Y27: 5.77 | Z27: 5.77 | AA27: 5.77 | AB27: 5.77 | AC27: 5.77 | AD27: 5.77 | AE27: 5.77 | AF27: 0
B28: Ethanol including denaturant | C28: 3.563 | D28: 3.563 | E28: 3.563 | F28: 3.563 | G28: 3.563 | H28: 3.563 | I28: 3.563 | J28: 3.563 | K28: 3.563 | L28: 3.563 | M28: 3.563 | N28: 3.563 | O28: 3.563 | P28: 3.563 | Q28: 3.563 | R28: 3.563 | S28: 3.563 | T28: 3.563 | U28: 3.563 | V28: 3.563 | W28: 3.563 | X28: 3.563 | Y28: 3.563 | Z28: 3.563 | AA28: 3.563 | AB28: 3.563 | AC28: 3.563 | AD28: 3.563 | AE28: 3.563 | AF28: 0
A29: CNV000:ba_Consumption | B29: E85 1/ | C29: 3.994413 | D29: 3.994413 | E29: 3.994413 | F29: 3.994413 | G29: 3.994413 | H29: 3.994413 | I29: 3.994413 | J29: 3.994413 | K29: 3.994413 | L29: 3.994413 | M29: 3.994413 | N29: 3.994413 | O29: 3.994413 | P29: 3.994413 | Q29: 3.994413 | R29: 3.994413 | S29: 3.994413 | T29: 3.994413 | U29: 3.994413 | V29: 3.994413 | W29: 3.994413 | X29: 3.994413 | Y29: 3.994413 | Z29: 3.994413 | AA29: 3.994413 | AB29: 3.994413 | AC29: 3.994413 | AD29: 3.994413 | AE29: 3.994413 | AF29: 0
A30: CNV000:ba_Utility | B30: Jet Fuel - Kerosene | C30: 5.67 | D30: 5.67 | E30: 5.67 | F30: 5.67 | G30: 5.67 | H30: 5.67 | I30: 5.67 | J30: 5.67 | K30: 5.67 | L30: 5.67 | M30: 5.67 | N30: 5.67 | O30: 5.67 | P30: 5.67 | Q30: 5.67 | R30: 5.67 | S30: 5.67 | T30: 5.67 | U30: 5.67 | V30: 5.67 | W30: 5.67 | X30: 5.67 | Y30: 5.67 | Z30: 5.67 | AA30: 5.67 | AB30: 5.67 | AC30: 5.67 | AD30: 5.67 | AE30: 5.67 | AF30: 0
A31: CNV000:ba_Nonutility | B31: Lubricants | C31: 6.065 | D31: 6.065 | E31: 6.065 | F31: 6.065 | G31: 6.065 | H31: 6.065 | I31: 6.065 | J31: 6.065 | K31: 6.065 | L31: 6.065 | M31: 6.065 | N31: 6.065 | O31: 6.065 | P31: 6.065 | Q31: 6.065 | R31: 6.065 | S31: 6.065 | T31: 6.065 | U31: 6.065 | V31: 6.065 | W31: 6.065 | X31: 6.065 | Y31: 6.065 | Z31: 6.065 | AA31: 6.065 | AB31: 6.065 | AC31: 6.065 | AD31: 6.065 | AE31: 6.065 | AF31: 0
A32: CNV000:ba_Production | B32: Motor Gasoline Average | C32: 5.051711 | D32: 5.050536 | E32: 5.049363 | F32: 5.048181 | G32: 5.046995 | H32: 5.045806 | I32: 5.044614 | J32: 5.043417 | K32: 5.042216 | L32: 5.041012 | M32: 5.039805 | N32: 5.038594 | O32: 5.037381 | P32: 5.036164 | Q32: 5.03513 | R32: 5.034097 | S32: 5.033101 | T32: 5.032113 | U32: 5.031125 | V32: 5.030226 | W32: 5.029317 | X32: 5.028415 | Y32: 5.02752 | Z32: 5.02663 | AA32: 5.025746 | AB32: 5.024862 | AC32: 5.023974 | AD32: 5.023084 | AE32: 5.0222 | AF32: -0.000209
A33: CNV000:ba_Imports | B33: Conventional Motor Gasoline | C33: 5.051239 | D33: 5.049952 | E33: 5.048665 | F33: 5.047375 | G33: 5.046085 | H33: 5.044794 | I33: 5.043502 | J33: 5.042209 | K33: 5.040914 | L33: 5.039618 | M33: 5.038322 | N33: 5.037026 | O33: 5.03573 | P33: 5.034434 | Q33: 5.033323 | R33: 5.032218 | S33: 5.03115 | T33: 5.030091 | U33: 5.029032 | V33: 5.028083 | W33: 5.027124 | X33: 5.026171 | Y33: 5.025226 | Z33: 5.024285 | AA33: 5.023351 | AB33: 5.022417 | AC33: 5.021479 | AD33: 5.020539 | AE33: 5.019606 | AF33: -0.000224
A34: CNV000:ba_Exports | B34: Reformulated Motor Gasoline | C34: 5.050956 | D34: 5.04961 | E34: 5.048264 | F34: 5.046918 | G34: 5.045574 | H34: 5.04423 | I34: 5.042888 | J34: 5.041545 | K34: 5.040203 | L34: 5.038862 | M34: 5.037521 | N34: 5.036182 | O34: 5.034844 | P34: 5.033506 | Q34: 5.032413 | R34: 5.031326 | S34: 5.030284 | T34: 5.029252 | U34: 5.028219 | V34: 5.027245 | W34: 5.026256 | X34: 5.025273 | Y34: 5.024298 | Z34: 5.023329 | AA34: 5.022367 | AB34: 5.021404 | AC34: 5.020434 | AD34: 5.019461 | AE34: 5.018494 | AF34: -0.00023
A35: CNV000:ba_CompressedNat | B35: Conventional before Blending | C35: 5.22228 | D35: 5.22228 | E35: 5.22228 | F35: 5.22228 | G35: 5.22228 | H35: 5.22228 | I35: 5.22228 | J35: 5.22228 | K35: 5.22228 | L35: 5.22228 | M35: 5.22228 | N35: 5.22228 | O35: 5.22228 | P35: 5.22228 | Q35: 5.22228 | R35: 5.22228 | S35: 5.22228 | T35: 5.22228 | U35: 5.22228 | V35: 5.22228 | W35: 5.22228 | X35: 5.22228 | Y35: 5.22228 | Z35: 5.22228 | AA35: 5.22228 | AB35: 5.22228 | AC35: 5.22228 | AD35: 5.22228 | AE35: 5.22228 | AF35: 0
B36: Reformulated before Blending | C36: 5.22228 | D36: 5.22228 | E36: 5.22228 | F36: 5.22228 | G36: 5.22228 | H36: 5.22228 | I36: 5.22228 | J36: 5.22228 | K36: 5.22228 | L36: 5.22228 | M36: 5.22228 | N36: 5.22228 | O36: 5.22228 | P36: 5.22228 | Q36: 5.22228 | R36: 5.22228 | S36: 5.22228 | T36: 5.22228 | U36: 5.22228 | V36: 5.22228 | W36: 5.22228 | X36: 5.22228 | Y36: 5.22228 | Z36: 5.22228 | AA36: 5.22228 | AB36: 5.22228 | AC36: 5.22228 | AD36: 5.22228 | AE36: 5.22228 | AF36: 0
B37: Natural Gasoline | C37: 4.638 | D37: 4.638 | E37: 4.638 | F37: 4.638 | G37: 4.638 | H37: 4.638 | I37: 4.638 | J37: 4.638 | K37: 4.638 | L37: 4.638 | M37: 4.638 | N37: 4.638 | O37: 4.638 | P37: 4.638 | Q37: 4.638 | R37: 4.638 | S37: 4.638 | T37: 4.638 | U37: 4.638 | V37: 4.638 | W37: 4.638 | X37: 4.638 | Y37: 4.638 | Z37: 4.638 | AA37: 4.638 | AB37: 4.638 | AC37: 4.638 | AD37: 4.638 | AE37: 4.638 | AF37: 0
A38: CNV000:ca_Production | B38: Other Petroleum | C38: 5.8 | D38: 5.8 | E38: 5.8 | F38: 5.8 | G38: 5.8 | H38: 5.8 | I38: 5.8 | J38: 5.8 | K38: 5.8 | L38: 5.8 | M38: 5.8 | N38: 5.8 | O38: 5.8 | P38: 5.8 | Q38: 5.8 | R38: 5.8 | S38: 5.8 | T38: 5.8 | U38: 5.8 | V38: 5.8 | W38: 5.8 | X38: 5.8 | Y38: 5.8 | Z38: 5.8 | AA38: 5.8 | AB38: 5.8 | AC38: 5.8 | AD38: 5.8 | AE38: 5.8 | AF38: 0
A39: CNV000:ca_EastoftheMiss | B39: Petrochemical Feedstocks | C39: 5.448283 | D39: 5.448283 | E39: 5.448283 | F39: 5.448283 | G39: 5.448283 | H39: 5.448283 | I39: 5.448283 | J39: 5.448283 | K39: 5.448283 | L39: 5.448283 | M39: 5.448283 | N39: 5.448283 | O39: 5.448283 | P39: 5.448283 | Q39: 5.448283 | R39: 5.448283 | S39: 5.448283 | T39: 5.448283 | U39: 5.448283 | V39: 5.448283 | W39: 5.448283 | X39: 5.448283 | Y39: 5.448283 | Z39: 5.448283 | AA39: 5.448283 | AB39: 5.448283 | AC39: 5.448283 | AD39: 5.448283 | AE39: 5.448283 | AF39: 0
A40: CNV000:ca_WestoftheMiss | B40: Petroleum Coke | C40: 6.287 | D40: 6.287 | E40: 6.287 | F40: 6.287 | G40: 6.287 | H40: 6.287 | I40: 6.287 | J40: 6.287 | K40: 6.287 | L40: 6.287 | M40: 6.287 | N40: 6.287 | O40: 6.287 | P40: 6.287 | Q40: 6.287 | R40: 6.287 | S40: 6.287 | T40: 6.287 | U40: 6.287 | V40: 6.287 | W40: 6.287 | X40: 6.287 | Y40: 6.287 | Z40: 6.287 | AA40: 6.287 | AB40: 6.287 | AC40: 6.287 | AD40: 6.287 | AE40: 6.287 | AF40: 0
A41: CNV000:ca_Consumption | B41: Residual Fuel | C41: 6.287 | D41: 6.287 | E41: 6.287 | F41: 6.287 | G41: 6.287 | H41: 6.287 | I41: 6.287 | J41: 6.287 | K41: 6.287 | L41: 6.287 | M41: 6.287 | N41: 6.287 | O41: 6.287 | P41: 6.287 | Q41: 6.287 | R41: 6.287 | S41: 6.287 | T41: 6.287 | U41: 6.287 | V41: 6.287 | W41: 6.287 | X41: 6.287 | Y41: 6.287 | Z41: 6.287 | AA41: 6.287 | AB41: 6.287 | AC41: 6.287 | AD41: 6.287 | AE41: 6.287 | AF41: 0
A42: CNV000:ca_Residentialan | B42: Still Gas | C42: 6.287 | D42: 6.287 | E42: 6.287 | F42: 6.287 | G42: 6.287 | H42: 6.287 | I42: 6.287 | J42: 6.287 | K42: 6.287 | L42: 6.287 | M42: 6.287 | N42: 6.287 | O42: 6.287 | P42: 6.287 | Q42: 6.287 | R42: 6.287 | S42: 6.287 | T42: 6.287 | U42: 6.287 | V42: 6.287 | W42: 6.287 | X42: 6.287 | Y42: 6.287 | Z42: 6.287 | AA42: 6.287 | AB42: 6.287 | AC42: 6.287 | AD42: 6.287 | AE42: 6.287 | AF42: 0
A43: CNV000:ca_Industrial | B43: Unfinished Oils | C43: 6.191736 | D43: 6.192239 | E43: 6.193067 | F43: 6.163516 | G43: 6.155307 | H43: 6.161367 | I43: 6.16242 | J43: 6.163478 | K43: 6.164545 | L43: 6.160776 | M43: 6.166696 | N43: 6.167782 | O43: 6.168875 | P43: 6.169975 | Q43: 6.171082 | R43: 6.172197 | S43: 6.173318 | T43: 6.174447 | U43: 6.175582 | V43: 6.176932 | W43: 6.178004 | X43: 6.179245 | Y43: 6.180129 | Z43: 6.181304 | AA43: 6.182486 | AB43: 6.183676 | AC43: 6.184874 | AD43: 6.18608 | AE43: 6.187586 | AF43: -2.4e-05
