Workbook

Sheet About
A1: BPMCCS BAU Policy Mandated Capacity Construction Schedule
A3: Sources: | B3: (see BHRaSYC.xlsx)
A10: Note:

Sheet Data
A1: Evolución de la capacidad (MW)
B2: 2012 | C2: 2013 | D2: 2014 | E2: 2015 | F2: 2016 | G2: 2017 | H2: 2018 | I2: 2019 | J2: 2020 | K2: 2021 | L2: 2022 | M2: 2023
A3: Ciclo combinado | B3: 18029 | C3: 22830 | D3: 23309 | E3: 24043 | F3: 27274 | G3: 28084 | H3: 30016 | I3: 31828 | J3: 31948 | K3: 33640 | L3: 34413 | M3: 35178
A4: Termoeléctrica convencional | B4: 13765 | C4: 15246 | D4: 14614 | E4: 13881 | F4: 14217 | G4: 14383 | H4: 12503 | I4: 12584 | J4: 12399 | K4: 12399 | L4: 11343 | M4: 11300
A5: Carboeléctrica | B5: 5378 | C5: 5378 | D5: 5378 | E5: 5378 | F5: 5378 | G5: 5378 | H5: 5498 | I5: 5498 | J5: 5498 | K5: 5498 | L5: 5463 | M5: 5463
A6: Turbogás | B6: 2658 | C6: 3418 | D6: 3419 | E6: 4904 | F6: 5052 | G6: 5136 | H6: 5087 | I6: 5308 | J6: 4697.5 | K6: 4896.5 | L6: 4969 | M6: 5049
A7: Combustión Interna | B7: 1052 | C7: 1146 | D7: 1312 | E7: 1163 | F7: 1453 | G7: 1634 | H7: 2045 | I7: 2118 | J7: 1426.25 | K7: 1277.25 | L7: 1305 | M7: 1309.5
A8: Nuclear | B8: 1610 | C8: 1400 | D8: 1400 | E8: 1510 | F8: 1608 | G8: 1608 | H8: 1634 | I8: 1634 | J8: 1634 | K8: 1634 | L8: 1608 | M8: 1608
A9: Hidroeléctrica | B9: 11498 | C9: 11679 | D9: 12429 | E9: 12489 | F9: 12589 | G9: 12642 | H9: 12641 | I9: 12641 | J9: 12641 | K9: 12643 | L9: 12613 | M9: 12612
A10: Eólica | B10: 1158 | C10: 1611 | D10: 2036 | E10: 2805 | F10: 3735 | G10: 4199 | H10: 4855 | I10: 6040 | J10: 6454 | K10: 6454 | L10: 6921 | M10: 7055
A11: Geotérmica | B11: 812 | C11: 823 | D11: 813 | E11: 926 | F11: 909 | G11: 926 | H11: 926 | I11: 951 | J11: 951 | K11: 976 | L11: 976 | M11: 976
A12: Solar | B12: 6 | C12: 46 | D12: 56 | E12: 56 | F12: 145 | G12: 214 | H12: 1946 | I12: 4598 | J12: 5630 | K12: 5955 | L12: 6535 | M12: 7469
A13: Biomasa | B13: 492 | C13: 554 | D13: 685 | E13: 760 | F13: 889 | G13: 1007 | H13: 1082 | I13: 1016 | J13: 954.25 | K13: 1016.485 | L13: 1047.316 | M13: 1050.194
B14: 56458 | C14: 64131 | D14: 65451 | E14: 67915 | F14: 73249 | G14: 75211 | H14: 78233 | I14: 84216 | J14: 84233 | K14: 86389.235 | L14: 87193.316 | M14: 89069.694
A16: Evolución de la generación (MWh)
B17: 2012 | C17: 2013 | D17: 2014 | E17: 2015 | F17: 2016 | G17: 2017 | H17: 2018 | I17: 2019 | J17: 2020 | K17: 2021 | L17: 2022 | M17: 2023
A18: Ciclo combinado | B18: 129331590 | C18: 139162757 | D18: 145335722 | E18: 151463563 | F18: 152587411 | G18: 154128126 | H18: 159082959 | I18: 171368943 | J18: 181382154 | K18: 184444135 | L18: 193994868 | M18: 203605022
A19: Termoeléctrica convencional | B19: 59561147 | C19: 55036664 | D19: 40410894 | E19: 42474410 | F19: 42023428 | G19: 43947148 | H19: 40010763 | I19: 38661529 | J19: 23095298 | K19: 23495780 | L19: 21116986 | M19: 31182145
A20: Carboeléctrica | B20: 35018872 | C20: 34641891 | D20: 34066857 | E20: 34056857 | F20: 34532398 | G20: 28663360 | H20: 27344983 | I20: 21609445 | J20: 12500718 | K20: 8703941 | L20: 14191640 | M20: 14237878
A21: Turbogás | B21: 7624532 | C21: 7088706 | D21: 9249223 | E21: 11806728 | F21: 12719487 | G21: 14687034 | H21: 14392288 | I21: 16352558 | J21: 14087648 | K21: 15875312 | L21: 15486778 | M21: 17849573
A22: Combustión Interna | B22: 2000855 | C22: 2152886 | D22: 2339164 | E22: 2687125 | F22: 3169777 | G22: 2333057 | H22: 2565641 | I22: 3170220 | J22: 2871416 | K22: 2057546 | L22: 1843740 | M22: 3636195
A23: Nuclear | B23: 8192869 | C23: 11389115 | D23: 9807663 | E23: 11734761 | F23: 10667410 | G23: 10571136 | H23: 13198780 | I23: 10879189 | J23: 10844159 | K23: 11604710 | L23: 10538743 | M23: 12043391
A24: Biomasa | B24: 1231312 | C24: 1086854 | D24: 1406020 | E24: 1388420 | F24: 1485058 | G24: 1884844 | H24: 1989116 | I24: 1861586 | J24: 2216007 | K24: 1531996 | L24: 1627355 | M24: 1628955
A26: Consumo de combustibles (PJ)
B27: 2012 | C27: 2013 | D27: 2014 | E27: 2015 | F27: 2016 | G27: 2017 | H27: 2018 | I27: 2019 | J27: 2020 | K27: 2021 | L27: 2022 | M27: 2023
A28: Ciclo combinado | B28: 1009.23 | C28: 1108.1 | D28: 1131.19 | E28: 1275.2 | F28: 1416.37 | G28: 1383.12 | H28: 1488.74 | I28: 1445.94 | J28: 1496.7 | K28: 1531.81 | L28: 1883.9485 | M28: 2018.241
A29: Termoeléctrica convencional | B29: 641.85 | C29: 581.14 | D29: 416.81 | E29: 425.87 | F29: 475.39 | G29: 507.01 | H29: 472.16 | I29: 439.98 | J29: 322.55 | K29: 331.56 | L29: 322.15025 | M29: 434.06675
A30: Carboeléctrica | B30: 351.49 | C30: 332.87 | D30: 353.1 | E30: 356.11 | F30: 372.85 | G30: 316.59 | H30: 315.71 | I30: 306.73 | J30: 164.1 | K30: 99.04 | L30: 145.06 | M30: 169.12
A31: Turbogás | B31: 79.26 | C31: 73.64 | D31: 89.95 | E31: 106.35 | F31: 143.81 | G31: 170.28 | H31: 170.51 | I31: 179.14 | J31: 158.38 | K31: 166.35 | L31: 164.8205 | M31: 203.07075
A32: Combustión Interna | B32: 24.18 | C32: 26.05 | D32: 26.53 | E32: 27.98 | F32: 41.47 | G32: 31.36 | H32: 35.24 | I32: 40.4 | J32: 34.75 | K32: 28.79 | L32: 30.5641 | M32: 50.8758
A33: Nuclear | B33: 91.32 | C33: 122.6 | D33: 100.6 | E33: 120.41 | F33: 109.95 | G33: 113.22 | H33: 156 | I33: 124.82 | J33: 125.62 | K33: 124.99 | L33: 152.77 | M33: 175.7
A34: Biomasa | B34: 52.97 | C34: 58.57 | D34: 68.15 | E34: 68.41 | F34: 70.41 | G34: 65.46 | H34: 64.61 | I34: 75.57 | J34: 87.82 | K34: 55.56 | L34: 48.13 | M34: 46.37
A36: Regimen térmico, incluye usos propios (GJ/MWh)
B37: 2012 | C37: 2013 | D37: 2014 | E37: 2015 | F37: 2016 | G37: 2017 | H37: 2018 | I37: 2019 | J37: 2020 | K37: 2021 | L37: 2022 | M37: 2023
A38: Ciclo combinado | B38: 7.8034299 | C38: 7.9626189 | D38: 7.7832895 | E38: 8.4191866 | F38: 9.2823516 | G38: 8.9738326 | H38: 9.3582619 | I38: 8.4375849 | J38: 8.2516387 | K38: 8.3050079 | L38: 9.7113316 | M38: 9.9125305
A39: Termoeléctrica convencional | B39: 10.77632 | C39: 10.559143 | D39: 10.314298 | E39: 10.026508 | F39: 11.312499 | G39: 11.536812 | H39: 11.800825 | I39: 11.380305 | J39: 13.966046 | K39: 14.11147 | L39: 15.255503 | M39: 13.920362
A40: Carboeléctrica | B40: 10.037159 | C40: 9.6088865 | D40: 10.364913 | E40: 10.456338 | F40: 10.797107 | G40: 11.045111 | H40: 11.545445 | I40: 14.194256 | J40: 13.127246 | K40: 11.378754 | L40: 10.221511 | M40: 11.878175
A41: Turbogás | B41: 10.395392 | C41: 10.388356 | D41: 9.7251412 | E41: 9.007576 | F41: 11.306274 | G41: 11.5939 | H41: 11.847317 | I41: 10.954861 | J41: 11.242473 | K41: 10.478534 | L41: 10.642659 | M41: 11.376785
A42: Combustión Interna | B42: 12.084834 | C42: 12.100037 | D42: 11.341659 | E42: 10.412616 | F42: 13.082939 | G42: 13.441592 | H42: 13.735359 | I42: 12.743595 | J42: 12.102043 | K42: 13.992397 | L42: 16.577229 | M42: 13.991494
A43: Nuclear | B43: 11.146279 | C43: 10.764664 | D43: 10.257286 | E43: 10.260967 | F43: 10.307094 | G43: 10.710296 | H43: 11.819274 | I43: 11.473282 | J43: 11.584116 | K43: 10.770627 | L43: 14.496036 | M43: 14.588914
...

Sheet BPMCCS
A1: Mandated Construction (MW) | B1: 2020 | C1: 2021 | D1: 2022 | E1: 2023 | F1: 2024 | G1: 2025 | H1: 2026 | I1: 2027 | J1: 2028 | K1: 2029 | L1: 2030 | M1: 2031 | N1: 2032 | O1: 2033 | P1: 2034 | Q1: 2035 | R1: 2036 | S1: 2037 | T1: 2038 | U1: 2039 | V1: 2040 | W1: 2041 | X1: 2042 | Y1: 2043 | Z1: 2044 | AA1: 2045 | AB1: 2046 | AC1: 2047 | AD1: 2048 | AE1: 2049 | AF1: 2050 | AG1: 2051 | AH1: 2052 | AI1: 2053 | AJ1: 2054 | AK1: 2055 | AL1: 2056 | AM1: 2057 | AN1: 2058 | AO1: 2059 | AP1: 2060 | AQ1: 2061 | AR1: 2062 | AS1: 2063 | AT1: 2064 | AU1: 2065 | AV1: 2066 | AW1: 2067 | AX1: 2068 | AY1: 2069 | AZ1: 2070
A2: hard coal | B2: 0 | C2: =Data!K75 -> 0 | D2: =Data!L75 -> 0 | E2: =Data!M75 -> 0 | F2: 0 | G2: 0 | H2: 0 | I2: 0 | J2: 0 | K2: 0 | L2: 0 | M2: 0 | N2: 0 | O2: 0 | P2: 0 | Q2: 0 | R2: 0 | S2: 0 | T2: 0 | U2: 0 | V2: 0 | W2: 0 | X2: 0 | Y2: 0 | Z2: 0 | AA2: 0 | AB2: 0 | AC2: 0 | AD2: 0 | AE2: 0 | AF2: 0 | AG2: 0 | AH2: 0 | AI2: 0 | AJ2: 0 | AK2: 0 | AL2: 0 | AM2: 0 | AN2: 0 | AO2: 0 | AP2: 0 | AQ2: 0 | AR2: 0 | AS2: 0 | AT2: 0 | AU2: 0 | AV2: 0 | AW2: 0 | AX2: 0 | AY2: 0 | AZ2: 0
A3: natural gas steam turbine | B3: 0 | C3: =Data!K76 -> 0 | D3: =Data!L76 -> 27.75 | E3: =Data!M76 -> 4.5 | F3: 0 | G3: 0 | H3: 0 | I3: 0 | J3: 0 | K3: 0 | L3: 0 | M3: 0 | N3: 0 | O3: 0 | P3: 0 | Q3: 0 | R3: 0 | S3: 0 | T3: 0 | U3: 0 | V3: 0 | W3: 0 | X3: 0 | Y3: 0 | Z3: 0 | AA3: 0 | AB3: 0 | AC3: 0 | AD3: 0 | AE3: 0 | AF3: 0 | AG3: 0 | AH3: 0 | AI3: 0 | AJ3: 0 | AK3: 0 | AL3: 0 | AM3: 0 | AN3: 0 | AO3: 0 | AP3: 0 | AQ3: 0 | AR3: 0 | AS3: 0 | AT3: 0 | AU3: 0 | AV3: 0 | AW3: 0 | AX3: 0 | AY3: 0 | AZ3: 0
A4: natural gas combined cycle | B4: 0 | C4: =Data!K77 -> 1692 | D4: =Data!L77 -> 773 | E4: =Data!M77 -> 765 | F4: 0 | G4: 0 | H4: 0 | I4: 0 | J4: 0 | K4: 0 | L4: 0 | M4: 0 | N4: 0 | O4: 0 | P4: 0 | Q4: 0 | R4: 0 | S4: 0 | T4: 0 | U4: 0 | V4: 0 | W4: 0 | X4: 0 | Y4: 0 | Z4: 0 | AA4: 0 | AB4: 0 | AC4: 0 | AD4: 0 | AE4: 0 | AF4: 0 | AG4: 0 | AH4: 0 | AI4: 0 | AJ4: 0 | AK4: 0 | AL4: 0 | AM4: 0 | AN4: 0 | AO4: 0 | AP4: 0 | AQ4: 0 | AR4: 0 | AS4: 0 | AT4: 0 | AU4: 0 | AV4: 0 | AW4: 0 | AX4: 0 | AY4: 0 | AZ4: 0
A5: nuclear | B5: 0 | C5: =Data!K78 -> 0 | D5: =Data!L78 -> 0 | E5: =Data!M78 -> 0 | F5: 0 | G5: 0 | H5: 0 | I5: 0 | J5: 0 | K5: 0 | L5: 0 | M5: 0 | N5: 0 | O5: 0 | P5: 0 | Q5: 0 | R5: 0 | S5: 0 | T5: 0 | U5: 0 | V5: 0 | W5: 0 | X5: 0 | Y5: 0 | Z5: 0 | AA5: 0 | AB5: 0 | AC5: 0 | AD5: 0 | AE5: 0 | AF5: 0 | AG5: 0 | AH5: 0 | AI5: 0 | AJ5: 0 | AK5: 0 | AL5: 0 | AM5: 0 | AN5: 0 | AO5: 0 | AP5: 0 | AQ5: 0 | AR5: 0 | AS5: 0 | AT5: 0 | AU5: 0 | AV5: 0 | AW5: 0 | AX5: 0 | AY5: 0 | AZ5: 0
A6: hydro | B6: 0 | C6: =Data!K79 -> 2 | D6: =Data!L79 -> 0 | E6: =Data!M79 -> 0 | F6: 0 | G6: 0 | H6: 0 | I6: 0 | J6: 0 | K6: 0 | L6: 0 | M6: 0 | N6: 0 | O6: 0 | P6: 0 | Q6: 0 | R6: 0 | S6: 0 | T6: 0 | U6: 0 | V6: 0 | W6: 0 | X6: 0 | Y6: 0 | Z6: 0 | AA6: 0 | AB6: 0 | AC6: 0 | AD6: 0 | AE6: 0 | AF6: 0 | AG6: 0 | AH6: 0 | AI6: 0 | AJ6: 0 | AK6: 0 | AL6: 0 | AM6: 0 | AN6: 0 | AO6: 0 | AP6: 0 | AQ6: 0 | AR6: 0 | AS6: 0 | AT6: 0 | AU6: 0 | AV6: 0 | AW6: 0 | AX6: 0 | AY6: 0 | AZ6: 0
A7: onshore wind | B7: 0 | C7: =Data!K80 -> 0 | D7: =Data!L80 -> 467 | E7: =Data!M80 -> 134 | F7: 0 | G7: 0 | H7: 0 | I7: 0 | J7: 0 | K7: 0 | L7: 0 | M7: 0 | N7: 0 | O7: 0 | P7: 0 | Q7: 0 | R7: 0 | S7: 0 | T7: 0 | U7: 0 | V7: 0 | W7: 0 | X7: 0 | Y7: 0 | Z7: 0 | AA7: 0 | AB7: 0 | AC7: 0 | AD7: 0 | AE7: 0 | AF7: 0 | AG7: 0 | AH7: 0 | AI7: 0 | AJ7: 0 | AK7: 0 | AL7: 0 | AM7: 0 | AN7: 0 | AO7: 0 | AP7: 0 | AQ7: 0 | AR7: 0 | AS7: 0 | AT7: 0 | AU7: 0 | AV7: 0 | AW7: 0 | AX7: 0 | AY7: 0 | AZ7: 0
A8: solar PV | B8: 0 | C8: =Data!K81 -> 325 | D8: =Data!L81 -> 580 | E8: =Data!M81 -> 934 | F8: 0 | G8: 0 | H8: 0 | I8: 0 | J8: 0 | K8: 0 | L8: 0 | M8: 0 | N8: 0 | O8: 0 | P8: 0 | Q8: 0 | R8: 0 | S8: 0 | T8: 0 | U8: 0 | V8: 0 | W8: 0 | X8: 0 | Y8: 0 | Z8: 0 | AA8: 0 | AB8: 0 | AC8: 0 | AD8: 0 | AE8: 0 | AF8: 0 | AG8: 0 | AH8: 0 | AI8: 0 | AJ8: 0 | AK8: 0 | AL8: 0 | AM8: 0 | AN8: 0 | AO8: 0 | AP8: 0 | AQ8: 0 | AR8: 0 | AS8: 0 | AT8: 0 | AU8: 0 | AV8: 0 | AW8: 0 | AX8: 0 | AY8: 0 | AZ8: 0
A9: solar thermal | B9: 0 | C9: =Data!K82 -> 0 | D9: =Data!L82 -> 0 | E9: =Data!M82 -> 0 | F9: 0 | G9: 0 | H9: 0 | I9: 0 | J9: 0 | K9: 0 | L9: 0 | M9: 0 | N9: 0 | O9: 0 | P9: 0 | Q9: 0 | R9: 0 | S9: 0 | T9: 0 | U9: 0 | V9: 0 | W9: 0 | X9: 0 | Y9: 0 | Z9: 0 | AA9: 0 | AB9: 0 | AC9: 0 | AD9: 0 | AE9: 0 | AF9: 0 | AG9: 0 | AH9: 0 | AI9: 0 | AJ9: 0 | AK9: 0 | AL9: 0 | AM9: 0 | AN9: 0 | AO9: 0 | AP9: 0 | AQ9: 0 | AR9: 0 | AS9: 0 | AT9: 0 | AU9: 0 | AV9: 0 | AW9: 0 | AX9: 0 | AY9: 0 | AZ9: 0
A10: biomass | B10: 0 | C10: =Data!K83 -> 62.235 | D10: =Data!L83 -> 30.831 | E10: =Data!M83 -> 2.878 | F10: 0 | G10: 0 | H10: 0 | I10: 0 | J10: 0 | K10: 0 | L10: 0 | M10: 0 | N10: 0 | O10: 0 | P10: 0 | Q10: 0 | R10: 0 | S10: 0 | T10: 0 | U10: 0 | V10: 0 | W10: 0 | X10: 0 | Y10: 0 | Z10: 0 | AA10: 0 | AB10: 0 | AC10: 0 | AD10: 0 | AE10: 0 | AF10: 0 | AG10: 0 | AH10: 0 | AI10: 0 | AJ10: 0 | AK10: 0 | AL10: 0 | AM10: 0 | AN10: 0 | AO10: 0 | AP10: 0 | AQ10: 0 | AR10: 0 | AS10: 0 | AT10: 0 | AU10: 0 | AV10: 0 | AW10: 0 | AX10: 0 | AY10: 0 | AZ10: 0
A11: geothermal | B11: 0 | C11: =Data!K84 -> 25 | D11: =Data!L84 -> 0 | E11: =Data!M84 -> 0 | F11: 0 | G11: 0 | H11: 0 | I11: 0 | J11: 0 | K11: 0 | L11: 0 | M11: 0 | N11: 0 | O11: 0 | P11: 0 | Q11: 0 | R11: 0 | S11: 0 | T11: 0 | U11: 0 | V11: 0 | W11: 0 | X11: 0 | Y11: 0 | Z11: 0 | AA11: 0 | AB11: 0 | AC11: 0 | AD11: 0 | AE11: 0 | AF11: 0 | AG11: 0 | AH11: 0 | AI11: 0 | AJ11: 0 | AK11: 0 | AL11: 0 | AM11: 0 | AN11: 0 | AO11: 0 | AP11: 0 | AQ11: 0 | AR11: 0 | AS11: 0 | AT11: 0 | AU11: 0 | AV11: 0 | AW11: 0 | AX11: 0 | AY11: 0 | AZ11: 0
A12: petroleum | B12: 0 | C12: =Data!K85 -> 0 | D12: =Data!L85 -> 0 | E12: =Data!M85 -> 0 | F12: 0 | G12: 0 | H12: 0 | I12: 0 | J12: 0 | K12: 0 | L12: 0 | M12: 0 | N12: 0 | O12: 0 | P12: 0 | Q12: 0 | R12: 0 | S12: 0 | T12: 0 | U12: 0 | V12: 0 | W12: 0 | X12: 0 | Y12: 0 | Z12: 0 | AA12: 0 | AB12: 0 | AC12: 0 | AD12: 0 | AE12: 0 | AF12: 0 | AG12: 0 | AH12: 0 | AI12: 0 | AJ12: 0 | AK12: 0 | AL12: 0 | AM12: 0 | AN12: 0 | AO12: 0 | AP12: 0 | AQ12: 0 | AR12: 0 | AS12: 0 | AT12: 0 | AU12: 0 | AV12: 0 | AW12: 0 | AX12: 0 | AY12: 0 | AZ12: 0
A13: natural gas peaker | B13: 0 | C13: =Data!K86 -> 199 | D13: =Data!L86 -> 72.5 | E13: =Data!M86 -> 80 | F13: 0 | G13: 0 | H13: 0 | I13: 0 | J13: 0 | K13: 0 | L13: 0 | M13: 0 | N13: 0 | O13: 0 | P13: 0 | Q13: 0 | R13: 0 | S13: 0 | T13: 0 | U13: 0 | V13: 0 | W13: 0 | X13: 0 | Y13: 0 | Z13: 0 | AA13: 0 | AB13: 0 | AC13: 0 | AD13: 0 | AE13: 0 | AF13: 0 | AG13: 0 | AH13: 0 | AI13: 0 | AJ13: 0 | AK13: 0 | AL13: 0 | AM13: 0 | AN13: 0 | AO13: 0 | AP13: 0 | AQ13: 0 | AR13: 0 | AS13: 0 | AT13: 0 | AU13: 0 | AV13: 0 | AW13: 0 | AX13: 0 | AY13: 0 | AZ13: 0
... A25: hydrogen combined cycle | B25: 0 | C25: =Data!K98 -> 0 | D25: =Data!L98 -> 0 | E25: =Data!M98 -> 0 | F25: 0 | G25: 0 | H25: 0 | I25: 0 | J25: 0 | K25: 0 | L25: 0 | M25: 0 | N25: 0 | O25: 0 | P25: 0 | Q25: 0 | R25: 0 | S25: 0 | T25: 0 | U25: 0 | V25: 0 | W25: 0 | X25: 0 | Y25: 0 | Z25: 0 | AA25: 0 | AB25: 0 | AC25: 0 | AD25: 0 | AE25: 0 | AF25: 0 | AG25: 0 | AH25: 0 | AI25: 0 | AJ25: 0 | AK25: 0 | AL25: 0 | AM25: 0 | AN25: 0 | AO25: 0 | AP25: 0 | AQ25: 0 | AR25: 0 | AS25: 0 | AT25: 0 | AU25: 0 | AV25: 0 | AW25: 0 | AX25: 0 | AY25: 0 | AZ25: 0
