Workbook
Name outputfrac_bio: #REF!
Name outputfrac_coal: #REF!
Name outputfrac_elec: #REF!
Name outputfrac_ngps: #REF!
Name outputfrac_nonenergy: #REF!
Name outputfrac_other: #REF!

Sheet About
A1: FoVObE Fraction of Vehicles Owned by Entity
A3: Source: | B3: Mexico data for LDV, HDV, motorbikes
B4: Instituto Nacional de Estadísticas y Geografía (INEGI)
B5: 2024
B6: Registered motor vehicles
B7: http://www.inegi.org.mx/lib/olap/consulta/general_ver4/MDXQueryDatos.asp?#Regreso&c=
A12: Note:
A14: Vehicle Exports
A15: Vehicles produced and sold for export (sold and used outside the modeled region) should not be included here.
A16: The transportation sector in the EPS only tracks transportation within the modeled region.
A17: (Exported vehicles may be included in grouped Industry Sector outputs, where exports are handled.)
A18: Therefore, the share of vehicles assigned to "foreign entities" in this variable should be zero.
A19: Even if a foreign entity owns vehicles in the modeled region, classify those vehicles as government-, industry-,
A20: or consumer-owned, depending on the nature of the foreign entitiy.
A23: In the output tab, we show more decimal places than the source data
A24: provide in order to avoid rounding error in Vensim (each column must
A25: add to 1).

Sheet Vehicle fleet by entity MEX
U2: Vehículos de motor registrados en circulación | AA2: Vehículos de motor registrados en circulación | AG2: Vehículos de motor registrados en circulación | AM2: Vehículos de motor registrados en circulación
U3: Tipo de servicio : Total | AA3: Tipo de servicio : Particulares | AG3: Tipo de servicio : Públicos | AM3: Tipo de servicio : Oficiales
U5: Consulta de: Vehículos registrados Por: Año de registro Según: Clase de vehículo | AA5: Consulta de: Vehículos registrados Por: Año de registro Según: Clase de vehículo | AG5: Consulta de: Vehículos registrados Por: Año de registro Según: Clase de vehículo | AM5: Consulta de: Vehículos registrados Por: Año de registro Según: Clase de vehículo
A6: Automóviles | F6: Camiones para pasajeros | K6: Camiones y camionetas para carga | P6: Motocicletas | V6: Total | W6: Total | X6: Total | Y6: Total | Z6: Total | AB6: Particulares | AC6: Particulares | AD6: Particulares | AE6: Particulares | AF6: Particulares | AH6: Publicos | AI6: Publicos | AJ6: Publicos | AK6: Publicos | AL6: Publicos | AN6: Oficiales | AO6: Oficiales | AP6: Oficiales | AQ6: Oficiales | AR6: Oficiales
A7: Tipo de servicio | B7: Particulares | C7: Públicos | D7: Oficiales | F7: Tipo de servicio | G7: Particulares | H7: Públicos | I7: Oficiales | K7: Tipo de servicio | L7: Particulares | M7: Públicos | N7: Oficiales | P7: Tipo de servicio | Q7: Particulares | R7: Públicos | S7: Oficiales | V7: Total | W7: Automóviles | X7: Camiones para pasajeros | Y7: Camiones y camionetas para carga | Z7: Motocicletas | AB7: Total | AC7: Automóviles | AD7: Camiones para pasajeros | AE7: Camiones y camionetas para carga | AF7: Motocicletas | AH7: Total | AI7: Automóviles | AJ7: Camiones para pasajeros | AK7: Camiones y camionetas para carga | AL7: Motocicletas | AN7: Total | AO7: Automóviles | AP7: Camiones para pasajeros | AQ7: Camiones y camionetas para carga | AR7: Motocicletas
A8: 1980 | B8: =AC8/W8 -> 0.96905299 | C8: =AI8/W8 -> 0.027060219 | D8: =AO8/W8 -> 0.0038867941 | F8: 1980 | G8: =AD8/X8 -> 0.15878983 | H8: =AJ8/X8 -> 0.82698549 | I8: =AP8/X8 -> 0.01422468 | K8: 1980 | L8: =AE8/Y8 -> 0.9573876 | M8: =AK8/Y8 -> 0.038919892 | N8: =AQ8/Y8 -> 0.0036925081 | P8: 1980 | Q8: =AF8/Z8 -> 0.99580993 | R8: =AL8/Z8 -> 0.001808116 | S8: =AR8/Z8 -> 0.0023819492 | U8: 1980 | V8: 5758330 | W8: 3950042 | X8: 60388 | Y8: 1470816 | Z8: 277084 | AA8: 1980 | AB8: 5521453 | AC8: 3827800 | AD8: 9589 | AE8: 1408141 | AF8: 275923 | AG8: 1980 | AH8: 214574 | AI8: 106889 | AJ8: 49940 | AK8: 57244 | AL8: 501 | AM8: 1980 | AN8: 22303 | AO8: 15353 | AP8: 859 | AQ8: 5431 | AR8: 660
A9: 1981 | B9: =AC9/W9 -> 0.96792321 | C9: =AI9/W9 -> 0.028211186 | D9: =AO9/W9 -> 0.0038656063 | F9: 1981 | G9: =AD9/X9 -> 0.16202115 | H9: =AJ9/X9 -> 0.82478876 | I9: =AP9/X9 -> 0.013190094 | K9: 1981 | L9: =AE9/Y9 -> 0.95884596 | M9: =AK9/Y9 -> 0.037244204 | N9: =AQ9/Y9 -> 0.0039098319 | P9: 1981 | Q9: =AF9/Z9 -> 0.99563049 | R9: =AL9/Z9 -> 0.0018003985 | S9: =AR9/Z9 -> 0.002569108 | U9: 1981 | V9: 6339836 | W9: 4341363 | X9: 64973 | Y9: 1636899 | Z9: 296601 | AA9: 1981 | AB9: 6077472 | AC9: 4202106 | AD9: 10527 | AE9: 1569534 | AF9: 295305 | AG9: 1981 | AH9: 237563 | AI9: 122475 | AJ9: 53589 | AK9: 60965 | AL9: 534 | AM9: 1981 | AN9: 24801 | AO9: 16782 | AP9: 857 | AQ9: 6400 | AR9: 762
A10: 1982 | B10: =AC10/W10 -> 0.96743765 | C10: =AI10/W10 -> 0.029982259 | D10: =AO10/W10 -> 0.0025800879 | F10: 1982 | G10: =AD10/X10 -> 0.158566 | H10: =AJ10/X10 -> 0.82922884 | I10: =AP10/X10 -> 0.012205162 | K10: 1982 | L10: =AE10/Y10 -> 0.96183809 | M10: =AK10/Y10 -> 0.03509478 | N10: =AQ10/Y10 -> 0.0030671327 | P10: 1982 | Q10: =AF10/Z10 -> 0.99505511 | R10: =AL10/Z10 -> 0.0021614477 | S10: =AR10/Z10 -> 0.002783447 | U10: 1982 | V10: 6695164 | W10: 4616897 | X10: 69233 | Y10: 1751799 | Z10: 257235 | AA10: 1982 | AB10: 6418448 | AC10: 4466560 | AD10: 10978 | AE10: 1684947 | AF10: 255963 | AG10: 1982 | AH10: 257870 | AI10: 138425 | AJ10: 57410 | AK10: 61479 | AL10: 556 | AM10: 1982 | AN10: 18846 | AO10: 11912 | AP10: 845 | AQ10: 5373 | AR10: 716
A11: 1983 | B11: =AC11/W11 -> 0.96553431 | C11: =AI11/W11 -> 0.031292555 | D11: =AO11/W11 -> 0.0031731382 | F11: 1983 | G11: =AD11/X11 -> 0.14513642 | H11: =AJ11/X11 -> 0.8373244 | I11: =AP11/X11 -> 0.017539186 | K11: 1983 | L11: =AE11/Y11 -> 0.96080405 | M11: =AK11/Y11 -> 0.034780684 | N11: =AQ11/Y11 -> 0.0044152617 | P11: 1983 | Q11: =AF11/Z11 -> 0.9949378 | R11: =AL11/Z11 -> 0.0022117181 | S11: =AR11/Z11 -> 0.0028504815 | U11: 1983 | V11: 6941252 | W11: 4726236 | X11: 71326 | Y11: 1893206 | Z11: 250484 | AA11: 1983 | AB11: 6641911 | AC11: 4563343 | AD11: 10352 | AE11: 1819000 | AF11: 249216 | AG11: 1983 | AH11: 274020 | AI11: 147896 | AJ11: 59723 | AK11: 65847 | AL11: 554 | AM11: 1983 | AN11: 25321 | AO11: 14997 | AP11: 1251 | AQ11: 8359 | AR11: 714
A12: 1984 | B12: =AC12/W12 -> 0.96548615 | C12: =AI12/W12 -> 0.030745237 | D12: =AO12/W12 -> 0.0037686152 | F12: 1984 | G12: =AD12/X12 -> 0.13843982 | H12: =AJ12/X12 -> 0.84058445 | I12: =AP12/X12 -> 0.020975731 | K12: 1984 | L12: =AE12/Y12 -> 0.9607289 | M12: =AK12/Y12 -> 0.034832017 | N12: =AQ12/Y12 -> 0.004439082 | P12: 1984 | Q12: =AF12/Z12 -> 0.99435015 | R12: =AL12/Z12 -> 0.0025307478 | S12: =AR12/Z12 -> 0.0031191063 | U12: 1984 | V12: 7305066 | W12: 4970526 | X12: 76517 | Y12: 2009875 | Z12: 248148 | AA12: 1984 | AB12: 6987258 | AC12: 4798974 | AD12: 10593 | AE12: 1930945 | AF12: 246746 | AG12: 1984 | AH12: 287775 | AI12: 152820 | AJ12: 64319 | AK12: 70008 | AL12: 628 | AM12: 1984 | AN12: 30033 | AO12: 18732 | AP12: 1605 | AQ12: 8922 | AR12: 774
A13: 1985 | B13: =AC13/W13 -> 0.96596831 | C13: =AI13/W13 -> 0.029884461 | D13: =AO13/W13 -> 0.0041472274 | F13: 1985 | G13: =AD13/X13 -> 0.13020702 | H13: =AJ13/X13 -> 0.84890166 | I13: =AP13/X13 -> 0.02089133 | K13: 1985 | L13: =AE13/Y13 -> 0.96137477 | M13: =AK13/Y13 -> 0.034180936 | N13: =AQ13/Y13 -> 0.0044442973 | P13: 1985 | Q13: =AF13/Z13 -> 0.99424824 | R13: =AL13/Z13 -> 0.0024884366 | S13: =AR13/Z13 -> 0.0032633269 | U13: 1985 | V13: 7725623 | W13: 5281842 | X13: 79028 | Y13: 2114395 | Z13: 250358 | AA13: 1985 | AB13: 7394026 | AC13: 5102092 | AD13: 10290 | AE13: 2032726 | AF13: 248918 | AG13: 1985 | AH13: 297827 | AI13: 157845 | AJ13: 67087 | AK13: 72272 | AL13: 623 | AM13: 1985 | AN13: 33770 | AO13: 21905 | AP13: 1651 | AQ13: 9397 | AR13: 817
A14: 1986 | B14: =AC14/W14 -> 0.96113453 | C14: =AI14/W14 -> 0.034343394 | D14: =AO14/W14 -> 0.0045220743 | F14: 1986 | G14: =AD14/X14 -> 0.12264162 | H14: =AJ14/X14 -> 0.85591259 | I14: =AP14/X14 -> 0.021445792 | K14: 1986 | L14: =AE14/Y14 -> 0.95844557 | M14: =AK14/Y14 -> 0.037009523 | N14: =AQ14/Y14 -> 0.0045449102 | P14: 1986 | Q14: =AF14/Z14 -> 0.99375999 | R14: =AL14/Z14 -> 0.0026687639 | S14: =AR14/Z14 -> 0.0035712444 | U14: 1986 | V14: 7732012 | W14: 5202922 | X14: 83373 | Y14: 2213025 | Z14: 232692 | AA14: 1986 | AB14: 7363237 | AC14: 5000708 | AD14: 10225 | AE14: 2121064 | AF14: 231240 | AG14: 1986 | AH14: 332570 | AI14: 178686 | AJ14: 71360 | AK14: 81903 | AL14: 621 | AM14: 1986 | AN14: 36205 | AO14: 23528 | AP14: 1788 | AQ14: 10058 | AR14: 831
A15: 1987 | B15: =AC15/W15 -> 0.95904748 | C15: =AI15/W15 -> 0.036495067 | D15: =AO15/W15 -> 0.0044574557 | F15: 1987 | G15: =AD15/X15 -> 0.1219596 | H15: =AJ15/X15 -> 0.85646721 | I15: =AP15/X15 -> 0.021573183 | K15: 1987 | L15: =AE15/Y15 -> 0.95888098 | M15: =AK15/Y15 -> 0.036630516 | N15: =AQ15/Y15 -> 0.0044885034 | P15: 1987 | Q15: =AF15/Z15 -> 0.99361256 | R15: =AL15/Z15 -> 0.0026825418 | S15: =AR15/Z15 -> 0.0037048933 | U15: 1987 | V15: 7933729 | W15: 5336228 | X15: 84364 | Y15: 2292078 | Z15: 221059 | AA15: 1987 | AB15: 7545462 | AC15: 5117696 | AD15: 10289 | AE15: 2197830 | AF15: 219647 | AG15: 1987 | AH15: 351554 | AI15: 194746 | AJ15: 72255 | AK15: 83960 | AL15: 593 | AM15: 1987 | AN15: 36713 | AO15: 23786 | AP15: 1820 | AQ15: 10288 | AR15: 819
A16: 1988 | B16: =AC16/W16 -> 0.960961 | C16: =AI16/W16 -> 0.034844093 | D16: =AO16/W16 -> 0.004194911 | F16: 1988 | G16: =AD16/X16 -> 0.12309191 | H16: =AJ16/X16 -> 0.85500241 | I16: =AP16/X16 -> 0.021905689 | K16: 1988 | L16: =AE16/Y16 -> 0.96068522 | M16: =AK16/Y16 -> 0.034950135 | N16: =AQ16/Y16 -> 0.0043646415 | P16: 1988 | Q16: =AF16/Z16 -> 0.99372183 | R16: =AL16/Z16 -> 0.002648028 | S16: =AR16/Z16 -> 0.0036301389 | U16: 1988 | V16: 8324887 | W16: 5597735 | X16: 85229 | Y16: 2424025 | Z16: 217898 | AA16: 1988 | AB16: 7934951 | AC16: 5379205 | AD16: 10491 | AE16: 2328725 | AF16: 216530 | AG16: 1988 | AH16: 353216 | AI16: 195048 | AJ16: 72871 | AK16: 84720 | AL16: 577 | AM16: 1988 | AN16: 36720 | AO16: 23482 | AP16: 1867 | AQ16: 10580 | AR16: 791
A17: 1989 | B17: =AC17/W17 -> 0.95709076 | C17: =AI17/W17 -> 0.038350591 | D17: =AO17/W17 -> 0.0045586498 | F17: 1989 | G17: =AD17/X17 -> 0.12267332 | H17: =AJ17/X17 -> 0.85085968 | I17: =AP17/X17 -> 0.026466999 | K17: 1989 | L17: =AE17/Y17 -> 0.95850385 | M17: =AK17/Y17 -> 0.036041673 | N17: =AQ17/Y17 -> 0.0054544759 | P17: 1989 | Q17: =AF17/Z17 -> 0.99332931 | R17: =AL17/Z17 -> 0.0028282287 | S17: =AR17/Z17 -> 0.0038424592 | U17: 1989 | V17: 9009048 | W17: 6003532 | X17: 90150 | Y17: 2691551 | Z17: 223815 | AA17: 1989 | AB17: 8559168 | AC17: 5745925 | AD17: 11059 | AE17: 2579862 | AF17: 222322 | AG17: 1989 | AH17: 404585 | AI17: 230239 | AJ17: 76705 | AK17: 97008 | AL17: 633 | AM17: 1989 | AN17: 45295 | AO17: 27368 | AP17: 2386 | AQ17: 14681 | AR17: 860
A18: 1990 | B18: =AC18/W18 -> 0.95495176 | C18: =AI18/W18 -> 0.040152543 | D18: =AO18/W18 -> 0.0048956991 | F18: 1990 | G18: =AD18/X18 -> 0.13190029 | H18: =AJ18/X18 -> 0.83750201 | I18: =AP18/X18 -> 0.030597695 | K18: 1990 | L18: =AE18/Y18 -> 0.95650068 | M18: =AK18/Y18 -> 0.037968642 | N18: =AQ18/Y18 -> 0.0055306779 | P18: 1990 | Q18: =AF18/Z18 -> 0.99237166 | R18: =AL18/Z18 -> 0.0029129299 | S18: =AR18/Z18 -> 0.0047154059 | U18: 1990 | V18: 9862108 | W18: 6555550 | X18: 93275 | Y18: 2964736 | Z18: 248547 | AA18: 1990 | AB18: 9354960 | AC18: 6260234 | AD18: 12303 | AE18: 2835772 | AF18: 246651 | AG18: 1990 | AH18: 454631 | AI18: 263222 | AJ18: 78118 | AK18: 112567 | AL18: 724 | AM18: 1990 | AN18: 52517 | AO18: 32094 | AP18: 2854 | AQ18: 16397 | AR18: 1172
A19: 1991 | B19: =AC19/W19 -> 0.95573285 | C19: =AI19/W19 -> 0.039289235 | D19: =AO19/W19 -> 0.0049779102 | F19: 1991 | G19: =AD19/X19 -> 0.12589 | H19: =AJ19/X19 -> 0.84194614 | I19: =AP19/X19 -> 0.032163863 | K19: 1991 | L19: =AE19/Y19 -> 0.95884271 | M19: =AK19/Y19 -> 0.035684247 | N19: =AQ19/Y19 -> 0.0054730441 | P19: 1991 | Q19: =AF19/Z19 -> 0.99242468 | R19: =AL19/Z19 -> 0.0028914906 | S19: =AR19/Z19 -> 0.0046838318 | U19: 1991 | V19: 10602143 | W19: 6950708 | X19: 96910 | Y19: 3293414 | Z19: 261111 | AA19: 1991 | AB19: 10072219 | AC19: 6643020 | AD19: 12200 | AE19: 3157866 | AF19: 259133 | AG19: 1991 | AH19: 472959 | AI19: 273088 | AJ19: 81593 | AK19: 117523 | AL19: 755 | AM19: 1991 | AN19: 56965 | AO19: 34600 | AP19: 3117 | AQ19: 18025 | AR19: 1223
... A51: 2023 | B51: =AC51/W51 -> 0.98013846 | C51: =AI51/W51 -> 0.018129938 | D51: =AO51/W51 -> 0.001731603 | F51: 2023 | G51: =AD51/X51 -> 0.62196481 | H51: =AJ51/X51 -> 0.37170159 | I51: =AP51/X51 -> 0.0063335954 | K51: 2023 | L51: =AE51/Y51 -> 0.98182133 | M51: =AK51/Y51 -> 0.010525868 | N51: =AQ51/Y51 -> 0.0076528059 | P51: 2023 | Q51: =AF51/Z51 -> 0.99472515 | R51: =AL51/Z51 -> 0.0029520253 | S51: =AR51/Z51 -> 0.0023228252 | U51: 2023 | V51: 58199293 | W51: 38039898 | X51: 487243 | Y51: 11887666 | Z51: 7784486 | AA51: 2023 | AB51: 57002403 | AC51: 37284367 | AD51: 303048 | AE51: 11671564 | AF51: 7743424 | AG51: 2023 | AH51: 1018878 | AI51: 689661 | AJ51: 181109 | AK51: 125128 | AL51: 22980 | AM51: 2023 | AN51: 178012 | AO51: 65870 | AP51: 3086 | AQ51: 90974 | AR51: 18082
A52: Average | F52: Average | K52: Average | P52: Average
A53: 2018-2022 | B53: =SUM(AC46:AC50)/SUM(W46:W50) -> 0.97765833 | C53: =SUM(AI46:AI50)/SUM(W46:W50) -> 0.020530968 | D53: =SUM(AO46:AO50)/SUM(W46:W50) -> 0.0018107038 | F53: 2018-2022 | G53: =SUM(AD46:AD50)/SUM(X46:X50) -> 0.57517607 | H53: =SUM(AJ46:AJ50)/SUM(X46:X50) -> 0.41754551 | I53: =SUM(AP46:AP50)/SUM(X46:X50) -> 0.0072784155 | K53: 2018-2022 | L53: =SUM(AE46:AE50)/SUM(Y46:Y50) -> 0.97766701 | M53: =SUM(AK46:AK50)/SUM(Y46:Y50) -> 0.014392488 | N53: =SUM(AQ46:AQ50)/SUM(Y46:Y50) -> 0.0079405048 | P53: 2018-2022 | Q53: =SUM(AF46:AF50)/SUM(Z46:Z50) -> 0.99332901 | R53: =SUM(AL46:AL50)/SUM(Z46:Z50) -> 0.0036269735 | S53: =SUM(AR46:AR50)/SUM(Z46:Z50) -> 0.0030440186
U55: FUENTE: INEGI. Estadísticas de vehículos de motor registrados en circulación. | AA55: FUENTE: INEGI. Estadísticas de vehículos de motor registrados en circulación. | AG55: FUENTE: INEGI. Estadísticas de vehículos de motor registrados en circulación. | AM55: FUENTE: INEGI. Estadísticas de vehículos de motor registrados en circulación.
U57: INEGI | W57: http://www.inegi.org.mx/lib/olap/consulta/general_ver4/MDXQueryDatos.asp?#Regreso&c=
U58: Veh_xD8F5_los de motor registrados en circulaci󮼢r>
U59: Consulta de: Veh_xD8F5_los registrados Por: A񯠤e registro Segn: Clase de veh_xD8F5_lo y Tipo de servicio
V62: Total | W62: Total | X62: Total | Y62: Total | Z62: Autom󶩬es | AA62: Autom󶩬es | AB62: Autom󶩬es | AC62: Autom󶩬es | AD62: Camiones para pasajeros | AE62: Camiones para pasajeros | AF62: Camiones para pasajeros | AG62: Camiones para pasajeros | AH62: Camiones y camionetas para carga | AI62: Camiones y camionetas para carga | AJ62: Camiones y camionetas para carga | AK62: Camiones y camionetas para carga | AL62: Motocicletas | AM62: Motocicletas | AN62: Motocicletas | AO62: Motocicletas
V63: Total | W63: Oficiales | X63: Pblicos | Y63: Particulares | Z63: Total | AA63: Oficiales | AB63: Pblicos | AC63: Particulares | AD63: Total | AE63: Oficiales | AF63: Pblicos | AG63: Particulares | AH63: Total | AI63: Oficiales | AJ63: Pblicos | AK63: Particulares | AL63: Total | AM63: Oficiales | AN63: Pblicos | AO63: Particulares
U64: 1980 | V64: 5758330 | W64: 22303 | X64: 214574 | Y64: 5521453 | Z64: 3950042 | AA64: 15353 | AB64: 106889 | AC64: 3827800 | AD64: 60388 | AE64: 859 | AF64: 49940 | AG64: 9589 | AH64: 1470816 | AI64: 5431 | AJ64: 57244 | AK64: 1408141 | AL64: 277084 | AM64: 660 | AN64: 501 | AO64: 275923
U65: 1981 | V65: 6339836 | W65: 24801 | X65: 237563 | Y65: 6077472 | Z65: 4341363 | AA65: 16782 | AB65: 122475 | AC65: 4202106 | AD65: 64973 | AE65: 857 | AF65: 53589 | AG65: 10527 | AH65: 1636899 | AI65: 6400 | AJ65: 60965 | AK65: 1569534 | AL65: 296601 | AM65: 762 | AN65: 534 | AO65: 295305
U66: 1982 | V66: 6695164 | W66: 18846 | X66: 257870 | Y66: 6418448 | Z66: 4616897 | AA66: 11912 | AB66: 138425 | AC66: 4466560 | AD66: 69233 | AE66: 845 | AF66: 57410 | AG66: 10978 | AH66: 1751799 | AI66: 5373 | AJ66: 61479 | AK66: 1684947 | AL66: 257235 | AM66: 716 | AN66: 556 | AO66: 255963
U67: 1983 | V67: 6941252 | W67: 25321 | X67: 274020 | Y67: 6641911 | Z67: 4726236 | AA67: 14997 | AB67: 147896 | AC67: 4563343 | AD67: 71326 | AE67: 1251 | AF67: 59723 | AG67: 10352 | AH67: 1893206 | AI67: 8359 | AJ67: 65847 | AK67: 1819000 | AL67: 250484 | AM67: 714 | AN67: 554 | AO67: 249216
U68: 1984 | V68: 7305066 | W68: 30033 | X68: 287775 | Y68: 6987258 | Z68: 4970526 | AA68: 18732 | AB68: 152820 | AC68: 4798974 | AD68: 76517 | AE68: 1605 | AF68: 64319 | AG68: 10593 | AH68: 2009875 | AI68: 8922 | AJ68: 70008 | AK68: 1930945 | AL68: 248148 | AM68: 774 | AN68: 628 | AO68: 246746
U69: 1985 | V69: 7725623 | W69: 33770 | X69: 297827 | Y69: 7394026 | Z69: 5281842 | AA69: 21905 | AB69: 157845 | AC69: 5102092 | AD69: 79028 | AE69: 1651 | AF69: 67087 | AG69: 10290 | AH69: 2114395 | AI69: 9397 | AJ69: 72272 | AK69: 2032726 | AL69: 250358 | AM69: 817 | AN69: 623 | AO69: 248918
U70: 1986 | V70: 7732012 | W70: 36205 | X70: 332570 | Y70: 7363237 | Z70: 5202922 | AA70: 23528 | AB70: 178686 | AC70: 5000708 | AD70: 83373 | AE70: 1788 | AF70: 71360 | AG70: 10225 | AH70: 2213025 | AI70: 10058 | AJ70: 81903 | AK70: 2121064 | AL70: 232692 | AM70: 831 | AN70: 621 | AO70: 231240
U71: 1987 | V71: 7933729 | W71: 36713 | X71: 351554 | Y71: 7545462 | Z71: 5336228 | AA71: 23786 | AB71: 194746 | AC71: 5117696 | AD71: 84364 | AE71: 1820 | AF71: 72255 | AG71: 10289 | AH71: 2292078 | AI71: 10288 | AJ71: 83960 | AK71: 2197830 | AL71: 221059 | AM71: 819 | AN71: 593 | AO71: 219647
U72: 1988 | V72: 8324887 | W72: 36720 | X72: 353216 | Y72: 7934951 | Z72: 5597735 | AA72: 23482 | AB72: 195048 | AC72: 5379205 | AD72: 85229 | AE72: 1867 | AF72: 72871 | AG72: 10491 | AH72: 2424025 | AI72: 10580 | AJ72: 84720 | AK72: 2328725 | AL72: 217898 | AM72: 791 | AN72: 577 | AO72: 216530
U73: 1989 | V73: 9009048 | W73: 45295 | X73: 404585 | Y73: 8559168 | Z73: 6003532 | AA73: 27368 | AB73: 230239 | AC73: 5745925 | AD73: 90150 | AE73: 2386 | AF73: 76705 | AG73: 11059 | AH73: 2691551 | AI73: 14681 | AJ73: 97008 | AK73: 2579862 | AL73: 223815 | AM73: 860 | AN73: 633 | AO73: 222322
U74: 1990 | V74: 9862108 | W74: 52517 | X74: 454631 | Y74: 9354960 | Z74: 6555550 | AA74: 32094 | AB74: 263222 | AC74: 6260234 | AD74: 93275 | AE74: 2854 | AF74: 78118 | AG74: 12303 | AH74: 2964736 | AI74: 16397 | AJ74: 112567 | AK74: 2835772 | AL74: 248547 | AM74: 1172 | AN74: 724 | AO74: 246651
U75: 1991 | V75: 10602143 | W75: 56965 | X75: 472959 | Y75: 10072219 | Z75: 6950708 | AA75: 34600 | AB75: 273088 | AC75: 6643020 | AD75: 96910 | AE75: 3117 | AF75: 81593 | AG75: 12200 | AH75: 3293414 | AI75: 18025 | AJ75: 117523 | AK75: 3157866 | AL75: 261111 | AM75: 1223 | AN75: 755 | AO75: 259133
... U100: 2016 | V100: 42932567 | W100: 160162 | X100: 933237 | Y100: 41839168 | Z100: 29164157 | AA100: 59069 | AB100: 609552 | AC100: 28495536 | AD100: 365419 | AE100: 2073 | AF100: 158919 | AG100: 204427 | AH100: 10415934 | AI100: 82541 | AJ100: 150753 | AK100: 10182640 | AL100: 2987057 | AM100: 16479 | AN100: 14013 | AO100: 2956565
W101: =W100/V100 -> 0.003730548 | X101: =X100/V100 -> 0.021737275 | Y101: =Y100/V100 -> 0.97453218 | AA101: =AA100/Z100 -> 0.0020253971 | AB101: =AB100/Z100 -> 0.020900724 | AC101: =AC100/Z100 -> 0.97707388 | AE101: =AE100/AD100 -> 0.0056729398 | AF101: =AF100/AD100 -> 0.43489528 | AG101: =AG100/AD100 -> 0.55943178 | AI101: =AI100/AH100 -> 0.0079244934 | AJ101: =AJ100/AH100 -> 0.014473306 | AK101: =AK100/AH100 -> 0.9776022 | AM101: =AM100/AL100 -> 0.0055168013 | AN101: =AN100/AL100 -> 0.0046912396 | AO101: =AO100/AL100 -> 0.98979196
...

Sheet FoVObE-passengers
A1: Fraction Owned by Entity (dimensionless) | B1: government | C1: domestic industries | D1: labor and consumers | E1: foreign entities
A2: LDVs | B2: ='Vehicle fleet by entity MEX'!D53 -> 0.0018107038 | C2: ='Vehicle fleet by entity MEX'!C53 -> 0.020530968 | D2: ='Vehicle fleet by entity MEX'!B53 -> 0.97765833 | E2: 0
A3: HDVs | B3: ='Vehicle fleet by entity MEX'!I53 -> 0.0072784155 | C3: ='Vehicle fleet by entity MEX'!H53 -> 0.41754551 | D3: ='Vehicle fleet by entity MEX'!G53 -> 0.57517607 | E3: 0
A4: aircraft | B4: =#REF! -> #REF! | C4: =#REF! -> #REF! | D4: =#REF! -> #REF! | E4: 0
A5: rail | B5: =#REF! -> #REF! | C5: =#REF! -> #REF! | D5: =#REF! -> #REF! | E5: 0
A6: ships | B6: =#REF! -> #REF! | C6: =#REF! -> #REF! | D6: =#REF! -> #REF! | E6: 0
A7: motorbikes | B7: ='Vehicle fleet by entity MEX'!Q53 -> 0.99332901 | C7: ='Vehicle fleet by entity MEX'!R53 -> 0.0036269735 | D7: ='Vehicle fleet by entity MEX'!S53 -> 0.0030440186 | E7: 0

Sheet FoVObE-freight
A1: Fraction Owned by Entity (dimensionless) | B1: government | C1: domestic industries | D1: labor and consumers | E1: foreign entities
A2: LDVs | B2: =#REF! -> #REF! | C2: =#REF! -> #REF! | D2: =#REF! -> #REF! | E2: 0
A3: HDVs | B3: ='Vehicle fleet by entity MEX'!N53 -> 0.0079405048 | C3: ='Vehicle fleet by entity MEX'!M53 -> 0.014392488 | D3: ='Vehicle fleet by entity MEX'!L53 -> 0.97766701 | E3: 0
A4: aircraft | B4: =#REF! -> #REF! | C4: =#REF! -> #REF! | D4: =#REF! -> #REF! | E4: 0
A5: rail | B5: =#REF! -> #REF! | C5: =#REF! -> #REF! | D5: =#REF! -> #REF! | E5: 0
A6: ships | B6: =#REF! -> #REF! | C6: =#REF! -> #REF! | D6: =#REF! -> #REF! | E6: 0
A7: motorbikes | B7: =#REF! -> #REF! | C7: =#REF! -> #REF! | D7: =#REF! -> #REF! | E7: 0
