Workbook
Name lignite_multiplier: '[1]Hard Coal and Lig Multipliers'!$N$16
Name nonlignite_multiplier: '[1]Hard Coal and Lig Multipliers'!$N$17

Sheet About
A1: EIaE BAU Imported Electricity
A2: EIaE BAU Exported Electricity
A3: EIaE Imported Electricity Price
A4: EIaE BAU Exported Electricity Price
A6: Source: | B6: Import and export | C6: Data 2022 and 2023
B7: Energy Ministry (SENER)
B8: 2024
B9: National Energy Balance 2023
B10: https://www.gob.mx/cms/uploads/attachment/file/947752/BALANCE_NACIONAL_DE_ENERG_A_PRELIMINAR_2023.pdf
B13: National council of humanities, sciences and technologies | C13: Data 2020 and 2021
B14: 2024
B15: Energy futures for Mexico by 2050 The path to a just and sustainable energy transition
B16: https://conahcyt.mx/wp-content/uploads/pronaces/micrositios/energia_y_cambio_climatico/energia/cuadernos_tematicos/Cuaderno_9.pdf
B17: Statistical annex
B18: https://docs.google.com/spreadsheets/d/1_RmvJpDh5CUSkNj1lKf5HorV8Rx0YtOkXj6PAuzNAF4/edit?gid=2140732780#gid=2140732780
B19: imp and exp sheets
B21: Imported and Exported Electricity Prices
B22: Energy Information Administration
B23: 2021 and 2022
B24: Annual Energy Outlook 2021 and 2022
B25: https://www.eia.gov/outlooks/aeo/tables_side.php
B26: Table 3
A35: Notes
A36: We need to know the mix of imported electricity types if we will be including
A37: pollutant emissions associated with imported electricity into the totals, which
A38: is managed by a control lever. If these emissions will not be included in the
A39: emissions totals, the breakdown is unimportant, and you may assign all
A40: imported electricity emissions to any one electricity source, if you prefer.
A42: Electricity exports are supplied by power plants in the modeled region and
A43: hence do not need their electricity source to be specified here.
A45: Since electricity imported to the U.S. comes overwhelmingly from Canada,
A46: we use Canada's electricity generation mix to approximate the mix
A47: of all imported electricity.
A49: All Canadian natural gas was assigned to the "natural gas nonpeaker" plant type
... A58: Conversion Factors
A59: 2.931e-07 | B59: MWh/BTU
A60: 0.88711067 | B60: 2012 USD/2020 USD
A61: 0.84730413 | B61: 2012 USD/2021 USD

Sheet AEO Table 3 2023
B1: ref2023.d020623a | C1: 2022 | D1: 2023 | E1: 2024 | F1: 2025 | G1: 2026 | H1: 2027 | I1: 2028 | J1: 2029 | K1: 2030 | L1: 2031 | M1: 2032 | N1: 2033 | O1: 2034 | P1: 2035 | Q1: 2036 | R1: 2037 | S1: 2038 | T1: 2039 | U1: 2040 | V1: 2041 | W1: 2042 | X1: 2043 | Y1: 2044 | Z1: 2045 | AA1: 2046 | AB1: 2047 | AC1: 2048 | AD1: 2049 | AE1: 2050
C3: Report | D3: Annual Energy Outlook 2023
C4: Scenario | D4: ref2023 | G4: Reference
C5: Datekey | D5: d020623a
C6: Release Date | E6: March 2023
A10: PRC000 | B10: 3. Energy Prices by Sector and Source | AF10: Average
B11: (2022 dollars per million Btu, unless otherwise noted) | AF11: Annual
AF12: Change
B13: Sector and Source | C13: 2022 | D13: 2023 | E13: 2024 | F13: 2025 | G13: 2026 | H13: 2027 | I13: 2028 | J13: 2029 | K13: 2030 | L13: 2031 | M13: 2032 | N13: 2033 | O13: 2034 | P13: 2035 | Q13: 2036 | R13: 2037 | S13: 2038 | T13: 2039 | U13: 2040 | V13: 2041 | W13: 2042 | X13: 2043 | Y13: 2044 | Z13: 2045 | AA13: 2046 | AB13: 2047 | AC13: 2048 | AD13: 2049 | AE13: 2050 | AF13: 2022–2050
B15: Residential
A16: PRC000:ba_LiquefiedPetr | B16: Propane | C16: 29.133368 | D16: 31.306763 | E16: 31.488976 | F16: 30.414381 | G16: 29.316694 | H16: 28.432261 | I16: 27.927179 | J16: 27.736774 | K16: 27.826454 | L16: 28.114607 | M16: 28.577341 | N16: 29.166182 | O16: 29.755032 | P16: 30.227194 | Q16: 30.581852 | R16: 30.898972 | S16: 31.307201 | T16: 31.50728 | U16: 31.831757 | V16: 32.150085 | W16: 32.377548 | X16: 32.495739 | Y16: 32.527752 | Z16: 32.601685 | AA16: 32.818344 | AB16: 32.85873 | AC16: 32.944168 | AD16: 32.974564 | AE16: 32.963577 | AF16: 0.004421
A17: PRC000:ba_DistillateFue | B17: Distillate Fuel Oil | C17: 35.242496 | D17: 32.825691 | E17: 31.613775 | F17: 29.971098 | G17: 29.506725 | H17: 29.058901 | I17: 28.775816 | J17: 28.863544 | K17: 28.871641 | L17: 29.047983 | M17: 29.134987 | N17: 29.251019 | O17: 29.296843 | P17: 29.470129 | Q17: 29.486605 | R17: 29.608255 | S17: 29.697092 | T17: 29.738928 | U17: 29.786015 | V17: 29.942484 | W17: 29.935656 | X17: 30.04907 | Y17: 29.954853 | Z17: 29.998642 | AA17: 30.208778 | AB17: 30.235264 | AC17: 30.267241 | AD17: 30.332973 | AE17: 30.333071 | AF17: -0.005343
A18: PRC000:ba_NaturalGas | B18: Natural Gas | C18: 14.293921 | D18: 14.064584 | E18: 12.820667 | F18: 12.096767 | G18: 11.4904 | H18: 11.084416 | I18: 10.822556 | J18: 10.873314 | K18: 10.916109 | L18: 11.018429 | M18: 11.109651 | N18: 11.256351 | O18: 11.376831 | P18: 11.484237 | Q18: 11.535565 | R18: 11.619214 | S18: 11.759008 | T18: 11.765636 | U18: 11.858184 | V18: 11.954752 | W18: 11.979805 | X18: 11.966863 | Y18: 11.924366 | Z18: 11.983916 | AA18: 12.29451 | AB18: 12.278927 | AC18: 12.246208 | AD18: 12.250841 | AE18: 12.285347 | AF18: -0.005394
A19: PRC000:ba_Electricity | B19: Electricity | C19: 42.669247 | D19: 41.433243 | E19: 40.553883 | F19: 39.341568 | G19: 38.636055 | H19: 38.098618 | I19: 37.73653 | J19: 37.638126 | K19: 37.737511 | L19: 37.934017 | M19: 38.113976 | N19: 38.685684 | O19: 39.125294 | P19: 39.167233 | Q19: 39.408443 | R19: 39.708202 | S19: 40.126545 | T19: 40.421806 | U19: 40.716976 | V19: 40.952396 | W19: 41.084854 | X19: 41.174622 | Y19: 41.248722 | Z19: 41.3391 | AA19: 41.270775 | AB19: 41.153133 | AC19: 41.092045 | AD19: 40.90506 | AE19: 40.599277 | AF19: -0.001774
B21: Commercial
A22: PRC000:ca_LiquefiedGas | B22: Propane | C22: 27.825644 | D22: 26.750048 | E22: 24.895067 | F22: 22.915489 | G22: 21.863068 | H22: 21.29063 | I22: 21.16449 | J22: 21.271128 | K22: 21.567476 | L22: 21.957167 | M22: 22.450293 | N22: 22.999268 | O22: 23.455528 | P22: 23.727991 | Q22: 23.893875 | R22: 24.081245 | S22: 24.430447 | T22: 24.450624 | U22: 24.742603 | V22: 24.982395 | W22: 25.090612 | X22: 25.093864 | Y22: 25.044073 | Z22: 25.106045 | AA22: 25.32711 | AB22: 25.361147 | AC22: 25.452358 | AD22: 25.443525 | AE22: 25.401167 | AF22: -0.003251
A23: PRC000:ca_DistillateFue | B23: Distillate Fuel Oil | C23: 35.263695 | D23: 32.981144 | E23: 30.614763 | F23: 27.813896 | G23: 26.172981 | H23: 24.57275 | I23: 23.124897 | J23: 23.207827 | K23: 23.210224 | L23: 23.375801 | M23: 23.469553 | N23: 23.574059 | O23: 23.628925 | P23: 23.780882 | Q23: 23.807659 | R23: 23.920523 | S23: 24.003952 | T23: 24.045341 | U23: 24.092535 | V23: 24.247444 | W23: 24.240576 | X23: 24.354948 | Y23: 24.264793 | Z23: 24.334454 | AA23: 24.855766 | AB23: 24.870148 | AC23: 24.901745 | AD23: 24.972281 | AE23: 24.973919 | AF23: -0.012247
A24: PRC000:ca_ResidualFuel | B24: Residual Fuel Oil | C24: 12.628995 | D24: 7.865066 | E24: 9.434374 | F24: 9.738273 | G24: 11.133956 | H24: 12.534562 | I24: 14.025284 | J24: 14.102822 | K24: 14.186954 | L24: 14.294547 | M24: 14.392586 | N24: 14.48232 | O24: 14.582383 | P24: 14.694341 | Q24: 14.783643 | R24: 14.88051 | S24: 14.985899 | T24: 15.052875 | U24: 15.137448 | V24: 15.264226 | W24: 15.277987 | X24: 15.347211 | Y24: 15.376574 | Z24: 15.433166 | AA24: 15.594908 | AB24: 15.594114 | AC24: 15.714553 | AD24: 15.804392 | AE24: 15.873075 | AF24: 0.008199
A25: PRC000:ca_NaturalGas | B25: Natural Gas | C25: 10.986808 | D25: 10.325419 | E25: 9.325422 | F25: 8.846206 | G25: 8.456365 | H25: 8.24514 | I25: 8.153749 | J25: 8.191227 | K25: 8.216532 | L25: 8.296233 | M25: 8.367693 | N25: 8.499839 | O25: 8.600746 | P25: 8.688319 | Q25: 8.723988 | R25: 8.792732 | S25: 8.916448 | T25: 8.913137 | U25: 8.995551 | V25: 9.080802 | W25: 9.096286 | X25: 9.076388 | Y25: 9.030754 | Z25: 9.079571 | AA25: 9.276369 | AB25: 9.235811 | AC25: 9.192889 | AD25: 9.192929 | AE25: 9.224361 | AF25: -0.006225
A26: PRC000:ca_Electricity | B26: Electricity | C26: 36.670883 | D26: 35.900337 | E26: 34.342381 | F26: 32.872684 | G26: 32.054314 | H26: 31.460438 | I26: 30.960938 | J26: 30.716866 | K26: 30.680281 | L26: 30.663637 | M26: 30.632755 | N26: 30.980528 | O26: 31.210361 | P26: 31.136457 | Q26: 31.231977 | R26: 31.342302 | S26: 31.591194 | T26: 31.754965 | U26: 31.889711 | V26: 31.993582 | W26: 32.010456 | X26: 32.017532 | Y26: 31.980669 | Z26: 31.929119 | AA26: 31.752293 | AB26: 31.48889 | AC26: 31.376942 | AD26: 31.126701 | AE26: 30.802555 | AF26: -0.006209
B28: Industrial 1/
A29: PRC000:da_LiquefiedPetr | B29: Propane | C29: 23.43502 | D29: 21.469131 | E29: 19.205515 | F29: 17.003975 | G29: 15.9326 | H29: 15.36812 | I29: 15.270111 | J29: 15.401594 | K29: 15.727974 | L29: 16.148449 | M29: 16.682365 | N29: 17.278715 | O29: 17.769476 | P29: 18.054674 | Q29: 18.227863 | R29: 18.434586 | S29: 18.832411 | T29: 18.834532 | U29: 19.175161 | V29: 19.442755 | W29: 19.555237 | X29: 19.550402 | Y29: 19.489828 | Z29: 19.551672 | AA29: 19.545284 | AB29: 19.586832 | AC29: 19.694736 | AD29: 19.679703 | AE29: 19.63002 | AF29: -0.006308
A30: PRC000:da_DistillateFue | B30: Distillate Fuel Oil | C30: 35.187302 | D30: 32.80463 | E30: 30.476191 | F30: 27.636358 | G30: 25.955219 | H30: 24.321341 | I30: 22.837069 | J30: 22.933369 | K30: 22.940443 | L30: 23.109438 | M30: 23.21262 | N30: 23.333881 | O30: 23.39049 | P30: 23.561224 | Q30: 23.589087 | R30: 23.713947 | S30: 23.804403 | T30: 23.853134 | U30: 23.908232 | V30: 24.072897 | W30: 24.073511 | X30: 24.198322 | Y30: 24.118036 | Z30: 24.174662 | AA30: 24.400406 | AB30: 24.425331 | AC30: 24.465715 | AD30: 24.54307 | AE30: 24.550739 | AF30: -0.012773
A31: PRC000:da_ResidualFuel | B31: Residual Fuel Oil | C31: 13.34515 | D31: 8.496145 | E31: 10.168447 | F31: 10.736027 | G31: 12.278802 | H31: 13.923551 | I31: 15.540428 | J31: 15.624061 | K31: 15.728378 | L31: 15.850405 | M31: 15.970654 | N31: 16.084974 | O31: 16.205595 | P31: 16.335403 | Q31: 16.434 | R31: 16.537802 | S31: 16.65823 | T31: 16.734859 | U31: 16.83429 | V31: 16.971537 | W31: 16.992592 | X31: 17.066227 | Y31: 17.056499 | Z31: 17.117035 | AA31: 17.292305 | AB31: 17.297117 | AC31: 17.411476 | AD31: 17.497351 | AE31: 17.570717 | AF31: 0.009873
A32: PRC000:da_NaturalGas | B32: Natural Gas 2/ | C32: 7.330917 | D32: 6.270033 | E32: 5.16042 | F32: 4.592026 | G32: 4.159236 | H32: 3.920227 | I32: 3.836974 | J32: 3.852003 | K32: 3.910489 | L32: 4.015809 | M32: 4.126628 | N32: 4.284631 | O32: 4.410897 | P32: 4.522078 | Q32: 4.541005 | R32: 4.585563 | S32: 4.709835 | T32: 4.654778 | U32: 4.774618 | V32: 4.851438 | W32: 4.845424 | X32: 4.794214 | Y32: 4.744589 | Z32: 4.742186 | AA32: 4.706445 | AB32: 4.671878 | AC32: 4.638087 | AD32: 4.596459 | AE32: 4.592654 | AF32: -0.016563
A33: PRC000:da_Metallurgical | B33: Metallurgical Coal | C33: 5.430425 | D33: 5.446697 | E33: 5.679083 | F33: 5.676692 | G33: 5.706998 | H33: 5.757409 | I33: 5.79744 | J33: 5.843367 | K33: 5.947584 | L33: 6.009778 | M33: 6.110779 | N33: 6.182961 | O33: 6.250663 | P33: 6.325945 | Q33: 6.403143 | R33: 6.495366 | S33: 6.56843 | T33: 6.639044 | U33: 6.709926 | V33: 6.759548 | W33: 6.8068 | X33: 6.856149 | Y33: 6.908331 | Z33: 6.965621 | AA33: 7.01844 | AB33: 7.069538 | AC33: 7.122657 | AD33: 7.171206 | AE33: 7.226233 | AF33: 0.010256
A34: PRC000:da_SteamCoal | B34: Other Industrial Coal | C34: 2.799599 | D34: 2.739652 | E34: 2.81602 | F34: 2.878773 | G34: 2.87116 | H34: 2.854581 | I34: 2.836225 | J34: 2.826388 | K34: 2.820199 | L34: 2.815378 | M34: 2.808907 | N34: 2.808419 | O34: 2.809438 | P34: 2.811175 | Q34: 2.815027 | R34: 2.825727 | S34: 2.838923 | T34: 2.847067 | U34: 2.84949 | V34: 2.85175 | W34: 2.851687 | X34: 2.85427 | Y34: 2.853814 | Z34: 2.857372 | AA34: 2.860795 | AB34: 2.865016 | AC34: 2.870122 | AD34: 2.866868 | AE34: 2.867251 | AF34: 0.000853
A35: PRC000:da_CoaltoLiquids | B35: Coal to Liquids | C35: -- | D35: -- | E35: -- | F35: -- | G35: -- | H35: -- | I35: -- | J35: -- | K35: -- | L35: -- | M35: -- | N35: -- | O35: -- | P35: -- | Q35: -- | R35: -- | S35: -- | T35: -- | U35: -- | V35: -- | W35: -- | X35: -- | Y35: -- | Z35: -- | AA35: -- | AB35: -- | AC35: -- | AD35: -- | AE35: -- | AF35: -- | AG35: --
A36: PRC000:da_Electricity | B36: Electricity | C36: 24.421028 | D36: 23.969261 | E36: 22.165068 | F36: 20.957455 | G36: 20.154661 | H36: 19.591454 | I36: 19.228178 | J36: 19.033813 | K36: 18.984463 | L36: 18.977394 | M36: 18.98955 | N36: 19.311668 | O36: 19.408781 | P36: 19.357767 | Q36: 19.480951 | R36: 19.64303 | S36: 19.909723 | T36: 20.139053 | U36: 20.302843 | V36: 20.438232 | W36: 20.447336 | X36: 20.409019 | Y36: 20.401766 | Z36: 20.352793 | AA36: 20.226259 | AB36: 20.095247 | AC36: 20.023176 | AD36: 19.89432 | AE36: 19.708027 | AF36: -0.007629
B38: Transportation
A39: PRC000:ea_LiquefiedPetr | B39: Propane | C39: 25.673756 | D39: 24.128675 | E39: 22.471951 | F39: 20.815958 | G39: 19.998926 | H39: 19.561989 | I39: 19.492157 | J39: 19.602236 | K39: 19.865448 | L39: 20.198456 | M39: 20.616091 | N39: 21.075577 | O39: 21.446709 | P39: 21.658113 | Q39: 21.785759 | R39: 21.940096 | S39: 22.238503 | T39: 22.234596 | U39: 22.490118 | V39: 22.68578 | W39: 22.765638 | X39: 22.760218 | Y39: 22.715187 | Z39: 22.775301 | AA39: 23.024887 | AB39: 23.057398 | AC39: 23.138636 | AD39: 23.127609 | AE39: 23.092308 | AF39: -0.003778
A40: PRC000:ea_Ethanol(E85) | B40: E85 3/ | C40: 38.155422 | D40: 33.744049 | E40: 32.413799 | F40: 30.254673 | G40: 29.96781 | H40: 29.806168 | I40: 29.845123 | J40: 29.921642 | K40: 30.057253 | L40: 30.034431 | M40: 30.226929 | N40: 30.330379 | O40: 30.467768 | P40: 30.563356 | Q40: 30.925976 | R40: 30.996416 | S40: 31.117224 | T40: 31.273573 | U40: 31.334126 | V40: 31.351469 | W40: 31.450729 | X40: 31.335976 | Y40: 31.554224 | Z40: 31.580019 | AA40: 32.420742 | AB40: 32.430134 | AC40: 32.712605 | AD40: 32.812477 | AE40: 33.119743 | AF40: -0.005042
A41: PRC000:ea_MotorGasoline | B41: Motor Gasoline 4/ | C41: 34.785816 | D41: 30.5009 | E41: 27.654461 | F41: 25.814499 | G41: 25.540665 | H41: 25.387987 | I41: 25.40008 | J41: 25.444729 | K41: 25.533381 | L41: 25.497232 | M41: 25.631807 | N41: 25.694864 | O41: 25.783964 | P41: 25.841785 | Q41: 26.121752 | R41: 26.161154 | S41: 26.242393 | T41: 26.358507 | U41: 26.395033 | V41: 26.397087 | W41: 26.466999 | X41: 26.361927 | Y41: 26.536808 | Z41: 26.548639 | AA41: 27.288559 | AB41: 27.287636 | AC41: 27.511337 | AD41: 27.584213 | AE41: 27.827412 | AF41: -0.007939
A42: PRC000:ea_JetFuel | B42: Jet Fuel 5/ | C42: 26.739815 | D42: 22.567797 | E42: 21.658487 | F42: 20.17568 | G42: 19.946627 | H42: 19.713881 | I42: 19.619631 | J42: 19.732992 | K42: 19.754887 | L42: 19.972422 | M42: 20.131733 | N42: 20.218672 | O42: 20.368309 | P42: 20.522896 | Q42: 20.622114 | R42: 20.746122 | S42: 20.869146 | T42: 20.96678 | U42: 21.087648 | V42: 21.294411 | W42: 21.343142 | X42: 21.507015 | Y42: 21.467026 | Z42: 21.622814 | AA42: 21.944468 | AB42: 21.990461 | AC42: 22.051092 | AD42: 22.151415 | AE42: 22.180281 | AF42: -0.006655
A43: PRC000:ea_DistillateFue | B43: Diesel Fuel (distillate fuel oil) 6/ | C43: 37.123703 | D43: 32.857502 | E43: 31.169697 | F43: 29.060146 | G43: 28.13373 | H43: 27.197218 | I43: 26.424463 | J43: 26.52013 | K43: 26.545546 | L43: 26.701553 | M43: 26.827372 | N43: 26.946201 | O43: 26.99394 | P43: 27.20031 | Q43: 27.206823 | R43: 27.345297 | S43: 27.446815 | T43: 27.489861 | U43: 27.537863 | V43: 27.708595 | W43: 27.718977 | X43: 27.838846 | Y43: 27.744848 | Z43: 27.80047 | AA43: 28.387547 | AB43: 28.413376 | AC43: 28.46122 | AD43: 28.524797 | AE43: 28.533144 | AF43: -0.009356
A44: PRC000:ea_ResidualFuel | B44: Residual Fuel Oil | C44: 15.39181 | D44: 15.551938 | E44: 17.300776 | F44: 16.409485 | G44: 16.427687 | H44: 16.502735 | I44: 16.535357 | J44: 16.614216 | K44: 16.714342 | L44: 16.791964 | M44: 16.89019 | N44: 16.984158 | O44: 17.077217 | P44: 17.192131 | Q44: 17.249979 | R44: 17.340448 | S44: 17.439604 | T44: 17.511599 | U44: 17.576931 | V44: 17.686035 | W44: 17.712141 | X44: 17.789486 | Y44: 17.786716 | Z44: 17.831644 | AA44: 18.012905 | AB44: 18.00956 | AC44: 18.112957 | AD44: 18.199448 | AE44: 18.28933 | AF44: 0.006179
A45: PRC000:ea_NaturalGas | B45: Natural Gas 7/ | C45: 17.54928 | D45: 16.298449 | E45: 14.88739 | F45: 14.304173 | G45: 13.609575 | H45: 13.258362 | I45: 13.009375 | J45: 12.877625 | K45: 12.804221 | L45: 12.79319 | M45: 12.772279 | N45: 12.814316 | O45: 12.811182 | P45: 12.783017 | Q45: 12.651464 | R45: 12.542599 | S45: 12.536258 | T45: 12.333598 | U45: 12.31179 | V45: 12.251882 | W45: 12.115541 | X45: 11.941437 | Y45: 11.766513 | Z45: 11.69476 | AA45: 12.298188 | AB45: 12.136044 | AC45: 11.981798 | AD45: 11.858985 | AE45: 11.776169 | AF45: -0.014147
A46: PRC000:ea_Electricity | B46: Electricity | C46: 42.503979 | D46: 44.014454 | E46: 42.699257 | F46: 40.270164 | G46: 39.897511 | H46: 39.828831 | I46: 39.741402 | J46: 39.72414 | K46: 39.732391 | L46: 39.929424 | M46: 40.166943 | N46: 40.565945 | O46: 40.854523 | P46: 41.05629 | Q46: 41.06863 | R46: 41.392082 | S46: 41.665051 | T46: 42.074825 | U46: 42.285225 | V46: 42.527729 | W46: 42.529423 | X46: 42.497456 | Y46: 42.464611 | Z46: 42.516262 | AA46: 42.623566 | AB46: 42.482262 | AC46: 42.484821 | AD46: 42.022789 | AE46: 41.658325 | AF46: -0.000717
B48: Electric Power 8/
A49: PRC000:ga_DistillateFue | B49: Distillate Fuel Oil | C49: 35.259407 | D49: 32.908623 | E49: 30.715006 | F49: 27.876041 | G49: 26.264648 | H49: 24.649519 | I49: 23.123522 | J49: 23.303953 | K49: 23.443438 | L49: 23.430513 | M49: 23.544266 | N49: 23.535339 | O49: 23.673569 | P49: 23.769455 | Q49: 23.84054 | R49: 23.890585 | S49: 23.930655 | T49: 24.005789 | U49: 24.099161 | V49: 24.257807 | W49: 24.249802 | X49: 24.362133 | Y49: 24.304323 | Z49: 24.419262 | AA49: 24.659782 | AB49: 24.697874 | AC49: 24.74641 | AD49: 24.866106 | AE49: 24.873064 | AF49: -0.012385
...

Sheet AEO Table 3 2022
B1: ref2022.d011222a | C1: 2021 | D1: 2022 | E1: 2023 | F1: 2024 | G1: 2025 | H1: 2026 | I1: 2027 | J1: 2028 | K1: 2029 | L1: 2030 | M1: 2031 | N1: 2032 | O1: 2033 | P1: 2034 | Q1: 2035 | R1: 2036 | S1: 2037 | T1: 2038 | U1: 2039 | V1: 2040 | W1: 2041 | X1: 2042 | Y1: 2043 | Z1: 2044 | AA1: 2045 | AB1: 2046 | AC1: 2047 | AD1: 2048 | AE1: 2049 | AF1: 2050
C3: Report | D3: Annual Energy Outlook 2022
C4: Scenario | D4: ref2022 | G4: Reference
C5: Datekey | D5: d011222a
C6: Release Date | E6: March 2022
A10: PRC000 | B10: 3. Energy Prices by Sector and Source | AG10: Average
B11: (2021 dollars per million Btu, unless otherwise noted) | AG11: Annual
AG12: Change
B13: Sector and Source | C13: 2021 | D13: 2022 | E13: 2023 | F13: 2024 | G13: 2025 | H13: 2026 | I13: 2027 | J13: 2028 | K13: 2029 | L13: 2030 | M13: 2031 | N13: 2032 | O13: 2033 | P13: 2034 | Q13: 2035 | R13: 2036 | S13: 2037 | T13: 2038 | U13: 2039 | V13: 2040 | W13: 2041 | X13: 2042 | Y13: 2043 | Z13: 2044 | AA13: 2045 | AB13: 2046 | AC13: 2047 | AD13: 2048 | AE13: 2049 | AF13: 2050 | AG13: 2021–2050
B15: Residential
A16: PRC000:ba_LiquefiedPetr | B16: Propane | C16: 21.519539 | D16: 23.171989 | E16: 22.882879 | F16: 22.879547 | G16: 22.81468 | H16: 22.860277 | I16: 23.090302 | J16: 23.526861 | K16: 24.041061 | L16: 24.518085 | M16: 24.986616 | N16: 25.594236 | O16: 26.029459 | P16: 26.333237 | Q16: 26.526838 | R16: 26.637016 | S16: 26.823605 | T16: 27.044893 | U16: 27.215189 | V16: 27.495535 | W16: 27.787014 | X16: 28.060249 | Y16: 28.415535 | Z16: 28.739542 | AA16: 28.873835 | AB16: 28.852163 | AC16: 28.765711 | AD16: 28.699755 | AE16: 28.682411 | AF16: 28.628248 | AG16: 0.009891
A17: PRC000:ba_DistillateFue | B17: Distillate Fuel Oil | C17: 21.74482 | D17: 22.068129 | E17: 21.495361 | F17: 22.810974 | G17: 23.416267 | H17: 23.953699 | I17: 24.605654 | J17: 24.700975 | K17: 24.801643 | L17: 24.726501 | M17: 24.89443 | N17: 25.006918 | O17: 25.06778 | P17: 25.021008 | Q17: 25.012953 | R17: 25.030716 | S17: 25.173168 | T17: 25.266403 | U17: 25.26918 | V17: 25.488142 | W17: 25.65202 | X17: 25.722313 | Y17: 25.994267 | Z17: 26.257401 | AA17: 26.239376 | AB17: 26.421463 | AC17: 26.39146 | AD17: 26.301579 | AE17: 26.37286 | AF17: 26.23348 | AG17: 0.006492
A18: PRC000:ba_NaturalGas | B18: Natural Gas | C18: 11.714767 | D18: 12.151939 | E18: 11.530189 | F18: 11.049291 | G18: 10.738748 | H18: 10.557094 | I18: 10.430874 | J18: 10.569336 | K18: 10.733542 | L18: 10.824615 | M18: 10.916719 | N18: 11.249624 | O18: 11.388998 | P18: 11.442094 | Q18: 11.442281 | R18: 11.411037 | S18: 11.449186 | T18: 11.482208 | U18: 11.520953 | V18: 11.549916 | W18: 11.630534 | X18: 11.626328 | Y18: 11.591697 | Z18: 11.577318 | AA18: 11.548356 | AB18: 11.546086 | AC18: 11.550601 | AD18: 11.556095 | AE18: 11.593725 | AF18: 11.616578 | AG18: -0.00029
A19: PRC000:ba_Electricity | B19: Electricity | C19: 38.76239 | D19: 38.520023 | E19: 38.213291 | F19: 37.571396 | G19: 37.389545 | H19: 37.544312 | I19: 37.608688 | J19: 37.67712 | K19: 37.800606 | L19: 37.826485 | M19: 37.95697 | N19: 38.120724 | O19: 38.280704 | P19: 38.361744 | Q19: 38.052212 | R19: 37.810265 | S19: 37.659115 | T19: 37.508751 | U19: 37.363533 | V19: 37.418816 | W19: 37.32682 | X19: 37.339638 | Y19: 37.170746 | Z19: 37.042542 | AA19: 37.059158 | AB19: 36.817814 | AC19: 36.777477 | AD19: 36.656681 | AE19: 36.538506 | AF19: 36.290455 | AG19: -0.00227
B21: Commercial
A22: PRC000:ca_LiquefiedGas | B22: Propane | C22: 18.82229 | D22: 19.715876 | E22: 18.120464 | F22: 18.024939 | G22: 17.919872 | H22: 18.009079 | I22: 18.3034 | J22: 18.778172 | K22: 19.233488 | L22: 19.571339 | M22: 19.902462 | N22: 20.432222 | O22: 20.743967 | P22: 20.877277 | Q22: 20.929077 | R22: 20.949825 | S22: 21.118494 | T22: 21.305202 | U22: 21.400408 | V22: 21.663759 | W22: 21.891474 | X22: 22.078979 | Y22: 22.382664 | Z22: 22.604012 | AA22: 22.578735 | AB22: 22.440573 | AC22: 22.312597 | AD22: 22.263029 | AE22: 22.278421 | AF22: 22.221497 | AG22: 0.005741
A23: PRC000:ca_DistillateFue | B23: Distillate Fuel Oil | C23: 21.823187 | D23: 22.151241 | E23: 20.410337 | F23: 20.680359 | G23: 20.203226 | H23: 19.669413 | I23: 19.257957 | J23: 19.355928 | K23: 19.454554 | L23: 19.407745 | M23: 19.577158 | N23: 20.015388 | O23: 20.072495 | P23: 20.03583 | Q23: 20.077394 | R23: 20.092907 | S23: 20.242428 | T23: 20.340593 | U23: 20.341209 | V23: 20.574266 | W23: 20.738567 | X23: 20.811586 | Y23: 21.077398 | Z23: 21.340584 | AA23: 21.334831 | AB23: 21.519756 | AC23: 21.496529 | AD23: 21.407711 | AE23: 21.483562 | AF23: 21.350731 | AG23: -0.000754
A24: PRC000:ca_ResidualFuel | B24: Residual Fuel Oil | C24: 6.510058 | D24: 7.557132 | E24: 7.507626 | F24: 8.768214 | G24: 9.385942 | H24: 9.938887 | I24: 10.723703 | J24: 10.872849 | K24: 10.957002 | L24: 11.106604 | M24: 11.208329 | N24: 11.39804 | O24: 11.494227 | P24: 11.57103 | Q24: 11.59597 | R24: 11.640589 | S24: 11.60836 | T24: 11.717171 | U24: 11.650704 | V24: 12.228127 | W24: 12.351459 | X24: 12.376053 | Y24: 12.620767 | Z24: 12.870325 | AA24: 12.911318 | AB24: 13.078762 | AC24: 13.098419 | AD24: 13.071736 | AE24: 13.146095 | AF24: 13.070272 | AG24: 0.024325
A25: PRC000:ca_NaturalGas | B25: Natural Gas | C25: 8.442578 | D25: 8.81864 | E25: 8.497001 | F25: 8.180623 | G25: 8.017892 | H25: 7.970574 | I25: 7.962804 | J25: 8.083815 | K25: 8.223901 | L25: 8.293325 | M25: 8.363929 | N25: 8.57109 | O25: 8.670591 | P25: 8.698514 | Q25: 8.671237 | R25: 8.627092 | S25: 8.651712 | T25: 8.673417 | U25: 8.701211 | V25: 8.720324 | W25: 8.789293 | X25: 8.774185 | Y25: 8.728896 | Z25: 8.705806 | AA25: 8.668962 | AB25: 8.657973 | AC25: 8.654889 | AD25: 8.653486 | AE25: 8.683637 | AF25: 8.700233 | AG25: 0.001037
A26: PRC000:ca_Electricity | B26: Electricity | C26: 33.23053 | D26: 32.918514 | E26: 32.008312 | F26: 31.329121 | G26: 31.108648 | H26: 31.226942 | I26: 31.192585 | J26: 31.205448 | K26: 31.239994 | L26: 31.164198 | M26: 31.207338 | N26: 31.252337 | O26: 31.384094 | P26: 31.392914 | Q26: 31.002916 | R26: 30.702438 | S26: 30.551657 | T26: 30.342772 | U26: 30.176033 | V26: 30.204935 | W26: 30.056618 | X26: 30.057528 | Y26: 29.873531 | Z26: 29.691975 | AA26: 29.655783 | AB26: 29.391348 | AC26: 29.304863 | AD26: 29.157902 | AE26: 29.036934 | AF26: 28.768715 | AG26: -0.004959
B28: Industrial 1/
A29: PRC000:da_LiquefiedPetr | B29: Propane | C29: 13.663833 | D29: 14.357594 | E29: 12.540752 | F29: 12.504602 | G29: 12.409207 | H29: 12.512104 | I29: 12.822186 | J29: 13.316794 | K29: 13.784143 | L29: 14.126072 | M29: 14.469291 | N29: 14.76237 | O29: 15.093699 | P29: 15.225082 | Q29: 15.235613 | R29: 15.257844 | S29: 15.447799 | T29: 15.651039 | U29: 15.74879 | V29: 16.04315 | W29: 16.289669 | X29: 16.49139 | Y29: 16.830481 | Z29: 17.069897 | AA29: 17.026379 | AB29: 16.866844 | AC29: 16.727716 | AD29: 16.679976 | AE29: 16.703079 | AF29: 16.638475 | AG29: 0.006815
A30: PRC000:da_DistillateFue | B30: Distillate Fuel Oil | C30: 21.75238 | D30: 22.07209 | E30: 20.410429 | F30: 20.646559 | G30: 20.162947 | H30: 19.615082 | I30: 19.183277 | J30: 19.286734 | K30: 19.397879 | L30: 19.367228 | M30: 19.537781 | N30: 19.664978 | O30: 19.740728 | P30: 19.7083 | Q30: 19.713743 | R30: 19.732658 | S30: 19.883741 | T30: 19.985138 | U30: 19.992161 | V30: 20.237799 | W30: 20.408806 | X30: 20.488091 | Y30: 20.759394 | Z30: 21.023619 | AA30: 21.028748 | AB30: 21.221027 | AC30: 21.206429 | AD30: 21.123951 | AE30: 21.206486 | AF30: 21.081644 | AG30: -0.001079
A31: PRC000:da_ResidualFuel | B31: Residual Fuel Oil | C31: 7.09223 | D31: 8.293962 | E31: 8.453308 | F31: 9.941956 | G31: 10.752403 | H31: 11.551449 | I31: 12.545612 | J31: 12.71112 | K31: 12.829576 | L31: 12.988939 | M31: 13.118169 | N31: 13.329255 | O31: 13.446094 | P31: 13.510265 | Q31: 13.572783 | R31: 13.618667 | S31: 13.563599 | T31: 13.682616 | U31: 13.633999 | V31: 14.207245 | W31: 14.34065 | X31: 14.376684 | Y31: 14.61781 | Z31: 14.86674 | AA31: 14.907736 | AB31: 15.082319 | AC31: 15.10018 | AD31: 15.080288 | AE31: 15.156901 | AF31: 15.086491 | AG31: 0.026369
A32: PRC000:da_NaturalGas | B32: Natural Gas 2/ | C32: 5.071276 | D32: 4.843464 | E32: 4.512031 | F32: 4.155407 | G32: 3.980554 | H32: 3.926305 | I32: 3.957039 | J32: 4.114555 | K32: 4.261919 | L32: 4.348165 | M32: 4.405538 | N32: 4.405082 | O32: 4.501796 | P32: 4.506782 | Q32: 4.436007 | R32: 4.385244 | S32: 4.383933 | T32: 4.405835 | U32: 4.426479 | V32: 4.448872 | W32: 4.503239 | X32: 4.510521 | Y32: 4.447511 | Z32: 4.412628 | AA32: 4.339705 | AB32: 4.309629 | AC32: 4.291151 | AD32: 4.285682 | AE32: 4.295768 | AF32: 4.30372 | AG32: -0.005643
A33: PRC000:da_Metallurgical | B33: Metallurgical Coal | C33: 3.927859 | D33: 3.518811 | E33: 3.347698 | F33: 3.188333 | G33: 3.098164 | H33: 3.037497 | I33: 3.009427 | J33: 3.004971 | K33: 3.016198 | L33: 3.040812 | M33: 3.063208 | N33: 3.094111 | O33: 3.112654 | P33: 3.12921 | Q33: 3.151268 | R33: 3.173285 | S33: 3.199473 | T33: 3.221655 | U33: 3.243439 | V33: 3.268032 | W33: 3.287717 | X33: 3.306536 | Y33: 3.33003 | Z33: 3.356462 | AA33: 3.383151 | AB33: 3.410095 | AC33: 3.436724 | AD33: 3.458919 | AE33: 3.483504 | AF33: 3.508619 | AG33: -0.003885
A34: PRC000:da_SteamCoal | B34: Other Industrial Coal | C34: 2.729489 | D34: 2.681275 | E34: 2.690543 | F34: 2.694087 | G34: 2.695647 | H34: 2.689396 | I34: 2.677643 | J34: 2.675602 | K34: 2.675394 | L34: 2.676888 | M34: 2.677192 | N34: 2.681719 | O34: 2.687179 | P34: 2.68689 | Q34: 2.675991 | R34: 2.671342 | S34: 2.666051 | T34: 2.66399 | U34: 2.670385 | V34: 2.672748 | W34: 2.678431 | X34: 2.677164 | Y34: 2.67528 | Z34: 2.679811 | AA34: 2.682535 | AB34: 2.685032 | AC34: 2.684788 | AD34: 2.68338 | AE34: 2.684288 | AF34: 2.68431 | AG34: -0.000575
A35: PRC000:da_CoaltoLiquids | B35: Coal to Liquids | C35: -- | D35: -- | E35: -- | F35: -- | G35: -- | H35: -- | I35: -- | J35: -- | K35: -- | L35: -- | M35: -- | N35: -- | O35: -- | P35: -- | Q35: -- | R35: -- | S35: -- | T35: -- | U35: -- | V35: -- | W35: -- | X35: -- | Y35: -- | Z35: -- | AA35: -- | AB35: -- | AC35: -- | AD35: -- | AE35: -- | AF35: -- | AG35: --
A36: PRC000:da_Electricity | B36: Electricity | C36: 21.954327 | D36: 21.585382 | E36: 20.592312 | F36: 19.991262 | G36: 19.767326 | H36: 19.610733 | I36: 19.56032 | J36: 19.572056 | K36: 19.607359 | L36: 19.590822 | M36: 19.607412 | N36: 19.627659 | O36: 19.631359 | P36: 19.629396 | Q36: 19.42919 | R36: 19.290569 | S36: 19.131826 | T36: 19.040081 | U36: 18.93644 | V36: 18.923027 | W36: 18.863256 | X36: 18.807621 | Y36: 18.641674 | Z36: 18.541803 | AA36: 18.475939 | AB36: 18.302622 | AC36: 18.235422 | AD36: 18.142365 | AE36: 18.062515 | AF36: 17.956863 | AG36: -0.006907
B38: Transportation
A39: PRC000:ea_LiquefiedPetr | B39: Propane | C39: 17.771591 | D39: 18.268835 | E39: 16.727415 | F39: 16.714048 | G39: 16.63475 | H39: 16.724779 | I39: 16.989109 | J39: 17.403635 | K39: 17.787142 | L39: 18.062943 | M39: 18.338911 | N39: 18.912962 | O39: 19.174692 | P39: 19.274258 | Q39: 19.327059 | R39: 19.342785 | S39: 19.492384 | T39: 19.649984 | U39: 19.722977 | V39: 19.951733 | W39: 20.139431 | X39: 20.291405 | Y39: 20.549433 | Z39: 20.727776 | AA39: 20.689186 | AB39: 20.564272 | AC39: 20.45661 | AD39: 20.419739 | AE39: 20.436655 | AF39: 20.384317 | AG39: 0.004741
A40: PRC000:ea_Ethanol(E85) | B40: E85 3/ | C40: 25.787903 | D40: 25.761244 | E40: 25.495865 | F40: 25.212345 | G40: 24.975626 | H40: 25.043127 | I40: 25.355228 | J40: 25.594719 | K40: 25.777565 | L40: 26.200195 | M40: 26.276876 | N40: 27.198093 | O40: 27.413271 | P40: 27.550776 | Q40: 27.680271 | R40: 27.711462 | S40: 27.855463 | T40: 28.059765 | U40: 28.008661 | V40: 28.442335 | W40: 28.682402 | X40: 28.964655 | Y40: 29.315157 | Z40: 29.494404 | AA40: 29.595737 | AB40: 29.879946 | AC40: 29.952457 | AD40: 30.036066 | AE40: 30.150232 | AF40: 29.900158 | AG40: 0.005115
A41: PRC000:ea_MotorGasoline | B41: Motor Gasoline 4/ | C41: 25.885534 | D41: 24.823555 | E41: 21.931265 | F41: 21.752617 | G41: 21.573097 | H41: 21.630323 | I41: 21.882795 | J41: 22.068708 | K41: 22.206301 | L41: 22.537537 | M41: 22.59231 | N41: 23.553766 | O41: 23.718866 | P41: 23.814569 | Q41: 23.936171 | R41: 23.943441 | S41: 24.047487 | T41: 24.204655 | U41: 24.154181 | V41: 24.491938 | W41: 24.685377 | X41: 24.854437 | Y41: 25.146194 | Z41: 25.343546 | AA41: 25.424524 | AB41: 25.671301 | AC41: 25.718651 | AD41: 25.792084 | AE41: 25.879534 | AF41: 25.666084 | AG41: -0.000294
A42: PRC000:ea_JetFuel | B42: Jet Fuel 5/ | C42: 14.720805 | D42: 15.38822 | E42: 14.073745 | F42: 15.179766 | G42: 15.292542 | H42: 15.463751 | I42: 15.70466 | J42: 15.898726 | K42: 16.05232 | L42: 16.046509 | M42: 16.330721 | N42: 16.697517 | O42: 16.757906 | P42: 16.780107 | Q42: 16.810595 | R42: 16.876972 | S42: 17.097425 | T42: 17.235626 | U42: 17.279207 | V42: 17.533007 | W42: 17.728834 | X42: 17.813095 | Y42: 18.115818 | Z42: 18.40634 | AA42: 18.427332 | AB42: 18.612141 | AC42: 18.622166 | AD42: 18.579237 | AE42: 18.690105 | AF42: 18.608126 | AG42: 0.008113
A43: PRC000:ea_DistillateFue | B43: Diesel Fuel (distillate fuel oil) 6/ | C43: 23.750263 | D43: 22.843327 | E43: 21.93634 | F43: 22.651623 | G43: 22.721119 | H43: 22.675623 | I43: 22.731689 | J43: 22.822958 | K43: 22.936224 | L43: 22.910614 | M43: 23.069981 | N43: 23.535149 | O43: 23.617865 | P43: 23.558996 | Q43: 23.605259 | R43: 23.598024 | S43: 23.764229 | T43: 23.864792 | U43: 23.869284 | V43: 24.107859 | W43: 24.278906 | X43: 24.369808 | Y43: 24.638464 | Z43: 24.907894 | AA43: 24.912159 | AB43: 25.116587 | AC43: 25.106068 | AD43: 25.002657 | AE43: 25.088144 | AF43: 24.951025 | AG43: 0.001702
A44: PRC000:ea_ResidualFuel | B44: Residual Fuel Oil | C44: 12.357966 | D44: 10.441763 | E44: 12.662357 | F44: 13.544412 | G44: 13.756763 | H44: 13.919001 | I44: 14.270379 | J44: 14.384391 | K44: 14.458046 | L44: 14.603832 | M44: 14.679204 | N44: 14.933182 | O44: 15.015419 | P44: 15.044872 | Q44: 15.107331 | R44: 15.142351 | S44: 15.144779 | T44: 15.235153 | U44: 15.196106 | V44: 15.646362 | W44: 15.738945 | X44: 15.785649 | Y44: 15.987934 | Z44: 16.203949 | AA44: 16.243937 | AB44: 16.391148 | AC44: 16.410231 | AD44: 16.386232 | AE44: 16.43816 | AF44: 16.369478 | AG44: 0.009741
A45: PRC000:ea_NaturalGas | B45: Natural Gas 7/ | C45: 14.654003 | D45: 14.619699 | E45: 13.872672 | F45: 13.306766 | G45: 12.89931 | H45: 12.541728 | I45: 12.263359 | J45: 12.130099 | K45: 12.005839 | L45: 11.846902 | M45: 11.685585 | N45: 12.332364 | O45: 12.244666 | P45: 12.103299 | Q45: 11.998527 | R45: 11.817566 | S45: 11.702035 | T45: 11.61793 | U45: 11.537097 | V45: 11.515666 | W45: 11.50357 | X45: 11.440135 | Y45: 11.341637 | Z45: 11.270406 | AA45: 11.16805 | AB45: 11.113301 | AC45: 11.064749 | AD45: 11.018502 | AE45: 10.993929 | AF45: 10.952426 | AG45: -0.00999
A46: PRC000:ea_Electricity | B46: Electricity | C46: 39.115726 | D46: 39.616028 | E46: 38.115593 | F46: 37.093182 | G46: 37.086498 | H46: 37.542118 | I46: 37.558929 | J46: 37.560974 | K46: 37.509598 | L46: 37.302563 | M46: 37.30394 | N46: 37.330086 | O46: 37.461796 | P46: 37.336975 | Q46: 36.881054 | R46: 36.467251 | S46: 36.202427 | T46: 35.905403 | U46: 35.639503 | V46: 35.46138 | W46: 35.281731 | X46: 35.079762 | Y46: 34.771469 | Z46: 34.571163 | AA46: 34.483639 | AB46: 34.241879 | AC46: 34.021767 | AD46: 33.821972 | AE46: 33.614403 | AF46: 33.397739 | AG46: -0.005435
B48: Electric Power 8/
A49: PRC000:ga_DistillateFue | B49: Distillate Fuel Oil | C49: 21.749472 | D49: 22.063303 | E49: 20.153975 | F49: 20.553831 | G49: 19.961508 | H49: 19.321976 | I49: 18.867052 | J49: 18.963041 | K49: 19.071278 | L49: 19.038746 | M49: 19.098368 | N49: 19.294424 | O49: 19.321995 | P49: 19.367441 | Q49: 19.355671 | R49: 19.394863 | S49: 19.574009 | T49: 19.640402 | U49: 19.645767 | V49: 19.901247 | W49: 20.06513 | X49: 20.117165 | Y49: 20.384939 | Z49: 20.628145 | AA49: 20.629406 | AB49: 20.826429 | AC49: 20.826172 | AD49: 20.740261 | AE49: 20.844084 | AF49: 20.736099 | AG49: -0.001644
...

Sheet AEO Table 3 2021
B1: highogs.d120120a | C1: 2020 | D1: 2021 | E1: 2022 | F1: 2023 | G1: 2024 | H1: 2025 | I1: 2026 | J1: 2027 | K1: 2028 | L1: 2029 | M1: 2030 | N1: 2031 | O1: 2032 | P1: 2033 | Q1: 2034 | R1: 2035 | S1: 2036 | T1: 2037 | U1: 2038 | V1: 2039 | W1: 2040 | X1: 2041 | Y1: 2042 | Z1: 2043 | AA1: 2044 | AB1: 2045 | AC1: 2046 | AD1: 2047 | AE1: 2048 | AF1: 2049 | AG1: 2050
C3: Report | D3: Annual Energy Outlook 2021
C4: Scenario | D4: ref2021 | G4: Reference case
C5: Datekey | D5: d113020a
C6: Release Date | E6: January 2021
A10: PRC000 | B10: 3. Energy Prices by Sector and Source | AH10: Compound
B11: (2020 dollars per million Btu, unless otherwise noted) | AH11: Growth
AH12: 2020-2050
B13: Sector and Source | C13: 2020 | D13: 2021 | E13: 2022 | F13: 2023 | G13: 2024 | H13: 2025 | I13: 2026 | J13: 2027 | K13: 2028 | L13: 2029 | M13: 2030 | N13: 2031 | O13: 2032 | P13: 2033 | Q13: 2034 | R13: 2035 | S13: 2036 | T13: 2037 | U13: 2038 | V13: 2039 | W13: 2040 | X13: 2041 | Y13: 2042 | Z13: 2043 | AA13: 2044 | AB13: 2045 | AC13: 2046 | AD13: 2047 | AE13: 2048 | AF13: 2049 | AG13: 2050 | AH13: (percent)
B15: Residential
A16: PRC000:ba_LiquefiedPetr | B16: Propane | C16: 17.296467 | D16: 17.183254 | E16: 17.386812 | F16: 17.278086 | G16: 17.282633 | H16: 17.365963 | I16: 17.281719 | J16: 17.232769 | K16: 17.352678 | L16: 17.525156 | M16: 18.105442 | N16: 18.397449 | O16: 18.665577 | P16: 18.88686 | Q16: 19.101889 | R16: 19.23711 | S16: 19.41116 | T16: 19.712313 | U16: 19.979467 | V16: 20.173357 | W16: 20.375391 | X16: 20.580265 | Y16: 20.773108 | Z16: 20.871334 | AA16: 21.039562 | AB16: 21.186533 | AC16: 21.38179 | AD16: 21.587627 | AE16: 21.790129 | AF16: 22.029543 | AG16: 22.264086 | AH16: 0.008451
A17: PRC000:ba_DistillateFue | B17: Distillate Fuel Oil | C17: 17.748362 | D17: 17.778864 | E17: 18.840994 | F17: 20.194542 | G17: 20.900642 | H17: 21.347786 | I17: 21.95985 | J17: 22.37348 | K17: 22.572247 | L17: 22.803102 | M17: 23.134237 | N17: 23.233164 | O17: 23.457367 | P17: 23.595133 | Q17: 23.692457 | R17: 23.53126 | S17: 23.427431 | T17: 23.58984 | U17: 23.769676 | V17: 23.632313 | W17: 24.000732 | X17: 24.13143 | Y17: 24.220469 | Z17: 24.344158 | AA17: 24.51425 | AB17: 24.754841 | AC17: 24.880373 | AD17: 24.974497 | AE17: 25.016258 | AF17: 25.183065 | AG17: 25.323921 | AH17: 0.011919
A18: PRC000:ba_NaturalGas | B18: Natural Gas | C18: 10.141716 | D18: 10.51412 | E18: 10.202188 | F18: 9.913226 | G18: 9.649481 | H18: 9.660916 | I18: 9.737484 | J18: 9.850092 | K18: 9.923312 | L18: 10.06601 | M18: 10.422234 | N18: 10.498061 | O18: 10.580394 | P18: 10.658723 | Q18: 10.693798 | R18: 10.700832 | S18: 10.715192 | T18: 10.731378 | U18: 10.724482 | V18: 10.712461 | W18: 10.708804 | X18: 10.731961 | Y18: 10.757458 | Z18: 10.775259 | AA18: 10.802486 | AB18: 10.823374 | AC18: 10.832982 | AD18: 10.843533 | AE18: 10.825556 | AF18: 10.832339 | AG18: 10.859445 | AH18: 0.002282
A19: PRC000:ba_Electricity | B19: Electricity | C19: 35.768967 | D19: 36.572845 | E19: 36.200897 | F19: 35.847927 | G19: 35.555779 | H19: 35.370304 | I19: 35.271217 | J19: 35.232407 | K19: 35.179947 | L19: 35.13731 | M19: 35.114113 | N19: 35.213707 | O19: 35.215427 | P19: 35.186943 | Q19: 35.111835 | R19: 34.965027 | S19: 34.841293 | T19: 34.730331 | U19: 34.648323 | V19: 34.567348 | W19: 34.484665 | X19: 34.428879 | Y19: 34.354916 | Z19: 34.264565 | AA19: 34.180298 | AB19: 34.138596 | AC19: 34.02042 | AD19: 33.894436 | AE19: 33.717102 | AF19: 33.468891 | AG19: 33.255077 | AH19: -0.002426
B21: Commercial
A22: PRC000:ca_LiquefiedGas | B22: Propane | C22: 12.770181 | D22: 13.596351 | E22: 14.132167 | F22: 13.946478 | G22: 13.993322 | H22: 14.10978 | I22: 13.959495 | J22: 13.925439 | K22: 14.114777 | L22: 14.294835 | M22: 14.966532 | N22: 15.145463 | O22: 15.316516 | P22: 15.455637 | Q22: 15.603415 | R22: 15.65097 | S22: 15.789752 | T22: 16.088108 | U22: 16.278292 | V22: 16.373463 | W22: 16.514631 | X22: 16.663309 | Y22: 16.795403 | Z22: 16.807695 | AA22: 16.958042 | AB22: 17.057177 | AC22: 17.22489 | AD22: 17.38492 | AE22: 17.530947 | AF22: 17.725052 | AG22: 17.895052 | AH22: 0.011311
A23: PRC000:ca_DistillateFue | B23: Distillate Fuel Oil | C23: 17.825056 | D23: 17.90453 | E23: 17.917162 | F23: 18.273129 | G23: 17.977633 | H23: 17.420301 | I23: 17.035746 | J23: 17.45133 | K23: 17.649296 | L23: 17.881008 | M23: 18.477827 | N23: 18.582241 | O23: 18.841583 | P23: 18.984005 | Q23: 19.086586 | R23: 18.923241 | S23: 18.824066 | T23: 18.987247 | U23: 19.171539 | V23: 19.037495 | W23: 19.410124 | X23: 19.543423 | Y23: 19.633228 | Z23: 19.766468 | AA23: 19.946016 | AB23: 20.19311 | AC23: 20.325541 | AD23: 20.426331 | AE23: 20.483273 | AF23: 20.656473 | AG23: 20.796879 | AH23: 0.005153
A24: PRC000:ca_ResidualFuel | B24: Residual Fuel Oil | C24: 5.24652 | D24: 4.094263 | E24: 5.155511 | F24: 6.388786 | G24: 7.417715 | H24: 8.084204 | I24: 8.797711 | J24: 9.271342 | K24: 9.380152 | L24: 9.630754 | M24: 9.977427 | N24: 10.056496 | O24: 10.322896 | P24: 10.494815 | Q24: 10.659212 | R24: 10.565108 | S24: 10.57521 | T24: 10.757941 | U24: 10.935437 | V24: 10.928781 | W24: 11.256635 | X24: 11.39807 | Y24: 11.526395 | Z24: 11.652904 | AA24: 11.895937 | AB24: 12.079579 | AC24: 12.28236 | AD24: 12.398063 | AE24: 12.434026 | AF24: 12.576524 | AG24: 12.679845 | AH24: 0.029852
A25: PRC000:ca_NaturalGas | B25: Natural Gas | C25: 7.227466 | D25: 7.757176 | E25: 7.758438 | F25: 7.432969 | G25: 7.15386 | H25: 7.140882 | I25: 7.187162 | J25: 7.262215 | K25: 7.303709 | L25: 7.416845 | M25: 7.668393 | N25: 7.709173 | O25: 7.756773 | P25: 7.814415 | Q25: 7.83147 | R25: 7.823295 | S25: 7.823662 | T25: 7.825634 | U25: 7.805791 | V25: 7.781954 | W25: 7.768893 | X25: 7.783077 | Y25: 7.799472 | Z25: 7.808736 | AA25: 7.828284 | AB25: 7.841544 | AC25: 7.844315 | AD25: 7.846509 | AE25: 7.819409 | AF25: 7.816325 | AG25: 7.833879 | AH25: 0.002689
A26: PRC000:ca_Electricity | B26: Electricity | C26: 31.322283 | D26: 31.751371 | E26: 31.36965 | F26: 30.770927 | G26: 30.355267 | H26: 30.114548 | I26: 29.891642 | J26: 29.798216 | K26: 29.668579 | L26: 29.54162 | M26: 29.447769 | N26: 29.516174 | O26: 29.407202 | P26: 29.362705 | Q26: 29.207033 | R26: 29.013252 | S26: 28.80307 | T26: 28.61985 | U26: 28.475729 | V26: 28.334457 | W26: 28.186321 | X26: 28.052315 | Y26: 27.894957 | Z26: 27.748571 | AA26: 27.573784 | AB26: 27.437696 | AC26: 27.26679 | AD26: 27.07099 | AE26: 26.838396 | AF26: 26.563028 | AG26: 26.336115 | AH26: -0.005763
B28: Industrial 1/
A29: PRC000:da_LiquefiedPetr | B29: Propane | C29: 7.622427 | D29: 8.496119 | E29: 8.995164 | F29: 8.791455 | G29: 8.841549 | H29: 8.954068 | I29: 8.804231 | J29: 8.777181 | K29: 8.962337 | L29: 9.129627 | M29: 9.562165 | N29: 9.718732 | O29: 9.847404 | P29: 9.979259 | Q29: 10.120852 | R29: 10.16201 | S29: 10.299414 | T29: 10.596047 | U29: 10.776484 | V29: 10.863864 | W29: 11.003838 | X29: 11.150719 | Y29: 11.280413 | Z29: 11.286859 | AA29: 11.442306 | AB29: 11.53952 | AC29: 11.710324 | AD29: 11.870821 | AE29: 12.016953 | AF29: 12.215362 | AG29: 12.386859 | AH29: 0.016316
A30: PRC000:da_DistillateFue | B30: Distillate Fuel Oil | C30: 17.750837 | D30: 17.784218 | E30: 17.832458 | F30: 18.255758 | G30: 17.965652 | H30: 17.418257 | I30: 17.043358 | J30: 17.464336 | K30: 17.665487 | L30: 17.90383 | M30: 18.228374 | N30: 18.345335 | O30: 18.564774 | P30: 18.711565 | Q30: 18.823149 | R30: 18.657301 | S30: 18.557192 | T30: 18.721062 | U30: 18.906944 | V30: 18.769888 | W30: 19.141384 | X30: 19.276993 | Y30: 19.368721 | Z30: 19.507063 | AA30: 19.688093 | AB30: 19.940121 | AC30: 20.075132 | AD30: 20.18284 | AE30: 20.246756 | AF30: 20.426596 | AG30: 20.570137 | AH30: 0.004926
A31: PRC000:da_ResidualFuel | B31: Residual Fuel Oil | C31: 5.42274 | D31: 4.431344 | E31: 5.806646 | F31: 7.352966 | G31: 8.604152 | H31: 9.588043 | I31: 10.678126 | J31: 11.122404 | K31: 11.319104 | L31: 11.560951 | M31: 11.886529 | N31: 11.988492 | O31: 12.214651 | P31: 12.396055 | Q31: 12.54118 | R31: 12.441391 | S31: 12.436083 | T31: 12.619387 | U31: 12.817525 | V31: 12.799622 | W31: 13.127106 | X31: 13.276533 | Y31: 13.38976 | Z31: 13.499092 | AA31: 13.732372 | AB31: 13.936438 | AC31: 14.088271 | AD31: 14.181102 | AE31: 14.234844 | AF31: 14.370006 | AG31: 14.531082 | AH31: 0.033402
A32: PRC000:da_NaturalGas | B32: Natural Gas 2/ | C32: 3.058431 | D32: 4.045059 | E32: 3.979237 | F32: 3.564088 | G32: 3.222769 | H32: 3.167117 | I32: 3.19632 | J32: 3.294182 | K32: 3.358054 | L32: 3.462901 | M32: 3.516128 | N32: 3.544856 | O32: 3.567816 | P32: 3.613658 | Q32: 3.614324 | R32: 3.59441 | S32: 3.587867 | T32: 3.575028 | U32: 3.557224 | V32: 3.53187 | W32: 3.511744 | X32: 3.512166 | Y32: 3.514958 | Z32: 3.50462 | AA32: 3.517149 | AB32: 3.499087 | AC32: 3.486105 | AD32: 3.499511 | AE32: 3.469027 | AF32: 3.445241 | AG32: 3.461729 | AH32: 0.004137
A33: PRC000:da_Metallurgical | B33: Metallurgical Coal | C33: 4.0174 | D33: 3.598935 | E33: 3.356058 | F33: 3.207879 | G33: 3.117534 | H33: 3.070951 | I33: 3.029583 | J33: 3.01361 | K33: 3.014059 | L33: 3.036777 | M33: 3.066812 | N33: 3.102134 | O33: 3.137037 | P33: 3.169176 | Q33: 3.199574 | R33: 3.23061 | S33: 3.261404 | T33: 3.294469 | U33: 3.328295 | V33: 3.36151 | W33: 3.395033 | X33: 3.429636 | Y33: 3.466346 | Z33: 3.505546 | AA33: 3.545559 | AB33: 3.58672 | AC33: 3.624724 | AD33: 3.661516 | AE33: 3.699104 | AF33: 3.737599 | AG33: 3.780184 | AH33: -0.002027
A34: PRC000:da_SteamCoal | B34: Other Industrial Coal | C34: 2.815477 | D34: 2.827866 | E34: 2.884658 | F34: 2.873684 | G34: 2.873563 | H34: 2.861837 | I34: 2.849145 | J34: 2.837385 | K34: 2.825764 | L34: 2.820652 | M34: 2.830257 | N34: 2.828997 | O34: 2.815725 | P34: 2.816442 | Q34: 2.817086 | R34: 2.821201 | S34: 2.823316 | T34: 2.827811 | U34: 2.827212 | V34: 2.82924 | W34: 2.837649 | X34: 2.840635 | Y34: 2.844644 | Z34: 2.84973 | AA34: 2.846455 | AB34: 2.857904 | AC34: 2.860906 | AD34: 2.869795 | AE34: 2.879357 | AF34: 2.888515 | AG34: 2.900779 | AH34: 0.000995
A35: PRC000:da_CoaltoLiquids | B35: Coal to Liquids | C35: -- | D35: -- | E35: -- | F35: -- | G35: -- | H35: -- | I35: -- | J35: -- | K35: -- | L35: -- | M35: -- | N35: -- | O35: -- | P35: -- | Q35: -- | R35: -- | S35: -- | T35: -- | U35: -- | V35: -- | W35: -- | X35: -- | Y35: -- | Z35: -- | AA35: -- | AB35: -- | AC35: -- | AD35: -- | AE35: -- | AF35: -- | AG35: -- | AH35: --
A36: PRC000:da_Electricity | B36: Electricity | C36: 20.703951 | D36: 20.963264 | E36: 20.467888 | F36: 19.783636 | G36: 19.357731 | H36: 19.106281 | I36: 18.963926 | J36: 18.841095 | K36: 18.735588 | L36: 18.663567 | M36: 18.617512 | N36: 18.676767 | O36: 18.634558 | P36: 18.5455 | Q36: 18.446602 | R36: 18.351669 | S36: 18.23979 | T36: 18.124399 | U36: 18.044464 | V36: 17.939983 | W36: 17.836859 | X36: 17.750677 | Y36: 17.663349 | Z36: 17.552032 | AA36: 17.48848 | AB36: 17.401014 | AC36: 17.289835 | AD36: 17.180754 | AE36: 17.048691 | AF36: 16.892347 | AG36: 16.778522 | AH36: -0.006983
B38: Transportation
A39: PRC000:ea_LiquefiedPetr | B39: Propane | C39: 11.989126 | D39: 12.919199 | E39: 13.387474 | F39: 13.175584 | G39: 13.226618 | H39: 13.334444 | I39: 13.185479 | J39: 13.161032 | K39: 13.340968 | L39: 13.497202 | M39: 14.332111 | N39: 14.464104 | O39: 14.634573 | P39: 14.748526 | Q39: 14.872234 | R39: 14.902267 | S39: 15.02397 | T39: 15.289154 | U39: 15.443079 | V39: 15.51417 | W39: 15.635192 | X39: 15.760916 | Y39: 15.870314 | Z39: 15.87043 | AA39: 16.006077 | AB39: 16.086893 | AC39: 16.233223 | AD39: 16.368509 | AE39: 16.490398 | AF39: 16.657537 | AG39: 16.799364 | AH39: 0.011308
A40: PRC000:ea_Ethanol(E85) | B40: E85 3/ | C40: 21.197994 | D40: 22.2544 | E40: 23.610071 | F40: 23.112133 | G40: 22.835497 | H40: 22.609148 | I40: 22.527273 | J40: 23.046518 | K40: 23.283846 | L40: 23.639156 | M40: 24.640181 | N40: 24.558275 | O40: 24.877409 | P40: 25.090036 | Q40: 25.61343 | R40: 25.3027 | S40: 25.378855 | T40: 25.66387 | U40: 25.927429 | V40: 25.975618 | W40: 26.159891 | X40: 26.357864 | Y40: 26.34479 | Z40: 26.476631 | AA40: 26.680527 | AB40: 26.959341 | AC40: 27.088846 | AD40: 27.212555 | AE40: 27.351645 | AF40: 27.548573 | AG40: 27.76218 | AH40: 0.009033
A41: PRC000:ea_MotorGasoline | B41: Motor Gasoline 4/ | C41: 18.753328 | D41: 19.581623 | E41: 19.852089 | F41: 19.731396 | G41: 19.549955 | H41: 19.404346 | I41: 19.369587 | J41: 19.802027 | K41: 19.986061 | L41: 20.267641 | M41: 21.249949 | N41: 21.156803 | O41: 21.426884 | P41: 21.582792 | Q41: 22.004717 | R41: 21.723974 | S41: 21.772913 | T41: 22.005011 | U41: 22.215183 | V41: 22.246717 | W41: 22.394073 | X41: 22.54735 | Y41: 22.523794 | Z41: 22.623035 | AA41: 22.783686 | AB41: 22.996141 | AC41: 23.074652 | AD41: 23.173857 | AE41: 23.260544 | AF41: 23.427748 | AG41: 23.597351 | AH41: 0.007688
A42: PRC000:ea_JetFuel | B42: Jet Fuel 5/ | C42: 9.568654 | D42: 10.382089 | E42: 11.359349 | F42: 12.190462 | G42: 12.696321 | H42: 12.90303 | I42: 13.260797 | J42: 13.761744 | K42: 14.027101 | L42: 14.319986 | M42: 14.720232 | N42: 14.946351 | O42: 15.259788 | P42: 15.467662 | Q42: 15.60177 | R42: 15.515354 | S42: 15.477219 | T42: 15.705438 | U42: 15.944727 | V42: 15.870375 | W42: 16.294031 | X42: 16.474258 | Y42: 16.612787 | Z42: 16.803795 | AA42: 17.055935 | AB42: 17.333384 | AC42: 17.508017 | AD42: 17.640877 | AE42: 17.718878 | AF42: 17.919552 | AG42: 18.07815 | AH42: 0.021433
A43: PRC000:ea_DistillateFue | B43: Diesel Fuel (distillate fuel oil) 6/ | C43: 18.329231 | D43: 18.273304 | E43: 19.018625 | F43: 20.184969 | G43: 20.458481 | H43: 20.666317 | I43: 20.773323 | J43: 21.303528 | K43: 21.534609 | L43: 21.744459 | M43: 22.445812 | N43: 22.594145 | O43: 22.867039 | P43: 23.024622 | Q43: 23.134773 | R43: 22.871685 | S43: 22.789751 | T43: 22.977484 | U43: 23.1539 | V43: 23.013912 | W43: 23.353069 | X43: 23.471916 | Y43: 23.546528 | Z43: 23.659164 | AA43: 23.822613 | AB43: 24.034845 | AC43: 24.17654 | AD43: 24.286657 | AE43: 24.364197 | AF43: 24.512602 | AG43: 24.657568 | AH43: 0.009935
A44: PRC000:ea_ResidualFuel | B44: Residual Fuel Oil | C44: 9.208066 | D44: 6.989611 | E44: 7.144215 | F44: 8.188413 | G44: 9.349967 | H44: 9.375696 | I44: 9.64027 | J44: 10.126381 | K44: 10.226327 | L44: 10.968683 | M44: 11.327226 | N44: 11.050945 | O44: 11.334099 | P44: 11.461785 | Q44: 11.880727 | R44: 11.526117 | S44: 11.641574 | T44: 11.783689 | U44: 11.978284 | V44: 12.118925 | W44: 12.296306 | X44: 12.352102 | Y44: 12.596483 | Z44: 12.935369 | AA44: 13.238238 | AB44: 13.200082 | AC44: 13.803732 | AD44: 13.884045 | AE44: 13.935925 | AF44: 14.105252 | AG44: 14.331807 | AH44: 0.014856
A45: PRC000:ea_NaturalGas | B45: Natural Gas 7/ | C45: 12.999203 | D45: 13.612721 | E45: 13.962173 | F45: 13.394044 | G45: 12.701125 | H45: 12.45573 | I45: 12.231554 | J45: 12.004652 | K45: 11.749408 | L45: 11.559972 | M45: 12.03606 | N45: 11.756859 | O45: 11.637913 | P45: 11.466904 | Q45: 11.297943 | R45: 11.07862 | S45: 10.936546 | T45: 10.797911 | U45: 10.667474 | V45: 10.546729 | W45: 10.458061 | X45: 10.372773 | Y45: 10.336288 | Z45: 10.268269 | AA45: 10.251918 | AB45: 10.198373 | AC45: 10.155938 | AD45: 10.137851 | AE45: 10.073518 | AF45: 10.031018 | AG45: 10.035291 | AH45: -0.008589
A46: PRC000:ea_Electricity | B46: Electricity | C46: 34.881683 | D46: 36.432148 | E46: 35.38266 | F46: 34.505398 | G46: 33.776939 | H46: 33.571579 | I46: 33.493298 | J46: 33.46344 | K46: 33.426533 | L46: 33.43816 | M46: 33.332623 | N46: 33.562084 | O46: 33.609898 | P46: 33.642971 | Q46: 33.577801 | R46: 33.383286 | S46: 33.236187 | T46: 33.11697 | U46: 32.992996 | V46: 32.848633 | W46: 32.697342 | X46: 32.558189 | Y46: 32.407673 | Z46: 32.201775 | AA46: 32.01421 | AB46: 31.856125 | AC46: 31.64279 | AD46: 31.444817 | AE46: 31.182276 | AF46: 30.867584 | AG46: 30.581863 | AH46: -0.004376
B48: Electric Power 8/
A49: PRC000:ga_DistillateFue | B49: Distillate Fuel Oil | C49: 17.708588 | D49: 17.73579 | E49: 17.772367 | F49: 17.757168 | G49: 17.440514 | H49: 16.906563 | I49: 16.321712 | J49: 16.740919 | K49: 16.886805 | L49: 17.092268 | M49: 17.428493 | N49: 17.382967 | O49: 17.607697 | P49: 17.75326 | Q49: 17.881567 | R49: 17.759588 | S49: 17.726187 | T49: 17.89739 | U49: 17.993275 | V49: 17.910707 | W49: 18.34079 | X49: 18.489763 | Y49: 18.573277 | Z49: 18.707031 | AA49: 18.910122 | AB49: 19.160456 | AC49: 19.33226 | AD49: 19.448906 | AE49: 19.543753 | AF49: 19.758375 | AG49: 19.904821 | AH49: 0.003905
...

Sheet BNE
B2: 2022 | C2: 2023
A3: Importación | B3: 7.73 | C3: 7.47
A4: Exportación | B4: -8.72 | C4: -11.2

Sheet Conahcyt
B2: 2020 | C2: 2021
A3: Importación | B3: 35.87 | C3: 6.25
A4: Exportación | B4: -21.44 | C4: -9.7

Sheet Calculations
B2: 2020 | C2: 2021 | D2: 2022 | E2: 2023
A3: Importación | B3: =Conahcyt!B3 -> 35.87 | C3: =Conahcyt!C3 -> 6.25 | D3: =BNE!B3 -> 7.73 | E3: =BNE!C3 -> 7.47
A4: Exportación | B4: =Conahcyt!B4 -> -21.44 | C4: =Conahcyt!C4 -> -9.7 | D4: =BNE!B4 -> -8.72 | E4: =BNE!C4 -> -11.2
A7: Importación | B7: =B3/0.0000036 -> 9963888.9 | C7: =C3/0.0000036 -> 1736111.1 | D7: =D3/0.0000036 -> 2147222.2 | E7: =E3/0.0000036 -> 2075000
A8: Exportación | B8: =-B4/0.0000036 -> 5955555.6 | C8: =-C4/0.0000036 -> 2694444.4 | D8: =-D4/0.0000036 -> 2422222.2 | E8: =-E4/0.0000036 -> 3111111.1

Sheet EIaE-BIE
A1: Imported Electricity (MW*hour) | B1: 2020 | C1: 2021 | D1: 2022 | E1: 2023 | F1: 2024 | G1: 2025 | H1: 2026 | I1: 2027 | J1: 2028 | K1: 2029 | L1: 2030 | M1: 2031 | N1: 2032 | O1: 2033 | P1: 2034 | Q1: 2035 | R1: 2036 | S1: 2037 | T1: 2038 | U1: 2039 | V1: 2040 | W1: 2041 | X1: 2042 | Y1: 2043 | Z1: 2044 | AA1: 2045 | AB1: 2046 | AC1: 2047 | AD1: 2048 | AE1: 2049 | AF1: 2050 | AG1: 2051 | AH1: 2052 | AI1: 2053 | AJ1: 2054 | AK1: 2055 | AL1: 2056 | AM1: 2057 | AN1: 2058 | AO1: 2059 | AP1: 2060 | AQ1: 2061 | AR1: 2062 | AS1: 2063 | AT1: 2064 | AU1: 2065 | AV1: 2066 | AW1: 2067 | AX1: 2068 | AY1: 2069 | AZ1: 2070
A2: hard coal | B2: 0 | C2: 0 | D2: 0 | E2: 0 | F2: 0 | G2: 0 | H2: 0 | I2: 0 | J2: 0 | K2: 0 | L2: 0 | M2: 0 | N2: 0 | O2: 0 | P2: 0 | Q2: 0 | R2: 0 | S2: 0 | T2: 0 | U2: 0 | V2: 0 | W2: 0 | X2: 0 | Y2: 0 | Z2: 0 | AA2: 0 | AB2: 0 | AC2: 0 | AD2: 0 | AE2: 0 | AF2: 0 | AG2: 0 | AH2: 0 | AI2: 0 | AJ2: 0 | AK2: 0 | AL2: 0 | AM2: 0 | AN2: 0 | AO2: 0 | AP2: 0 | AQ2: 0 | AR2: 0 | AS2: 0 | AT2: 0 | AU2: 0 | AV2: 0 | AW2: 0 | AX2: 0 | AY2: 0 | AZ2: 0
A3: natural gas steam turbine | B3: =0.2*Calculations!B$7 -> 1992777.8 | C3: =0.2*Calculations!C$7 -> 347222.22 | D3: =0.2*Calculations!D$7 -> 429444.44 | E3: =0.2*Calculations!E$7 -> 415000 | F3: =AVERAGE($B3:$E3) -> 796111.11 | G3: =AVERAGE($B3:$E3) -> 796111.11 | H3: =AVERAGE($B3:$E3) -> 796111.11 | I3: =AVERAGE($B3:$E3) -> 796111.11 | J3: =AVERAGE($B3:$E3) -> 796111.11 | K3: =AVERAGE($B3:$E3) -> 796111.11 | L3: =AVERAGE($B3:$E3) -> 796111.11 | M3: =AVERAGE($B3:$E3) -> 796111.11 | ... AZ3: =AVERAGE($B3:$E3) -> 796111.11
A4: natural gas combined cycle | B4: =0.2*Calculations!B$7 -> 1992777.8 | C4: =0.2*Calculations!C$7 -> 347222.22 | D4: =0.2*Calculations!D$7 -> 429444.44 | E4: =0.2*Calculations!E$7 -> 415000 | F4: =AVERAGE($B4:$E4) -> 796111.11 | G4: =AVERAGE($B4:$E4) -> 796111.11 | H4: =AVERAGE($B4:$E4) -> 796111.11 | I4: =AVERAGE($B4:$E4) -> 796111.11 | J4: =AVERAGE($B4:$E4) -> 796111.11 | K4: =AVERAGE($B4:$E4) -> 796111.11 | L4: =AVERAGE($B4:$E4) -> 796111.11 | M4: =AVERAGE($B4:$E4) -> 796111.11 | ... AZ4: =AVERAGE($B4:$E4) -> 796111.11
A5: nuclear | B5: 0 | C5: 0 | D5: 0 | E5: 0 | F5: 0 | G5: 0 | H5: 0 | I5: 0 | J5: 0 | K5: 0 | L5: 0 | M5: 0 | N5: 0 | O5: 0 | P5: 0 | Q5: 0 | R5: 0 | S5: 0 | T5: 0 | U5: 0 | V5: 0 | W5: 0 | X5: 0 | Y5: 0 | Z5: 0 | AA5: 0 | AB5: 0 | AC5: 0 | AD5: 0 | AE5: 0 | AF5: 0 | AG5: 0 | AH5: 0 | AI5: 0 | AJ5: 0 | AK5: 0 | AL5: 0 | AM5: 0 | AN5: 0 | AO5: 0 | AP5: 0 | AQ5: 0 | AR5: 0 | AS5: 0 | AT5: 0 | AU5: 0 | AV5: 0 | AW5: 0 | AX5: 0 | AY5: 0 | AZ5: 0
A6: hydro | B6: 0 | C6: 0 | D6: 0 | E6: 0 | F6: 0 | G6: 0 | H6: 0 | I6: 0 | J6: 0 | K6: 0 | L6: 0 | M6: 0 | N6: 0 | O6: 0 | P6: 0 | Q6: 0 | R6: 0 | S6: 0 | T6: 0 | U6: 0 | V6: 0 | W6: 0 | X6: 0 | Y6: 0 | Z6: 0 | AA6: 0 | AB6: 0 | AC6: 0 | AD6: 0 | AE6: 0 | AF6: 0 | AG6: 0 | AH6: 0 | AI6: 0 | AJ6: 0 | AK6: 0 | AL6: 0 | AM6: 0 | AN6: 0 | AO6: 0 | AP6: 0 | AQ6: 0 | AR6: 0 | AS6: 0 | AT6: 0 | AU6: 0 | AV6: 0 | AW6: 0 | AX6: 0 | AY6: 0 | AZ6: 0
A7: onshore wind | B7: =0.2*Calculations!B$7 -> 1992777.8 | C7: =0.2*Calculations!C$7 -> 347222.22 | D7: =0.2*Calculations!D$7 -> 429444.44 | E7: =0.2*Calculations!E$7 -> 415000 | F7: =AVERAGE($B7:$E7) -> 796111.11 | G7: =AVERAGE($B7:$E7) -> 796111.11 | H7: =AVERAGE($B7:$E7) -> 796111.11 | I7: =AVERAGE($B7:$E7) -> 796111.11 | J7: =AVERAGE($B7:$E7) -> 796111.11 | K7: =AVERAGE($B7:$E7) -> 796111.11 | L7: =AVERAGE($B7:$E7) -> 796111.11 | M7: =AVERAGE($B7:$E7) -> 796111.11 | ... AZ7: =AVERAGE($B7:$E7) -> 796111.11
A8: solar PV | B8: =0.2*Calculations!B$7 -> 1992777.8 | C8: =0.2*Calculations!C$7 -> 347222.22 | D8: =0.2*Calculations!D$7 -> 429444.44 | E8: =0.2*Calculations!E$7 -> 415000 | F8: =AVERAGE($B8:$E8) -> 796111.11 | G8: =AVERAGE($B8:$E8) -> 796111.11 | H8: =AVERAGE($B8:$E8) -> 796111.11 | I8: =AVERAGE($B8:$E8) -> 796111.11 | J8: =AVERAGE($B8:$E8) -> 796111.11 | K8: =AVERAGE($B8:$E8) -> 796111.11 | L8: =AVERAGE($B8:$E8) -> 796111.11 | M8: =AVERAGE($B8:$E8) -> 796111.11 | ... AZ8: =AVERAGE($B8:$E8) -> 796111.11
A9: solar thermal | B9: 0 | C9: 0 | D9: 0 | E9: 0 | F9: 0 | G9: 0 | H9: 0 | I9: 0 | J9: 0 | K9: 0 | L9: 0 | M9: 0 | N9: 0 | O9: 0 | P9: 0 | Q9: 0 | R9: 0 | S9: 0 | T9: 0 | U9: 0 | V9: 0 | W9: 0 | X9: 0 | Y9: 0 | Z9: 0 | AA9: 0 | AB9: 0 | AC9: 0 | AD9: 0 | AE9: 0 | AF9: 0 | AG9: 0 | AH9: 0 | AI9: 0 | AJ9: 0 | AK9: 0 | AL9: 0 | AM9: 0 | AN9: 0 | AO9: 0 | AP9: 0 | AQ9: 0 | AR9: 0 | AS9: 0 | AT9: 0 | AU9: 0 | AV9: 0 | AW9: 0 | AX9: 0 | AY9: 0 | AZ9: 0
A10: biomass | B10: 0 | C10: 0 | D10: 0 | E10: 0 | F10: 0 | G10: 0 | H10: 0 | I10: 0 | J10: 0 | K10: 0 | L10: 0 | M10: 0 | N10: 0 | O10: 0 | P10: 0 | Q10: 0 | R10: 0 | S10: 0 | T10: 0 | U10: 0 | V10: 0 | W10: 0 | X10: 0 | Y10: 0 | Z10: 0 | AA10: 0 | AB10: 0 | AC10: 0 | AD10: 0 | AE10: 0 | AF10: 0 | AG10: 0 | AH10: 0 | AI10: 0 | AJ10: 0 | AK10: 0 | AL10: 0 | AM10: 0 | AN10: 0 | AO10: 0 | AP10: 0 | AQ10: 0 | AR10: 0 | AS10: 0 | AT10: 0 | AU10: 0 | AV10: 0 | AW10: 0 | AX10: 0 | AY10: 0 | AZ10: 0
A11: geothermal | B11: 0 | C11: 0 | D11: 0 | E11: 0 | F11: 0 | G11: 0 | H11: 0 | I11: 0 | J11: 0 | K11: 0 | L11: 0 | M11: 0 | N11: 0 | O11: 0 | P11: 0 | Q11: 0 | R11: 0 | S11: 0 | T11: 0 | U11: 0 | V11: 0 | W11: 0 | X11: 0 | Y11: 0 | Z11: 0 | AA11: 0 | AB11: 0 | AC11: 0 | AD11: 0 | AE11: 0 | AF11: 0 | AG11: 0 | AH11: 0 | AI11: 0 | AJ11: 0 | AK11: 0 | AL11: 0 | AM11: 0 | AN11: 0 | AO11: 0 | AP11: 0 | AQ11: 0 | AR11: 0 | AS11: 0 | AT11: 0 | AU11: 0 | AV11: 0 | AW11: 0 | AX11: 0 | AY11: 0 | AZ11: 0
A12: petroleum | B12: 0 | C12: 0 | D12: 0 | E12: 0 | F12: 0 | G12: 0 | H12: 0 | I12: 0 | J12: 0 | K12: 0 | L12: 0 | M12: 0 | N12: 0 | O12: 0 | P12: 0 | Q12: 0 | R12: 0 | S12: 0 | T12: 0 | U12: 0 | V12: 0 | W12: 0 | X12: 0 | Y12: 0 | Z12: 0 | AA12: 0 | AB12: 0 | AC12: 0 | AD12: 0 | AE12: 0 | AF12: 0 | AG12: 0 | AH12: 0 | AI12: 0 | AJ12: 0 | AK12: 0 | AL12: 0 | AM12: 0 | AN12: 0 | AO12: 0 | AP12: 0 | AQ12: 0 | AR12: 0 | AS12: 0 | AT12: 0 | AU12: 0 | AV12: 0 | AW12: 0 | AX12: 0 | AY12: 0 | AZ12: 0
A13: natural gas peaker | B13: =0.2*Calculations!B$7 -> 1992777.8 | C13: =0.2*Calculations!C$7 -> 347222.22 | D13: =0.2*Calculations!D$7 -> 429444.44 | E13: =0.2*Calculations!E$7 -> 415000 | F13: =AVERAGE($B13:$E13) -> 796111.11 | G13: =AVERAGE($B13:$E13) -> 796111.11 | H13: =AVERAGE($B13:$E13) -> 796111.11 | I13: =AVERAGE($B13:$E13) -> 796111.11 | J13: =AVERAGE($B13:$E13) -> 796111.11 | K13: =AVERAGE($B13:$E13) -> 796111.11 | L13: =AVERAGE($B13:$E13) -> 796111.11 | M13: =AVERAGE($B13:$E13) -> 796111.11 | ... AZ13: =AVERAGE($B13:$E13) -> 796111.11
A14: lignite | B14: 0 | C14: 0 | D14: 0 | E14: 0 | F14: 0 | G14: 0 | H14: 0 | I14: 0 | J14: 0 | K14: 0 | L14: 0 | M14: 0 | N14: 0 | O14: 0 | P14: 0 | Q14: 0 | R14: 0 | S14: 0 | T14: 0 | U14: 0 | V14: 0 | W14: 0 | X14: 0 | Y14: 0 | Z14: 0 | AA14: 0 | AB14: 0 | AC14: 0 | AD14: 0 | AE14: 0 | AF14: 0 | AG14: 0 | AH14: 0 | AI14: 0 | AJ14: 0 | AK14: 0 | AL14: 0 | AM14: 0 | AN14: 0 | AO14: 0 | AP14: 0 | AQ14: 0 | AR14: 0 | AS14: 0 | AT14: 0 | AU14: 0 | AV14: 0 | AW14: 0 | AX14: 0 | AY14: 0 | AZ14: 0
A15: offshore wind | B15: 0 | C15: 0 | D15: 0 | E15: 0 | F15: 0 | G15: 0 | H15: 0 | I15: 0 | J15: 0 | K15: 0 | L15: 0 | M15: 0 | N15: 0 | O15: 0 | P15: 0 | Q15: 0 | R15: 0 | S15: 0 | T15: 0 | U15: 0 | V15: 0 | W15: 0 | X15: 0 | Y15: 0 | Z15: 0 | AA15: 0 | AB15: 0 | AC15: 0 | AD15: 0 | AE15: 0 | AF15: 0 | AG15: 0 | AH15: 0 | AI15: 0 | AJ15: 0 | AK15: 0 | AL15: 0 | AM15: 0 | AN15: 0 | AO15: 0 | AP15: 0 | AQ15: 0 | AR15: 0 | AS15: 0 | AT15: 0 | AU15: 0 | AV15: 0 | AW15: 0 | AX15: 0 | AY15: 0 | AZ15: 0
A16: crude oil | B16: 0 | C16: 0 | D16: 0 | E16: 0 | F16: 0 | G16: 0 | H16: 0 | I16: 0 | J16: 0 | K16: 0 | L16: 0 | M16: 0 | N16: 0 | O16: 0 | P16: 0 | Q16: 0 | R16: 0 | S16: 0 | T16: 0 | U16: 0 | V16: 0 | W16: 0 | X16: 0 | Y16: 0 | Z16: 0 | AA16: 0 | AB16: 0 | AC16: 0 | AD16: 0 | AE16: 0 | AF16: 0 | AG16: 0 | AH16: 0 | AI16: 0 | AJ16: 0 | AK16: 0 | AL16: 0 | AM16: 0 | AN16: 0 | AO16: 0 | AP16: 0 | AQ16: 0 | AR16: 0 | AS16: 0 | AT16: 0 | AU16: 0 | AV16: 0 | AW16: 0 | AX16: 0 | AY16: 0 | AZ16: 0
A17: heavy or residual fuel oil | B17: 0 | C17: 0 | D17: 0 | E17: 0 | F17: 0 | G17: 0 | H17: 0 | I17: 0 | J17: 0 | K17: 0 | L17: 0 | M17: 0 | N17: 0 | O17: 0 | P17: 0 | Q17: 0 | R17: 0 | S17: 0 | T17: 0 | U17: 0 | V17: 0 | W17: 0 | X17: 0 | Y17: 0 | Z17: 0 | AA17: 0 | AB17: 0 | AC17: 0 | AD17: 0 | AE17: 0 | AF17: 0 | AG17: 0 | AH17: 0 | AI17: 0 | AJ17: 0 | AK17: 0 | AL17: 0 | AM17: 0 | AN17: 0 | AO17: 0 | AP17: 0 | AQ17: 0 | AR17: 0 | AS17: 0 | AT17: 0 | AU17: 0 | AV17: 0 | AW17: 0 | AX17: 0 | AY17: 0 | AZ17: 0
A18: municipal solid waste | B18: 0 | C18: 0 | D18: 0 | E18: 0 | F18: 0 | G18: 0 | H18: 0 | I18: 0 | J18: 0 | K18: 0 | L18: 0 | M18: 0 | N18: 0 | O18: 0 | P18: 0 | Q18: 0 | R18: 0 | S18: 0 | T18: 0 | U18: 0 | V18: 0 | W18: 0 | X18: 0 | Y18: 0 | Z18: 0 | AA18: 0 | AB18: 0 | AC18: 0 | AD18: 0 | AE18: 0 | AF18: 0 | AG18: 0 | AH18: 0 | AI18: 0 | AJ18: 0 | AK18: 0 | AL18: 0 | AM18: 0 | AN18: 0 | AO18: 0 | AP18: 0 | AQ18: 0 | AR18: 0 | AS18: 0 | AT18: 0 | AU18: 0 | AV18: 0 | AW18: 0 | AX18: 0 | AY18: 0 | AZ18: 0
