Workbook
Name BARRILES: 6.28982
Name calorcarbonII: 5164.3
Name calordiesel: 9243.22
Name Calorgas: 8967.6
Name calorpeta: 6389.256
Name calorrio: 3900.6
Name calorvacio: 13700
Name corr: 1
Name Eno_TM: #REF!
Name Eno_Tons: #REF!
Name ft: 35.31466
Name GWP: 21
Name iva: 1.15
Name joules: 4186.8402
Name litros: 158.987
Name NTS_YR: #REF!
Name Sum_T2: #REF!
Name Sum_TTM: #REF!
Name ti_tbl_50: #REF!
Name ti_tbl_69: #REF!
Name tonelada: 907.185

Sheet About
A1: AVL Avg Vehicle Lifetime
A3: Sources: | B3: LDV Lifetimes
B4: Calibrated
A6: Sources: | B6: On-road fleet by type of vehicle and technology
B7: Updated Transport Model Data Base (2024), self-analysis with data from INEGI
B8: 2024
B10: LDVs: Market Shares of Cars and Light Trucks
B11: INEGI -
B12: 2016
B13: National Transportation Statistics 2015
B14: http://www.rita.dot.gov/bts/sites/rita.dot.gov.bts/files/publications/national_transportation_statistics/index.html
B15: Table 1-20
B17: aircraft
B18: Secretaria de comunicaciones y transportes
B19: 2024
B20: Estadísticas de flota
B21: https://www.gob.mx/cms/uploads/attachment/file/970059/flota-reg-2024-4-trim-27012025.pdf
B22: Slide 2
B24: rail and ships
B25: California State Controller's Office
B26: 1992 (but still current)
B27: Audit Guidelines and Uniform Accounting Systems: Special Districts
B28: http://www.sco.ca.gov/ard_local_rep_uas_special_dist.html
B29: Appendix A: Suggested Useful Lives of Fixed Assets
A31: US, not used | B31: Freight HDVs
B32: Oak Ridge National Laboratory
B33: 2015
B34: Transportation Energy Data Book Ed. 34
B35: http://cta.ornl.gov/data/tedb34/Spreadsheets/Table3_14.xls
B36: Table 3-14, Row 43
A38: US, not used | B38: Passenger HDVs (Buses)
B39: ThoughtCo
B40: 2019
B41: How Long Do Buses and Other Transit Vehicles Last?
B42: https://www.thoughtco.com/buses-and-other-transit-lifetime-2798844
A44: US, not used | B44: motorbikes
B45: Bureau of Transportation Statistics
B46: 2009
B47: Motorcycle Trends in the United States
B48: http://www.rita.dot.gov/bts/sites/rita.dot.gov.bts/files/publications/special_reports_and_issue_briefs/special_report/2009_05_14/pdf/entire.pdf
...

Sheet Mexico Road Fleet
B1: Registered Vehicles INEGI | D1: 1980 | E1: 1981 | F1: 1982 | G1: 1983 | H1: 1984 | I1: 1985 | J1: 1986 | K1: 1987 | L1: 1988 | M1: 1989 | N1: 1990 | O1: 1991 | P1: 1992 | Q1: 1993 | R1: 1994 | S1: 1995 | T1: 1996 | U1: 1997 | V1: 1998 | W1: 1999 | X1: 2000 | Y1: 2001 | Z1: 2002 | AA1: 2003 | AB1: 2004 | AC1: 2005 | AD1: 2006 | AE1: 2007 | AF1: 2008 | AG1: 2009 | AH1: 2010 | AI1: 2011 | AJ1: 2012 | AK1: 2013 | AL1: 2014 | AM1: 2015 | AN1: 2016 | AO1: 2017 | AP1: 2018 | AQ1: 2019 | AR1: 2020 | AS1: 2021 | AT1: 2022 | AU1: 2023 | AV1: 2024 | BW1: . | CC1: .
B2: Automóviles | C2: Units | D2: 3950042 | E2: 4341363 | F2: 4616897 | G2: 4726236 | H2: 4970526 | I2: 5281842 | J2: 5202922 | K2: 5336228 | L2: 5597735 | M2: 6003532 | N2: 6555550 | O2: 6950708 | P2: 7399178 | Q2: 7715951 | R2: 7217732 | S2: 7469504 | T2: 7830864 | U2: 8402995 | V2: 9086209 | W2: 9582796 | X2: 10176179 | Y2: 11351982 | Z2: 12254910 | AA2: 12742049 | AB2: 13388011 | AC2: 14300380 | AD2: 16411813 | AE2: 17696623 | AF2: 19420942 | AG2: 20519224 | AH2: 21152773 | AI2: 22374326 | AJ2: 23569623 | AK2: 24819922 | AL2: 25543908 | AM2: 26907994 | AN2: 28664295 | AO2: 30696542 | AP2: 31552351 | AQ2: 32316144 | AR2: 32848577 | AS2: 33368689 | AT2: 33855651 | AU2: 34453866 | AV2: 35090355 | AX2: =(AV2/AP2)^(1/($AV$1-$AP$1))-1 -> 0.01787084 | BW2: . | CC2: .
B3: Camiones para pasajeros | C3: Units | D3: 60388 | E3: 64973 | F3: 69233 | G3: 71326 | H3: 76517 | I3: 79028 | J3: 83373 | K3: 84364 | L3: 85229 | M3: 90150 | N3: 93275 | O3: 96910 | P3: 95179 | Q3: 85941 | R3: 114577 | S3: 120497 | T3: 96933 | U3: 125445 | V3: 176443 | W3: 200357 | X3: 202396 | Y3: 273536 | Z3: 299365 | AA3: 308101 | AB3: 264585 | AC3: 268817 | AD3: 310189 | AE3: 322078 | AF3: 333287 | AG3: 337465 | AH3: 312738 | AI3: 327565 | AJ3: 338520 | AK3: 347144 | AL3: 347720 | AM3: 357452 | AN3: 367772 | AO3: 398584 | AP3: 440470 | AQ3: 450423 | AR3: 457620 | AS3: 456923 | AT3: 465103 | AU3: 484157 | AV3: 485698 | AX3: =(AV3/AP3)^(1/($AV$1-$AP$1))-1 -> 0.0164242 | BW3: . | CC3: .
B4: Camiones y camionetas para carga | C4: Units | D4: 1470816 | E4: 1636899 | F4: 1751799 | G4: 1893206 | H4: 2009875 | I4: 2114395 | J4: 2213025 | K4: 2292078 | L4: 2424025 | M4: 2691551 | N4: 2964736 | O4: 3293414 | P4: 3492416 | Q4: 3592977 | R4: 3613808 | S4: 3598685 | T4: 3645672 | U4: 3878581 | V4: 4078068 | W4: 4340112 | X4: 4939417 | Y4: 5394206 | Z4: 5860797 | AA4: 6317293 | AB4: 6707535 | AC4: 6980738 | AD4: 7462918 | AE4: 7849491 | AF4: 8453601 | AG4: 8835194 | AH4: 9015356 | AI4: 9260456 | AJ4: 9385466 | AK4: 9704131 | AL4: 9863980 | AM4: 10073288 | AN4: 10384621 | AO4: 10806605 | AP4: 11409902 | AQ4: 11998035 | AR4: 12439548 | AS4: 12961227 | AT4: 13603884 | AU4: 14413656 | AV4: 15324327 | AX4: =(AV4/AP4)^(1/($AV$1-$AP$1))-1 -> 0.050388398 | BW4: . | CC4: .
B5: Motocicletas | C5: Units | D5: 277084 | E5: 296601 | F5: 257235 | G5: 250484 | H5: 248148 | I5: 250358 | J5: 232692 | K5: 221059 | L5: 217898 | M5: 223815 | N5: 248547 | O5: 261111 | P5: 273411 | Q5: 198209 | R5: 214972 | S5: 128960 | T5: 176559 | U5: 178166 | V5: 222100 | W5: 262599 | X5: 293924 | Y5: 280806 | Z5: 369522 | AA5: 439517 | AB5: 518307 | AC5: 588543 | AD5: 722309 | AE5: 879005 | AF5: 1080073 | AG5: 1198253 | AH5: 1154145 | AI5: 1313122 | AJ5: 1582228 | AK5: 1873641 | AL5: 2271563 | AM5: 2637264 | AN5: 3037577 | AO5: 3574402 | AP5: 4135368 | AQ5: 4616977 | AR5: 5326447 | AS5: 5821035 | AT5: 6472998 | AU5: 7349263 | AV5: 8307284.5 | AX5: =(AV5/AP5)^(1/($AV$1-$AP$1))-1 -> 0.12328723 | BW5: .
B6: High | BW6: . | CC6: .
B7: Med | S7: 114785 | T7: 120868 | U7: 97716 | V7: 126892 | W7: 177674 | X7: 202140 | Y7: 205214 | Z7: 275459 | AA7: 301034 | AB7: 309753 | AC7: 266501 | AD7: 270606 | AE7: 311560 | AF7: 324102 | AG7: 334075 | AH7: 338486 | AI7: 314264 | AJ7: 328867 | AK7: 340200 | AL7: 348870 | AM7: 348891 | AN7: 359010 | AO7: 369436 | AP7: 400270 | AQ7: 442262 | AR7: 450973 | AS7: 458162 | AT7: 457667 | AU7: 466564 | AV7: 485698 | BW7: . | CC7: .
B8: Low | AO8: . | BW8: . | CC8: .
B9: Choose Growth Rate = | C9: High | AO9: . | BW9: . | CC9: .
AO10: . | BW10: .
B11: Future car fleet | D11: 2010 | E11: 2015 | F11: 2020 | G11: 2030 | H11: 2040 | I11: 2050 | AO11: . | BW11: .
B12: Car fleet growth | C12: Million vehicles | D12: =AH43/10^6 -> 16.525114 | E12: =AM44/10^6 -> 20.339859 | F12: =AR44/10^6 -> 25.226119 | G12: =BB44/10^6 -> 38.802117 | H12: =BL44/10^6 -> 59.684342 | I12: =BV44/10^6 -> 91.804802 | BW12: .
B13: Motorisation rate growth | C13: Million vehicles | D13: =AH43/10^6 -> 16.525114 | E13: =AM44/10^6 -> 20.339859 | F13: =AR45/10^6 -> 24.170076 | G13: =BB45/10^6 -> 33.469053 | H13: =BL45/10^6 -> 45.315848 | I13: =BV45/10^6 -> 60.17088 | BW13: .
B14: Car registration growth | C14: Million vehicles | D14: =AH43/10^6 -> 16.525114 | E14: =AM46/10^6 -> 20.339859 | F14: =AR46/10^6 -> 21.219673 | G14: =BB46/10^6 -> 24.576986 | H14: =BL46/10^6 -> 31.195879 | I14: =BV46/10^6 -> 42.433952 | BW14: .
BW15: .
BW16: .
BW17: .
BW18: .
BW19: .
BW20: .
BW21: .
BW22: .
BW23: .
BW24: .
BW25: .
BW26: .
... BW31: .
B32: Estimations of Actual Fleets 2015 | BW32: .
BW33: .
B34: Modelling vehicle & motorcycle retirement | BW34: .
B35: Age of car | C35: years | D35: 0 | E35: 5 | F35: 10 | G35: 15 | H35: 20 | I35: 25 | J35: 30 | K35: 35 | L35: 40 | M35: 45 | N35: 50 | O35: 55 | P35: 60 | Q35: 65 | R35: 70 | BW35: .
B36: Percent survival per age | C36: % | D36: 1 | E36: 0.99 | F36: 0.96 | G36: 0.85 | H36: 0.67 | I36: 0.48 | J36: 0.32 | K36: 0.21 | L36: 0.13 | M36: 0.08 | N36: 0.045 | O36: 0.025 | P36: 0.01 | Q36: 0.004 | R36: 0 | BW36: .
B37: Adapted (with "a lag" to the Mexican context) from: Fridstrøm, L., Østli, V. & Johansen, K.W. Eur. Transp. Res. Rev. (2016) 8: 22. https://doi.org/10.1007/s12544-016-0210-z | BW37: .
BW38: .
B39: Age of car | C39: years | D39: 0 | E39: 1 | F39: 2 | G39: 3 | H39: 4 | I39: 5 | J39: 6 | K39: 7 | L39: 8 | M39: 9 | N39: 10 | O39: 11 | P39: 12 | Q39: 13 | R39: 14 | S39: 15 | T39: 16 | U39: 17 | V39: 18 | W39: 19 | X39: 20 | Y39: 21 | Z39: 22 | AA39: 23 | AB39: 24 | AC39: 25 | AD39: 26 | AE39: 27 | AF39: 28 | AG39: 29 | AH39: 30 | AI39: 31 | AJ39: 32 | AK39: 33 | AL39: 34 | AM39: 35 | AN39: 36 | AO39: 37 | AP39: 38 | AQ39: 39 | AR39: 40 | AS39: 41 | AT39: 42 | AU39: 43 | AV39: 44 | AW39: 45 | AX39: 46 | AY39: 47 | AZ39: 48 | BA39: 49 | BB39: 50 | BC39: 51 | BD39: 52 | BE39: 53 | BF39: 54 | BG39: 55 | BH39: 56 | BI39: 57 | BJ39: 58 | BK39: 59 | BL39: 60 | BM39: 61 | BN39: 62 | BO39: 63 | BP39: 64 | BQ39: 65 | BR39: 66 | BS39: 67 | BT39: 68 | BU39: 69 | BV39: 70 | BW39: .
B40: Percent survival per age | C40: % | D40: =D36 -> 1 | E40: =($I40-$D40)/($I$39-$D$39)+D40 -> 0.998 | F40: =($I40-$D40)/($I$39-$D$39)+E40 -> 0.996 | G40: =($I40-$D40)/($I$39-$D$39)+F40 -> 0.994 | H40: =($I40-$D40)/($I$39-$D$39)+G40 -> 0.992 | I40: =E36 -> 0.99 | J40: =($N40-$I40)/($N$39-$I$39)+I40 -> 0.984 | K40: =($N40-$I40)/($N$39-$I$39)+J40 -> 0.978 | L40: =($N40-$I40)/($N$39-$I$39)+K40 -> 0.972 | M40: =($N40-$I40)/($N$39-$I$39)+L40 -> 0.966 | N40: =F36 -> 0.96 | O40: =($S40-$N40)/($S$39-$N$39)+N40 -> 0.938 | P40: =($S40-$N40)/($S$39-$N$39)+O40 -> 0.916 | Q40: =($S40-$N40)/($S$39-$N$39)+P40 -> 0.894 | R40: =($S40-$N40)/($S$39-$N$39)+Q40 -> 0.872 | S40: =G36 -> 0.85 | T40: =($X40-$S40)/($X$39-$S$39)+S40 -> 0.814 | U40: =($X40-$S40)/($X$39-$S$39)+T40 -> 0.778 | V40: =($X40-$S40)/($X$39-$S$39)+U40 -> 0.742 | W40: =($X40-$S40)/($X$39-$S$39)+V40 -> 0.706 | X40: =H36 -> 0.67 | Y40: =($AC40-$X40)/($AC$39-$X$39)+X40 -> 0.632 | Z40: =($AC40-$X40)/($AC$39-$X$39)+Y40 -> 0.594 | AA40: =($AC40-$X40)/($AC$39-$X$39)+Z40 -> 0.556 | AB40: =($AC40-$X40)/($AC$39-$X$39)+AA40 -> 0.518 | AC40: =I36 -> 0.48 | AD40: =($AH40-$AC40)/($AH$39-$AC$39)+AC40 -> 0.448 | AE40: =($AH40-$AC40)/($AH$39-$AC$39)+AD40 -> 0.416 | AF40: =($AH40-$AC40)/($AH$39-$AC$39)+AE40 -> 0.384 | AG40: =($AH40-$AC40)/($AH$39-$AC$39)+AF40 -> 0.352 | AH40: =J36 -> 0.32 | AI40: =($AM40-$AH40)/($AM$39-$AH$39)+AH40 -> 0.298 | AJ40: =($AM40-$AH40)/($AM$39-$AH$39)+AI40 -> 0.276 | AK40: =($AM40-$AH40)/($AM$39-$AH$39)+AJ40 -> 0.254 | AL40: =($AM40-$AH40)/($AM$39-$AH$39)+AK40 -> 0.232 | AM40: =K36 -> 0.21 | AN40: =($AR40-$AM40)/($AR$39-$AM$39)+AM40 -> 0.194 | AO40: =($AR40-$AM40)/($AR$39-$AM$39)+AN40 -> 0.178 | AP40: =($AR40-$AM40)/($AR$39-$AM$39)+AO40 -> 0.162 | AQ40: =($AR40-$AM40)/($AR$39-$AM$39)+AP40 -> 0.146 | AR40: =L36 -> 0.13 | AS40: =($AW40-$AR40)/($AW$39-$AR$39)+AR40 -> 0.12 | AT40: =($AW40-$AR40)/($AW$39-$AR$39)+AS40 -> 0.11 | AU40: =($AW40-$AR40)/($AW$39-$AR$39)+AT40 -> 0.1 | AV40: =($AW40-$AR40)/($AW$39-$AR$39)+AU40 -> 0.09 | AW40: =M36 -> 0.08 | AX40: =($BB40-$AW40)/($BB$39-$AW$39)+AW40 -> 0.073 | AY40: =($BB40-$AW40)/($BB$39-$AW$39)+AX40 -> 0.066 | AZ40: =($BB40-$AW40)/($BB$39-$AW$39)+AY40 -> 0.059 | BA40: =($BB40-$AW40)/($BB$39-$AW$39)+AZ40 -> 0.052 | BB40: =N36 -> 0.045 | BC40: =($BG40-$BB40)/($BG$39-$BB$39)+BB40 -> 0.041 | BD40: =($BG40-$BB40)/($BG$39-$BB$39)+BC40 -> 0.037 | BE40: =($BG40-$BB40)/($BG$39-$BB$39)+BD40 -> 0.033 | BF40: =($BG40-$BB40)/($BG$39-$BB$39)+BE40 -> 0.029 | BG40: =O36 -> 0.025 | BH40: =($BL40-$BG40)/($BL$39-$BG$39)+BG40 -> 0.022 | BI40: =($BL40-$BG40)/($BL$39-$BG$39)+BH40 -> 0.019 | BJ40: =($BL40-$BG40)/($BL$39-$BG$39)+BI40 -> 0.016 | BK40: =($BL40-$BG40)/($BL$39-$BG$39)+BJ40 -> 0.013 | BL40: =P36 -> 0.01 | BM40: =($BQ40-$BL40)/($BQ$39-$BL$39)+BL40 -> 0.0088 | BN40: =($BQ40-$BL40)/($BQ$39-$BL$39)+BM40 -> 0.0076 | BO40: =($BQ40-$BL40)/($BQ$39-$BL$39)+BN40 -> 0.0064 | BP40: =($BQ40-$BL40)/($BQ$39-$BL$39)+BO40 -> 0.0052 | BQ40: =Q36 -> 0.004 | BR40: =($BV40-$BQ40)/($BV$39-$BQ$39)+BQ40 -> 0.0032 | BS40: =($BV40-$BQ40)/($BV$39-$BQ$39)+BR40 -> 0.0024 | BT40: =($BV40-$BQ40)/($BV$39-$BQ$39)+BS40 -> 0.0016 | BU40: =($BV40-$BQ40)/($BV$39-$BQ$39)+BT40 -> 0.0008 | BV40: =R36 -> 0 | BW40: .
BW41: .
D42: 1980 | E42: 1981 | F42: 1982 | G42: 1983 | H42: 1984 | I42: 1985 | J42: 1986 | K42: 1987 | L42: 1988 | M42: 1989 | N42: 1990 | O42: 1991 | P42: 1992 | Q42: 1993 | R42: 1994 | S42: 1995 | T42: 1996 | U42: 1997 | V42: 1998 | W42: 1999 | X42: 2000 | Y42: 2001 | Z42: 2002 | AA42: 2003 | AB42: 2004 | AC42: 2005 | AD42: 2006 | AE42: 2007 | AF42: 2008 | AG42: 2009 | AH42: 2010 | AI42: 2011 | AJ42: 2012 | AK42: 2013 | AL42: 2014 | AM42: 2015 | AN42: 2016 | AO42: 2017 | AP42: 2018 | AQ42: 2019 | AR42: 2020 | AS42: 2021 | AT42: 2022 | AU42: 2023 | AV42: 2024 | AW42: 2025 | AX42: 2026 | AY42: 2027 | AZ42: 2028 | BA42: 2029 | BB42: 2030 | BC42: 2031 | BD42: 2032 | BE42: 2033 | BF42: 2034 | BG42: 2035 | BH42: 2036 | BI42: 2037 | BJ42: 2038 | BK42: 2039 | BL42: 2040 | BM42: 2041 | BN42: 2042 | BO42: 2043 | BP42: 2044 | BQ42: 2045 | BR42: 2046 | BS42: 2047 | BT42: 2048 | BU42: 2049 | BV42: 2050 | BW42: .
B43: TOTAL CAR FLEET | C43: Units | D43: =D55 -> 4298190.1 | E43: =E55 -> 4680898.9 | F43: =F55 -> 4947038.1 | G43: =G55 -> 5046431.2 | H43: =H55 -> 5280556.6 | I43: =I55 -> 5565419.3 | J43: =J55 -> 5457999.2 | K43: =K55 -> 5561239.7 | ... AV43: =AV55 -> 23298996 | BW43: .
B44: Average age real fleet (2024) | C44: Years | D44: =BE55/BD55 -> 12.99737 | L44: Milion vehicles in 2050: | AL44: Projected fleet based on its own growth trends >> | AM44: =$AM$55 -> 20339859 | AN44: =AM44*(1+$E$46) -> 21234813 | AO44: =AN44*(1+$E$46) -> 22169145 | AP44: =AO44*(1+$E$46) -> 23144587 | AQ44: =AP44*(1+$E$46) -> 24162949 | AR44: =AQ44*(1+$E$46) -> 25226119 | AS44: =AR44*(1+$E$46) -> 26336068 | AT44: =AS44*(1+$E$46) -> 27494855 | AU44: =AT44*(1+$E$46) -> 28704629 | ... BV44: =BU44*(1+$E$46) -> 91804802 | BW44: .
...

Sheet Mexico AirFleet
B26: Age of air fleet in 2022
B27: 7.7
B29: Lifetime estimated at twice the average age
B30: =B27*2 -> 15.4

Sheet Table_38._Light-Duty_Vehicle_Sa
A1: Table 38. Light-Duty Vehicle Sales by Technology Type
A2: https://www.eia.gov/outlooks/aeo/data/browser/#/?id=48-AEO2022&cases=lowmacro&sourcekey=0
A3: Fri Dec 09 2022 10:03:54 GMT-0500 (Eastern Standard Time)
A4: Source: U.S. Energy Information Administration
B5: full name | C5: api key | D5: units | E5: 2020 | F5: 2021 | G5: 2022 | H5: 2023 | I5: 2024 | J5: 2025 | K5: 2026 | L5: 2027 | M5: 2028 | N5: 2029 | O5: 2030 | P5: 2031 | Q5: 2032 | R5: 2033 | S5: 2034 | T5: 2035 | U5: 2036 | V5: 2037 | W5: 2038 | X5: 2039 | Y5: 2040 | Z5: 2041 | AA5: 2042 | AB5: 2043 | AC5: 2044 | AD5: 2045 | AE5: 2046 | AF5: 2047 | AG5: 2048 | AH5: 2049 | AI5: 2050 | AJ5: Growth (2021-2050)
A6: New Car Sales
A7: Conventional Cars
A8: Gasoline ICE Vehicles | B8: Light-Duty Vehicle Sales: Conventional Cars: Gasoline: Low economic growth | C8: AEO.2022.LOWMACRO.ECI_SAL_TRN_CAR_GSL_NA_NA_TH.A | D8: thousands | F8: 4708.5171 | G8: 4027.0447 | H8: 3831.8833 | I8: 3672.634 | J8: 3461.1855 | K8: 3333.5042 | L8: 3228.2043 | M8: 3174.7429 | N8: 3117.6521 | O8: 3060.6807 | P8: 2996.7515 | Q8: 3020.3459 | R8: 3005.4482 | S8: 2916.3523 | T8: 2828.9541 | U8: 2771.4673 | V8: 2742.8406 | W8: 2741.3857 | X8: 2738.3291 | Y8: 2743.7698 | Z8: 2718.2727 | AA8: 2685.4128 | AB8: 2655.9783 | AC8: 2617.8574 | AD8: 2571.8245 | AE8: 2557.7061 | AF8: 2528.2446 | AG8: 2487.0168 | AH8: 2470.873 | AI8: 2424.7546 | AJ8: -0.023
A9: TDI Diesel ICE | B9: Light-Duty Vehicle Sales: Conventional Cars: TDI Diesel: Low economic growth | C9: AEO.2022.LOWMACRO.ECI_SAL_TRN_CAR_TDS_NA_NA_TH.A | D9: thousands | F9: 0.055604 | G9: 0.052588 | H9: 0.052776 | I9: 0.047209 | J9: 0.043953 | K9: 0.043103 | L9: 0.042453 | M9: 0.042038 | N9: 0.041436 | O9: 0.04163 | P9: 0.040842 | Q9: 0.04214 | R9: 0.042788 | S9: 0.042154 | T9: 0.041222 | U9: 0.040598 | V9: 0.04015 | W9: 0.040506 | X9: 0.040439 | Y9: 0.040958 | Z9: 0.040855 | AA9: 0.040838 | AB9: 0.040575 | AC9: 0.039879 | AD9: 0.039518 | AE9: 0.039347 | AF9: 0.039286 | AG9: 0.039098 | AH9: 0.038984 | AI9: 0.038242 | AJ9: -0.013
A10: Total Conventional Cars | B10: Light-Duty Vehicle Sales: Conventional Cars: Total: Low economic growth | C10: AEO.2022.LOWMACRO.ECI_SAL_TRN_CAR_CNV_NA_NA_TH.A | D10: thousands | F10: 4708.5728 | G10: 4027.0972 | H10: 3831.936 | I10: 3672.6812 | J10: 3461.2295 | K10: 3333.5474 | L10: 3228.2468 | M10: 3174.7849 | N10: 3117.6936 | O10: 3060.7224 | P10: 2996.7922 | Q10: 3020.3882 | R10: 3005.491 | S10: 2916.3945 | T10: 2828.9954 | U10: 2771.5078 | V10: 2742.8806 | W10: 2741.4263 | X10: 2738.3696 | Y10: 2743.8108 | Z10: 2718.3135 | AA10: 2685.4536 | AB10: 2656.0188 | AC10: 2617.8972 | AD10: 2571.864 | AE10: 2557.7454 | AF10: 2528.2839 | AG10: 2487.0559 | AH10: 2470.9121 | AI10: 2424.793 | AJ10: -0.023
A11: Alternative-Fuel Cars
A12: Ethanol-Flex Fuel ICE | B12: Light-Duty Vehicle Sales: Alternative-Fuel Cars: Ethanol-Flex Fuel ICE: Low economic growth | C12: AEO.2022.LOWMACRO.ECI_SAL_TRN_CAR_EFFI_NA_NA_TH.A | D12: thousands | F12: 70.343307 | G12: 60.549362 | H12: 58.041054 | I12: 55.635876 | J12: 52.402313 | K12: 50.446724 | L12: 48.850254 | M12: 48.098244 | N12: 47.30896 | O12: 46.54229 | P12: 45.684765 | Q12: 46.060051 | R12: 46.024467 | S12: 44.769226 | T12: 43.527195 | U12: 42.754539 | V12: 42.415855 | W12: 42.501331 | X12: 42.568268 | Y12: 42.744873 | Z12: 42.494694 | AA12: 42.101707 | AB12: 41.76836 | AC12: 41.300838 | AD12: 40.689476 | AE12: 40.579243 | AF12: 40.234856 | AG12: 39.691223 | AH12: 39.541573 | AI12: 38.713806 | AJ12: -0.02
A13: 100 Mile Electric Vehicle | B13: Light-Duty Vehicle Sales: Alternative-Fuel Cars: 100 Mile Electric Vehicle: Low economic growth | C13: AEO.2022.LOWMACRO.ECI_SAL_TRN_CAR_100EV_NA_NA_TH.A | D13: thousands | F13: 1.889388 | G13: 1.853578 | H13: 2.010953 | I13: 2.130904 | J13: 2.194248 | K13: 2.286907 | L13: 2.380218 | M13: 2.512388 | N13: 2.639935 | O13: 2.764761 | P13: 2.882028 | Q13: 3.07301 | R13: 3.249978 | S13: 3.330011 | T13: 3.404459 | U13: 3.509104 | V13: 3.645464 | W13: 3.819031 | X13: 3.995179 | Y13: 4.179914 | Z13: 4.331512 | AA13: 4.463648 | AB13: 4.601828 | AC13: 4.724389 | AD13: 4.825278 | AE13: 4.984514 | AF13: 5.115482 | AG13: 5.218546 | AH13: 5.371593 | AI13: 5.454651 | AJ13: 0.037
A14: 200 Mile Electric Vehicle | B14: Light-Duty Vehicle Sales: Alternative-Fuel Cars: 200 Mile Electric Vehicle: Low economic growth | C14: AEO.2022.LOWMACRO.ECI_SAL_TRN_CAR_200EV_NA_NA_TH.A | D14: thousands | F14: 23.375469 | G14: 25.162935 | H14: 26.887745 | I14: 28.182169 | J14: 27.906448 | K14: 28.487347 | L14: 29.056843 | M14: 30.245136 | N14: 31.850908 | O14: 33.557735 | P14: 35.134197 | Q14: 38.987633 | R14: 41.828842 | S14: 43.608128 | T14: 45.457848 | U14: 47.45253 | V14: 49.824116 | W14: 52.774906 | X14: 55.452347 | Y14: 58.692047 | Z14: 61.099415 | AA14: 63.306271 | AB14: 65.701378 | AC14: 67.526718 | AD14: 68.845268 | AE14: 71.151718 | AF14: 72.830406 | AG14: 74.05481 | AH14: 76.02253 | AI14: 76.51194 | AJ14: 0.042
A15: 300 Mile Electric Vehicle | B15: Light-Duty Vehicle Sales: Alternative-Fuel Cars: 300 Mile Electric Vehicle: Low economic growth | C15: AEO.2022.LOWMACRO.ECI_SAL_TRN_CAR_300EV_NA_NA_TH.A | D15: thousands | F15: 147.40178 | G15: 155.99675 | H15: 171.69786 | I15: 181.12497 | J15: 175.2215 | K15: 171.76187 | L15: 168.80046 | M15: 169.34013 | N15: 172.23846 | O15: 179.98 | P15: 184.51266 | Q15: 199.95792 | R15: 212.35974 | S15: 218.05942 | T15: 224.15056 | U15: 230.9104 | V15: 239.59773 | W15: 251.35535 | X15: 262.51718 | Y15: 275.64163 | Z15: 286.47797 | AA15: 296.27103 | AB15: 307.46561 | AC15: 316.62567 | AD15: 323.55627 | AE15: 335.51575 | AF15: 345.19446 | AG15: 353.00534 | AH15: 364.80512 | AI15: 370.38699 | AJ15: 0.032
A16: Plug-in 20 Gasoline Hybrid | B16: Light-Duty Vehicle Sales: Alternative-Fuel Cars: Plug-in 20 Gasoline Hybrid: Low economic growth | C16: AEO.2022.LOWMACRO.#N/A.A | D16: thousands | F16: 46.07452 | G16: 41.307823 | H16: 35.311195 | I16: 33.157207 | J16: 32.668339 | K16: 31.887579 | L16: 31.637594 | M16: 31.960209 | N16: 32.534397 | O16: 33.628281 | P16: 34.726852 | Q16: 38.217216 | R16: 40.075108 | S16: 40.901299 | T16: 41.703312 | U16: 42.683685 | V16: 44.039829 | W16: 45.875614 | X16: 47.390827 | Y16: 49.550098 | Z16: 50.653801 | AA16: 51.584179 | AB16: 52.619587 | AC16: 53.227955 | AD16: 53.513435 | AE16: 54.554977 | AF16: 55.090519 | AG16: 55.30695 | AH16: 56.10244 | AI16: 55.769161 | AJ16: 0.007
A17: Plug-in 50 Gasoline Hybrid | B17: Light-Duty Vehicle Sales: Alternative-Fuel Cars: Plug-in 50 Gasoline Hybrid: Low economic growth | C17: AEO.2022.LOWMACRO.#N/A.A | D17: thousands | F17: 2.051092 | G17: 1.980519 | H17: 2.072338 | I17: 2.267704 | J17: 2.410676 | K17: 2.600569 | L17: 2.797372 | M17: 3.04156 | N17: 3.288033 | O17: 3.549641 | P17: 3.802512 | Q17: 4.214235 | R17: 4.552578 | S17: 4.759618 | T17: 4.9583 | U17: 5.187163 | V17: 5.460164 | W17: 5.792198 | X17: 6.113984 | Y17: 6.475055 | Z17: 6.761046 | AA17: 7.020243 | AB17: 7.293337 | AC17: 7.528407 | AD17: 7.722812 | AE17: 8.01825 | AF17: 8.25815 | AG17: 8.451497 | AH17: 8.728467 | AI17: 8.870539 | AJ17: 0.052
A18: Electric-Diesel Hybrid | B18: Light-Duty Vehicle Sales: Alternative-Fuel Cars: Electric-Diesel Hybrid: Low economic growth | C18: AEO.2022.LOWMACRO.ECI_SAL_TRN_CAR_EDH_NA_NA_TH.A | D18: thousands | F18: 0 | G18: 0 | H18: 0 | I18: 0 | J18: 0 | K18: 0 | L18: 0 | M18: 0 | N18: 0 | O18: 0 | P18: 0 | Q18: 0 | R18: 0 | S18: 0 | T18: 0 | U18: 0 | V18: 0 | W18: 0 | X18: 0 | Y18: 0 | Z18: 0 | AA18: 0 | AB18: 0 | AC18: 0 | AD18: 0 | AE18: 0 | AF18: 0 | AG18: 0 | AH18: 0 | AI18: 0 | AJ18: - -
A19: Electric-Gasoline Hybrid | B19: Light-Duty Vehicle Sales: Alternative-Fuel Cars: Electric-Gasoline Hybrid: Low economic growth | C19: AEO.2022.LOWMACRO.ECI_SAL_TRN_CAR_EGH_NA_NA_TH.A | D19: thousands | F19: 332.48666 | G19: 337.24652 | H19: 365.72226 | I19: 361.76471 | J19: 343.10757 | K19: 337.5228 | L19: 334.77814 | M19: 336.78854 | N19: 337.88992 | O19: 339.16202 | P19: 338.97922 | Q19: 350.40442 | R19: 355.52737 | S19: 350.95868 | T19: 346.27304 | U19: 344.43457 | V19: 346.00168 | W19: 351.18692 | X19: 355.50055 | Y19: 362.08258 | Z19: 366.14453 | AA19: 367.11215 | AB19: 368.55566 | AC19: 368.23932 | AD19: 366.31882 | AE19: 369.05972 | AF19: 369.16357 | AG19: 367.36792 | AH19: 369.24075 | AI19: 365.6044 | AJ19: 0.003
A20: Natural Gas ICE | B20: Light-Duty Vehicle Sales: Alternative-Fuel Cars: Natural Gas ICE: Low economic growth | C20: AEO.2022.LOWMACRO.ECI_SAL_TRN_CAR_NGI_NA_NA_TH.A | D20: thousands | F20: 0.125795 | G20: 0.137188 | H20: 0.16456 | I20: 0.178194 | J20: 0.178977 | K20: 0.17513 | L20: 0.169911 | M20: 0.166769 | N20: 0.16133 | O20: 0.157814 | P20: 0.155445 | Q20: 0.153072 | R20: 0.154532 | S20: 0.150304 | T20: 0.145904 | U20: 0.143305 | V20: 0.141849 | W20: 0.142148 | X20: 0.142495 | Y20: 0.142984 | Z20: 0.143385 | AA20: 0.143712 | AB20: 0.144666 | AC20: 0.144943 | AD20: 0.143982 | AE20: 0.144406 | AF20: 0.144026 | AG20: 0.142705 | AH20: 0.142891 | AI20: 0.141464 | AJ20: 0.004
A21: Natural Gas Bi-fuel | B21: Light-Duty Vehicle Sales: Alternative-Fuel Cars: Natural Gas Bi-fuel: Low economic growth | C21: AEO.2022.LOWMACRO.ECI_SAL_TRN_CAR_NBF_NA_NA_TH.A | D21: thousands | F21: 0.08721 | G21: 0.083797 | H21: 0.086701 | I21: 0.082955 | J21: 0.077557 | K21: 0.07438 | L21: 0.072463 | M21: 0.071962 | N21: 0.071043 | O21: 0.070278 | P21: 0.069926 | Q21: 0.068586 | R21: 0.070636 | S21: 0.069626 | T21: 0.068207 | U21: 0.067855 | V21: 0.067926 | W21: 0.068939 | X21: 0.069968 | Y21: 0.071117 | Z21: 0.072263 | AA21: 0.073052 | AB21: 0.074277 | AC21: 0.075227 | AD21: 0.075636 | AE21: 0.076905 | AF21: 0.077803 | AG21: 0.078107 | AH21: 0.079107 | AI21: 0.079022 | AJ21: -0.003
A22: Propane ICE | B22: Light-Duty Vehicle Sales: Alternative-Fuel Cars: Propane: Low economic growth | C22: AEO.2022.LOWMACRO.ECI_SAL_TRN_CAR_PROP_NA_NA_TH.A | D22: thousands | F22: 0.05824 | G22: 0.083935 | H22: 0.102234 | I22: 0.100122 | J22: 0.094563 | K22: 0.091009 | L22: 0.088827 | M22: 0.088865 | N22: 0.088482 | O22: 0.08789 | P22: 0.088635 | Q22: 0.089944 | R22: 0.095838 | S22: 0.095839 | T22: 0.095929 | U22: 0.097352 | V22: 0.098851 | W22: 0.10141 | X22: 0.105067 | Y22: 0.106972 | Z22: 0.110404 | AA22: 0.112637 | AB22: 0.114746 | AC22: 0.11737 | AD22: 0.119959 | AE22: 0.124351 | AF22: 0.128778 | AG22: 0.132005 | AH22: 0.136136 | AI22: 0.139824 | AJ22: 0.031
A23: Propane Bi-fuel | B23: Light-Duty Vehicle Sales: Alternative-Fuel Cars: Propane: Low economic growth | C23: AEO.2022.LOWMACRO.ECI_SAL_TRN_CAR_PBF_NA_NA_TH.A | D23: thousands | F23: 0.034324 | G23: 0.03163 | H23: 0.032664 | I23: 0.031067 | J23: 0.028989 | K23: 0.027804 | L23: 0.026821 | M23: 0.026294 | N23: 0.025703 | O23: 0.025183 | P23: 0.024775 | Q23: 0.025119 | R23: 0.025592 | S23: 0.025025 | T23: 0.024549 | U23: 0.024303 | V23: 0.024152 | W23: 0.024312 | X23: 0.024516 | Y23: 0.024692 | Z23: 0.024848 | AA23: 0.02486 | AB23: 0.024879 | AC23: 0.024869 | AD23: 0.024892 | AE23: 0.025346 | AF23: 0.025631 | AG23: 0.025672 | AH23: 0.025926 | AI23: 0.025838 | AJ23: -0.01
A24: Fuel Cell Methanol | B24: Light-Duty Vehicle Sales: Alternative-Fuel Cars: Fuel Cell Methanol: Low economic growth | C24: AEO.2022.LOWMACRO.ECI_SAL_TRN_CAR_FCLMTH_NA_NA_TH.A | D24: thousands | F24: 0 | G24: 0 | H24: 0 | I24: 0 | J24: 0 | K24: 0 | L24: 0 | M24: 0 | N24: 0 | O24: 0 | P24: 0 | Q24: 0 | R24: 0 | S24: 0 | T24: 0 | U24: 0 | V24: 0 | W24: 0 | X24: 0 | Y24: 0 | Z24: 0 | AA24: 0 | AB24: 0 | AC24: 0 | AD24: 0 | AE24: 0 | AF24: 0 | AG24: 0 | AH24: 0 | AI24: 0 | AJ24: - -
A25: Fuel Cell Hydrogen | B25: Light-Duty Vehicle Sales: Alternative-Fuel cars: Fuel Cell Hydrogen: Low economic growth | C25: AEO.2022.LOWMACRO.ECI_SAL_TRN_CAR_FCH_NA_NA_TH.A | D25: thousands | F25: 2.810565 | G25: 2.579295 | H25: 2.900511 | I25: 3.099156 | J25: 3.365274 | K25: 3.752151 | L25: 4.085079 | M25: 4.495492 | N25: 4.871282 | O25: 5.194482 | P25: 5.450906 | Q25: 5.798769 | R25: 6.174509 | S25: 6.189462 | T25: 6.141377 | U25: 6.097211 | V25: 6.046902 | W25: 6.255177 | X25: 6.485738 | Y25: 6.689171 | Z25: 6.886049 | AA25: 7.010755 | AB25: 7.137501 | AC25: 7.23891 | AD25: 7.278145 | AE25: 7.388267 | AF25: 7.455015 | AG25: 7.461854 | AH25: 7.526855 | AI25: 7.509429 | AJ25: 0.034
A26: Total Alternative Cars | B26: Light-Duty Vehicle Sales: Alternative-Fuel Cars: Total: Low economic growth | C26: AEO.2022.LOWMACRO.ECI_SAL_TRN_CAR_ALT_NA_NA_TH.A | D26: thousands | F26: 626.73834 | G26: 627.01331 | H26: 665.03003 | I26: 667.75507 | J26: 639.65643 | K26: 629.11426 | L26: 622.74402 | M26: 626.83557 | N26: 632.96844 | O26: 644.72034 | P26: 651.51196 | Q26: 687.04999 | R26: 710.13922 | S26: 712.91663 | T26: 715.95062 | U26: 723.362 | V26: 737.36444 | W26: 759.8974 | X26: 780.36609 | Y26: 806.40118 | Z26: 825.19989 | AA26: 839.22424 | AB26: 855.50189 | AC26: 866.7746 | AD26: 873.11395 | AE26: 891.62335 | AF26: 903.71875 | AG26: 910.93671 | AH26: 927.72333 | AI26: 929.20703 | AJ26: 0.014
A27: Percent Alternative Car Sales | B27: Light-Duty Vehicle Sales: Percent Alternative Car: Low economic growth | C27: AEO.2022.LOWMACRO.ECI_SAL_TRN_CAR_ALT_NA_NA_PCT.A | D27: percent | F27: 11.746987 | G27: 13.472249 | H27: 14.788416 | I27: 15.384516 | J27: 15.598006 | K27: 15.876053 | L27: 16.171009 | M27: 16.488642 | N27: 16.876179 | O27: 17.399279 | P27: 17.857939 | Q27: 18.531664 | R27: 19.112215 | S27: 19.643305 | T27: 20.196375 | U27: 20.697823 | V27: 21.187141 | W27: 21.703146 | X27: 22.177456 | Y27: 22.71417 | Z27: 23.287619 | AA27: 23.809956 | AB27: 24.362717 | AC27: 24.873922 | AD27: 25.344545 | AE27: 25.848886 | AF27: 26.332109 | AG27: 26.808083 | AH27: 27.296936 | AI27: 27.704445 | AJ27: 0.03
A28: Total New Car Sales | B28: Light-Duty Vehicle Sales: Total New Car: Low economic growth | C28: AEO.2022.LOWMACRO.ECI_SAL_TRN_CAR_TOT_NA_NA_TH.A | D28: thousands | F28: 5335.311 | G28: 4654.1104 | H28: 4496.9658 | I28: 4340.436 | J28: 4100.8857 | K28: 3962.6616 | L28: 3850.9907 | M28: 3801.6206 | N28: 3750.6621 | O28: 3705.4429 | P28: 3648.3042 | Q28: 3707.4382 | R28: 3715.6301 | S28: 3629.311 | T28: 3544.946 | U28: 3494.8699 | V28: 3480.2451 | W28: 3501.3237 | X28: 3518.7358 | Y28: 3550.2119 | Z28: 3543.5134 | AA28: 3524.6777 | AB28: 3511.5208 | AC28: 3484.6719 | AD28: 3444.978 | AE28: 3449.3687 | AF28: 3432.0027 | AG28: 3397.9927 | AH28: 3398.6355 | AI28: 3354 | AJ28: -0.016
A29: New Light Truck Sales
A30: Conventional Light Trucks
A31: Gasoline ICE Vehicles | B31: Light-Duty Vehicle Sales: Conventional Light Trucks: Gasoline: Low economic growth | C31: AEO.2022.LOWMACRO.ECI_SAL_TRN_LTK_GSL_NA_NA_TH.A | D31: thousands | F31: 8724.5283 | G31: 7939.5649 | H31: 8116.8813 | I31: 8314.5391 | J31: 8323.5039 | K31: 8322.1758 | L31: 8213.2363 | M31: 8182.4932 | N31: 8148.5396 | O31: 8039.1226 | P31: 7956.1636 | Q31: 7892.4268 | R31: 7877.8208 | S31: 7680.5063 | T31: 7491.6279 | U31: 7401.8281 | V31: 7379.4507 | W31: 7421.5366 | X31: 7516.1909 | Y31: 7545.4082 | Z31: 7531.5078 | AA31: 7480.3242 | AB31: 7421.3354 | AC31: 7365.7759 | AD31: 7297.77 | AE31: 7308.1538 | AF31: 7296.1382 | AG31: 7261.7114 | AH31: 7295.6362 | AI31: 7308.436 | AJ31: -0.006
A32: TDI Diesel ICE | B32: Light-Duty Vehicle Sales: Conventional Light Trucks: TDI Diesel: Low economic growth | C32: AEO.2022.LOWMACRO.ECI_SAL_TRN_LTK_DSL_NA_NA_TH.A | D32: thousands | F32: 46.41877 | G32: 51.253639 | H32: 54.700764 | I32: 52.197567 | J32: 51.239521 | K32: 51.580734 | L32: 51.742249 | M32: 52.058838 | N32: 51.945 | O32: 52.957184 | P32: 52.219421 | Q32: 53.612389 | R32: 54.034382 | S32: 53.363277 | T32: 52.099304 | U32: 51.40202 | V32: 50.977821 | W32: 51.689278 | X32: 51.969776 | Y32: 53.049381 | Z32: 53.070942 | AA32: 53.386406 | AB32: 53.157028 | AC32: 52.364655 | AD32: 52.270599 | AE32: 52.341469 | AF32: 52.742237 | AG32: 53.071175 | AH32: 53.468132 | AI32: 53.209236 | AJ32: 0.005
A33: Total Conventional Light Trucks | B33: Light-Duty Vehicle Sales: Conventional Light Trucks: Total: Low economic growth | C33: AEO.2022.LOWMACRO.ECI_SAL_TRN_LTK_CNV_NA_NA_TH.A | D33: thousands | F33: 8770.9473 | G33: 7990.8184 | H33: 8171.582 | I33: 8366.7363 | J33: 8374.7432 | K33: 8373.7568 | L33: 8264.9785 | M33: 8234.5518 | N33: 8200.4844 | O33: 8092.0796 | P33: 8008.3828 | Q33: 7946.0391 | R33: 7931.855 | S33: 7733.8696 | T33: 7543.7271 | U33: 7453.23 | V33: 7430.4287 | W33: 7473.2261 | X33: 7568.1606 | Y33: 7598.4575 | Z33: 7584.5786 | AA33: 7533.7104 | AB33: 7474.4927 | AC33: 7418.1406 | AD33: 7350.0405 | AE33: 7360.4951 | AF33: 7348.8804 | AG33: 7314.7827 | AH33: 7349.1045 | AI33: 7361.6455 | AJ33: -0.006
A34: Alternative-Fuel Light Trucks
A35: Ethanol-Flex Fuel ICE | B35: Light-Duty Vehicle Sales: Alternative-Fuel Light Trucks: Ethanol-Flex Fuel ICE: Low economic growth | C35: AEO.2022.LOWMACRO.ECI_SAL_TRN_LTK_EFFI_NA_NA_TH.A | D35: thousands | F35: 596.271 | G35: 546.36578 | H35: 560.06812 | I35: 574.92841 | J35: 576.18988 | K35: 576.79669 | L35: 569.94995 | M35: 568.57684 | N35: 566.88086 | O35: 560.06952 | P35: 554.92859 | Q35: 552.00311 | R35: 551.68054 | S35: 538.38373 | T35: 525.73877 | U35: 519.98261 | V35: 519.21204 | W35: 522.88904 | X35: 529.97516 | Y35: 532.82471 | Z35: 532.42767 | AA35: 529.45483 | AB35: 525.90851 | AC35: 522.56659 | AD35: 518.38086 | AE35: 519.85077 | AF35: 519.60535 | AG35: 517.68317 | AH35: 520.55609 | AI35: 521.65747 | AJ35: -0.005
A36: 100 Mile Electric Vehicle | B36: Light-Duty Vehicle Sales: Alternative-Fuel Light Trucks: 100 Mile Electric Vehicle: Low economic growth | C36: AEO.2022.LOWMACRO.ECI_SAL_TRN_LTK_100EV_NA_NA_TH.A | D36: thousands | F36: 0.093778 | G36: 0.084562 | H36: 0.083867 | I36: 0.082934 | J36: 0.079843 | K36: 0.076699 | L36: 0.072665 | M36: 0.069366 | N36: 0.066088 | O36: 0.062316 | P36: 0.05875 | Q36: 0.05555 | R36: 0.052556 | S36: 0.048386 | T36: 0.044404 | U36: 0.041074 | V36: 0.038148 | W36: 0.035541 | X36: 0.033077 | Y36: 0.030316 | Z36: 0.027324 | AA36: 0.024208 | AB36: 0.021095 | AC36: 0.018 | AD36: 0.014901 | AE36: 0.011975 | AF36: 0.008991 | AG36: 0.005981 | AH36: 0.003012 | AI36: 0 | AJ36: - -
A37: 200 Mile Electric Vehicle | B37: Light-Duty Vehicle Sales: Alternative-Fuel Light Trucks: 200 Mile Electric Vehicle: Low economic growth | C37: AEO.2022.LOWMACRO.ECI_SAL_TRN_LTK_200EV_NA_NA_TH.A | D37: thousands | F37: 28.579189 | G37: 37.799797 | H37: 46.339046 | I37: 54.261101 | J37: 58.176041 | K37: 61.65593 | L37: 64.917702 | M37: 68.914391 | N37: 73.443619 | O37: 78.091064 | P37: 80.645233 | Q37: 85.000328 | R37: 88.585281 | S37: 89.981232 | T37: 91.31456 | U37: 93.395668 | V37: 96.163765 | W37: 99.826248 | X37: 103.86043 | Y37: 107.46287 | Z37: 110.17909 | AA37: 112.39967 | AB37: 114.57875 | AC37: 116.57037 | AD37: 118.28721 | AE37: 121.47288 | AF37: 124.27996 | AG37: 126.7664 | AH37: 130.59279 | AI37: 133.89475 | AJ37: 0.055
A38: 300 Mile Electric Vehicle | B38: Light-Duty Vehicle Sales: Alternative-Fuel Light Trucks: 300 Mile Electric Vehicle: Low economic growth | C38: AEO.2022.LOWMACRO.ECI_SAL_TRN_LTK_300EV_NA_NA_TH.A | D38: thousands | F38: 116.33713 | G38: 128.26813 | H38: 155.00763 | I38: 182.8981 | J38: 195.78984 | K38: 205.34196 | L38: 213.27428 | M38: 223.44061 | N38: 236.34247 | O38: 247.95653 | P38: 258.8595 | Q38: 282.15915 | R38: 301.43454 | S38: 312.80041 | T38: 324.20505 | U38: 337.03262 | V38: 352.85297 | W38: 373.2952 | X38: 393.44055 | Y38: 416.24756 | Z38: 434.52277 | AA38: 451.46811 | AB38: 469.5571 | AC38: 484.46344 | AD38: 496.07871 | AE38: 515.07562 | AF38: 530.70703 | AG38: 543.75415 | AH38: 562.82434 | AI38: 573.33344 | AJ38: 0.057
A39: Plug-in 20 Gasoline Hybrid | B39: Light-Duty Vehicle Sales: Alternative-Fuel Light Trucks: Plug-in 20 Gasoline Hybrid: Low economic growth | C39: AEO.2022.LOWMACRO.#N/A.A | D39: thousands | F39: 55.057671 | G39: 53.127327 | H39: 53.622997 | I39: 53.152264 | J39: 51.774372 | K39: 51.00499 | L39: 50.355652 | M39: 50.621254 | N39: 51.208557 | O39: 52.072277 | P39: 53.217651 | Q39: 55.713207 | R39: 57.525776 | S39: 58.145058 | T39: 58.647335 | U39: 59.694374 | V39: 61.187141 | W39: 63.272671 | X39: 65.54245 | Y39: 67.744652 | Z39: 69.149834 | AA39: 70.186066 | AB39: 71.208481 | AC39: 71.972328 | AD39: 72.425598 | AE39: 73.737701 | AF39: 74.667358 | AG39: 75.298149 | AH39: 76.662216 | AI39: 77.354256 | AJ39: 0.012
A40: Plug-in 50 Gasoline Hybrid | B40: Light-Duty Vehicle Sales: Alternative-Fuel Light Trucks: Plug-in 50 Gasoline Hybrid: Low economic growth | C40: AEO.2022.LOWMACRO.#N/A.A | D40: thousands | F40: 36.218811 | G40: 154.58676 | H40: 190.44367 | I40: 194.14935 | J40: 189.67104 | K40: 186.11908 | L40: 182.59335 | M40: 182.38986 | N40: 183.34767 | O40: 185.21614 | P40: 188.22492 | Q40: 195.50043 | R40: 201.6022 | S40: 202.48445 | T40: 203.07191 | U40: 205.48602 | V40: 209.44359 | W40: 215.51012 | X40: 222.27899 | Y40: 228.56625 | Z40: 232.79988 | AA40: 235.78497 | AB40: 238.74777 | AC40: 241.03796 | AD40: 242.18599 | AE40: 246.25104 | AF40: 249.1515 | AG40: 250.96053 | AH40: 255.1868 | AI40: 257.30136 | AJ40: 0.07
...

Sheet Table 44
A1: ref2023.d020623a | B1: 2022 | C1: 2023 | D1: 2024 | E1: 2025 | F1: 2026 | G1: 2027 | H1: 2028 | I1: 2029 | J1: 2030 | K1: 2031 | L1: 2032 | M1: 2033 | N1: 2034 | O1: 2035 | P1: 2036 | Q1: 2037 | R1: 2038 | S1: 2039 | T1: 2040 | U1: 2041 | V1: 2042 | W1: 2043 | X1: 2044 | Y1: 2045 | Z1: 2046 | AA1: 2047 | AB1: 2048 | AC1: 2049 | AD1: 2050
B3: Report | C3: Annual Energy Outlook 2023
B4: Scenario | C4: ref2023 | F4: Reference
B5: Datekey | C5: d020623a
B6: Release Date | D6: March 2023
A10: 44. Transportation Fleet Car and Truck Sales by Type and Technology | AE10: Annual
A11: (thousands) | AE11: Change
AE12: 2022–2050
A13: Technology Type | B13: 2022 | C13: 2023 | D13: 2024 | E13: 2025 | F13: 2026 | G13: 2027 | H13: 2028 | I13: 2029 | J13: 2030 | K13: 2031 | L13: 2032 | M13: 2033 | N13: 2034 | O13: 2035 | P13: 2036 | Q13: 2037 | R13: 2038 | S13: 2039 | T13: 2040 | U13: 2041 | V13: 2042 | W13: 2043 | X13: 2044 | Y13: 2045 | Z13: 2046 | AA13: 2047 | AB13: 2048 | AC13: 2049 | AD13: 2050 | AE13: 2050
A15: New Car Sales 1/
A16: Conventional Cars
A17: Gasoline ICE Vehicles | B17: 745.48859 | C17: 752.84778 | D17: 752.35828 | E17: 735.73346 | F17: 714.39777 | G17: 699.98785 | H17: 685.04047 | I17: 673.87494 | J17: 663.85052 | K17: 653.93219 | L17: 646.67609 | M17: 638 | N17: 632.65363 | O17: 629.94421 | P17: 630.54657 | Q17: 627.93366 | R17: 625.11896 | S17: 622.16144 | T17: 618.44098 | U17: 611.17291 | V17: 603.78058 | W17: 594.08051 | X17: 586.63452 | Y17: 582.1673 | Z17: 581.98822 | AA17: 575.44702 | AB17: 569.67371 | AC17: 564.75281 | AD17: 561.18835 | AE17: -0.010091
A18: TDI Diesel ICE | B18: 0 | C18: 0 | D18: 0 | E18: 0 | F18: 0 | G18: 0 | H18: 0 | I18: 0 | J18: 0 | K18: 0 | L18: 0 | M18: 0 | N18: 0 | O18: 0 | P18: 0 | Q18: 0 | R18: 0 | S18: 0 | T18: 0 | U18: 0 | V18: 0 | W18: 0 | X18: 0 | Y18: 0 | Z18: 0 | AA18: 0 | AB18: 0 | AC18: 0 | AD18: 0 | AE18: --
A19: Total Conventional Cars | B19: 745.48859 | C19: 752.84778 | D19: 752.35828 | E19: 735.73346 | F19: 714.39777 | G19: 699.98785 | H19: 685.04047 | I19: 673.87494 | J19: 663.85052 | K19: 653.93219 | L19: 646.67609 | M19: 638 | N19: 632.65363 | O19: 629.94421 | P19: 630.54657 | Q19: 627.93366 | R19: 625.11896 | S19: 622.16144 | T19: 618.44098 | U19: 611.17291 | V19: 603.78058 | W19: 594.08051 | X19: 586.63452 | Y19: 582.1673 | Z19: 581.98822 | AA19: 575.44702 | AB19: 569.67371 | AC19: 564.75281 | AD19: 561.18835 | AE19: -0.010091
A21: Alternative-Fuel Cars
A22: Ethanol-Flex Fuel ICE | B22: 27.701494 | C22: 28.161213 | D22: 28.336246 | E22: 27.930389 | F22: 27.360483 | G22: 27.062561 | H22: 26.745171 | I22: 26.574789 | J22: 26.450092 | K22: 26.327152 | L22: 26.309853 | M22: 26.236437 | N22: 26.300083 | O22: 26.476437 | P22: 26.802656 | Q22: 26.993179 | R22: 27.175011 | S22: 27.3564 | T22: 27.506229 | U22: 27.497744 | V22: 27.48558 | W22: 27.36544 | X22: 27.347322 | Y22: 27.466482 | Z22: 27.77367 | AA22: 27.796991 | AB22: 27.862095 | AC22: 27.968414 | AD22: 27.940855 | AE22: 0.000307
A23: 100-Mile Electric Vehicle | B23: 1.733732 | C23: 2.015718 | D23: 2.282101 | E23: 2.494302 | F23: 2.678695 | G23: 2.879138 | H23: 3.07065 | I23: 3.273858 | J23: 3.479208 | K23: 3.682477 | L23: 3.899189 | M23: 4.106014 | N23: 4.333928 | O23: 4.58201 | P23: 4.858603 | Q23: 5.115785 | R23: 5.375243 | S23: 5.636921 | T23: 5.89505 | U23: 6.120733 | V23: 6.344616 | W23: 6.542595 | X23: 6.763642 | Y23: 7.019996 | Z23: 7.332982 | AA23: 7.569391 | AB23: 7.816744 | AC23: 8.077607 | AD23: 8.358113 | AE23: 0.057785
A24: 200-Mile Electric Vehicle | B24: 2.34727 | C24: 4.423422 | D24: 6.51033 | E24: 8.447515 | F24: 10.260118 | G24: 12.106405 | H24: 13.894964 | I24: 15.720405 | J24: 17.546631 | K24: 19.353251 | L24: 21.224617 | M24: 23.038656 | N24: 24.968584 | O24: 27.018316 | P24: 29.246431 | Q24: 31.364456 | R24: 33.500416 | S24: 35.655449 | T24: 37.791504 | U24: 39.719631 | V24: 41.633911 | W24: 43.373734 | X24: 45.262123 | Y24: 47.386185 | Z24: 49.898258 | AA24: 51.892063 | AB24: 53.95982 | AC24: 56.121365 | AD24: 58.420788 | AE24: 0.12165
A25: 300-Mile Electric Vehicle | B25: 16.660831 | C25: 19.503101 | D25: 22.200615 | E25: 24.367395 | F25: 26.25774 | G25: 28.301954 | H25: 30.256197 | I25: 32.324257 | J25: 34.412506 | K25: 36.479725 | L25: 38.679714 | M25: 40.781128 | N25: 43.091831 | O25: 45.603497 | P25: 48.399467 | Q25: 51.002945 | R25: 53.629681 | S25: 56.278992 | T25: 58.893322 | U25: 61.18375 | V25: 63.455978 | W25: 65.468964 | X25: 67.712502 | Y25: 70.309715 | Z25: 73.47554 | AA25: 75.873489 | AB25: 78.380974 | AC25: 81.024094 | AD25: 83.864441 | AE25: 0.059418
A26: Plug-in 20 Gasoline Hybrid | B26: 2.416381 | C26: 2.779324 | D26: 3.120898 | E26: 3.388887 | F26: 3.61952 | G26: 3.871928 | H26: 4.112279 | I26: 4.368149 | J26: 4.626535 | K26: 4.881974 | L26: 5.155017 | M26: 5.414467 | N26: 5.701344 | O26: 6.014175 | P26: 6.363098 | Q26: 6.686507 | R26: 7.012915 | S26: 7.341406 | T26: 7.665002 | U26: 7.946321 | V26: 8.224556 | W26: 8.469109 | X26: 8.743222 | Y26: 9.063097 | Z26: 9.459611 | AA26: 9.753787 | AB26: 10.060923 | AC26: 10.385608 | AD26: 10.734817 | AE26: 0.054702
A27: Plug-in 50 Gasoline Hybrid | B27: 0.85057 | C27: 1.23013 | D27: 1.607591 | E27: 1.947863 | F27: 2.261849 | G27: 2.585001 | H27: 2.896867 | I27: 3.217093 | J27: 3.53761 | K27: 3.854425 | L27: 4.184191 | M27: 4.502318 | N27: 4.842849 | O27: 5.205986 | P27: 5.601945 | Q27: 5.976532 | R27: 6.354444 | S27: 6.735092 | T27: 7.111816 | U27: 7.449342 | V27: 7.783675 | W27: 8.085442 | X27: 8.414771 | Y27: 8.788048 | Z27: 9.236242 | AA27: 9.585274 | AB27: 9.946996 | AC27: 10.326148 | AD27: 10.729992 | AE27: 0.094756
A28: Electric-Diesel Hybrid | B28: 0 | C28: 0 | D28: 0 | E28: 0 | F28: 0 | G28: 0 | H28: 0 | I28: 0 | J28: 0 | K28: 0 | L28: 0 | M28: 0 | N28: 0 | O28: 0 | P28: 0 | Q28: 0 | R28: 0 | S28: 0 | T28: 0 | U28: 0 | V28: 0 | W28: 0 | X28: 0 | Y28: 0 | Z28: 0 | AA28: 0 | AB28: 0 | AC28: 0 | AD28: 0 | AE28: --
A29: Electric-Gasoline Hybrid | B29: 32.527454 | C29: 34.683559 | D29: 36.517467 | E29: 37.527821 | F29: 38.211796 | G29: 39.194439 | H29: 40.098598 | I29: 41.186401 | J29: 42.318878 | K29: 43.439339 | L29: 44.725349 | M29: 45.902386 | N29: 47.315739 | O29: 48.939678 | P29: 50.848152 | Q29: 52.535007 | R29: 54.232723 | S29: 55.940033 | T29: 57.601685 | U29: 58.942471 | V29: 60.265564 | W29: 61.346802 | X29: 62.647991 | Y29: 64.274544 | Z29: 66.418465 | AA29: 67.85157 | AB29: 69.378136 | AC29: 71.021629 | AD29: 72.830383 | AE29: 0.029206
A30: Natural Gas ICE | B30: 0 | C30: 0 | D30: 0 | E30: 0 | F30: 0 | G30: 0 | H30: 0 | I30: 0 | J30: 0 | K30: 0 | L30: 0 | M30: 0 | N30: 0 | O30: 0 | P30: 0 | Q30: 0 | R30: 0 | S30: 0 | T30: 0 | U30: 0 | V30: 0 | W30: 0 | X30: 0 | Y30: 0 | Z30: 0 | AA30: 0 | AB30: 0 | AC30: 0 | AD30: 0 | AE30: --
A31: Natural Gas Bi-fuel | B31: 0 | C31: 0 | D31: 0 | E31: 0 | F31: 0 | G31: 0 | H31: 0 | I31: 0 | J31: 0 | K31: 0 | L31: 0 | M31: 0 | N31: 0 | O31: 0 | P31: 0 | Q31: 0 | R31: 0 | S31: 0 | T31: 0 | U31: 0 | V31: 0 | W31: 0 | X31: 0 | Y31: 0 | Z31: 0 | AA31: 0 | AB31: 0 | AC31: 0 | AD31: 0 | AE31: --
A32: Propane ICE | B32: 0 | C32: 0 | D32: 0 | E32: 0 | F32: 0 | G32: 0 | H32: 0 | I32: 0 | J32: 0 | K32: 0 | L32: 0 | M32: 0 | N32: 0 | O32: 0 | P32: 0 | Q32: 0 | R32: 0 | S32: 0 | T32: 0 | U32: 0 | V32: 0 | W32: 0 | X32: 0 | Y32: 0 | Z32: 0 | AA32: 0 | AB32: 0 | AC32: 0 | AD32: 0 | AE32: --
A33: Propane Bi-fuel | B33: 0 | C33: 0 | D33: 0 | E33: 0 | F33: 0 | G33: 0 | H33: 0 | I33: 0 | J33: 0 | K33: 0 | L33: 0 | M33: 0 | N33: 0 | O33: 0 | P33: 0 | Q33: 0 | R33: 0 | S33: 0 | T33: 0 | U33: 0 | V33: 0 | W33: 0 | X33: 0 | Y33: 0 | Z33: 0 | AA33: 0 | AB33: 0 | AC33: 0 | AD33: 0 | AE33: --
A34: Fuel Cell Methanol | B34: 0 | C34: 0 | D34: 0 | E34: 0 | F34: 0 | G34: 0 | H34: 0 | I34: 0 | J34: 0 | K34: 0 | L34: 0 | M34: 0 | N34: 0 | O34: 0 | P34: 0 | Q34: 0 | R34: 0 | S34: 0 | T34: 0 | U34: 0 | V34: 0 | W34: 0 | X34: 0 | Y34: 0 | Z34: 0 | AA34: 0 | AB34: 0 | AC34: 0 | AD34: 0 | AE34: --
A35: Fuel Cell Hydrogen | B35: 0.048113 | C35: 0.092384 | D35: 0.137451 | E35: 0.179425 | F35: 0.218551 | G35: 0.258121 | H35: 0.29623 | I35: 0.334905 | J35: 0.373342 | K35: 0.411207 | L35: 0.450298 | M35: 0.487883 | N35: 0.527722 | O35: 0.569856 | P35: 0.615191 | Q35: 0.65825 | R35: 0.701748 | S35: 0.745306 | T35: 0.78838 | U35: 0.827084 | V35: 0.865125 | W35: 0.89946 | X35: 0.936702 | Y35: 0.978884 | Z35: 1.03084 | AA35: 1.070397 | AB35: 1.110929 | AC35: 1.153482 | AD35: 1.19854 | AE35: 0.121686
A36: Total Alternative Cars | B36: 84.285843 | C36: 92.888847 | D36: 100.7127 | E36: 106.28359 | F36: 110.86876 | G36: 116.25954 | H36: 121.37095 | I36: 126.99986 | J36: 132.7448 | K36: 138.42955 | L36: 144.62823 | M36: 150.46928 | N36: 157.08208 | O36: 164.40996 | P36: 172.73555 | Q36: 180.33266 | R36: 187.98219 | S36: 195.68961 | T36: 203.25299 | U36: 209.68707 | V36: 216.05902 | W36: 221.55154 | X36: 227.82828 | Y36: 235.28696 | Z36: 244.62561 | AA36: 251.39296 | AB36: 258.51663 | AC36: 266.07834 | AD36: 274.07794 | AE36: 0.043014
A38: Percent Alternative Car Sales | B38: 10.157681 | C38: 10.983189 | D38: 11.8059 | E38: 12.622499 | F38: 13.434297 | G38: 14.243176 | H38: 15.050748 | I38: 15.857643 | J38: 16.664019 | K38: 17.470499 | L38: 18.277195 | M38: 19.083721 | N38: 19.890461 | O38: 20.697311 | P38: 21.503721 | Q38: 22.311045 | R38: 23.119165 | S38: 23.92729 | T38: 24.735849 | U38: 25.544804 | V38: 26.353815 | W38: 27.163172 | X38: 27.97283 | Y38: 28.782892 | Z38: 29.5937 | AA38: 30.404064 | AB38: 31.214642 | AC38: 32.025562 | AD38: 32.813244 | AE38: 0.042768
A39: Total New Car Sales | B39: 829.77441 | C39: 845.73663 | D39: 853.07098 | E39: 842.01703 | F39: 825.26654 | G39: 816.24738 | H39: 806.41144 | I39: 800.87482 | J39: 796.59534 | K39: 792.36176 | L39: 791.30432 | M39: 788.4693 | N39: 789.73572 | O39: 794.35419 | P39: 803.2821 | Q39: 808.2663 | R39: 813.10113 | S39: 817.85107 | T39: 821.69397 | U39: 820.85999 | V39: 819.8396 | W39: 815.63208 | X39: 814.46277 | Y39: 817.45422 | Z39: 826.61383 | AA39: 826.83997 | AB39: 828.19031 | AC39: 830.83118 | AD39: 835.2663 | AE39: 0.000236
A41: New Light Truck Sales 1/
A42: Conventional Light Trucks
A43: Gasoline ICE Vehicles | B43: 1139.8827 | C43: 1177.5922 | D43: 1225.1962 | E43: 1266.6293 | F43: 1280.5264 | G43: 1273.6564 | H43: 1266.3192 | I43: 1266.3704 | J43: 1255.4795 | K43: 1247.1234 | L43: 1238.2233 | M43: 1229.917 | N43: 1228.6764 | O43: 1234.7007 | P43: 1240.9656 | Q43: 1247.8655 | R43: 1256.8419 | S43: 1264.0477 | T43: 1273.665 | U43: 1276.9398 | V43: 1280.7981 | W43: 1284.9028 | X43: 1287.0942 | Y43: 1296.9729 | Z43: 1299.4546 | AA43: 1304.3114 | AB43: 1303.999 | AC43: 1310.5312 | AD43: 1318.3575 | AE43: 0.005209
A44: TDI Diesel ICE | B44: 0.042834 | C44: 0.0448 | D44: 0.047137 | E44: 0.049205 | F44: 0.050164 | G44: 0.05028 | H44: 0.050354 | I44: 0.050707 | J44: 0.050606 | K44: 0.050601 | L44: 0.050573 | M44: 0.05056 | N44: 0.050837 | O44: 0.051416 | P44: 0.051999 | Q44: 0.052623 | R44: 0.053332 | S44: 0.053966 | T44: 0.054716 | U44: 0.055203 | V44: 0.05572 | W44: 0.056254 | X44: 0.056709 | Y44: 0.057515 | Z44: 0.058032 | AA44: 0.058632 | AB44: 0.058999 | AC44: 0.059676 | AD44: 0.06041 | AE44: 0.012355
A45: Total Conventional Light Trucks | B45: 1139.9255 | C45: 1177.637 | D45: 1225.2433 | E45: 1266.6785 | F45: 1280.5765 | G45: 1273.7067 | H45: 1266.3696 | I45: 1266.421 | J45: 1255.5302 | K45: 1247.1741 | L45: 1238.2738 | M45: 1229.9675 | N45: 1228.7272 | O45: 1234.7521 | P45: 1241.0176 | Q45: 1247.9181 | R45: 1256.8953 | S45: 1264.1017 | T45: 1273.7197 | U45: 1276.995 | V45: 1280.8538 | W45: 1284.9591 | X45: 1287.151 | Y45: 1297.0304 | Z45: 1299.5126 | AA45: 1304.37 | AB45: 1304.058 | AC45: 1310.5909 | AD45: 1318.418 | AE45: 0.005209
A47: Alternative-Fuel Light Trucks
A48: Ethanol-Flex Fuel ICE | B48: 97.975632 | C48: 102.39687 | D48: 107.67007 | E48: 112.33575 | F48: 114.48013 | G48: 114.70761 | H48: 114.84385 | I48: 115.61748 | J48: 115.36041 | K48: 115.32437 | L48: 115.23352 | M48: 115.18002 | N48: 115.78656 | O48: 117.08218 | P48: 118.38756 | Q48: 119.78483 | R48: 121.37783 | S48: 122.8025 | T48: 124.48741 | U48: 125.57402 | V48: 126.72716 | W48: 127.91966 | X48: 128.93149 | Y48: 130.74116 | Z48: 131.88454 | AA48: 133.22308 | AB48: 134.03351 | AC48: 135.54968 | AD48: 137.19547 | AE48: 0.012097
A49: 100-Mile Electric Vehicle | B49: 0.077187 | C49: 0.076893 | D49: 0.07708 | E49: 0.076725 | F49: 0.074614 | G49: 0.071291 | H49: 0.067977 | I49: 0.065073 | J49: 0.061625 | K49: 0.058332 | L49: 0.055036 | M49: 0.051793 | N49: 0.048852 | O49: 0.046172 | P49: 0.043459 | Q49: 0.040714 | R49: 0.037982 | S49: 0.035139 | T49: 0.0323 | U49: 0.029246 | V49: 0.026166 | W49: 0.02305 | X49: 0.019861 | Y49: 0.016736 | Z49: 0.013458 | AA49: 0.010167 | AB49: 0.006801 | AC49: 0.00343 | AD49: 0 | AE49: --
...

Sheet Table 45
A1: ref2023.d020623a | B1: 2022 | C1: 2023 | D1: 2024 | E1: 2025 | F1: 2026 | G1: 2027 | H1: 2028 | I1: 2029 | J1: 2030 | K1: 2031 | L1: 2032 | M1: 2033 | N1: 2034 | O1: 2035 | P1: 2036 | Q1: 2037 | R1: 2038 | S1: 2039 | T1: 2040 | U1: 2041 | V1: 2042 | W1: 2043 | X1: 2044 | Y1: 2045 | Z1: 2046 | AA1: 2047 | AB1: 2048 | AC1: 2049 | AD1: 2050
B3: Report | C3: Annual Energy Outlook 2023
B4: Scenario | C4: ref2023 | F4: Reference
B5: Datekey | C5: d020623a
B6: Release Date | D6: March 2023
A10: 45. Transportation Fleet Car and Truck Stock by Type and Technology | AE10: Annual
A11: (thousands) | AE11: Change
AE12: 2022–2050
A13: Technology Type | B13: 2022 | C13: 2023 | D13: 2024 | E13: 2025 | F13: 2026 | G13: 2027 | H13: 2028 | I13: 2029 | J13: 2030 | K13: 2031 | L13: 2032 | M13: 2033 | N13: 2034 | O13: 2035 | P13: 2036 | Q13: 2037 | R13: 2038 | S13: 2039 | T13: 2040 | U13: 2041 | V13: 2042 | W13: 2043 | X13: 2044 | Y13: 2045 | Z13: 2046 | AA13: 2047 | AB13: 2048 | AC13: 2049 | AD13: 2050 | AE13: 2050
A15: Car Stock 1/
A16: Conventional Cars
A17: Gasoline ICE Vehicles | B17: 5006.5488 | C17: 4623.4966 | D17: 4322.0991 | E17: 4050.3804 | F17: 3798.4448 | G17: 3573.9875 | H17: 3375.2903 | I17: 3201.9536 | J17: 3049.9338 | K17: 2915.8713 | L17: 2799.1982 | M17: 2695.3247 | N17: 2605.9509 | O17: 2531.2725 | P17: 2471.8772 | Q17: 2420.7988 | R17: 2375.9214 | S17: 2335.8723 | T17: 2299.6143 | U17: 2263.064 | V17: 2226.7246 | W17: 2188.9048 | X17: 2153.0828 | Y17: 2121.8831 | Z17: 2098.4036 | AA17: 2073.5654 | AB17: 2048.2012 | AC17: 2023.4009 | AD17: 2001.2681 | AE17: -0.032218
A18: TDI Diesel ICE | B18: 16.267254 | C18: 14.041601 | D18: 12.078984 | E18: 10.34063 | F18: 8.810128 | G18: 7.452874 | H18: 6.247537 | I18: 5.194445 | J18: 4.291502 | K18: 3.527866 | L18: 2.892869 | M18: 2.376716 | N18: 1.965617 | O18: 1.6438 | P18: 1.393396 | Q18: 1.198524 | R18: 1.047394 | S18: 0.928337 | T18: 0.828804 | U18: 0.742408 | V18: 0.667005 | W18: 0.600459 | X18: 0.541114 | Y18: 0.488003 | Z18: 0.440443 | AA18: 0.39783 | AB18: 0.359624 | AC18: 0.325348 | AD18: 0.294577 | AE18: -0.133474
A19: Total Conventional Cars | B19: 5022.8159 | C19: 4637.5381 | D19: 4334.1782 | E19: 4060.7209 | F19: 3807.2549 | G19: 3581.4404 | H19: 3381.5378 | I19: 3207.1479 | J19: 3054.2253 | K19: 2919.3992 | L19: 2802.0911 | M19: 2697.7014 | N19: 2607.9165 | O19: 2532.9163 | P19: 2473.2705 | Q19: 2421.9973 | R19: 2376.9688 | S19: 2336.8005 | T19: 2300.4431 | U19: 2263.8064 | V19: 2227.3916 | W19: 2189.5051 | X19: 2153.6238 | Y19: 2122.3711 | Z19: 2098.844 | AA19: 2073.9634 | AB19: 2048.5608 | AC19: 2023.7262 | AD19: 2001.5626 | AE19: -0.032325
A21: Alternative-Fuel Cars
A22: Ethanol-Flex Fuel ICE | B22: 260.40921 | C22: 233.98811 | D22: 209.63817 | E22: 186.64131 | F22: 165.97789 | G22: 147.82109 | H22: 132.07271 | I22: 118.78522 | J22: 107.73377 | K22: 98.722214 | L22: 91.63073 | M22: 86.220879 | N22: 82.223007 | O22: 79.438202 | P22: 77.735916 | Q22: 76.54174 | R22: 75.666542 | S22: 75.034683 | T22: 74.555443 | U22: 74.032272 | V22: 73.489876 | W22: 72.862831 | X22: 72.320984 | Y22: 71.990898 | Z22: 72.008469 | AA22: 71.941269 | AB22: 71.822685 | AC22: 71.715027 | AD22: 71.534599 | AE22: -0.045097
A23: 100-Mile Electric Vehicle | B23: 11.328024 | C23: 11.751799 | D23: 12.242356 | E23: 12.619924 | F23: 12.897101 | G23: 13.181957 | H23: 13.471307 | I23: 13.783559 | J23: 14.123207 | K23: 14.488546 | L23: 14.888898 | M23: 15.317131 | N23: 15.79207 | O23: 16.327549 | P23: 16.936695 | Q23: 17.57663 | R23: 18.235157 | S23: 18.903063 | T23: 19.57601 | U23: 20.217279 | V23: 20.833857 | W23: 21.407917 | X23: 21.97821 | Y23: 22.581919 | Z23: 23.266811 | AA23: 23.926888 | AB23: 24.574036 | AC23: 25.223347 | AD23: 25.902096 | AE23: 0.029978
A24: 200-Mile Electric Vehicle | B24: 17.462101 | C24: 18.744711 | D24: 21.541321 | E24: 25.222059 | F24: 29.118896 | G24: 33.20546 | H24: 37.426132 | I24: 41.846264 | J24: 46.466694 | K24: 51.259415 | L24: 56.27491 | M24: 61.416988 | N24: 66.797653 | O24: 72.494194 | P24: 78.615685 | Q24: 84.929886 | R24: 91.387436 | S24: 97.968834 | T24: 104.64284 | U24: 111.18373 | V24: 117.62488 | W24: 123.84116 | X24: 130.07907 | Y24: 136.56813 | Z24: 143.62234 | AA24: 150.50897 | AB24: 157.30911 | AC24: 164.12808 | AD24: 171.15567 | AE24: 0.084934
A25: 300-Mile Electric Vehicle | B25: 55.467815 | C25: 63.862431 | D25: 72.749718 | E25: 81.883339 | F25: 90.405708 | G25: 98.471451 | H25: 106.06701 | I25: 113.40288 | J25: 120.48434 | K25: 127.29469 | L25: 133.98381 | M25: 140.44589 | N25: 146.91003 | O25: 153.54129 | P25: 160.5623 | Q25: 167.61523 | R25: 174.68607 | S25: 181.77106 | T25: 188.8676 | U25: 195.65595 | V25: 202.22496 | W25: 208.40951 | X25: 214.59907 | Y25: 221.16119 | Z25: 228.55313 | AA25: 235.69231 | AB25: 242.69841 | AC25: 249.72317 | AD25: 257.04065 | AE25: 0.056293
A26: Plug-in 20 Gasoline Hybrid | B26: 18.620897 | C26: 18.742386 | D26: 19.225786 | E26: 19.769812 | F26: 20.255058 | G26: 20.684639 | H26: 21.07461 | I26: 21.458031 | J26: 21.848562 | K26: 22.249832 | L26: 22.686924 | M26: 23.151102 | N26: 23.674931 | O26: 24.288008 | P26: 25.015554 | Q26: 25.810991 | R26: 26.663719 | S26: 27.561453 | T26: 28.491934 | U26: 29.406263 | V26: 30.308496 | W26: 31.167662 | X26: 32.028728 | Y26: 32.935436 | Z26: 33.948967 | AA26: 34.930641 | AB26: 35.897713 | AC26: 36.868179 | AD26: 37.873577 | AE26: 0.02568
A27: Plug-in 50 Gasoline Hybrid | B27: 9.18985 | C27: 9.232191 | D27: 9.513065 | E27: 9.890547 | F27: 10.297814 | G27: 10.742392 | H27: 11.226655 | I27: 11.782159 | J27: 12.41293 | K27: 13.113447 | L27: 13.8957 | M27: 14.741248 | N27: 15.667826 | O27: 16.685068 | P27: 17.809175 | Q27: 18.991947 | R27: 20.221149 | S27: 21.486172 | T27: 22.775742 | U27: 24.045906 | V27: 25.302801 | W27: 26.519762 | X27: 27.738804 | Y27: 29.00321 | Z27: 30.374689 | AA27: 31.715918 | AB27: 33.043564 | AC27: 34.375633 | AD27: 35.743801 | AE27: 0.049706
A28: Electric-Diesel Hybrid | B28: 0 | C28: 0 | D28: 0 | E28: 0 | F28: 0 | G28: 0 | H28: 0 | I28: 0 | J28: 0 | K28: 0 | L28: 0 | M28: 0 | N28: 0 | O28: 0 | P28: 0 | Q28: 0 | R28: 0 | S28: 0 | T28: 0 | U28: 0 | V28: 0 | W28: 0 | X28: 0 | Y28: 0 | Z28: 0 | AA28: 0 | AB28: 0 | AC28: 0 | AD28: 0 | AE28: --
A29: Electric-Gasoline Hybrid | B29: 223.61549 | C29: 216.07962 | D29: 210.16901 | E29: 203.94279 | F29: 198.138 | G29: 193.12856 | H29: 188.94823 | I29: 185.78183 | J29: 183.58957 | K29: 182.24689 | L29: 181.81209 | M29: 182.02373 | N29: 183.03459 | O29: 184.91509 | P29: 187.75081 | Q29: 191.07138 | R29: 194.74928 | S29: 198.696 | T29: 202.83295 | U29: 206.79274 | V29: 210.62627 | W29: 214.1521 | X29: 217.71721 | Y29: 221.63664 | Z29: 226.31955 | AA29: 230.77928 | AB29: 235.12669 | AC29: 239.49492 | AD29: 244.11679 | AE29: 0.003138
A30: Natural Gas ICE | B30: 11.524047 | C30: 10.680966 | D30: 9.790733 | E30: 8.885427 | F30: 7.990345 | G30: 7.103336 | H30: 6.237593 | I30: 5.428048 | J30: 4.758622 | K30: 4.129239 | L30: 3.577585 | M30: 3.107362 | N30: 2.721086 | O30: 2.399466 | P30: 2.138429 | Q30: 1.966115 | R30: 1.819323 | S30: 1.697581 | T30: 1.589439 | U30: 1.488186 | V30: 1.393384 | W30: 1.30462 | X30: 1.221511 | Y30: 1.143696 | Z30: 1.070839 | AA30: 1.002622 | AB30: 0.938752 | AC30: 0.87895 | AD30: 0.822958 | AE30: -0.089954
A31: Natural Gas Bi-fuel | B31: 0.307861 | C31: 0.264919 | D31: 0.239802 | E31: 0.224525 | F31: 0.210222 | G31: 0.19683 | H31: 0.184292 | I31: 0.172551 | J31: 0.161559 | K31: 0.151267 | L31: 0.141631 | M31: 0.132609 | N31: 0.124161 | O31: 0.116252 | P31: 0.108846 | Q31: 0.101912 | R31: 0.09542 | S31: 0.089341 | T31: 0.08365 | U31: 0.078321 | V31: 0.073332 | W31: 0.06866 | X31: 0.064286 | Y31: 0.060191 | Z31: 0.056357 | AA31: 0.052767 | AB31: 0.049405 | AC31: 0.046258 | AD31: 0.043311 | AE31: -0.067647
A32: Propane ICE | B32: 2.087991 | C32: 1.784609 | D32: 1.535312 | E32: 1.333347 | F32: 1.206512 | G32: 1.127065 | H32: 1.055267 | I32: 0.988043 | J32: 0.925101 | K32: 0.866168 | L32: 0.810991 | M32: 0.759328 | N32: 0.710956 | O32: 0.665665 | P32: 0.62326 | Q32: 0.583556 | R32: 0.546381 | S32: 0.511575 | T32: 0.478986 | U32: 0.448473 | V32: 0.419903 | W32: 0.393154 | X32: 0.368109 | Y32: 0.344659 | Z32: 0.322703 | AA32: 0.302145 | AB32: 0.282898 | AC32: 0.264876 | AD32: 0.248003 | AE32: -0.073267
A33: Propane Bi-fuel | B33: 4.082679 | C33: 3.480398 | D33: 2.97779 | E33: 2.565041 | F33: 2.283806 | G33: 2.108607 | H33: 1.959856 | I33: 1.835006 | J33: 1.718109 | K33: 1.60866 | L33: 1.506182 | M33: 1.410233 | N33: 1.320396 | O33: 1.236282 | P33: 1.157526 | Q33: 1.083788 | R33: 1.014747 | S33: 0.950104 | T33: 0.889579 | U33: 0.832909 | V33: 0.77985 | W33: 0.730171 | X33: 0.683656 | Y33: 0.640105 | Z33: 0.599328 | AA33: 0.561149 | AB33: 0.525401 | AC33: 0.491931 | AD33: 0.460594 | AE33: -0.074969
A34: Fuel Cell Methanol | B34: 0 | C34: 0 | D34: 0 | E34: 0 | F34: 0 | G34: 0 | H34: 0 | I34: 0 | J34: 0 | K34: 0 | L34: 0 | M34: 0 | N34: 0 | O34: 0 | P34: 0 | Q34: 0 | R34: 0 | S34: 0 | T34: 0 | U34: 0 | V34: 0 | W34: 0 | X34: 0 | Y34: 0 | Z34: 0 | AA34: 0 | AB34: 0 | AC34: 0 | AD34: 0 | AE34: --
A35: Fuel Cell Hydrogen | B35: 0.695658 | C35: 0.693525 | D35: 0.730931 | E35: 0.79699 | F35: 0.88554 | G35: 0.9894 | H35: 1.10531 | I35: 1.234237 | J35: 1.374475 | K35: 1.524476 | L35: 1.685228 | M35: 1.854181 | N35: 2.033293 | O35: 2.223712 | P35: 2.427094 | Q35: 2.639039 | R35: 2.858608 | S35: 3.08428 | T35: 3.314411 | U35: 3.544198 | V35: 3.773129 | W35: 3.997288 | X35: 4.220754 | Y35: 4.448301 | Z35: 4.688444 | AA35: 4.925473 | AB35: 5.161976 | AC35: 5.399414 | AD35: 5.639956 | AE35: 0.077606
A36: Total Alternative Cars | B36: 614.79175 | C36: 589.30566 | D36: 570.354 | E36: 553.77508 | F36: 539.66693 | G36: 528.7608 | H36: 520.82898 | I36: 516.4978 | J36: 515.59692 | K36: 517.65485 | L36: 522.89471 | M36: 530.58075 | N36: 541.01001 | O36: 554.33075 | P36: 570.88135 | Q36: 588.91223 | R36: 607.94379 | S36: 627.75415 | T36: 648.09857 | U36: 667.7262 | V36: 686.85071 | W36: 704.85486 | X36: 723.02039 | Y36: 742.51434 | Z36: 764.8316 | AA36: 786.33948 | AB36: 807.43066 | AC36: 828.60986 | AD36: 850.58197 | AE36: 0.011662
A38: Total Car Stock | B38: 5637.6074 | C38: 5226.8438 | D38: 4904.5322 | E38: 4614.4961 | F38: 4346.9219 | G38: 4110.2012 | H38: 3902.3667 | I38: 3723.6458 | J38: 3569.8223 | K38: 3437.054 | L38: 3324.9858 | M38: 3228.2822 | N38: 3148.9265 | O38: 3087.2471 | P38: 3044.1519 | Q38: 3010.9097 | R38: 2984.9126 | S38: 2964.5547 | T38: 2948.5417 | U38: 2931.5327 | V38: 2914.2422 | W38: 2894.3599 | X38: 2876.644 | Y38: 2864.8855 | Z38: 2863.6755 | AA38: 2860.3027 | AB38: 2855.9915 | AC38: 2852.3359 | AD38: 2852.1445 | AE38: -0.024042
A40: Light Truck Stock 1/
A41: Conventional Light Trucks
A42: Gasoline ICE Vehicles | B42: 7639.083 | C42: 7655.0962 | D42: 7760.314 | E42: 7895.3628 | F42: 8023.1143 | G42: 8127.6328 | H42: 8212.9814 | I42: 8290.5889 | J42: 8349.9736 | K42: 8394.4512 | L42: 8423.9824 | M42: 8440.4258 | N42: 8451.6865 | O42: 8465.3477 | P42: 8480.6543 | Q42: 8497.1035 | R42: 8516.1016 | S42: 8536.0273 | T42: 8559.6494 | U42: 8580.2031 | V42: 8599.4805 | W42: 8618.3643 | X42: 8635.5254 | Y42: 8659.0557 | Z42: 8680.4678 | AA42: 8702.9229 | AB42: 8720.7891 | AC42: 8742.2803 | AD42: 8768.0771 | AE42: 0.004935
A43: TDI Diesel ICE | B43: 60.55452 | C43: 54.813412 | D43: 48.998947 | E43: 43.883667 | F43: 39.715416 | G43: 35.790714 | H43: 32.023296 | I43: 28.420086 | J43: 24.994423 | K43: 21.770369 | L43: 18.758324 | M43: 15.995414 | N43: 13.487585 | O43: 11.270679 | P43: 9.33564 | Q43: 7.682456 | R43: 6.313601 | S43: 5.195662 | T43: 4.315732 | U43: 3.636456 | V43: 3.103021 | W43: 2.68296 | X43: 2.347914 | Y43: 2.093235 | Z43: 1.89311 | AA43: 1.714415 | AB43: 1.55453 | AC43: 1.411821 | AD43: 1.284441 | AE43: -0.128566
