Workbook
Name Eno_TM: '[1]1997 Table 1a Modified'!#REF!
Name Eno_Tons: '[1]1997 Table 1a Modified'!#REF!
Name Sum_T2: '[1]1997 Table 1a Modified'!#REF!
Name Sum_TTM: '[1]1997 Table 1a Modified'!#REF!
Name ti_tbl_50: #REF!
Name ti_tbl_69: #REF!

Sheet About
A1: BHNVFEAL BAU Historical New Vehicle Fuel Economy After Lifetime
A3: Sources: | B3: BAU New Vehicle Fuel Economy
B4: For sources and calculations, see the variable BNVFE.
B6: LDVs
B7: EIA
B8: 2008
B9: Annual Energy Outlook 2008
B10: https://www.eia.gov/outlooks/archive/aeo08/index.html
B11: Tables 35, 49, 55
B13: Perc Reduction in Fuel Use for Electricity
B14: For sources and calculations, see the variable PTFURfE.
B16: Perc of Electricity Use for Plug-In Hybrid Vehicles
B17: For source, see the variable BPoEFUbVT.
B19: Vehicle Lifetimes
B20: For sources and calculations, see the variable AVL.
B22: Efficiency modifiers for LPG and hydrogen vehicles
B23: See the variable BNVFE
A25: Notes
A26: To estimate the BAU New Vehicle Fuel Economy in historical years (up to one
A27: vehicle lifetime before the first simulated year of the model run), we use
A28: a somewhat simplified approach. We linearly extrapolate backwards from
A29: the future year values in BNVFE, using the entire period (2016-2050) as the
A30: basis for extrapolation. We adjust the Y-intercept of the extrapolated
A31: line when needed to avoid any discontinuity.
A33: More than one vehicle lifetime into
A34: the model run, the model will have switched
A35: over to using data from retiring vehicles that were added during the
A36: model run itself and no longer needs to reference the historical input data
A37: in this variable. However, we include values in this variable out to
... A48: energy consumption that more closely matches EIA's AEO trajectory: freight LDVs, passenger HDVs, freight HDVs, passenger ships, passenger motorbikes.

Sheet BNVFE
A1: This tab contains BAU New Vehicle Fuel Economy (BNVFE) data for the primary
A2: vehicle technology for each vehicle/cargo combination. This is the technology
A3: from which the BAU new vehicle fuel economies of the other technologies
A4: are calculated.
A6: BAU New Vehicle Fuel Economy (from BNVFE variable)
A7: vehicle type | B7: cargo type | D7: 2021 | E7: 2022 | F7: 2023 | G7: 2024 | H7: 2025 | I7: 2026 | J7: 2027 | K7: 2028 | L7: 2029 | M7: 2030 | N7: 2031 | O7: 2032 | P7: 2033 | Q7: 2034 | R7: 2035 | S7: 2036 | T7: 2037 | U7: 2038 | V7: 2039 | W7: 2040 | X7: 2041 | Y7: 2042 | Z7: 2043 | AA7: 2044 | AB7: 2045 | AC7: 2046 | AD7: 2047 | AE7: 2048 | AF7: 2049 | AG7: 2050
A8: LDVs | B8: psgr | C8: gasoline vehicle | D8: 0.00038560343 | E8: 0.00039389771 | F8: 0.00040102816 | G8: 0.00040668873 | H8: 0.0004214844 | I8: 0.00042638034 | J8: 0.00042993929 | K8: 0.00044295233 | L8: 0.00044402927 | M8: 0.00044423001 | N8: 0.00044444787 | O8: 0.00044510596 | P8: 0.00044626178 | Q8: 0.00044757258 | R8: 0.0004491939 | S8: 0.00045078104 | T8: 0.00045211629 | U8: 0.00045326957 | V8: 0.00045520696 | W8: 0.00045553578 | X8: 0.00045584945 | Y8: 0.00045595611 | Z8: 0.00045572121 | AA8: 0.00045509854 | AB8: 0.00045449906 | AC8: 0.00045443665 | AD8: 0.00045380063 | AE8: 0.00045343326 | AF8: 0.0004549456 | AG8: 0.00045447279
A9: LDVs | B9: frgt | C9: gasoline vehicle | D9: 0.00010420516 | E9: 0.00010877082 | F9: 0.00011192287 | G9: 0.00011596329 | H9: 0.00011990275 | I9: 0.00012199635 | J9: 0.00012434671 | K9: 0.00012468075 | L9: 0.00012577381 | M9: 0.00012646319 | N9: 0.00012698407 | O9: 0.00012710494 | P9: 0.00012713125 | Q9: 0.00012714496 | R9: 0.00012712313 | S9: 0.00012710052 | T9: 0.00012708001 | U9: 0.00012705407 | V9: 0.0001270263 | W9: 0.00012701194 | X9: 0.00012701796 | Y9: 0.00012701802 | Z9: 0.00012703279 | AA9: 0.00012702817 | AB9: 0.00012698132 | AC9: 0.00012695571 | AD9: 0.00012640539 | AE9: 0.00012643551 | AF9: 0.00012650242 | AG9: 0.00012663654
A10: HDVs | B10: psgr | C10: diesel vehicle | D10: 0.0011137362 | E10: 0.0011868928 | F10: 0.0012242022 | G10: 0.0012625148 | H10: 0.0012984725 | I10: 0.0013325459 | J10: 0.0013625499 | K10: 0.0013753174 | L10: 0.0013946841 | M10: 0.0014146533 | N10: 0.0014334183 | O10: 0.001444591 | P10: 0.0014455847 | Q10: 0.0014457022 | R10: 0.0014456854 | S10: 0.0014457034 | T10: 0.0014456555 | U10: 0.001445563 | V10: 0.0014452171 | W10: 0.0014450917 | X10: 0.001444853 | Y10: 0.001443856 | Z10: 0.0014432142 | AA10: 0.0014432665 | AB10: 0.0014434251 | AC10: 0.0014437811 | AD10: 0.0014442054 | AE10: 0.0014447501 | AF10: 0.0014451805 | AG10: 0.0014456904
A11: HDVs | B11: frgt | C11: diesel vehicle | D11: 0.00074742412 | E11: 0.00079651925 | F11: 0.00082155739 | G11: 0.00084726887 | H11: 0.00087139991 | I11: 0.00089426646 | J11: 0.00091440204 | K11: 0.00092297026 | L11: 0.00093596719 | M11: 0.00094936846 | N11: 0.00096196153 | O11: 0.00096945948 | P11: 0.00097012637 | Q11: 0.00097020521 | R11: 0.00097019398 | S11: 0.00097020604 | T11: 0.00097017391 | U11: 0.0009701118 | V11: 0.00096987971 | W11: 0.00096979549 | X11: 0.00096963531 | Y11: 0.00096896628 | Z11: 0.00096853554 | AA11: 0.00096857066 | AB11: 0.00096867709 | AC11: 0.00096891599 | AD11: 0.00096920076 | AE11: 0.00096956627 | AF11: 0.0009698551 | AG11: 0.00097019732
A12: aircraft | B12: psgr | C12: diesel vehicle | D12: 0.00057245969 | E12: 0.00057245969 | F12: 0.00057245969 | G12: 0.00057245969 | H12: 0.00057245969 | I12: 0.00057245969 | J12: 0.00057245969 | K12: 0.00057245969 | L12: 0.00057245969 | M12: 0.00057245969 | N12: 0.00057245969 | O12: 0.00057245969 | P12: 0.00057245969 | Q12: 0.00057245969 | R12: 0.00057245969 | S12: 0.00057245969 | T12: 0.00057245969 | U12: 0.00057245969 | V12: 0.00057245969 | W12: 0.00057245969 | X12: 0.00057245969 | Y12: 0.00057245969 | Z12: 0.00057245969 | AA12: 0.00057245969 | AB12: 0.00057245969 | AC12: 0.00057245969 | AD12: 0.00057245969 | AE12: 0.00057245969 | AF12: 0.00057245969 | AG12: 0.00057245969
A13: aircraft | B13: frgt | C13: diesel vehicle | D13: 4.8563096e-05 | E13: 4.7951938e-05 | F13: 4.8199149e-05 | G13: 4.846329e-05 | H13: 4.8810101e-05 | I13: 4.9248402e-05 | J13: 4.9544254e-05 | K13: 4.9847838e-05 | L13: 5.0132631e-05 | M13: 5.0441473e-05 | N13: 5.0785598e-05 | O13: 5.1172517e-05 | P13: 5.1611513e-05 | Q13: 5.2082893e-05 | R13: 5.2576863e-05 | S13: 5.3077127e-05 | T13: 5.3586049e-05 | U13: 5.4105335e-05 | V13: 5.4610539e-05 | W13: 5.5125026e-05 | X13: 5.5644352e-05 | Y13: 5.6164575e-05 | Z13: 5.6693978e-05 | AA13: 5.7214939e-05 | AB13: 5.7733179e-05 | AC13: 5.8241709e-05 | AD13: 5.8749514e-05 | AE13: 5.9249763e-05 | AF13: 5.9740126e-05 | AG13: 6.0224657e-05
A14: rail | B14: psgr | C14: diesel vehicle | D14: 7.1745362e-05 | E14: 7.1745362e-05 | F14: 7.1745362e-05 | G14: 7.1745362e-05 | H14: 7.1745362e-05 | I14: 7.1745362e-05 | J14: 7.1745362e-05 | K14: 7.1745362e-05 | L14: 7.1745362e-05 | M14: 7.1745362e-05 | N14: 7.1745362e-05 | O14: 7.1745362e-05 | P14: 7.1745362e-05 | Q14: 7.1745362e-05 | R14: 7.1745362e-05 | S14: 7.1745362e-05 | T14: 7.1745362e-05 | U14: 7.1745362e-05 | V14: 7.1745362e-05 | W14: 7.1745362e-05 | X14: 7.1745362e-05 | Y14: 7.1745362e-05 | Z14: 7.1745362e-05 | AA14: 7.1745362e-05 | AB14: 7.1745362e-05 | AC14: 7.1745362e-05 | AD14: 7.1745362e-05 | AE14: 7.1745362e-05 | AF14: 7.1745362e-05 | AG14: 7.1745362e-05
A15: rail | B15: psgr | C15: battery electric vehicle | D15: 0.00075686214 | E15: 0.00075686214 | F15: 0.00075686214 | G15: 0.00075686214 | H15: 0.00075686214 | I15: 0.00075686214 | J15: 0.00075686214 | K15: 0.00075686214 | L15: 0.00075686214 | M15: 0.00075686214 | N15: 0.00075686214 | O15: 0.00075686214 | P15: 0.00075686214 | Q15: 0.00075686214 | R15: 0.00075686214 | S15: 0.00075686214 | T15: 0.00075686214 | U15: 0.00075686214 | V15: 0.00075686214 | W15: 0.00075686214 | X15: 0.00075686214 | Y15: 0.00075686214 | Z15: 0.00075686214 | AA15: 0.00075686214 | AB15: 0.00075686214 | AC15: 0.00075686214 | AD15: 0.00075686214 | AE15: 0.00075686214 | AF15: 0.00075686214 | AG15: 0.00075686214
A16: rail | B16: frgt | C16: diesel vehicle | D16: 0.003512003 | E16: 0.00336634 | F16: 0.003369893 | G16: 0.00337345 | H16: 0.00337701 | I16: 0.003380574 | J16: 0.003384142 | K16: 0.003387713 | L16: 0.003391289 | M16: 0.003394868 | N16: 0.003398451 | O16: 0.003402037 | P16: 0.003405628 | Q16: 0.003409222 | R16: 0.00341282 | S16: 0.003416422 | T16: 0.003420027 | U16: 0.003423637 | V16: 0.00342725 | W16: 0.003430867 | X16: 0.003434488 | Y16: 0.003438113 | Z16: 0.003441741 | AA16: 0.003445373 | AB16: 0.00344901 | AC16: 0.003452649 | AD16: 0.003456293 | AE16: 0.003459941 | AF16: 0.003463593 | AG16: 0.003467248
A17: ships | B17: psgr | C17: diesel vehicle | D17: 1.2594546e-05 | E17: 1.2594546e-05 | F17: 1.2594546e-05 | G17: 1.2594546e-05 | H17: 1.2594546e-05 | I17: 1.2594546e-05 | J17: 1.2594546e-05 | K17: 1.2594546e-05 | L17: 1.2594546e-05 | M17: 1.2594546e-05 | N17: 1.2594546e-05 | O17: 1.2594546e-05 | P17: 1.2594546e-05 | Q17: 1.2594546e-05 | R17: 1.2594546e-05 | S17: 1.2594546e-05 | T17: 1.2594546e-05 | U17: 1.2594546e-05 | V17: 1.2594546e-05 | W17: 1.2594546e-05 | X17: 1.2594546e-05 | Y17: 1.2594546e-05 | Z17: 1.2594546e-05 | AA17: 1.2594546e-05 | AB17: 1.2594546e-05 | AC17: 1.2594546e-05 | AD17: 1.2594546e-05 | AE17: 1.2594546e-05 | AF17: 1.2594546e-05 | AG17: 1.2594546e-05
A18: ships | B18: frgt | C18: diesel vehicle | D18: 0.0052454272 | E18: 0.0052454272 | F18: 0.0052454272 | G18: 0.0052454272 | H18: 0.0052454272 | I18: 0.0052454272 | J18: 0.0052454272 | K18: 0.0052454272 | L18: 0.0052454272 | M18: 0.0052454272 | N18: 0.0052454272 | O18: 0.0052454272 | P18: 0.0052454272 | Q18: 0.0052454272 | R18: 0.0052454272 | S18: 0.0052454272 | T18: 0.0052454272 | U18: 0.0052454272 | V18: 0.0052454272 | W18: 0.0052454272 | X18: 0.0052454272 | Y18: 0.0052454272 | Z18: 0.0052454272 | AA18: 0.0052454272 | AB18: 0.0052454272 | AC18: 0.0052454272 | AD18: 0.0052454272 | AE18: 0.0052454272 | AF18: 0.0052454272 | AG18: 0.0052454272
A19: motorbikes | B19: psgr | C19: gasoline vehicle | D19: 0.0014345302 | E19: 0.0014345302 | F19: 0.0014345302 | G19: 0.0014345302 | H19: 0.0014345302 | I19: 0.0014345302 | J19: 0.0014345302 | K19: 0.0014345302 | L19: 0.0014345302 | M19: 0.0014345302 | N19: 0.0014345302 | O19: 0.0014345302 | P19: 0.0014345302 | Q19: 0.0014345302 | R19: 0.0014345302 | S19: 0.0014345302 | T19: 0.0014345302 | U19: 0.0014345302 | V19: 0.0014345302 | W19: 0.0014345302 | X19: 0.0014345302 | Y19: 0.0014345302 | Z19: 0.0014345302 | AA19: 0.0014345302 | AB19: 0.0014345302 | AC19: 0.0014345302 | AD19: 0.0014345302 | AE19: 0.0014345302 | AF19: 0.0014345302 | AG19: 0.0014345302
A20: motorbikes | B20: frgt | C20: gasoline vehicle | D20: 0 | E20: 0 | F20: 0 | G20: 0 | H20: 0 | I20: 0 | J20: 0 | K20: 0 | L20: 0 | M20: 0 | N20: 0 | O20: 0 | P20: 0 | Q20: 0 | R20: 0 | S20: 0 | T20: 0 | U20: 0 | V20: 0 | W20: 0 | X20: 0 | Y20: 0 | Z20: 0 | AA20: 0 | AB20: 0 | AC20: 0 | AD20: 0 | AE20: 0 | AF20: 0 | AG20: 0
A22: All passenger LDVs
A23: Fuel Economy (thing*miles/BTU) | B23: 2021 | C23: 2022 | D23: 2023 | E23: 2024 | F23: 2025 | G23: 2026 | H23: 2027 | I23: 2028 | J23: 2029 | K23: 2030 | L23: 2031 | M23: 2032 | N23: 2033 | O23: 2034 | P23: 2035 | Q23: 2036 | R23: 2037 | S23: 2038 | T23: 2039 | U23: 2040 | V23: 2041 | W23: 2042 | X23: 2043 | Y23: 2044 | Z23: 2045 | AA23: 2046 | AB23: 2047 | AC23: 2048 | AD23: 2049 | AE23: 2050
A24: battery electric vehicle | B24: 0.0011058184 | C24: 0.0011654654 | D24: 0.0011704178 | E24: 0.0011680699 | F24: 0.0011715925 | G24: 0.0011717837 | H24: 0.0011670455 | I24: 0.0011663554 | J24: 0.0011600296 | K24: 0.0011556234 | L24: 0.0011543479 | M24: 0.0011538248 | N24: 0.0011534771 | O24: 0.0011533584 | P24: 0.0011533778 | Q24: 0.001153384 | R24: 0.0011531365 | S24: 0.0011528518 | T24: 0.0011527114 | U24: 0.0011521629 | V24: 0.0011516854 | W24: 0.0011511845 | X24: 0.0011504834 | Y24: 0.0011498404 | Z24: 0.0011492401 | AA24: 0.0011499033 | AB24: 0.0011491304 | AC24: 0.0011489135 | AD24: 0.0011490607 | AE24: 0.0011487859
A25: natural gas vehicle | B25: 0.00041435623 | C25: 0.00041583861 | D25: 0.00042674811 | E25: 0.00042774094 | F25: 0.00044088947 | G25: 0.00044515587 | H25: 0.00044712215 | I25: 0.00045871378 | J25: 0.00046008723 | K25: 0.00045997511 | L25: 0.0004595269 | M25: 0.00045879531 | N25: 0.00045885758 | O25: 0.00045899315 | P25: 0.00045978048 | Q25: 0.00046013086 | R25: 0.00046092082 | S25: 0.00046154655 | T25: 0.00046289202 | U25: 0.00046286159 | V25: 0.00046295981 | W25: 0.00046271618 | X25: 0.0004624392 | Y25: 0.00046116751 | Z25: 0.00046042306 | AA25: 0.00045913991 | AB25: 0.00045839403 | AC25: 0.00045733271 | AD25: 0.00045895199 | AE25: 0.00045796322
A26: gasoline vehicle | B26: 0.00038560343 | C26: 0.00039389771 | D26: 0.00040102816 | E26: 0.00040668873 | F26: 0.0004214844 | G26: 0.00042638034 | H26: 0.00042993929 | I26: 0.00044295233 | J26: 0.00044402927 | K26: 0.00044423001 | L26: 0.00044444787 | M26: 0.00044510596 | N26: 0.00044626178 | O26: 0.00044757258 | P26: 0.0004491939 | Q26: 0.00045078104 | R26: 0.00045211629 | S26: 0.00045326957 | T26: 0.00045520696 | U26: 0.00045553578 | V26: 0.00045584945 | W26: 0.00045595611 | X26: 0.00045572121 | Y26: 0.00045509854 | Z26: 0.00045449906 | AA26: 0.00045443665 | AB26: 0.00045380063 | AC26: 0.00045343326 | AD26: 0.0004549456 | AE26: 0.00045447279
A27: diesel vehicle | B27: 0.00040465652 | C27: 0.00041576203 | D27: 0.0004187093 | E27: 0.0004216819 | F27: 0.00043266444 | G27: 0.00043735322 | H27: 0.00043922149 | I27: 0.00044603511 | J27: 0.00044678679 | K27: 0.00044699303 | L27: 0.0004477141 | M27: 0.00044831498 | N27: 0.00044967056 | O27: 0.00045096087 | P27: 0.00045263002 | Q27: 0.00045367403 | R27: 0.00045509703 | S27: 0.00045632605 | T27: 0.000457731 | U27: 0.00045821745 | V27: 0.00045881268 | W27: 0.00045899094 | X27: 0.00045931421 | Y27: 0.00045870544 | Z27: 0.00045840896 | AA27: 0.00045781993 | AB27: 0.00045749536 | AC27: 0.00045687733 | AD27: 0.00045823892 | AE27: 0.00045756641
A28: plugin hybrid vehicle | B28: 0.0006551728 | C28: 0.00060514508 | D28: 0.00060150704 | E28: 0.00061427036 | F28: 0.00063712461 | G28: 0.00064738617 | H28: 0.00065513359 | I28: 0.00067192512 | J28: 0.00067577275 | K28: 0.00067933446 | L28: 0.00068029519 | M28: 0.00068243037 | N28: 0.0006850237 | O28: 0.00068784464 | P28: 0.00069068441 | Q28: 0.00069349336 | R28: 0.00069575679 | S28: 0.00069777924 | T28: 0.00070046159 | U28: 0.00070126821 | V28: 0.00070187449 | W28: 0.00070235628 | X28: 0.00070245879 | Y28: 0.00070208139 | Z28: 0.00070164277 | AA28: 0.00070187588 | AB28: 0.00070121741 | AC28: 0.00070084703 | AD28: 0.00070243269 | AE28: 0.00070193182
A29: LPG vehicle | B29: 0.00036045504 | C29: 0.00035950685 | D29: 0.00037560488 | E29: 0.00037971585 | F29: 0.00039181403 | G29: 0.00039880574 | H29: 0.00040115976 | I29: 0.0004115335 | J29: 0.00041265933 | K29: 0.0004129118 | L29: 0.00041327834 | M29: 0.00041383221 | N29: 0.00041515855 | O29: 0.00041645841 | P29: 0.00041783872 | Q29: 0.0004185963 | R29: 0.00041957711 | S29: 0.00042039727 | T29: 0.00042149458 | U29: 0.00042162481 | V29: 0.00042172823 | W29: 0.00042146362 | X29: 0.00042111122 | Y29: 0.00041994582 | Z29: 0.00041909062 | AA29: 0.00041770703 | AB29: 0.00041703563 | AC29: 0.00041601978 | AD29: 0.00041673942 | AE29: 0.00041566875
A30: hydrogen vehicle | B30: 0.00058311378 | C30: 0.00057223209 | D30: 0.00056894734 | E30: 0.00056725048 | F30: 0.00056996008 | G30: 0.00056951817 | H30: 0.00057010979 | I30: 0.00057487956 | J30: 0.00057443519 | K30: 0.00057407102 | L30: 0.00057368079 | M30: 0.00057338591 | N30: 0.0005735287 | O30: 0.00057404524 | P30: 0.00057495598 | Q30: 0.00057567197 | R30: 0.00057606742 | S30: 0.00057607237 | T30: 0.0005762329 | U30: 0.00057598406 | V30: 0.00057576784 | W30: 0.00057552144 | X30: 0.00057518244 | Y30: 0.00057458173 | Z30: 0.00057415135 | AA30: 0.00057420812 | AB30: 0.00057395892 | AC30: 0.0005736192 | AD30: 0.00057393877 | AE30: 0.00057343896

Sheet SYFAFE
A1: Fuel Economy (passenger*miles/BTU) | B1: battery electric vehicle | C1: natural gas vehicle | D1: gasoline vehicle | E1: diesel vehicle | F1: plugin hybrid vehicle | G1: LPG vehicle | H1: hydrogen vehicle
A2: LDVs | B2: 0.0013018081 | C2: 0.0003303175 | D2: 0.00031903543 | E2: 0.00038594188 | F2: 0.00063946128 | G2: 0.00028289784 | H2: 0.00058506341
A3: HDVs | B3: 0.0034003582 | C3: 0.002822677 | D3: 0.00091563612 | E3: 0.0010581562 | F3: 0.0023463673 | G3: 0.0030762664 | H3: 0.0031744687
A4: aircraft | B4: 0.0016475084 | C4: 0.00051268752 | D4: 0.00051268752 | E4: 0.00051268752 | F4: 0 | G4: 0 | H4: 0.0015380626
A5: rail | B5: 0.00075686214 | C5: 7.1745362e-05 | D5: 7.1745362e-05 | E5: 7.1745362e-05 | F5: 0 | G5: 0 | H5: 0.00021523609
A6: ships | B6: 4.0472255e-05 | C6: 0 | D6: 1.2594546e-05 | E6: 1.2594546e-05 | F6: 0 | G6: 0 | H6: 3.7783639e-05
A7: motorbikes | B7: 0.0045678463 | C7: 0.0014345302 | D7: 0.0014345302 | E7: 0.0014345302 | F7: 0.0031578541 | G7: 0.0011117609 | H7: 0.0043035907
A9: Fuel Economy (freight ton*miles/BTU) | B9: battery electric vehicle | C9: natural gas vehicle | D9: gasoline vehicle | E9: diesel vehicle | F9: plugin hybrid vehicle | G9: LPG vehicle | H9: hydrogen vehicle
A10: LDVs | B10: 0.00010150689 | C10: 6.674878e-05 | D10: 9.6215656e-05 | E10: 6.8445241e-05 | F10: 0.00021334966 | G10: 4.0500619e-05 | H10: 0.002080262
A11: HDVs | B11: 0.0022282897 | C11: 0.00049095868 | D11: 0.0065279356 | E11: 0.00069342067 | F11: 0.0013400471 | G11: 0.0027723416 | H11: 0.0025188575
A12: aircraft | B12: 0.00013976199 | C12: 4.3492483e-05 | D12: 4.3492483e-05 | E12: 4.3492483e-05 | F12: 0 | G12: 0 | H12: 0.00013047745
A13: rail | B13: 0.011213005 | C13: 0.003489371 | D13: 0.003489371 | E13: 0.003489371 | F13: 0 | G13: 0 | H13: 0.010468113
A14: ships | B14: 0.015559516 | C14: 0.00484196 | D14: 0.00484196 | E14: 0.00484196 | F14: 0 | G14: 0 | H14: 0.01452588
A15: motorbikes | B15: 0 | C15: 0 | D15: 0 | E15: 0 | F15: 0 | G15: 0 | H15: 0

Sheet Other Values
A1: Perc Reduction in Fuel Use for Electricity
A2: LDVs and motorbikes | B2: 0.68595041
A3: HDVs | B3: 0.68881037
A5: Perc of Electricity Use for Plug-In Hybrid Vehicles
A6: electricity share | B6: 0.55
A8: Vehicle Lifetimes (years)
A9: LDVs | B9: 13.378782
A10: HDVs | B10: 28
A11: aircraft | B11: 24
A12: rail | B12: 34
A13: ships | B13: 33
A14: motorbikes | B14: 17.223321

Sheet Calculations
A1: Vehicle Loadings (in people or freight tons / vehicle) | D1: Source:
A2: passenger LDVs | B2: 1.67 | D2: For sources and calculations, see the variable AVLo.
A3: freight LDVs | B3: 1
A4: passenger HDVs | B4: 21.2
A5: freight HDVs | B5: 16
A6: passenger rail | B6: 48.656732
A8: BTU per Gallon Liquid Fuels | AK8: Source:
A9: gasoline | B9: 120476 | AK9: EIA | AL9: Energy Explained: Units and Calculators
A10: diesel | B10: 137452 | AK10: 2017 | AL10: https://www.eia.gov/energyexplained/index.cfm/index.cfm?page=about_energy_units
A12: Historical AEO fuel economy - passenger LDVs
B13: 2007 | C13: 2007 | D13: 2021
A14: Source | C14: AEO 2010 Table 7
A15: MPG | C15: 22.670399
A16: thing-miles/BTU | B16: =TREND(C16:D16,C13:D13,B13) -> 0.00031424986 | C16: =C15*$B$2/$B$9 -> 0.00031424986 | D16: =BNVFE!D8 -> 0.00038560343
A18: Historical fuel economy - freight HDV
A19: 2002 diesel heavy-duty vehicles | B19: 5.76
A20: Ratio of 2019 AEO overall freight efficiency to "heavy" freight efficiency, AEO 2019 | B20: =7.1/6.1 -> 1.1639344
A21: 2002 Average Freight HDV efficiency (MPG) | B21: =B19*$B$20 -> 6.7042623
A22: 2002 Average Freight HDV efficiency (thing-miles/BTU) | B22: =B21*$B$5/$B$10 -> 0.00078040477
A24: Hydrogen vs. Gasoline Efficiency | D24: Source:
A25: gasoline car efficiency | B25: 0.2 | D25: See the variable BNVFE
A26: hydrogen FCV efficiency | B26: 0.6
A27: distance multiplier for hydrogen vehicles | B27: =B26/B25 -> 3
A29: Propane (LPG) vs. Gasoline Efficiency | D29: Source:
A30: reduction in efficiency for propane | B30: 0.225 | D30: See the variable BNVFE
A31: distance multiplier for propane vehicles | B31: =1-B30 -> 0.775

Sheet Extrapolations
C1: 1983 | D1: 1984 | E1: 1985 | F1: 1986 | G1: 1987 | H1: 1988 | I1: 1989 | J1: 1990 | K1: 1991 | L1: 1992 | M1: 1993 | N1: 1994 | O1: 1995 | P1: 1996 | Q1: 1997 | R1: 1998 | S1: 1999 | T1: 2000 | U1: 2001 | V1: 2002 | W1: 2003 | X1: 2004 | Y1: 2005 | Z1: 2006 | AA1: 2007 | AB1: 2008 | AC1: 2009 | AD1: 2010 | AE1: 2011 | AF1: 2012 | AG1: 2013 | AH1: 2014 | AI1: 2015 | AJ1: 2016 | AK1: 2017 | AL1: 2018 | AM1: 2019 | AN1: 2020 | AO1: 2021 | AP1: 2022 | AQ1: 2023 | AR1: 2024 | AS1: 2025 | AT1: 2026 | AU1: 2027 | AV1: 2028 | AW1: 2029 | AX1: 2030 | AY1: 2031 | AZ1: 2032 | BA1: 2033 | BB1: 2034 | BC1: 2035 | BD1: 2036 | BE1: 2037 | BF1: 2038 | BG1: 2039 | BH1: 2040 | BI1: 2041 | BJ1: 2042 | BK1: 2043 | BL1: 2044 | BM1: 2045 | BN1: 2046 | BO1: 2047 | BP1: 2048 | BQ1: 2049 | BR1: 2050
A2: LDVs | B2: psgr | AA2: =Calculations!C16 -> 0.00031424986 | AB2: =($AO$2-$AA$2)/COUNT($AB$1:$AO$1)+AA2 -> 0.00031934654 | AC2: =($AO$2-$AA$2)/COUNT($AB$1:$AO$1)+AB2 -> 0.00032444323 | AD2: =($AO$2-$AA$2)/COUNT($AB$1:$AO$1)+AC2 -> 0.00032953991 | AE2: =($AO$2-$AA$2)/COUNT($AB$1:$AO$1)+AD2 -> 0.00033463659 | AF2: =($AO$2-$AA$2)/COUNT($AB$1:$AO$1)+AE2 -> 0.00033973328 | AG2: =($AO$2-$AA$2)/COUNT($AB$1:$AO$1)+AF2 -> 0.00034482996 | AH2: =($AO$2-$AA$2)/COUNT($AB$1:$AO$1)+AG2 -> 0.00034992664 | AI2: =($AO$2-$AA$2)/COUNT($AB$1:$AO$1)+AH2 -> 0.00035502333 | ... AN2: =($AO$2-$AA$2)/COUNT($AB$1:$AO$1)+AM2 -> 0.00038050674 | AO2: =BNVFE!D8 -> 0.00038560343 | AP2: =BNVFE!E8 -> 0.00039389771 | AQ2: =BNVFE!F8 -> 0.00040102816 | AR2: =BNVFE!G8 -> 0.00040668873 | AS2: =BNVFE!H8 -> 0.0004214844 | AT2: =BNVFE!I8 -> 0.00042638034 | AU2: =BNVFE!J8 -> 0.00042993929 | AV2: =BNVFE!K8 -> 0.00044295233 | ... BR2: =BNVFE!AG8 -> 0.00045447279
A3: LDVs | B3: frgt | AA3: {=TREND($AO$3:$AS$3,$AO$1:$AS$1,AA1)} -> 5.0412726e-05 | AB3: {=TREND($AO$3:$AS$3,$AO$1:$AS$1,AB1)} -> 5.4271492e-05 | AC3: {=TREND($AO$3:$AS$3,$AO$1:$AS$1,AC1)} -> 5.8130258e-05 | AD3: {=TREND($AO$3:$AS$3,$AO$1:$AS$1,AD1)} -> 6.1989024e-05 | AE3: {=TREND($AO$3:$AS$3,$AO$1:$AS$1,AE1)} -> 6.584779e-05 | AF3: {=TREND($AO$3:$AS$3,$AO$1:$AS$1,AF1)} -> 6.9706555e-05 | AG3: {=TREND($AO$3:$AS$3,$AO$1:$AS$1,AG1)} -> 7.3565321e-05 | AH3: {=TREND($AO$3:$AS$3,$AO$1:$AS$1,AH1)} -> 7.7424087e-05 | ... AN3: {=TREND($AO$3:$AS$3,$AO$1:$AS$1,AN1)} -> 0.00010057668 | AO3: =BNVFE!D9 -> 0.00010420516 | AP3: =BNVFE!E9 -> 0.00010877082 | AQ3: =BNVFE!F9 -> 0.00011192287 | AR3: =BNVFE!G9 -> 0.00011596329 | AS3: =BNVFE!H9 -> 0.00011990275 | AT3: =BNVFE!I9 -> 0.00012199635 | AU3: =BNVFE!J9 -> 0.00012434671 | AV3: =BNVFE!K9 -> 0.00012468075 | ... BR3: =BNVFE!AG9 -> 0.00012663654
A4: HDVs | B4: psgr | L4: =L5/M5*M4 -> 0.0011628807 | M4: =M5/N5*N4 -> 0.0011628807 | N4: =N5/O5*O4 -> 0.0011628807 | O4: =O5/P5*P4 -> 0.0011628807 | P4: =P5/Q5*Q4 -> 0.0011628807 | Q4: =Q5/R5*R4 -> 0.0011628807 | R4: =R5/S5*S4 -> 0.0011628807 | S4: =S5/T5*T4 -> 0.0011628807 | ... AN4: =AN5/AO5*AO4 -> 0.0011186507 | AO4: =BNVFE!D10 -> 0.0011137362 | AP4: =BNVFE!E10 -> 0.0011868928 | AQ4: =BNVFE!F10 -> 0.0012242022 | AR4: =BNVFE!G10 -> 0.0012625148 | AS4: =BNVFE!H10 -> 0.0012984725 | AT4: =BNVFE!I10 -> 0.0013325459 | AU4: =BNVFE!J10 -> 0.0013625499 | AV4: =BNVFE!K10 -> 0.0013753174 | ... BR4: =BNVFE!AG10 -> 0.0014456904
A5: HDVs | B5: frgt | L5: =M5 -> 0.00078040477 | M5: =N5 -> 0.00078040477 | N5: =O5 -> 0.00078040477 | O5: =P5 -> 0.00078040477 | P5: =Q5 -> 0.00078040477 | Q5: =R5 -> 0.00078040477 | R5: =S5 -> 0.00078040477 | S5: =T5 -> 0.00078040477 | ... U5: =V5 -> 0.00078040477 | V5: =Calculations!B22 -> 0.00078040477 | W5: =($AO$5-$V$5)/COUNT($V$1:$AO$1)+V5 -> 0.00077875574 | X5: =($AO$5-$V$5)/COUNT($V$1:$AO$1)+W5 -> 0.00077710671 | Y5: =($AO$5-$V$5)/COUNT($V$1:$AO$1)+X5 -> 0.00077545767 | Z5: =($AO$5-$V$5)/COUNT($V$1:$AO$1)+Y5 -> 0.00077380864 | AA5: =($AO$5-$V$5)/COUNT($V$1:$AO$1)+Z5 -> 0.00077215961 | AB5: =($AO$5-$V$5)/COUNT($V$1:$AO$1)+AA5 -> 0.00077051058 | AC5: =($AO$5-$V$5)/COUNT($V$1:$AO$1)+AB5 -> 0.00076886154 | AD5: =($AO$5-$V$5)/COUNT($V$1:$AO$1)+AC5 -> 0.00076721251 | ... AN5: =($AO$5-$V$5)/COUNT($V$1:$AO$1)+AM5 -> 0.00075072218 | AO5: =BNVFE!D11 -> 0.00074742412 | AP5: =BNVFE!E11 -> 0.00079651925 | AQ5: =BNVFE!F11 -> 0.00082155739 | AR5: =BNVFE!G11 -> 0.00084726887 | AS5: =BNVFE!H11 -> 0.00087139991 | AT5: =BNVFE!I11 -> 0.00089426646 | AU5: =BNVFE!J11 -> 0.00091440204 | AV5: =BNVFE!K11 -> 0.00092297026 | ... BR5: =BNVFE!AG11 -> 0.00097019732
A6: aircraft | B6: psgr | P6: =TREND($AO6:$BR6,$AO$1:$BR$1,P$1) -> 0.00057245969 | Q6: =TREND($AO6:$BR6,$AO$1:$BR$1,Q$1) -> 0.00057245969 | R6: =TREND($AO6:$BR6,$AO$1:$BR$1,R$1) -> 0.00057245969 | S6: =TREND($AO6:$BR6,$AO$1:$BR$1,S$1) -> 0.00057245969 | T6: =TREND($AO6:$BR6,$AO$1:$BR$1,T$1) -> 0.00057245969 | U6: =TREND($AO6:$BR6,$AO$1:$BR$1,U$1) -> 0.00057245969 | V6: =TREND($AO6:$BR6,$AO$1:$BR$1,V$1) -> 0.00057245969 | W6: =TREND($AO6:$BR6,$AO$1:$BR$1,W$1) -> 0.00057245969 | ... AN6: =TREND($AO6:$BR6,$AO$1:$BR$1,AN$1) -> 0.00057245969 | AO6: =BNVFE!D12 -> 0.00057245969 | AP6: =BNVFE!E12 -> 0.00057245969 | AQ6: =BNVFE!F12 -> 0.00057245969 | AR6: =BNVFE!G12 -> 0.00057245969 | AS6: =BNVFE!H12 -> 0.00057245969 | AT6: =BNVFE!I12 -> 0.00057245969 | AU6: =BNVFE!J12 -> 0.00057245969 | AV6: =BNVFE!K12 -> 0.00057245969 | ... BR6: =BNVFE!AG12 -> 0.00057245969
A7: aircraft | B7: frgt | P7: =TREND($AO7:$BR7,$AO$1:$BR$1,P$1)-($AR7-$AO7) -> 3.6038412e-05 | Q7: =TREND($AO7:$BR7,$AO$1:$BR$1,Q$1)-($AR7-$AO7) -> 3.6478441e-05 | R7: =TREND($AO7:$BR7,$AO$1:$BR$1,R$1)-($AR7-$AO7) -> 3.691847e-05 | S7: =TREND($AO7:$BR7,$AO$1:$BR$1,S$1)-($AR7-$AO7) -> 3.7358499e-05 | T7: =TREND($AO7:$BR7,$AO$1:$BR$1,T$1)-($AR7-$AO7) -> 3.7798527e-05 | U7: =TREND($AO7:$BR7,$AO$1:$BR$1,U$1)-($AR7-$AO7) -> 3.8238556e-05 | V7: =TREND($AO7:$BR7,$AO$1:$BR$1,V$1)-($AR7-$AO7) -> 3.8678585e-05 | W7: =TREND($AO7:$BR7,$AO$1:$BR$1,W$1)-($AR7-$AO7) -> 3.9118614e-05 | ... AN7: =TREND($AO7:$BR7,$AO$1:$BR$1,AN$1)-($AR7-$AO7) -> 4.6599106e-05 | AO7: =BNVFE!D13 -> 4.8563096e-05 | AP7: =BNVFE!E13 -> 4.7951938e-05 | AQ7: =BNVFE!F13 -> 4.8199149e-05 | AR7: =BNVFE!G13 -> 4.846329e-05 | AS7: =BNVFE!H13 -> 4.8810101e-05 | AT7: =BNVFE!I13 -> 4.9248402e-05 | AU7: =BNVFE!J13 -> 4.9544254e-05 | AV7: =BNVFE!K13 -> 4.9847838e-05 | ... BR7: =BNVFE!AG13 -> 6.0224657e-05
A8: rail | B8: psgr - diesel | F8: =SYFAFE!$E$5 -> 7.1745362e-05 | G8: =F8 -> 7.1745362e-05 | H8: =G8 -> 7.1745362e-05 | I8: =H8 -> 7.1745362e-05 | J8: =I8 -> 7.1745362e-05 | K8: =J8 -> 7.1745362e-05 | L8: =K8 -> 7.1745362e-05 | M8: =L8 -> 7.1745362e-05 | N8: =M8 -> 7.1745362e-05 | ... BR8: =BQ8 -> 7.1745362e-05
A9: rail | B9: psgr - electric | F9: =SYFAFE!$B$5 -> 0.00075686214 | G9: =F9 -> 0.00075686214 | H9: =G9 -> 0.00075686214 | I9: =H9 -> 0.00075686214 | J9: =I9 -> 0.00075686214 | K9: =J9 -> 0.00075686214 | L9: =K9 -> 0.00075686214 | M9: =L9 -> 0.00075686214 | N9: =M9 -> 0.00075686214 | ... BR9: =BQ9 -> 0.00075686214
A10: rail | B10: frgt | F10: =TREND($AO10:$BR10,$AO$1:$BR$1,F$1) -> 0.0032890938 | G10: =TREND($AO10:$BR10,$AO$1:$BR$1,G$1) -> 0.003291733 | H10: =TREND($AO10:$BR10,$AO$1:$BR$1,H$1) -> 0.0032943723 | I10: =TREND($AO10:$BR10,$AO$1:$BR$1,I$1) -> 0.0032970115 | J10: =TREND($AO10:$BR10,$AO$1:$BR$1,J$1) -> 0.0032996508 | K10: =TREND($AO10:$BR10,$AO$1:$BR$1,K$1) -> 0.00330229 | L10: =TREND($AO10:$BR10,$AO$1:$BR$1,L$1) -> 0.0033049293 | M10: =TREND($AO10:$BR10,$AO$1:$BR$1,M$1) -> 0.0033075685 | ... AN10: =TREND($AO10:$BR10,$AO$1:$BR$1,AN$1) -> 0.0033788281 | AO10: =BNVFE!D16 -> 0.003512003 | AP10: =BNVFE!E16 -> 0.00336634 | AQ10: =BNVFE!F16 -> 0.003369893 | AR10: =BNVFE!G16 -> 0.00337345 | AS10: =BNVFE!H16 -> 0.00337701 | AT10: =BNVFE!I16 -> 0.003380574 | AU10: =BNVFE!J16 -> 0.003384142 | AV10: =BNVFE!K16 -> 0.003387713 | ... BR10: =BNVFE!AG16 -> 0.003467248
A11: ships | B11: psgr | G11: =TREND($AO11:$BR11,$AO$1:$BR$1,G$1) -> 1.2594546e-05 | H11: =TREND($AO11:$BR11,$AO$1:$BR$1,H$1) -> 1.2594546e-05 | I11: =TREND($AO11:$BR11,$AO$1:$BR$1,I$1) -> 1.2594546e-05 | J11: =TREND($AO11:$BR11,$AO$1:$BR$1,J$1) -> 1.2594546e-05 | K11: =TREND($AO11:$BR11,$AO$1:$BR$1,K$1) -> 1.2594546e-05 | L11: =TREND($AO11:$BR11,$AO$1:$BR$1,L$1) -> 1.2594546e-05 | M11: =TREND($AO11:$BR11,$AO$1:$BR$1,M$1) -> 1.2594546e-05 | N11: =TREND($AO11:$BR11,$AO$1:$BR$1,N$1) -> 1.2594546e-05 | ... AN11: =TREND($AO11:$BR11,$AO$1:$BR$1,AN$1) -> 1.2594546e-05 | AO11: =BNVFE!D17 -> 1.2594546e-05 | AP11: =BNVFE!E17 -> 1.2594546e-05 | AQ11: =BNVFE!F17 -> 1.2594546e-05 | AR11: =BNVFE!G17 -> 1.2594546e-05 | AS11: =BNVFE!H17 -> 1.2594546e-05 | AT11: =BNVFE!I17 -> 1.2594546e-05 | AU11: =BNVFE!J17 -> 1.2594546e-05 | AV11: =BNVFE!K17 -> 1.2594546e-05 | ... BR11: =BNVFE!AG17 -> 1.2594546e-05
A12: ships | B12: frgt | G12: =TREND($AO12:$BR12,$AO$1:$BR$1,G$1) -> 0.0052454272 | H12: =TREND($AO12:$BR12,$AO$1:$BR$1,H$1) -> 0.0052454272 | I12: =TREND($AO12:$BR12,$AO$1:$BR$1,I$1) -> 0.0052454272 | J12: =TREND($AO12:$BR12,$AO$1:$BR$1,J$1) -> 0.0052454272 | K12: =TREND($AO12:$BR12,$AO$1:$BR$1,K$1) -> 0.0052454272 | L12: =TREND($AO12:$BR12,$AO$1:$BR$1,L$1) -> 0.0052454272 | M12: =TREND($AO12:$BR12,$AO$1:$BR$1,M$1) -> 0.0052454272 | N12: =TREND($AO12:$BR12,$AO$1:$BR$1,N$1) -> 0.0052454272 | ... AN12: =TREND($AO12:$BR12,$AO$1:$BR$1,AN$1) -> 0.0052454272 | AO12: =BNVFE!D18 -> 0.0052454272 | AP12: =BNVFE!E18 -> 0.0052454272 | AQ12: =BNVFE!F18 -> 0.0052454272 | AR12: =BNVFE!G18 -> 0.0052454272 | AS12: =BNVFE!H18 -> 0.0052454272 | AT12: =BNVFE!I18 -> 0.0052454272 | AU12: =BNVFE!J18 -> 0.0052454272 | AV12: =BNVFE!K18 -> 0.0052454272 | ... BR12: =BNVFE!AG18 -> 0.0052454272
A13: motorbikes | B13: psgr | W13: =TREND($AO13:$BR13,$AO$1:$BR$1,W$1) -> 0.0014345302 | X13: =TREND($AO13:$BR13,$AO$1:$BR$1,X$1) -> 0.0014345302 | Y13: =TREND($AO13:$BR13,$AO$1:$BR$1,Y$1) -> 0.0014345302 | Z13: =TREND($AO13:$BR13,$AO$1:$BR$1,Z$1) -> 0.0014345302 | AA13: =TREND($AO13:$BR13,$AO$1:$BR$1,AA$1) -> 0.0014345302 | AB13: =TREND($AO13:$BR13,$AO$1:$BR$1,AB$1) -> 0.0014345302 | AC13: =TREND($AO13:$BR13,$AO$1:$BR$1,AC$1) -> 0.0014345302 | AD13: =TREND($AO13:$BR13,$AO$1:$BR$1,AD$1) -> 0.0014345302 | ... AN13: =TREND($AO13:$BR13,$AO$1:$BR$1,AN$1) -> 0.0014345302 | AO13: =BNVFE!D19 -> 0.0014345302 | AP13: =BNVFE!E19 -> 0.0014345302 | AQ13: =BNVFE!F19 -> 0.0014345302 | AR13: =BNVFE!G19 -> 0.0014345302 | AS13: =BNVFE!H19 -> 0.0014345302 | AT13: =BNVFE!I19 -> 0.0014345302 | AU13: =BNVFE!J19 -> 0.0014345302 | AV13: =BNVFE!K19 -> 0.0014345302 | ... BR13: =BNVFE!AG19 -> 0.0014345302
A14: motorbikes | B14: frgt | W14: =$AO14 -> 0 | X14: =$AO14 -> 0 | Y14: =$AO14 -> 0 | Z14: =$AO14 -> 0 | AA14: =$AO14 -> 0 | AB14: =$AO14 -> 0 | AC14: =$AO14 -> 0 | AD14: =$AO14 -> 0 | ... AN14: =$AO14 -> 0 | AO14: =BNVFE!D20 -> 0 | AP14: =BNVFE!E20 -> 0 | AQ14: =BNVFE!F20 -> 0 | AR14: =BNVFE!G20 -> 0 | AS14: =BNVFE!H20 -> 0 | AT14: =BNVFE!I20 -> 0 | AU14: =BNVFE!J20 -> 0 | AV14: =BNVFE!K20 -> 0 | ... BR14: =BNVFE!AG20 -> 0

Sheet BHNVFEAL-LDVs-psgr
A1: Fuel Economy ((thing*miles)/BTU) | B1: 2021 | C1: 2022 | D1: 2023 | E1: 2024 | F1: 2025 | G1: 2026 | H1: 2027 | I1: 2028 | J1: 2029 | K1: 2030 | L1: 2031 | M1: 2032 | N1: 2033 | O1: 2034 | P1: 2035 | Q1: 2036 | R1: 2037 | S1: 2038 | T1: 2039 | U1: 2040 | V1: 2041 | W1: 2042 | X1: 2043 | Y1: 2044 | Z1: 2045 | AA1: 2046 | AB1: 2047 | AC1: 2048 | AD1: 2049 | AE1: 2050 | AF1: 2051 | AG1: 2052 | AH1: 2053 | AI1: 2054 | AJ1: 2055 | AK1: 2056 | AL1: 2057 | AM1: 2058 | AN1: 2059 | AO1: 2060 | AP1: 2061 | AQ1: 2062 | AR1: 2063 | AS1: 2064 | AT1: 2065 | AU1: 2066 | AV1: 2067 | AW1: 2068 | AX1: 2069 | AY1: 2070
A2: battery electric vehicle | B2: =SYFAFE!$B$2 -> 0.0013018081 | C2: =SYFAFE!$B$2 -> 0.0013018081 | D2: =SYFAFE!$B$2 -> 0.0013018081 | E2: =SYFAFE!$B$2 -> 0.0013018081 | F2: =SYFAFE!$B$2 -> 0.0013018081 | G2: =SYFAFE!$B$2 -> 0.0013018081 | H2: =SYFAFE!$B$2 -> 0.0013018081 | I2: =SYFAFE!$B$2 -> 0.0013018081 | ... AE2: =SYFAFE!$B$2 -> 0.0013018081 | AF2: =AE2 -> 0.0013018081 | AG2: =AF2 -> 0.0013018081 | AH2: =AG2 -> 0.0013018081 | AI2: =AH2 -> 0.0013018081 | AJ2: =AI2 -> 0.0013018081 | AK2: =AJ2 -> 0.0013018081 | AL2: =AK2 -> 0.0013018081 | AM2: =AL2 -> 0.0013018081 | ... AY2: =AX2 -> 0.0013018081
A3: natural gas vehicle | B3: =BNVFE!B25*('BHNVFEAL-LDVs-psgr'!B$4/BNVFE!B$26) -> 0.00034315886 | C3: =BNVFE!C25*('BHNVFEAL-LDVs-psgr'!C$4/BNVFE!C$26) -> 0.00034251537 | D3: =BNVFE!D25*('BHNVFEAL-LDVs-psgr'!D$4/BNVFE!D$26) -> 0.00035067496 | E3: =BNVFE!E25*('BHNVFEAL-LDVs-psgr'!E$4/BNVFE!E$26) -> 0.00035195903 | F3: =BNVFE!F25*('BHNVFEAL-LDVs-psgr'!F$4/BNVFE!F$26) -> 0.00035537454 | G3: =BNVFE!G25*('BHNVFEAL-LDVs-psgr'!G$4/BNVFE!G$26) -> 0.00036001444 | H3: =BNVFE!H25*('BHNVFEAL-LDVs-psgr'!H$4/BNVFE!H$26) -> 0.00036391174 | I3: =BNVFE!I25*('BHNVFEAL-LDVs-psgr'!I$4/BNVFE!I$26) -> 0.00036765603 | ... AE3: =BNVFE!AE25*('BHNVFEAL-LDVs-psgr'!AE$4/BNVFE!AE$26) -> 0.00045558862 | AF3: =AE3 -> 0.00045558862 | AG3: =AF3 -> 0.00045558862 | AH3: =AG3 -> 0.00045558862 | AI3: =AH3 -> 0.00045558862 | AJ3: =AI3 -> 0.00045558862 | AK3: =AJ3 -> 0.00045558862 | AL3: =AK3 -> 0.00045558862 | AM3: =AL3 -> 0.00045558862 | ... AY3: =AX3 -> 0.00045558862
A4: gasoline vehicle | B4: =Extrapolations!AB2 -> 0.00031934654 | C4: =Extrapolations!AC2 -> 0.00032444323 | D4: =Extrapolations!AD2 -> 0.00032953991 | E4: =Extrapolations!AE2 -> 0.00033463659 | F4: =Extrapolations!AF2 -> 0.00033973328 | G4: =Extrapolations!AG2 -> 0.00034482996 | H4: =Extrapolations!AH2 -> 0.00034992664 | I4: =Extrapolations!AI2 -> 0.00035502333 | ... AE4: =Extrapolations!BE2 -> 0.00045211629 | AF4: =AE4 -> 0.00045211629 | AG4: =AF4 -> 0.00045211629 | AH4: =AG4 -> 0.00045211629 | AI4: =AH4 -> 0.00045211629 | AJ4: =AI4 -> 0.00045211629 | AK4: =AJ4 -> 0.00045211629 | AL4: =AK4 -> 0.00045211629 | AM4: =AL4 -> 0.00045211629 | ... AY4: =AX4 -> 0.00045211629
A5: diesel vehicle | B5: =BNVFE!B27*('BHNVFEAL-LDVs-psgr'!B$4/BNVFE!B$26) -> 0.00033512581 | C5: =BNVFE!C27*('BHNVFEAL-LDVs-psgr'!C$4/BNVFE!C$26) -> 0.00034245229 | D5: =BNVFE!D27*('BHNVFEAL-LDVs-psgr'!D$4/BNVFE!D$26) -> 0.00034406917 | E5: =BNVFE!E27*('BHNVFEAL-LDVs-psgr'!E$4/BNVFE!E$26) -> 0.00034697346 | F5: =BNVFE!F27*('BHNVFEAL-LDVs-psgr'!F$4/BNVFE!F$26) -> 0.00034874484 | G5: =BNVFE!G27*('BHNVFEAL-LDVs-psgr'!G$4/BNVFE!G$26) -> 0.00035370414 | H5: =BNVFE!H27*('BHNVFEAL-LDVs-psgr'!H$4/BNVFE!H$26) -> 0.00035748141 | I5: =BNVFE!I27*('BHNVFEAL-LDVs-psgr'!I$4/BNVFE!I$26) -> 0.00035749416 | ... AE5: =BNVFE!AE27*('BHNVFEAL-LDVs-psgr'!AE$4/BNVFE!AE$26) -> 0.00045519387 | AF5: =AE5 -> 0.00045519387 | AG5: =AF5 -> 0.00045519387 | AH5: =AG5 -> 0.00045519387 | AI5: =AH5 -> 0.00045519387 | AJ5: =AI5 -> 0.00045519387 | AK5: =AJ5 -> 0.00045519387 | AL5: =AK5 -> 0.00045519387 | AM5: =AL5 -> 0.00045519387 | ... AY5: =AX5 -> 0.00045519387
A6: plugin hybrid vehicle | B6: =BNVFE!B28*('BHNVFEAL-LDVs-psgr'!B$4/BNVFE!B$26) -> 0.00054259676 | C6: =BNVFE!C28*('BHNVFEAL-LDVs-psgr'!C$4/BNVFE!C$26) -> 0.00049844215 | D6: =BNVFE!D28*('BHNVFEAL-LDVs-psgr'!D$4/BNVFE!D$26) -> 0.00049428095 | E6: =BNVFE!E28*('BHNVFEAL-LDVs-psgr'!E$4/BNVFE!E$26) -> 0.00050544145 | F6: =BNVFE!F28*('BHNVFEAL-LDVs-psgr'!F$4/BNVFE!F$26) -> 0.00051354791 | G6: =BNVFE!G28*('BHNVFEAL-LDVs-psgr'!G$4/BNVFE!G$26) -> 0.00052356576 | H6: =BNVFE!H28*('BHNVFEAL-LDVs-psgr'!H$4/BNVFE!H$26) -> 0.00053321179 | I6: =BNVFE!I28*('BHNVFEAL-LDVs-psgr'!I$4/BNVFE!I$26) -> 0.00053854348 | ... AE6: =BNVFE!AE28*('BHNVFEAL-LDVs-psgr'!AE$4/BNVFE!AE$26) -> 0.00069829222 | AF6: =AE6 -> 0.00069829222 | AG6: =AF6 -> 0.00069829222 | AH6: =AG6 -> 0.00069829222 | AI6: =AH6 -> 0.00069829222 | AJ6: =AI6 -> 0.00069829222 | AK6: =AJ6 -> 0.00069829222 | AL6: =AK6 -> 0.00069829222 | AM6: =AL6 -> 0.00069829222 | ... AY6: =AX6 -> 0.00069829222
A7: LPG vehicle | B7: =BNVFE!B29*('BHNVFEAL-LDVs-psgr'!B$4/BNVFE!B$26) -> 0.00029851932 | C7: =BNVFE!C29*('BHNVFEAL-LDVs-psgr'!C$4/BNVFE!C$26) -> 0.00029611637 | D7: =BNVFE!D29*('BHNVFEAL-LDVs-psgr'!D$4/BNVFE!D$26) -> 0.00030864865 | E7: =BNVFE!E29*('BHNVFEAL-LDVs-psgr'!E$4/BNVFE!E$26) -> 0.00031244244 | F7: =BNVFE!F29*('BHNVFEAL-LDVs-psgr'!F$4/BNVFE!F$26) -> 0.00031581778 | G7: =BNVFE!G29*('BHNVFEAL-LDVs-psgr'!G$4/BNVFE!G$26) -> 0.00032252933 | H7: =BNVFE!H29*('BHNVFEAL-LDVs-psgr'!H$4/BNVFE!H$26) -> 0.00032650305 | I7: =BNVFE!I29*('BHNVFEAL-LDVs-psgr'!I$4/BNVFE!I$26) -> 0.00032984134 | ... AE7: =BNVFE!AE29*('BHNVFEAL-LDVs-psgr'!AE$4/BNVFE!AE$26) -> 0.00041351346 | AF7: =AE7 -> 0.00041351346 | AG7: =AF7 -> 0.00041351346 | AH7: =AG7 -> 0.00041351346 | AI7: =AH7 -> 0.00041351346 | AJ7: =AI7 -> 0.00041351346 | AK7: =AJ7 -> 0.00041351346 | AL7: =AK7 -> 0.00041351346 | AM7: =AL7 -> 0.00041351346 | ... AY7: =AX7 -> 0.00041351346
A8: hydrogen vehicle | B8: =SYFAFE!$H$2 -> 0.00058506341 | C8: =B8 -> 0.00058506341 | D8: =C8 -> 0.00058506341 | E8: =D8 -> 0.00058506341 | F8: =E8 -> 0.00058506341 | G8: =F8 -> 0.00058506341 | H8: =G8 -> 0.00058506341 | I8: =H8 -> 0.00058506341 | J8: =I8 -> 0.00058506341 | ... AY8: =AX8 -> 0.00058506341

Sheet BHNVFEAL-LDVs-frgt
A1: Fuel Economy ((thing*miles)/BTU) | B1: 2021 | C1: 2022 | D1: 2023 | E1: 2024 | F1: 2025 | G1: 2026 | H1: 2027 | I1: 2028 | J1: 2029 | K1: 2030 | L1: 2031 | M1: 2032 | N1: 2033 | O1: 2034 | P1: 2035 | Q1: 2036 | R1: 2037 | S1: 2038 | T1: 2039 | U1: 2040 | V1: 2041 | W1: 2042 | X1: 2043 | Y1: 2044 | Z1: 2045 | AA1: 2046 | AB1: 2047 | AC1: 2048 | AD1: 2049 | AE1: 2050 | AF1: 2051 | AG1: 2052 | AH1: 2053 | AI1: 2054 | AJ1: 2055 | AK1: 2056 | AL1: 2057 | AM1: 2058 | AN1: 2059 | AO1: 2060 | AP1: 2061 | AQ1: 2062 | AR1: 2063 | AS1: 2064 | AT1: 2065 | AU1: 2066 | AV1: 2067 | AW1: 2068 | AX1: 2069 | AY1: 2070
A2: battery electric vehicle | B2: {=TRANSPOSE(SYFAFE!B10:H10)} -> 0.00010150689 | C2: =B2 -> 0.00010150689 | D2: =C2 -> 0.00010150689 | E2: =D2 -> 0.00010150689 | F2: =E2 -> 0.00010150689 | G2: =F2 -> 0.00010150689 | H2: =G2 -> 0.00010150689 | I2: =H2 -> 0.00010150689 | J2: =I2 -> 0.00010150689 | ... AY2: =AX2 -> 0.00010150689
A3: natural gas vehicle | B3: 6.674878e-05 | C3: =B3 -> 6.674878e-05 | D3: =C3 -> 6.674878e-05 | E3: =D3 -> 6.674878e-05 | F3: =E3 -> 6.674878e-05 | G3: =F3 -> 6.674878e-05 | H3: =G3 -> 6.674878e-05 | I3: =H3 -> 6.674878e-05 | J3: =I3 -> 6.674878e-05 | ... AY3: =AX3 -> 6.674878e-05
A4: gasoline vehicle | B4: 9.6215656e-05 | C4: =B4 -> 9.6215656e-05 | D4: =C4 -> 9.6215656e-05 | E4: =D4 -> 9.6215656e-05 | F4: =E4 -> 9.6215656e-05 | G4: =F4 -> 9.6215656e-05 | H4: =G4 -> 9.6215656e-05 | I4: =H4 -> 9.6215656e-05 | J4: =I4 -> 9.6215656e-05 | ... AY4: =AX4 -> 9.6215656e-05
A5: diesel vehicle | B5: 6.8445241e-05 | C5: =B5 -> 6.8445241e-05 | D5: =C5 -> 6.8445241e-05 | E5: =D5 -> 6.8445241e-05 | F5: =E5 -> 6.8445241e-05 | G5: =F5 -> 6.8445241e-05 | H5: =G5 -> 6.8445241e-05 | I5: =H5 -> 6.8445241e-05 | J5: =I5 -> 6.8445241e-05 | ... AY5: =AX5 -> 6.8445241e-05
A6: plugin hybrid vehicle | B6: 0.00021334966 | C6: =B6 -> 0.00021334966 | D6: =C6 -> 0.00021334966 | E6: =D6 -> 0.00021334966 | F6: =E6 -> 0.00021334966 | G6: =F6 -> 0.00021334966 | H6: =G6 -> 0.00021334966 | I6: =H6 -> 0.00021334966 | J6: =I6 -> 0.00021334966 | ... AY6: =AX6 -> 0.00021334966
A7: LPG vehicle | B7: 4.0500619e-05 | C7: =B7 -> 4.0500619e-05 | D7: =C7 -> 4.0500619e-05 | E7: =D7 -> 4.0500619e-05 | F7: =E7 -> 4.0500619e-05 | G7: =F7 -> 4.0500619e-05 | H7: =G7 -> 4.0500619e-05 | I7: =H7 -> 4.0500619e-05 | J7: =I7 -> 4.0500619e-05 | ... AY7: =AX7 -> 4.0500619e-05
A8: hydrogen vehicle | B8: 0.002080262 | C8: =B8 -> 0.002080262 | D8: =C8 -> 0.002080262 | E8: =D8 -> 0.002080262 | F8: =E8 -> 0.002080262 | G8: =F8 -> 0.002080262 | H8: =G8 -> 0.002080262 | I8: =H8 -> 0.002080262 | J8: =I8 -> 0.002080262 | ... AY8: =AX8 -> 0.002080262

Sheet BHNVFEAL-HDVs-psgr
A1: Fuel Economy ((thing*miles)/BTU) | B1: 2021 | C1: 2022 | D1: 2023 | E1: 2024 | F1: 2025 | G1: 2026 | H1: 2027 | I1: 2028 | J1: 2029 | K1: 2030 | L1: 2031 | M1: 2032 | N1: 2033 | O1: 2034 | P1: 2035 | Q1: 2036 | R1: 2037 | S1: 2038 | T1: 2039 | U1: 2040 | V1: 2041 | W1: 2042 | X1: 2043 | Y1: 2044 | Z1: 2045 | AA1: 2046 | AB1: 2047 | AC1: 2048 | AD1: 2049 | AE1: 2050 | AF1: 2051 | AG1: 2052 | AH1: 2053 | AI1: 2054 | AJ1: 2055 | AK1: 2056 | AL1: 2057 | AM1: 2058 | AN1: 2059 | AO1: 2060 | AP1: 2061 | AQ1: 2062 | AR1: 2063 | AS1: 2064 | AT1: 2065 | AU1: 2066 | AV1: 2067 | AW1: 2068 | AX1: 2069 | AY1: 2070
A2: battery electric vehicle | B2: {=TRANSPOSE(SYFAFE!B3:H3)} -> 0.0034003582 | C2: =B2 -> 0.0034003582 | D2: =C2 -> 0.0034003582 | E2: =D2 -> 0.0034003582 | F2: =E2 -> 0.0034003582 | G2: =F2 -> 0.0034003582 | H2: =G2 -> 0.0034003582 | I2: =H2 -> 0.0034003582 | J2: =I2 -> 0.0034003582 | ... AY2: =AX2 -> 0.0034003582
A3: natural gas vehicle | B3: 0.002822677 | C3: =B3 -> 0.002822677 | D3: =C3 -> 0.002822677 | E3: =D3 -> 0.002822677 | F3: =E3 -> 0.002822677 | G3: =F3 -> 0.002822677 | H3: =G3 -> 0.002822677 | I3: =H3 -> 0.002822677 | J3: =I3 -> 0.002822677 | ... AY3: =AX3 -> 0.002822677
A4: gasoline vehicle | B4: 0.00091563612 | C4: =B4 -> 0.00091563612 | D4: =C4 -> 0.00091563612 | E4: =D4 -> 0.00091563612 | F4: =E4 -> 0.00091563612 | G4: =F4 -> 0.00091563612 | H4: =G4 -> 0.00091563612 | I4: =H4 -> 0.00091563612 | J4: =I4 -> 0.00091563612 | ... AY4: =AX4 -> 0.00091563612
A5: diesel vehicle | B5: 0.0010581562 | C5: =B5 -> 0.0010581562 | D5: =C5 -> 0.0010581562 | E5: =D5 -> 0.0010581562 | F5: =E5 -> 0.0010581562 | G5: =F5 -> 0.0010581562 | H5: =G5 -> 0.0010581562 | I5: =H5 -> 0.0010581562 | J5: =I5 -> 0.0010581562 | ... AY5: =AX5 -> 0.0010581562
A6: plugin hybrid vehicle | B6: 0.0023463673 | C6: =B6 -> 0.0023463673 | D6: =C6 -> 0.0023463673 | E6: =D6 -> 0.0023463673 | F6: =E6 -> 0.0023463673 | G6: =F6 -> 0.0023463673 | H6: =G6 -> 0.0023463673 | I6: =H6 -> 0.0023463673 | J6: =I6 -> 0.0023463673 | ... AY6: =AX6 -> 0.0023463673
A7: LPG vehicle | B7: 0.0030762664 | C7: =B7 -> 0.0030762664 | D7: =C7 -> 0.0030762664 | E7: =D7 -> 0.0030762664 | F7: =E7 -> 0.0030762664 | G7: =F7 -> 0.0030762664 | H7: =G7 -> 0.0030762664 | I7: =H7 -> 0.0030762664 | J7: =I7 -> 0.0030762664 | ... AY7: =AX7 -> 0.0030762664
A8: hydrogen vehicle | B8: 0.0031744687 | C8: =B8 -> 0.0031744687 | D8: =C8 -> 0.0031744687 | E8: =D8 -> 0.0031744687 | F8: =E8 -> 0.0031744687 | G8: =F8 -> 0.0031744687 | H8: =G8 -> 0.0031744687 | I8: =H8 -> 0.0031744687 | J8: =I8 -> 0.0031744687 | ... AY8: =AX8 -> 0.0031744687

Sheet BHNVFEAL-HDVs-frgt
A1: Fuel Economy ((thing*miles)/BTU) | B1: 2021 | C1: 2022 | D1: 2023 | E1: 2024 | F1: 2025 | G1: 2026 | H1: 2027 | I1: 2028 | J1: 2029 | K1: 2030 | L1: 2031 | M1: 2032 | N1: 2033 | O1: 2034 | P1: 2035 | Q1: 2036 | R1: 2037 | S1: 2038 | T1: 2039 | U1: 2040 | V1: 2041 | W1: 2042 | X1: 2043 | Y1: 2044 | Z1: 2045 | AA1: 2046 | AB1: 2047 | AC1: 2048 | AD1: 2049 | AE1: 2050 | AF1: 2051 | AG1: 2052 | AH1: 2053 | AI1: 2054 | AJ1: 2055 | AK1: 2056 | AL1: 2057 | AM1: 2058 | AN1: 2059 | AO1: 2060 | AP1: 2061 | AQ1: 2062 | AR1: 2063 | AS1: 2064 | AT1: 2065 | AU1: 2066 | AV1: 2067 | AW1: 2068 | AX1: 2069 | AY1: 2070
A2: battery electric vehicle | B2: {=TRANSPOSE(SYFAFE!B11:H11)} -> 0.0022282897 | C2: =B2 -> 0.0022282897 | D2: =C2 -> 0.0022282897 | E2: =D2 -> 0.0022282897 | F2: =E2 -> 0.0022282897 | G2: =F2 -> 0.0022282897 | H2: =G2 -> 0.0022282897 | I2: =H2 -> 0.0022282897 | J2: =I2 -> 0.0022282897 | ... AY2: =AX2 -> 0.0022282897
A3: natural gas vehicle | B3: 0.00049095868 | C3: =B3 -> 0.00049095868 | D3: =C3 -> 0.00049095868 | E3: =D3 -> 0.00049095868 | F3: =E3 -> 0.00049095868 | G3: =F3 -> 0.00049095868 | H3: =G3 -> 0.00049095868 | I3: =H3 -> 0.00049095868 | J3: =I3 -> 0.00049095868 | ... AY3: =AX3 -> 0.00049095868
A4: gasoline vehicle | B4: 0.0065279356 | C4: =B4 -> 0.0065279356 | D4: =C4 -> 0.0065279356 | E4: =D4 -> 0.0065279356 | F4: =E4 -> 0.0065279356 | G4: =F4 -> 0.0065279356 | H4: =G4 -> 0.0065279356 | I4: =H4 -> 0.0065279356 | J4: =I4 -> 0.0065279356 | ... AY4: =AX4 -> 0.0065279356
A5: diesel vehicle | B5: 0.00069342067 | C5: =B5 -> 0.00069342067 | D5: =C5 -> 0.00069342067 | E5: =D5 -> 0.00069342067 | F5: =E5 -> 0.00069342067 | G5: =F5 -> 0.00069342067 | H5: =G5 -> 0.00069342067 | I5: =H5 -> 0.00069342067 | J5: =I5 -> 0.00069342067 | ... AY5: =AX5 -> 0.00069342067
A6: plugin hybrid vehicle | B6: 0.0013400471 | C6: =B6 -> 0.0013400471 | D6: =C6 -> 0.0013400471 | E6: =D6 -> 0.0013400471 | F6: =E6 -> 0.0013400471 | G6: =F6 -> 0.0013400471 | H6: =G6 -> 0.0013400471 | I6: =H6 -> 0.0013400471 | J6: =I6 -> 0.0013400471 | ... AY6: =AX6 -> 0.0013400471
A7: LPG vehicle | B7: 0.0027723416 | C7: =B7 -> 0.0027723416 | D7: =C7 -> 0.0027723416 | E7: =D7 -> 0.0027723416 | F7: =E7 -> 0.0027723416 | G7: =F7 -> 0.0027723416 | H7: =G7 -> 0.0027723416 | I7: =H7 -> 0.0027723416 | J7: =I7 -> 0.0027723416 | ... AY7: =AX7 -> 0.0027723416
A8: hydrogen vehicle | B8: 0.0025188575 | C8: =B8 -> 0.0025188575 | D8: =C8 -> 0.0025188575 | E8: =D8 -> 0.0025188575 | F8: =E8 -> 0.0025188575 | G8: =F8 -> 0.0025188575 | H8: =G8 -> 0.0025188575 | I8: =H8 -> 0.0025188575 | J8: =I8 -> 0.0025188575 | ... AY8: =AX8 -> 0.0025188575

Sheet BHNVFEAL-aircraft-psgr
A1: Fuel Economy ((thing*miles)/BTU) | B1: 2021 | C1: 2022 | D1: 2023 | E1: 2024 | F1: 2025 | G1: 2026 | H1: 2027 | I1: 2028 | J1: 2029 | K1: 2030 | L1: 2031 | M1: 2032 | N1: 2033 | O1: 2034 | P1: 2035 | Q1: 2036 | R1: 2037 | S1: 2038 | T1: 2039 | U1: 2040 | V1: 2041 | W1: 2042 | X1: 2043 | Y1: 2044 | Z1: 2045 | AA1: 2046 | AB1: 2047 | AC1: 2048 | AD1: 2049 | AE1: 2050 | AF1: 2051 | AG1: 2052 | AH1: 2053 | AI1: 2054 | AJ1: 2055 | AK1: 2056 | AL1: 2057 | AM1: 2058 | AN1: 2059 | AO1: 2060 | AP1: 2061 | AQ1: 2062 | AR1: 2063 | AS1: 2064 | AT1: 2065 | AU1: 2066 | AV1: 2067 | AW1: 2068 | AX1: 2069 | AY1: 2070
A2: battery electric vehicle | B2: =B$5/(1-'Other Values'!$B$3) -> 0.0018395847 | C2: =C$5/(1-'Other Values'!$B$3) -> 0.0018395847 | D2: =D$5/(1-'Other Values'!$B$3) -> 0.0018395847 | E2: =E$5/(1-'Other Values'!$B$3) -> 0.0018395847 | F2: =F$5/(1-'Other Values'!$B$3) -> 0.0018395847 | G2: =G$5/(1-'Other Values'!$B$3) -> 0.0018395847 | H2: =H$5/(1-'Other Values'!$B$3) -> 0.0018395847 | I2: =I$5/(1-'Other Values'!$B$3) -> 0.0018395847 | ... AE2: =AE$5/(1-'Other Values'!$B$3) -> 0.0018395847 | AF2: =AE2 -> 0.0018395847 | AG2: =AF2 -> 0.0018395847 | AH2: =AG2 -> 0.0018395847 | AI2: =AH2 -> 0.0018395847 | AJ2: =AI2 -> 0.0018395847 | AK2: =AJ2 -> 0.0018395847 | AL2: =AK2 -> 0.0018395847 | AM2: =AL2 -> 0.0018395847 | ... AY2: =AX2 -> 0.0018395847
A3: natural gas vehicle | B3: 0 | C3: 0 | D3: 0 | E3: 0 | F3: 0 | G3: 0 | H3: 0 | I3: 0 | J3: 0 | K3: 0 | L3: 0 | M3: 0 | N3: 0 | O3: 0 | P3: 0 | Q3: 0 | R3: 0 | S3: 0 | T3: 0 | U3: 0 | V3: 0 | W3: 0 | X3: 0 | Y3: 0 | Z3: 0 | AA3: 0 | AB3: 0 | AC3: 0 | AD3: 0 | AE3: 0 | AF3: =AE3 -> 0 | AG3: =AF3 -> 0 | AH3: =AG3 -> 0 | AI3: =AH3 -> 0 | AJ3: =AI3 -> 0 | AK3: =AJ3 -> 0 | AL3: =AK3 -> 0 | AM3: =AL3 -> 0 | ... AY3: =AX3 -> 0
A4: gasoline vehicle | B4: 0 | C4: 0 | D4: 0 | E4: 0 | F4: 0 | G4: 0 | H4: 0 | I4: 0 | J4: 0 | K4: 0 | L4: 0 | M4: 0 | N4: 0 | O4: 0 | P4: 0 | Q4: 0 | R4: 0 | S4: 0 | T4: 0 | U4: 0 | V4: 0 | W4: 0 | X4: 0 | Y4: 0 | Z4: 0 | AA4: 0 | AB4: 0 | AC4: 0 | AD4: 0 | AE4: 0 | AF4: =AE4 -> 0 | AG4: =AF4 -> 0 | AH4: =AG4 -> 0 | AI4: =AH4 -> 0 | AJ4: =AI4 -> 0 | AK4: =AJ4 -> 0 | AL4: =AK4 -> 0 | AM4: =AL4 -> 0 | ... AY4: =AX4 -> 0
A5: diesel vehicle | B5: =Extrapolations!Q6 -> 0.00057245969 | C5: =Extrapolations!R6 -> 0.00057245969 | D5: =Extrapolations!S6 -> 0.00057245969 | E5: =Extrapolations!T6 -> 0.00057245969 | F5: =Extrapolations!U6 -> 0.00057245969 | G5: =Extrapolations!V6 -> 0.00057245969 | H5: =Extrapolations!W6 -> 0.00057245969 | I5: =Extrapolations!X6 -> 0.00057245969 | ... AE5: =Extrapolations!AT6 -> 0.00057245969 | AF5: =AE5 -> 0.00057245969 | AG5: =AF5 -> 0.00057245969 | AH5: =AG5 -> 0.00057245969 | AI5: =AH5 -> 0.00057245969 | AJ5: =AI5 -> 0.00057245969 | AK5: =AJ5 -> 0.00057245969 | AL5: =AK5 -> 0.00057245969 | AM5: =AL5 -> 0.00057245969 | ... AY5: =AX5 -> 0.00057245969
A6: plugin hybrid vehicle | B6: 0 | C6: 0 | D6: 0 | E6: 0 | F6: 0 | G6: 0 | H6: 0 | I6: 0 | J6: 0 | K6: 0 | L6: 0 | M6: 0 | N6: 0 | O6: 0 | P6: 0 | Q6: 0 | R6: 0 | S6: 0 | T6: 0 | U6: 0 | V6: 0 | W6: 0 | X6: 0 | Y6: 0 | Z6: 0 | AA6: 0 | AB6: 0 | AC6: 0 | AD6: 0 | AE6: 0 | AF6: =AE6 -> 0 | AG6: =AF6 -> 0 | AH6: =AG6 -> 0 | AI6: =AH6 -> 0 | AJ6: =AI6 -> 0 | AK6: =AJ6 -> 0 | AL6: =AK6 -> 0 | AM6: =AL6 -> 0 | ... AY6: =AX6 -> 0
A7: LPG vehicle | B7: 0 | C7: 0 | D7: 0 | E7: 0 | F7: 0 | G7: 0 | H7: 0 | I7: 0 | J7: 0 | K7: 0 | L7: 0 | M7: 0 | N7: 0 | O7: 0 | P7: 0 | Q7: 0 | R7: 0 | S7: 0 | T7: 0 | U7: 0 | V7: 0 | W7: 0 | X7: 0 | Y7: 0 | Z7: 0 | AA7: 0 | AB7: 0 | AC7: 0 | AD7: 0 | AE7: 0 | AF7: =AE7 -> 0 | AG7: =AF7 -> 0 | AH7: =AG7 -> 0 | AI7: =AH7 -> 0 | AJ7: =AI7 -> 0 | AK7: =AJ7 -> 0 | AL7: =AK7 -> 0 | AM7: =AL7 -> 0 | ... AY7: =AX7 -> 0
A8: hydrogen vehicle | B8: =B$5*Calculations!$B$27 -> 0.0017173791 | C8: =C$5*Calculations!$B$27 -> 0.0017173791 | D8: =D$5*Calculations!$B$27 -> 0.0017173791 | E8: =E$5*Calculations!$B$27 -> 0.0017173791 | F8: =F$5*Calculations!$B$27 -> 0.0017173791 | G8: =G$5*Calculations!$B$27 -> 0.0017173791 | H8: =H$5*Calculations!$B$27 -> 0.0017173791 | I8: =I$5*Calculations!$B$27 -> 0.0017173791 | ... AE8: =AE$5*Calculations!$B$27 -> 0.0017173791 | AF8: =AE8 -> 0.0017173791 | AG8: =AF8 -> 0.0017173791 | AH8: =AG8 -> 0.0017173791 | AI8: =AH8 -> 0.0017173791 | AJ8: =AI8 -> 0.0017173791 | AK8: =AJ8 -> 0.0017173791 | AL8: =AK8 -> 0.0017173791 | AM8: =AL8 -> 0.0017173791 | ... AY8: =AX8 -> 0.0017173791

Sheet BHNVFEAL-aircraft-frgt
A1: Fuel Economy ((thing*miles)/BTU) | B1: 2021 | C1: 2022 | D1: 2023 | E1: 2024 | F1: 2025 | G1: 2026 | H1: 2027 | I1: 2028 | J1: 2029 | K1: 2030 | L1: 2031 | M1: 2032 | N1: 2033 | O1: 2034 | P1: 2035 | Q1: 2036 | R1: 2037 | S1: 2038 | T1: 2039 | U1: 2040 | V1: 2041 | W1: 2042 | X1: 2043 | Y1: 2044 | Z1: 2045 | AA1: 2046 | AB1: 2047 | AC1: 2048 | AD1: 2049 | AE1: 2050 | AF1: 2051 | AG1: 2052 | AH1: 2053 | AI1: 2054 | AJ1: 2055 | AK1: 2056 | AL1: 2057 | AM1: 2058 | AN1: 2059 | AO1: 2060 | AP1: 2061 | AQ1: 2062 | AR1: 2063 | AS1: 2064 | AT1: 2065 | AU1: 2066 | AV1: 2067 | AW1: 2068 | AX1: 2069 | AY1: 2070
A2: battery electric vehicle | B2: =B$5/(1-'Other Values'!$B$3) -> 0.00011722254 | C2: =C$5/(1-'Other Values'!$B$3) -> 0.00011863657 | D2: =D$5/(1-'Other Values'!$B$3) -> 0.00012005059 | E2: =E$5/(1-'Other Values'!$B$3) -> 0.00012146461 | F2: =F$5/(1-'Other Values'!$B$3) -> 0.00012287863 | G2: =G$5/(1-'Other Values'!$B$3) -> 0.00012429265 | H2: =H$5/(1-'Other Values'!$B$3) -> 0.00012570667 | I2: =I$5/(1-'Other Values'!$B$3) -> 0.0001271207 | ... AE2: =AE$5/(1-'Other Values'!$B$3) -> 0.00015825849 | AF2: =AE2 -> 0.00015825849 | AG2: =AF2 -> 0.00015825849 | AH2: =AG2 -> 0.00015825849 | AI2: =AH2 -> 0.00015825849 | AJ2: =AI2 -> 0.00015825849 | AK2: =AJ2 -> 0.00015825849 | AL2: =AK2 -> 0.00015825849 | AM2: =AL2 -> 0.00015825849 | ... AY2: =AX2 -> 0.00015825849
A3: natural gas vehicle | B3: 0 | C3: 0 | D3: 0 | E3: 0 | F3: 0 | G3: 0 | H3: 0 | I3: 0 | J3: 0 | K3: 0 | L3: 0 | M3: 0 | N3: 0 | O3: 0 | P3: 0 | Q3: 0 | R3: 0 | S3: 0 | T3: 0 | U3: 0 | V3: 0 | W3: 0 | X3: 0 | Y3: 0 | Z3: 0 | AA3: 0 | AB3: 0 | AC3: 0 | AD3: 0 | AE3: 0 | AF3: =AE3 -> 0 | AG3: =AF3 -> 0 | AH3: =AG3 -> 0 | AI3: =AH3 -> 0 | AJ3: =AI3 -> 0 | AK3: =AJ3 -> 0 | AL3: =AK3 -> 0 | AM3: =AL3 -> 0 | ... AY3: =AX3 -> 0
A4: gasoline vehicle | B4: 0 | C4: 0 | D4: 0 | E4: 0 | F4: 0 | G4: 0 | H4: 0 | I4: 0 | J4: 0 | K4: 0 | L4: 0 | M4: 0 | N4: 0 | O4: 0 | P4: 0 | Q4: 0 | R4: 0 | S4: 0 | T4: 0 | U4: 0 | V4: 0 | W4: 0 | X4: 0 | Y4: 0 | Z4: 0 | AA4: 0 | AB4: 0 | AC4: 0 | AD4: 0 | AE4: 0 | AF4: =AE4 -> 0 | AG4: =AF4 -> 0 | AH4: =AG4 -> 0 | AI4: =AH4 -> 0 | AJ4: =AI4 -> 0 | AK4: =AJ4 -> 0 | AL4: =AK4 -> 0 | AM4: =AL4 -> 0 | ... AY4: =AX4 -> 0
A5: diesel vehicle | B5: =Extrapolations!Q7 -> 3.6478441e-05 | C5: =Extrapolations!R7 -> 3.691847e-05 | D5: =Extrapolations!S7 -> 3.7358499e-05 | E5: =Extrapolations!T7 -> 3.7798527e-05 | F5: =Extrapolations!U7 -> 3.8238556e-05 | G5: =Extrapolations!V7 -> 3.8678585e-05 | H5: =Extrapolations!W7 -> 3.9118614e-05 | I5: =Extrapolations!X7 -> 3.9558643e-05 | ... AE5: =Extrapolations!AT7 -> 4.9248402e-05 | AF5: =AE5 -> 4.9248402e-05 | AG5: =AF5 -> 4.9248402e-05 | AH5: =AG5 -> 4.9248402e-05 | AI5: =AH5 -> 4.9248402e-05 | AJ5: =AI5 -> 4.9248402e-05 | AK5: =AJ5 -> 4.9248402e-05 | AL5: =AK5 -> 4.9248402e-05 | AM5: =AL5 -> 4.9248402e-05 | ... AY5: =AX5 -> 4.9248402e-05
A6: plugin hybrid vehicle | B6: 0 | C6: 0 | D6: 0 | E6: 0 | F6: 0 | G6: 0 | H6: 0 | I6: 0 | J6: 0 | K6: 0 | L6: 0 | M6: 0 | N6: 0 | O6: 0 | P6: 0 | Q6: 0 | R6: 0 | S6: 0 | T6: 0 | U6: 0 | V6: 0 | W6: 0 | X6: 0 | Y6: 0 | Z6: 0 | AA6: 0 | AB6: 0 | AC6: 0 | AD6: 0 | AE6: 0 | AF6: =AE6 -> 0 | AG6: =AF6 -> 0 | AH6: =AG6 -> 0 | AI6: =AH6 -> 0 | AJ6: =AI6 -> 0 | AK6: =AJ6 -> 0 | AL6: =AK6 -> 0 | AM6: =AL6 -> 0 | ... AY6: =AX6 -> 0
A7: LPG vehicle | B7: 0 | C7: 0 | D7: 0 | E7: 0 | F7: 0 | G7: 0 | H7: 0 | I7: 0 | J7: 0 | K7: 0 | L7: 0 | M7: 0 | N7: 0 | O7: 0 | P7: 0 | Q7: 0 | R7: 0 | S7: 0 | T7: 0 | U7: 0 | V7: 0 | W7: 0 | X7: 0 | Y7: 0 | Z7: 0 | AA7: 0 | AB7: 0 | AC7: 0 | AD7: 0 | AE7: 0 | AF7: =AE7 -> 0 | AG7: =AF7 -> 0 | AH7: =AG7 -> 0 | AI7: =AH7 -> 0 | AJ7: =AI7 -> 0 | AK7: =AJ7 -> 0 | AL7: =AK7 -> 0 | AM7: =AL7 -> 0 | ... AY7: =AX7 -> 0
A8: hydrogen vehicle | B8: =B$5*Calculations!$B$27 -> 0.00010943532 | C8: =C$5*Calculations!$B$27 -> 0.00011075541 | D8: =D$5*Calculations!$B$27 -> 0.0001120755 | E8: =E$5*Calculations!$B$27 -> 0.00011339558 | F8: =F$5*Calculations!$B$27 -> 0.00011471567 | G8: =G$5*Calculations!$B$27 -> 0.00011603576 | H8: =H$5*Calculations!$B$27 -> 0.00011735584 | I8: =I$5*Calculations!$B$27 -> 0.00011867593 | ... AE8: =AE$5*Calculations!$B$27 -> 0.00014774521 | AF8: =AE8 -> 0.00014774521 | AG8: =AF8 -> 0.00014774521 | AH8: =AG8 -> 0.00014774521 | AI8: =AH8 -> 0.00014774521 | AJ8: =AI8 -> 0.00014774521 | AK8: =AJ8 -> 0.00014774521 | AL8: =AK8 -> 0.00014774521 | AM8: =AL8 -> 0.00014774521 | ... AY8: =AX8 -> 0.00014774521

Sheet BHNVFEAL-rail-psgr
A1: Fuel Economy ((thing*miles)/BTU) | B1: 2021 | C1: 2022 | D1: 2023 | E1: 2024 | F1: 2025 | G1: 2026 | H1: 2027 | I1: 2028 | J1: 2029 | K1: 2030 | L1: 2031 | M1: 2032 | N1: 2033 | O1: 2034 | P1: 2035 | Q1: 2036 | R1: 2037 | S1: 2038 | T1: 2039 | U1: 2040 | V1: 2041 | W1: 2042 | X1: 2043 | Y1: 2044 | Z1: 2045 | AA1: 2046 | AB1: 2047 | AC1: 2048 | AD1: 2049 | AE1: 2050 | AF1: 2051 | AG1: 2052 | AH1: 2053 | AI1: 2054 | AJ1: 2055 | AK1: 2056 | AL1: 2057 | AM1: 2058 | AN1: 2059 | AO1: 2060 | AP1: 2061 | AQ1: 2062 | AR1: 2063 | AS1: 2064 | AT1: 2065 | AU1: 2066 | AV1: 2067 | AW1: 2068 | AX1: 2069 | AY1: 2070
A2: battery electric vehicle | B2: =Extrapolations!G9 -> 0.00075686214 | C2: =Extrapolations!H9 -> 0.00075686214 | D2: =Extrapolations!I9 -> 0.00075686214 | E2: =Extrapolations!J9 -> 0.00075686214 | F2: =Extrapolations!K9 -> 0.00075686214 | G2: =Extrapolations!L9 -> 0.00075686214 | H2: =Extrapolations!M9 -> 0.00075686214 | I2: =Extrapolations!N9 -> 0.00075686214 | ... AE2: =Extrapolations!AJ9 -> 0.00075686214 | AF2: =AE2 -> 0.00075686214 | AG2: =AF2 -> 0.00075686214 | AH2: =AG2 -> 0.00075686214 | AI2: =AH2 -> 0.00075686214 | AJ2: =AI2 -> 0.00075686214 | AK2: =AJ2 -> 0.00075686214 | AL2: =AK2 -> 0.00075686214 | AM2: =AL2 -> 0.00075686214 | ... AY2: =AX2 -> 0.00075686214
A3: natural gas vehicle | B3: 0 | C3: 0 | D3: 0 | E3: 0 | F3: 0 | G3: 0 | H3: 0 | I3: 0 | J3: 0 | K3: 0 | L3: 0 | M3: 0 | N3: 0 | O3: 0 | P3: 0 | Q3: 0 | R3: 0 | S3: 0 | T3: 0 | U3: 0 | V3: 0 | W3: 0 | X3: 0 | Y3: 0 | Z3: 0 | AA3: 0 | AB3: 0 | AC3: 0 | AD3: 0 | AE3: 0 | AF3: =AE3 -> 0 | AG3: =AF3 -> 0 | AH3: =AG3 -> 0 | AI3: =AH3 -> 0 | AJ3: =AI3 -> 0 | AK3: =AJ3 -> 0 | AL3: =AK3 -> 0 | AM3: =AL3 -> 0 | ... AY3: =AX3 -> 0
A4: gasoline vehicle | B4: 0 | C4: 0 | D4: 0 | E4: 0 | F4: 0 | G4: 0 | H4: 0 | I4: 0 | J4: 0 | K4: 0 | L4: 0 | M4: 0 | N4: 0 | O4: 0 | P4: 0 | Q4: 0 | R4: 0 | S4: 0 | T4: 0 | U4: 0 | V4: 0 | W4: 0 | X4: 0 | Y4: 0 | Z4: 0 | AA4: 0 | AB4: 0 | AC4: 0 | AD4: 0 | AE4: 0 | AF4: =AE4 -> 0 | AG4: =AF4 -> 0 | AH4: =AG4 -> 0 | AI4: =AH4 -> 0 | AJ4: =AI4 -> 0 | AK4: =AJ4 -> 0 | AL4: =AK4 -> 0 | AM4: =AL4 -> 0 | ... AY4: =AX4 -> 0
A5: diesel vehicle | B5: =Extrapolations!G8 -> 7.1745362e-05 | C5: =Extrapolations!H8 -> 7.1745362e-05 | D5: =Extrapolations!I8 -> 7.1745362e-05 | E5: =Extrapolations!J8 -> 7.1745362e-05 | F5: =Extrapolations!K8 -> 7.1745362e-05 | G5: =Extrapolations!L8 -> 7.1745362e-05 | H5: =Extrapolations!M8 -> 7.1745362e-05 | I5: =Extrapolations!N8 -> 7.1745362e-05 | ... AE5: =Extrapolations!AJ8 -> 7.1745362e-05 | AF5: =AE5 -> 7.1745362e-05 | AG5: =AF5 -> 7.1745362e-05 | AH5: =AG5 -> 7.1745362e-05 | AI5: =AH5 -> 7.1745362e-05 | AJ5: =AI5 -> 7.1745362e-05 | AK5: =AJ5 -> 7.1745362e-05 | AL5: =AK5 -> 7.1745362e-05 | AM5: =AL5 -> 7.1745362e-05 | ... AY5: =AX5 -> 7.1745362e-05
A6: plugin hybrid vehicle | B6: 0 | C6: 0 | D6: 0 | E6: 0 | F6: 0 | G6: 0 | H6: 0 | I6: 0 | J6: 0 | K6: 0 | L6: 0 | M6: 0 | N6: 0 | O6: 0 | P6: 0 | Q6: 0 | R6: 0 | S6: 0 | T6: 0 | U6: 0 | V6: 0 | W6: 0 | X6: 0 | Y6: 0 | Z6: 0 | AA6: 0 | AB6: 0 | AC6: 0 | AD6: 0 | AE6: 0 | AF6: =AE6 -> 0 | AG6: =AF6 -> 0 | AH6: =AG6 -> 0 | AI6: =AH6 -> 0 | AJ6: =AI6 -> 0 | AK6: =AJ6 -> 0 | AL6: =AK6 -> 0 | AM6: =AL6 -> 0 | ... AY6: =AX6 -> 0
A7: LPG vehicle | B7: 0 | C7: 0 | D7: 0 | E7: 0 | F7: 0 | G7: 0 | H7: 0 | I7: 0 | J7: 0 | K7: 0 | L7: 0 | M7: 0 | N7: 0 | O7: 0 | P7: 0 | Q7: 0 | R7: 0 | S7: 0 | T7: 0 | U7: 0 | V7: 0 | W7: 0 | X7: 0 | Y7: 0 | Z7: 0 | AA7: 0 | AB7: 0 | AC7: 0 | AD7: 0 | AE7: 0 | AF7: =AE7 -> 0 | AG7: =AF7 -> 0 | AH7: =AG7 -> 0 | AI7: =AH7 -> 0 | AJ7: =AI7 -> 0 | AK7: =AJ7 -> 0 | AL7: =AK7 -> 0 | AM7: =AL7 -> 0 | ... AY7: =AX7 -> 0
A8: hydrogen vehicle | B8: =B$5*Calculations!$B$27 -> 0.00021523609 | C8: =C$5*Calculations!$B$27 -> 0.00021523609 | D8: =D$5*Calculations!$B$27 -> 0.00021523609 | E8: =E$5*Calculations!$B$27 -> 0.00021523609 | F8: =F$5*Calculations!$B$27 -> 0.00021523609 | G8: =G$5*Calculations!$B$27 -> 0.00021523609 | H8: =H$5*Calculations!$B$27 -> 0.00021523609 | I8: =I$5*Calculations!$B$27 -> 0.00021523609 | ... AE8: =AE$5*Calculations!$B$27 -> 0.00021523609 | AF8: =AE8 -> 0.00021523609 | AG8: =AF8 -> 0.00021523609 | AH8: =AG8 -> 0.00021523609 | AI8: =AH8 -> 0.00021523609 | AJ8: =AI8 -> 0.00021523609 | AK8: =AJ8 -> 0.00021523609 | AL8: =AK8 -> 0.00021523609 | AM8: =AL8 -> 0.00021523609 | ... AY8: =AX8 -> 0.00021523609

Sheet BHNVFEAL-rail-frgt
A1: Fuel Economy ((thing*miles)/BTU) | B1: 2021 | C1: 2022 | D1: 2023 | E1: 2024 | F1: 2025 | G1: 2026 | H1: 2027 | I1: 2028 | J1: 2029 | K1: 2030 | L1: 2031 | M1: 2032 | N1: 2033 | O1: 2034 | P1: 2035 | Q1: 2036 | R1: 2037 | S1: 2038 | T1: 2039 | U1: 2040 | V1: 2041 | W1: 2042 | X1: 2043 | Y1: 2044 | Z1: 2045 | AA1: 2046 | AB1: 2047 | AC1: 2048 | AD1: 2049 | AE1: 2050 | AF1: 2051 | AG1: 2052 | AH1: 2053 | AI1: 2054 | AJ1: 2055 | AK1: 2056 | AL1: 2057 | AM1: 2058 | AN1: 2059 | AO1: 2060 | AP1: 2061 | AQ1: 2062 | AR1: 2063 | AS1: 2064 | AT1: 2065 | AU1: 2066 | AV1: 2067 | AW1: 2068 | AX1: 2069 | AY1: 2070
A2: battery electric vehicle | B2: =B$5/(1-'Other Values'!$B$3) -> 0.010577901 | C2: =C$5/(1-'Other Values'!$B$3) -> 0.010586382 | D2: =D$5/(1-'Other Values'!$B$3) -> 0.010594863 | E2: =E$5/(1-'Other Values'!$B$3) -> 0.010603344 | F2: =F$5/(1-'Other Values'!$B$3) -> 0.010611825 | G2: =G$5/(1-'Other Values'!$B$3) -> 0.010620306 | H2: =H$5/(1-'Other Values'!$B$3) -> 0.010628788 | I2: =I$5/(1-'Other Values'!$B$3) -> 0.010637269 | ... AE2: =AE$5/(1-'Other Values'!$B$3) -> 0.010823854 | AF2: =AE2 -> 0.010823854 | AG2: =AF2 -> 0.010823854 | AH2: =AG2 -> 0.010823854 | AI2: =AH2 -> 0.010823854 | AJ2: =AI2 -> 0.010823854 | AK2: =AJ2 -> 0.010823854 | AL2: =AK2 -> 0.010823854 | AM2: =AL2 -> 0.010823854 | ... AY2: =AX2 -> 0.010823854
A3: natural gas vehicle | B3: 0 | C3: 0 | D3: 0 | E3: 0 | F3: 0 | G3: 0 | H3: 0 | I3: 0 | J3: 0 | K3: 0 | L3: 0 | M3: 0 | N3: 0 | O3: 0 | P3: 0 | Q3: 0 | R3: 0 | S3: 0 | T3: 0 | U3: 0 | V3: 0 | W3: 0 | X3: 0 | Y3: 0 | Z3: 0 | AA3: 0 | AB3: 0 | AC3: 0 | AD3: 0 | AE3: 0 | AF3: =AE3 -> 0 | AG3: =AF3 -> 0 | AH3: =AG3 -> 0 | AI3: =AH3 -> 0 | AJ3: =AI3 -> 0 | AK3: =AJ3 -> 0 | AL3: =AK3 -> 0 | AM3: =AL3 -> 0 | ... AY3: =AX3 -> 0
