Workbook
Name A.a.Scenario.EcoGrowth: [1]Control!$E$72
Name A.a.Scenario.Population: [1]Control!$E$71
Name Constants.Density.JetFuel: [1]Constants!$C$37
Name Constants.GCV.ATF: [1]Constants!$C$18
Name Constants.GCV.Diesel: [1]Constants!$C$17
Name Constants.GCV.NaturalGasProduced: [1]Constants!$C$21
Name Conversion.Barril.to.litres: [1]Conversions!$E$72
Name Conversion.to.annual.energy: [1]Conversions!$E$62
Name Conversion.to.average.power: [1]Conversions!$E$61
Name Conversion.to.energy.per.second: [1]Conversions!$E$63
Name Conversion.UKgallons.to.litres: [1]Conversions!$E$69
Name Conversions.Area.m2: [1]Conversions!$E$50:$E$55
Name Conversions.Area.Units: [1]Conversions!$B$50:$B$55
Name Conversions.Energy.Joules: [1]Conversions!$E$5:$E$26
Name Conversions.Energy.Units: [1]Conversions!$B$5:$B$26
Name Conversions.Money.MXP: [1]Conversions!$F$78:$F$90
Name Conversions.Money.Units: [1]Conversions!$B$78:$B$90
Name Conversions.Power.Units: [1]Conversions!$B$31:$B$36
Name Conversions.Power.Watts: [1]Conversions!$E$31:$E$36
Name Conversions.Time.Seconds: [1]Conversions!$E$41:$E$45
Name Conversions.Time.Units: [1]Conversions!$B$41:$B$45
Name Cost.FinanceCostTable: '[1]Global assumptions'!$B$41:$I$90
Name discount_factors: '[1]Global assumptions'!$D$33:$K$33
Name Discount_rate: '[1]Global assumptions'!$C$32
Name EF.BlastFurnaceGas.CO2: [1]Constants!$F$11
Name EF.Diesel.CH4: [1]Constants!$G$9
Name EF.Diesel.CO2: [1]Constants!$F$9
Name EF.Diesel.N2O: [1]Constants!$H$9
Name EF.IndustrialCoal.CH4: [1]Constants!$G$8
Name EF.IndustrialCoal.CO2: [1]Constants!$F$8
Name EF.IndustrialCoal.N2O: [1]Constants!$H$8
Name EF.NaturalGas.CH4: [1]Constants!$G$10
Name EF.NaturalGas.CO2: [1]Constants!$F$10
Name EF.NaturalGas.N2O: [1]Constants!$H$10
Name Fraction_coal: [2]About!#REF!
Name gal_per_barrel: [3]About!$A$63
Name GBP: [1]Conversions!$E$90
Name Global.MEXIncidentSolarEnergy: '[1]Global assumptions'!$D$26
Name GWP.CH4: [1]Constants!$K$9
Name GWP.N2O: [1]Constants!$K$10
Name I.a.Scenario: [1]Control!$E$6
Name I.b.1.Scenario: [1]Control!$E$8
Name II.a.Scenario: [1]Control!$E$5
Name III.a.Scenario: [1]Control!$E$10
Name III.b.Scenario: [1]Control!$E$11
Name III.c.Scenario: [1]Control!$E$12
Name III.d.Scenario: [1]Control!$E$13
Name III.e.Scenario: [1]Control!$E$14
Name IV.a.Scenario: [1]Control!$E$15
Name IX.a.Scenario.Comfort: [1]Control!#REF!
Name IX.a.Scenario.HHSize: [1]Control!#REF!
Name IX.a.Scenario.Insulation: [1]Control!$E$43
Name IX.a.Scenario.Technology: [1]Control!$E$44
Name IX.c.Scenario.Technology: [1]Control!$E$55
Name MGBP: [1]Conversions!$E$85
Name MMXP: [1]Conversions!$E$80
Name MUSD: [1]Conversions!$E$88
Name MXP: [1]Conversions!$E$82
Name Peak_Electricity_Generation_Capacity: '[1]Intermediate output'!$AY$132:$BG$132
Name Percent_rural: [2]About!#REF!

Sheet About
A1: BIFUbC BAU Industrial Fuel Use before CCS
A3: Sources: | B3: Energy consumption (agriculture and industry)
B4: Energy Ministry (SENER)
B5: National Energy Balance 2023
B6: https://www.gob.mx/cms/uploads/attachment/file/977268/Balance_Nacional_de_Energ_a_2023.FINAL06.02.2025.1.pdf
B7: Cuadro A.18 Agriculture
B8: Cuadro A.15 Industry
B9: Energy consumption by end use (residential, commercial & public)
B10: National Council of Humanities, Sciences and Technologies (Conahcyt)
B11: Energy futures for Mexico by 2050 The path to a just and sustainable energy transition
B12: https://conahcyt.mx/wp-content/uploads/pronaces/micrositios/energia_y_cambio_climatico/energia/cuadernos_tematicos/Cuaderno_9.pdf
B16: EPS V4.0
B17: agriculture and forestry 01T03
B18: coal mining 05
... B40: water and waste 36T39
A44: Unit conversion
A45: BTU/PJ | B45: =D46/D47 -> 9.4786714e+11
B46: 1 | C46: BEP | D46: 5414093.9 | E46: BTU
B47: 1 | C47: BEP | D47: 5.71187e-06 | E47: PJ
A48: Source: https://dof.gob.mx/nota_detalle.php?codigo=5278970&fecha=23/11/2012#gsc.tab=0

Sheet A.18
C2: 2013 | D2: 2014 | E2: 2015 | F2: 2016 | G2: 2017 | H2: 2018 | I2: 2019 | J2: 2020 | K2: 2021 | L2: 2022 | M2: 2023
B3: Gas licuado | C3: 6.03 | D3: 6.08 | E3: 6.01 | F3: 5.12 | G3: 4.96 | H3: 4.76 | I3: 3.53 | J3: 5.88 | K3: 4.33 | L3: 4.68 | M3: 4.21
B4: Queroseno | C4: 0.01 | D4: 0 | E4: 0 | F4: 0 | G4: 0 | H4: 0 | I4: 0 | J4: 0 | K4: 0 | L4: 0 | M4: 0
B5: Diésel | C5: 115.55 | D5: 117.28 | E5: 136.84 | F5: 134.31 | G5: 135.28 | H5: 139.95 | I5: 141.1 | J5: 127.34 | K5: 125.74 | L5: 130.11 | M5: 123.53
B6: Electricidad | C6: 37.03 | D6: 36.12 | E6: 36.24 | F6: 40.81 | G6: 41.66 | H6: 44.56 | I6: 47.27 | J6: 52.79 | K6: 48.63 | L6: 53.35 | M6: 55.48

Sheet A.15
B1: 2013 | C1: 2014 | D1: 2015 | E1: 2016 | F1: 2017 | G1: 2018 | H1: 2019 | I1: 2020 | J1: 2021 | K1: 2022 | L1: 2023
A2: Total Sector Industrial | B2: 1599 | C2: 1553.17 | D2: 1601.84 | E2: 1680.74 | F2: 1876.65 | G2: 1680.77 | H2: 1589.45 | I2: 1418.05 | J2: 1152.67 | K2: 1476.99 | L2: 1238.96
A3: Coque total | B3: 176.27 | C3: 183.02 | D3: 191.08 | E3: 205.65 | F3: 206.11 | G3: 180.15 | H3: 173.8 | I3: 161.26 | J3: 175.44 | K3: 176.54 | L3: 183.83
A4: Coque de carbón | B4: 65.13 | C4: 68.7 | D4: 58.64 | E4: 63.52 | F4: 63.75 | G4: 47.43 | H4: 57.03 | I4: 44.56 | J4: 48.39 | K4: 42.73 | L4: 42.58
A5: Coque de petróleo | B5: 111.15 | C5: 114.32 | D5: 132.44 | E5: 142.14 | F5: 142.36 | G5: 132.72 | H5: 116.77 | I5: 116.7 | J5: 127.05 | K5: 133.82 | L5: 141.25
A6: Total de petrolíferos | B6: 134.71 | C6: 118.83 | D6: 139.94 | E6: 163.09 | F6: 132.69 | G6: 113.09 | H6: 104.72 | I6: 124.55 | J6: 108.59 | K6: 121.5 | L6: 114.23
A7: Gas licuado | B7: 43.97 | C7: 42.48 | D7: 42.26 | E7: 46.21 | F7: 45.02 | G7: 45.9 | H7: 29.29 | I7: 49.15 | J7: 38.45 | K7: 45.02 | L7: 41.82
A8: Gasolinas y naftas | B8: 0.85 | C8: 1.05 | D8: 0.99 | E8: 1.15 | F8: 1.17 | G8: 1.18 | H8: 1.29 | I8: 1.47 | J8: 1.47 | K8: 1.34 | L8: 1.34
A9: Querosenos | B9: 0 | C9: 0 | D9: 0 | E9: 0 | F9: 0 | G9: 0 | H9: 0 | I9: 0 | J9: 0 | K9: 0 | L9: 0
A10: Diesel | B10: 64.53 | C10: 60.37 | D10: 74.63 | E10: 83.16 | F10: 57.54 | G10: 57.31 | H10: 60.55 | I10: 62.21 | J10: 54.19 | K10: 62.11 | L10: 57.58
A11: Combustóleo | B11: 25.36 | C11: 14.93 | D11: 22.05 | E11: 32.57 | F11: 28.97 | G11: 8.71 | H11: 13.58 | I11: 11.72 | J11: 14.48 | K11: 13.03 | L11: 13.49
A12: Productos no energéticos | B12: 0 | C12: 0 | D12: 0 | E12: 0 | F12: 0 | G12: 0 | H12: 0 | I12: 0 | J12: 0 | K12: 0 | L12: 0
A13: Gas seco | B13: 593.19 | C13: 603.28 | D13: 608.62 | E13: 647.99 | F13: 683.23 | G13: 538 | H13: 506.36 | I13: 438.81 | J13: 376.34 | K13: 385.83 | L13: 395.57
... A17: Solar | B17: 0.43 | C17: 0.42 | D17: 0.5 | E17: 0.56 | F17: 0.6 | G17: 0.67 | H17: 0.74 | I17: 1.3 | J17: 1.29 | K17: 1.14 | L17: 1.44
B18: 2013 | C18: 2014 | D18: 2015 | E18: 2016 | F18: 2017 | G18: 2018 | H18: 2019 | I18: 2020 | J18: 2021 | K18: 2022 | L18: 2023
A19: 212.- Minería de minerales metálicos y no metálicos, excepto petróleo y gas
A20: Total | B20: 61.48 | C20: 55.97 | D20: 62.81 | E20: 66.4 | F20: 71.3 | G20: 71.61 | H20: 74.99 | I20: 79.84 | J20: 67.66 | K20: 68.15 | L20: 66.23
A21: Coque total | B21: 0 | C21: 0 | D21: 0 | E21: 0 | F21: 0 | G21: 0 | H21: 0 | I21: 0 | J21: 0 | K21: 0 | L21: 0
A22: Coque de carbón | B22: 0 | C22: 0 | D22: 0 | E22: 0 | F22: 0 | G22: 0 | H22: 0 | I22: 0 | J22: 0 | K22: 0 | L22: 0
A23: Coque de petróleo | B23: 0 | C23: 0 | D23: 0 | E23: 0 | F23: 0 | G23: 0 | H23: 0 | I23: 0 | J23: 0 | K23: 0 | L23: 0
A24: Total de petrolíferos | B24: 15.91 | C24: 14.9 | D24: 14.6 | E24: 15.11 | F24: 16.31 | G24: 13.1 | H24: 15.78 | I24: 21.33 | J24: 16.32 | K24: 16.12 | L24: 15.51
A25: Gas licuado | B25: 9.32 | C25: 8.09 | D25: 7.02 | E25: 7.44 | F25: 8.44 | G25: 8.08 | H25: 7.04 | I25: 15.97 | J25: 5.56 | K25: 5.5 | L25: 5.35
A26: Gasolinas y naftas | B26: 0 | C26: 0 | D26: 0 | E26: 0 | F26: 0 | G26: 0 | H26: 0 | I26: 0 | J26: 0 | K26: 0 | L26: 0
A27: Querosenos | B27: 0 | C27: 0 | D27: 0 | E27: 0 | F27: 0 | G27: 0 | H27: 0 | I27: 0 | J27: 0 | K27: 0 | L27: 0
A28: Diesel | B28: 4.37 | C28: 4.59 | D28: 5.5 | E28: 5.65 | F28: 5.96 | G28: 4.45 | H28: 6.88 | I28: 3.56 | J28: 9.54 | K28: 9.41 | L28: 8.98
A29: Combustóleo | B29: 2.23 | C29: 2.22 | D29: 2.08 | E29: 2.02 | F29: 1.91 | G29: 0.57 | H29: 1.86 | I29: 1.81 | J29: 1.22 | K29: 1.21 | L29: 1.18
A30: Productos no energéticos | B30: 0 | C30: 0 | D30: 0 | E30: 0 | F30: 0 | G30: 0 | H30: 0 | I30: 0 | J30: 0 | K30: 0 | L30: 0
A31: Gas seco | B31: 9.27 | C31: 6.72 | D31: 10.1 | E31: 10.66 | F31: 11.84 | G31: 12.3 | H31: 12.94 | I31: 11.21 | J31: 9.54 | K31: 9.67 | L31: 9.43
... A35: Solar | B35: 0 | C35: 0 | D35: 0 | E35: 0 | F35: 0 | G35: 0 | H35: 0 | I35: 0 | J35: 0 | K35: 0 | L35: 0
B36: 2013 | C36: 2014 | E36: 2015 | F36: 2016 | G36: 2017 | H36: 2018 | I36: 2019 | J36: 2020 | K36: 2021 | L36: 2022 | M36: 2023
A37: 236.- Edificación
A38: Total | B38: 12.72 | C38: 11.89 | D38: 13.83 | F38: 13.96 | G38: 13.18 | H38: 13.33 | I38: 13.44 | J38: 16.26 | K38: 116.17 | L38: 115.91 | M38: 122.39
A39: Coque total | B39: 0 | C39: 0 | D39: 0 | F39: 0 | G39: 0 | H39: 0 | I39: 0 | J39: 0 | K39: 107.74 | L39: 107.48 | M39: 113.64
A40: Coque de carbón | B40: 0 | C40: 0 | D40: 0 | F40: 0 | G40: 0 | H40: 0 | I40: 0 | J40: 0 | K40: 0 | L40: 0 | M40: 0
A41: Coque de petróleo | B41: 0 | C41: 0 | D41: 0 | F41: 0 | G41: 0 | H41: 0 | I41: 0 | J41: 0 | K41: 107.74 | L41: 107.48 | M41: 113.64
A42: Total de petrolíferos | B42: 10.95 | C42: 10.05 | D42: 11.96 | F42: 11.96 | G42: 11.18 | H42: 11.3 | I42: 11.38 | J42: 14.16 | K42: 5.62 | L42: 5.6 | M42: 5.77
A43: Gas licuado | B43: 0 | C43: 0 | D43: 0 | F43: 0 | G43: 0 | H43: 0 | I43: 0 | J43: 0 | K43: 0 | L43: 0 | M43: 0
A44: Gasolinas y naftas | B44: 0 | C44: 0 | D44: 0 | F44: 0 | G44: 0 | H44: 0 | I44: 0 | J44: 0 | K44: 0 | L44: 0 | M44: 0
A45: Querosenos | B45: 0 | C45: 0 | D45: 0 | F45: 0 | G45: 0 | H45: 0 | I45: 0 | J45: 0 | K45: 0 | L45: 0 | M45: 0
A46: Diésel | B46: 10.95 | C46: 10.05 | D46: 11.96 | F46: 11.96 | G46: 11.18 | H46: 11.3 | I46: 11.38 | J46: 14.16 | K46: 5.61 | L46: 5.6 | M46: 5.77
...

Sheet Esc
A1: Agropecuario
A2: PJ | B2: 2013 | C2: 2014 | D2: 2015 | E2: 2016 | F2: 2017 | G2: 2018 | H2: 2019 | I2: 2020 | J2: 2021 | K2: 2022 | L2: 2023 | M2: 2024 | N2: 2025 | O2: 2026 | P2: 2027 | Q2: 2028 | R2: 2029 | S2: 2030 | T2: 2031 | U2: 2032 | V2: 2033 | W2: 2034 | X2: 2035 | Y2: 2036 | Z2: 2037 | AA2: 2038 | AB2: 2039 | AC2: 2040 | AD2: 2041 | AE2: 2042 | AF2: 2043 | AG2: 2044 | AH2: 2045 | AI2: 2046 | AJ2: 2047 | AK2: 2048 | AL2: 2049 | AM2: 2050
A3: Carbón | B3: 0 | C3: 0 | D3: 0 | E3: 0 | F3: 0 | G3: 0 | H3: 0 | I3: 0 | J3: 0 | K3: 0 | L3: 0 | M3: 0 | N3: 0 | O3: 0 | P3: 0 | Q3: 0 | R3: 0 | S3: 0 | T3: 0 | U3: 0 | V3: 0 | W3: 0 | X3: 0 | Y3: 0 | Z3: 0 | AA3: 0 | AB3: 0 | AC3: 0 | AD3: 0 | AE3: 0 | AF3: 0 | AG3: 0 | AH3: 0 | AI3: 0 | AJ3: 0 | AK3: 0 | AL3: 0 | AM3: 0
A4: Petróleo | B4: 0 | C4: 0 | D4: 0 | E4: 0 | F4: 0 | G4: 0 | H4: 0 | I4: 0 | J4: 0 | K4: 0 | L4: 0 | M4: 0 | N4: 0 | O4: 0 | P4: 0 | Q4: 0 | R4: 0 | S4: 0 | T4: 0 | U4: 0 | V4: 0 | W4: 0 | X4: 0 | Y4: 0 | Z4: 0 | AA4: 0 | AB4: 0 | AC4: 0 | AD4: 0 | AE4: 0 | AF4: 0 | AG4: 0 | AH4: 0 | AI4: 0 | AJ4: 0 | AK4: 0 | AL4: 0 | AM4: 0
A5: Condensados | B5: 0 | C5: 0 | D5: 0 | E5: 0 | F5: 0 | G5: 0 | H5: 0 | I5: 0 | J5: 0 | K5: 0 | L5: 0 | M5: 0 | N5: 0 | O5: 0 | P5: 0 | Q5: 0 | R5: 0 | S5: 0 | T5: 0 | U5: 0 | V5: 0 | W5: 0 | X5: 0 | Y5: 0 | Z5: 0 | AA5: 0 | AB5: 0 | AC5: 0 | AD5: 0 | AE5: 0 | AF5: 0 | AG5: 0 | AH5: 0 | AI5: 0 | AJ5: 0 | AK5: 0 | AL5: 0 | AM5: 0
A6: Gas natural | B6: 0 | C6: 0 | D6: 0 | E6: 0 | F6: 0 | G6: 0 | H6: 0 | I6: 0 | J6: 0 | K6: 0 | L6: 0 | M6: 0 | N6: 0 | O6: 0 | P6: 0 | Q6: 0 | R6: 0 | S6: 0 | T6: 0 | U6: 0 | V6: 0 | W6: 0 | X6: 0 | Y6: 0 | Z6: 0 | AA6: 0 | AB6: 0 | AC6: 0 | AD6: 0 | AE6: 0 | AF6: 0 | AG6: 0 | AH6: 0 | AI6: 0 | AJ6: 0 | AK6: 0 | AL6: 0 | AM6: 0
A7: Nuclear | B7: 0 | C7: 0 | D7: 0 | E7: 0 | F7: 0 | G7: 0 | H7: 0 | I7: 0 | J7: 0 | K7: 0 | L7: 0 | M7: 0 | N7: 0 | O7: 0 | P7: 0 | Q7: 0 | R7: 0 | S7: 0 | T7: 0 | U7: 0 | V7: 0 | W7: 0 | X7: 0 | Y7: 0 | Z7: 0 | AA7: 0 | AB7: 0 | AC7: 0 | AD7: 0 | AE7: 0 | AF7: 0 | AG7: 0 | AH7: 0 | AI7: 0 | AJ7: 0 | AK7: 0 | AL7: 0 | AM7: 0
A8: Hidroenergía | B8: 0 | C8: 0 | D8: 0 | E8: 0 | F8: 0 | G8: 0 | H8: 0 | I8: 0 | J8: 0 | K8: 0 | L8: 0 | M8: 0 | N8: 0 | O8: 0 | P8: 0 | Q8: 0 | R8: 0 | S8: 0 | T8: 0 | U8: 0 | V8: 0 | W8: 0 | X8: 0 | Y8: 0 | Z8: 0 | AA8: 0 | AB8: 0 | AC8: 0 | AD8: 0 | AE8: 0 | AF8: 0 | AG8: 0 | AH8: 0 | AI8: 0 | AJ8: 0 | AK8: 0 | AL8: 0 | AM8: 0
A9: Radiación solar | B9: 0 | C9: 0 | D9: 0 | E9: 0 | F9: 0 | G9: 0 | H9: 0 | I9: 0 | J9: 0 | K9: 0 | L9: 0 | M9: 0 | N9: 0 | O9: 0 | P9: 0 | Q9: 0 | R9: 0 | S9: 0 | T9: 0 | U9: 0 | V9: 0 | W9: 0 | X9: 0 | Y9: 0 | Z9: 0 | AA9: 0 | AB9: 0 | AC9: 0 | AD9: 0 | AE9: 0 | AF9: 0 | AG9: 0 | AH9: 0 | AI9: 0 | AJ9: 0 | AK9: 0 | AL9: 0 | AM9: 0
A10: Energía eólica | B10: 0 | C10: 0 | D10: 0 | E10: 0 | F10: 0 | G10: 0 | H10: 0 | I10: 0 | J10: 0 | K10: 0 | L10: 0 | M10: 0 | N10: 0 | O10: 0 | P10: 0 | Q10: 0 | R10: 0 | S10: 0 | T10: 0 | U10: 0 | V10: 0 | W10: 0 | X10: 0 | Y10: 0 | Z10: 0 | AA10: 0 | AB10: 0 | AC10: 0 | AD10: 0 | AE10: 0 | AF10: 0 | AG10: 0 | AH10: 0 | AI10: 0 | AJ10: 0 | AK10: 0 | AL10: 0 | AM10: 0
A11: Geoenergía | B11: 0 | C11: 0 | D11: 0 | E11: 0 | F11: 0 | G11: 0 | H11: 0 | I11: 0 | J11: 0 | K11: 0 | L11: 0 | M11: 0 | N11: 0 | O11: 0 | P11: 0 | Q11: 0 | R11: 0 | S11: 0 | T11: 0 | U11: 0 | V11: 0 | W11: 0 | X11: 0 | Y11: 0 | Z11: 0 | AA11: 0 | AB11: 0 | AC11: 0 | AD11: 0 | AE11: 0 | AF11: 0 | AG11: 0 | AH11: 0 | AI11: 0 | AJ11: 0 | AK11: 0 | AL11: 0 | AM11: 0
A12: Bagazos | B12: 0 | C12: 0 | D12: 0 | E12: 0 | F12: 0 | G12: 0 | H12: 0 | I12: 0 | J12: 0 | K12: 0 | L12: 0 | M12: 0 | N12: 0 | O12: 0 | P12: 0 | Q12: 0 | R12: 0 | S12: 0 | T12: 0 | U12: 0 | V12: 0 | W12: 0 | X12: 0 | Y12: 0 | Z12: 0 | AA12: 0 | AB12: 0 | AC12: 0 | AD12: 0 | AE12: 0 | AF12: 0 | AG12: 0 | AH12: 0 | AI12: 0 | AJ12: 0 | AK12: 0 | AL12: 0 | AM12: 0
A13: Leña | B13: 0 | C13: 0 | D13: 0 | E13: 0 | F13: 0 | G13: 0 | H13: 0 | I13: 0 | J13: 0 | K13: 0 | L13: 0 | M13: 0 | N13: 0 | O13: 0 | P13: 0 | Q13: 0 | R13: 0 | S13: 0 | T13: 0 | U13: 0 | V13: 0 | W13: 0 | X13: 0 | Y13: 0 | Z13: 0 | AA13: 0 | AB13: 0 | AC13: 0 | AD13: 0 | AE13: 0 | AF13: 0 | AG13: 0 | AH13: 0 | AI13: 0 | AJ13: 0 | AK13: 0 | AL13: 0 | AM13: 0
... A31: Amoniaco | B31: 0 | C31: 0 | D31: 0 | E31: 0 | F31: 0 | G31: 0 | H31: 0 | I31: 0 | J31: 0 | K31: 0 | L31: 0 | M31: 0 | N31: 0 | O31: 0 | P31: 0 | Q31: 0 | R31: 0 | S31: 0 | T31: 0 | U31: 0 | V31: 0 | W31: 0 | X31: 0 | Y31: 0 | Z31: 0 | AA31: 0 | AB31: 0 | AC31: 0 | AD31: 0 | AE31: 0 | AF31: 0 | AG31: 0 | AH31: 0 | AI31: 0 | AJ31: 0 | AK31: 0 | AL31: 0 | AM31: 0
A32: Hierro y acero
A33: PJ | B33: 2013 | C33: 2014 | D33: 2015 | E33: 2016 | F33: 2017 | G33: 2018 | H33: 2019 | I33: 2020 | J33: 2021 | K33: 2022 | L33: 2023 | M33: 2024 | N33: 2025 | O33: 2026 | P33: 2027 | Q33: 2028 | R33: 2029 | S33: 2030 | T33: 2031 | U33: 2032 | V33: 2033 | W33: 2034 | X33: 2035 | Y33: 2036 | Z33: 2037 | AA33: 2038 | AB33: 2039 | AC33: 2040 | AD33: 2041 | AE33: 2042 | AF33: 2043 | AG33: 2044 | AH33: 2045 | AI33: 2046 | AJ33: 2047 | AK33: 2048 | AL33: 2049 | AM33: 2050
A34: Carbón | B34: 0 | C34: 0 | D34: 0 | E34: 0 | F34: 0 | G34: 0 | H34: 0 | I34: 0 | J34: 0 | K34: 0 | L34: 0 | M34: 0 | N34: 0 | O34: 0 | P34: 0 | Q34: 0 | R34: 0 | S34: 0 | T34: 0 | U34: 0 | V34: 0 | W34: 0 | X34: 0 | Y34: 0 | Z34: 0 | AA34: 0 | AB34: 0 | AC34: 0 | AD34: 0 | AE34: 0 | AF34: 0 | AG34: 0 | AH34: 0 | AI34: 0 | AJ34: 0 | AK34: 0 | AL34: 0 | AM34: 0
A35: Petróleo | B35: 0 | C35: 0 | D35: 0 | E35: 0 | F35: 0 | G35: 0 | H35: 0 | I35: 0 | J35: 0 | K35: 0 | L35: 0 | M35: 0 | N35: 0 | O35: 0 | P35: 0 | Q35: 0 | R35: 0 | S35: 0 | T35: 0 | U35: 0 | V35: 0 | W35: 0 | X35: 0 | Y35: 0 | Z35: 0 | AA35: 0 | AB35: 0 | AC35: 0 | AD35: 0 | AE35: 0 | AF35: 0 | AG35: 0 | AH35: 0 | AI35: 0 | AJ35: 0 | AK35: 0 | AL35: 0 | AM35: 0
A36: Condensados | B36: 0 | C36: 0 | D36: 0 | E36: 0 | F36: 0 | G36: 0 | H36: 0 | I36: 0 | J36: 0 | K36: 0 | L36: 0 | M36: 0 | N36: 0 | O36: 0 | P36: 0 | Q36: 0 | R36: 0 | S36: 0 | T36: 0 | U36: 0 | V36: 0 | W36: 0 | X36: 0 | Y36: 0 | Z36: 0 | AA36: 0 | AB36: 0 | AC36: 0 | AD36: 0 | AE36: 0 | AF36: 0 | AG36: 0 | AH36: 0 | AI36: 0 | AJ36: 0 | AK36: 0 | AL36: 0 | AM36: 0
A37: Gas natural | B37: 0 | C37: 0 | D37: 0 | E37: 0 | F37: 0 | G37: 0 | H37: 0 | I37: 0 | J37: 0 | K37: 0 | L37: 0 | M37: 0 | N37: 0 | O37: 0 | P37: 0 | Q37: 0 | R37: 0 | S37: 0 | T37: 0 | U37: 0 | V37: 0 | W37: 0 | X37: 0 | Y37: 0 | Z37: 0 | AA37: 0 | AB37: 0 | AC37: 0 | AD37: 0 | AE37: 0 | AF37: 0 | AG37: 0 | AH37: 0 | AI37: 0 | AJ37: 0 | AK37: 0 | AL37: 0 | AM37: 0
A38: Nuclear | B38: 0 | C38: 0 | D38: 0 | E38: 0 | F38: 0 | G38: 0 | H38: 0 | I38: 0 | J38: 0 | K38: 0 | L38: 0 | M38: 0 | N38: 0 | O38: 0 | P38: 0 | Q38: 0 | R38: 0 | S38: 0 | T38: 0 | U38: 0 | V38: 0 | W38: 0 | X38: 0 | Y38: 0 | Z38: 0 | AA38: 0 | AB38: 0 | AC38: 0 | AD38: 0 | AE38: 0 | AF38: 0 | AG38: 0 | AH38: 0 | AI38: 0 | AJ38: 0 | AK38: 0 | AL38: 0 | AM38: 0
A39: Hidroenergía | B39: 0 | C39: 0 | D39: 0 | E39: 0 | F39: 0 | G39: 0 | H39: 0 | I39: 0 | J39: 0 | K39: 0 | L39: 0 | M39: 0 | N39: 0 | O39: 0 | P39: 0 | Q39: 0 | R39: 0 | S39: 0 | T39: 0 | U39: 0 | V39: 0 | W39: 0 | X39: 0 | Y39: 0 | Z39: 0 | AA39: 0 | AB39: 0 | AC39: 0 | AD39: 0 | AE39: 0 | AF39: 0 | AG39: 0 | AH39: 0 | AI39: 0 | AJ39: 0 | AK39: 0 | AL39: 0 | AM39: 0
A40: Radiación solar | B40: 0 | C40: 0 | D40: 0 | E40: 0 | F40: 0 | G40: 0 | H40: 0 | I40: 0 | J40: 0 | K40: 0 | L40: 0 | M40: 0 | N40: 0 | O40: 0 | P40: 0 | Q40: 0 | R40: 0 | S40: 0 | T40: 0 | U40: 0 | V40: 0 | W40: 0 | X40: 0 | Y40: 0 | Z40: 0 | AA40: 0 | AB40: 0 | AC40: 0 | AD40: 0 | AE40: 0 | AF40: 0 | AG40: 0 | AH40: 0 | AI40: 0 | AJ40: 0 | AK40: 0 | AL40: 0 | AM40: 0
A41: Energía eólica | B41: 0 | C41: 0 | D41: 0 | E41: 0 | F41: 0 | G41: 0 | H41: 0 | I41: 0 | J41: 0 | K41: 0 | L41: 0 | M41: 0 | N41: 0 | O41: 0 | P41: 0 | Q41: 0 | R41: 0 | S41: 0 | T41: 0 | U41: 0 | V41: 0 | W41: 0 | X41: 0 | Y41: 0 | Z41: 0 | AA41: 0 | AB41: 0 | AC41: 0 | AD41: 0 | AE41: 0 | AF41: 0 | AG41: 0 | AH41: 0 | AI41: 0 | AJ41: 0 | AK41: 0 | AL41: 0 | AM41: 0
A42: Geoenergía | B42: 0 | C42: 0 | D42: 0 | E42: 0 | F42: 0 | G42: 0 | H42: 0 | I42: 0 | J42: 0 | K42: 0 | L42: 0 | M42: 0 | N42: 0 | O42: 0 | P42: 0 | Q42: 0 | R42: 0 | S42: 0 | T42: 0 | U42: 0 | V42: 0 | W42: 0 | X42: 0 | Y42: 0 | Z42: 0 | AA42: 0 | AB42: 0 | AC42: 0 | AD42: 0 | AE42: 0 | AF42: 0 | AG42: 0 | AH42: 0 | AI42: 0 | AJ42: 0 | AK42: 0 | AL42: 0 | AM42: 0
A43: Bagazos | B43: 0 | C43: 0 | D43: 0 | E43: 0 | F43: 0 | G43: 0 | H43: 0 | I43: 0 | J43: 0 | K43: 0 | L43: 0 | M43: 0 | N43: 0 | O43: 0 | P43: 0 | Q43: 0 | R43: 0 | S43: 0 | T43: 0 | U43: 0 | V43: 0 | W43: 0 | X43: 0 | Y43: 0 | Z43: 0 | AA43: 0 | AB43: 0 | AC43: 0 | AD43: 0 | AE43: 0 | AF43: 0 | AG43: 0 | AH43: 0 | AI43: 0 | AJ43: 0 | AK43: 0 | AL43: 0 | AM43: 0
A44: Leña | B44: 0 | C44: 0 | D44: 0 | E44: 0 | F44: 0 | G44: 0 | H44: 0 | I44: 0 | J44: 0 | K44: 0 | L44: 0 | M44: 0 | N44: 0 | O44: 0 | P44: 0 | Q44: 0 | R44: 0 | S44: 0 | T44: 0 | U44: 0 | V44: 0 | W44: 0 | X44: 0 | Y44: 0 | Z44: 0 | AA44: 0 | AB44: 0 | AC44: 0 | AD44: 0 | AE44: 0 | AF44: 0 | AG44: 0 | AH44: 0 | AI44: 0 | AJ44: 0 | AK44: 0 | AL44: 0 | AM44: 0
... A62: Amoniaco | B62: 0 | C62: 0 | D62: 0 | E62: 0 | F62: 0 | G62: 0 | H62: 0 | I62: 0 | J62: 0 | K62: 0 | L62: 0 | M62: 0 | N62: 0 | O62: 0 | P62: 0 | Q62: 0 | R62: 0 | S62: 0 | T62: 0 | U62: 0 | V62: 0 | W62: 0 | X62: 0 | Y62: 0 | Z62: 0 | AA62: 0 | AB62: 0 | AC62: 0 | AD62: 0 | AE62: 0 | AF62: 0 | AG62: 0 | AH62: 0 | AI62: 0 | AJ62: 0 | AK62: 0 | AL62: 0 | AM62: 0
A63: Cemento y derivados
A64: PJ | B64: 2013 | C64: 2014 | D64: 2015 | E64: 2016 | F64: 2017 | G64: 2018 | H64: 2019 | I64: 2020 | J64: 2021 | K64: 2022 | L64: 2023 | M64: 2024 | N64: 2025 | O64: 2026 | P64: 2027 | Q64: 2028 | R64: 2029 | S64: 2030 | T64: 2031 | U64: 2032 | V64: 2033 | W64: 2034 | X64: 2035 | Y64: 2036 | Z64: 2037 | AA64: 2038 | AB64: 2039 | AC64: 2040 | AD64: 2041 | AE64: 2042 | AF64: 2043 | AG64: 2044 | AH64: 2045 | AI64: 2046 | AJ64: 2047 | AK64: 2048 | AL64: 2049 | AM64: 2050
A65: Carbón | B65: 5.86 | C65: 6 | D65: 6.41 | E65: 6.82 | F65: 7.05 | G65: 7.31 | H65: 7.66 | I65: 9.53 | J65: 28.99 | K65: 28.78 | L65: 28.47 | M65: 28.17 | N65: 27.86 | O65: 27.56 | P65: 27.25 | Q65: 26.95 | R65: 26.64 | S65: 26.34 | T65: 26.03 | U65: 25.73 | V65: 25.42 | W65: 25.12 | X65: 24.81 | Y65: 24.51 | Z65: 24.2 | AA65: 23.9 | AB65: 23.6 | AC65: 23.29 | AD65: 22.99 | AE65: 22.68 | AF65: 22.38 | AG65: 22.07 | AH65: 21.77 | AI65: 21.46 | AJ65: 21.16 | AK65: 20.85 | AL65: 20.55 | AM65: 20.24
A66: Petróleo | B66: 0 | C66: 0 | D66: 0 | E66: 0 | F66: 0 | G66: 0 | H66: 0 | I66: 0 | J66: 0 | K66: 0 | L66: 0 | M66: 0 | N66: 0 | O66: 0 | P66: 0 | Q66: 0 | R66: 0 | S66: 0 | T66: 0 | U66: 0 | V66: 0 | W66: 0 | X66: 0 | Y66: 0 | Z66: 0 | AA66: 0 | AB66: 0 | AC66: 0 | AD66: 0 | AE66: 0 | AF66: 0 | AG66: 0 | AH66: 0 | AI66: 0 | AJ66: 0 | AK66: 0 | AL66: 0 | AM66: 0
A67: Condensados | B67: 0 | C67: 0 | D67: 0 | E67: 0 | F67: 0 | G67: 0 | H67: 0 | I67: 0 | J67: 0 | K67: 0 | L67: 0 | M67: 0 | N67: 0 | O67: 0 | P67: 0 | Q67: 0 | R67: 0 | S67: 0 | T67: 0 | U67: 0 | V67: 0 | W67: 0 | X67: 0 | Y67: 0 | Z67: 0 | AA67: 0 | AB67: 0 | AC67: 0 | AD67: 0 | AE67: 0 | AF67: 0 | AG67: 0 | AH67: 0 | AI67: 0 | AJ67: 0 | AK67: 0 | AL67: 0 | AM67: 0
A68: Gas natural | B68: 0 | C68: 0 | D68: 0 | E68: 0 | F68: 0 | G68: 0 | H68: 0 | I68: 0 | J68: 0 | K68: 0 | L68: 0 | M68: 0 | N68: 0 | O68: 0 | P68: 0 | Q68: 0 | R68: 0 | S68: 0 | T68: 0 | U68: 0 | V68: 0 | W68: 0 | X68: 0 | Y68: 0 | Z68: 0 | AA68: 0 | AB68: 0 | AC68: 0 | AD68: 0 | AE68: 0 | AF68: 0 | AG68: 0 | AH68: 0 | AI68: 0 | AJ68: 0 | AK68: 0 | AL68: 0 | AM68: 0
A69: Nuclear | B69: 0 | C69: 0 | D69: 0 | E69: 0 | F69: 0 | G69: 0 | H69: 0 | I69: 0 | J69: 0 | K69: 0 | L69: 0 | M69: 0 | N69: 0 | O69: 0 | P69: 0 | Q69: 0 | R69: 0 | S69: 0 | T69: 0 | U69: 0 | V69: 0 | W69: 0 | X69: 0 | Y69: 0 | Z69: 0 | AA69: 0 | AB69: 0 | AC69: 0 | AD69: 0 | AE69: 0 | AF69: 0 | AG69: 0 | AH69: 0 | AI69: 0 | AJ69: 0 | AK69: 0 | AL69: 0 | AM69: 0
A70: Hidroenergía | B70: 0 | C70: 0 | D70: 0 | E70: 0 | F70: 0 | G70: 0 | H70: 0 | I70: 0 | J70: 0 | K70: 0 | L70: 0 | M70: 0 | N70: 0 | O70: 0 | P70: 0 | Q70: 0 | R70: 0 | S70: 0 | T70: 0 | U70: 0 | V70: 0 | W70: 0 | X70: 0 | Y70: 0 | Z70: 0 | AA70: 0 | AB70: 0 | AC70: 0 | AD70: 0 | AE70: 0 | AF70: 0 | AG70: 0 | AH70: 0 | AI70: 0 | AJ70: 0 | AK70: 0 | AL70: 0 | AM70: 0
A71: Radiación solar | B71: 0 | C71: 0 | D71: 0 | E71: 0 | F71: 0 | G71: 0 | H71: 0 | I71: 0 | J71: 0 | K71: 0 | L71: 0 | M71: 0 | N71: 0 | O71: 0 | P71: 0 | Q71: 0 | R71: 0 | S71: 0 | T71: 0 | U71: 0 | V71: 0 | W71: 0 | X71: 0 | Y71: 0 | Z71: 0 | AA71: 0 | AB71: 0 | AC71: 0 | AD71: 0 | AE71: 0 | AF71: 0 | AG71: 0 | AH71: 0 | AI71: 0 | AJ71: 0 | AK71: 0 | AL71: 0 | AM71: 0
A72: Energía eólica | B72: 0 | C72: 0 | D72: 0 | E72: 0 | F72: 0 | G72: 0 | H72: 0 | I72: 0 | J72: 0 | K72: 0 | L72: 0 | M72: 0 | N72: 0 | O72: 0 | P72: 0 | Q72: 0 | R72: 0 | S72: 0 | T72: 0 | U72: 0 | V72: 0 | W72: 0 | X72: 0 | Y72: 0 | Z72: 0 | AA72: 0 | AB72: 0 | AC72: 0 | AD72: 0 | AE72: 0 | AF72: 0 | AG72: 0 | AH72: 0 | AI72: 0 | AJ72: 0 | AK72: 0 | AL72: 0 | AM72: 0
A73: Geoenergía | B73: 0 | C73: 0 | D73: 0 | E73: 0 | F73: 0 | G73: 0 | H73: 0 | I73: 0 | J73: 0 | K73: 0 | L73: 0 | M73: 0 | N73: 0 | O73: 0 | P73: 0 | Q73: 0 | R73: 0 | S73: 0 | T73: 0 | U73: 0 | V73: 0 | W73: 0 | X73: 0 | Y73: 0 | Z73: 0 | AA73: 0 | AB73: 0 | AC73: 0 | AD73: 0 | AE73: 0 | AF73: 0 | AG73: 0 | AH73: 0 | AI73: 0 | AJ73: 0 | AK73: 0 | AL73: 0 | AM73: 0
A74: Bagazos | B74: 0 | C74: 0 | D74: 0 | E74: 0 | F74: 0 | G74: 0 | H74: 0 | I74: 0 | J74: 0 | K74: 0 | L74: 0 | M74: 0 | N74: 0 | O74: 0 | P74: 0 | Q74: 0 | R74: 0 | S74: 0 | T74: 0 | U74: 0 | V74: 0 | W74: 0 | X74: 0 | Y74: 0 | Z74: 0 | AA74: 0 | AB74: 0 | AC74: 0 | AD74: 0 | AE74: 0 | AF74: 0 | AG74: 0 | AH74: 0 | AI74: 0 | AJ74: 0 | AK74: 0 | AL74: 0 | AM74: 0
...

Sheet Calculations PJ
C1: 2013 | D1: 2014 | E1: 2015 | F1: 2016 | G1: 2017 | H1: 2018 | I1: 2019 | J1: 2020 | K1: 2021 | L1: 2022 | M1: 2023 | N1: 2024 | O1: 2025 | P1: 2026 | Q1: 2027 | R1: 2028 | S1: 2029 | T1: 2030 | U1: 2031 | V1: 2032 | W1: 2033 | X1: 2034 | Y1: 2035 | Z1: 2036 | AA1: 2037 | AB1: 2038 | AC1: 2039 | AD1: 2040 | AE1: 2041 | AF1: 2042 | AG1: 2043 | AH1: 2044 | AI1: 2045 | AJ1: 2046 | AK1: 2047 | AL1: 2048 | AM1: 2049 | AN1: 2050 | AO1: 2051 | AP1: 2052 | AQ1: 2053 | AR1: 2054 | AS1: 2055 | AT1: 2056 | AU1: 2057 | AV1: 2058 | AW1: 2059 | AX1: 2060 | AY1: 2061 | AZ1: 2062 | BA1: 2063 | BB1: 2064 | BC1: 2065 | BD1: 2066 | BE1: 2067 | BF1: 2068 | BG1: 2069 | BH1: 2070
A2: electricity (PJ) | C2: =SUM(C3:C27) -> 581.35 | D2: =SUM(D3:D27) -> 592.75 | E2: =SUM(E3:E27) -> 590.4 | F2: =SUM(F3:F27) -> 593.79 | G2: =SUM(G3:G27) -> 606.34 | H2: =SUM(H3:H27) -> 642.65 | I2: =SUM(I3:I27) -> 655.48 | J2: =SUM(J3:J27) -> 652 | ... BH2: =SUM(BH3:BH27) -> 1064.8274
B3: agriculture and forestry 01T03 | C3: =C243 -> 37.5 | D3: =D243 -> 36.85 | E3: =E243 -> 36.95 | F3: =F243 -> 41.53 | G3: =G243 -> 41.44 | H3: =H243 -> 40.67 | I3: =I243 -> 40.78 | J3: =J243 -> 51.24 | ... BH3: =BH243 -> 88.495
B4: coal mining 05 | C4: =C250 -> 5.4435 | D4: =D250 -> 5.6775 | E4: =E250 -> 5.7165 | F4: =F250 -> 6.0945 | G4: =G250 -> 6.4725 | H4: =H250 -> 6.9315 | I4: =I250 -> 6.9315 | J4: =J250 -> 7.0935 | ... BH4: =BH250 -> 17.2515
B5: oil and gas extraction 06
B6: other mining and quarrying 07T08 | C6: =C257 -> 30.8465 | D6: =D257 -> 32.1725 | E6: =E257 -> 32.3935 | F6: =F257 -> 34.5355 | G6: =G257 -> 36.6775 | H6: =H257 -> 39.2785 | I6: =I257 -> 39.2785 | J6: =J257 -> 40.1965 | ... BH6: =BH257 -> 97.7585
B7: food beverage and tobacco 10T12 | C7: =C262 -> 11.62 | D7: =D262 -> 10.72 | E7: =E262 -> 11.07 | F7: =F262 -> 12.02 | G7: =G262 -> 12.12 | H7: =H262 -> 12.34 | I7: =I262 -> 12.85 | J7: =J262 -> 12.37 | ... BH7: =BH262 -> 21.96
B8: textiles apparel and leather 13T15 | C8: =C271 -> 3.81 | D8: =D271 -> 3.78 | E8: =E271 -> 3.99 | F8: =F271 -> 4 | G8: =G271 -> 3.91 | H8: =H271 -> 4.01 | I8: =I271 -> 3.78 | J8: =J271 -> 2.69 | ... BH8: =BH271 -> 3.0267084
B9: wood products 16
B10: pulp paper and printing 17T18 | C10: =C278 -> 10.3 | D10: =D278 -> 10.96 | E10: =E278 -> 10.9 | F10: =F278 -> 11.93 | G10: =G278 -> 11.58 | H10: =H278 -> 11.85 | I10: =I278 -> 12.28 | J10: =J278 -> 11.6 | ... BH10: =BH278 -> 52.07
B11: refined petroleum and coke 19
B12: chemicals 20 | C12: =C287 -> 17.12 | D12: =D287 -> 17.06 | E12: =E287 -> 16.68 | F12: =F287 -> 16.86 | G12: =G287 -> 15.8 | H12: =H287 -> 15.52 | I12: =I287 -> 14.79 | J12: =J287 -> 13.95 | ... BH12: =BH287 -> 83.48
B13: rubber and plastic products 22 | C13: =C293 -> 1.65 | D13: =D293 -> 1.73 | E13: =E293 -> 1.82 | F13: =F293 -> 1.95 | G13: =G293 -> 1.79 | H13: =H293 -> 1.81 | I13: =I293 -> 1.65 | J13: =J293 -> 1.73 | ... BH13: =BH293 -> 2.51
B14: glass and glass products 231 | C14: =C300 -> 5.18 | D14: =D300 -> 4.25 | E14: =E300 -> 4.49 | F14: =F300 -> 4.8 | G14: =G300 -> 4.56 | H14: =H300 -> 4.65 | I14: =I300 -> 4.57 | J14: =J300 -> 4.28 | ... BH14: =BH300 -> 3.94
B15: cement and other nonmetallic minerals 239 | C15: =C307 -> 36.13 | D15: =D307 -> 37.01 | E15: =E307 -> 36.87 | F15: =F307 -> 37.28 | G15: =G307 -> 36.73 | H15: =H307 -> 37.01 | I15: =I307 -> 36.29 | J15: =J307 -> 37.52 | ... BH15: =BH307 -> 131.63
B16: iron and steel 241 | C16: =C315 -> 31.58 | D16: =D315 -> 29.85 | E16: =E315 -> 23.22 | F16: =F315 -> 20.63 | G16: =G315 -> 20.46 | H16: =H315 -> 19.99 | I16: =I315 -> 18.43 | J16: =J315 -> 18.91 | ... BH16: =BH315 -> 131.46
B17: other metals 242
B18: metal products except machinery and vehicles 25
B19: computers and electronics 26 | C19: =C321 -> 0.73 | D19: =D321 -> 0.84 | E19: =E321 -> 0.91 | F19: =F321 -> 0.93 | G19: =G321 -> 0.97 | H19: =H321 -> 0.96 | I19: =I321 -> 1.01 | J19: =J321 -> 0.93 | ... BH19: =BH321 -> 0.78957611
B20: appliances and electrical equipment 27 | C20: =C326 -> 0.23 | D20: =D326 -> 0.24 | E20: =E326 -> 0.25 | F20: =F326 -> 0.26 | G20: =G326 -> 0.27 | H20: =H326 -> 0.27 | I20: =I326 -> 0.27 | J20: =J326 -> 0.26 | ... BH20: =BH326 -> 0.26319204
B21: other machinery 28
B22: road vehicles 29 | C22: =C332 -> 8.3 | D22: =D332 -> 8.53 | E22: =E332 -> 9.21 | F22: =F332 -> 9.62 | G22: =G332 -> 9.59 | H22: =H332 -> 9.9 | I22: =I332 -> 10.21 | J22: =J332 -> 10.61 | ... BH22: =BH332 -> 22.67
B23: nonroad vehicles 30
B24: other manufacturing 31T33 | C24: =C350 -> 379.14 | D24: =D350 -> 391.24 | E24: =E350 -> 394.06 | F24: =F350 -> 389.35 | G24: =G350 -> 401.97 | H24: =H350 -> 435.43 | I24: =I350 -> 450.3 | J24: =J350 -> 436.52 | ... BH24: =BH350 -> 398.73291
B25: energy pipelines and gas processing 352T353
B26: water and waste 36T39
B27: construction 41T43 | C27: =C357 -> 1.77 | D27: =D357 -> 1.84 | E27: =E357 -> 1.87 | F27: =F357 -> 2 | G27: =G357 -> 2 | H27: =H357 -> 2.03 | I27: =I357 -> 2.06 | J27: =J357 -> 2.1 | ... BH27: =BH357 -> 8.79
A28: coal (PJ) | C28: =SUM(C29:C53) -> 165.2 | D28: =SUM(D29:D53) -> 145.71 | E28: =SUM(E29:E53) -> 147.93 | F28: =SUM(F29:F53) -> 127.29 | G28: =SUM(G29:G53) -> 301.19 | H28: =SUM(H29:H53) -> 234.36 | I28: =SUM(I29:I53) -> 178.72 | J28: =SUM(J29:J53) -> 65.51 | ... BH28: =SUM(BH29:BH53) -> 51.5
B29: agriculture and forestry 01T03
B30: coal mining 05
B31: oil and gas extraction 06
B32: other mining and quarrying 07T08
B33: food beverage and tobacco 10T12
B34: textiles apparel and leather 13T15
B35: wood products 16
B36: pulp paper and printing 17T18
B37: refined petroleum and coke 19
B38: chemicals 20
B39: rubber and plastic products 22
B40: glass and glass products 231
...

Sheet Calculations BTU
C1: 2013 | D1: 2014 | E1: 2015 | F1: 2016 | G1: 2017 | H1: 2018 | I1: 2019 | J1: 2020 | K1: 2021 | L1: 2022 | M1: 2023 | N1: 2024 | O1: 2025 | P1: 2026 | Q1: 2027 | R1: 2028 | S1: 2029 | T1: 2030 | U1: 2031 | V1: 2032 | W1: 2033 | X1: 2034 | Y1: 2035 | Z1: 2036 | AA1: 2037 | AB1: 2038 | AC1: 2039 | AD1: 2040 | AE1: 2041 | AF1: 2042 | AG1: 2043 | AH1: 2044 | AI1: 2045 | AJ1: 2046 | AK1: 2047 | AL1: 2048 | AM1: 2049 | AN1: 2050 | AO1: 2051 | AP1: 2052 | AQ1: 2053 | AR1: 2054 | AS1: 2055 | AT1: 2056 | AU1: 2057 | AV1: 2058 | AW1: 2059 | AX1: 2060 | AY1: 2061 | AZ1: 2062 | BA1: 2063 | BB1: 2064 | BC1: 2065 | BD1: 2066 | BE1: 2067 | BF1: 2068 | BG1: 2069 | BH1: 2070
A2: electricity (PJ) | C2: =SUM(C3:C27) -> 5.5104256e+14 | D2: =SUM(D3:D27) -> 5.6184825e+14 | E2: =SUM(E3:E27) -> 5.5962076e+14 | F2: =SUM(F3:F27) -> 5.6283403e+14 | G2: =SUM(G3:G27) -> 5.7472976e+14 | H2: =SUM(H3:H27) -> 6.0914682e+14 | I2: =SUM(I3:I27) -> 6.2130795e+14 | J2: =SUM(J3:J27) -> 6.1800937e+14 | ... BH2: =SUM(BH3:BH27) -> 1.0093149e+15
B3: agriculture and forestry 01T03 | C3: =IF('Calculations PJ'!C3<>0,'Calculations PJ'!C3*About!$B$45,0) -> 3.5545018e+13 | D3: =IF('Calculations PJ'!D3<>0,'Calculations PJ'!D3*About!$B$45,0) -> 3.4928904e+13 | E3: =IF('Calculations PJ'!E3<>0,'Calculations PJ'!E3*About!$B$45,0) -> 3.5023691e+13 | F3: =IF('Calculations PJ'!F3<>0,'Calculations PJ'!F3*About!$B$45,0) -> 3.9364922e+13 | G3: =IF('Calculations PJ'!G3<>0,'Calculations PJ'!G3*About!$B$45,0) -> 3.9279614e+13 | H3: =IF('Calculations PJ'!H3<>0,'Calculations PJ'!H3*About!$B$45,0) -> 3.8549757e+13 | I3: =IF('Calculations PJ'!I3<>0,'Calculations PJ'!I3*About!$B$45,0) -> 3.8654022e+13 | J3: =IF('Calculations PJ'!J3<>0,'Calculations PJ'!J3*About!$B$45,0) -> 4.8568712e+13 | ... BH3: =IF('Calculations PJ'!BH3<>0,'Calculations PJ'!BH3*About!$B$45,0) -> 8.3881502e+13
B4: coal mining 05 | C4: =IF('Calculations PJ'!C4<>0,'Calculations PJ'!C4*About!$B$45,0) -> 5.1597148e+12 | D4: =IF('Calculations PJ'!D4<>0,'Calculations PJ'!D4*About!$B$45,0) -> 5.3815157e+12 | E4: =IF('Calculations PJ'!E4<>0,'Calculations PJ'!E4*About!$B$45,0) -> 5.4184825e+12 | F4: =IF('Calculations PJ'!F4<>0,'Calculations PJ'!F4*About!$B$45,0) -> 5.7767763e+12 | G4: =IF('Calculations PJ'!G4<>0,'Calculations PJ'!G4*About!$B$45,0) -> 6.1350701e+12 | H4: =IF('Calculations PJ'!H4<>0,'Calculations PJ'!H4*About!$B$45,0) -> 6.5701411e+12 | I4: =IF('Calculations PJ'!I4<>0,'Calculations PJ'!I4*About!$B$45,0) -> 6.5701411e+12 | J4: =IF('Calculations PJ'!J4<>0,'Calculations PJ'!J4*About!$B$45,0) -> 6.7236955e+12 | ... BH4: =IF('Calculations PJ'!BH4<>0,'Calculations PJ'!BH4*About!$B$45,0) -> 1.635213e+13
B5: oil and gas extraction 06 | C5: =IF('Calculations PJ'!C5<>0,'Calculations PJ'!C5*About!$B$45,0) -> 0 | D5: =IF('Calculations PJ'!D5<>0,'Calculations PJ'!D5*About!$B$45,0) -> 0 | E5: =IF('Calculations PJ'!E5<>0,'Calculations PJ'!E5*About!$B$45,0) -> 0 | F5: =IF('Calculations PJ'!F5<>0,'Calculations PJ'!F5*About!$B$45,0) -> 0 | G5: =IF('Calculations PJ'!G5<>0,'Calculations PJ'!G5*About!$B$45,0) -> 0 | H5: =IF('Calculations PJ'!H5<>0,'Calculations PJ'!H5*About!$B$45,0) -> 0 | I5: =IF('Calculations PJ'!I5<>0,'Calculations PJ'!I5*About!$B$45,0) -> 0 | J5: =IF('Calculations PJ'!J5<>0,'Calculations PJ'!J5*About!$B$45,0) -> 0 | ... BH5: =IF('Calculations PJ'!BH5<>0,'Calculations PJ'!BH5*About!$B$45,0) -> 0
B6: other mining and quarrying 07T08 | C6: =IF('Calculations PJ'!C6<>0,'Calculations PJ'!C6*About!$B$45,0) -> 2.9238384e+13 | D6: =IF('Calculations PJ'!D6<>0,'Calculations PJ'!D6*About!$B$45,0) -> 3.0495255e+13 | E6: =IF('Calculations PJ'!E6<>0,'Calculations PJ'!E6*About!$B$45,0) -> 3.0704734e+13 | F6: =IF('Calculations PJ'!F6<>0,'Calculations PJ'!F6*About!$B$45,0) -> 3.2735066e+13 | G6: =IF('Calculations PJ'!G6<>0,'Calculations PJ'!G6*About!$B$45,0) -> 3.4765397e+13 | H6: =IF('Calculations PJ'!H6<>0,'Calculations PJ'!H6*About!$B$45,0) -> 3.7230799e+13 | I6: =IF('Calculations PJ'!I6<>0,'Calculations PJ'!I6*About!$B$45,0) -> 3.7230799e+13 | J6: =IF('Calculations PJ'!J6<>0,'Calculations PJ'!J6*About!$B$45,0) -> 3.8100941e+13 | ... BH6: =IF('Calculations PJ'!BH6<>0,'Calculations PJ'!BH6*About!$B$45,0) -> 9.266207e+13
B7: food beverage and tobacco 10T12 | C7: =IF('Calculations PJ'!C7<>0,'Calculations PJ'!C7*About!$B$45,0) -> 1.1014216e+13 | D7: =IF('Calculations PJ'!D7<>0,'Calculations PJ'!D7*About!$B$45,0) -> 1.0161136e+13 | E7: =IF('Calculations PJ'!E7<>0,'Calculations PJ'!E7*About!$B$45,0) -> 1.0492889e+13 | F7: =IF('Calculations PJ'!F7<>0,'Calculations PJ'!F7*About!$B$45,0) -> 1.1393363e+13 | G7: =IF('Calculations PJ'!G7<>0,'Calculations PJ'!G7*About!$B$45,0) -> 1.148815e+13 | H7: =IF('Calculations PJ'!H7<>0,'Calculations PJ'!H7*About!$B$45,0) -> 1.169668e+13 | I7: =IF('Calculations PJ'!I7<>0,'Calculations PJ'!I7*About!$B$45,0) -> 1.2180093e+13 | J7: =IF('Calculations PJ'!J7<>0,'Calculations PJ'!J7*About!$B$45,0) -> 1.1725116e+13 | ... BH7: =IF('Calculations PJ'!BH7<>0,'Calculations PJ'!BH7*About!$B$45,0) -> 2.0815162e+13
B8: textiles apparel and leather 13T15 | C8: =IF('Calculations PJ'!C8<>0,'Calculations PJ'!C8*About!$B$45,0) -> 3.6113738e+12 | D8: =IF('Calculations PJ'!D8<>0,'Calculations PJ'!D8*About!$B$45,0) -> 3.5829378e+12 | E8: =IF('Calculations PJ'!E8<>0,'Calculations PJ'!E8*About!$B$45,0) -> 3.7819899e+12 | F8: =IF('Calculations PJ'!F8<>0,'Calculations PJ'!F8*About!$B$45,0) -> 3.7914686e+12 | G8: =IF('Calculations PJ'!G8<>0,'Calculations PJ'!G8*About!$B$45,0) -> 3.7061605e+12 | H8: =IF('Calculations PJ'!H8<>0,'Calculations PJ'!H8*About!$B$45,0) -> 3.8009472e+12 | I8: =IF('Calculations PJ'!I8<>0,'Calculations PJ'!I8*About!$B$45,0) -> 3.5829378e+12 | J8: =IF('Calculations PJ'!J8<>0,'Calculations PJ'!J8*About!$B$45,0) -> 2.5497626e+12 | ... BH8: =IF('Calculations PJ'!BH8<>0,'Calculations PJ'!BH8*About!$B$45,0) -> 2.8689175e+12
B9: wood products 16 | C9: =IF('Calculations PJ'!C9<>0,'Calculations PJ'!C9*About!$B$45,0) -> 0 | D9: =IF('Calculations PJ'!D9<>0,'Calculations PJ'!D9*About!$B$45,0) -> 0 | E9: =IF('Calculations PJ'!E9<>0,'Calculations PJ'!E9*About!$B$45,0) -> 0 | F9: =IF('Calculations PJ'!F9<>0,'Calculations PJ'!F9*About!$B$45,0) -> 0 | G9: =IF('Calculations PJ'!G9<>0,'Calculations PJ'!G9*About!$B$45,0) -> 0 | H9: =IF('Calculations PJ'!H9<>0,'Calculations PJ'!H9*About!$B$45,0) -> 0 | I9: =IF('Calculations PJ'!I9<>0,'Calculations PJ'!I9*About!$B$45,0) -> 0 | J9: =IF('Calculations PJ'!J9<>0,'Calculations PJ'!J9*About!$B$45,0) -> 0 | ... BH9: =IF('Calculations PJ'!BH9<>0,'Calculations PJ'!BH9*About!$B$45,0) -> 0
B10: pulp paper and printing 17T18 | C10: =IF('Calculations PJ'!C10<>0,'Calculations PJ'!C10*About!$B$45,0) -> 9.7630315e+12 | D10: =IF('Calculations PJ'!D10<>0,'Calculations PJ'!D10*About!$B$45,0) -> 1.0388624e+13 | E10: =IF('Calculations PJ'!E10<>0,'Calculations PJ'!E10*About!$B$45,0) -> 1.0331752e+13 | F10: =IF('Calculations PJ'!F10<>0,'Calculations PJ'!F10*About!$B$45,0) -> 1.1308055e+13 | G10: =IF('Calculations PJ'!G10<>0,'Calculations PJ'!G10*About!$B$45,0) -> 1.0976301e+13 | H10: =IF('Calculations PJ'!H10<>0,'Calculations PJ'!H10*About!$B$45,0) -> 1.1232226e+13 | I10: =IF('Calculations PJ'!I10<>0,'Calculations PJ'!I10*About!$B$45,0) -> 1.1639808e+13 | J10: =IF('Calculations PJ'!J10<>0,'Calculations PJ'!J10*About!$B$45,0) -> 1.0995259e+13 | ... BH10: =IF('Calculations PJ'!BH10<>0,'Calculations PJ'!BH10*About!$B$45,0) -> 4.9355442e+13
B11: refined petroleum and coke 19 | C11: =IF('Calculations PJ'!C11<>0,'Calculations PJ'!C11*About!$B$45,0) -> 0 | D11: =IF('Calculations PJ'!D11<>0,'Calculations PJ'!D11*About!$B$45,0) -> 0 | E11: =IF('Calculations PJ'!E11<>0,'Calculations PJ'!E11*About!$B$45,0) -> 0 | F11: =IF('Calculations PJ'!F11<>0,'Calculations PJ'!F11*About!$B$45,0) -> 0 | G11: =IF('Calculations PJ'!G11<>0,'Calculations PJ'!G11*About!$B$45,0) -> 0 | H11: =IF('Calculations PJ'!H11<>0,'Calculations PJ'!H11*About!$B$45,0) -> 0 | I11: =IF('Calculations PJ'!I11<>0,'Calculations PJ'!I11*About!$B$45,0) -> 0 | J11: =IF('Calculations PJ'!J11<>0,'Calculations PJ'!J11*About!$B$45,0) -> 0 | ... BH11: =IF('Calculations PJ'!BH11<>0,'Calculations PJ'!BH11*About!$B$45,0) -> 0
B12: chemicals 20 | C12: =IF('Calculations PJ'!C12<>0,'Calculations PJ'!C12*About!$B$45,0) -> 1.6227485e+13 | D12: =IF('Calculations PJ'!D12<>0,'Calculations PJ'!D12*About!$B$45,0) -> 1.6170613e+13 | E12: =IF('Calculations PJ'!E12<>0,'Calculations PJ'!E12*About!$B$45,0) -> 1.5810424e+13 | F12: =IF('Calculations PJ'!F12<>0,'Calculations PJ'!F12*About!$B$45,0) -> 1.598104e+13 | G12: =IF('Calculations PJ'!G12<>0,'Calculations PJ'!G12*About!$B$45,0) -> 1.4976301e+13 | H12: =IF('Calculations PJ'!H12<>0,'Calculations PJ'!H12*About!$B$45,0) -> 1.4710898e+13 | I12: =IF('Calculations PJ'!I12<>0,'Calculations PJ'!I12*About!$B$45,0) -> 1.4018955e+13 | J12: =IF('Calculations PJ'!J12<>0,'Calculations PJ'!J12*About!$B$45,0) -> 1.3222747e+13 | ... BH12: =IF('Calculations PJ'!BH12<>0,'Calculations PJ'!BH12*About!$B$45,0) -> 7.9127949e+13
B13: rubber and plastic products 22 | C13: =IF('Calculations PJ'!C13<>0,'Calculations PJ'!C13*About!$B$45,0) -> 1.5639808e+12 | D13: =IF('Calculations PJ'!D13<>0,'Calculations PJ'!D13*About!$B$45,0) -> 1.6398101e+12 | E13: =IF('Calculations PJ'!E13<>0,'Calculations PJ'!E13*About!$B$45,0) -> 1.7251182e+12 | F13: =IF('Calculations PJ'!F13<>0,'Calculations PJ'!F13*About!$B$45,0) -> 1.8483409e+12 | G13: =IF('Calculations PJ'!G13<>0,'Calculations PJ'!G13*About!$B$45,0) -> 1.6966822e+12 | H13: =IF('Calculations PJ'!H13<>0,'Calculations PJ'!H13*About!$B$45,0) -> 1.7156395e+12 | I13: =IF('Calculations PJ'!I13<>0,'Calculations PJ'!I13*About!$B$45,0) -> 1.5639808e+12 | J13: =IF('Calculations PJ'!J13<>0,'Calculations PJ'!J13*About!$B$45,0) -> 1.6398101e+12 | ... BH13: =IF('Calculations PJ'!BH13<>0,'Calculations PJ'!BH13*About!$B$45,0) -> 2.3791465e+12
B14: glass and glass products 231 | C14: =IF('Calculations PJ'!C14<>0,'Calculations PJ'!C14*About!$B$45,0) -> 4.9099518e+12 | D14: =IF('Calculations PJ'!D14<>0,'Calculations PJ'!D14*About!$B$45,0) -> 4.0284353e+12 | E14: =IF('Calculations PJ'!E14<>0,'Calculations PJ'!E14*About!$B$45,0) -> 4.2559234e+12 | F14: =IF('Calculations PJ'!F14<>0,'Calculations PJ'!F14*About!$B$45,0) -> 4.5497623e+12 | G14: =IF('Calculations PJ'!G14<>0,'Calculations PJ'!G14*About!$B$45,0) -> 4.3222741e+12 | H14: =IF('Calculations PJ'!H14<>0,'Calculations PJ'!H14*About!$B$45,0) -> 4.4075822e+12 | I14: =IF('Calculations PJ'!I14<>0,'Calculations PJ'!I14*About!$B$45,0) -> 4.3317528e+12 | J14: =IF('Calculations PJ'!J14<>0,'Calculations PJ'!J14*About!$B$45,0) -> 4.0568714e+12 | ... BH14: =IF('Calculations PJ'!BH14<>0,'Calculations PJ'!BH14*About!$B$45,0) -> 3.7345965e+12
... B27: construction 41T43 | C27: =IF('Calculations PJ'!C27<>0,'Calculations PJ'!C27*About!$B$45,0) -> 1.6777248e+12 | D27: =IF('Calculations PJ'!D27<>0,'Calculations PJ'!D27*About!$B$45,0) -> 1.7440755e+12 | E27: =IF('Calculations PJ'!E27<>0,'Calculations PJ'!E27*About!$B$45,0) -> 1.7725115e+12 | F27: =IF('Calculations PJ'!F27<>0,'Calculations PJ'!F27*About!$B$45,0) -> 1.8957343e+12 | G27: =IF('Calculations PJ'!G27<>0,'Calculations PJ'!G27*About!$B$45,0) -> 1.8957343e+12 | H27: =IF('Calculations PJ'!H27<>0,'Calculations PJ'!H27*About!$B$45,0) -> 1.9241703e+12 | I27: =IF('Calculations PJ'!I27<>0,'Calculations PJ'!I27*About!$B$45,0) -> 1.9526063e+12 | J27: =IF('Calculations PJ'!J27<>0,'Calculations PJ'!J27*About!$B$45,0) -> 1.990521e+12 | ... BH27: =IF('Calculations PJ'!BH27<>0,'Calculations PJ'!BH27*About!$B$45,0) -> 8.3317521e+12
A28: coal (PJ) | C28: =SUM(C29:C53) -> 1.5658765e+14 | D28: =SUM(D29:D53) -> 1.3811372e+14 | E28: =SUM(E29:E53) -> 1.4021799e+14 | F28: =SUM(F29:F53) -> 1.2065401e+14 | G28: =SUM(G29:G53) -> 2.854881e+14 | H28: =SUM(H29:H53) -> 2.2214214e+14 | I28: =SUM(I29:I53) -> 1.6940281e+14 | J28: =SUM(J29:J53) -> 6.2094776e+13 | ... BH28: =SUM(BH29:BH53) -> 4.8815158e+13
B29: agriculture and forestry 01T03 | C29: =IF('Calculations PJ'!C29<>0,'Calculations PJ'!C29*About!$B$45,0) -> 0 | D29: =IF('Calculations PJ'!D29<>0,'Calculations PJ'!D29*About!$B$45,0) -> 0 | E29: =IF('Calculations PJ'!E29<>0,'Calculations PJ'!E29*About!$B$45,0) -> 0 | F29: =IF('Calculations PJ'!F29<>0,'Calculations PJ'!F29*About!$B$45,0) -> 0 | G29: =IF('Calculations PJ'!G29<>0,'Calculations PJ'!G29*About!$B$45,0) -> 0 | H29: =IF('Calculations PJ'!H29<>0,'Calculations PJ'!H29*About!$B$45,0) -> 0 | I29: =IF('Calculations PJ'!I29<>0,'Calculations PJ'!I29*About!$B$45,0) -> 0 | J29: =IF('Calculations PJ'!J29<>0,'Calculations PJ'!J29*About!$B$45,0) -> 0 | ... BH29: =IF('Calculations PJ'!BH29<>0,'Calculations PJ'!BH29*About!$B$45,0) -> 0
B30: coal mining 05 | C30: =IF('Calculations PJ'!C30<>0,'Calculations PJ'!C30*About!$B$45,0) -> 0 | D30: =IF('Calculations PJ'!D30<>0,'Calculations PJ'!D30*About!$B$45,0) -> 0 | E30: =IF('Calculations PJ'!E30<>0,'Calculations PJ'!E30*About!$B$45,0) -> 0 | F30: =IF('Calculations PJ'!F30<>0,'Calculations PJ'!F30*About!$B$45,0) -> 0 | G30: =IF('Calculations PJ'!G30<>0,'Calculations PJ'!G30*About!$B$45,0) -> 0 | H30: =IF('Calculations PJ'!H30<>0,'Calculations PJ'!H30*About!$B$45,0) -> 0 | I30: =IF('Calculations PJ'!I30<>0,'Calculations PJ'!I30*About!$B$45,0) -> 0 | J30: =IF('Calculations PJ'!J30<>0,'Calculations PJ'!J30*About!$B$45,0) -> 0 | ... BH30: =IF('Calculations PJ'!BH30<>0,'Calculations PJ'!BH30*About!$B$45,0) -> 0
B31: oil and gas extraction 06 | C31: =IF('Calculations PJ'!C31<>0,'Calculations PJ'!C31*About!$B$45,0) -> 0 | D31: =IF('Calculations PJ'!D31<>0,'Calculations PJ'!D31*About!$B$45,0) -> 0 | E31: =IF('Calculations PJ'!E31<>0,'Calculations PJ'!E31*About!$B$45,0) -> 0 | F31: =IF('Calculations PJ'!F31<>0,'Calculations PJ'!F31*About!$B$45,0) -> 0 | G31: =IF('Calculations PJ'!G31<>0,'Calculations PJ'!G31*About!$B$45,0) -> 0 | H31: =IF('Calculations PJ'!H31<>0,'Calculations PJ'!H31*About!$B$45,0) -> 0 | I31: =IF('Calculations PJ'!I31<>0,'Calculations PJ'!I31*About!$B$45,0) -> 0 | J31: =IF('Calculations PJ'!J31<>0,'Calculations PJ'!J31*About!$B$45,0) -> 0 | ... BH31: =IF('Calculations PJ'!BH31<>0,'Calculations PJ'!BH31*About!$B$45,0) -> 0
B32: other mining and quarrying 07T08 | C32: =IF('Calculations PJ'!C32<>0,'Calculations PJ'!C32*About!$B$45,0) -> 0 | D32: =IF('Calculations PJ'!D32<>0,'Calculations PJ'!D32*About!$B$45,0) -> 0 | E32: =IF('Calculations PJ'!E32<>0,'Calculations PJ'!E32*About!$B$45,0) -> 0 | F32: =IF('Calculations PJ'!F32<>0,'Calculations PJ'!F32*About!$B$45,0) -> 0 | G32: =IF('Calculations PJ'!G32<>0,'Calculations PJ'!G32*About!$B$45,0) -> 0 | H32: =IF('Calculations PJ'!H32<>0,'Calculations PJ'!H32*About!$B$45,0) -> 0 | I32: =IF('Calculations PJ'!I32<>0,'Calculations PJ'!I32*About!$B$45,0) -> 0 | J32: =IF('Calculations PJ'!J32<>0,'Calculations PJ'!J32*About!$B$45,0) -> 0 | ... BH32: =IF('Calculations PJ'!BH32<>0,'Calculations PJ'!BH32*About!$B$45,0) -> 0
B33: food beverage and tobacco 10T12 | C33: =IF('Calculations PJ'!C33<>0,'Calculations PJ'!C33*About!$B$45,0) -> 0 | D33: =IF('Calculations PJ'!D33<>0,'Calculations PJ'!D33*About!$B$45,0) -> 0 | E33: =IF('Calculations PJ'!E33<>0,'Calculations PJ'!E33*About!$B$45,0) -> 0 | F33: =IF('Calculations PJ'!F33<>0,'Calculations PJ'!F33*About!$B$45,0) -> 0 | G33: =IF('Calculations PJ'!G33<>0,'Calculations PJ'!G33*About!$B$45,0) -> 0 | H33: =IF('Calculations PJ'!H33<>0,'Calculations PJ'!H33*About!$B$45,0) -> 0 | I33: =IF('Calculations PJ'!I33<>0,'Calculations PJ'!I33*About!$B$45,0) -> 0 | J33: =IF('Calculations PJ'!J33<>0,'Calculations PJ'!J33*About!$B$45,0) -> 0 | ... BH33: =IF('Calculations PJ'!BH33<>0,'Calculations PJ'!BH33*About!$B$45,0) -> 0
B34: textiles apparel and leather 13T15 | C34: =IF('Calculations PJ'!C34<>0,'Calculations PJ'!C34*About!$B$45,0) -> 0 | D34: =IF('Calculations PJ'!D34<>0,'Calculations PJ'!D34*About!$B$45,0) -> 0 | E34: =IF('Calculations PJ'!E34<>0,'Calculations PJ'!E34*About!$B$45,0) -> 0 | F34: =IF('Calculations PJ'!F34<>0,'Calculations PJ'!F34*About!$B$45,0) -> 0 | G34: =IF('Calculations PJ'!G34<>0,'Calculations PJ'!G34*About!$B$45,0) -> 0 | H34: =IF('Calculations PJ'!H34<>0,'Calculations PJ'!H34*About!$B$45,0) -> 0 | I34: =IF('Calculations PJ'!I34<>0,'Calculations PJ'!I34*About!$B$45,0) -> 0 | J34: =IF('Calculations PJ'!J34<>0,'Calculations PJ'!J34*About!$B$45,0) -> 0 | ... BH34: =IF('Calculations PJ'!BH34<>0,'Calculations PJ'!BH34*About!$B$45,0) -> 0
B35: wood products 16 | C35: =IF('Calculations PJ'!C35<>0,'Calculations PJ'!C35*About!$B$45,0) -> 0 | D35: =IF('Calculations PJ'!D35<>0,'Calculations PJ'!D35*About!$B$45,0) -> 0 | E35: =IF('Calculations PJ'!E35<>0,'Calculations PJ'!E35*About!$B$45,0) -> 0 | F35: =IF('Calculations PJ'!F35<>0,'Calculations PJ'!F35*About!$B$45,0) -> 0 | G35: =IF('Calculations PJ'!G35<>0,'Calculations PJ'!G35*About!$B$45,0) -> 0 | H35: =IF('Calculations PJ'!H35<>0,'Calculations PJ'!H35*About!$B$45,0) -> 0 | I35: =IF('Calculations PJ'!I35<>0,'Calculations PJ'!I35*About!$B$45,0) -> 0 | J35: =IF('Calculations PJ'!J35<>0,'Calculations PJ'!J35*About!$B$45,0) -> 0 | ... BH35: =IF('Calculations PJ'!BH35<>0,'Calculations PJ'!BH35*About!$B$45,0) -> 0
B36: pulp paper and printing 17T18 | C36: =IF('Calculations PJ'!C36<>0,'Calculations PJ'!C36*About!$B$45,0) -> 0 | D36: =IF('Calculations PJ'!D36<>0,'Calculations PJ'!D36*About!$B$45,0) -> 0 | E36: =IF('Calculations PJ'!E36<>0,'Calculations PJ'!E36*About!$B$45,0) -> 0 | F36: =IF('Calculations PJ'!F36<>0,'Calculations PJ'!F36*About!$B$45,0) -> 0 | G36: =IF('Calculations PJ'!G36<>0,'Calculations PJ'!G36*About!$B$45,0) -> 0 | H36: =IF('Calculations PJ'!H36<>0,'Calculations PJ'!H36*About!$B$45,0) -> 0 | I36: =IF('Calculations PJ'!I36<>0,'Calculations PJ'!I36*About!$B$45,0) -> 0 | J36: =IF('Calculations PJ'!J36<>0,'Calculations PJ'!J36*About!$B$45,0) -> 0 | ... BH36: =IF('Calculations PJ'!BH36<>0,'Calculations PJ'!BH36*About!$B$45,0) -> 0
B37: refined petroleum and coke 19 | C37: =IF('Calculations PJ'!C37<>0,'Calculations PJ'!C37*About!$B$45,0) -> 0 | D37: =IF('Calculations PJ'!D37<>0,'Calculations PJ'!D37*About!$B$45,0) -> 0 | E37: =IF('Calculations PJ'!E37<>0,'Calculations PJ'!E37*About!$B$45,0) -> 0 | F37: =IF('Calculations PJ'!F37<>0,'Calculations PJ'!F37*About!$B$45,0) -> 0 | G37: =IF('Calculations PJ'!G37<>0,'Calculations PJ'!G37*About!$B$45,0) -> 0 | H37: =IF('Calculations PJ'!H37<>0,'Calculations PJ'!H37*About!$B$45,0) -> 0 | I37: =IF('Calculations PJ'!I37<>0,'Calculations PJ'!I37*About!$B$45,0) -> 0 | J37: =IF('Calculations PJ'!J37<>0,'Calculations PJ'!J37*About!$B$45,0) -> 0 | ... BH37: =IF('Calculations PJ'!BH37<>0,'Calculations PJ'!BH37*About!$B$45,0) -> 0
B38: chemicals 20 | C38: =IF('Calculations PJ'!C38<>0,'Calculations PJ'!C38*About!$B$45,0) -> 0 | D38: =IF('Calculations PJ'!D38<>0,'Calculations PJ'!D38*About!$B$45,0) -> 0 | E38: =IF('Calculations PJ'!E38<>0,'Calculations PJ'!E38*About!$B$45,0) -> 0 | F38: =IF('Calculations PJ'!F38<>0,'Calculations PJ'!F38*About!$B$45,0) -> 0 | G38: =IF('Calculations PJ'!G38<>0,'Calculations PJ'!G38*About!$B$45,0) -> 0 | H38: =IF('Calculations PJ'!H38<>0,'Calculations PJ'!H38*About!$B$45,0) -> 0 | I38: =IF('Calculations PJ'!I38<>0,'Calculations PJ'!I38*About!$B$45,0) -> 0 | J38: =IF('Calculations PJ'!J38<>0,'Calculations PJ'!J38*About!$B$45,0) -> 0 | ... BH38: =IF('Calculations PJ'!BH38<>0,'Calculations PJ'!BH38*About!$B$45,0) -> 0
B39: rubber and plastic products 22 | C39: =IF('Calculations PJ'!C39<>0,'Calculations PJ'!C39*About!$B$45,0) -> 0 | D39: =IF('Calculations PJ'!D39<>0,'Calculations PJ'!D39*About!$B$45,0) -> 0 | E39: =IF('Calculations PJ'!E39<>0,'Calculations PJ'!E39*About!$B$45,0) -> 0 | F39: =IF('Calculations PJ'!F39<>0,'Calculations PJ'!F39*About!$B$45,0) -> 0 | G39: =IF('Calculations PJ'!G39<>0,'Calculations PJ'!G39*About!$B$45,0) -> 0 | H39: =IF('Calculations PJ'!H39<>0,'Calculations PJ'!H39*About!$B$45,0) -> 0 | I39: =IF('Calculations PJ'!I39<>0,'Calculations PJ'!I39*About!$B$45,0) -> 0 | J39: =IF('Calculations PJ'!J39<>0,'Calculations PJ'!J39*About!$B$45,0) -> 0 | ... BH39: =IF('Calculations PJ'!BH39<>0,'Calculations PJ'!BH39*About!$B$45,0) -> 0
B40: glass and glass products 231 | C40: =IF('Calculations PJ'!C40<>0,'Calculations PJ'!C40*About!$B$45,0) -> 0 | D40: =IF('Calculations PJ'!D40<>0,'Calculations PJ'!D40*About!$B$45,0) -> 0 | E40: =IF('Calculations PJ'!E40<>0,'Calculations PJ'!E40*About!$B$45,0) -> 0 | F40: =IF('Calculations PJ'!F40<>0,'Calculations PJ'!F40*About!$B$45,0) -> 0 | G40: =IF('Calculations PJ'!G40<>0,'Calculations PJ'!G40*About!$B$45,0) -> 0 | H40: =IF('Calculations PJ'!H40<>0,'Calculations PJ'!H40*About!$B$45,0) -> 0 | I40: =IF('Calculations PJ'!I40<>0,'Calculations PJ'!I40*About!$B$45,0) -> 0 | J40: =IF('Calculations PJ'!J40<>0,'Calculations PJ'!J40*About!$B$45,0) -> 0 | ... BH40: =IF('Calculations PJ'!BH40<>0,'Calculations PJ'!BH40*About!$B$45,0) -> 0
... B53: construction 41T43 | C53: =IF('Calculations PJ'!C53<>0,'Calculations PJ'!C53*About!$B$45,0) -> 0 | D53: =IF('Calculations PJ'!D53<>0,'Calculations PJ'!D53*About!$B$45,0) -> 0 | E53: =IF('Calculations PJ'!E53<>0,'Calculations PJ'!E53*About!$B$45,0) -> 0 | F53: =IF('Calculations PJ'!F53<>0,'Calculations PJ'!F53*About!$B$45,0) -> 0 | G53: =IF('Calculations PJ'!G53<>0,'Calculations PJ'!G53*About!$B$45,0) -> 0 | H53: =IF('Calculations PJ'!H53<>0,'Calculations PJ'!H53*About!$B$45,0) -> 0 | I53: =IF('Calculations PJ'!I53<>0,'Calculations PJ'!I53*About!$B$45,0) -> 0 | J53: =IF('Calculations PJ'!J53<>0,'Calculations PJ'!J53*About!$B$45,0) -> 0 | ... BH53: =IF('Calculations PJ'!BH53<>0,'Calculations PJ'!BH53*About!$B$45,0) -> 0
A54: natural gas (PJ) | C54: =SUM(C55:C79) -> 1.1422984e+15 | D54: =SUM(D55:D79) -> 1.1530662e+15 | E54: =SUM(E55:E79) -> 1.1425922e+15 | F54: =SUM(F55:F79) -> 1.1850993e+15 | G54: =SUM(G55:G79) -> 1.3004074e+15 | H54: =SUM(H55:H79) -> 965203628038156 | I54: =SUM(I55:I79) -> 9.3207093e+14 | J54: =SUM(J55:J79) -> 896317383778001 | ... BH54: =SUM(BH55:BH79) -> 1.3192184e+15
B55: agriculture and forestry 01T03 | C55: =IF('Calculations PJ'!C55<>0,'Calculations PJ'!C55*About!$B$45,0) -> 4.9289091e+11 | D55: =IF('Calculations PJ'!D55<>0,'Calculations PJ'!D55*About!$B$45,0) -> 4.7393357e+11 | E55: =IF('Calculations PJ'!E55<>0,'Calculations PJ'!E55*About!$B$45,0) -> 3.6018951e+11 | F55: =IF('Calculations PJ'!F55<>0,'Calculations PJ'!F55*About!$B$45,0) -> 3.6966818e+11 | G55: =IF('Calculations PJ'!G55<>0,'Calculations PJ'!G55*About!$B$45,0) -> 0 | H55: =IF('Calculations PJ'!H55<>0,'Calculations PJ'!H55*About!$B$45,0) -> 3.0331748e+11 | I55: =IF('Calculations PJ'!I55<>0,'Calculations PJ'!I55*About!$B$45,0) -> 2.3696678e+11 | J55: =IF('Calculations PJ'!J55<>0,'Calculations PJ'!J55*About!$B$45,0) -> 2.0853077e+11 | ... BH55: =IF('Calculations PJ'!BH55<>0,'Calculations PJ'!BH55*About!$B$45,0) -> 2.1800944e+11
B56: coal mining 05 | C56: =IF('Calculations PJ'!C56<>0,'Calculations PJ'!C56*About!$B$45,0) -> 1.3180093e+12 | D56: =IF('Calculations PJ'!D56<>0,'Calculations PJ'!D56*About!$B$45,0) -> 9.5545008e+11 | E56: =IF('Calculations PJ'!E56<>0,'Calculations PJ'!E56*About!$B$45,0) -> 1.4360187e+12 | F56: =IF('Calculations PJ'!F56<>0,'Calculations PJ'!F56*About!$B$45,0) -> 1.5156396e+12 | G56: =IF('Calculations PJ'!G56<>0,'Calculations PJ'!G56*About!$B$45,0) -> 1.683412e+12 | H56: =IF('Calculations PJ'!H56<>0,'Calculations PJ'!H56*About!$B$45,0) -> 1.7488149e+12 | I56: =IF('Calculations PJ'!I56<>0,'Calculations PJ'!I56*About!$B$45,0) -> 1.8398101e+12 | J56: =IF('Calculations PJ'!J56<>0,'Calculations PJ'!J56*About!$B$45,0) -> 1.5938386e+12 | ... BH56: =IF('Calculations PJ'!BH56<>0,'Calculations PJ'!BH56*About!$B$45,0) -> 2.3488148e+12
B57: oil and gas extraction 06 | C57: =IF('Calculations PJ'!C57<>0,'Calculations PJ'!C57*About!$B$45,0) -> 0 | D57: =IF('Calculations PJ'!D57<>0,'Calculations PJ'!D57*About!$B$45,0) -> 0 | E57: =IF('Calculations PJ'!E57<>0,'Calculations PJ'!E57*About!$B$45,0) -> 0 | F57: =IF('Calculations PJ'!F57<>0,'Calculations PJ'!F57*About!$B$45,0) -> 0 | G57: =IF('Calculations PJ'!G57<>0,'Calculations PJ'!G57*About!$B$45,0) -> 0 | H57: =IF('Calculations PJ'!H57<>0,'Calculations PJ'!H57*About!$B$45,0) -> 0 | I57: =IF('Calculations PJ'!I57<>0,'Calculations PJ'!I57*About!$B$45,0) -> 0 | J57: =IF('Calculations PJ'!J57<>0,'Calculations PJ'!J57*About!$B$45,0) -> 0 | ... BH57: =IF('Calculations PJ'!BH57<>0,'Calculations PJ'!BH57*About!$B$45,0) -> 0
B58: other mining and quarrying 07T08 | C58: =IF('Calculations PJ'!C58<>0,'Calculations PJ'!C58*About!$B$45,0) -> 7.4687191e+12 | D58: =IF('Calculations PJ'!D58<>0,'Calculations PJ'!D58*About!$B$45,0) -> 5.4142171e+12 | E58: =IF('Calculations PJ'!E58<>0,'Calculations PJ'!E58*About!$B$45,0) -> 8.1374394e+12 | F58: =IF('Calculations PJ'!F58<>0,'Calculations PJ'!F58*About!$B$45,0) -> 8.5886241e+12 | G58: =IF('Calculations PJ'!G58<>0,'Calculations PJ'!G58*About!$B$45,0) -> 9.5393349e+12 | H58: =IF('Calculations PJ'!H58<>0,'Calculations PJ'!H58*About!$B$45,0) -> 9.9099509e+12 | I58: =IF('Calculations PJ'!I58<>0,'Calculations PJ'!I58*About!$B$45,0) -> 1.0425591e+13 | J58: =IF('Calculations PJ'!J58<>0,'Calculations PJ'!J58*About!$B$45,0) -> 9.031752e+12 | ... BH58: =IF('Calculations PJ'!BH58<>0,'Calculations PJ'!BH58*About!$B$45,0) -> 1.330995e+13
B59: food beverage and tobacco 10T12 | C59: =IF('Calculations PJ'!C59<>0,'Calculations PJ'!C59*About!$B$45,0) -> 1.5630329e+13 | D59: =IF('Calculations PJ'!D59<>0,'Calculations PJ'!D59*About!$B$45,0) -> 1.4218007e+13 | E59: =IF('Calculations PJ'!E59<>0,'Calculations PJ'!E59*About!$B$45,0) -> 1.5886253e+13 | F59: =IF('Calculations PJ'!F59<>0,'Calculations PJ'!F59*About!$B$45,0) -> 1.7791466e+13 | G59: =IF('Calculations PJ'!G59<>0,'Calculations PJ'!G59*About!$B$45,0) -> 1.9033172e+13 | H59: =IF('Calculations PJ'!H59<>0,'Calculations PJ'!H59*About!$B$45,0) -> 2.1090044e+13 | I59: =IF('Calculations PJ'!I59<>0,'Calculations PJ'!I59*About!$B$45,0) -> 2.3440754e+13 | J59: =IF('Calculations PJ'!J59<>0,'Calculations PJ'!J59*About!$B$45,0) -> 2.0322271e+13 | ... BH59: =IF('Calculations PJ'!BH59<>0,'Calculations PJ'!BH59*About!$B$45,0) -> 5.0028428e+13
B60: textiles apparel and leather 13T15 | C60: =IF('Calculations PJ'!C60<>0,'Calculations PJ'!C60*About!$B$45,0) -> 8.1706147e+12 | D60: =IF('Calculations PJ'!D60<>0,'Calculations PJ'!D60*About!$B$45,0) -> 8.104264e+12 | E60: =IF('Calculations PJ'!E60<>0,'Calculations PJ'!E60*About!$B$45,0) -> 8.5497616e+12 | F60: =IF('Calculations PJ'!F60<>0,'Calculations PJ'!F60*About!$B$45,0) -> 8.5876763e+12 | G60: =IF('Calculations PJ'!G60<>0,'Calculations PJ'!G60*About!$B$45,0) -> 8.3886242e+12 | H60: =IF('Calculations PJ'!H60<>0,'Calculations PJ'!H60*About!$B$45,0) -> 8.5876763e+12 | I60: =IF('Calculations PJ'!I60<>0,'Calculations PJ'!I60*About!$B$45,0) -> 8.0947854e+12 | J60: =IF('Calculations PJ'!J60<>0,'Calculations PJ'!J60*About!$B$45,0) -> 5.7535535e+12 | ... BH60: =IF('Calculations PJ'!BH60<>0,'Calculations PJ'!BH60*About!$B$45,0) -> 6.4862482e+12
B61: wood products 16 | C61: =IF('Calculations PJ'!C61<>0,'Calculations PJ'!C61*About!$B$45,0) -> 0 | D61: =IF('Calculations PJ'!D61<>0,'Calculations PJ'!D61*About!$B$45,0) -> 0 | E61: =IF('Calculations PJ'!E61<>0,'Calculations PJ'!E61*About!$B$45,0) -> 0 | F61: =IF('Calculations PJ'!F61<>0,'Calculations PJ'!F61*About!$B$45,0) -> 0 | G61: =IF('Calculations PJ'!G61<>0,'Calculations PJ'!G61*About!$B$45,0) -> 0 | H61: =IF('Calculations PJ'!H61<>0,'Calculations PJ'!H61*About!$B$45,0) -> 0 | I61: =IF('Calculations PJ'!I61<>0,'Calculations PJ'!I61*About!$B$45,0) -> 0 | J61: =IF('Calculations PJ'!J61<>0,'Calculations PJ'!J61*About!$B$45,0) -> 0 | ... BH61: =IF('Calculations PJ'!BH61<>0,'Calculations PJ'!BH61*About!$B$45,0) -> 0
B62: pulp paper and printing 17T18 | C62: =IF('Calculations PJ'!C62<>0,'Calculations PJ'!C62*About!$B$45,0) -> 3.0957341e+13 | D62: =IF('Calculations PJ'!D62<>0,'Calculations PJ'!D62*About!$B$45,0) -> 2.9355445e+13 | E62: =IF('Calculations PJ'!E62<>0,'Calculations PJ'!E62*About!$B$45,0) -> 3.0303312e+13 | F62: =IF('Calculations PJ'!F62<>0,'Calculations PJ'!F62*About!$B$45,0) -> 3.3573454e+13 | G62: =IF('Calculations PJ'!G62<>0,'Calculations PJ'!G62*About!$B$45,0) -> 3.2180089e+13 | H62: =IF('Calculations PJ'!H62<>0,'Calculations PJ'!H62*About!$B$45,0) -> 3.3383881e+13 | I62: =IF('Calculations PJ'!I62<>0,'Calculations PJ'!I62*About!$B$45,0) -> 3.45308e+13 | J62: =IF('Calculations PJ'!J62<>0,'Calculations PJ'!J62*About!$B$45,0) -> 2.9924166e+13 | ... BH62: =IF('Calculations PJ'!BH62<>0,'Calculations PJ'!BH62*About!$B$45,0) -> 3.9611368e+13
B63: refined petroleum and coke 19 | C63: =IF('Calculations PJ'!C63<>0,'Calculations PJ'!C63*About!$B$45,0) -> 1.4228908e+14 | D63: =IF('Calculations PJ'!D63<>0,'Calculations PJ'!D63*About!$B$45,0) -> 1.3790045e+14 | E63: =IF('Calculations PJ'!E63<>0,'Calculations PJ'!E63*About!$B$45,0) -> 5.1398096e+13 | F63: =IF('Calculations PJ'!F63<>0,'Calculations PJ'!F63*About!$B$45,0) -> 3.9061605e+13 | G63: =IF('Calculations PJ'!G63<>0,'Calculations PJ'!G63*About!$B$45,0) -> 5.7563971e+13 | H63: =IF('Calculations PJ'!H63<>0,'Calculations PJ'!H63*About!$B$45,0) -> 9.6777235e+12 | I63: =IF('Calculations PJ'!I63<>0,'Calculations PJ'!I63*About!$B$45,0) -> 2.4298574e+13 | J63: =IF('Calculations PJ'!J63<>0,'Calculations PJ'!J63*About!$B$45,0) -> 1.9056869e+13 | ... BH63: =IF('Calculations PJ'!BH63<>0,'Calculations PJ'!BH63*About!$B$45,0) -> 4.0572132e+13
B64: chemicals 20 | C64: =IF('Calculations PJ'!C64<>0,'Calculations PJ'!C64*About!$B$45,0) -> 6.2834113e+13 | D64: =IF('Calculations PJ'!D64<>0,'Calculations PJ'!D64*About!$B$45,0) -> 7.4388613e+13 | E64: =IF('Calculations PJ'!E64<>0,'Calculations PJ'!E64*About!$B$45,0) -> 6.7658756e+13 | F64: =IF('Calculations PJ'!F64<>0,'Calculations PJ'!F64*About!$B$45,0) -> 7.0047382e+13 | G64: =IF('Calculations PJ'!G64<>0,'Calculations PJ'!G64*About!$B$45,0) -> 7.7137428e+13 | H64: =IF('Calculations PJ'!H64<>0,'Calculations PJ'!H64*About!$B$45,0) -> 8.1270128e+13 | I64: =IF('Calculations PJ'!I64<>0,'Calculations PJ'!I64*About!$B$45,0) -> 7.6530793e+13 | J64: =IF('Calculations PJ'!J64<>0,'Calculations PJ'!J64*About!$B$45,0) -> 7.4540272e+13 | ... BH64: =IF('Calculations PJ'!BH64<>0,'Calculations PJ'!BH64*About!$B$45,0) -> 1.0369666e+14
...

Sheet BIFUbC-electricity
