Workbook

Sheet About
A1: VBDR Vehicle Buyer Discount Rate
A3: Source: | B3: Secretaría de Hacienda y Crédito Público
B4: 2020
B5: Tasa Social de Descuento (TSD)
B6: https://www.gob.mx/shcp/documentos/tasa-social-de-descuento-tsd
A9: Mexico Notes:
A10: We used the official government discount rate for consistency and according to
A11: the available data.
A12: US Notes
A13: Vehicle buyer discount rates vary tremendously by study.
A14: The implied discount rate is sensitive to numerous assumptions
A15: the underlying studies might make, such as what lifetime
A16: or future fuel price consumers are expecting. Accordingly,
A17: there is no consensus on what a reasonable discount rate
A18: might be.
A20: We use a value of 15%, as it falls between values of 12% and
A21: greater than 17% in the studies cited above.
... A26: a company that purchases trucks.

Sheet Cuadros Iniciales
A1: Mexico: Tasa Social de Descuento
A2: [Estimacion. Fecha: Marzo 8, 2022]
A4: Nomenclatura INEGI | B4: B.1b - Valor agregado bruto / Producto interno bruto a precios de mercado | C4: Impuestos netos sobre la producción (D.21 - Impuestos sobre los productos menos D.31 - Subsidios a los productos) | D4: Valor agregado bruto a precios básicos | E4: D.1 - Remuneración de los asalariados | F4: Otros impuestos netos sobre la producción (D.29 - Otros impuestos sobre la producción menos D.39 - Otros subsidios a la producción) | G4: B.3b - Ingreso mixto bruto | H4: B.2b - Excedente bruto de operación | J4: Nomenclatura INEGI | K4: Valor agregado bruto a precios básicos | L4: D.1 - Remuneración de los asalariados sobre Valor agregado bruto a precios básicos | M4: P.51c - Consumo de capital fijo | N4: Producto Interno Neto a precios básicos (Valor agregado bruto a precios básicos menos P.51c - Consumo de capital fijo) | O4: D.1 - Remuneración de los asalariados sobre Valor agregado neto a precios básicos | P4: B.3b - Ingreso mixto bruto | Q4: Valor agregado neto a precios básicos menos B.3b - Ingreso mixto bruto | R4: D.1 - Remuneración de los asalariados sobre Valor agregado bruto a precios básicos menos B.3b - Ingreso mixto bruto | T4: Nomenclatura INEGI | U4: D.1 - Remuneración de los asalariados ajustado por B.3b - Ingreso mixto bruto (método LS4) | V4: D.1 - Remuneración de los asalariados ajustado (LS4) sobre Producto Interno Neto a precios básicos | W4: D.1 - Remuneración de los asalariados ajustado por B.3b - Ingreso mixto bruto (método LS5) | X4: D.1 - Remuneración de los asalariados ajustado (LS5) sobre Producto Interno Neto a precios básicos | Y4: D.1 - Remuneración de los asalariados ajustado por B.3b - Ingreso mixto bruto | Z4: D.1 - Remuneración de los asalariados promedio ajustado sobre Producto Interno Neto a precios básicos | AB4: Nomenclatura INEGI | AC4: D.1 - Remuneración de los asalariados promedio ajustado por B.3b - Ingreso mixto bruto [Promedio de metodo LS4 y LS5] | AD4: Ingreso de capital (Producto Interno Neto a precios básicos menos D.1 Remuneración de los asalariados ajustado) | AE4: Ingresos netos de capital sobre Producto Interno Neto a precios básicos | AF4: Ingresos netos de capital sobre B.1b - Producto interno bruto a precios de mercado | AH4: Nomenclatura INEGI | AI4: D.1 - Remuneración de los asalariados ajustado por B.3b - Ingreso mixto bruto (método LS4) | AJ4: D.1 - Remuneración de los asalariados ajustado (LS4) sobre Producto Interno Neto a precios básicos | AK4: Empleadores | AL4: Trabajadores subordinados y remunerados | AM4: Trabajadores por cuenta propia | AN4: D.1 - Remuneración de los asalariados por Trabajadores por cuenta propia e B.3b - Ingreso mixto bruto (LS5)
A6: Cuadro 1 | J6: Cuadro 2.1 | T6: Cuadro 2.2 | AB6: Cuadro 2.3 | AH6: Cuadro Intermedio A
A7: México: Cuentas Nacionales [1000 millones de Pesos Constantes de 2013] | J7: México: Remuneracion Asalariados (1000 millones de Pesos) y participación porcentual | T7: Remuneracion Asalariados ajustados por participación en ingreso mixto | AB7: Remuneracion asalariados ajustados e ingresos de capital | AH7: Ajuste al ingreso laboral [LS4 y LS5]
A8: Año | B8: PIB a precios de mercado, precios constantes de 2013 | C8: Impuestos indirectos a la producción netos de subsidios | D8: Producto Interno Bruto a precio de factores | E8: Remuneración de los asalariados | F8: Otros impuestos sobre la producción - Otros subsidios a la producción | G8: Ingreso mixto bruto | H8: Excedente Bruto de Operación (PIB P. factores, menos Rem. Asal., menos Ing. Mixto menos otros impuestos) | J8: Año | K8: Producto Interno Bruto a precio de factores = PIB a precios de mercado - Impuestos indirectos netos | L8: Remuneración de los asalariados / Valor agregado bruto a precio de factores | M8: Consumo de capital fijo | N8: Producto Interno Neto a precio de Factores (VBA - Depreciación) | O8: Remuneración de los asalariados / Producto Interno Neto a precio de factores | P8: Ingreso mixto bruto | Q8: Producto Interno Neto a costo de factores - Ingreso mixto bruto | R8: Remuneración de los asalariados/Producto Interno Neto a precio de factores menos ingreso mixto | T8: Año | U8: Remuneracion asalariados ajustado por ingreso mixto bruto (método LS4) | V8: Remuneracion asalariados ajustado (LS4) sobre Producto Iinterno Neto a precio de factores | W8: Remuneracion asalariados ajustado por ingresos mixtos (método LS5) | X8: Remuneracion asalariados ajustado (LS5) sobre PIN a costos de factores | Y8: Remuneracion asalariados promedio ajustado por ingresos mixtos [Promedio de metodo LS4 y LS5] | Z8: Remuneracion asalariados promedio ajustado sobre PIN a costos de factores | AB8: Año | AC8: Remuneracion asalariados promedio ajustado por ingresos mixtos [Promedio de metodo LS4 y LS5] | AD8: Ingreso de neto capital (PIN neto - Remuneracion asalariados ajustado) | AE8: Ingresos netos de capital sobre PIN (precio de factores) | AF8: Ingresos netos de capital sobre PIB | AH8: Año | AI8: Ingreso laboral ajustado por ingresos mixtos (método LS4) | AJ8: Ingreso laboral ajustado (LS4) sobre PIN a costos de factores | AK8: Empleadores [Miles] | AL8: Empleados [miles] | AM8: Empleados Propios [miles] | AN8: Ingreso laboral ajustado por empleo propio e ingreso mixto (LS5)
B9: [A] | C9: [B] | D9: [C=A-B] | E9: [D] | F9: [E] | G9: [F] | H9: [G] | K9: [H=C] | L9: [I=E/C] | M9: [J] | N9: [K=H-J] | O9: [L=E/K] | P9: [M=F] | Q9: [N=K-M] | R9: [=E/N)] | U9: O | V9: P | W9: Q | X9: R | Y9: S | Z9: T | AC9: S | AD9: U | AE9: V | AF9: W | AI9: O | AJ9: P | AK9: X | AL9: Y | AM9: Z | AN9: Q
D10: [=D+E+F+G]
A12: 2003 | B12: =E188/1000 -> 13061.782 | C12: =D188/1000 -> 652.70313 | D12: =B12-C12 -> 12409.079 | E12: =H188/1000 -> 3904.647 | F12: =(O188+P188)/1000 -> 76.609375 | G12: =J188/1000 -> 2592.9611 | H12: =I188/1000 -> 5834.8618 | J12: 2003 | K12: =D12 -> 12409.079 | L12: =E12/K12 -> 0.31466049 | M12: =F188/1000 -> 1905.7807 | N12: =K12-M12 -> 10503.299 | O12: =E12/N12 -> 0.37175436 | P12: =G12 -> 2592.9611 | Q12: =N12-P12 -> 7910.3375 | R12: =E12/Q12 -> 0.4936132 | T12: =A12 -> 2003 | U12: =+AI12 -> 5184.5668 | V12: =+AJ12 -> 0.4936132 | W12: =+AN12 -> 5343.5147 | X12: =+W12/N12 -> 0.50874634 | Y12: =+U12/2+W12/2 -> 5264.0408 | Z12: =+Y12/N12 -> 0.50117977 | AB12: 2003 | AC12: =+AI12/2+AN12/2 -> 5264.0408 | AD12: =N12-AC12 -> 5239.2578 | AE12: =AD12/N12 -> 0.49882023 | AF12: =AD12/B12 -> 0.40111354 | AH12: 2003 | AI12: =+E12+P12*R12 -> 5184.5668 | AJ12: =+AI12/N12 -> 0.4936132 | AK12: 2018.0327 | AL12: 26795.213 | AM12: 9874.0723 | AN12: =+E12/AL12*(AL12+AM12) -> 5343.5147
A13: 2004 | B13: =E189/1000 -> 13573.751 | C13: =D189/1000 -> 600.16722 | D13: =B13-C13 -> 12973.583 | E13: =H189/1000 -> 3892.1199 | F13: =(O189+P189)/1000 -> 62.710278 | G13: =J189/1000 -> 2690.8319 | H13: =I189/1000 -> 6327.9213 | J13: 2004 | K13: =D13 -> 12973.583 | L13: =E13/K13 -> 0.30000346 | M13: =F189/1000 -> 1975.8862 | N13: =K13-M13 -> 10997.697 | O13: =E13/N13 -> 0.35390317 | P13: =G13 -> 2690.8319 | Q13: =N13-P13 -> 8306.8653 | R13: =E13/Q13 -> 0.46854256 | T13: =A13 -> 2004 | U13: =+AI13 -> 5152.8892 | V13: =+AJ13 -> 0.46854256 | W13: =+AN13 -> 5314.1816 | X13: =+W13/N13 -> 0.48320858 | Y13: =+U13/2+W13/2 -> 5233.5354 | Z13: =+Y13/N13 -> 0.47587557 | AB13: 2004 | AC13: =+AI13/2+AN13/2 -> 5233.5354 | AD13: =N13-AC13 -> 5764.1618 | AE13: =AD13/N13 -> 0.52412443 | AF13: =AD13/B13 -> 0.42465505 | AH13: 2004 | AI13: =+E13+P13*R13 -> 5152.8892 | AJ13: =+AI13/N13 -> 0.46854256 | AK13: 2022.6695 | AL13: 27283.601 | AM13: 9968.5942 | AN13: =+E13/AL13*(AL13+AM13) -> 5314.1816
A14: 2005 | B14: =E190/1000 -> 13887.087 | C14: =D190/1000 -> 574.60832 | D14: =B14-C14 -> 13312.479 | E14: =H190/1000 -> 3940.9369 | F14: =(O190+P190)/1000 -> 66.770518 | G14: =J190/1000 -> 2764.2975 | H14: =I190/1000 -> 6540.4738 | J14: 2005 | K14: =D14 -> 13312.479 | L14: =E14/K14 -> 0.29603329 | M14: =F190/1000 -> 2001.6892 | N14: =K14-M14 -> 11310.789 | O14: =E14/N14 -> 0.3484228 | P14: =G14 -> 2764.2975 | Q14: =N14-P14 -> 8546.4919 | R14: =E14/Q14 -> 0.46111749 | T14: =A14 -> 2005 | U14: =+AI14 -> 5215.6028 | V14: =+AJ14 -> 0.46111749 | W14: =+AN14 -> 5368.5971 | X14: =+W14/N14 -> 0.47464389 | Y14: =+U14/2+W14/2 -> 5292.0999 | Z14: =+Y14/N14 -> 0.46788069 | AB14: 2005 | AC14: =+AI14/2+AN14/2 -> 5292.0999 | AD14: =N14-AC14 -> 6018.6895 | AE14: =AD14/N14 -> 0.53211931 | AF14: =AD14/B14 -> 0.43340187 | AH14: 2005 | AI14: =+E14+P14*R14 -> 5215.6028 | AJ14: =+AI14/N14 -> 0.46111749 | AK14: 2027.317 | AL14: 27780.891 | AM14: 10064.021 | AN14: =+E14/AL14*(AL14+AM14) -> 5368.5971
A15: 2006 | B15: =E191/1000 -> 14511.247 | C15: =D191/1000 -> 546.00585 | D15: =B15-C15 -> 13965.241 | E15: =H191/1000 -> 4035.5651 | F15: =(O191+P191)/1000 -> 72.893254 | G15: =J191/1000 -> 2842.0095 | H15: =I191/1000 -> 7014.7731 | J15: 2006 | K15: =D15 -> 13965.241 | L15: =E15/K15 -> 0.28897211 | M15: =F191/1000 -> 2072.7348 | N15: =K15-M15 -> 11892.506 | O15: =E15/N15 -> 0.33933681 | P15: =G15 -> 2842.0095 | Q15: =N15-P15 -> 9050.4967 | R15: =E15/Q15 -> 0.44589432 | T15: =A15 -> 2006 | U15: =+AI15 -> 5302.801 | V15: =+AJ15 -> 0.44589432 | W15: =+AN15 -> 5445.8034 | X15: =+W15/N15 -> 0.4579189 | Y15: =+U15/2+W15/2 -> 5374.3022 | Z15: =+Y15/N15 -> 0.45190661 | AB15: 2006 | AC15: =+AI15/2+AN15/2 -> 5374.3022 | AD15: =N15-AC15 -> 6518.204 | AE15: =AD15/N15 -> 0.54809339 | AF15: =AD15/B15 -> 0.4491829 | AH15: 2006 | AI15: =+E15+P15*R15 -> 5302.801 | AJ15: =+AI15/N15 -> 0.44589432 | AK15: 2173.431 | AL15: 28741.961 | AM15: 10043.95 | AN15: =+E15/AL15*(AL15+AM15) -> 5445.8034
A16: 2007 | B16: =E192/1000 -> 14843.777 | C16: =D192/1000 -> 563.73801 | D16: =B16-C16 -> 14280.039 | E16: =H192/1000 -> 4087.1089 | F16: =(O192+P192)/1000 -> 77.238058 | G16: =J192/1000 -> 2924.1226 | H16: =I192/1000 -> 7191.5693 | J16: 2007 | K16: =D16 -> 14280.039 | L16: =E16/K16 -> 0.28621133 | M16: =F192/1000 -> 2132.267 | N16: =K16-M16 -> 12147.772 | O16: =E16/N16 -> 0.33644926 | P16: =G16 -> 2924.1226 | Q16: =N16-P16 -> 9223.6493 | R16: =E16/Q16 -> 0.44311191 | T16: =A16 -> 2007 | U16: =+AI16 -> 5382.8224 | V16: =+AJ16 -> 0.44311191 | W16: =+AN16 -> 5477.2169 | X16: =+W16/N16 -> 0.45088243 | Y16: =+U16/2+W16/2 -> 5430.0197 | Z16: =+Y16/N16 -> 0.44699717 | AB16: 2007 | AC16: =+AI16/2+AN16/2 -> 5430.0197 | AD16: =N16-AC16 -> 6717.7522 | AE16: =AD16/N16 -> 0.55300283 | AF16: =AD16/B16 -> 0.45256354 | AH16: 2007 | AI16: =+E16+P16*R16 -> 5382.8224 | AJ16: =+AI16/N16 -> 0.44311191 | AK16: 2277.608 | AL16: 29738.598 | AM16: 10114.696 | AN16: =+E16/AL16*(AL16+AM16) -> 5477.2169
A17: 2008 | B17: =E193/1000 -> 15013.666 | C17: =D193/1000 -> 384.51702 | D17: =B17-C17 -> 14629.149 | E17: =H193/1000 -> 4161.8564 | F17: =(O193+P193)/1000 -> 78.952161 | G17: =J193/1000 -> 2954.9107 | H17: =I193/1000 -> 7433.4302 | J17: 2008 | K17: =D17 -> 14629.149 | L17: =E17/K17 -> 0.28449066 | M17: =F193/1000 -> 2228.5749 | N17: =K17-M17 -> 12400.575 | O17: =E17/N17 -> 0.33561803 | P17: =G17 -> 2954.9107 | Q17: =N17-P17 -> 9445.6639 | R17: =E17/Q17 -> 0.44061026 | T17: =A17 -> 2008 | U17: =+AI17 -> 5463.8203 | V17: =+AJ17 -> 0.44061026 | W17: =+AN17 -> 5470.5242 | X17: =+W17/N17 -> 0.44115086 | Y17: =+U17/2+W17/2 -> 5467.1722 | Z17: =+Y17/N17 -> 0.44088056 | AB17: 2008 | AC17: =+AI17/2+AN17/2 -> 5467.1722 | AD17: =N17-AC17 -> 6933.4023 | AE17: =AD17/N17 -> 0.55911944 | AF17: =AD17/B17 -> 0.46180607 | AH17: 2008 | AI17: =+E17+P17*R17 -> 5463.8203 | AJ17: =+AI17/N17 -> 0.44061026 | AK17: 1824.004 | AL17: 30474.427 | AM17: 9582.479 | AN17: =+E17/AL17*(AL17+AM17) -> 5470.5242
A18: 2009 | B18: =E194/1000 -> 14219.965 | C18: =D194/1000 -> 589.07349 | D18: =B18-C18 -> 13630.892 | E18: =H194/1000 -> 4106.0384 | F18: =(O194+P194)/1000 -> 77.708987 | G18: =J194/1000 -> 3137.3444 | H18: =I194/1000 -> 6309.7999 | J18: 2009 | K18: =D18 -> 13630.892 | L18: =E18/K18 -> 0.30123036 | M18: =F194/1000 -> 2355.8143 | N18: =K18-M18 -> 11275.077 | O18: =E18/N18 -> 0.36416942 | P18: =G18 -> 3137.3444 | Q18: =N18-P18 -> 8137.733 | R18: =E18/Q18 -> 0.50456785 | T18: =A18 -> 2009 | U18: =+AI18 -> 5689.0416 | V18: =+AJ18 -> 0.50456785 | W18: =+AN18 -> 5587.3097 | X18: =+W18/N18 -> 0.49554513 | Y18: =+U18/2+W18/2 -> 5638.1756 | Z18: =+Y18/N18 -> 0.50005649 | AB18: 2009 | AC18: =+AI18/2+AN18/2 -> 5638.1756 | AD18: =N18-AC18 -> 5636.9018 | AE18: =AD18/N18 -> 0.49994351 | AF18: =AD18/B18 -> 0.39640756 | AH18: 2009 | AI18: =+E18+P18*R18 -> 5689.0416 | AJ18: =+AI18/N18 -> 0.50456785 | AK18: 2088.232 | AL18: 30190.632 | AM18: 10891.402 | AN18: =+E18/AL18*(AL18+AM18) -> 5587.3097
A19: 2010 | B19: =E195/1000 -> 14947.861 | C19: =D195/1000 -> 606.30281 | D19: =B19-C19 -> 14341.558 | E19: =H195/1000 -> 4161.8252 | F19: =(O195+P195)/1000 -> 81.017158 | G19: =J195/1000 -> 3329.7584 | H19: =I195/1000 -> 6768.9572 | J19: 2010 | K19: =D19 -> 14341.558 | L19: =E19/K19 -> 0.29019338 | M19: =F195/1000 -> 2363.1719 | N19: =K19-M19 -> 11978.386 | O19: =E19/N19 -> 0.34744457 | P19: =G19 -> 3329.7584 | Q19: =N19-P19 -> 8648.6277 | R19: =E19/Q19 -> 0.48121221 | T19: =A19 -> 2010 | U19: =+AI19 -> 5764.1456 | V19: =+AJ19 -> 0.48121221 | W19: =+AN19 -> 5372.5348 | X19: =+W19/N19 -> 0.44851909 | Y19: =+U19/2+W19/2 -> 5568.3402 | Z19: =+Y19/N19 -> 0.46486565 | AB19: 2010 | AC19: =+AI19/2+AN19/2 -> 5568.3402 | AD19: =N19-AC19 -> 6410.0459 | AE19: =AD19/N19 -> 0.53513435 | AF19: =AD19/B19 -> 0.42882697 | AH19: 2010 | AI19: =+E19+P19*R19 -> 5764.1456 | AJ19: =+AI19/N19 -> 0.48121221 | AK19: 1764.154 | AL19: 31926.649 | AM19: 9287.728 | AN19: =+E19/AL19*(AL19+AM19) -> 5372.5348
A20: 2011 | B20: =E196/1000 -> 15495.353 | C20: =D196/1000 -> 533.39175 | D20: =B20-C20 -> 14961.961 | E20: =H196/1000 -> 4228.9734 | F20: =(O196+P196)/1000 -> 84.389516 | G20: =J196/1000 -> 3380.8626 | H20: =I196/1000 -> 7267.7353 | J20: 2011 | K20: =D20 -> 14961.961 | L20: =E20/K20 -> 0.28264834 | M20: =F196/1000 -> 2425.8521 | N20: =K20-M20 -> 12536.109 | O20: =E20/N20 -> 0.33734339 | P20: =G20 -> 3380.8626 | Q20: =N20-P20 -> 9155.2461 | R20: =E20/Q20 -> 0.46191805 | T20: =A20 -> 2011 | U20: =+AI20 -> 5790.6549 | V20: =+AJ20 -> 0.46191805 | W20: =+AN20 -> 5672.792 | X20: =+W20/N20 -> 0.45251618 | Y20: =+U20/2+W20/2 -> 5731.7234 | Z20: =+Y20/N20 -> 0.45721711 | AB20: 2011 | AC20: =+AI20/2+AN20/2 -> 5731.7234 | AD20: =N20-AC20 -> 6804.3853 | AE20: =AD20/N20 -> 0.54278289 | AF20: =AD20/B20 -> 0.43912426 | AH20: 2011 | AI20: =+E20+P20*R20 -> 5790.6549 | AJ20: =+AI20/N20 -> 0.46191805 | AK20: 2325.825 | AL20: 31973.036 | AM20: 10915.95 | AN20: =+E20/AL20*(AL20+AM20) -> 5672.792
A21: 2012 | B21: =E197/1000 -> 16059.775 | C21: =D197/1000 -> 490.20223 | D21: =B21-C21 -> 15569.573 | E21: =H197/1000 -> 4385.8549 | F21: =(O197+P197)/1000 -> 79.331005 | G21: =J197/1000 -> 3366.7221 | H21: =I197/1000 -> 7737.6651 | J21: 2012 | K21: =D21 -> 15569.573 | L21: =E21/K21 -> 0.28169397 | M21: =F197/1000 -> 2547.2476 | N21: =K21-M21 -> 13022.326 | O21: =E21/N21 -> 0.33679506 | P21: =G21 -> 3366.7221 | Q21: =N21-P21 -> 9655.6035 | R21: =E21/Q21 -> 0.45422898 | T21: =A21 -> 2012 | U21: =+AI21 -> 5915.1177 | V21: =+AJ21 -> 0.45422898 | W21: =+AN21 -> 5673.182 | X21: =+W21/N21 -> 0.43565045 | Y21: =+U21/2+W21/2 -> 5794.1499 | Z21: =+Y21/N21 -> 0.44493972 | AB21: 2012 | AC21: =+AI21/2+AN21/2 -> 5794.1499 | AD21: =N21-AC21 -> 7228.1757 | AE21: =AD21/N21 -> 0.55506028 | AF21: =AD21/B21 -> 0.4500795 | AH21: 2012 | AI21: =+E21+P21*R21 -> 5915.1177 | AJ21: =+AI21/N21 -> 0.45422898 | AK21: 1903.568 | AL21: 33962.012 | AM21: 9968.46 | AN21: =+E21/AL21*(AL21+AM21) -> 5673.182
A22: 2013 | B22: =E198/1000 -> 16277.187 | C22: =D198/1000 -> 634.56723 | D22: =B22-C22 -> 15642.62 | E22: =H198/1000 -> 4542.8534 | F22: =(O198+P198)/1000 -> 87.418506 | G22: =J198/1000 -> 3477.7761 | H22: =I198/1000 -> 7534.5719 | J22: 2013 | K22: =D22 -> 15642.62 | L22: =E22/K22 -> 0.29041512 | M22: =F198/1000 -> 2567.2304 | N22: =K22-M22 -> 13075.389 | O22: =E22/N22 -> 0.34743542 | P22: =G22 -> 3477.7761 | Q22: =N22-P22 -> 9597.6133 | R22: =E22/Q22 -> 0.47333157 | T22: =A22 -> 2013 | U22: =+AI22 -> 6188.9946 | V22: =+AJ22 -> 0.47333157 | W22: =+AN22 -> 6042.4506 | X22: =+W22/N22 -> 0.46212395 | Y22: =+U22/2+W22/2 -> 6115.7226 | Z22: =+Y22/N22 -> 0.46772776 | AB22: 2013 | AC22: =+AI22/2+AN22/2 -> 6115.7226 | AD22: =N22-AC22 -> 6959.6668 | AE22: =AD22/N22 -> 0.53227224 | AF22: =AD22/B22 -> 0.42757184 | AH22: 2013 | AI22: =+E22+P22*R22 -> 6188.9946 | AJ22: =+AI22/N22 -> 0.47333157 | AK22: 2292.799 | AL22: 33614.596 | AM22: 11096.188 | AN22: =+E22/AL22*(AL22+AM22) -> 6042.4506
A23: 2014 | B23: =E199/1000 -> 16741.005 | C23: =D199/1000 -> 865.89918 | D23: =B23-C23 -> 15875.106 | E23: =H199/1000 -> 4598.6768 | F23: =(O199+P199)/1000 -> 94.057776 | G23: =J199/1000 -> 3518.499 | H23: =I199/1000 -> 7663.8722 | J23: 2014 | K23: =D23 -> 15875.106 | L23: =E23/K23 -> 0.2896785 | M23: =F199/1000 -> 2607.4836 | N23: =K23-M23 -> 13267.622 | O23: =E23/N23 -> 0.34660896 | P23: =G23 -> 3518.499 | Q23: =N23-P23 -> 9749.1232 | R23: =E23/Q23 -> 0.47170158 | T23: =A23 -> 2014 | U23: =+AI23 -> 6258.3583 | V23: =+AJ23 -> 0.47170158 | W23: =+AN23 -> 6117.9515 | X23: =+W23/N23 -> 0.46111891 | Y23: =+U23/2+W23/2 -> 6188.1549 | Z23: =+Y23/N23 -> 0.46641024 | AB23: 2014 | AC23: =+AI23/2+AN23/2 -> 6188.1549 | AD23: =N23-AC23 -> 7079.4673 | AE23: =AD23/N23 -> 0.53358976 | AF23: =AD23/B23 -> 0.42288186 | AH23: 2014 | AI23: =+E23+P23*R23 -> 6258.3583 | AJ23: =+AI23/N23 -> 0.47170158 | AK23: 2072.609 | AL23: 33836.47 | AM23: 11178.627 | AN23: =+E23/AL23*(AL23+AM23) -> 6117.9515
... A29: 2020 | B29: =E205/1000 -> 17159.654 | C29: =D205/1000 -> 1082.4056 | D29: =B29-C29 -> 16077.248 | E29: =H205/1000 -> 4874.5058 | F29: =(O205+P205)/1000 -> 105.32828 | G29: =J205/1000 -> 3443.5929 | H29: =I205/1000 -> 7653.8215 | J29: 2020 | K29: =D29 -> 16077.248 | L29: =E29/K29 -> 0.30319279 | M29: =F205/1000 -> 3384.7223 | N29: =K29-M29 -> 12692.526 | O29: =E29/N29 -> 0.38404536 | P29: =G29 -> 3443.5929 | Q29: =N29-P29 -> 9248.9333 | R29: =E29/Q29 -> 0.52703438 | T29: =A29 -> 2020 | U29: =+AI29 -> 6689.3976 | V29: =+AJ29 -> 0.52703438 | W29: =+AN29 -> 6493.6035 | X29: =+W29/N29 -> 0.51160844 | Y29: =+U29/2+W29/2 -> 6591.5006 | Z29: =+Y29/N29 -> 0.51932141 | AB29: 2020 | AC29: =+AI29/2+AN29/2 -> 6591.5006 | AD29: =N29-AC29 -> 6101.0256 | AE29: =AD29/N29 -> 0.48067859 | AF29: =AD29/B29 -> 0.35554479 | AH29: 2020 | AI29: =+E29+P29*R29 -> 6689.3976 | AJ29: =+AI29/N29 -> 0.52703438 | AK29: 2427.313 | AL29: 36585.968 | AM29: 12152.259 | AN29: =+E29/AL29*(AL29+AM29) -> 6493.6035
A33: Nomenclatura INEGI | B33: Valores Reales, Stocks de Capital, Construcción, K Stocks (C) | C33: Valores Reales, Stocks de Capital, Equipos, K Stocks (E) | D33: Valores Reales, Stocks de Capital, Total, K Stocks (C+E) | E33: P.51c - Consumo de capital fijo | F33: P.52/N.12 - Variación de existencias por tipo de activo | H33: Nomenclatura INEGI | I33: Formación bruta de capital fijo > Total Construcción | J33: Formación bruta de capital fijo > Total Maquinaria y equipo | K33: Formación bruta de capital fijo > Total | L33: P.51c - Consumo de capital fijo sobre B.1b - Producto interno bruto a precios de mercado | M33: % de Acervo de Capital | N33: Formación bruta de capital fijo > Total Construcción | O33: Formación bruta de capital fijo > Total Maquinaria y equipo | P33: Formación bruta de capital fijo > Total Construcción Real | Q33: P.51c - Consumo de capital fijo | R33: ormación bruta de capital fijo > Total Construcción Real sobre Producto interno bruto a precios de mercado | S33: P.51c - Consumo de capital fijo sobre Producto interno bruto a precios de mercado | U33: Nomenclatura INEGI | V33: Inversión Total | W33: Formación bruta de capital fijo > Privada Construcción | X33: Formación bruta de capital fijo > Privada Maquinaria y equipo | Y33: Formación bruta de capital fijo > Pública Construcción | Z33: Formación bruta de capital fijo > Pública Maquinaria y equipo | AA33: Stock Capital Privado-Construcción | AB33: Stock Capital Privado-Equipos | AC33: Stock Capital Publico-Construcción | AD33: Stock Capital Publico-Equipos | AE33: Total de stocks de capital | AH33: Nomenclatura INEGI | AI33: Stocks de capital total | AJ33: Stocks de capital privados | AK33: Stocks de capital público | AL33: Stocks de capital privado sobre Stock de capital total | AM33: Stocks de capital público sobre Stock de capital total | AN33: Stocks de capital privado sobre Producto interno bruto a precios de mercado | AO33: Stocks de capital público sobre Producto interno bruto a precios de mercado | AP33: Stocks de capital total sobre Producto interno bruto a precios de mercado | AR33: Nomenclatura INEGI | AS33: P.51c - Consumo de capital fijo | AT33: P.52/N.12 - Variación de existencias por tipo de activo | AU33: Inversión total sobre PIB | AV33: Formación bruta de capital fijo> Privada Construcción sobre Producto interno bruto a precios de mercado | AW33: Formación bruta de capital fijo > Privada Maquinaria y equipo sobre Producto interno bruto a precios de mercado | AX33: Formación bruta de capital fijo > Pública Construcción sobre Producto interno bruto a precios de mercado | AY33: Formación bruta de capital fijo> Pública Maquinaria y equipo sobre Producto interno bruto a precios de mercado | AZ33: Formación bruta de capital fijo > Privada Total sobre Producto interno bruto a precios de mercado | BA33: P.52/N.12 - Variación de existencias por tipo de activo sobre Producto interno bruto a precios de mercado | BC33: Nomenclatura INEGI | BD33: P.52/N.12 - Variación de existencias por tipo de activo | BE33: Stock de Inventarios | BF33: Stock de Inventarios sobre Producto interno bruto a precios de mercado
A35: Variable de ajuste | B35: 0.039628664
A36: Cuadro Intermedio B. Stocks de Capital Construccion Equipos | H36: Cuadro Intermedio C. | U36: Cuadro Intermedio D | AH36: Cuadro Intermedio E: Participacion Porcentual | AR36: Cuadro Intermedio F | BC36: Cuadro Intermedio G
A37: Tasas depreciacion | H37: Inversion y Consumo de Capital Fijo | U37: Inversiones y Stocks de Capital Publico y Privado | AA37: Valores asumidos y reconciliados con cuentas nacionales | AR37: Cuentas Nacionales, Depreciación e Inversiones | BC37: Valoración de inventarios
A38: Asumidas y | I38: Inversiones (Datos) | N38: Tasas de Depreciación | AA38: Depreciación | AC38: Depreciación | AL38: Participación | AR38: Valores Reales 2013 | AU38: Inversión % del PIB | BD38: Tasa Crecimiento Acervo Inventarios
A39: reconciliadas | B39: =B35 -> 0.039628664 | C39: =B39+3% -> 0.069628664 | E39: Depreciación | F39: Inventarios | I39: Total (Real) | N39: =B39 -> 0.039628664 | O39: =C39 -> 0.069628664 | V39: Inversión | W39: Inversión | X39: Inversión | Y39: Inversión | Z39: Inversión | AA39: =N39 -> 0.039628664 | AB39: =O39 -> 0.069628664 | AC39: =AA39 -> 0.039628664 | AD39: =AB39 -> 0.069628664 | AV39: Inversión | AW39: Inversión | AX39: Inversión | AY39: Inversión | BD39: Asumida: | BE39: 0.05
B40: Construcción | C40: Equipos | D40: Total | E40: Capital | F40: Cambios en | I40: Construcción | J40: Equipos | K40: Total | L40: Consumo Capital Fijo | N40: Construcción | O40: Equipos | P40: Depreciación | V40: Total | W40: Construcción | X40: Equipos | Y40: Construcción | Z40: Equipos | AA40: Stock Capital Privado | AB40: Stock Capital Privado | AC40: Stock Capital Publico | AD40: Stock Capital Publico | AE40: Suma | AL40: en K Total | AS40: Consumo Capital Fijo | AT40: Cambio en Inventarios | AU40: Inversión Total % del PIB | AV40: Construcción | AW40: Equipos | AX40: Construcción | AY40: Equipos | BE40: [Incl.perdidas]
A41: Stocks de Capital | B41: K Stocks (C) | C41: K Stocks (E) | D41: K Stocks (C+E) | F41: Existencias | N41: Precios Reales | P41: Estimada | R41: Depreciación/PIB | W41: Privada | X41: Privada | Y41: Publica | Z41: Publica | AA41: Construcción | AB41: Equipos | AC41: Construcción | AD41: Equipos | AI41: K Stocks | AJ41: K Stocks | AK41: K Stocks | AV41: Privada | AW41: Privada | AX41: Publica | AY41: Publica | AZ41: Inversión | BA41: Inverson | BD41: Inversión en Inventarios | BE41: Stock de Inventarios | BF41: Proporción al PIB
A42: Año | B42: 29493.204 | C42: 14092.465 | D42: Capital | E42: Depreciación Annual/Datos | F42: Cambio Anual | H42: Año | L42: %/GDP | M42: % de Acervo de Capital | P42: Real | Q42: Datos | R42: Real | S42: Datos | U42: Año | Y42: Stocks Iniciales | AA42: 20927.479 | AB42: 12346.028 | AC42: 8565.7247 | AD42: 1746.4368 | AE42: K Stocks | AH42: Año | AI42: Total | AJ42: Privados | AK42: Públicos | AL42: Kp (Privado)/K | AM42: Kpu (Publico)/K | AN42: Kp (Privado)/ PIB | AO42: Kpu (Publico)/PIB | AP42: K/PIB | AR42: Año | AS42: Capital | AT42: Inventarios | AZ42: Privada Total | BA42: Inventarios/PIB | BC42: Año
B43: AA | C43: AB | D43: AC | E43: J | F43: AD | I43: AG | J43: AH | K43: AI | L43: AJ | M43: AK | N43: AG | O43: AH | P43: AL | Q43: J | R43: AM | S43: AJ | V43: AI | W43: AN | X43: AO | Y43: AP | Z43: AQ | AA43: AR | AB43: AS | AC43: AT | AD43: AU | AE43: AC | AI43: AC | AJ43: AV | AK43: AW | AL43: AX | AM43: AY | AN43: AZ | AO43: BA | AP43: BB | AS43: J | AT43: AD | AU43: BC | AV43: BD | AW43: BE | AX43: BF | AY43: BG | AZ43: BH | BA43: BI | BD43: AD | BE43: BJ | BF43: BK
A44: 2003 | B44: =B42+I44-($B$39)*B42 -> 29996.329 | C44: =C42+J44-($C$39)*C42 -> 13889.919 | D44: =B44+C44 -> 43886.248 | E44: =M12 -> 1905.7807 | F44: =Q188/1000 -> 172.15065 | H44: 2003 | I44: 1671.9018 | J44: 778.69331 | K44: =SUM(I44:J44) -> 2450.5951 | L44: =E44/B12 -> 0.1459051 | M44: =E44/B44 -> 0.063533796 | N44: =I44 -> 1671.9018 | O44: =J44 -> 778.69331 | P44: =$N$39*B44+$O$39*C44 -> 2155.8509 | Q44: =AS44 -> 1905.7807 | R44: =P44/B12 -> 0.16505029 | S44: =Q44/B12 -> 0.1459051 | U44: 2003 | V44: =SUM(W44:Z44) -> 2450.5951 | W44: 1103.4072 | X44: 693.37315 | Y44: 568.49461 | Z44: 85.320163 | AA44: =AA42+W44-$AA$39*AA42 -> 21201.558 | AB44: =AB42+X44-AB$39*AB42 -> 12179.764 | AC44: =AC42+Y44-AC$39*AC42 -> 8794.7711 | AD44: =AD42+Z44-AD$39*AD42 -> 1710.1549 | AE44: =SUM(AA44:AD44) -> 43886.248 | AF44: =B77 -> 43886.248 | AH44: 2003 | AI44: =SUM(AJ44:AK44) -> 43886.248 | AJ44: =AA44+AB44 -> 33381.322 | AK44: =AC44+AD44 -> 10504.926 | AL44: =AJ44/$AE44 -> 0.76063285 | AM44: =AK44/$AE44 -> 0.23936715 | AN44: =AJ44/B12 -> 2.5556483 | AO44: =AK44/B12 -> 0.80424904 | AP44: =(AJ44+AK44)/B12 -> 3.3598973 | AR44: 2003 | AS44: =M12 -> 1905.7807 | AT44: =F44 -> 172.15065 | AU44: =V44/B12 -> 0.18761567 | AV44: =W44/B12 -> 0.084476005 | AW44: =X44/B12 -> 0.053084114 | AX44: =Y44/B12 -> 0.04352351 | AY44: =Z44/B12 -> 0.006532046 | AZ44: =AV44+AW44 -> 0.13756012 | BA44: =AT44/B12 -> 0.013179721 | BC44: 2003 | BD44: =F44 -> 172.15065 | BE44: =BD44/$BE$39 -> 3443.0129 | BF44: =BE44/B12 -> 0.26359442
A45: 2004 | B45: =B44+I45-($B$39)*B44 -> 30608.353 | C45: =C44+J45-($C$39)*C44 -> 13822.944 | D45: =B45+C45 -> 44431.297 | E45: =M13 -> 1975.8862 | F45: =Q189/1000 -> 222.75864 | H45: 2004 | I45: 1800.7386 | J45: 900.16135 | K45: =SUM(I45:J45) -> 2700.9 | L45: =E45/B13 -> 0.14556671 | M45: =E45/B45 -> 0.064553824 | N45: =I45 -> 1800.7386 | O45: =J45 -> 900.16135 | P45: =$N$39*B45+$O$39*C45 -> 2175.4413 | Q45: =AS45 -> 1975.8862 | R45: =P45/B13 -> 0.16026825 | S45: =Q45/B13 -> 0.14556671 | U45: 2004 | V45: =SUM(W45:Z45) -> 2700.9 | W45: 1197.3146 | X45: 793.26987 | Y45: 603.42407 | Z45: 106.89147 | AA45: =AA44+W45-$AA$39*AA44 -> 21558.683 | AB45: =AB44+X45-AB$39*AB44 -> 12124.973 | AC45: =AC44+Y45-AC$39*AC44 -> 9049.6701 | AD45: =AD44+Z45-AD$39*AD44 -> 1697.9706 | AE45: =SUM(AA45:AD45) -> 44431.297 | AF45: =B78 -> 44431.297 | AH45: 2004 | AI45: =SUM(AJ45:AK45) -> 44431.297 | AJ45: =AA45+AB45 -> 33683.656 | AK45: =AC45+AD45 -> 10747.641 | AL45: =AJ45/$AE45 -> 0.75810653 | AM45: =AK45/$AE45 -> 0.24189347 | AN45: =AJ45/B13 -> 2.481529 | AO45: =AK45/B13 -> 0.79179594 | AP45: =(AJ45+AK45)/B13 -> 3.273325 | AR45: 2004 | AS45: =M13 -> 1975.8862 | AT45: =F45 -> 222.75864 | AU45: =V45/B13 -> 0.19897964 | AV45: =W45/B13 -> 0.088208086 | AW45: =X45/B13 -> 0.058441465 | AX45: =Y45/B13 -> 0.04445522 | AY45: =Z45/B13 -> 0.0078748665 | AZ45: =AV45+AW45 -> 0.14664955 | BA45: =AT45/B13 -> 0.016410987 | BC45: 2004 | BD45: =F45 -> 222.75864 | BE45: =BE44*(0.98)+BD45 -> 3596.9113 | BF45: =BE45/B13 -> 0.26499023
A46: 2005 | B46: =B45+I46-($B$39)*B45 -> 31306.407 | C46: =C45+J46-($C$39)*C45 -> 13877.445 | D46: =B46+C46 -> 45183.852 | E46: =M14 -> 2001.6892 | F46: =Q190/1000 -> 130.58316 | H46: 2005 | I46: 1911.0215 | J46: 1016.9745 | K46: =SUM(I46:J46) -> 2927.996 | L46: =E46/B14 -> 0.14414033 | M46: =E46/B46 -> 0.063938646 | N46: =I46 -> 1911.0215 | O46: =J46 -> 1016.9745 | P46: =$N$39*B46+$O$39*C46 -> 2206.899 | Q46: =AS46 -> 2001.6892 | R46: =P46/B14 -> 0.15891735 | S46: =Q46/B14 -> 0.14414033 | U46: 2005 | V46: =SUM(W46:Z46) -> 2927.996 | W46: 1283.24 | X46: 864.98361 | Y46: 627.78147 | Z46: 151.99093 | AA46: =AA45+W46-$AA$39*AA45 -> 21987.581 | AB46: =AB45+X46-AB$39*AB45 -> 12145.711 | AC46: =AC45+Y46-AC$39*AC45 -> 9318.8253 | AD46: =AD45+Z46-AD$39*AD45 -> 1731.7341 | AE46: =SUM(AA46:AD46) -> 45183.852 | AF46: =B79 -> 45183.852 | AH46: 2005 | AI46: =SUM(AJ46:AK46) -> 45183.852 | AJ46: =AA46+AB46 -> 34133.292 | AK46: =AC46+AD46 -> 11050.559 | AL46: =AJ46/$AE46 -> 0.75543122 | AM46: =AK46/$AE46 -> 0.24456878 | AN46: =AJ46/B14 -> 2.4579159 | AO46: =AK46/B14 -> 0.79574351 | AP46: =(AJ46+AK46)/B14 -> 3.2536594 | AR46: 2005 | AS46: =M14 -> 2001.6892 | AT46: =F46 -> 130.58316 | AU46: =V46/B14 -> 0.21084307 | AV46: =W46/B14 -> 0.092405268 | AW46: =X46/B14 -> 0.0622869 | AX46: =Y46/B14 -> 0.045206131 | AY46: =Z46/B14 -> 0.010944767 | AZ46: =AV46+AW46 -> 0.15469217 | BA46: =AT46/B14 -> 0.0094032071 | BC46: 2005 | BD46: =F46 -> 130.58316 | BE46: =BE45*(0.98)+BD46 -> 3655.5562 | BF46: =BE46/B14 -> 0.2632342
A47: 2006 | B47: =B46+I47-($B$39)*B46 -> 32161.681 | C47: =C46+J47-($C$39)*C46 -> 13993.812 | D47: =B47+C47 -> 46155.492 | E47: =M15 -> 2072.7348 | F47: =Q191/1000 -> 185.68286 | H47: 2006 | I47: 2095.9052 | J47: 1082.6345 | K47: =SUM(I47:J47) -> 3178.5397 | L47: =E47/B15 -> 0.14283644 | M47: =E47/B47 -> 0.064447341 | N47: =I47 -> 2095.9052 | O47: =J47 -> 1082.6345 | P47: =$N$39*B47+$O$39*C47 -> 2248.8949 | Q47: =AS47 -> 2072.7348 | R47: =P47/B15 -> 0.15497599 | S47: =Q47/B15 -> 0.14283644 | U47: 2006 | V47: =SUM(W47:Z47) -> 3178.5397 | W47: 1475.5385 | X47: 902.96272 | Y47: 620.36664 | Z47: 179.6718 | AA47: =AA46+W47-$AA$39*AA46 -> 22591.781 | AB47: =AB46+X47-AB$39*AB46 -> 12202.984 | AC47: =AC46+Y47-AC$39*AC46 -> 9569.8993 | AD47: =AD46+Z47-AD$39*AD46 -> 1790.8275 | AE47: =SUM(AA47:AD47) -> 46155.492 | AF47: =B80 -> 46155.492 | AH47: 2006 | AI47: =SUM(AJ47:AK47) -> 46155.492 | AJ47: =AA47+AB47 -> 34794.765 | AK47: =AC47+AD47 -> 11360.727 | AL47: =AJ47/$AE47 -> 0.7538597 | AM47: =AK47/$AE47 -> 0.2461403 | AN47: =AJ47/B15 -> 2.3977792 | AO47: =AK47/B15 -> 0.78289116 | AP47: =(AJ47+AK47)/B15 -> 3.1806703 | AR47: 2006 | AS47: =M15 -> 2072.7348 | AT47: =F47 -> 185.68286 | AU47: =V47/B15 -> 0.21903974 | AV47: =W47/B15 -> 0.10168241 | AW47: =X47/B15 -> 0.062225027 | AX47: =Y47/B15 -> 0.042750747 | AY47: =Z47/B15 -> 0.012381555 | AZ47: =AV47+AW47 -> 0.16390744 | BA47: =AT47/B15 -> 0.012795789 | BC47: 2006 | BD47: =F47 -> 185.68286 | BE47: =BE46*(0.98)+BD47 -> 3768.128 | BF47: =BE47/B15 -> 0.25966948
A48: 2007 | B48: =B47+I48-($B$39)*B47 -> 33208.626 | C48: =C47+J48-($C$39)*C47 -> 14176.876 | D48: =B48+C48 -> 47385.502 | E48: =M16 -> 2132.267 | F48: =Q192/1000 -> 174.69714 | H48: 2007 | I48: 2321.4696 | J48: 1157.435 | K48: =SUM(I48:J48) -> 3478.9046 | L48: =E48/B16 -> 0.1436472 | M48: =E48/B48 -> 0.064208227 | N48: =I48 -> 2321.4696 | O48: =J48 -> 1157.435 | P48: =$N$39*B48+$O$39*C48 -> 2303.1304 | Q48: =AS48 -> 2132.267 | R48: =P48/B16 -> 0.15515798 | S48: =Q48/B16 -> 0.1436472 | U48: 2007 | V48: =SUM(W48:Z48) -> 3478.9046 | W48: 1576.2161 | X48: 1028.4778 | Y48: 745.25343 | Z48: 128.95718 | AA48: =AA47+W48-$AA$39*AA47 -> 23272.715 | AB48: =AB47+X48-AB$39*AB47 -> 12381.784 | AC48: =AC47+Y48-AC$39*AC47 -> 9935.9104 | AD48: =AD47+Z48-AD$39*AD47 -> 1795.0918 | AE48: =SUM(AA48:AD48) -> 47385.502 | AF48: =B81 -> 47385.502 | AH48: 2007 | AI48: =SUM(AJ48:AK48) -> 47385.502 | AJ48: =AA48+AB48 -> 35654.5 | AK48: =AC48+AD48 -> 11731.002 | AL48: =AJ48/$AE48 -> 0.75243478 | AM48: =AK48/$AE48 -> 0.24756522 | AN48: =AJ48/B16 -> 2.401983 | AO48: =AK48/B16 -> 0.79029766 | AP48: =(AJ48+AK48)/B16 -> 3.1922807 | AR48: 2007 | AS48: =M16 -> 2132.267 | AT48: =F48 -> 174.69714 | AU48: =V48/B16 -> 0.23436788 | AV48: =W48/B16 -> 0.106187 | AW48: =X48/B16 -> 0.069286801 | AX48: =Y48/B16 -> 0.050206456 | AY48: =Z48/B16 -> 0.0086876257 | AZ48: =AV48+AW48 -> 0.1754738 | BA48: =AT48/B16 -> 0.011769049 | BC48: 2007 | BD48: =F48 -> 174.69714 | BE48: =BE47*(0.98)+BD48 -> 3867.4626 | BF48: =BE48/B16 -> 0.26054437
A49: 2008 | B49: =B48+I49-($B$39)*B48 -> 34188.943 | C49: =C48+J49-($C$39)*C48 -> 14346.579 | D49: =B49+C49 -> 48535.522 | E49: =M17 -> 2228.5749 | F49: =Q193/1000 -> 141.4967 | H49: 2008 | I49: 2296.3305 | J49: 1156.8196 | K49: =SUM(I49:J49) -> 3453.1501 | L49: =E49/B17 -> 0.14843642 | M49: =E49/B49 -> 0.065184083 | N49: =I49 -> 2296.3305 | O49: =J49 -> 1156.8196 | P49: =$N$39*B49+$O$39*C49 -> 2353.7953 | Q49: =AS49 -> 2228.5749 | R49: =P49/B17 -> 0.15677685 | S49: =Q49/B17 -> 0.14843642 | U49: 2008 | V49: =SUM(W49:Z49) -> 3453.1501 | W49: 1475.4353 | X49: 979.12861 | Y49: 820.89521 | Z49: 177.69094 | AA49: =AA48+W49-$AA$39*AA48 -> 23825.884 | AB49: =AB48+X49-AB$39*AB48 -> 12498.786 | AC49: =AC48+Y49-AC$39*AC48 -> 10363.059 | AD49: =AD48+Z49-AD$39*AD48 -> 1847.7929 | AE49: =SUM(AA49:AD49) -> 48535.522 | AF49: =B82 -> 48535.522 | AH49: 2008 | AI49: =SUM(AJ49:AK49) -> 48535.522 | AJ49: =AA49+AB49 -> 36324.67 | AK49: =AC49+AD49 -> 12210.852 | AL49: =AJ49/$AE49 -> 0.74841413 | AM49: =AK49/$AE49 -> 0.25158587 | AN49: =AJ49/B17 -> 2.4194403 | AO49: =AK49/B17 -> 0.81331577 | AP49: =(AJ49+AK49)/B17 -> 3.2327561 | AR49: 2008 | AS49: =M17 -> 2228.5749 | AT49: =F49 -> 141.4967 | AU49: =V49/B17 -> 0.23000045 | AV49: =W49/B17 -> 0.098272819 | AW49: =X49/B17 -> 0.065215823 | AX49: =Y49/B17 -> 0.054676532 | AY49: =Z49/B17 -> 0.01183528 | AZ49: =AV49+AW49 -> 0.16348864 | BA49: =AT49/B17 -> 0.0094245265 | BC49: 2008 | BD49: =F49 -> 141.4967 | BE49: =BE48*(0.98)+BD49 -> 3931.61 | BF49: =BE49/B17 -> 0.26186875
A50: 2009 | B50: =B49+I50-($B$39)*B49 -> 34958.309 | C50: =C49+J50-($C$39)*C49 -> 14368.679 | D50: =B50+C50 -> 49326.988 | E50: =M18 -> 2355.8143 | F50: =Q194/1000 -> 108.41905 | H50: 2009 | I50: 2124.2279 | J50: 1021.0338 | K50: =SUM(I50:J50) -> 3145.2617 | L50: =E50/B18 -> 0.16566949 | M50: =E50/B50 -> 0.067389253 | N50: =I50 -> 2124.2279 | O50: =J50 -> 1021.0338 | P50: =$N$39*B50+$O$39*C50 -> 2385.823 | Q50: =AS50 -> 2355.8143 | R50: =P50/B18 -> 0.16777981 | S50: =Q50/B18 -> 0.16566949 | U50: 2009 | V50: =SUM(W50:Z50) -> 3145.2617 | W50: 1346.9414 | X50: 890.5257 | Y50: 777.2865 | Z50: 130.50813 | AA50: =AA49+W50-$AA$39*AA49 -> 24228.637 | AB50: =AB49+X50-AB$39*AB49 -> 12519.038 | AC50: =AC49+Y50-AC$39*AC49 -> 10729.671 | AD50: =AD49+Z50-AD$39*AD49 -> 1849.6417 | AE50: =SUM(AA50:AD50) -> 49326.988 | AF50: =B83 -> 49326.988 | AH50: 2009 | AI50: =SUM(AJ50:AK50) -> 49326.988 | AJ50: =AA50+AB50 -> 36747.675 | AK50: =AC50+AD50 -> 12579.313 | AL50: =AJ50/$AE50 -> 0.74498113 | AM50: =AK50/$AE50 -> 0.25501887 | AN50: =AJ50/B18 -> 2.584231 | AO50: =AK50/B18 -> 0.88462331 | AP50: =(AJ50+AK50)/B18 -> 3.4688543 | AR50: 2009 | AS50: =M18 -> 2355.8143 | AT50: =F50 -> 108.41905 | AU50: =V50/B18 -> 0.22118631 | AV50: =W50/B18 -> 0.094721846 | AW50: =X50/B18 -> 0.062625027 | AX50: =Y50/B18 -> 0.054661631 | AY50: =Z50/B18 -> 0.0091778091 | AZ50: =AV50+AW50 -> 0.15734687 | BA50: =AT50/B18 -> 0.0076244244 | BC50: 2009 | BD50: =F50 -> 108.41905 | BE50: =BE49*(0.98)+BD50 -> 3961.3969 | BF50: =BE50/B18 -> 0.27857993
A51: 2010 | B51: =B50+I51-($B$39)*B50 -> 35715.886 | C51: =C50+J51-($C$39)*C50 -> 14577.72 | D51: =B51+C51 -> 50293.606 | E51: =M19 -> 2363.1719 | F51: =Q195/1000 -> 180.92807 | H51: 2010 | I51: 2142.9289 | J51: 1209.5122 | K51: =SUM(I51:J51) -> 3352.441 | L51: =E51/B19 -> 0.15809432 | M51: =E51/B51 -> 0.066165848 | N51: =I51 -> 2142.9289 | O51: =J51 -> 1209.5122 | P51: =$N$39*B51+$O$39*C51 -> 2430.4 | Q51: =AS51 -> 2363.1719 | R51: =P51/B19 -> 0.16259183 | S51: =Q51/B19 -> 0.15809432 | U51: 2010 | V51: =SUM(W51:Z51) -> 3352.441 | W51: 1300.7348 | X51: 1030.9989 | Y51: 842.19402 | Z51: 178.51327 | AA51: =AA50+W51-$AA$39*AA50 -> 24569.224 | AB51: =AB50+X51-AB$39*AB50 -> 12678.353 | AC51: =AC50+Y51-AC$39*AC50 -> 11146.663 | AD51: =AD50+Z51-AD$39*AD50 -> 1899.3668 | AE51: =SUM(AA51:AD51) -> 50293.606 | AF51: =B84 -> 50293.606 | AH51: 2010 | AI51: =SUM(AJ51:AK51) -> 50293.606 | AJ51: =AA51+AB51 -> 37247.577 | AK51: =AC51+AD51 -> 13046.029 | AL51: =AJ51/$AE51 -> 0.74060262 | AM51: =AK51/$AE51 -> 0.25939738 | AN51: =AJ51/B19 -> 2.4918332 | AO51: =AK51/B19 -> 0.87276899 | AP51: =(AJ51+AK51)/B19 -> 3.3646022 | AR51: 2010 | AS51: =M19 -> 2363.1719 | AT51: =F51 -> 180.92807 | AU51: =V51/B19 -> 0.22427564 | AV51: =W51/B19 -> 0.087018126 | AW51: =X51/B19 -> 0.068973005 | AX51: =Y51/B19 -> 0.05634211 | AY51: =Z51/B19 -> 0.011942395 | AZ51: =AV51+AW51 -> 0.15599113 | BA51: =AT51/B19 -> 0.012103944 | BC51: 2010 | BD51: =F51 -> 180.92807 | BE51: =BE50*(0.98)+BD51 -> 4063.097 | BF51: =BE51/B19 -> 0.27181796
A52: 2011 | B52: =B51+I52-($B$39)*B51 -> 36683.491 | C52: =C51+J52-($C$39)*C51 -> 14901.004 | D52: =B52+C52 -> 51584.494 | E52: =M20 -> 2425.8521 | F52: =Q196/1000 -> 156.08374 | H52: 2011 | I52: 2382.9773 | J52: 1338.3112 | K52: =SUM(I52:J52) -> 3721.2885 | L52: =E52/B20 -> 0.15655353 | M52: =E52/B52 -> 0.066129261 | N52: =I52 -> 2382.9773 | O52: =J52 -> 1338.3112 | P52: =$N$39*B52+$O$39*C52 -> 2491.2547 | Q52: =AS52 -> 2425.8521 | R52: =P52/B20 -> 0.16077432 | S52: =Q52/B20 -> 0.15655353 | U52: 2011 | V52: =SUM(W52:Z52) -> 3721.2885 | W52: 1635.7449 | X52: 1163.1817 | Y52: 747.23242 | Z52: 175.1295 | AA52: =AA51+W52-$AA$39*AA51 -> 25231.323 | AB52: =AB51+X52-AB$39*AB51 -> 12958.758 | AC52: =AC51+Y52-AC$39*AC51 -> 11452.168 | AD52: =AD51+Z52-AD$39*AD51 -> 1942.246 | AE52: =SUM(AA52:AD52) -> 51584.494 | AF52: =B85 -> 51584.494 | AH52: 2011 | AI52: =SUM(AJ52:AK52) -> 51584.494 | AJ52: =AA52+AB52 -> 38190.081 | AK52: =AC52+AD52 -> 13394.414 | AL52: =AJ52/$AE52 -> 0.74034031 | AM52: =AK52/$AE52 -> 0.25965969 | AN52: =AJ52/B20 -> 2.4646152 | AO52: =AK52/B20 -> 0.8644149 | AP52: =(AJ52+AK52)/B20 -> 3.3290301 | AR52: 2011 | AS52: =M20 -> 2425.8521 | AT52: =F52 -> 156.08374 | AU52: =V52/B20 -> 0.24015514 | AV52: =W52/B20 -> 0.10556358 | AW52: =X52/B20 -> 0.075066489 | AX52: =Y52/B20 -> 0.048223002 | AY52: =Z52/B20 -> 0.011302066 | AZ52: =AV52+AW52 -> 0.18063007 | BA52: =AT52/B20 -> 0.010072939 | BC52: 2011 | BD52: =F52 -> 156.08374 | BE52: =BE51*(0.98)+BD52 -> 4137.9188 | BF52: =BE52/B20 -> 0.26704257
...

Sheet VBDR
B1: Discount Rate (dimensionless)
A2: LDVs | B2: ='Cuadros Iniciales'!$P$163 -> 0.10903896
A3: HDVs | B3: ='Cuadros Iniciales'!$P$163 -> 0.10903896
A4: aircraft | B4: ='Cuadros Iniciales'!$P$163 -> 0.10903896
A5: rail | B5: ='Cuadros Iniciales'!$P$163 -> 0.10903896
A6: ships | B6: ='Cuadros Iniciales'!$P$163 -> 0.10903896
A7: motorbikes | B7: ='Cuadros Iniciales'!$P$163 -> 0.10903896
