Workbook
Name Eno_TM: '[1]1997 Table 1a Modified'!#REF!
Name Eno_TM: '[2]1997 Table 1a Modified'!#REF!
Name Eno_TM: '[1]1997 Table 1a Modified'!#REF!
Name Eno_Tons: '[1]1997 Table 1a Modified'!#REF!
Name Eno_Tons: '[2]1997 Table 1a Modified'!#REF!
Name Eno_Tons: '[1]1997 Table 1a Modified'!#REF!
Name NTS_YR: [3]About!$B$136
Name Sum_T2: '[1]1997 Table 1a Modified'!#REF!
Name Sum_T2: '[1]1997 Table 1a Modified'!#REF!
Name Sum_TTM: '[1]1997 Table 1a Modified'!#REF!
Name Sum_TTM: '[1]1997 Table 1a Modified'!#REF!
Name ti_tbl_50: #REF!
Name ti_tbl_50: #REF!
Name ti_tbl_50: #REF!
Name ti_tbl_69: #REF!
Name ti_tbl_69: #REF!
Name ti_tbl_69: #REF!

Sheet About
A1: BCDTRtSY BAU Cargo Dist Transported Relative to Start Year
A3: Mexico: | B3: Fuel demand for transport sector
B4: INECC
B5: 2015
B6: Modelo Christopher de flota vehicular
B7: N/A
B10: Motorcycle anual travelled distance
B11: INEGI
B12: 2016
B13: Vehicle fleet
B14: http://www.inegi.org.mx/lib/olap/consulta/general_ver4/MDXQueryDatos.asp?#Regreso&c=
A16: Mexico Notes
A17: We used the energy demand annual growth rate to estimate this variable for
A18: LDVs, HDVs, rail, aircraft and ships.
A20: For motorcycles we used INEGI proyections for anual distance travelled.
A23: Notes
A24: This variable contains ratios of cargo distance transported in each year of the
A25: model run relative to the start year. The start year is the year before the
A26: first simulated year. So if the first year for which the model outputs data
A27: is 2020, the start year is 2019. The start year column does not have to be
A28: included in the outputs but is retained here for visual clarity.
A29: We use AEO 2021 to calculate start year vehicles, as AEO 2021 does not include 2019 data.

Sheet Mexico-Christopher
C1: Km/mile | D1: 1.60934 | G1: INECC
C2: L/Gallon | D2: 3.78541 | G2: Modelo Christopher
D4: 2016 data | H4: Kilómetros recorridos (Flota total) | BU4: CARGO-DISTANCE (Km)
D5: Gasoline | G5: Flota total por categoría
D6: litres | E6: Pax/Cargo | K6: 1990 | L6: 1991 | M6: 1992 | N6: 1993 | O6: 1994 | P6: 1995 | Q6: 1996 | R6: 1997 | S6: 1998 | T6: 1999 | U6: 2000 | V6: 2001 | W6: 2002 | X6: 2003 | Y6: 2004 | Z6: 2005 | AA6: 2006 | AB6: 2007 | AC6: 2008 | AD6: 2009 | AE6: 2010 | AF6: 2011 | AG6: 2012 | AH6: 2013 | AI6: 2014 | AJ6: 2015 | AK6: 2016 | AL6: 2017 | AM6: 2018 | AN6: 2019 | AO6: 2020 | AP6: 2021 | AQ6: 2022 | AR6: 2023 | AS6: 2024 | AT6: 2025 | AU6: 2026 | AV6: 2027 | AW6: 2028 | AX6: 2029 | AY6: 2030 | AZ6: 2031 | BA6: 2032 | BB6: 2033 | BC6: 2034 | BD6: 2035 | BE6: 2036 | BF6: 2037 | BG6: 2038 | BH6: 2039 | BI6: 2040 | BJ6: 2041 | BK6: 2042 | BL6: 2043 | BM6: 2044 | BN6: 2045 | BO6: 2046 | BP6: 2047 | BQ6: 2048 | BR6: 2049 | BS6: 2050 | BU6: 2016 | BV6: 2017 | BW6: 2018 | BX6: 2019 | BY6: 2020 | BZ6: 2021 | CA6: 2022 | CB6: 2023 | CC6: 2024 | CD6: 2025 | CE6: 2026 | CF6: 2027 | CG6: 2028 | CH6: 2029 | CI6: 2030 | CJ6: 2031 | CK6: 2032 | CL6: 2033 | CM6: 2034 | CN6: 2035 | CO6: 2036 | CP6: 2037 | CQ6: 2038 | CR6: 2039 | CS6: 2040 | CT6: 2041 | CU6: 2042 | CV6: 2043 | CW6: 2044 | CX6: 2045 | CY6: 2046 | CZ6: 2047 | DA6: 2048 | DB6: 2049 | DC6: 2050
B7: Ligeros | D7: =AK7 -> 132336.3 | E7: =$C$54 -> 1.4 | I7: Ligeros | K7: 46792.041 | L7: 50346.099 | M7: 54310.253 | N7: 57449.21 | O7: 60691.788 | P7: 58959.446 | Q7: 58107.118 | R7: 59031.223 | S7: 61948.933 | T7: 65189.037 | U7: 70665.332 | V7: 77137.352 | W7: 84051.541 | X7: 90208.585 | Y7: 96817.596 | Z7: 102528.03 | AA7: 107322.4 | AB7: 111096.74 | AC7: 113646.32 | AD7: 113394.12 | AE7: 114129.21 | AF7: 116180.88 | AG7: 119029.86 | AH7: 122491.45 | AI7: 125828.04 | AJ7: 129108.9 | AK7: 132336.3 | AL7: 135505.41 | AM7: 138647.55 | AN7: 141688.4 | AO7: 144727.31 | AP7: 147919.72 | AQ7: 151234.17 | AR7: 154613.61 | AS7: 158062.67 | AT7: 161637.85 | AU7: 165345.28 | AV7: 169197.26 | AW7: 173216.55 | AX7: 177437.42 | AY7: 181846.67 | AZ7: 186274.62 | BA7: 190731.19 | BB7: 195207.24 | BC7: 199682.32 | BD7: =SUM(BD8:BD10) -> 201705.49 | BE7: =SUM(BE8:BE10) -> 203749.16 | BF7: =SUM(BF8:BF10) -> 205813.54 | BG7: =SUM(BG8:BG10) -> 207898.84 | BH7: =SUM(BH8:BH10) -> 210005.27 | BI7: =SUM(BI8:BI10) -> 212133.04 | BJ7: =SUM(BJ8:BJ10) -> 214282.37 | BK7: =SUM(BK8:BK10) -> 216453.47 | ... BS7: =SUM(BS8:BS10) -> 234633.3 | BT7: 0.020264132 | BU7: =AK7*$E7 -> 185270.82 | BV7: =AL7*$E7 -> 189707.58 | BW7: =AM7*$E7 -> 194106.56 | BX7: =AN7*$E7 -> 198363.76 | BY7: =AO7*$E7 -> 202618.24 | BZ7: =AP7*$E7 -> 207087.61 | CA7: =AQ7*$E7 -> 211727.84 | CB7: =AR7*$E7 -> 216459.06 | ... DC7: =BS7*$E7 -> 328486.63
B8: Compactos | C8: Compactos | D8: =AK8 -> 65613.419 | E8: =$C$54 -> 1.4 | J8: Compactos | K8: 24956.061 | L8: 26650.423 | M8: 28239.793 | N8: 29492.795 | O8: 31109.882 | P8: 30003.168 | Q8: 29122.661 | R8: 29216.981 | S8: 30577.133 | T8: 32090.939 | U8: 34564.688 | V8: 37963.577 | W8: 42395.806 | X8: 46888.167 | Y8: 51885.744 | Z8: 56058.91 | AA8: 58941.269 | AB8: 60526.553 | AC8: 61567.165 | AD8: 61076.531 | AE8: 60951.811 | AF8: 61439.433 | AG8: 62167.299 | AH8: 63064.616 | AI8: 63926.141 | AJ8: 64778.737 | AK8: 65613.419 | AL8: 66434.863 | AM8: 67271.303 | AN8: 68091.406 | AO8: 68927.605 | AP8: 69860.611 | AQ8: 70883.577 | AR8: 71964.593 | AS8: 73100.537 | AT8: 74321.148 | AU8: 75638.477 | AV8: 77056.107 | AW8: 78575.978 | AX8: 80221.131 | AY8: 81986.957 | AZ8: 83801.03 | BA8: 85673.283 | BB8: 87598.323 | BC8: 89543.372 | BD8: =BC8*(1+$BT8/2) -> 90443.397 | BE8: =BD8*(1+$BT8/2) -> 91352.469 | BF8: =BE8*(1+$BT8/2) -> 92270.678 | BG8: =BF8*(1+$BT8/2) -> 93198.116 | BH8: =BG8*(1+$BT8/2) -> 94134.876 | BI8: =BH8*(1+$BT8/2) -> 95081.052 | BJ8: =BI8*(1+$BT8/2) -> 96036.738 | BK8: =BJ8*(1+$BT8/2) -> 97002.03 | ... BS8: =BR8*(1+$BT8/2) -> 105081.97 | BT8: 0.020102553 | BU8: =AK8*$E8 -> 91858.786 | BV8: =AL8*$E8 -> 93008.808 | BW8: =AM8*$E8 -> 94179.825 | BX8: =AN8*$E8 -> 95327.969 | BY8: =AO8*$E8 -> 96498.647 | BZ8: =AP8*$E8 -> 97804.856 | CA8: =AQ8*$E8 -> 99237.007 | CB8: =AR8*$E8 -> 100750.43 | ... DC8: =BS8*$E8 -> 147114.75
B9: Sumcompactos | C9: Sumcompactos | D9: =AK9 -> 54807 | E9: =$C$54 -> 1.4 | J9: Sumcompactos | K9: 15682.493 | L9: 17094.309 | M9: 18895.362 | N9: 20430.938 | O9: 21750.652 | P9: 21332.911 | Q9: 21431.651 | R9: 22424.837 | S9: 23911.663 | T9: 25566.861 | U9: 28269.657 | V9: 31073.925 | W9: 33195.028 | X9: 34657.345 | Y9: 36072.511 | Z9: 37416.671 | AA9: 39007.412 | AB9: 40948.369 | AC9: 42244.161 | AD9: 42542.167 | AE9: 43434.627 | AF9: 44932.789 | AG9: 46619.716 | AH9: 48755.806 | AI9: 50813.16 | AJ9: 52827.639 | AK9: 54807 | AL9: 56744.463 | AM9: 58645.395 | AN9: 60472.528 | AO9: 62279.742 | AP9: 64129.475 | AQ9: 66004.952 | AR9: 67881.936 | AS9: 69771.103 | AT9: 71696.093 | AU9: 73651.42 | AV9: 75642.015 | AW9: 77689.206 | AX9: 79801.027 | AY9: 81967.8 | AZ9: 84109.606 | BA9: 86228.6 | BB9: 88318.179 | BC9: 90390.487 | BD9: =BC9*(1+$BT9/2) -> 91311.868 | BE9: =BD9*(1+$BT9/2) -> 92242.641 | BF9: =BE9*(1+$BT9/2) -> 93182.902 | BG9: =BF9*(1+$BT9/2) -> 94132.747 | BH9: =BG9*(1+$BT9/2) -> 95092.274 | BI9: =BH9*(1+$BT9/2) -> 96061.583 | BJ9: =BI9*(1+$BT9/2) -> 97040.771 | BK9: =BJ9*(1+$BT9/2) -> 98029.941 | ... BS9: =BR9*(1+$BT9/2) -> 106315.05 | BT9: 0.020386683 | BU9: =AK9*$E9 -> 76729.8 | BV9: =AL9*$E9 -> 79442.249 | BW9: =AM9*$E9 -> 82103.552 | BX9: =AN9*$E9 -> 84661.539 | BY9: =AO9*$E9 -> 87191.639 | BZ9: =AP9*$E9 -> 89781.264 | CA9: =AQ9*$E9 -> 92406.933 | CB9: =AR9*$E9 -> 95034.71 | ... DC9: =BS9*$E9 -> 148841.07
B10: Lujo y deportivos | C10: Lujo y deportivos | D10: =AK10 -> 11915.879 | E10: =$C$54 -> 1.4 | J10: Lujo y deportivos | K10: 6153.4877 | L10: 6601.3673 | M10: 7175.0985 | N10: 7525.4769 | O10: 7831.2537 | P10: 7623.3677 | Q10: 7552.806 | R10: 7389.4046 | S10: 7460.1373 | T10: 7531.2375 | U10: 7830.9876 | V10: 8099.8509 | W10: 8460.707 | X10: 8663.0727 | Y10: 8859.3417 | Z10: 9052.4536 | AA10: 9373.7186 | AB10: 9621.8208 | AC10: 9834.9968 | AD10: 9775.4232 | AE10: 9742.7756 | AF10: 9808.6627 | AG10: 10242.846 | AH10: 10671.027 | AI10: 11088.739 | AJ10: 11502.529 | AK10: 11915.879 | AL10: 12326.085 | AM10: 12730.848 | AN10: 13124.468 | AO10: 13519.965 | AP10: 13929.639 | AQ10: 14345.639 | AR10: 14767.086 | AS10: 15191.029 | AT10: 15620.611 | AU10: 16055.388 | AV10: 16499.141 | AW10: 16951.37 | AX10: 17415.266 | AY10: 17891.917 | AZ10: 18363.979 | BA10: 18829.306 | BB10: 19290.738 | BC10: 19748.459 | BD10: =BC10*(1+$BT10/2) -> 19950.225 | BE10: =BD10*(1+$BT10/2) -> 20154.053 | BF10: =BE10*(1+$BT10/2) -> 20359.963 | BG10: =BF10*(1+$BT10/2) -> 20567.977 | BH10: =BG10*(1+$BT10/2) -> 20778.116 | BI10: =BH10*(1+$BT10/2) -> 20990.402 | BJ10: =BI10*(1+$BT10/2) -> 21204.857 | BK10: =BJ10*(1+$BT10/2) -> 21421.504 | ... BS10: =BR10*(1+$BT10/2) -> 23236.285 | BT10: 0.020433629 | BU10: =AK10*$E10 -> 16682.23 | BV10: =AL10*$E10 -> 17256.519 | BW10: =AM10*$E10 -> 17823.187 | BX10: =AN10*$E10 -> 18374.256 | BY10: =AO10*$E10 -> 18927.951 | BZ10: =AP10*$E10 -> 19501.494 | CA10: =AQ10*$E10 -> 20083.895 | CB10: =AR10*$E10 -> 20673.92 | ... DC10: =BS10*$E10 -> 32530.799
B11: Camionetas | D11: =AK11 -> 92015.038 | E11: =$C$54 -> 1.4 | I11: Camionetas | K11: 27671.216 | L11: 30501.392 | M11: 33223.73 | N11: 34897.639 | O11: 36279.101 | P11: 35682.34 | Q11: 35955.282 | R11: 37223.144 | S11: 39215.646 | T11: 41032.728 | U11: 43758.716 | V11: 46179.527 | W11: 48752.369 | X11: 51554.509 | Y11: 55556.002 | Z11: 60650.394 | AA11: 66328.229 | AB11: 71726.138 | AC11: 76406.744 | AD11: 78391.464 | AE11: 80177.839 | AF11: 81712.343 | AG11: 83549.262 | AH11: 85743.856 | AI11: 87853.615 | AJ11: 89939.759 | AK11: 92015.038 | AL11: 94066.632 | AM11: 96100.106 | AN11: 97789.249 | AO11: 99477.531 | AP11: 101210.42 | AQ11: 102993.04 | AR11: 104847.14 | AS11: 106786.26 | AT11: 108790.68 | AU11: 110857.15 | AV11: 113012.53 | AW11: 115262.44 | AX11: 117631.52 | AY11: 120110.2 | AZ11: 122606.66 | BA11: 125118.9 | BB11: 127654.43 | BC11: 130220.79 | BD11: =SUM(BD12:BD15) -> 131471.28 | BE11: =SUM(BE12:BE15) -> 132733.78 | BF11: =SUM(BF12:BF15) -> 134008.42 | BG11: =SUM(BG12:BG15) -> 135295.32 | BH11: =SUM(BH12:BH15) -> 136594.58 | BI11: =SUM(BI12:BI15) -> 137906.34 | BJ11: =SUM(BJ12:BJ15) -> 139230.7 | BK11: =SUM(BK12:BK15) -> 140567.8 | ... BS11: =SUM(BS12:BS15) -> 151737.86 | BT11: 0.019209644 | BU11: =AK11*$E11 -> 128821.05 | BV11: =AL11*$E11 -> 131693.28 | BW11: =AM11*$E11 -> 134540.15 | BX11: =AN11*$E11 -> 136904.95 | BY11: =AO11*$E11 -> 139268.54 | BZ11: =AP11*$E11 -> 141694.59 | CA11: =AQ11*$E11 -> 144190.26 | CB11: =AR11*$E11 -> 146786 | ... DC11: =BS11*$E11 -> 212433.01
B12: Uso Múltiple | C12: Uso Múltiple | D12: =AK12 -> 48143.583 | E12: =$C$54 -> 1.4 | J12: Uso Múltiple | K12: 16186.806 | L12: 16054.95 | M12: 16039.633 | N12: 15949.48 | O12: 15707.683 | P12: 15052.604 | Q12: 14823.019 | R12: 14917.6 | S12: 15373.417 | T12: 15797.495 | U12: 16700.817 | V12: 17799.771 | W12: 19091.398 | X12: 20744.867 | Y12: 23140.539 | Z12: 26167.952 | AA12: 29485.052 | AB12: 32558.619 | AC12: 35196.554 | AD12: 36441.828 | AE12: 37735.073 | AF12: 39055.818 | AG12: 40600.668 | AH12: 42591.427 | AI12: 44492.35 | AJ12: 46339.608 | AK12: 48143.583 | AL12: 49916.208 | AM12: 51659.296 | AN12: 53167.705 | AO12: 54642.964 | AP12: 56114.145 | AQ12: 57578.912 | AR12: 59057.634 | AS12: 60570.548 | AT12: 62094.06 | AU12: 63630.551 | AV12: 65204.611 | AW12: 66814.231 | AX12: 68477.579 | AY12: 70181.02 | AZ12: 71867.454 | BA12: 73539.875 | BB12: 75203.144 | BC12: 76864.712 | BD12: =BC12*(1+$BT12/2) -> 77619.319 | BE12: =BD12*(1+$BT12/2) -> 78381.335 | BF12: =BE12*(1+$BT12/2) -> 79150.832 | BG12: =BF12*(1+$BT12/2) -> 79927.883 | BH12: =BG12*(1+$BT12/2) -> 80712.563 | BI12: =BH12*(1+$BT12/2) -> 81504.946 | BJ12: =BI12*(1+$BT12/2) -> 82305.108 | BK12: =BJ12*(1+$BT12/2) -> 83113.126 | ... BS12: =BR12*(1+$BT12/2) -> 89869.48 | BT12: 0.019634692 | BU12: =AK12*$E12 -> 67401.016 | BV12: =AL12*$E12 -> 69882.691 | BW12: =AM12*$E12 -> 72323.014 | BX12: =AN12*$E12 -> 74434.788 | BY12: =AO12*$E12 -> 76500.15 | BZ12: =AP12*$E12 -> 78559.804 | CA12: =AQ12*$E12 -> 80610.477 | CB12: =AR12*$E12 -> 82680.688 | ... DC12: =BS12*$E12 -> 125817.27
B13: C1 | C13: C1 | D13: =AK13 -> 22516.809 | E13: =$C$54 -> 1.4 | J13: C1 | K13: 5503.7578 | L13: 5883.2623 | M13: 6224.4662 | N13: 6542.0251 | O13: 6776.1196 | P13: 6763.9718 | Q13: 6887.4759 | R13: 7285.0558 | S13: 7908.7612 | T13: 8502.6122 | U13: 9268.0099 | V13: 9939.8484 | W13: 10625.27 | X13: 11351.223 | Y13: 12295.435 | Z13: 13548.841 | AA13: 15134.738 | AB13: 16756.962 | AC13: 18130.031 | AD13: 18787.827 | AE13: 19386.461 | AF13: 19929.219 | AG13: 20474.821 | AH13: 20990.31 | AI13: 21496.462 | AJ13: 22006.228 | AK13: 22516.809 | AL13: 23012.141 | AM13: 23494.852 | AN13: 23889.54 | AO13: 24276.908 | AP13: 24668.284 | AQ13: 25067.859 | AR13: 25478.069 | AS13: 25901.375 | AT13: 26339.212 | AU13: 26793 | AV13: 27264.774 | AW13: 27758.814 | AX13: 28278.798 | AY13: 28826.57 | AZ13: 29379.977 | BA13: 29939.375 | BB13: 30506.371 | BC13: 31082.323 | BD13: =BC13*(1+$BT13/2) -> 31376.42 | BE13: =BD13*(1+$BT13/2) -> 31673.299 | BF13: =BE13*(1+$BT13/2) -> 31972.988 | BG13: =BF13*(1+$BT13/2) -> 32275.513 | BH13: =BG13*(1+$BT13/2) -> 32580.9 | BI13: =BH13*(1+$BT13/2) -> 32889.176 | BJ13: =BI13*(1+$BT13/2) -> 33200.369 | BK13: =BJ13*(1+$BT13/2) -> 33514.507 | ... BS13: =BR13*(1+$BT13/2) -> 36137.01 | BT13: 0.018923752 | BU13: =AK13*$E13 -> 31523.533 | BV13: =AL13*$E13 -> 32216.998 | BW13: =AM13*$E13 -> 32892.792 | BX13: =AN13*$E13 -> 33445.356 | BY13: =AO13*$E13 -> 33987.672 | BZ13: =AP13*$E13 -> 34535.598 | CA13: =AQ13*$E13 -> 35095.002 | CB13: =AR13*$E13 -> 35669.297 | ... DC13: =BS13*$E13 -> 50591.813
B14: C2 | C14: C2 | D14: =AK14 -> 14590.596 | E14: =$C$54 -> 1.4 | J14: C2 | K14: 3870.9326 | L14: 5178.1198 | M14: 6408.1438 | N14: 7319.7934 | O14: 8253.5143 | P14: 8363.7576 | Q14: 8715.6849 | R14: 9321.7374 | S14: 9987.178 | T14: 10528.085 | U14: 11256.756 | V14: 11689.756 | W14: 12020.27 | X14: 12333.978 | Y14: 12841.642 | Z14: 13445.795 | AA14: 14011.73 | AB14: 14579.024 | AC14: 15133.052 | AD14: 15280.906 | AE14: 15277.04 | AF14: 15075.491 | AG14: 14925.867 | AH14: 14825.404 | AI14: 14730.838 | AJ14: 14651.511 | AK14: 14590.596 | AL14: 14541.566 | AM14: 14504.304 | AN14: 14443.533 | AO14: 14403.53 | AP14: 14389.541 | AQ14: 14402.464 | AR14: 14442.383 | AS14: 14505.311 | AT14: 14593.596 | AU14: 14703.008 | AV14: 14834.125 | AW14: 14988.726 | AX14: 15168.208 | AY14: 15374.664 | AZ14: 15598.394 | BA14: 15835.236 | BB14: 16084.944 | BC14: 16347.733 | BD14: =BC14*(1+$BT14/2) -> 16498.533 | BE14: =BD14*(1+$BT14/2) -> 16650.725 | BF14: =BE14*(1+$BT14/2) -> 16804.32 | BG14: =BF14*(1+$BT14/2) -> 16959.332 | BH14: =BG14*(1+$BT14/2) -> 17115.774 | BI14: =BH14*(1+$BT14/2) -> 17273.659 | BJ14: =BI14*(1+$BT14/2) -> 17433.001 | BK14: =BJ14*(1+$BT14/2) -> 17593.812 | ... BS14: =BR14*(1+$BT14/2) -> 18934.872 | BT14: 0.018449084 | BU14: =AK14*$E14 -> 20426.834 | BV14: =AL14*$E14 -> 20358.193 | BW14: =AM14*$E14 -> 20306.025 | BX14: =AN14*$E14 -> 20220.947 | BY14: =AO14*$E14 -> 20164.943 | BZ14: =AP14*$E14 -> 20145.357 | CA14: =AQ14*$E14 -> 20163.449 | CB14: =AR14*$E14 -> 20219.337 | ... DC14: =BS14*$E14 -> 26508.821
B15: C3 | C15: C3 | D15: =AK15 -> 6764.0495 | E15: =$C$54 -> 1.4 | J15: C3 | K15: 2109.7193 | L15: 3385.0601 | M15: 4551.4867 | N15: 5086.3403 | O15: 5541.7837 | P15: 5502.0065 | Q15: 5529.1021 | R15: 5698.7504 | S15: 5946.289 | T15: 6204.5362 | U15: 6533.1331 | V15: 6750.1524 | W15: 7015.4308 | X15: 7124.4409 | Y15: 7278.3854 | Z15: 7487.8068 | AA15: 7696.7077 | AB15: 7831.533 | AC15: 7947.1066 | AD15: 7880.9031 | AE15: 7779.2655 | AF15: 7651.8146 | AG15: 7547.9066 | AH15: 7336.7146 | AI15: 7133.9643 | AJ15: 6942.4113 | AK15: 6764.0495 | AL15: 6596.7166 | AM15: 6441.6553 | AN15: 6288.4703 | AO15: 6154.1279 | AP15: 6038.4535 | AQ15: 5943.8071 | AR15: 5869.056 | AS15: 5809.022 | AT15: 5763.8124 | AU15: 5730.5913 | AV15: 5709.0189 | AW15: 5700.6726 | AX15: 5706.9351 | AY15: 5727.9512 | AZ15: 5760.8344 | BA15: 5804.4106 | BB15: 5859.9714 | BC15: 5926.0242 | BD15: =BC15*(1+$BT15/2) -> 5977.004 | BE15: =BD15*(1+$BT15/2) -> 6028.4224 | BF15: =BE15*(1+$BT15/2) -> 6080.2832 | BG15: =BF15*(1+$BT15/2) -> 6132.59 | BH15: =BG15*(1+$BT15/2) -> 6185.3469 | BI15: =BH15*(1+$BT15/2) -> 6238.5576 | BJ15: =BI15*(1+$BT15/2) -> 6292.2261 | BK15: =BJ15*(1+$BT15/2) -> 6346.3562 | ... BS15: =BR15*(1+$BT15/2) -> 6796.5024 | BT15: 0.017205409 | BU15: =AK15*$E15 -> 9469.6694 | BV15: =AL15*$E15 -> 9235.4032 | BW15: =AM15*$E15 -> 9018.3174 | BX15: =AN15*$E15 -> 8803.8585 | BY15: =AO15*$E15 -> 8615.779 | BZ15: =AP15*$E15 -> 8453.8349 | CA15: =AQ15*$E15 -> 8321.3299 | CB15: =AR15*$E15 -> 8216.6784 | ... DC15: =BS15*$E15 -> 9515.1033
B16: Carga Ligeros | D16: =AK16 -> 4784.719 | E16: =$D$54 -> 1 | I16: Carga Ligeros | K16: 4593.9598 | L16: 4500.4935 | M16: 4401.8598 | N16: 4290.1744 | O16: 4201.434 | P16: 4060.1151 | Q16: 3967.3439 | R16: 4000.1559 | S16: 4013.6948 | T16: 4086.4013 | U16: 4176.0319 | V16: 4243.0334 | W16: 4347.5066 | X16: 4429.2697 | Y16: 4515.3657 | Z16: 4655.1878 | AA16: 4813.7373 | AB16: 4933.355 | AC16: 5115.0884 | AD16: 5129.4112 | AE16: 5211.7823 | AF16: 5161.2481 | AG16: 5159.0009 | AH16: 5063.6372 | AI16: 4976.6442 | AJ16: 4888.4513 | AK16: 4784.719 | AL16: 4719.5643 | AM16: 4697.6463 | AN16: 4656.9981 | AO16: 4586.9761 | AP16: 4477.9157 | AQ16: 4360.6715 | AR16: 4348.2891 | AS16: 4391.865 | AT16: 4416.8014 | AU16: 4433.6546 | AV16: 4514.69 | AW16: 4599.529 | AX16: 4696.0622 | AY16: 4795.1154 | AZ16: 4891.2524 | BA16: 4987.8437 | BB16: 5087.9225 | BC16: 5193.2973 | BD16: =SUM(BD17:BD19) -> 5231.5427 | BE16: =SUM(BE17:BE19) -> 5270.2059 | BF16: =SUM(BF17:BF19) -> 5309.2919 | BG16: =SUM(BG17:BG19) -> 5348.8057 | BH16: =SUM(BH17:BH19) -> 5388.7526 | BI16: =SUM(BI17:BI19) -> 5429.1378 | BJ16: =SUM(BJ17:BJ19) -> 5469.9665 | BK16: =SUM(BK17:BK19) -> 5511.2442 | ... BS16: =SUM(BS17:BS19) -> 5858.2913 | BT16: 0.015526796 | BU16: =AK16*$E16 -> 4784.719 | BV16: =AL16*$E16 -> 4719.5643 | BW16: =AM16*$E16 -> 4697.6463 | BX16: =AN16*$E16 -> 4656.9981 | BY16: =AO16*$E16 -> 4586.9761 | BZ16: =AP16*$E16 -> 4477.9157 | CA16: =AQ16*$E16 -> 4360.6715 | CB16: =AR16*$E16 -> 4348.2891 | ... DC16: =BS16*$E16 -> 5858.2913
B17: C4 | C17: C4 | D17: =AK17 -> 2230.7088 | E17: =$D$54 -> 1 | J17: C4 | K17: 105.53604 | L17: 99.366171 | M17: 96.708394 | N17: 94.077729 | O17: 91.474629 | P17: 88.899137 | Q17: 124.26287 | R17: 277.01856 | S17: 401.92774 | T17: 575.95034 | U17: 756.40408 | V17: 909.30909 | W17: 1101.6775 | X17: 1262.9661 | Y17: 1419.4348 | Z17: 1588.0905 | AA17: 1748.5076 | AB17: 1857.0428 | AC17: 2040.7165 | AD17: 2103.846 | AE17: 2181.6234 | AF17: 2202.5254 | AG17: 2228.4326 | AH17: 2223.7368 | AI17: 2225.2561 | AJ17: 2227.4064 | AK17: 2230.7088 | AL17: 2234.9287 | AM17: 2239.8534 | AN17: 2246.0688 | AO17: 2253.0863 | AP17: 2261.5864 | AQ17: 2271.6793 | AR17: 2283.2184 | AS17: 2296.1187 | AT17: 2311.4719 | AU17: 2323.6376 | AV17: 2338.9304 | AW17: 2354.2411 | AX17: 2370.3711 | AY17: 2386.5588 | AZ17: 2405.6977 | BA17: 2430.4196 | BB17: 2456.7116 | BC17: 2484.616 | BD17: =BC17*(1+$BT17/2) -> 2489.6886 | BE17: =BD17*(1+$BT17/2) -> 2494.7715 | BF17: =BE17*(1+$BT17/2) -> 2499.8647 | BG17: =BF17*(1+$BT17/2) -> 2504.9684 | BH17: =BG17*(1+$BT17/2) -> 2510.0825 | BI17: =BH17*(1+$BT17/2) -> 2515.207 | BJ17: =BI17*(1+$BT17/2) -> 2520.342 | BK17: =BJ17*(1+$BT17/2) -> 2525.4874 | ... BS17: =BR17*(1+$BT17/2) -> 2567.0312 | BT17: 0.0040831495 | BU17: =AK17*$E17 -> 2230.7088 | BV17: =AL17*$E17 -> 2234.9287 | BW17: =AM17*$E17 -> 2239.8534 | BX17: =AN17*$E17 -> 2246.0688 | BY17: =AO17*$E17 -> 2253.0863 | BZ17: =AP17*$E17 -> 2261.5864 | CA17: =AQ17*$E17 -> 2271.6793 | CB17: =AR17*$E17 -> 2283.2184 | ... DC17: =BS17*$E17 -> 2567.0312
B18: C5 | C18: C5 | D18: =AK18 -> 828.16039 | E18: =$D$54 -> 1 | J18: C5 | K18: 0 | L18: 19.866037 | M18: 46.433635 | N18: 54.282449 | O18: 59.228718 | P18: 59.260294 | Q18: 58.840342 | R18: 56.989384 | S18: 55.428455 | T18: 53.883881 | U18: 66.837035 | V18: 77.37103 | W18: 88.726602 | X18: 98.475509 | Y18: 113.43082 | Z18: 162.89176 | AA18: 232.97955 | AB18: 316.34476 | AC18: 388.97274 | AD18: 426.04098 | AE18: 485.27775 | AF18: 550.1784 | AG18: 633.55774 | AH18: 677.94555 | AI18: 727.88507 | AJ18: 777.97199 | AK18: 828.16039 | AL18: 878.58647 | AM18: 929.1822 | AN18: 979.93396 | AO18: 1030.7496 | AP18: 1081.9799 | AQ18: 1133.8827 | AR18: 1186.5791 | AS18: 1240.168 | AT18: 1294.4218 | AU18: 1349.0343 | AV18: 1404.5336 | AW18: 1461.0843 | AX18: 1518.7636 | AY18: 1577.1124 | AZ18: 1635.4024 | BA18: 1689.5715 | BB18: 1741.6458 | BC18: 1797.4533 | BD18: =BC18*(1+$BT18/2) -> 1820.2924 | BE18: =BD18*(1+$BT18/2) -> 1843.4216 | BF18: =BE18*(1+$BT18/2) -> 1866.8448 | BG18: =BF18*(1+$BT18/2) -> 1890.5655 | BH18: =BG18*(1+$BT18/2) -> 1914.5877 | BI18: =BH18*(1+$BT18/2) -> 1938.9151 | BJ18: =BI18*(1+$BT18/2) -> 1963.5516 | BK18: =BJ18*(1+$BT18/2) -> 1988.5012 | ... BS18: =BR18*(1+$BT18/2) -> 2199.8552 | BT18: 0.025412688 | BU18: =AK18*$E18 -> 828.16039 | BV18: =AL18*$E18 -> 878.58647 | BW18: =AM18*$E18 -> 929.1822 | BX18: =AN18*$E18 -> 979.93396 | BY18: =AO18*$E18 -> 1030.7496 | BZ18: =AP18*$E18 -> 1081.9799 | CA18: =AQ18*$E18 -> 1133.8827 | CB18: =AR18*$E18 -> 1186.5791 | ... DC18: =BS18*$E18 -> 2199.8552
B19: C6 | C19: C6 | D19: =AK19 -> 1725.8499 | E19: =$D$54 -> 1 | J19: C6 | K19: 4488.4238 | L19: 4381.2613 | M19: 4258.7178 | N19: 4141.8142 | O19: 4050.7307 | P19: 3911.9557 | Q19: 3784.2407 | R19: 3666.148 | S19: 3556.3386 | T19: 3456.5671 | U19: 3352.7908 | V19: 3256.3532 | W19: 3157.1025 | X19: 3067.828 | Y19: 2982.5001 | Z19: 2904.2055 | AA19: 2832.2502 | AB19: 2759.9674 | AC19: 2685.3992 | AD19: 2599.5242 | AE19: 2544.8811 | AF19: 2408.5443 | AG19: 2297.0106 | AH19: 2161.9549 | AI19: 2023.503 | AJ19: 1883.0729 | AK19: 1725.8499 | AL19: 1606.0491 | AM19: 1528.6107 | AN19: 1430.9953 | AO19: 1303.1402 | AP19: 1134.3494 | AQ19: 955.10958 | AR19: 878.49157 | AS19: 855.57831 | AT19: 810.90772 | AU19: 760.98275 | AV19: 771.22597 | AW19: 784.20359 | AX19: 806.92751 | AY19: 831.44419 | AZ19: 850.15237 | BA19: 867.8526 | BB19: 889.56501 | BC19: 911.22792 | BD19: =BC19*(1+$BT19/2) -> 921.56176 | BE19: =BD19*(1+$BT19/2) -> 932.0128 | BF19: =BE19*(1+$BT19/2) -> 942.58236 | BG19: =BF19*(1+$BT19/2) -> 953.27179 | BH19: =BG19*(1+$BT19/2) -> 964.08243 | BI19: =BH19*(1+$BT19/2) -> 975.01568 | BJ19: =BI19*(1+$BT19/2) -> 986.07292 | BK19: =BJ19*(1+$BT19/2) -> 997.25555 | ... BS19: =BR19*(1+$BT19/2) -> 1091.4049 | BT19: 0.022681146 | BU19: =AK19*$E19 -> 1725.8499 | BV19: =AL19*$E19 -> 1606.0491 | BW19: =AM19*$E19 -> 1528.6107 | BX19: =AN19*$E19 -> 1430.9953 | BY19: =AO19*$E19 -> 1303.1402 | BZ19: =AP19*$E19 -> 1134.3494 | CA19: =AQ19*$E19 -> 955.10958 | CB19: =AR19*$E19 -> 878.49157 | ... DC19: =BS19*$E19 -> 1091.4049
B20: Carga extrapesados | D20: =AK20 -> 2809.9519 | E20: =$D$55 -> 18.688702 | I20: Carga extrapesados | K20: 764.19011 | L20: 1108.9713 | M20: 1661.4373 | N20: 2043.8611 | O20: 2487.0231 | P20: 2375.5595 | Q20: 2418.217 | R20: 2535.9103 | S20: 2594.5503 | T20: 2671.8742 | U20: 2764.2078 | V20: 2874.6959 | W20: 2842.8622 | X20: 2826.0251 | Y20: 2926.6634 | Z20: 3014.5456 | AA20: 3105.6769 | AB20: 3160.1856 | AC20: 3247.2149 | AD20: 3114.1896 | AE20: 3044.9561 | AF20: 2983.4309 | AG20: 2919.924 | AH20: 2889.5971 | AI20: 2858.9691 | AJ20: 2832.3692 | AK20: 2809.9519 | AL20: 2792.0825 | AM20: 2778.2582 | AN20: 2766.7059 | AO20: 2758.992 | AP20: 2752.7527 | AQ20: 2746.7835 | AR20: 2750.9493 | AS20: 2762.6816 | AT20: 2778.2423 | AU20: 2796.3051 | AV20: 2818.4378 | AW20: 2845.9361 | AX20: 2873.8229 | AY20: 2901.2332 | AZ20: 2923.0959 | BA20: 2937.5263 | BB20: 2936.3394 | BC20: 2947.2646 | BD20: =SUM(BD21) -> 2972.2592 | BE20: =SUM(BE21) -> 2997.4658 | BF20: =SUM(BF21) -> 3022.8861 | BG20: =SUM(BG21) -> 3048.522 | BH20: =SUM(BH21) -> 3074.3753 | BI20: =SUM(BI21) -> 3100.4479 | BJ20: =SUM(BJ21) -> 3126.7415 | BK20: =SUM(BK21) -> 3153.2582 | ... BS20: =SUM(BS21) -> 3373.6492 | BT20: 0.016961206 | BU20: =AK20*$E20 -> 52514.354 | BV20: =AL20*$E20 -> 52180.396 | BW20: =AM20*$E20 -> 51922.038 | BX20: =AN20*$E20 -> 51706.142 | BY20: =AO20*$E20 -> 51561.978 | BZ20: =AP20*$E20 -> 51445.374 | CA20: =AQ20*$E20 -> 51333.817 | CB20: =AR20*$E20 -> 51411.671 | ... DC20: =BS20*$E20 -> 63049.124
B21: C7 | C21: C7 | D21: =AK21 -> 2809.9519 | E21: =$D$55 -> 18.688702 | J21: C7 | K21: 764.19011 | L21: 1108.9713 | M21: 1661.4373 | N21: 2043.8611 | O21: 2487.0231 | P21: 2375.5595 | Q21: 2418.217 | R21: 2535.9103 | S21: 2594.5503 | T21: 2671.8742 | U21: 2764.2078 | V21: 2874.6959 | W21: 2842.8622 | X21: 2826.0251 | Y21: 2926.6634 | Z21: 3014.5456 | AA21: 3105.6769 | AB21: 3160.1856 | AC21: 3247.2149 | AD21: 3114.1896 | AE21: 3044.9561 | AF21: 2983.4309 | AG21: 2919.924 | AH21: 2889.5971 | AI21: 2858.9691 | AJ21: 2832.3692 | AK21: 2809.9519 | AL21: 2792.0825 | AM21: 2778.2582 | AN21: 2766.7059 | AO21: 2758.992 | AP21: 2752.7527 | AQ21: 2746.7835 | AR21: 2750.9493 | AS21: 2762.6816 | AT21: 2778.2423 | AU21: 2796.3051 | AV21: 2818.4378 | AW21: 2845.9361 | AX21: 2873.8229 | AY21: 2901.2332 | AZ21: 2923.0959 | BA21: 2937.5263 | BB21: 2936.3394 | BC21: 2947.2646 | BD21: =BC21*(1+$BT21/2) -> 2972.2592 | BE21: =BD21*(1+$BT21/2) -> 2997.4658 | BF21: =BE21*(1+$BT21/2) -> 3022.8861 | BG21: =BF21*(1+$BT21/2) -> 3048.522 | BH21: =BG21*(1+$BT21/2) -> 3074.3753 | BI21: =BH21*(1+$BT21/2) -> 3100.4479 | BJ21: =BI21*(1+$BT21/2) -> 3126.7415 | BK21: =BJ21*(1+$BT21/2) -> 3153.2582 | ... BS21: =BR21*(1+$BT21/2) -> 3373.6492 | BT21: 0.016961206 | BU21: =AK21*$E21 -> 52514.354 | BV21: =AL21*$E21 -> 52180.396 | BW21: =AM21*$E21 -> 51922.038 | BX21: =AN21*$E21 -> 51706.142 | BY21: =AO21*$E21 -> 51561.978 | BZ21: =AP21*$E21 -> 51445.374 | CA21: =AQ21*$E21 -> 51333.817 | CB21: =AR21*$E21 -> 51411.671 | ... DC21: =BS21*$E21 -> 63049.124
B22: Tractocamiones | D22: =AK22 -> 31744.943 | E22: =$D$55 -> 18.688702 | I22: Tractocamiones | K22: 6638.6401 | L22: 7620.639 | M22: 8461.1099 | N22: 9097.0714 | O22: 9702.274 | P22: 9062.2185 | Q22: 8827.2876 | R22: 9367.8886 | S22: 10577.418 | T22: 11880.709 | U22: 14024.547 | V22: 15012.22 | W22: 16172.517 | X22: 17108.781 | Y22: 17957.445 | Z22: 19441.776 | AA22: 21372.06 | AB22: 23845.547 | AC22: 25412.181 | AD22: 24658.503 | AE22: 25117.176 | AF22: 25907.751 | AG22: 27336.005 | AH22: 28437.843 | AI22: 29547.666 | AJ22: 30649.492 | AK22: 31744.943 | AL22: 32859.815 | AM22: 33980.972 | AN22: 35101.326 | AO22: 36213.084 | AP22: 37323.244 | AQ22: 38435.688 | AR22: 39611.061 | AS22: 40860.755 | AT22: 42128.184 | AU22: 43389.882 | AV22: 44700.819 | AW22: 46041.935 | AX22: 47411.507 | AY22: 48800.296 | AZ22: 50168.645 | BA22: 51499.685 | BB22: 52830.341 | BC22: 54172.577 | BD22: =SUM(BD23) -> 54764.715 | BE22: =SUM(BE23) -> 55363.325 | BF22: =SUM(BF23) -> 55968.479 | BG22: =SUM(BG23) -> 56580.247 | BH22: =SUM(BH23) -> 57198.703 | BI22: =SUM(BI23) -> 57823.918 | BJ22: =SUM(BJ23) -> 58455.968 | BK22: =SUM(BK23) -> 59094.926 | ... BS22: =SUM(BS23) -> 64464.54 | BT22: 0.021861174 | BU22: =AK22*$E22 -> 593271.77 | BV22: =AL22*$E22 -> 614107.28 | BW22: =AM22*$E22 -> 635060.25 | BX22: =AN22*$E22 -> 655998.21 | BY22: =AO22*$E22 -> 676775.53 | BZ22: =AP22*$E22 -> 697522.97 | CA22: =AQ22*$E22 -> 718313.1 | CB22: =AR22*$E22 -> 740279.3 | ... DC22: =BS22*$E22 -> 1204758.6
B23: C8 | C23: C8 | D23: =AK23 -> 31744.943 | E23: =$D$55 -> 18.688702 | J23: C8 | K23: 6638.6401 | L23: 7620.639 | M23: 8461.1099 | N23: 9097.0714 | O23: 9702.274 | P23: 9062.2185 | Q23: 8827.2876 | R23: 9367.8886 | S23: 10577.418 | T23: 11880.709 | U23: 14024.547 | V23: 15012.22 | W23: 16172.517 | X23: 17108.781 | Y23: 17957.445 | Z23: 19441.776 | AA23: 21372.06 | AB23: 23845.547 | AC23: 25412.181 | AD23: 24658.503 | AE23: 25117.176 | AF23: 25907.751 | AG23: 27336.005 | AH23: 28437.843 | AI23: 29547.666 | AJ23: 30649.492 | AK23: 31744.943 | AL23: 32859.815 | AM23: 33980.972 | AN23: 35101.326 | AO23: 36213.084 | AP23: 37323.244 | AQ23: 38435.688 | AR23: 39611.061 | AS23: 40860.755 | AT23: 42128.184 | AU23: 43389.882 | AV23: 44700.819 | AW23: 46041.935 | AX23: 47411.507 | AY23: 48800.296 | AZ23: 50168.645 | BA23: 51499.685 | BB23: 52830.341 | BC23: 54172.577 | BD23: =BC23*(1+$BT23/2) -> 54764.715 | BE23: =BD23*(1+$BT23/2) -> 55363.325 | BF23: =BE23*(1+$BT23/2) -> 55968.479 | BG23: =BF23*(1+$BT23/2) -> 56580.247 | BH23: =BG23*(1+$BT23/2) -> 57198.703 | BI23: =BH23*(1+$BT23/2) -> 57823.918 | BJ23: =BI23*(1+$BT23/2) -> 58455.968 | BK23: =BJ23*(1+$BT23/2) -> 59094.926 | ... BS23: =BR23*(1+$BT23/2) -> 64464.54 | BT23: 0.021861174 | BU23: =AK23*$E23 -> 593271.77 | BV23: =AL23*$E23 -> 614107.28 | BW23: =AM23*$E23 -> 635060.25 | BX23: =AN23*$E23 -> 655998.21 | BY23: =AO23*$E23 -> 676775.53 | BZ23: =AP23*$E23 -> 697522.97 | CA23: =AQ23*$E23 -> 718313.1 | CB23: =AR23*$E23 -> 740279.3 | ... DC23: =BS23*$E23 -> 1204758.6
B24: Motocicletas | D24: =AK24 -> 17320.037 | E24: 1 | I24: Motocicletas | K24: 1093.6158 | L24: 1155.4412 | M24: 1189.2436 | N24: 1247.6441 | O24: 1340.482 | P24: 1458.3769 | Q24: 1595.3095 | R24: 1855.4538 | S24: 2091.5896 | T24: 2338.7777 | U24: 2365.542 | V24: 2360.5698 | W24: 2440.03 | X24: 2645.2569 | Y24: 2926.2759 | Z24: 3377.3452 | AA24: 3884.4333 | AB24: 4817.0432 | AC24: 5991.3013 | AD24: 7376.6413 | AE24: 8989.2138 | AF24: 10638.119 | AG24: 12009.316 | AH24: 13428.108 | AI24: 14783.393 | AJ24: 16080.631 | AK24: 17320.037 | AL24: 18501.797 | AM24: 19628.31 | AN24: 20701.863 | AO24: 21724.859 | AP24: 22711.413 | AQ24: 23665.994 | AR24: 24591.388 | AS24: 25493.214 | AT24: 26375.116 | AU24: 27243.244 | AV24: 28102.491 | AW24: 28954.461 | AX24: 29804.172 | AY24: 30655.735 | AZ24: 31480.644 | BA24: 32285.483 | BB24: 33071.81 | BC24: 33842.993 | BD24: =BC24*(1+$BT24*0.66) -> 34294.86 | BE24: =BD24*(1+$BT24*0.66) -> 34752.761 | BF24: =BE24*(1+$BT24*0.66) -> 35216.776 | BG24: =BF24*(1+$BT24*0.66) -> 35686.986 | BH24: =BG24*(1+$BT24*0.66) -> 36163.474 | BI24: =BH24*(1+$BT24*0.66) -> 36646.325 | BJ24: =BI24*(1+$BT24*0.66) -> 37135.622 | BK24: =BJ24*(1+$BT24*0.66) -> 37631.452 | ... BS24: =BR24*(1+$BT24*0.66) -> 41844 | BT24: 0.02023012 | BU24: =AK24*$E24 -> 17320.037 | BV24: =AL24*$E24 -> 18501.797 | BW24: =AM24*$E24 -> 19628.31 | BX24: =AN24*$E24 -> 20701.863 | BY24: =AO24*$E24 -> 21724.859 | BZ24: =AP24*$E24 -> 22711.413 | CA24: =AQ24*$E24 -> 23665.994 | CB24: =AR24*$E24 -> 24591.388 | ... DC24: =BS24*$E24 -> 41844
B25: No privado | D25: =AK25 -> 11186.736 | E25: =$C$55 -> 35.666667 | I25: No privado | K25: 9276.481 | L25: 10493.19 | M25: 12490.735 | N25: 14053.905 | O25: 15301.476 | P25: 14369.234 | Q25: 13732.28 | R25: 13524.302 | S25: 13379.111 | T25: 13273.074 | U25: 13366.428 | V25: 13743.916 | W25: 13566.811 | X25: 13402.71 | Y25: 13581 | Z25: 13814.034 | AA25: 14021.888 | AB25: 13997.317 | AC25: 14156.052 | AD25: 13408.917 | AE25: 12861.834 | AF25: 12417.573 | AG25: 12003.886 | AH25: 11770.337 | AI25: 11558.146 | AJ25: 11370.309 | AK25: 11186.736 | AL25: 11061.668 | AM25: 10999.802 | AN25: 10935.954 | AO25: 10856.477 | AP25: 10754.918 | AQ25: 10662.248 | AR25: 10698.523 | AS25: 10811.662 | AT25: 10918.243 | AU25: 11037.095 | AV25: 11236.031 | AW25: 11456.486 | AX25: 11696.54 | AY25: 11948.068 | AZ25: 12189.507 | BA25: 12424.391 | BB25: 12654.057 | BC25: 12889.344 | BD25: =SUM(BD26:BD28) -> 13013.003 | BE25: =SUM(BE26:BE28) -> 13137.852 | BF25: =SUM(BF26:BF28) -> 13263.904 | BG25: =SUM(BG26:BG28) -> 13391.17 | BH25: =SUM(BH26:BH28) -> 13519.662 | BI25: =SUM(BI26:BI28) -> 13649.392 | BJ25: =SUM(BJ26:BJ28) -> 13780.372 | BK25: =SUM(BK26:BK28) -> 13912.613 | ... BS25: =SUM(BS26:BS28) -> 15017.459 | BT25: 0.019199091 | BU25: =AK25*$E25 -> 398993.57 | BV25: =AL25*$E25 -> 394532.84 | BW25: =AM25*$E25 -> 392326.26 | BX25: =AN25*$E25 -> 390049.04 | BY25: =AO25*$E25 -> 387214.35 | BZ25: =AP25*$E25 -> 383592.06 | CA25: =AQ25*$E25 -> 380286.85 | CB25: =AR25*$E25 -> 381580.66 | ... DC25: =BS25*$E25 -> 535622.71
B26: Autobuses | C26: Autobuses | D26: =AK26 -> 7317.2663 | E26: =$C$55 -> 35.666667 | J26: Autobuses | K26: 3675.3286 | L26: 4981.9835 | M26: 7084.2414 | N26: 8754.9828 | O26: 10067.503 | P26: 9322.3501 | Q26: 8859.8133 | R26: 8786.6087 | S26: 8727.8887 | T26: 8687.3292 | U26: 8814.3253 | V26: 9189.5162 | W26: 8979.5581 | X26: 8768.5317 | Y26: 8877.1198 | Z26: 9056.0532 | AA26: 9241.821 | AB26: 9234.9831 | AC26: 9431.4997 | AD26: 8781.8097 | AE26: 8295.0314 | AF26: 7973.7103 | AG26: 7653.0977 | AH26: 7527.5185 | AI26: 7430.9539 | AJ26: 7362.173 | AK26: 7317.2663 | AL26: 7294.8655 | AM26: 7292.6105 | AN26: 7307.9013 | AO26: 7339.1597 | AP26: 7387.8012 | AQ26: 7450.3793 | AR26: 7532.6615 | AS26: 7634.5617 | AT26: 7749.2042 | AU26: 7876.9917 | AV26: 8019.6894 | AW26: 8177.6467 | AX26: 8341.4719 | AY26: 8511.3662 | AZ26: 8675.574 | BA26: 8832.3723 | BB26: 8978.1638 | BC26: 9129.1171 | BD26: =BC26*(1+$BT26/2) -> 9213.6152 | BE26: =BD26*(1+$BT26/2) -> 9298.8955 | BF26: =BE26*(1+$BT26/2) -> 9384.965 | BG26: =BF26*(1+$BT26/2) -> 9471.8313 | BH26: =BG26*(1+$BT26/2) -> 9559.5015 | BI26: =BH26*(1+$BT26/2) -> 9647.9832 | BJ26: =BI26*(1+$BT26/2) -> 9737.2839 | BK26: =BJ26*(1+$BT26/2) -> 9827.4112 | ... BS26: =BR26*(1+$BT26/2) -> 10579.118 | BT26: 0.018511785 | BU26: =AK26*$E26 -> 260982.5 | BV26: =AL26*$E26 -> 260183.54 | BW26: =AM26*$E26 -> 260103.11 | BX26: =AN26*$E26 -> 260648.48 | BY26: =AO26*$E26 -> 261763.36 | BZ26: =AP26*$E26 -> 263498.24 | CA26: =AQ26*$E26 -> 265730.19 | CB26: =AR26*$E26 -> 268664.93 | ... DC26: =BS26*$E26 -> 377321.89
B27: Urbano y Suburbano | C27: Urbano y Suburbano | D27: =AK27 -> 1854.2382 | E27: =$C$55 -> 35.666667 | J27: Urbano y Suburbano | K27: 4834.6593 | L27: 4692.6732 | M27: 4539.1445 | N27: 4393.0887 | O27: 4278.4736 | P27: 4125.375 | Q27: 3978.0019 | R27: 3840.3319 | S27: 3712.0855 | T27: 3600.1126 | U27: 3490.4929 | V27: 3388.3975 | W27: 3285.1202 | X27: 3194.0692 | Y27: 3110.2765 | Z27: 3036.2041 | AA27: 2969.7619 | AB27: 2903.3392 | AC27: 2833.5963 | AD27: 2751.2206 | AE27: 2694.7467 | AF27: 2556.8299 | AG27: 2441.4003 | AH27: 2305.8707 | AI27: 2163.783 | AJ27: 2018.5409 | AK27: 1854.2382 | AL27: 1726.3419 | AM27: 1641.0401 | AN27: 1534.9528 | AO27: 1396.7969 | AP27: 1216.234 | AQ27: 1027.8993 | AR27: 947.06609 | AS27: 921.84012 | AT27: 874.76731 | AU27: 823.90454 | AV27: 835.17271 | AW27: 849.59979 | AX27: 873.95279 | AY27: 900.04817 | AZ27: 920.30486 | BA27: 939.67509 | BB27: 963.25633 | BC27: 986.72574 | BD27: =BC27*(1+$BT27/2) -> 997.88067 | BE27: =BD27*(1+$BT27/2) -> 1009.1617 | BF27: =BE27*(1+$BT27/2) -> 1020.5703 | BG27: =BF27*(1+$BT27/2) -> 1032.1078 | BH27: =BG27*(1+$BT27/2) -> 1043.7757 | BI27: =BH27*(1+$BT27/2) -> 1055.5756 | BJ27: =BI27*(1+$BT27/2) -> 1067.5089 | BK27: =BJ27*(1+$BT27/2) -> 1079.5771 | ... BS27: =BR27*(1+$BT27/2) -> 1181.1657 | BT27: 0.022609973 | BU27: =AK27*$E27 -> 66134.494 | BV27: =AL27*$E27 -> 61572.861 | BW27: =AM27*$E27 -> 58530.43 | BX27: =AN27*$E27 -> 54746.649 | BY27: =AO27*$E27 -> 49819.09 | BZ27: =AP27*$E27 -> 43379.012 | CA27: =AQ27*$E27 -> 36661.743 | CB27: =AR27*$E27 -> 33778.691 | ... DC27: =BS27*$E27 -> 42128.244
B28: Taxis | C28: Taxis | D28: =AK28 -> 2015.2313 | E28: =C54+0.5 -> 1.9 | J28: Taxis | K28: 766.49313 | L28: 818.53326 | M28: 867.3487 | N28: 905.83305 | O28: 955.49979 | P28: 921.50849 | Q28: 894.46486 | R28: 897.36177 | S28: 939.13708 | T28: 985.63169 | U28: 1061.6097 | V28: 1166.0022 | W28: 1302.1323 | X28: 1440.1094 | Y28: 1593.6035 | Z28: 1721.7769 | AA28: 1810.3049 | AB28: 1858.9948 | AC28: 1890.9558 | AD28: 1875.8867 | AE28: 1872.056 | AF28: 1887.0327 | AG28: 1909.3882 | AH28: 1936.9481 | AI28: 1963.4087 | AJ28: 1989.5951 | AK28: 2015.2313 | AL28: 2040.4609 | AM28: 2066.1511 | AN28: 2093.1004 | AO28: 2120.5205 | AP28: 2150.8825 | AQ28: 2183.9696 | AR28: 2218.7956 | AS28: 2255.2598 | AT28: 2294.2717 | AU28: 2336.1985 | AV28: 2381.1692 | AW28: 2429.2399 | AX28: 2481.1157 | AY28: 2536.6534 | AZ28: 2593.6277 | BA28: 2652.3437 | BB28: 2712.6368 | BC28: 2773.5016 | BD28: =BC28*(1+$BT28/2) -> 2801.507 | BE28: =BD28*(1+$BT28/2) -> 2829.7952 | BF28: =BE28*(1+$BT28/2) -> 2858.369 | BG28: =BF28*(1+$BT28/2) -> 2887.2314 | BH28: =BG28*(1+$BT28/2) -> 2916.3851 | BI28: =BH28*(1+$BT28/2) -> 2945.8333 | BJ28: =BI28*(1+$BT28/2) -> 2975.5788 | BK28: =BJ28*(1+$BT28/2) -> 3005.6247 | ... BS28: =BR28*(1+$BT28/2) -> 3257.1749 | BT28: 0.020194979 | BU28: =AK28*$E28 -> 3828.9394 | BV28: =AL28*$E28 -> 3876.8757 | BW28: =AM28*$E28 -> 3925.687 | BX28: =AN28*$E28 -> 3976.8908 | BY28: =AO28*$E28 -> 4028.9889 | BZ28: =AP28*$E28 -> 4086.6768 | CA28: =AQ28*$E28 -> 4149.5422 | CB28: =AR28*$E28 -> 4215.7116 | ... DC28: =BS28*$E28 -> 6188.6324
B29: Importados | D29: =AK29 -> 68672.257 | E29: =$C$54 -> 1.4 | I29: Importados | K29: 0 | L29: 0 | M29: 0 | N29: 0 | O29: 0 | P29: 0 | Q29: 0 | R29: 0 | S29: 0 | T29: 0 | U29: 0 | V29: 0 | W29: 0 | X29: 0 | Y29: 0 | Z29: 0 | AA29: 20202.823 | AB29: 35138.771 | AC29: 45400.671 | AD29: 45056.508 | AE29: 47356.873 | AF29: 50649.316 | AG29: 52351.043 | AH29: 56421.242 | AI29: 60350.005 | AJ29: 64554.436 | AK29: 68672.257 | AL29: 73580.76 | AM29: 78489.206 | AN29: 84305.898 | AO29: 90215.876 | AP29: 96218.653 | AQ29: 102308.69 | AR29: 108471.53 | AS29: 114727.75 | AT29: 121075.01 | AU29: 127502.03 | AV29: 134010.5 | AW29: 140604.12 | AX29: 147268.3 | AY29: 153992.66 | AZ29: 160786.81 | BA29: 167642.29 | BB29: 174530.93 | BC29: 181459.87 | BD29: =SUM(BD30:BD32) -> 184562.46 | BE29: =SUM(BE30:BE32) -> 187719.46 | BF29: =SUM(BF30:BF32) -> 190931.85 | BG29: =SUM(BG30:BG32) -> 194200.61 | BH29: =SUM(BH30:BH32) -> 197526.75 | BI29: =SUM(BI30:BI32) -> 200911.31 | BJ29: =SUM(BJ30:BJ32) -> 204355.33 | BK29: =SUM(BK30:BK32) -> 207859.87 | ... BS29: =SUM(BS30:BS32) -> 238209.5 | BT29: 0.03441779 | BU29: =AK29*$E29 -> 96141.16 | BV29: =AL29*$E29 -> 103013.06 | BW29: =AM29*$E29 -> 109884.89 | BX29: =AN29*$E29 -> 118028.26 | BY29: =AO29*$E29 -> 126302.23 | BZ29: =AP29*$E29 -> 134706.11 | CA29: =AQ29*$E29 -> 143232.16 | CB29: =AR29*$E29 -> 151860.14 | ... DC29: =BS29*$E29 -> 333493.29
B30: Ligeros importados | C30: Ligeros importados | D30: =AK30 -> 16327.792 | E30: =$C$54 -> 1.4 | J30: Ligeros importados | K30: 0 | L30: 0 | M30: 0 | N30: 0 | O30: 0 | P30: 0 | Q30: 0 | R30: 0 | S30: 0 | T30: 0 | U30: 0 | V30: 0 | W30: 0 | X30: 0 | Y30: 0 | Z30: 0 | AA30: 5398.2701 | AB30: 9373.3795 | AC30: 12085.263 | AD30: 11903.693 | AE30: 12382.785 | AF30: 13113.786 | AG30: 13351.479 | AH30: 14114.043 | AI30: 14815.699 | AJ30: 15594.776 | AK30: 16327.792 | AL30: 17310.784 | AM30: 18272.042 | AN30: 19507.767 | AO30: 20747.378 | AP30: 21998.973 | AQ30: 23265.521 | AR30: 24539.436 | AS30: 25824.873 | AT30: 27119.63 | AU30: 28418.284 | AV30: 29725.208 | AW30: 31037.974 | AX30: 32343.571 | AY30: 33635.452 | AZ30: 34911.072 | BA30: 36168.505 | BB30: 37401.073 | BC30: 38612.236 | BD30: =BC30*(1+$BT30/2) -> 39107.824 | BE30: =BD30*(1+$BT30/2) -> 39609.773 | BF30: =BE30*(1+$BT30/2) -> 40118.164 | BG30: =BF30*(1+$BT30/2) -> 40633.08 | BH30: =BG30*(1+$BT30/2) -> 41154.606 | BI30: =BH30*(1+$BT30/2) -> 41682.825 | BJ30: =BI30*(1+$BT30/2) -> 42217.824 | BK30: =BJ30*(1+$BT30/2) -> 42759.689 | ... BS30: =BR30*(1+$BT30/2) -> 47352.633 | BT30: 0.02566999 | BU30: =AK30*$E30 -> 22858.909 | BV30: =AL30*$E30 -> 24235.098 | BW30: =AM30*$E30 -> 25580.858 | BX30: =AN30*$E30 -> 27310.874 | BY30: =AO30*$E30 -> 29046.33 | BZ30: =AP30*$E30 -> 30798.563 | CA30: =AQ30*$E30 -> 32571.73 | CB30: =AR30*$E30 -> 34355.211 | ... DC30: =BS30*$E30 -> 66293.686
B31: Camionetas importadas | C31: Camionetas importadas | D31: =AK31 -> 47767.087 | E31: =$C$54 -> 1.4 | J31: Camionetas importadas | K31: 0 | L31: 0 | M31: 0 | N31: 0 | O31: 0 | P31: 0 | Q31: 0 | R31: 0 | S31: 0 | T31: 0 | U31: 0 | V31: 0 | W31: 0 | X31: 0 | Y31: 0 | Z31: 0 | AA31: 14804.553 | AB31: 25765.392 | AC31: 33315.408 | AD31: 32986.045 | AE31: 34502.244 | AF31: 36759.673 | AG31: 37717.431 | AH31: 40161.362 | AI31: 42552.605 | AJ31: 45168.003 | AK31: 47767.087 | AL31: 50929.478 | AM31: 54134.876 | AN31: 57994.041 | AO31: 61960.789 | AP31: 66025.006 | AQ31: 70177.061 | AR31: 74409.106 | AS31: 78736.823 | AT31: 83159.176 | AU31: 87669.546 | AV31: 92264.252 | AW31: 96948.287 | AX31: 101719.54 | AY31: 106573.6 | AZ31: 111521.82 | BA31: 116557.02 | BB31: 121657.3 | BC31: 126827.07 | BD31: =BC31*(1+$BT31/2) -> 129223.56 | BE31: =BD31*(1+$BT31/2) -> 131665.33 | BF31: =BE31*(1+$BT31/2) -> 134153.24 | BG31: =BF31*(1+$BT31/2) -> 136688.17 | BH31: =BG31*(1+$BT31/2) -> 139270.99 | BI31: =BH31*(1+$BT31/2) -> 141902.62 | BJ31: =BI31*(1+$BT31/2) -> 144583.97 | BK31: =BJ31*(1+$BT31/2) -> 147315.99 | ... BS31: =BR31*(1+$BT31/2) -> 171114.91 | BT31: 0.037791466 | BU31: =AK31*$E31 -> 66873.922 | BV31: =AL31*$E31 -> 71301.269 | BW31: =AM31*$E31 -> 75788.826 | BX31: =AN31*$E31 -> 81191.658 | BY31: =AO31*$E31 -> 86745.105 | BZ31: =AP31*$E31 -> 92435.009 | CA31: =AQ31*$E31 -> 98247.886 | CB31: =AR31*$E31 -> 104172.75 | ... DC31: =BS31*$E31 -> 239560.87
B32: Pesados importados | C32: Pesados importados | D32: =AK32 -> 4577.3769 | E32: =$D$55 -> 18.688702 | J32: Pesados importados | K32: 0 | L32: 0 | M32: 0 | N32: 0 | O32: 0 | P32: 0 | Q32: 0 | R32: 0 | S32: 0 | T32: 0 | U32: 0 | V32: 0 | W32: 0 | X32: 0 | Y32: 0 | Z32: 0 | AA32: 0 | AB32: 0 | AC32: 0 | AD32: 166.76975 | AE32: 471.84356 | AF32: 775.85704 | AG32: 1282.1328 | AH32: 2145.8375 | AI32: 2981.7005 | AJ32: 3791.6578 | AK32: 4577.3769 | AL32: 5340.4988 | AM32: 6082.2888 | AN32: 6804.0904 | AO32: 7507.709 | AP32: 8194.6736 | AQ32: 8866.1025 | AR32: 9522.9882 | AS32: 10166.054 | AT32: 10796.203 | AU32: 11414.204 | AV32: 12021.039 | AW32: 12617.864 | AX32: 13205.193 | AY32: 13783.616 | AZ32: 14353.92 | BA32: 14916.767 | BB32: 15472.557 | BC32: 16020.567 | BD32: =BC32*(1+$BT32/2) -> 16231.08 | BE32: =BD32*(1+$BT32/2) -> 16444.358 | BF32: =BE32*(1+$BT32/2) -> 16660.439 | BG32: =BF32*(1+$BT32/2) -> 16879.36 | BH32: =BG32*(1+$BT32/2) -> 17101.157 | BI32: =BH32*(1+$BT32/2) -> 17325.868 | BJ32: =BI32*(1+$BT32/2) -> 17553.532 | BK32: =BJ32*(1+$BT32/2) -> 17784.188 | ... BS32: =BR32*(1+$BT32/2) -> 19741.957 | BT32: 0.026280266 | BU32: =AK32*$E32 -> 85545.232 | BV32: =AL32*$E32 -> 99806.99 | BW32: =AM32*$E32 -> 113670.08 | BX32: =AN32*$E32 -> 127159.62 | BY32: =AO32*$E32 -> 140309.33 | BZ32: =AP32*$E32 -> 153147.81 | CA32: =AQ32*$E32 -> 165695.94 | CB32: =AR32*$E32 -> 177972.29 | ... DC32: =BS32*$E32 -> 368951.54
B33: Nuevas tecnologías | D33: =AK33 -> 1.6442209 | E33: =$C$54 -> 1.4 | I33: Nuevas tecnologías | K33: 0 | L33: 0 | M33: 0 | N33: 0 | O33: 0 | P33: 0 | Q33: 0 | R33: 0 | S33: 0 | T33: 0 | U33: 0 | V33: 0 | W33: 0 | X33: 0 | Y33: 0 | Z33: 0 | AA33: 0 | AB33: 0 | AC33: 0 | AD33: 0.060727992 | AE33: 0.10619337 | AF33: 0.17455217 | AG33: 0.26489023 | AH33: 0.39376803 | AI33: 0.61934465 | AJ33: 1.0006289 | AK33: 1.6442209 | AL33: 2.7296517 | AM33: 4.5594026 | AN33: 6.5178711 | AO33: 118.13635 | AP33: 305.51924 | AQ33: 393.09396 | AR33: 557.6772 | AS33: 850.87355 | AT33: 1363.9252 | AU33: 2253.6295 | AV33: 3238.5537 | AW33: 5058.4616 | AX33: 7756.8973 | AY33: 10289.602 | AZ33: 13125.18 | BA33: 16281.239 | BB33: 19793.92 | BC33: 23704.721 | BD33: =SUM(BD34:BD36) -> 25410.704 | BE33: =SUM(BE34:BE36) -> 27239.503 | BF33: =SUM(BF34:BF36) -> 29199.962 | BG33: =SUM(BG34:BG36) -> 31301.562 | BH33: =SUM(BH34:BH36) -> 33554.466 | BI33: =SUM(BI34:BI36) -> 35969.57 | BJ33: =SUM(BJ34:BJ36) -> 38558.554 | BK33: =SUM(BK34:BK36) -> 41333.94 | ... BS33: =SUM(BS34:BS36) -> 72079.993 | BT33: 0.14398041 | BU33: =AK33*$E33 -> 2.3019092 | BV33: =AL33*$E33 -> 3.8215123 | BW33: =AM33*$E33 -> 6.3831637 | BX33: =AN33*$E33 -> 9.1250195 | BY33: =AO33*$E33 -> 165.39089 | BZ33: =AP33*$E33 -> 427.72694 | CA33: =AQ33*$E33 -> 550.33155 | CB33: =AR33*$E33 -> 780.74808 | ... DC33: =BS33*$E33 -> 100911.99
B34: Híbridos | C34: Híbridos | D34: =AK34 -> 1.6442209 | E34: =$C$54 -> 1.4 | J34: Híbridos | K34: 0 | L34: 0 | M34: 0 | N34: 0 | O34: 0 | P34: 0 | Q34: 0 | R34: 0 | S34: 0 | T34: 0 | U34: 0 | V34: 0 | W34: 0 | X34: 0 | Y34: 0 | Z34: 0 | AA34: 0 | AB34: 0 | AC34: 0 | AD34: 0.060727992 | AE34: 0.10619337 | AF34: 0.17455217 | AG34: 0.26489023 | AH34: 0.39376803 | AI34: 0.61934465 | AJ34: 1.0006289 | AK34: 1.6442209 | AL34: 2.7296517 | AM34: 4.5594026 | AN34: 6.5178711 | AO34: 10.129361 | AP34: 15.434649 | AQ34: 20.216122 | AR34: 25.891684 | AS34: 30.392165 | AT34: 34.111828 | AU34: 40.003237 | AV34: 46.212795 | AW34: 53.192864 | AX34: 60.680403 | AY34: 68.680751 | AZ34: 77.325866 | BA34: 86.691213 | BB34: 96.861182 | BC34: 107.93042 | BD34: =BC34*(1+$BT34/2) -> 113.62728 | BE34: =BD34*(1+$BT34/2) -> 119.62484 | BF34: =BE34*(1+$BT34/2) -> 125.93897 | BG34: =BF34*(1+$BT34/2) -> 132.58637 | BH34: =BG34*(1+$BT34/2) -> 139.58464 | BI34: =BH34*(1+$BT34/2) -> 146.95231 | BJ34: =BI34*(1+$BT34/2) -> 154.70885 | BK34: =BJ34*(1+$BT34/2) -> 162.87481 | ... BS34: =BR34*(1+$BT34/2) -> 245.78988 | BT34: 0.10556549 | BU34: =AK34*$E34 -> 2.3019092 | BV34: =AL34*$E34 -> 3.8215123 | BW34: =AM34*$E34 -> 6.3831637 | BX34: =AN34*$E34 -> 9.1250195 | BY34: =AO34*$E34 -> 14.181106 | BZ34: =AP34*$E34 -> 21.608509 | CA34: =AQ34*$E34 -> 28.302571 | CB34: =AR34*$E34 -> 36.248358 | ... DC34: =BS34*$E34 -> 344.10583
B35: Eléctricos | C35: Eléctricos | D35: =AK35 -> 0 | E35: =$C$54 -> 1.4 | J35: Eléctricos | K35: 0 | L35: 0 | M35: 0 | N35: 0 | O35: 0 | P35: 0 | Q35: 0 | R35: 0 | S35: 0 | T35: 0 | U35: 0 | V35: 0 | W35: 0 | X35: 0 | Y35: 0 | Z35: 0 | AA35: 0 | AB35: 0 | AC35: 0 | AD35: 0 | AE35: 0 | AF35: 0 | AG35: 0 | AH35: 0 | AI35: 0 | AJ35: 0 | AK35: 0 | AL35: 0 | AM35: 0 | AN35: 0 | AO35: 108.00699 | AP35: 290.08459 | AQ35: 372.87784 | AR35: 531.78551 | AS35: 820.48138 | AT35: 1329.8133 | AU35: 2213.6263 | AV35: 3192.3409 | AW35: 5005.2687 | AX35: 7696.2169 | AY35: 10220.921 | AZ35: 13047.854 | BA35: 16194.548 | BB35: 19697.058 | BC35: 23596.791 | BD35: =BC35*(1+$BT35/2) -> 25297.077 | BE35: =BD35*(1+$BT35/2) -> 27119.878 | BF35: =BE35*(1+$BT35/2) -> 29074.023 | BG35: =BF35*(1+$BT35/2) -> 31168.975 | BH35: =BG35*(1+$BT35/2) -> 33414.881 | BI35: =BH35*(1+$BT35/2) -> 35822.617 | BJ35: =BI35*(1+$BT35/2) -> 38403.845 | BK35: =BJ35*(1+$BT35/2) -> 41171.066 | ... BS35: =BR35*(1+$BT35/2) -> 71834.203 | BT35: 0.14411163 | BU35: =AK35*$E35 -> 0 | BV35: =AL35*$E35 -> 0 | BW35: =AM35*$E35 -> 0 | BX35: =AN35*$E35 -> 0 | BY35: =AO35*$E35 -> 151.20978 | BZ35: =AP35*$E35 -> 406.11843 | CA35: =AQ35*$E35 -> 522.02898 | CB35: =AR35*$E35 -> 744.49972 | ... DC35: =BS35*$E35 -> 100567.88
B36: Celdas Hidrógeno | C36: Celdas Hidrógeno | D36: =AK36 -> 0 | E36: =$C$54 -> 1.4 | J36: Celdas Hidrógeno | K36: 0 | L36: 0 | M36: 0 | N36: 0 | O36: 0 | P36: 0 | Q36: 0 | R36: 0 | S36: 0 | T36: 0 | U36: 0 | V36: 0 | W36: 0 | X36: 0 | Y36: 0 | Z36: 0 | AA36: 0 | AB36: 0 | AC36: 0 | AD36: 0 | AE36: 0 | AF36: 0 | AG36: 0 | AH36: 0 | AI36: 0 | AJ36: 0 | AK36: 0 | AL36: 0 | AM36: 0 | AN36: 0 | AO36: 0 | AP36: 0 | AQ36: 0 | AR36: 0 | AS36: 0 | AT36: 0 | AU36: 0 | AV36: 0 | AW36: 0 | AX36: 0 | AY36: 0 | AZ36: 0 | BA36: 0 | BB36: 0 | BC36: 0 | BD36: =BC36*(1+$BT36/2) -> 0 | BE36: =BD36*(1+$BT36/2) -> 0 | BF36: =BE36*(1+$BT36/2) -> 0 | BG36: =BF36*(1+$BT36/2) -> 0 | BH36: =BG36*(1+$BT36/2) -> 0 | BI36: =BH36*(1+$BT36/2) -> 0 | BJ36: =BI36*(1+$BT36/2) -> 0 | BK36: =BJ36*(1+$BT36/2) -> 0 | ... BS36: =BR36*(1+$BT36/2) -> 0 | BT36: 0 | BU36: =AK36*$E36 -> 0 | BV36: =AL36*$E36 -> 0 | BW36: =AM36*$E36 -> 0 | BX36: =AN36*$E36 -> 0 | BY36: =AO36*$E36 -> 0 | BZ36: =AP36*$E36 -> 0 | CA36: =AQ36*$E36 -> 0 | CB36: =AR36*$E36 -> 0 | ... DC36: =BS36*$E36 -> 0
K37: 96830.144 | L37: 105726.23 | M37: 115738.37 | N37: 123079.5 | O37: 130003.58 | P37: 125967.29 | Q37: 124602.84 | R37: 127538.08 | S37: 133820.94 | T37: 140472.6 | U37: 151120.81 | V37: 161551.31 | W37: 172173.64 | X37: 182175.14 | Y37: 194280.35 | Z37: 207481.32 | AA37: 241051.25 | AB37: 268715.1 | AC37: 289375.57 | AD37: 290529.82 | AE37: 296888.99 | AF37: 305650.84 | AG37: 314358.56 | AH37: 326246.46 | AI37: 337757.1 | AJ37: 349425.35 | AK37: 360871.62 | AL37: 373090.46 | AM37: 385326.41 | AN37: 397952.91 | AO37: 410679.24 | AP37: 423674.56 | AQ37: 436800.37 | AR37: 450490.18 | AS37: 464747.73 | AT37: 479484.05 | AU37: 494858.28 | AV37: 510831.31 | AW37: 528039.93 | AX37: 546576.25 | AY37: 565339.59 | AZ37: 584446.41 | BA37: 603908.54 | BB37: 623766.99 | BC37: 644113.18 | BD37: =BD33+BD29+BD25+BD24+BD22+BD20+BD16+BD11+BD7 -> 653426.31 | BE37: =BE33+BE29+BE25+BE24+BE22+BE20+BE16+BE11+BE7 -> 662963.52 | BF37: =BF33+BF29+BF25+BF24+BF22+BF20+BF16+BF11+BF7 -> 672735.11 | BG37: =BG33+BG29+BG25+BG24+BG22+BG20+BG16+BG11+BG7 -> 682752.06 | BH37: =BH33+BH29+BH25+BH24+BH22+BH20+BH16+BH11+BH7 -> 693026.04 | BI37: =BI33+BI29+BI25+BI24+BI22+BI20+BI16+BI11+BI7 -> 703569.48 | BJ37: =BJ33+BJ29+BJ25+BJ24+BJ22+BJ20+BJ16+BJ11+BJ7 -> 714395.62 | BK37: =BK33+BK29+BK25+BK24+BK22+BK20+BK16+BK11+BK7 -> 725518.58 | ... BS37: =BS33+BS29+BS25+BS24+BS22+BS20+BS16+BS11+BS7 -> 827218.6 | BT37: =(BS37/BD37)^(1/($BS$6-$BD$6))-1 -> 0.015846865 | BU37: =AK37*$E37 -> 0 | BV37: =AL37*$E37 -> 0 | BW37: =AM37*$E37 -> 0 | BX37: =AN37*$E37 -> 0 | BY37: =AO37*$E37 -> 0 | BZ37: =AP37*$E37 -> 0 | CA37: =AQ37*$E37 -> 0 | CB37: =AR37*$E37 -> 0 | ... DC37: =BS37*$E37 -> 0
D38: =SUM(D7:D36) -> 704423.21 | J38: KILOMETROS RECORRIDOS (MILLONES)
D40: Km | BU40: Cargo-Distance | BV40: =BV6 -> 2017 | BW40: =BW6 -> 2018 | BX40: =BX6 -> 2019 | BY40: =BY6 -> 2020 | BZ40: =BZ6 -> 2021 | CA40: =CA6 -> 2022 | CB40: =CB6 -> 2023 | CC40: =CC6 -> 2024 | ... DC40: =DC6 -> 2050
B41: LDV | C41: Passengers | D41: =D7+D12+D28+D30+D33 -> 198824.55 | BS41: LDV | BT41: Passengers | BU41: =BU7+BU12+BU28+BU30+BU33 -> 279361.98 | BV41: =BV7+BV12+BV28+BV30+BV33 -> 287706.06 | BW41: =BW7+BW12+BW28+BW30+BW33 -> 295942.51 | BX41: =BX7+BX12+BX28+BX30+BX33 -> 304095.44 | BY41: =BY7+BY12+BY28+BY30+BY33 -> 312359.1 | BZ41: =BZ7+BZ12+BZ28+BZ30+BZ33 -> 320960.38 | CA41: =CA7+CA12+CA28+CA30+CA33 -> 329609.92 | CB41: =CB7+CB12+CB28+CB30+CB33 -> 338491.42 | ... DC41: =DC7+DC12+DC28+DC30+DC33 -> 627698.21
B42: HDV | C42: Passengers | D42: =D26+D27 -> 9171.5045 | BS42: HDV | BT42: Passengers | BU42: =BU26+BU27 -> 327116.99 | BV42: =BV26+BV27 -> 321756.4 | BW42: =BW26+BW27 -> 318633.54 | BX42: =BX26+BX27 -> 315395.13 | BY42: =BY26+BY27 -> 311582.45 | BZ42: =BZ26+BZ27 -> 306877.25 | CA42: =CA26+CA27 -> 302391.94 | CB42: =CB26+CB27 -> 302443.62 | ... DC42: =DC26+DC27 -> 419450.13
...

Sheet Oil Prospective
A1: Fuels demand - Oil industry prospective 2017-2031 | AL1: 2017-2030 | AM1: 2030-2050
C2: 2017 | D2: 2018 | E2: 2019 | F2: 2020 | G2: 2021 | H2: 2022 | I2: 2023 | J2: 2024 | K2: 2025 | L2: 2026 | M2: 2027 | N2: 2028 | O2: 2029 | P2: 2030 | Q2: 2031 | R2: =Q2+1 -> 2032 | S2: =R2+1 -> 2033 | T2: =S2+1 -> 2034 | U2: =T2+1 -> 2035 | V2: =U2+1 -> 2036 | W2: =V2+1 -> 2037 | X2: =W2+1 -> 2038 | Y2: =X2+1 -> 2039 | ... AK2: =AJ2+1 -> 2051 | AL2: TMCA | AM2: TMCA
A3: LDVs | C3: 33.9 | D3: 34 | E3: 34.3 | F3: 34.6 | G3: 34.9 | H3: 35.1 | I3: 35.8 | J3: 36 | K3: 36.6 | L3: 36.9 | M3: 37.1 | N3: 37 | O3: 37 | P3: 37 | Q3: 36.8 | R3: {=TREND(M3:Q3,M$2:Q$2,R$2)} -> 36.8 | S3: {=TREND(N3:R3,N$2:R$2,S$2)} -> 36.74 | T3: {=TREND(O3:S3,O$2:S$2,T$2)} -> 36.652 | U3: {=TREND(P3:T3,P$2:T$2,U$2)} -> 36.5716 | V3: {=TREND(Q3:U3,Q$2:U$2,V$2)} -> 36.53128 | W3: {=TREND(R3:V3,R$2:V$2,W$2)} -> 36.447224 | X3: {=TREND(S3:W3,S$2:W$2,X$2)} -> 36.376539 | Y3: {=TREND(T3:X3,T$2:X$2,Y$2)} -> 36.313139 | ... AK3: {=TREND(AF3:AJ3,AF$2:AJ$2,AK$2)} -> 35.488988 | AL3: 0.6 | AM3: =(AJ3/P3)^(1/(AJ$2-P$2))-1 -> -0.0019858872
A4: HDVs | C4: 0.8 | D4: 0.8 | E4: 0.9 | F4: 0.9 | G4: 0.9 | H4: 1 | I4: 1.1 | J4: 1.1 | K4: 1.2 | L4: 1.3 | M4: 1.3 | N4: 1.4 | O4: 1.4 | P4: 1.5 | Q4: 1.6 | R4: {=TREND(M4:Q4,M$2:Q$2,R$2)} -> 1.65 | S4: {=TREND(N4:R4,N$2:R$2,S$2)} -> 1.72 | T4: {=TREND(O4:S4,O$2:S$2,T$2)} -> 1.811 | U4: {=TREND(P4:T4,P$2:T$2,U$2)} -> 1.8788 | V4: {=TREND(Q4:U4,Q$2:U$2,V$2)} -> 1.94754 | W4: {=TREND(R4:V4,R$2:V$2,W$2)} -> 2.027632 | X4: {=TREND(S4:W4,S$2:W$2,X$2)} -> 2.1025356 | Y4: {=TREND(T4:X4,T$2:X$2,Y$2)} -> 2.1730725 | ... AK4: {=TREND(AF4:AJ4,AF$2:AJ$2,AK$2)} -> 3.0663379 | AL4: 4.9 | AM4: =(AJ4/P4)^(1/(AJ$2-P$2))-1 -> 0.035126722
A5: Air | B5: Aéreo | C5: 76.7 | D5: 78.9 | E5: 81 | F5: 83.9 | G5: 86.3 | H5: 88.8 | I5: 91.4 | J5: 94 | K5: 96.7 | L5: 99.5 | M5: 102.5 | N5: 105.5 | O5: 108.6 | P5: 111.9 | Q5: 115.2 | R5: {=TREND(M5:Q5,M$2:Q$2,R$2)} -> 118.28 | S5: {=TREND(N5:R5,N$2:R$2,S$2)} -> 121.544 | T5: {=TREND(O5:S5,O$2:S$2,T$2)} -> 124.7852 | U5: {=TREND(P5:T5,P$2:T$2,U$2)} -> 127.97616 | V5: {=TREND(Q5:U5,Q$2:U$2,V$2)} -> 131.17433 | W5: {=TREND(R5:V5,R$2:V$2,W$2)} -> 134.41818 | X5: {=TREND(S5:W5,S$2:W$2,X$2)} -> 137.62082 | Y5: {=TREND(T5:X5,T$2:X$2,Y$2)} -> 140.82892 | ... AK5: {=TREND(AF5:AJ5,AF$2:AJ$2,AK$2)} -> 179.40588 | AL5: 2.9 | AM5: =(AJ5/P5)^(1/(AJ$2-P$2))-1 -> 0.022957863
A6: rail | B6: Ferroviario | C6: 13.7 | D6: 14.1 | E6: 14.5 | F6: 14.9 | G6: 15.4 | H6: 15.9 | I6: 16.4 | J6: 16.9 | K6: 17.4 | L6: 17.9 | M6: 18.5 | N6: 19 | O6: 19.6 | P6: 20.2 | Q6: 20.8 | R6: {=TREND(M6:Q6,M$2:Q$2,R$2)} -> 21.36 | S6: {=TREND(N6:R6,N$2:R$2,S$2)} -> 21.968 | T6: {=TREND(O6:S6,O$2:S$2,T$2)} -> 22.5544 | U6: {=TREND(P6:T6,P$2:T$2,U$2)} -> 23.13952 | V6: {=TREND(Q6:U6,Q$2:U$2,V$2)} -> 23.726416 | W6: {=TREND(R6:V6,R$2:V$2,W$2)} -> 24.320973 | X6: {=TREND(S6:W6,S$2:W$2,X$2)} -> 24.90525 | Y6: {=TREND(T6:X6,T$2:X$2,Y$2)} -> 25.494258 | ... AK6: {=TREND(AF6:AJ6,AF$2:AJ$2,AK$2)} -> 32.557734 | AL6: 3 | AM6: =(AJ6/P6)^(1/(AJ$2-P$2))-1 -> 0.023219952
A7: Ship | B7: Marítimo | C7: 14.3 | D7: 13.7 | E7: 13.5 | F7: 13.3 | G7: 13.2 | H7: 13.3 | I7: 13.4 | J7: 13.5 | K7: 13.5 | L7: 13.6 | M7: 13.7 | N7: 13.8 | O7: 13.9 | P7: 14 | Q7: 14.1 | R7: {=TREND(M7:Q7,M$2:Q$2,R$2)} -> 14.2 | S7: {=TREND(N7:R7,N$2:R$2,S$2)} -> 14.3 | T7: {=TREND(O7:S7,O$2:S$2,T$2)} -> 14.4 | U7: {=TREND(P7:T7,P$2:T$2,U$2)} -> 14.5 | V7: {=TREND(Q7:U7,Q$2:U$2,V$2)} -> 14.6 | W7: {=TREND(R7:V7,R$2:V$2,W$2)} -> 14.7 | X7: {=TREND(S7:W7,S$2:W$2,X$2)} -> 14.8 | Y7: {=TREND(T7:X7,T$2:X$2,Y$2)} -> 14.9 | ... AK7: {=TREND(AF7:AJ7,AF$2:AJ$2,AK$2)} -> 16.1 | AL7: -0.1 | AM7: =(AJ7/P7)^(1/(AJ$2-P$2))-1 -> 0.0066989076
F12: 2020 | G12: 2021 | H12: 2022 | I12: 2023 | J12: 2024 | K12: 2025 | L12: 2026 | M12: 2027 | N12: 2028 | O12: 2029 | P12: 2030 | Q12: 2031 | R12: 2032 | S12: 2033 | T12: 2034 | U12: 2035 | V12: 2036 | W12: 2037 | X12: 2038 | Y12: 2039 | Z12: 2040 | AA12: 2041 | AB12: 2042 | AC12: 2043 | AD12: 2044 | AE12: 2045 | AF12: 2046 | AG12: 2047 | AH12: 2048 | AI12: 2049 | AJ12: 2050 | AK12: 2051 | AL12: 2052 | AM12: 2053 | AN12: 2054 | AO12: 2055 | AP12: 2056 | AQ12: 2057 | AR12: 2058 | AS12: 2059 | AT12: 2060 | AU12: 2061 | AV12: 2062 | AW12: 2063 | AX12: 2064 | AY12: 2065 | AZ12: 2066 | BA12: 2067 | BB12: 2068 | BC12: 2069 | BD12: 2070
A13: LDV | D13: LDV | F13: =F3/$F3 -> 1 | G13: =G3/$F3 -> 1.0086705 | H13: =H3/$F3 -> 1.0144509 | I13: =I3/$F3 -> 1.0346821 | J13: =J3/$F3 -> 1.0404624 | K13: =K3/$F3 -> 1.0578035 | L13: =L3/$F3 -> 1.066474 | M13: =M3/$F3 -> 1.0722543 | ... AJ13: =AJ3/$F3 -> 1.0276832
A14: HDV | D14: HDV | F14: =F4/$F4 -> 1 | G14: =G4/$F4 -> 1 | H14: =H4/$F4 -> 1.1111111 | I14: =I4/$F4 -> 1.2222222 | J14: =J4/$F4 -> 1.2222222 | K14: =K4/$F4 -> 1.3333333 | L14: =L4/$F4 -> 1.4444444 | M14: =M4/$F4 -> 1.4444444 | ... AJ14: =AJ4/$F4 -> 3.324445
A15: Air | B15: Aéreo | D15: Air | F15: =F5/$F5 -> 1 | G15: =G5/$F5 -> 1.0286055 | H15: =H5/$F5 -> 1.0584029 | I15: =I5/$F5 -> 1.0893921 | J15: =J5/$F5 -> 1.1203814 | K15: =K5/$F5 -> 1.1525626 | L15: =L5/$F5 -> 1.1859356 | M15: =M5/$F5 -> 1.2216925 | ... AJ15: =AJ5/$F5 -> 2.100018
A16: rail | B16: Ferroviario | D16: rail | F16: =F6/$F6 -> 1 | G16: =G6/$F6 -> 1.033557 | H16: =H6/$F6 -> 1.0671141 | I16: =I6/$F6 -> 1.1006711 | J16: =J6/$F6 -> 1.1342282 | K16: =K6/$F6 -> 1.1677852 | L16: =L6/$F6 -> 1.2013423 | M16: =M6/$F6 -> 1.2416107 | ... AJ16: =AJ6/$F6 -> 2.1455819
A17: Ship | B17: Marítimo | D17: Ship | F17: =MAX(1,F7/$F7) -> 1 | G17: =MAX(1,G7/$F7) -> 1 | H17: =MAX(1,H7/$F7) -> 1 | I17: =MAX(1,I7/$F7) -> 1.0075188 | J17: =MAX(1,J7/$F7) -> 1.0150376 | K17: =MAX(1,K7/$F7) -> 1.0150376 | L17: =MAX(1,L7/$F7) -> 1.0225564 | M17: =MAX(1,M7/$F7) -> 1.0300752 | ... AJ17: =MAX(1,AJ7/$F7) -> 1.2030075

Sheet Motorcycles INEGI
B2: Year | C2: Distance/motorbike/year | D2: Growth ratio | H2: Motorcycle growth
B3: 2009 | C3: 1198253 | F3: 2020 | G3: 2021 | H3: 2022 | I3: 2023 | J3: 2024 | K3: 2025 | L3: 2026 | M3: 2027 | N3: 2028 | O3: 2029 | P3: 2030 | Q3: 2031 | R3: 2032 | S3: 2033 | T3: 2034 | U3: 2035 | V3: 2036 | W3: 2037 | X3: 2038 | Y3: 2039 | Z3: 2040 | AA3: 2041 | AB3: 2042 | AC3: 2043 | AD3: 2044 | AE3: 2045 | AF3: 2046 | AG3: 2047 | AH3: 2048 | AI3: 2049 | AJ3: 2050 | AK3: 2051 | AL3: 2052 | AM3: 2053 | AN3: 2054 | AO3: 2055 | AP3: 2056 | AQ3: 2057 | AR3: 2058 | AS3: 2059 | AT3: 2060 | AU3: 2061 | AV3: 2062 | AW3: 2063 | AX3: 2064 | AY3: 2065 | AZ3: 2066 | BA3: 2067 | BB3: 2068 | BC3: 2069 | BD3: 2070
B4: 2010 | C4: 1154145 | F4: {=TRANSPOSE(D14:D44)} -> 1 | G4: 1.0670055 | H4: 1.134011 | I4: 1.2010165 | J4: 1.268022 | K4: 1.3350275 | L4: 1.402033 | M4: 1.4690385 | N4: 1.536044 | O4: 1.6030494 | P4: 1.6700549 | Q4: 1.7370604 | R4: 1.8040659 | S4: 1.8710714 | T4: 1.9380769 | U4: 2.0050824 | V4: 2.0720879 | W4: 2.1390934 | X4: 2.2060989 | Y4: 2.2731044 | Z4: 2.3401099 | AA4: 2.4071154 | AB4: 2.4741209 | AC4: 2.5411264 | AD4: 2.6081319 | AE4: 2.6751374 | AF4: 2.7421428 | AG4: 2.8091483 | AH4: 2.8761538 | AI4: 2.9431593 | AJ4: 3.0101648 | AK4: =AJ4+(AJ4-AE4)/5 -> 3.0771703 | AL4: =AK4+(AK4-AF4)/5 -> 3.1441758 | AM4: =AL4+(AL4-AG4)/5 -> 3.2111813 | AN4: =AM4+(AM4-AH4)/5 -> 3.2781868 | AO4: =AN4+(AN4-AI4)/5 -> 3.3451923 | AP4: =AO4+(AO4-AJ4)/5 -> 3.4121978 | AQ4: =AP4+(AP4-AK4)/5 -> 3.4792033 | AR4: =AQ4+(AQ4-AL4)/5 -> 3.5462088 | ... BD4: =BC4+(BC4-AX4)/5 -> 4.3502747
B5: 2011 | C5: 1313122
B6: 2012 | C6: 1582228
B7: 2013 | C7: 1873641
B8: 2014 | C8: 2271563
B9: 2015 | C9: 2610199
B10: 2016 | C10: 2987057
B11: 2017 | C11: 3260493.1
B12: 2018 | C12: 3533929.2
B13: 2019 | C13: 3807365.4
B14: 2020 | C14: 4080801.5 | D14: =C14/C$14 -> 1
B15: 2021 | C15: 4354237.6 | D15: =C15/C$14 -> 1.0670055
B16: 2022 | C16: 4627673.7 | D16: =C16/C$14 -> 1.134011
B17: 2023 | C17: 4901109.8 | D17: =C17/C$14 -> 1.2010165
B18: 2024 | C18: 5174546 | D18: =C18/C$14 -> 1.268022
B19: 2025 | C19: 5447982.1 | D19: =C19/C$14 -> 1.3350275
B20: 2026 | C20: 5721418.2 | D20: =C20/C$14 -> 1.402033
B21: 2027 | C21: 5994854.3 | D21: =C21/C$14 -> 1.4690385
B22: 2028 | C22: 6268290.4 | D22: =C22/C$14 -> 1.536044
B23: 2029 | C23: 6541726.5 | D23: =C23/C$14 -> 1.6030494
B24: 2030 | C24: 6815162.7 | D24: =C24/C$14 -> 1.6700549
B25: 2031 | C25: 7088598.8 | D25: =C25/C$14 -> 1.7370604
... B44: 2050 | C44: 12283885 | D44: =C44/C$14 -> 3.0101648

Sheet BCDTRtSY-psgr
A1: Cargo Dist Transported Relative to Start Year (dimensionless) | B1: 2020 | C1: 2021 | D1: 2022 | E1: 2023 | F1: 2024 | G1: 2025 | H1: 2026 | I1: 2027 | J1: 2028 | K1: 2029 | L1: 2030 | M1: 2031 | N1: 2032 | O1: 2033 | P1: 2034 | Q1: 2035 | R1: 2036 | S1: 2037 | T1: 2038 | U1: 2039 | V1: 2040 | W1: 2041 | X1: 2042 | Y1: 2043 | Z1: 2044 | AA1: 2045 | AB1: 2046 | AC1: 2047 | AD1: 2048 | AE1: 2049 | AF1: 2050 | AG1: 2051 | AH1: 2052 | AI1: 2053 | AJ1: 2054 | AK1: 2055 | AL1: 2056 | AM1: 2057 | AN1: 2058 | AO1: 2059 | AP1: 2060 | AQ1: 2061 | AR1: 2062 | AS1: 2063 | AT1: 2064 | AU1: 2065 | AV1: 2066 | AW1: 2067 | AX1: 2068 | AY1: 2069 | AZ1: 2070
