Workbook
Name Aircraftshare: About!#REF!
Name DaysPerWeek: About!$B$70
Name FallWeekdays: 'Category Mapping'!$E$45
Name FallWeekendDays: 'Category Mapping'!$D$45
Name HDVshare: About!#REF!
Name Hour: 'Source Data'!$F$2:$AC$2
Name LDVshare: About!#REF!
Name Load: 'Source Data'!$F$3:$AC$290
Name LoadFactorHours: 'Summarized Source Data'!$C$600:$C$743
Name LoadFactorSeasons: 'Summarized Source Data'!$A$600:$A$743
Name Motorbikesshare: About!#REF!
Name Railshare: About!#REF!
Name Season: 'Source Data'!$AD$3:$AD$290
Name Sector: 'Source Data'!$AF$3:$AF$290
Name Shipshare: About!#REF!
Name SpringWeekdays: 'Category Mapping'!$E$43
Name SpringWeekendDays: 'Category Mapping'!$D$43
Name Subsector: 'Source Data'!$AG$3:$AG$290
Name SummerWeekdays: 'Category Mapping'!$E$44
Name SummerWeekendDays: 'Category Mapping'!$D$44
Name TimeOfWeek: 'Source Data'!$AE$3:$AE$290
Name Weekdays: About!$B$69
Name WeekendDays: About!$B$68
Name WinterWeekdays: 'Category Mapping'!$E$42
Name WinterWeekendDays: 'Category Mapping'!$D$42

Sheet About
A1: SHELF Seasonal Hourly Equipment Load Factors
A3: Source: | B3: Hourly Load Data | H3: Meixco SHELF Seasonal Hourly Equipment Load Factors
B4: NREL
B5: 2018 | H5: Source: | I5: National Energy Control Center (Cenace)
B6: Electrification Futures Study Load Profiles | I6: Accessed 2024
B7: https://data.nrel.gov/submissions/126 | I7: Public area of ​​the market information system
B8: EFSLoadProfile_Medium_Moderate | I8: https://www.cenace.gob.mx/Paginas/SIM/PronosticosHorasCriticas.aspx
I9: Horas criticas de 2022
B10: Monthly natural gas and electricity consumption
B11: EIA | I11: National Energy Control Center (Cenace)
B12: 2023 | I12: Accessed 2024
B13: Monthly Energy Review | I13: Public area of ​​the market information system
B14: https://www.eia.gov/totalenergy/data/monthly/ | I14: https://www.cenace.gob.mx/APSIM.aspx
B15: Tables and 4.3 and 7.6 | I15: Obtained through the Energy Transition Observatory in Mexico (Obtrenmx.org)
I16: https://obtrenmx.org/
B17: Hourly Load Data
B18: Zapata, Victhalia (2022)
B19: “Data for: Future global electricity demand load curves”
B20: https://data.mendeley.com/datasets/pmd2dchk44/1
A23: About
A24: This file specifies the ratio of the electricity consumed in each hour of the year to the
A25: total amount of electricity consumed during the year, disaggregated by sector.
A27: For the US, we use data from NREL's Electrification Futures Study. We choose to use
A28: the Medium Electrification scenario with Moderate technology advancement, which
A29: is more in line with deployment of technologies like electric vehicles in the EPS
A30: BAU case when compared to NREL's Reference scenario. We choose data from the
A31: year 2018 to ensure we're using historical data.
A32: Due to file size limitations, the raw NREL data is already consolidated using Excel's
A33: Power Query feature.
A35: If you are adapting the EPS to a new geography and don't have hourly load data broken out
A36: by sector, you can use total economywide data in all of the blue output tabs.
... A64: by certain sectors, you can use total economy-wide or sector-wide data.
B67: Number of days per week
A68: Weekend | B68: 2
A69: Weekday | B69: 5
A70: Total | B70: =SUM(B68:B69) -> 7
A72: heating | B72: cooling
A73: 0.19 | B73: 0.81
A74: 0.19 | B74: 0.81

Sheet Sheet1
A1: Source.Name | B1: (Multiple Items)
A3: Row Labels | B3: Sum of h9
A4: 1 | B4: 3644419482
A5: 2 | B5: 3344886095
A6: 3 | B6: 2802555286
A7: 4 | B7: 2341700000
A8: 5 | B8: 3131751653
A9: 6 | B9: 4128820248
A10: 7 | B10: 5206847849
A11: 8 | B11: 5034742693
A12: 9 | B12: 3488297097
A13: 10 | B13: 2458800000
A14: 11 | B14: 2822700000
A15: 12 | B15: 3439303342
A16: Grand Total | B16: 41844823745

Sheet Source Data
A1: Source Data | AD1: Category Mapping
A2: Source.Name | B2: Year | C2: Region | D2: Regions_code.Region Name | E2: Month | F2: h1 | G2: h2 | H2: h3 | I2: h4 | J2: h5 | K2: h6 | L2: h7 | M2: h8 | N2: h9 | O2: h10 | P2: h11 | Q2: h12 | R2: h13 | S2: h14 | T2: h15 | U2: h16 | V2: h17 | W2: h18 | X2: h19 | Y2: h20 | Z2: h21 | AA2: h22 | AB2: h23 | AC2: h24 | AD2: season | AE2: time of week | AF2: sector | AG2: subsector
A3: Residential_cooling_weekday.csv | B3: 2019 | C3: 3 | D3: Mexico | E3: 1 | F3: 297235 | G3: 215977 | H3: 192095 | I3: 216924 | J3: 292622 | K3: 411259 | L3: 521714 | M3: 640741 | N3: 817725 | O3: 1081544 | P3: 1544113 | Q3: 2373507 | R3: 3274609 | S3: 3857826 | T3: 4201111 | U3: 4399980 | V3: 4206632 | W3: 3627806 | X3: 2930211 | Y3: 2234029 | Z3: 1580521 | AA3: 1064353 | AB3: 677984 | AC3: 448604 | AD3: =IF(AND(E3>=3,E3<=5),"Spring",IF(AND(E3>=6,E3<=8),"Summer",IF(AND(E3>=9,E3<=10),"Fall","Winter"))) -> Winter | AE3: =INDEX('Category Mapping'!$B$2:$B$25,MATCH('Source Data'!A3,'Category Mapping'!$A$2:$A$25,0)) -> Weekday | AF3: =INDEX('Category Mapping'!$C$2:$C$25,MATCH('Source Data'!A3,'Category Mapping'!$A$2:$A$25,0)) -> Residential | AG3: =INDEX('Category Mapping'!$D$2:$D$25,MATCH('Source Data'!A3,'Category Mapping'!$A$2:$A$25,0)) -> Cooling
A4: Residential_cooling_weekday.csv | B4: 2019 | C4: 3 | D4: Mexico | E4: 2 | F4: 445010 | G4: 346547 | H4: 317629 | I4: 348067 | J4: 438103 | K4: 584946 | L4: 733644 | M4: 841912 | N4: 1058560 | O4: 1395286 | P4: 1996647 | Q4: 2978823 | R4: 3873366 | S4: 4412848 | T4: 4756987 | U4: 5033001 | V4: 4975810 | W4: 4553007 | X4: 3788969 | Y4: 2882090 | Z4: 2046015 | AA4: 1398524 | AB4: 953393 | AC4: 638063 | AD4: =IF(AND(E4>=3,E4<=5),"Spring",IF(AND(E4>=6,E4<=8),"Summer",IF(AND(E4>=9,E4<=10),"Fall","Winter"))) -> Winter | AE4: =INDEX('Category Mapping'!$B$2:$B$25,MATCH('Source Data'!A4,'Category Mapping'!$A$2:$A$25,0)) -> Weekday | AF4: =INDEX('Category Mapping'!$C$2:$C$25,MATCH('Source Data'!A4,'Category Mapping'!$A$2:$A$25,0)) -> Residential | AG4: =INDEX('Category Mapping'!$D$2:$D$25,MATCH('Source Data'!A4,'Category Mapping'!$A$2:$A$25,0)) -> Cooling
A5: Residential_cooling_weekday.csv | B5: 2019 | C5: 3 | D5: Mexico | E5: 3 | F5: 973628 | G5: 774974 | H5: 720664 | I5: 778374 | J5: 958517 | K5: 1220127 | L5: 1429568 | M5: 1659914 | N5: 2088819 | O5: 2686019 | P5: 3704179 | Q5: 5219125 | R5: 6565219 | S5: 7357147 | T5: 7890942 | U5: 8391072 | V5: 8433820 | W5: 7977214 | X5: 7029294 | Y5: 5548218 | Z5: 4037329 | AA5: 2757331 | AB5: 1857769 | AC5: 1330923 | AD5: =IF(AND(E5>=3,E5<=5),"Spring",IF(AND(E5>=6,E5<=8),"Summer",IF(AND(E5>=9,E5<=10),"Fall","Winter"))) -> Spring | AE5: =INDEX('Category Mapping'!$B$2:$B$25,MATCH('Source Data'!A5,'Category Mapping'!$A$2:$A$25,0)) -> Weekday | AF5: =INDEX('Category Mapping'!$C$2:$C$25,MATCH('Source Data'!A5,'Category Mapping'!$A$2:$A$25,0)) -> Residential | AG5: =INDEX('Category Mapping'!$D$2:$D$25,MATCH('Source Data'!A5,'Category Mapping'!$A$2:$A$25,0)) -> Cooling
A6: Residential_cooling_weekday.csv | B6: 2019 | C6: 3 | D6: Mexico | E6: 4 | F6: 2127434 | G6: 1731629 | H6: 1624547 | I6: 1739224 | J6: 2094415 | K6: 2568006 | L6: 2981361 | M6: 3324563 | N6: 3935264 | O6: 4846495 | P6: 6380863 | Q6: 8675352 | R6: 10700000 | S6: 11900000 | T6: 12700000 | U6: 13500000 | V6: 13700000 | W6: 13300000 | X6: 12100000 | Y6: 10000000 | Z6: 7606189 | AA6: 5522527 | AB6: 3874374 | AC6: 2801197 | AD6: =IF(AND(E6>=3,E6<=5),"Spring",IF(AND(E6>=6,E6<=8),"Summer",IF(AND(E6>=9,E6<=10),"Fall","Winter"))) -> Spring | AE6: =INDEX('Category Mapping'!$B$2:$B$25,MATCH('Source Data'!A6,'Category Mapping'!$A$2:$A$25,0)) -> Weekday | AF6: =INDEX('Category Mapping'!$C$2:$C$25,MATCH('Source Data'!A6,'Category Mapping'!$A$2:$A$25,0)) -> Residential | AG6: =INDEX('Category Mapping'!$D$2:$D$25,MATCH('Source Data'!A6,'Category Mapping'!$A$2:$A$25,0)) -> Cooling
A7: Residential_cooling_weekday.csv | B7: 2019 | C7: 3 | D7: Mexico | E7: 5 | F7: 3539755 | G7: 3061268 | H7: 2925658 | I7: 3074695 | J7: 3484815 | K7: 4077843 | L7: 4534234 | M7: 4695486 | N7: 5151005 | O7: 5856330 | P7: 7239026 | Q7: 9491340 | R7: 11500000 | S7: 12600000 | T7: 13400000 | U7: 14300000 | V7: 14700000 | W7: 14500000 | X7: 13700000 | Y7: 12100000 | Z7: 9956007 | AA7: 7799806 | AB7: 5892380 | AC7: 4448138 | AD7: =IF(AND(E7>=3,E7<=5),"Spring",IF(AND(E7>=6,E7<=8),"Summer",IF(AND(E7>=9,E7<=10),"Fall","Winter"))) -> Spring | AE7: =INDEX('Category Mapping'!$B$2:$B$25,MATCH('Source Data'!A7,'Category Mapping'!$A$2:$A$25,0)) -> Weekday | AF7: =INDEX('Category Mapping'!$C$2:$C$25,MATCH('Source Data'!A7,'Category Mapping'!$A$2:$A$25,0)) -> Residential | AG7: =INDEX('Category Mapping'!$D$2:$D$25,MATCH('Source Data'!A7,'Category Mapping'!$A$2:$A$25,0)) -> Cooling
A8: Residential_cooling_weekday.csv | B8: 2019 | C8: 3 | D8: Mexico | E8: 6 | F8: 4392643 | G8: 3868408 | H8: 3701412 | I8: 3885375 | J8: 4324465 | K8: 4849092 | L8: 5068487 | M8: 4962979 | N8: 5190879 | O8: 5670306 | P8: 6822479 | Q8: 8802688 | R8: 10500000 | S8: 11500000 | T8: 12200000 | U8: 13100000 | V8: 13500000 | W8: 13500000 | X8: 12900000 | Y8: 11700000 | Z8: 10000000 | AA8: 8244146 | AB8: 6586658 | AC8: 5289422 | AD8: =IF(AND(E8>=3,E8<=5),"Spring",IF(AND(E8>=6,E8<=8),"Summer",IF(AND(E8>=9,E8<=10),"Fall","Winter"))) -> Summer | AE8: =INDEX('Category Mapping'!$B$2:$B$25,MATCH('Source Data'!A8,'Category Mapping'!$A$2:$A$25,0)) -> Weekday | AF8: =INDEX('Category Mapping'!$C$2:$C$25,MATCH('Source Data'!A8,'Category Mapping'!$A$2:$A$25,0)) -> Residential | AG8: =INDEX('Category Mapping'!$D$2:$D$25,MATCH('Source Data'!A8,'Category Mapping'!$A$2:$A$25,0)) -> Cooling
A9: Residential_cooling_weekday.csv | B9: 2019 | C9: 3 | D9: Mexico | E9: 7 | F9: 4774775 | G9: 4276473 | H9: 4116400 | I9: 4295230 | J9: 4700666 | K9: 5161769 | L9: 5294096 | M9: 5054550 | N9: 5155255 | O9: 5523447 | P9: 6609618 | Q9: 8519837 | R9: 10200000 | S9: 11100000 | T9: 11800000 | U9: 12700000 | V9: 13100000 | W9: 13000000 | X9: 12500000 | Y9: 11400000 | Z9: 9964223 | AA9: 8396257 | AB9: 6879846 | AC9: 5630492 | AD9: =IF(AND(E9>=3,E9<=5),"Spring",IF(AND(E9>=6,E9<=8),"Summer",IF(AND(E9>=9,E9<=10),"Fall","Winter"))) -> Summer | AE9: =INDEX('Category Mapping'!$B$2:$B$25,MATCH('Source Data'!A9,'Category Mapping'!$A$2:$A$25,0)) -> Weekday | AF9: =INDEX('Category Mapping'!$C$2:$C$25,MATCH('Source Data'!A9,'Category Mapping'!$A$2:$A$25,0)) -> Residential | AG9: =INDEX('Category Mapping'!$D$2:$D$25,MATCH('Source Data'!A9,'Category Mapping'!$A$2:$A$25,0)) -> Cooling
A10: Residential_cooling_weekday.csv | B10: 2019 | C10: 3 | D10: Mexico | E10: 8 | F10: 4413787 | G10: 3934235 | H10: 3782551 | I10: 3951491 | J10: 4345281 | K10: 4821944 | L10: 4995566 | M10: 4857231 | N10: 5047920 | O10: 5490485 | P10: 6649056 | Q10: 8632058 | R10: 10400000 | S10: 11300000 | T10: 12100000 | U10: 12900000 | V10: 13300000 | W10: 13200000 | X10: 12600000 | Y10: 11300000 | Z10: 9756763 | AA10: 8068485 | AB10: 6491894 | AC10: 5259808 | AD10: =IF(AND(E10>=3,E10<=5),"Spring",IF(AND(E10>=6,E10<=8),"Summer",IF(AND(E10>=9,E10<=10),"Fall","Winter"))) -> Summer | AE10: =INDEX('Category Mapping'!$B$2:$B$25,MATCH('Source Data'!A10,'Category Mapping'!$A$2:$A$25,0)) -> Weekday | AF10: =INDEX('Category Mapping'!$C$2:$C$25,MATCH('Source Data'!A10,'Category Mapping'!$A$2:$A$25,0)) -> Residential | AG10: =INDEX('Category Mapping'!$D$2:$D$25,MATCH('Source Data'!A10,'Category Mapping'!$A$2:$A$25,0)) -> Cooling
A11: Residential_cooling_weekday.csv | B11: 2019 | C11: 3 | D11: Mexico | E11: 9 | F11: 3581765 | G11: 3195126 | H11: 3071571 | I11: 3209140 | J11: 3526173 | K11: 3923516 | L11: 4056470 | M11: 3948261 | N11: 4119243 | O11: 4527900 | P11: 5529613 | Q11: 7234027 | R11: 8727007 | S11: 9568934 | T11: 10200000 | U11: 10900000 | V11: 11200000 | W11: 11100000 | X11: 10500000 | Y11: 9352791 | Z11: 7961789 | AA11: 6558570 | AB11: 5271510 | AC11: 4279797 | AD11: =IF(AND(E11>=3,E11<=5),"Spring",IF(AND(E11>=6,E11<=8),"Summer",IF(AND(E11>=9,E11<=10),"Fall","Winter"))) -> Fall | AE11: =INDEX('Category Mapping'!$B$2:$B$25,MATCH('Source Data'!A11,'Category Mapping'!$A$2:$A$25,0)) -> Weekday | AF11: =INDEX('Category Mapping'!$C$2:$C$25,MATCH('Source Data'!A11,'Category Mapping'!$A$2:$A$25,0)) -> Residential | AG11: =INDEX('Category Mapping'!$D$2:$D$25,MATCH('Source Data'!A11,'Category Mapping'!$A$2:$A$25,0)) -> Cooling
A12: Residential_cooling_weekday.csv | B12: 2019 | C12: 3 | D12: Mexico | E12: 10 | F12: 2140364 | G12: 1825491 | H12: 1733188 | I12: 1833498 | J12: 2107143 | K12: 2445803 | L12: 2636924 | M12: 2681117 | N12: 2936138 | O12: 3377885 | P12: 4330062 | Q12: 5881621 | R12: 7250151 | S12: 8039681 | T12: 8594724 | U12: 9169525 | V12: 9313698 | W12: 8989812 | X12: 8217012 | Y12: 6977331 | Z12: 5675049 | AA12: 4453681 | AB12: 3426765 | AC12: 2667898 | AD12: =IF(AND(E12>=3,E12<=5),"Spring",IF(AND(E12>=6,E12<=8),"Summer",IF(AND(E12>=9,E12<=10),"Fall","Winter"))) -> Fall | AE12: =INDEX('Category Mapping'!$B$2:$B$25,MATCH('Source Data'!A12,'Category Mapping'!$A$2:$A$25,0)) -> Weekday | AF12: =INDEX('Category Mapping'!$C$2:$C$25,MATCH('Source Data'!A12,'Category Mapping'!$A$2:$A$25,0)) -> Residential | AG12: =INDEX('Category Mapping'!$D$2:$D$25,MATCH('Source Data'!A12,'Category Mapping'!$A$2:$A$25,0)) -> Cooling
A13: Residential_cooling_weekday.csv | B13: 2019 | C13: 3 | D13: Mexico | E13: 11 | F13: 839224 | G13: 700923 | H13: 658545 | I13: 703997 | J13: 826199 | K13: 1008084 | L13: 1171396 | M13: 1275839 | N13: 1493450 | O13: 1857810 | P13: 2545438 | Q13: 3777382 | R13: 4912516 | S13: 5594227 | T13: 6028992 | U13: 6380403 | V13: 6310723 | W13: 5773570 | X13: 4830390 | Y13: 3837476 | Z13: 2886582 | AA13: 2119332 | AB13: 1522267 | AC13: 1099625 | AD13: =IF(AND(E13>=3,E13<=5),"Spring",IF(AND(E13>=6,E13<=8),"Summer",IF(AND(E13>=9,E13<=10),"Fall","Winter"))) -> Winter | AE13: =INDEX('Category Mapping'!$B$2:$B$25,MATCH('Source Data'!A13,'Category Mapping'!$A$2:$A$25,0)) -> Weekday | AF13: =INDEX('Category Mapping'!$C$2:$C$25,MATCH('Source Data'!A13,'Category Mapping'!$A$2:$A$25,0)) -> Residential | AG13: =INDEX('Category Mapping'!$D$2:$D$25,MATCH('Source Data'!A13,'Category Mapping'!$A$2:$A$25,0)) -> Cooling
A14: Residential_cooling_weekday.csv | B14: 2019 | C14: 3 | D14: Mexico | E14: 12 | F14: 456666 | G14: 358304 | H14: 328026 | I14: 359876 | J14: 449578 | K14: 574277 | L14: 687779 | M14: 791918 | N14: 966917 | O14: 1239267 | P14: 1741929 | Q14: 2683936 | R14: 3660106 | S14: 4269033 | T14: 4635586 | U14: 4868975 | V14: 4701851 | W14: 4102284 | X14: 3305600 | Y14: 2559820 | Z14: 1868884 | AA14: 1315477 | AB14: 893791 | AC14: 626425 | AD14: =IF(AND(E14>=3,E14<=5),"Spring",IF(AND(E14>=6,E14<=8),"Summer",IF(AND(E14>=9,E14<=10),"Fall","Winter"))) -> Winter | AE14: =INDEX('Category Mapping'!$B$2:$B$25,MATCH('Source Data'!A14,'Category Mapping'!$A$2:$A$25,0)) -> Weekday | AF14: =INDEX('Category Mapping'!$C$2:$C$25,MATCH('Source Data'!A14,'Category Mapping'!$A$2:$A$25,0)) -> Residential | AG14: =INDEX('Category Mapping'!$D$2:$D$25,MATCH('Source Data'!A14,'Category Mapping'!$A$2:$A$25,0)) -> Cooling
... A290: Transport_total_weekend.csv | B290: 2019 | C290: 3 | D290: Mexico | E290: 12 | F290: 939000 | G290: 933000 | H290: 931000 | I290: 931000 | J290: 930000 | K290: 931000 | L290: 1140000 | M290: 1470000 | N290: 1690000 | O290: 1840000 | P290: 1910000 | Q290: 1920000 | R290: 1850000 | S290: 1720000 | T290: 1720000 | U290: 1710000 | V290: 2040000 | W290: 2040000 | X290: 2040000 | Y290: 2030000 | Z290: 2020000 | AA290: 2010000 | AB290: 2010000 | AC290: 1350000 | AD290: =IF(AND(E290>=3,E290<=5),"Spring",IF(AND(E290>=6,E290<=8),"Summer",IF(AND(E290>=9,E290<=10),"Fall","Winter"))) -> Winter | AE290: =INDEX('Category Mapping'!$B$2:$B$25,MATCH('Source Data'!A290,'Category Mapping'!$A$2:$A$25,0)) -> Weekend | AF290: =INDEX('Category Mapping'!$C$2:$C$25,MATCH('Source Data'!A290,'Category Mapping'!$A$2:$A$25,0)) -> Transportation | AG290: =INDEX('Category Mapping'!$D$2:$D$25,MATCH('Source Data'!A290,'Category Mapping'!$A$2:$A$25,0)) -> Transportation

Sheet Summarized Source Data
A1: Total Season Demand Per Specified Hour, Time of Week, and End Use (kW/month)
E2: Residential | F2: Residential | G2: Residential | H2: Residential | I2: Residential | J2: Residential | K2: Commercial | L2: Commercial | M2: Commercial | N2: Commercial | O2: Commercial | P2: Commercial | Q2: Transportation | R2: Transportation | S2: Transportation | T2: Transportation | U2: Transportation | V2: Transportation | W2: Industry | X2: Industry | Y2: Industry
A3: Season | B3: Hour | D3: Time of Week | E3: Heating | F3: Cooling | G3: Envelope | H3: Lighting | I3: Appliances | J3: Other | K3: Heating | L3: Cooling | M3: Envelope | N3: Lighting | O3: Appliances | P3: Other | Q3: LDVs | R3: HDVs | S3: Aircraft | T3: Rail | U3: Ships | V3: Motorbikes | W3: Industry | X3: District Heat and Hydrogen | Y3: Geoengineering
A4: Winter | B4: h1 | C4: Hour0 | D4: Weekday | E4: =SUMIFS(INDEX(Load,,MATCH('Summarized Source Data'!$B4,Hour,0)),Season,'Summarized Source Data'!$A4,Sector,'Summarized Source Data'!E$2,Subsector,'Summarized Source Data'!E$3,TimeOfWeek,$D4) -> 0 | F4: =SUMIFS(INDEX(Load,,MATCH('Summarized Source Data'!$B4,Hour,0)),Season,'Summarized Source Data'!$A4,Sector,'Summarized Source Data'!F$2,Subsector,'Summarized Source Data'!F$3,TimeOfWeek,$D4) -> 2038135 | G4: =SUMIFS(INDEX(Load,,MATCH('Summarized Source Data'!$B4,Hour,0)),Season,'Summarized Source Data'!$A4,Sector,'Summarized Source Data'!G$2,Subsector,'Summarized Source Data'!G$3,TimeOfWeek,$D4) -> 0 | H4: =SUMIFS(INDEX(Load,,MATCH('Summarized Source Data'!$B4,Hour,0)),Season,'Summarized Source Data'!$A4,Sector,'Summarized Source Data'!H$2,Subsector,'Summarized Source Data'!H$3,TimeOfWeek,$D4) -> 72100000 | I4: =H4 -> 72100000 | J4: =H4 -> 72100000 | K4: =SUMIFS(INDEX(Load,,MATCH('Summarized Source Data'!$B4,Hour,0)),Season,'Summarized Source Data'!$A4,Sector,'Summarized Source Data'!K$2,Subsector,'Summarized Source Data'!K$3,TimeOfWeek,$D4) -> 15281527 | L4: =SUMIFS(INDEX(Load,,MATCH('Summarized Source Data'!$B4,Hour,0)),Season,'Summarized Source Data'!$A4,Sector,'Summarized Source Data'!L$2,Subsector,'Summarized Source Data'!L$3,TimeOfWeek,$D4) -> 14985535 | M4: =SUMIFS(INDEX(Load,,MATCH('Summarized Source Data'!$B4,Hour,0)),Season,'Summarized Source Data'!$A4,Sector,'Summarized Source Data'!M$2,Subsector,'Summarized Source Data'!M$3,TimeOfWeek,$D4) -> 0 | N4: =H4 -> 72100000 | O4: =N4 -> 72100000 | P4: =N4 -> 72100000 | Q4: =SUMIFS(INDEX(Load,,MATCH('Summarized Source Data'!$B4,Hour,0)),Season,'Summarized Source Data'!$A4,Sector,'Summarized Source Data'!Q$2,TimeOfWeek,$D4) -> 7120000 | R4: =SUMIFS(INDEX(Load,,MATCH('Summarized Source Data'!$B4,Hour,0)),Season,'Summarized Source Data'!$A4,Sector,'Summarized Source Data'!R$2,TimeOfWeek,$D4) -> 7120000 | S4: =SUMIFS(INDEX(Load,,MATCH('Summarized Source Data'!$B4,Hour,0)),Season,'Summarized Source Data'!$A4,Sector,'Summarized Source Data'!S$2,TimeOfWeek,$D4) -> 7120000 | T4: =SUMIFS(INDEX(Load,,MATCH('Summarized Source Data'!$B4,Hour,0)),Season,'Summarized Source Data'!$A4,Sector,'Summarized Source Data'!T$2,TimeOfWeek,$D4) -> 7120000 | U4: =SUMIFS(INDEX(Load,,MATCH('Summarized Source Data'!$B4,Hour,0)),Season,'Summarized Source Data'!$A4,Sector,'Summarized Source Data'!U$2,TimeOfWeek,$D4) -> 7120000 | V4: =SUMIFS(INDEX(Load,,MATCH('Summarized Source Data'!$B4,Hour,0)),Season,'Summarized Source Data'!$A4,Sector,'Summarized Source Data'!V$2,TimeOfWeek,$D4) -> 7120000 | W4: =SUMIFS(INDEX(Load,,MATCH('Summarized Source Data'!$B4,Hour,0)),Season,'Summarized Source Data'!$A4,Sector,'Summarized Source Data'!W$2,Subsector,'Summarized Source Data'!W$3,TimeOfWeek,$D4) -> 1305000000 | X4: =$W4 -> 1305000000 | Y4: =$W4 -> 1305000000
A5: Winter | B5: h2 | C5: Hour1 | D5: Weekday | E5: =SUMIFS(INDEX(Load,,MATCH('Summarized Source Data'!$B5,Hour,0)),Season,'Summarized Source Data'!$A5,Sector,'Summarized Source Data'!E$2,Subsector,'Summarized Source Data'!E$3,TimeOfWeek,$D5) -> 0 | F5: =SUMIFS(INDEX(Load,,MATCH('Summarized Source Data'!$B5,Hour,0)),Season,'Summarized Source Data'!$A5,Sector,'Summarized Source Data'!F$2,Subsector,'Summarized Source Data'!F$3,TimeOfWeek,$D5) -> 1621751 | G5: =SUMIFS(INDEX(Load,,MATCH('Summarized Source Data'!$B5,Hour,0)),Season,'Summarized Source Data'!$A5,Sector,'Summarized Source Data'!G$2,Subsector,'Summarized Source Data'!G$3,TimeOfWeek,$D5) -> 0 | H5: =SUMIFS(INDEX(Load,,MATCH('Summarized Source Data'!$B5,Hour,0)),Season,'Summarized Source Data'!$A5,Sector,'Summarized Source Data'!H$2,Subsector,'Summarized Source Data'!H$3,TimeOfWeek,$D5) -> 66500000 | I5: =H5 -> 66500000 | J5: =H5 -> 66500000 | K5: =SUMIFS(INDEX(Load,,MATCH('Summarized Source Data'!$B5,Hour,0)),Season,'Summarized Source Data'!$A5,Sector,'Summarized Source Data'!K$2,Subsector,'Summarized Source Data'!K$3,TimeOfWeek,$D5) -> 13958713 | L5: =SUMIFS(INDEX(Load,,MATCH('Summarized Source Data'!$B5,Hour,0)),Season,'Summarized Source Data'!$A5,Sector,'Summarized Source Data'!L$2,Subsector,'Summarized Source Data'!L$3,TimeOfWeek,$D5) -> 14015817 | M5: =SUMIFS(INDEX(Load,,MATCH('Summarized Source Data'!$B5,Hour,0)),Season,'Summarized Source Data'!$A5,Sector,'Summarized Source Data'!M$2,Subsector,'Summarized Source Data'!M$3,TimeOfWeek,$D5) -> 0 | N5: =H5 -> 66500000 | O5: =N5 -> 66500000 | P5: =N5 -> 66500000 | Q5: =SUMIFS(INDEX(Load,,MATCH('Summarized Source Data'!$B5,Hour,0)),Season,'Summarized Source Data'!$A5,Sector,'Summarized Source Data'!Q$2,TimeOfWeek,$D5) -> 7100000 | R5: =SUMIFS(INDEX(Load,,MATCH('Summarized Source Data'!$B5,Hour,0)),Season,'Summarized Source Data'!$A5,Sector,'Summarized Source Data'!R$2,TimeOfWeek,$D5) -> 7100000 | S5: =SUMIFS(INDEX(Load,,MATCH('Summarized Source Data'!$B5,Hour,0)),Season,'Summarized Source Data'!$A5,Sector,'Summarized Source Data'!S$2,TimeOfWeek,$D5) -> 7100000 | T5: =SUMIFS(INDEX(Load,,MATCH('Summarized Source Data'!$B5,Hour,0)),Season,'Summarized Source Data'!$A5,Sector,'Summarized Source Data'!T$2,TimeOfWeek,$D5) -> 7100000 | U5: =SUMIFS(INDEX(Load,,MATCH('Summarized Source Data'!$B5,Hour,0)),Season,'Summarized Source Data'!$A5,Sector,'Summarized Source Data'!U$2,TimeOfWeek,$D5) -> 7100000 | V5: =SUMIFS(INDEX(Load,,MATCH('Summarized Source Data'!$B5,Hour,0)),Season,'Summarized Source Data'!$A5,Sector,'Summarized Source Data'!V$2,TimeOfWeek,$D5) -> 7100000 | W5: =SUMIFS(INDEX(Load,,MATCH('Summarized Source Data'!$B5,Hour,0)),Season,'Summarized Source Data'!$A5,Sector,'Summarized Source Data'!W$2,Subsector,'Summarized Source Data'!W$3,TimeOfWeek,$D5) -> 1303000000 | X5: =$W5 -> 1303000000 | Y5: =$W5 -> 1303000000
A6: Winter | B6: h3 | C6: Hour2 | D6: Weekday | E6: =SUMIFS(INDEX(Load,,MATCH('Summarized Source Data'!$B6,Hour,0)),Season,'Summarized Source Data'!$A6,Sector,'Summarized Source Data'!E$2,Subsector,'Summarized Source Data'!E$3,TimeOfWeek,$D6) -> 0 | F6: =SUMIFS(INDEX(Load,,MATCH('Summarized Source Data'!$B6,Hour,0)),Season,'Summarized Source Data'!$A6,Sector,'Summarized Source Data'!F$2,Subsector,'Summarized Source Data'!F$3,TimeOfWeek,$D6) -> 1496295 | G6: =SUMIFS(INDEX(Load,,MATCH('Summarized Source Data'!$B6,Hour,0)),Season,'Summarized Source Data'!$A6,Sector,'Summarized Source Data'!G$2,Subsector,'Summarized Source Data'!G$3,TimeOfWeek,$D6) -> 0 | H6: =SUMIFS(INDEX(Load,,MATCH('Summarized Source Data'!$B6,Hour,0)),Season,'Summarized Source Data'!$A6,Sector,'Summarized Source Data'!H$2,Subsector,'Summarized Source Data'!H$3,TimeOfWeek,$D6) -> 65800000 | I6: =H6 -> 65800000 | J6: =H6 -> 65800000 | K6: =SUMIFS(INDEX(Load,,MATCH('Summarized Source Data'!$B6,Hour,0)),Season,'Summarized Source Data'!$A6,Sector,'Summarized Source Data'!K$2,Subsector,'Summarized Source Data'!K$3,TimeOfWeek,$D6) -> 12516633 | L6: =SUMIFS(INDEX(Load,,MATCH('Summarized Source Data'!$B6,Hour,0)),Season,'Summarized Source Data'!$A6,Sector,'Summarized Source Data'!L$2,Subsector,'Summarized Source Data'!L$3,TimeOfWeek,$D6) -> 13628712 | M6: =SUMIFS(INDEX(Load,,MATCH('Summarized Source Data'!$B6,Hour,0)),Season,'Summarized Source Data'!$A6,Sector,'Summarized Source Data'!M$2,Subsector,'Summarized Source Data'!M$3,TimeOfWeek,$D6) -> 0 | N6: =H6 -> 65800000 | O6: =N6 -> 65800000 | P6: =N6 -> 65800000 | Q6: =SUMIFS(INDEX(Load,,MATCH('Summarized Source Data'!$B6,Hour,0)),Season,'Summarized Source Data'!$A6,Sector,'Summarized Source Data'!Q$2,TimeOfWeek,$D6) -> 7100000 | R6: =SUMIFS(INDEX(Load,,MATCH('Summarized Source Data'!$B6,Hour,0)),Season,'Summarized Source Data'!$A6,Sector,'Summarized Source Data'!R$2,TimeOfWeek,$D6) -> 7100000 | S6: =SUMIFS(INDEX(Load,,MATCH('Summarized Source Data'!$B6,Hour,0)),Season,'Summarized Source Data'!$A6,Sector,'Summarized Source Data'!S$2,TimeOfWeek,$D6) -> 7100000 | T6: =SUMIFS(INDEX(Load,,MATCH('Summarized Source Data'!$B6,Hour,0)),Season,'Summarized Source Data'!$A6,Sector,'Summarized Source Data'!T$2,TimeOfWeek,$D6) -> 7100000 | U6: =SUMIFS(INDEX(Load,,MATCH('Summarized Source Data'!$B6,Hour,0)),Season,'Summarized Source Data'!$A6,Sector,'Summarized Source Data'!U$2,TimeOfWeek,$D6) -> 7100000 | V6: =SUMIFS(INDEX(Load,,MATCH('Summarized Source Data'!$B6,Hour,0)),Season,'Summarized Source Data'!$A6,Sector,'Summarized Source Data'!V$2,TimeOfWeek,$D6) -> 7100000 | W6: =SUMIFS(INDEX(Load,,MATCH('Summarized Source Data'!$B6,Hour,0)),Season,'Summarized Source Data'!$A6,Sector,'Summarized Source Data'!W$2,Subsector,'Summarized Source Data'!W$3,TimeOfWeek,$D6) -> 1303000000 | X6: =$W6 -> 1303000000 | Y6: =$W6 -> 1303000000
A7: Winter | B7: h4 | C7: Hour3 | D7: Weekday | E7: =SUMIFS(INDEX(Load,,MATCH('Summarized Source Data'!$B7,Hour,0)),Season,'Summarized Source Data'!$A7,Sector,'Summarized Source Data'!E$2,Subsector,'Summarized Source Data'!E$3,TimeOfWeek,$D7) -> 0 | F7: =SUMIFS(INDEX(Load,,MATCH('Summarized Source Data'!$B7,Hour,0)),Season,'Summarized Source Data'!$A7,Sector,'Summarized Source Data'!F$2,Subsector,'Summarized Source Data'!F$3,TimeOfWeek,$D7) -> 1628864 | G7: =SUMIFS(INDEX(Load,,MATCH('Summarized Source Data'!$B7,Hour,0)),Season,'Summarized Source Data'!$A7,Sector,'Summarized Source Data'!G$2,Subsector,'Summarized Source Data'!G$3,TimeOfWeek,$D7) -> 0 | H7: =SUMIFS(INDEX(Load,,MATCH('Summarized Source Data'!$B7,Hour,0)),Season,'Summarized Source Data'!$A7,Sector,'Summarized Source Data'!H$2,Subsector,'Summarized Source Data'!H$3,TimeOfWeek,$D7) -> 67300000 | I7: =H7 -> 67300000 | J7: =H7 -> 67300000 | K7: =SUMIFS(INDEX(Load,,MATCH('Summarized Source Data'!$B7,Hour,0)),Season,'Summarized Source Data'!$A7,Sector,'Summarized Source Data'!K$2,Subsector,'Summarized Source Data'!K$3,TimeOfWeek,$D7) -> 12915332 | L7: =SUMIFS(INDEX(Load,,MATCH('Summarized Source Data'!$B7,Hour,0)),Season,'Summarized Source Data'!$A7,Sector,'Summarized Source Data'!L$2,Subsector,'Summarized Source Data'!L$3,TimeOfWeek,$D7) -> 13486616 | M7: =SUMIFS(INDEX(Load,,MATCH('Summarized Source Data'!$B7,Hour,0)),Season,'Summarized Source Data'!$A7,Sector,'Summarized Source Data'!M$2,Subsector,'Summarized Source Data'!M$3,TimeOfWeek,$D7) -> 0 | N7: =H7 -> 67300000 | O7: =N7 -> 67300000 | P7: =N7 -> 67300000 | Q7: =SUMIFS(INDEX(Load,,MATCH('Summarized Source Data'!$B7,Hour,0)),Season,'Summarized Source Data'!$A7,Sector,'Summarized Source Data'!Q$2,TimeOfWeek,$D7) -> 7100000 | R7: =SUMIFS(INDEX(Load,,MATCH('Summarized Source Data'!$B7,Hour,0)),Season,'Summarized Source Data'!$A7,Sector,'Summarized Source Data'!R$2,TimeOfWeek,$D7) -> 7100000 | S7: =SUMIFS(INDEX(Load,,MATCH('Summarized Source Data'!$B7,Hour,0)),Season,'Summarized Source Data'!$A7,Sector,'Summarized Source Data'!S$2,TimeOfWeek,$D7) -> 7100000 | T7: =SUMIFS(INDEX(Load,,MATCH('Summarized Source Data'!$B7,Hour,0)),Season,'Summarized Source Data'!$A7,Sector,'Summarized Source Data'!T$2,TimeOfWeek,$D7) -> 7100000 | U7: =SUMIFS(INDEX(Load,,MATCH('Summarized Source Data'!$B7,Hour,0)),Season,'Summarized Source Data'!$A7,Sector,'Summarized Source Data'!U$2,TimeOfWeek,$D7) -> 7100000 | V7: =SUMIFS(INDEX(Load,,MATCH('Summarized Source Data'!$B7,Hour,0)),Season,'Summarized Source Data'!$A7,Sector,'Summarized Source Data'!V$2,TimeOfWeek,$D7) -> 7100000 | W7: =SUMIFS(INDEX(Load,,MATCH('Summarized Source Data'!$B7,Hour,0)),Season,'Summarized Source Data'!$A7,Sector,'Summarized Source Data'!W$2,Subsector,'Summarized Source Data'!W$3,TimeOfWeek,$D7) -> 1303000000 | X7: =$W7 -> 1303000000 | Y7: =$W7 -> 1303000000
A8: Winter | B8: h5 | C8: Hour4 | D8: Weekday | E8: =SUMIFS(INDEX(Load,,MATCH('Summarized Source Data'!$B8,Hour,0)),Season,'Summarized Source Data'!$A8,Sector,'Summarized Source Data'!E$2,Subsector,'Summarized Source Data'!E$3,TimeOfWeek,$D8) -> 0 | F8: =SUMIFS(INDEX(Load,,MATCH('Summarized Source Data'!$B8,Hour,0)),Season,'Summarized Source Data'!$A8,Sector,'Summarized Source Data'!F$2,Subsector,'Summarized Source Data'!F$3,TimeOfWeek,$D8) -> 2006502 | G8: =SUMIFS(INDEX(Load,,MATCH('Summarized Source Data'!$B8,Hour,0)),Season,'Summarized Source Data'!$A8,Sector,'Summarized Source Data'!G$2,Subsector,'Summarized Source Data'!G$3,TimeOfWeek,$D8) -> 0 | H8: =SUMIFS(INDEX(Load,,MATCH('Summarized Source Data'!$B8,Hour,0)),Season,'Summarized Source Data'!$A8,Sector,'Summarized Source Data'!H$2,Subsector,'Summarized Source Data'!H$3,TimeOfWeek,$D8) -> 86500000 | I8: =H8 -> 86500000 | J8: =H8 -> 86500000 | K8: =SUMIFS(INDEX(Load,,MATCH('Summarized Source Data'!$B8,Hour,0)),Season,'Summarized Source Data'!$A8,Sector,'Summarized Source Data'!K$2,Subsector,'Summarized Source Data'!K$3,TimeOfWeek,$D8) -> 13541989 | L8: =SUMIFS(INDEX(Load,,MATCH('Summarized Source Data'!$B8,Hour,0)),Season,'Summarized Source Data'!$A8,Sector,'Summarized Source Data'!L$2,Subsector,'Summarized Source Data'!L$3,TimeOfWeek,$D8) -> 13604391 | M8: =SUMIFS(INDEX(Load,,MATCH('Summarized Source Data'!$B8,Hour,0)),Season,'Summarized Source Data'!$A8,Sector,'Summarized Source Data'!M$2,Subsector,'Summarized Source Data'!M$3,TimeOfWeek,$D8) -> 0 | N8: =H8 -> 86500000 | O8: =N8 -> 86500000 | P8: =N8 -> 86500000 | Q8: =SUMIFS(INDEX(Load,,MATCH('Summarized Source Data'!$B8,Hour,0)),Season,'Summarized Source Data'!$A8,Sector,'Summarized Source Data'!Q$2,TimeOfWeek,$D8) -> 7100000 | R8: =SUMIFS(INDEX(Load,,MATCH('Summarized Source Data'!$B8,Hour,0)),Season,'Summarized Source Data'!$A8,Sector,'Summarized Source Data'!R$2,TimeOfWeek,$D8) -> 7100000 | S8: =SUMIFS(INDEX(Load,,MATCH('Summarized Source Data'!$B8,Hour,0)),Season,'Summarized Source Data'!$A8,Sector,'Summarized Source Data'!S$2,TimeOfWeek,$D8) -> 7100000 | T8: =SUMIFS(INDEX(Load,,MATCH('Summarized Source Data'!$B8,Hour,0)),Season,'Summarized Source Data'!$A8,Sector,'Summarized Source Data'!T$2,TimeOfWeek,$D8) -> 7100000 | U8: =SUMIFS(INDEX(Load,,MATCH('Summarized Source Data'!$B8,Hour,0)),Season,'Summarized Source Data'!$A8,Sector,'Summarized Source Data'!U$2,TimeOfWeek,$D8) -> 7100000 | V8: =SUMIFS(INDEX(Load,,MATCH('Summarized Source Data'!$B8,Hour,0)),Season,'Summarized Source Data'!$A8,Sector,'Summarized Source Data'!V$2,TimeOfWeek,$D8) -> 7100000 | W8: =SUMIFS(INDEX(Load,,MATCH('Summarized Source Data'!$B8,Hour,0)),Season,'Summarized Source Data'!$A8,Sector,'Summarized Source Data'!W$2,Subsector,'Summarized Source Data'!W$3,TimeOfWeek,$D8) -> 1305000000 | X8: =$W8 -> 1305000000 | Y8: =$W8 -> 1305000000
A9: Winter | B9: h6 | C9: Hour5 | D9: Weekday | E9: =SUMIFS(INDEX(Load,,MATCH('Summarized Source Data'!$B9,Hour,0)),Season,'Summarized Source Data'!$A9,Sector,'Summarized Source Data'!E$2,Subsector,'Summarized Source Data'!E$3,TimeOfWeek,$D9) -> 0 | F9: =SUMIFS(INDEX(Load,,MATCH('Summarized Source Data'!$B9,Hour,0)),Season,'Summarized Source Data'!$A9,Sector,'Summarized Source Data'!F$2,Subsector,'Summarized Source Data'!F$3,TimeOfWeek,$D9) -> 2578566 | G9: =SUMIFS(INDEX(Load,,MATCH('Summarized Source Data'!$B9,Hour,0)),Season,'Summarized Source Data'!$A9,Sector,'Summarized Source Data'!G$2,Subsector,'Summarized Source Data'!G$3,TimeOfWeek,$D9) -> 0 | H9: =SUMIFS(INDEX(Load,,MATCH('Summarized Source Data'!$B9,Hour,0)),Season,'Summarized Source Data'!$A9,Sector,'Summarized Source Data'!H$2,Subsector,'Summarized Source Data'!H$3,TimeOfWeek,$D9) -> 148800000 | I9: =H9 -> 148800000 | J9: =H9 -> 148800000 | K9: =SUMIFS(INDEX(Load,,MATCH('Summarized Source Data'!$B9,Hour,0)),Season,'Summarized Source Data'!$A9,Sector,'Summarized Source Data'!K$2,Subsector,'Summarized Source Data'!K$3,TimeOfWeek,$D9) -> 13820387 | L9: =SUMIFS(INDEX(Load,,MATCH('Summarized Source Data'!$B9,Hour,0)),Season,'Summarized Source Data'!$A9,Sector,'Summarized Source Data'!L$2,Subsector,'Summarized Source Data'!L$3,TimeOfWeek,$D9) -> 14309159 | M9: =SUMIFS(INDEX(Load,,MATCH('Summarized Source Data'!$B9,Hour,0)),Season,'Summarized Source Data'!$A9,Sector,'Summarized Source Data'!M$2,Subsector,'Summarized Source Data'!M$3,TimeOfWeek,$D9) -> 0 | N9: =H9 -> 148800000 | O9: =N9 -> 148800000 | P9: =N9 -> 148800000 | Q9: =SUMIFS(INDEX(Load,,MATCH('Summarized Source Data'!$B9,Hour,0)),Season,'Summarized Source Data'!$A9,Sector,'Summarized Source Data'!Q$2,TimeOfWeek,$D9) -> 7120000 | R9: =SUMIFS(INDEX(Load,,MATCH('Summarized Source Data'!$B9,Hour,0)),Season,'Summarized Source Data'!$A9,Sector,'Summarized Source Data'!R$2,TimeOfWeek,$D9) -> 7120000 | S9: =SUMIFS(INDEX(Load,,MATCH('Summarized Source Data'!$B9,Hour,0)),Season,'Summarized Source Data'!$A9,Sector,'Summarized Source Data'!S$2,TimeOfWeek,$D9) -> 7120000 | T9: =SUMIFS(INDEX(Load,,MATCH('Summarized Source Data'!$B9,Hour,0)),Season,'Summarized Source Data'!$A9,Sector,'Summarized Source Data'!T$2,TimeOfWeek,$D9) -> 7120000 | U9: =SUMIFS(INDEX(Load,,MATCH('Summarized Source Data'!$B9,Hour,0)),Season,'Summarized Source Data'!$A9,Sector,'Summarized Source Data'!U$2,TimeOfWeek,$D9) -> 7120000 | V9: =SUMIFS(INDEX(Load,,MATCH('Summarized Source Data'!$B9,Hour,0)),Season,'Summarized Source Data'!$A9,Sector,'Summarized Source Data'!V$2,TimeOfWeek,$D9) -> 7120000 | W9: =SUMIFS(INDEX(Load,,MATCH('Summarized Source Data'!$B9,Hour,0)),Season,'Summarized Source Data'!$A9,Sector,'Summarized Source Data'!W$2,Subsector,'Summarized Source Data'!W$3,TimeOfWeek,$D9) -> 1311000000 | X9: =$W9 -> 1311000000 | Y9: =$W9 -> 1311000000
A10: Winter | B10: h7 | C10: Hour6 | D10: Weekday | E10: =SUMIFS(INDEX(Load,,MATCH('Summarized Source Data'!$B10,Hour,0)),Season,'Summarized Source Data'!$A10,Sector,'Summarized Source Data'!E$2,Subsector,'Summarized Source Data'!E$3,TimeOfWeek,$D10) -> 0 | F10: =SUMIFS(INDEX(Load,,MATCH('Summarized Source Data'!$B10,Hour,0)),Season,'Summarized Source Data'!$A10,Sector,'Summarized Source Data'!F$2,Subsector,'Summarized Source Data'!F$3,TimeOfWeek,$D10) -> 3114533 | G10: =SUMIFS(INDEX(Load,,MATCH('Summarized Source Data'!$B10,Hour,0)),Season,'Summarized Source Data'!$A10,Sector,'Summarized Source Data'!G$2,Subsector,'Summarized Source Data'!G$3,TimeOfWeek,$D10) -> 0 | H10: =SUMIFS(INDEX(Load,,MATCH('Summarized Source Data'!$B10,Hour,0)),Season,'Summarized Source Data'!$A10,Sector,'Summarized Source Data'!H$2,Subsector,'Summarized Source Data'!H$3,TimeOfWeek,$D10) -> 217400000 | I10: =H10 -> 217400000 | J10: =H10 -> 217400000 | K10: =SUMIFS(INDEX(Load,,MATCH('Summarized Source Data'!$B10,Hour,0)),Season,'Summarized Source Data'!$A10,Sector,'Summarized Source Data'!K$2,Subsector,'Summarized Source Data'!K$3,TimeOfWeek,$D10) -> 17799212 | L10: =SUMIFS(INDEX(Load,,MATCH('Summarized Source Data'!$B10,Hour,0)),Season,'Summarized Source Data'!$A10,Sector,'Summarized Source Data'!L$2,Subsector,'Summarized Source Data'!L$3,TimeOfWeek,$D10) -> 16256157 | M10: =SUMIFS(INDEX(Load,,MATCH('Summarized Source Data'!$B10,Hour,0)),Season,'Summarized Source Data'!$A10,Sector,'Summarized Source Data'!M$2,Subsector,'Summarized Source Data'!M$3,TimeOfWeek,$D10) -> 0 | N10: =H10 -> 217400000 | O10: =N10 -> 217400000 | P10: =N10 -> 217400000 | Q10: =SUMIFS(INDEX(Load,,MATCH('Summarized Source Data'!$B10,Hour,0)),Season,'Summarized Source Data'!$A10,Sector,'Summarized Source Data'!Q$2,TimeOfWeek,$D10) -> 10310000 | R10: =SUMIFS(INDEX(Load,,MATCH('Summarized Source Data'!$B10,Hour,0)),Season,'Summarized Source Data'!$A10,Sector,'Summarized Source Data'!R$2,TimeOfWeek,$D10) -> 10310000 | S10: =SUMIFS(INDEX(Load,,MATCH('Summarized Source Data'!$B10,Hour,0)),Season,'Summarized Source Data'!$A10,Sector,'Summarized Source Data'!S$2,TimeOfWeek,$D10) -> 10310000 | T10: =SUMIFS(INDEX(Load,,MATCH('Summarized Source Data'!$B10,Hour,0)),Season,'Summarized Source Data'!$A10,Sector,'Summarized Source Data'!T$2,TimeOfWeek,$D10) -> 10310000 | U10: =SUMIFS(INDEX(Load,,MATCH('Summarized Source Data'!$B10,Hour,0)),Season,'Summarized Source Data'!$A10,Sector,'Summarized Source Data'!U$2,TimeOfWeek,$D10) -> 10310000 | V10: =SUMIFS(INDEX(Load,,MATCH('Summarized Source Data'!$B10,Hour,0)),Season,'Summarized Source Data'!$A10,Sector,'Summarized Source Data'!V$2,TimeOfWeek,$D10) -> 10310000 | W10: =SUMIFS(INDEX(Load,,MATCH('Summarized Source Data'!$B10,Hour,0)),Season,'Summarized Source Data'!$A10,Sector,'Summarized Source Data'!W$2,Subsector,'Summarized Source Data'!W$3,TimeOfWeek,$D10) -> 1319000000 | X10: =$W10 -> 1319000000 | Y10: =$W10 -> 1319000000
A11: Winter | B11: h8 | C11: Hour7 | D11: Weekday | E11: =SUMIFS(INDEX(Load,,MATCH('Summarized Source Data'!$B11,Hour,0)),Season,'Summarized Source Data'!$A11,Sector,'Summarized Source Data'!E$2,Subsector,'Summarized Source Data'!E$3,TimeOfWeek,$D11) -> 0 | F11: =SUMIFS(INDEX(Load,,MATCH('Summarized Source Data'!$B11,Hour,0)),Season,'Summarized Source Data'!$A11,Sector,'Summarized Source Data'!F$2,Subsector,'Summarized Source Data'!F$3,TimeOfWeek,$D11) -> 3550410 | G11: =SUMIFS(INDEX(Load,,MATCH('Summarized Source Data'!$B11,Hour,0)),Season,'Summarized Source Data'!$A11,Sector,'Summarized Source Data'!G$2,Subsector,'Summarized Source Data'!G$3,TimeOfWeek,$D11) -> 0 | H11: =SUMIFS(INDEX(Load,,MATCH('Summarized Source Data'!$B11,Hour,0)),Season,'Summarized Source Data'!$A11,Sector,'Summarized Source Data'!H$2,Subsector,'Summarized Source Data'!H$3,TimeOfWeek,$D11) -> 92000000 | I11: =H11 -> 92000000 | J11: =H11 -> 92000000 | K11: =SUMIFS(INDEX(Load,,MATCH('Summarized Source Data'!$B11,Hour,0)),Season,'Summarized Source Data'!$A11,Sector,'Summarized Source Data'!K$2,Subsector,'Summarized Source Data'!K$3,TimeOfWeek,$D11) -> 44467501 | L11: =SUMIFS(INDEX(Load,,MATCH('Summarized Source Data'!$B11,Hour,0)),Season,'Summarized Source Data'!$A11,Sector,'Summarized Source Data'!L$2,Subsector,'Summarized Source Data'!L$3,TimeOfWeek,$D11) -> 19900585 | M11: =SUMIFS(INDEX(Load,,MATCH('Summarized Source Data'!$B11,Hour,0)),Season,'Summarized Source Data'!$A11,Sector,'Summarized Source Data'!M$2,Subsector,'Summarized Source Data'!M$3,TimeOfWeek,$D11) -> 0 | N11: =H11 -> 92000000 | O11: =N11 -> 92000000 | P11: =N11 -> 92000000 | Q11: =SUMIFS(INDEX(Load,,MATCH('Summarized Source Data'!$B11,Hour,0)),Season,'Summarized Source Data'!$A11,Sector,'Summarized Source Data'!Q$2,TimeOfWeek,$D11) -> 20680000 | R11: =SUMIFS(INDEX(Load,,MATCH('Summarized Source Data'!$B11,Hour,0)),Season,'Summarized Source Data'!$A11,Sector,'Summarized Source Data'!R$2,TimeOfWeek,$D11) -> 20680000 | S11: =SUMIFS(INDEX(Load,,MATCH('Summarized Source Data'!$B11,Hour,0)),Season,'Summarized Source Data'!$A11,Sector,'Summarized Source Data'!S$2,TimeOfWeek,$D11) -> 20680000 | T11: =SUMIFS(INDEX(Load,,MATCH('Summarized Source Data'!$B11,Hour,0)),Season,'Summarized Source Data'!$A11,Sector,'Summarized Source Data'!T$2,TimeOfWeek,$D11) -> 20680000 | U11: =SUMIFS(INDEX(Load,,MATCH('Summarized Source Data'!$B11,Hour,0)),Season,'Summarized Source Data'!$A11,Sector,'Summarized Source Data'!U$2,TimeOfWeek,$D11) -> 20680000 | V11: =SUMIFS(INDEX(Load,,MATCH('Summarized Source Data'!$B11,Hour,0)),Season,'Summarized Source Data'!$A11,Sector,'Summarized Source Data'!V$2,TimeOfWeek,$D11) -> 20680000 | W11: =SUMIFS(INDEX(Load,,MATCH('Summarized Source Data'!$B11,Hour,0)),Season,'Summarized Source Data'!$A11,Sector,'Summarized Source Data'!W$2,Subsector,'Summarized Source Data'!W$3,TimeOfWeek,$D11) -> 1326000000 | X11: =$W11 -> 1326000000 | Y11: =$W11 -> 1326000000
A12: Winter | B12: h9 | C12: Hour8 | D12: Weekday | E12: =SUMIFS(INDEX(Load,,MATCH('Summarized Source Data'!$B12,Hour,0)),Season,'Summarized Source Data'!$A12,Sector,'Summarized Source Data'!E$2,Subsector,'Summarized Source Data'!E$3,TimeOfWeek,$D12) -> 0 | F12: =SUMIFS(INDEX(Load,,MATCH('Summarized Source Data'!$B12,Hour,0)),Season,'Summarized Source Data'!$A12,Sector,'Summarized Source Data'!F$2,Subsector,'Summarized Source Data'!F$3,TimeOfWeek,$D12) -> 4336652 | G12: =SUMIFS(INDEX(Load,,MATCH('Summarized Source Data'!$B12,Hour,0)),Season,'Summarized Source Data'!$A12,Sector,'Summarized Source Data'!G$2,Subsector,'Summarized Source Data'!G$3,TimeOfWeek,$D12) -> 0 | H12: =SUMIFS(INDEX(Load,,MATCH('Summarized Source Data'!$B12,Hour,0)),Season,'Summarized Source Data'!$A12,Sector,'Summarized Source Data'!H$2,Subsector,'Summarized Source Data'!H$3,TimeOfWeek,$D12) -> 66100000 | I12: =H12 -> 66100000 | J12: =H12 -> 66100000 | K12: =SUMIFS(INDEX(Load,,MATCH('Summarized Source Data'!$B12,Hour,0)),Season,'Summarized Source Data'!$A12,Sector,'Summarized Source Data'!K$2,Subsector,'Summarized Source Data'!K$3,TimeOfWeek,$D12) -> 44830553 | L12: =SUMIFS(INDEX(Load,,MATCH('Summarized Source Data'!$B12,Hour,0)),Season,'Summarized Source Data'!$A12,Sector,'Summarized Source Data'!L$2,Subsector,'Summarized Source Data'!L$3,TimeOfWeek,$D12) -> 25280880 | M12: =SUMIFS(INDEX(Load,,MATCH('Summarized Source Data'!$B12,Hour,0)),Season,'Summarized Source Data'!$A12,Sector,'Summarized Source Data'!M$2,Subsector,'Summarized Source Data'!M$3,TimeOfWeek,$D12) -> 0 | N12: =H12 -> 66100000 | O12: =N12 -> 66100000 | P12: =N12 -> 66100000 | Q12: =SUMIFS(INDEX(Load,,MATCH('Summarized Source Data'!$B12,Hour,0)),Season,'Summarized Source Data'!$A12,Sector,'Summarized Source Data'!Q$2,TimeOfWeek,$D12) -> 20940000 | R12: =SUMIFS(INDEX(Load,,MATCH('Summarized Source Data'!$B12,Hour,0)),Season,'Summarized Source Data'!$A12,Sector,'Summarized Source Data'!R$2,TimeOfWeek,$D12) -> 20940000 | S12: =SUMIFS(INDEX(Load,,MATCH('Summarized Source Data'!$B12,Hour,0)),Season,'Summarized Source Data'!$A12,Sector,'Summarized Source Data'!S$2,TimeOfWeek,$D12) -> 20940000 | T12: =SUMIFS(INDEX(Load,,MATCH('Summarized Source Data'!$B12,Hour,0)),Season,'Summarized Source Data'!$A12,Sector,'Summarized Source Data'!T$2,TimeOfWeek,$D12) -> 20940000 | U12: =SUMIFS(INDEX(Load,,MATCH('Summarized Source Data'!$B12,Hour,0)),Season,'Summarized Source Data'!$A12,Sector,'Summarized Source Data'!U$2,TimeOfWeek,$D12) -> 20940000 | V12: =SUMIFS(INDEX(Load,,MATCH('Summarized Source Data'!$B12,Hour,0)),Season,'Summarized Source Data'!$A12,Sector,'Summarized Source Data'!V$2,TimeOfWeek,$D12) -> 20940000 | W12: =SUMIFS(INDEX(Load,,MATCH('Summarized Source Data'!$B12,Hour,0)),Season,'Summarized Source Data'!$A12,Sector,'Summarized Source Data'!W$2,Subsector,'Summarized Source Data'!W$3,TimeOfWeek,$D12) -> 1328000000 | X12: =$W12 -> 1328000000 | Y12: =$W12 -> 1328000000
A13: Winter | B13: h10 | C13: Hour9 | D13: Weekday | E13: =SUMIFS(INDEX(Load,,MATCH('Summarized Source Data'!$B13,Hour,0)),Season,'Summarized Source Data'!$A13,Sector,'Summarized Source Data'!E$2,Subsector,'Summarized Source Data'!E$3,TimeOfWeek,$D13) -> 0 | F13: =SUMIFS(INDEX(Load,,MATCH('Summarized Source Data'!$B13,Hour,0)),Season,'Summarized Source Data'!$A13,Sector,'Summarized Source Data'!F$2,Subsector,'Summarized Source Data'!F$3,TimeOfWeek,$D13) -> 5573907 | G13: =SUMIFS(INDEX(Load,,MATCH('Summarized Source Data'!$B13,Hour,0)),Season,'Summarized Source Data'!$A13,Sector,'Summarized Source Data'!G$2,Subsector,'Summarized Source Data'!G$3,TimeOfWeek,$D13) -> 0 | H13: =SUMIFS(INDEX(Load,,MATCH('Summarized Source Data'!$B13,Hour,0)),Season,'Summarized Source Data'!$A13,Sector,'Summarized Source Data'!H$2,Subsector,'Summarized Source Data'!H$3,TimeOfWeek,$D13) -> 63500000 | I13: =H13 -> 63500000 | J13: =H13 -> 63500000 | K13: =SUMIFS(INDEX(Load,,MATCH('Summarized Source Data'!$B13,Hour,0)),Season,'Summarized Source Data'!$A13,Sector,'Summarized Source Data'!K$2,Subsector,'Summarized Source Data'!K$3,TimeOfWeek,$D13) -> 31972869 | L13: =SUMIFS(INDEX(Load,,MATCH('Summarized Source Data'!$B13,Hour,0)),Season,'Summarized Source Data'!$A13,Sector,'Summarized Source Data'!L$2,Subsector,'Summarized Source Data'!L$3,TimeOfWeek,$D13) -> 29693132 | M13: =SUMIFS(INDEX(Load,,MATCH('Summarized Source Data'!$B13,Hour,0)),Season,'Summarized Source Data'!$A13,Sector,'Summarized Source Data'!M$2,Subsector,'Summarized Source Data'!M$3,TimeOfWeek,$D13) -> 0 | N13: =H13 -> 63500000 | O13: =N13 -> 63500000 | P13: =N13 -> 63500000 | Q13: =SUMIFS(INDEX(Load,,MATCH('Summarized Source Data'!$B13,Hour,0)),Season,'Summarized Source Data'!$A13,Sector,'Summarized Source Data'!Q$2,TimeOfWeek,$D13) -> 18850000 | R13: =SUMIFS(INDEX(Load,,MATCH('Summarized Source Data'!$B13,Hour,0)),Season,'Summarized Source Data'!$A13,Sector,'Summarized Source Data'!R$2,TimeOfWeek,$D13) -> 18850000 | S13: =SUMIFS(INDEX(Load,,MATCH('Summarized Source Data'!$B13,Hour,0)),Season,'Summarized Source Data'!$A13,Sector,'Summarized Source Data'!S$2,TimeOfWeek,$D13) -> 18850000 | T13: =SUMIFS(INDEX(Load,,MATCH('Summarized Source Data'!$B13,Hour,0)),Season,'Summarized Source Data'!$A13,Sector,'Summarized Source Data'!T$2,TimeOfWeek,$D13) -> 18850000 | U13: =SUMIFS(INDEX(Load,,MATCH('Summarized Source Data'!$B13,Hour,0)),Season,'Summarized Source Data'!$A13,Sector,'Summarized Source Data'!U$2,TimeOfWeek,$D13) -> 18850000 | V13: =SUMIFS(INDEX(Load,,MATCH('Summarized Source Data'!$B13,Hour,0)),Season,'Summarized Source Data'!$A13,Sector,'Summarized Source Data'!V$2,TimeOfWeek,$D13) -> 18850000 | W13: =SUMIFS(INDEX(Load,,MATCH('Summarized Source Data'!$B13,Hour,0)),Season,'Summarized Source Data'!$A13,Sector,'Summarized Source Data'!W$2,Subsector,'Summarized Source Data'!W$3,TimeOfWeek,$D13) -> 1326000000 | X13: =$W13 -> 1326000000 | Y13: =$W13 -> 1326000000
A14: Winter | B14: h11 | C14: Hour10 | D14: Weekday | E14: =SUMIFS(INDEX(Load,,MATCH('Summarized Source Data'!$B14,Hour,0)),Season,'Summarized Source Data'!$A14,Sector,'Summarized Source Data'!E$2,Subsector,'Summarized Source Data'!E$3,TimeOfWeek,$D14) -> 0 | F14: =SUMIFS(INDEX(Load,,MATCH('Summarized Source Data'!$B14,Hour,0)),Season,'Summarized Source Data'!$A14,Sector,'Summarized Source Data'!F$2,Subsector,'Summarized Source Data'!F$3,TimeOfWeek,$D14) -> 7828127 | G14: =SUMIFS(INDEX(Load,,MATCH('Summarized Source Data'!$B14,Hour,0)),Season,'Summarized Source Data'!$A14,Sector,'Summarized Source Data'!G$2,Subsector,'Summarized Source Data'!G$3,TimeOfWeek,$D14) -> 0 | H14: =SUMIFS(INDEX(Load,,MATCH('Summarized Source Data'!$B14,Hour,0)),Season,'Summarized Source Data'!$A14,Sector,'Summarized Source Data'!H$2,Subsector,'Summarized Source Data'!H$3,TimeOfWeek,$D14) -> 64500000 | I14: =H14 -> 64500000 | J14: =H14 -> 64500000 | K14: =SUMIFS(INDEX(Load,,MATCH('Summarized Source Data'!$B14,Hour,0)),Season,'Summarized Source Data'!$A14,Sector,'Summarized Source Data'!K$2,Subsector,'Summarized Source Data'!K$3,TimeOfWeek,$D14) -> 26328397 | L14: =SUMIFS(INDEX(Load,,MATCH('Summarized Source Data'!$B14,Hour,0)),Season,'Summarized Source Data'!$A14,Sector,'Summarized Source Data'!L$2,Subsector,'Summarized Source Data'!L$3,TimeOfWeek,$D14) -> 33366063 | M14: =SUMIFS(INDEX(Load,,MATCH('Summarized Source Data'!$B14,Hour,0)),Season,'Summarized Source Data'!$A14,Sector,'Summarized Source Data'!M$2,Subsector,'Summarized Source Data'!M$3,TimeOfWeek,$D14) -> 0 | N14: =H14 -> 64500000 | O14: =N14 -> 64500000 | P14: =N14 -> 64500000 | Q14: =SUMIFS(INDEX(Load,,MATCH('Summarized Source Data'!$B14,Hour,0)),Season,'Summarized Source Data'!$A14,Sector,'Summarized Source Data'!Q$2,TimeOfWeek,$D14) -> 15570000 | R14: =SUMIFS(INDEX(Load,,MATCH('Summarized Source Data'!$B14,Hour,0)),Season,'Summarized Source Data'!$A14,Sector,'Summarized Source Data'!R$2,TimeOfWeek,$D14) -> 15570000 | S14: =SUMIFS(INDEX(Load,,MATCH('Summarized Source Data'!$B14,Hour,0)),Season,'Summarized Source Data'!$A14,Sector,'Summarized Source Data'!S$2,TimeOfWeek,$D14) -> 15570000 | T14: =SUMIFS(INDEX(Load,,MATCH('Summarized Source Data'!$B14,Hour,0)),Season,'Summarized Source Data'!$A14,Sector,'Summarized Source Data'!T$2,TimeOfWeek,$D14) -> 15570000 | U14: =SUMIFS(INDEX(Load,,MATCH('Summarized Source Data'!$B14,Hour,0)),Season,'Summarized Source Data'!$A14,Sector,'Summarized Source Data'!U$2,TimeOfWeek,$D14) -> 15570000 | V14: =SUMIFS(INDEX(Load,,MATCH('Summarized Source Data'!$B14,Hour,0)),Season,'Summarized Source Data'!$A14,Sector,'Summarized Source Data'!V$2,TimeOfWeek,$D14) -> 15570000 | W14: =SUMIFS(INDEX(Load,,MATCH('Summarized Source Data'!$B14,Hour,0)),Season,'Summarized Source Data'!$A14,Sector,'Summarized Source Data'!W$2,Subsector,'Summarized Source Data'!W$3,TimeOfWeek,$D14) -> 1324000000 | X14: =$W14 -> 1324000000 | Y14: =$W14 -> 1324000000
A15: Winter | B15: h12 | C15: Hour11 | D15: Weekday | E15: =SUMIFS(INDEX(Load,,MATCH('Summarized Source Data'!$B15,Hour,0)),Season,'Summarized Source Data'!$A15,Sector,'Summarized Source Data'!E$2,Subsector,'Summarized Source Data'!E$3,TimeOfWeek,$D15) -> 0 | F15: =SUMIFS(INDEX(Load,,MATCH('Summarized Source Data'!$B15,Hour,0)),Season,'Summarized Source Data'!$A15,Sector,'Summarized Source Data'!F$2,Subsector,'Summarized Source Data'!F$3,TimeOfWeek,$D15) -> 11813648 | G15: =SUMIFS(INDEX(Load,,MATCH('Summarized Source Data'!$B15,Hour,0)),Season,'Summarized Source Data'!$A15,Sector,'Summarized Source Data'!G$2,Subsector,'Summarized Source Data'!G$3,TimeOfWeek,$D15) -> 0 | H15: =SUMIFS(INDEX(Load,,MATCH('Summarized Source Data'!$B15,Hour,0)),Season,'Summarized Source Data'!$A15,Sector,'Summarized Source Data'!H$2,Subsector,'Summarized Source Data'!H$3,TimeOfWeek,$D15) -> 70800000 | I15: =H15 -> 70800000 | J15: =H15 -> 70800000 | K15: =SUMIFS(INDEX(Load,,MATCH('Summarized Source Data'!$B15,Hour,0)),Season,'Summarized Source Data'!$A15,Sector,'Summarized Source Data'!K$2,Subsector,'Summarized Source Data'!K$3,TimeOfWeek,$D15) -> 22933364 | L15: =SUMIFS(INDEX(Load,,MATCH('Summarized Source Data'!$B15,Hour,0)),Season,'Summarized Source Data'!$A15,Sector,'Summarized Source Data'!L$2,Subsector,'Summarized Source Data'!L$3,TimeOfWeek,$D15) -> 36322526 | M15: =SUMIFS(INDEX(Load,,MATCH('Summarized Source Data'!$B15,Hour,0)),Season,'Summarized Source Data'!$A15,Sector,'Summarized Source Data'!M$2,Subsector,'Summarized Source Data'!M$3,TimeOfWeek,$D15) -> 0 | N15: =H15 -> 70800000 | O15: =N15 -> 70800000 | P15: =N15 -> 70800000 | Q15: =SUMIFS(INDEX(Load,,MATCH('Summarized Source Data'!$B15,Hour,0)),Season,'Summarized Source Data'!$A15,Sector,'Summarized Source Data'!Q$2,TimeOfWeek,$D15) -> 15580000 | R15: =SUMIFS(INDEX(Load,,MATCH('Summarized Source Data'!$B15,Hour,0)),Season,'Summarized Source Data'!$A15,Sector,'Summarized Source Data'!R$2,TimeOfWeek,$D15) -> 15580000 | S15: =SUMIFS(INDEX(Load,,MATCH('Summarized Source Data'!$B15,Hour,0)),Season,'Summarized Source Data'!$A15,Sector,'Summarized Source Data'!S$2,TimeOfWeek,$D15) -> 15580000 | T15: =SUMIFS(INDEX(Load,,MATCH('Summarized Source Data'!$B15,Hour,0)),Season,'Summarized Source Data'!$A15,Sector,'Summarized Source Data'!T$2,TimeOfWeek,$D15) -> 15580000 | U15: =SUMIFS(INDEX(Load,,MATCH('Summarized Source Data'!$B15,Hour,0)),Season,'Summarized Source Data'!$A15,Sector,'Summarized Source Data'!U$2,TimeOfWeek,$D15) -> 15580000 | V15: =SUMIFS(INDEX(Load,,MATCH('Summarized Source Data'!$B15,Hour,0)),Season,'Summarized Source Data'!$A15,Sector,'Summarized Source Data'!V$2,TimeOfWeek,$D15) -> 15580000 | W15: =SUMIFS(INDEX(Load,,MATCH('Summarized Source Data'!$B15,Hour,0)),Season,'Summarized Source Data'!$A15,Sector,'Summarized Source Data'!W$2,Subsector,'Summarized Source Data'!W$3,TimeOfWeek,$D15) -> 1320000000 | X15: =$W15 -> 1320000000 | Y15: =$W15 -> 1320000000
... A195: Fall | B195: h24 | C195: Hour23 | D195: Weekend | E195: =SUMIFS(INDEX(Load,,MATCH('Summarized Source Data'!$B195,Hour,0)),Season,'Summarized Source Data'!$A195,Sector,'Summarized Source Data'!E$2,Subsector,'Summarized Source Data'!E$3,TimeOfWeek,$D195) -> 0 | F195: =SUMIFS(INDEX(Load,,MATCH('Summarized Source Data'!$B195,Hour,0)),Season,'Summarized Source Data'!$A195,Sector,'Summarized Source Data'!F$2,Subsector,'Summarized Source Data'!F$3,TimeOfWeek,$D195) -> 3060919 | G195: =SUMIFS(INDEX(Load,,MATCH('Summarized Source Data'!$B195,Hour,0)),Season,'Summarized Source Data'!$A195,Sector,'Summarized Source Data'!G$2,Subsector,'Summarized Source Data'!G$3,TimeOfWeek,$D195) -> 0 | H195: =SUMIFS(INDEX(Load,,MATCH('Summarized Source Data'!$B195,Hour,0)),Season,'Summarized Source Data'!$A195,Sector,'Summarized Source Data'!H$2,Subsector,'Summarized Source Data'!H$3,TimeOfWeek,$D195) -> 30400000 | I195: =H195 -> 30400000 | J195: =H195 -> 30400000 | K195: =SUMIFS(INDEX(Load,,MATCH('Summarized Source Data'!$B195,Hour,0)),Season,'Summarized Source Data'!$A195,Sector,'Summarized Source Data'!K$2,Subsector,'Summarized Source Data'!K$3,TimeOfWeek,$D195) -> 1151991 | L195: =SUMIFS(INDEX(Load,,MATCH('Summarized Source Data'!$B195,Hour,0)),Season,'Summarized Source Data'!$A195,Sector,'Summarized Source Data'!L$2,Subsector,'Summarized Source Data'!L$3,TimeOfWeek,$D195) -> 10391793 | M195: =SUMIFS(INDEX(Load,,MATCH('Summarized Source Data'!$B195,Hour,0)),Season,'Summarized Source Data'!$A195,Sector,'Summarized Source Data'!M$2,Subsector,'Summarized Source Data'!M$3,TimeOfWeek,$D195) -> 0 | N195: =H195 -> 30400000 | O195: =N195 -> 30400000 | P195: =N195 -> 30400000 | Q195: =SUMIFS(INDEX(Load,,MATCH('Summarized Source Data'!$B195,Hour,0)),Season,'Summarized Source Data'!$A195,Sector,'Summarized Source Data'!Q$2,TimeOfWeek,$D195) -> 2550000 | R195: =SUMIFS(INDEX(Load,,MATCH('Summarized Source Data'!$B195,Hour,0)),Season,'Summarized Source Data'!$A195,Sector,'Summarized Source Data'!R$2,TimeOfWeek,$D195) -> 2550000 | S195: =SUMIFS(INDEX(Load,,MATCH('Summarized Source Data'!$B195,Hour,0)),Season,'Summarized Source Data'!$A195,Sector,'Summarized Source Data'!S$2,TimeOfWeek,$D195) -> 2550000 | T195: =SUMIFS(INDEX(Load,,MATCH('Summarized Source Data'!$B195,Hour,0)),Season,'Summarized Source Data'!$A195,Sector,'Summarized Source Data'!T$2,TimeOfWeek,$D195) -> 2550000 | U195: =SUMIFS(INDEX(Load,,MATCH('Summarized Source Data'!$B195,Hour,0)),Season,'Summarized Source Data'!$A195,Sector,'Summarized Source Data'!U$2,TimeOfWeek,$D195) -> 2550000 | V195: =SUMIFS(INDEX(Load,,MATCH('Summarized Source Data'!$B195,Hour,0)),Season,'Summarized Source Data'!$A195,Sector,'Summarized Source Data'!V$2,TimeOfWeek,$D195) -> 2550000 | W195: =SUMIFS(INDEX(Load,,MATCH('Summarized Source Data'!$B195,Hour,0)),Season,'Summarized Source Data'!$A195,Sector,'Summarized Source Data'!W$2,Subsector,'Summarized Source Data'!W$3,TimeOfWeek,$D195) -> 341000000 | X195: =$W195 -> 341000000 | Y195: =$W195 -> 341000000
A198: Hourly Demand by Time of Week and End Use (kW/day)
E199: Residential | F199: Residential | G199: Residential | H199: Residential | I199: Residential | J199: Residential | K199: Commercial | L199: Commercial | M199: Commercial | N199: Commercial | O199: Commercial | P199: Commercial | Q199: Transportation | R199: Transportation | S199: Transportation | T199: Transportation | U199: Transportation | V199: Transportation | W199: Industry | X199: Industry | Y199: Industry
A200: Season | B200: Hour | D200: Time of Week | E200: Heating | F200: Cooling | G200: Envelope | H200: Lighting | I200: Appliances | J200: Other | K200: Heating | L200: Cooling | M200: Envelope | N200: Lighting | O200: Appliances | P200: Other | Q200: LDVs | R200: HDVs | S200: Aircraft | T200: Rail | U200: Ships | V200: Motorbikes | W200: Industry | X200: District Heat and Hydrogen | Y200: Geoengineering
A201: Winter | B201: h1 | C201: Hour0 | D201: Weekday | E201: =E4/WinterWeekdays -> 0 | F201: =F4/WinterWeekdays -> 31704.322 | G201: =G4/WinterWeekdays -> 0 | H201: =H4/WinterWeekdays -> 1121555.6 | I201: =I4/WinterWeekdays -> 1121555.6 | J201: =J4/WinterWeekdays -> 1121555.6 | K201: =K4/WinterWeekdays -> 237712.64 | L201: =L4/WinterWeekdays -> 233108.32 | ... Y201: =Y4/WinterWeekdays -> 20300000
A202: Winter | B202: h2 | C202: Hour1 | D202: Weekday | E202: =E5/WinterWeekdays -> 0 | F202: =F5/WinterWeekdays -> 25227.238 | G202: =G5/WinterWeekdays -> 0 | H202: =H5/WinterWeekdays -> 1034444.4 | I202: =I5/WinterWeekdays -> 1034444.4 | J202: =J5/WinterWeekdays -> 1034444.4 | K202: =K5/WinterWeekdays -> 217135.54 | L202: =L5/WinterWeekdays -> 218023.82 | ... Y202: =Y5/WinterWeekdays -> 20268889
A203: Winter | B203: h3 | C203: Hour2 | D203: Weekday | E203: =E6/WinterWeekdays -> 0 | F203: =F6/WinterWeekdays -> 23275.7 | G203: =G6/WinterWeekdays -> 0 | H203: =H6/WinterWeekdays -> 1023555.6 | I203: =I6/WinterWeekdays -> 1023555.6 | J203: =J6/WinterWeekdays -> 1023555.6 | K203: =K6/WinterWeekdays -> 194703.18 | L203: =L6/WinterWeekdays -> 212002.19 | ... Y203: =Y6/WinterWeekdays -> 20268889
A204: Winter | B204: h4 | C204: Hour3 | D204: Weekday | E204: =E7/WinterWeekdays -> 0 | F204: =F7/WinterWeekdays -> 25337.884 | G204: =G7/WinterWeekdays -> 0 | H204: =H7/WinterWeekdays -> 1046888.9 | I204: =I7/WinterWeekdays -> 1046888.9 | J204: =J7/WinterWeekdays -> 1046888.9 | K204: =K7/WinterWeekdays -> 200905.16 | L204: =L7/WinterWeekdays -> 209791.8 | ... Y204: =Y7/WinterWeekdays -> 20268889
A205: Winter | B205: h5 | C205: Hour4 | D205: Weekday | E205: =E8/WinterWeekdays -> 0 | F205: =F8/WinterWeekdays -> 31212.253 | G205: =G8/WinterWeekdays -> 0 | H205: =H8/WinterWeekdays -> 1345555.6 | I205: =I8/WinterWeekdays -> 1345555.6 | J205: =J8/WinterWeekdays -> 1345555.6 | K205: =K8/WinterWeekdays -> 210653.16 | L205: =L8/WinterWeekdays -> 211623.86 | ... Y205: =Y8/WinterWeekdays -> 20300000
A206: Winter | B206: h6 | C206: Hour5 | D206: Weekday | E206: =E9/WinterWeekdays -> 0 | F206: =F9/WinterWeekdays -> 40111.027 | G206: =G9/WinterWeekdays -> 0 | H206: =H9/WinterWeekdays -> 2314666.7 | I206: =I9/WinterWeekdays -> 2314666.7 | J206: =J9/WinterWeekdays -> 2314666.7 | K206: =K9/WinterWeekdays -> 214983.8 | L206: =L9/WinterWeekdays -> 222586.92 | ... Y206: =Y9/WinterWeekdays -> 20393333
A207: Winter | B207: h7 | C207: Hour6 | D207: Weekday | E207: =E10/WinterWeekdays -> 0 | F207: =F10/WinterWeekdays -> 48448.291 | G207: =G10/WinterWeekdays -> 0 | H207: =H10/WinterWeekdays -> 3381777.8 | I207: =I10/WinterWeekdays -> 3381777.8 | J207: =J10/WinterWeekdays -> 3381777.8 | K207: =K10/WinterWeekdays -> 276876.63 | L207: =L10/WinterWeekdays -> 252873.55 | ... Y207: =Y10/WinterWeekdays -> 20517778
A208: Winter | B208: h8 | C208: Hour7 | D208: Weekday | E208: =E11/WinterWeekdays -> 0 | F208: =F11/WinterWeekdays -> 55228.6 | G208: =G11/WinterWeekdays -> 0 | H208: =H11/WinterWeekdays -> 1431111.1 | I208: =I11/WinterWeekdays -> 1431111.1 | J208: =J11/WinterWeekdays -> 1431111.1 | K208: =K11/WinterWeekdays -> 691716.68 | L208: =L11/WinterWeekdays -> 309564.66 | ... Y208: =Y11/WinterWeekdays -> 20626667
A209: Winter | B209: h9 | C209: Hour8 | D209: Weekday | E209: =E12/WinterWeekdays -> 0 | F209: =F12/WinterWeekdays -> 67459.031 | G209: =G12/WinterWeekdays -> 0 | H209: =H12/WinterWeekdays -> 1028222.2 | I209: =I12/WinterWeekdays -> 1028222.2 | J209: =J12/WinterWeekdays -> 1028222.2 | K209: =K12/WinterWeekdays -> 697364.16 | L209: =L12/WinterWeekdays -> 393258.13 | ... Y209: =Y12/WinterWeekdays -> 20657778
A210: Winter | B210: h10 | C210: Hour9 | D210: Weekday | E210: =E13/WinterWeekdays -> 0 | F210: =F13/WinterWeekdays -> 86705.22 | G210: =G13/WinterWeekdays -> 0 | H210: =H13/WinterWeekdays -> 987777.78 | I210: =I13/WinterWeekdays -> 987777.78 | J210: =J13/WinterWeekdays -> 987777.78 | K210: =K13/WinterWeekdays -> 497355.74 | L210: =L13/WinterWeekdays -> 461893.16 | ... Y210: =Y13/WinterWeekdays -> 20626667
A211: Winter | B211: h11 | C211: Hour10 | D211: Weekday | E211: =E14/WinterWeekdays -> 0 | F211: =F14/WinterWeekdays -> 121770.86 | G211: =G14/WinterWeekdays -> 0 | H211: =H14/WinterWeekdays -> 1003333.3 | I211: =I14/WinterWeekdays -> 1003333.3 | J211: =J14/WinterWeekdays -> 1003333.3 | K211: =K14/WinterWeekdays -> 409552.84 | L211: =L14/WinterWeekdays -> 519027.65 | ... Y211: =Y14/WinterWeekdays -> 20595556
