Workbook
Name acres_per_hectare: #REF!
Name acres_per_million_hectares: #REF!
Name C_to_CO2: #REF!
Name C_to_CO2: #REF!
Name C_to_CO2: 44/12
Name CH4_Ar4_to_AR5: #REF!
Name CH4_to_CO2e: #REF!
Name dollars_2009_2012: #REF!
Name gal_per_barrel: #REF!
Name grams_per_ton: #REF!
Name HHV_Adjust: #REF!
Name IQ_CH: 110000
Name IQ_CQ: 5000
Name IQ_CY: 10000
Name IQ_DAILY: 500000
Name IQ_FH: 100000
Name IQ_FQ: 500
Name IQ_FY: 1000
Name IQ_LTM: 2000
Name IQ_MONTH: 15000
Name IQ_NTM: 6000
Name IQ_WEEK: 50000
Name IQ_YTD: 3000
Name metricton_to_shortton: #REF!
Name million: #REF!
Name N2O_to_CO2e: #REF!
Name unit_conv: #REF!

Sheet About
A1: ICoLUPpUA Implementation Cost of Land Use Policies per Unit Area
A3: Source: | B3: Comisión Nacional Forestal (CONAFOR)
B4: 2023
B5: Costos de referencia para reforestación, restauración y su mantenimiento
B6: https://dof.gob.mx/nota_detalle.php?codigo=5682057&fecha=08/03/2023#gsc.tab=0
B7: Publicado en DOF
A9: Notes
A10: In 2023, land compensation costs were published with updated reference costs for reforestation, restoration and maintenance.
A12: This variable is for the costs to maintain lands previously affected by one of the
A13: land use policies (such as "Afforestation/Reforestation") and thereby
A14: avoid emission of sequestered CO2.
A16: This variable is NOT for use with the Improved Forest Management policy,
A17: as that policy must be repeated every year in order to obtain carbon benefits
A18: in that year. Its cost is handled in the "Implementation Cost of Land Use
A19: Policies per Unit Area" variable.
A21: Both new forests (from afforestation/reforestation) and forests set aside from
A22: timber harvesting need to be managed.
A24: Currency Year
A25: We converted 2023 pesos to usd and then to 2012 usd.

Sheet Updated costs 2023
A1: ACUERDO MEDIANTE EL CUAL SE EXPIDEN LOS COSTOS DE REFERENCIA PARA LA
A2: COMPENSACIÓN AMBIENTAL POR CAMBIO DE USO DE SUELO EN TERRENOS FORESTALES Y LA
A3: METODOLOGÍA PARA SU ESTIMACIÓN
A4: Artículo 1.- Los costos de referencia para actividades de reforestación o restauración y su mantenimiento por concepto de compensación ambiental por Cambio de Uso del Suelo en Terrenos Forestales son los siguientes:
P6: Cuadro 5.
P7: COSTOS UNITARIOS DE ACTIVIDADES PARA REFORESTACIÓN
B8: Concepto | C8: Costos de referencia, en pesos por hectárea, para las diferentes zonas | P8: O RESTAURACIÓN Y SU MANTENIMIENTO.
C9: ecológicas
C10: Templada | D10: Tropical | E10: Árida | F10: Zona inundable o transición | P10: Actividad | Q10: Unidad de Medida | R10: Costo Unitario ($)
F11: tierra mar (humedales) | P11: Cercado con postes de madera | Q11: Km | R11: 57495.3
B12: Actividades y obras de restauración o reforestación y su mantenimiento. | C12: 58647.44 | D12: 44382.98 | E12: 32714.84 | F12: 76880 | P12: Brechas corta fuego | Q12: Km | R12: 7987.7
P13: Zanja bordo manual | Q13: M | R13: 29.83.85
P14: Zanja bordo con maquinaria | Q14: M | R14: 15.18
P15: Roturación con bulldozer | Q15: M | R15: 8.16
P16: Zampeado seco | Q16: metro cuadrado (m2) | R16: 169.45
B17: Cuadro 11. | K17: SECCIÓN III. | P17: Apertura de canales | Q17: metro cubico (m3) | R17: 434.47
B18: COSTOS DE REFERENCIA PARA REFORESTACIÓN O RESTAURACIÓN Y SU MANTENIMIENTO PARA | K18: COSTOS HORARIOS DE MANO DE OBRA. | P18: Terrazas individuales | Q18: Pieza | R18: 12.92
B19: COMPENSACIÓN AMBIENTAL POR CAMBIO DE USO DE SUELO EN TERRENOS FORESTALES. | K19: Profesión u Oficio | L19: Salario real ($) | M19: Costo horario ($) | P19: Reforestación con apertura de cepa común de 20 cm de diámetro por 30 cm de profundidad. | Q19: Pieza | R19: 7.89
B20: Concepto. | C20: Costos de referencia, en pesos por hectárea, para las diferentes zonas | K20: Jornalero o Peón. | L20: 300.68 | M20: 37.58 | P20: Reforestación usando pala plantadora | Q20: Pieza | R20: 3.32
C21: ecológicas | K21: Brigada de topografía (topógrafo y estadalero). | L21: 1275.67 | M21: 159.46 | P21: Reforestación con pala plantadora en manglares | Q21: Pieza | R21: 5.19
C22: Templada | D22: Tropical | E22: Árida | F22: Zona inundable o transición tierra | K22: Brigada de campo (proyectista y ayudante). | L22: 1952.55 | M22: 244.07 | P22: Producción planta ciclo corto | Q22: Pieza | R22: 4.5
F23: mar (humedales) | K23: Asesoría técnica especializada para supervisión de vivero forestal. | L23: 1301.7 | M23: 162.71 | P23: Producción planta ciclo largo | Q23: Pieza | R23: 6
B24: Actividades y obras de restauración | C24: 58647.44 | D24: 44382.98 | E24: 32714.84 | F24: 76880 | K24: Los cargos por mano de obra se calculan multiplicando el costo de la mano de obra (especializada y no especializada) requerida para la realización de la actividad, por el consumo de mano de obra de la actividad o práctica que se va a realizar. | P24: Transporte de planta | Q24: Pieza | R24: 0.55
B25: o reforestación y su mantenimiento. | K25: Para el caso de las actividades realizadas con maquinaria los valores se calcularon empleando las fórmulas establecidas en el Reglamento de la Ley de Obras Públicas y Servicios Relacionados con las Mismas, a continuación se muestra un ejemplo de dichos cálculos: | P25: Deshierbe circular en terrazas individuales | Q25: Pieza | R25: 8.34
P26: Asesoría técnica | Q26: ha | R26: 2730
B30: Cuadro 7. | K30: Cuadro 8.
B31: CONCENTRADO DE ACTIVIDADES DE REFORESTACIÓN O RESTAURACIÓN Y SU MANTENIMIENTO | K31: CONCENTRADO DE ACTIVIDADES DE REFORESTACIÓN O RESTAURACIÓN Y SU MANTENIMIENTO
B32: PARA COMPENSACIÓN AMBIENTAL POR CAMBIO DE USO DEL SUELO EN TERRENOS | K32: PARA COMPENSACIÓN AMBIENTAL POR CAMBIO DE USO DEL SUELO EN TERRENOS
B33: FORESTALES PARA EL ECOSISTEMA ÁRIDO Y SEMIÁRIDO. | K33: FORESTALES PARA EL ECOSISTEMA TEMPLADO FRÍO.
B34: Tipo de actividad | C34: Actividad específica | D34: Unidad de | E34: Costo | F34: Cantidad | G34: Costo Total | K34: Tipo de actividad | L34: Actividad específica | M34: Unidad de | N34: Costo | O34: Cantidad | P34: Costo ($)
D35: medida | E35: Unitario ($) | F35: mínima por | G35: ($) | M35: medida | N35: Unitario | O35: mínima (ha)
F36: hectárea | N36: ($)
B37: Restauración de suelos | C37: Zanja bordo con maquinaria | D37: M | E37: 15.18 | F37: 1000 | G37: 15181.97 | K37: Restauración de suelos | L37: Terrazas o zanjas a nivel construidas manualmente. | M37: m | N37: 27.85 | O37: 660 | P37: 18381
B38: Reforestación | C38: Producción de planta | D38: Planta | E38: 4.5 | F38: 400 | G38: 1800 | K38: Restauración de suelos | L38: Terrazas individuales | M38: Pieza | N38: 12.92 | O38: 880 | P38: 11369.6
C39: Transporte de planta | D39: Planta | E39: 0.55 | F39: 400 | G39: 221.47 | K39: Reforestación | L39: Producción de planta | M39: Planta | N39: 6 | O39: 1100 | P39: 6600
C40: Reforestación mediante cepa común | D40: Planta | E40: 7.89 | F40: 400 | G40: 3154.12 | K40: Transporte de planta | L40: Planta | M40: 0.55 | N40: 1100 | O40: 605
B41: Mantenimiento 1er año. | C41: Producción de planta | D41: Planta | E41: 4.5 | F41: 200 | G41: 900 | K41: Reforestación con pala plantadora | L41: Planta | M41: 3.32 | N41: 1100 | O41: 3652
A42: =SUM(G41:G43) -> 2587.8 | C42: Transporte de planta | D42: Planta | E42: 0.55 | F42: 200 | G42: 110.74 | K42: Mantenimiento 1er año. | L42: Producción de planta para replante | M42: Planta | N42: 6 | O42: 550 | P42: 3300
C43: Reforestación mediante cepa común | D43: Pieza | E43: 7.89 | F43: 200 | G43: 1577.06 | J43: =SUM(P42:P44) -> 5428.5 | L43: Transporte de planta de replante | M43: Planta | N43: 0.55 | O43: 550 | P43: 302.5
B44: Mantenimiento 2do año. | C44: Producción de planta | D44: Planta | E44: 4.5 | F44: 120 | G44: 540 | L44: Reforestación de la planta de replante con pala plantadora. | M44: Planta | N44: 3.32 | O44: 550 | P44: 1826
...

Sheet Cost_DATA
A1: Source: | B1: https://dof.gob.mx/nota_detalle.php?codigo=5682057&fecha=08/03/2023&print=true
B2: https://dof.gob.mx/nota_detalle.php?codigo=5682057&fecha=08/03/2023#gsc.tab=0
A4: ACUERDO MEDIANTE EL CUAL SE EXPIDEN LOS COSTOS DE REFERENCIA PARA LA
A5: COMPENSACIÓN AMBIENTAL POR CAMBIO DE USO DE SUELO EN TERRENOS FORESTALES Y LA
A6: METODOLOGÍA PARA SU ESTIMACIÓN
A7: Artículo 1.- Los costos de referencia para actividades de reforestación o restauración y su mantenimiento por concepto de compensación ambiental por Cambio de Uso del Suelo en Terrenos Forestales son los siguientes:
K9: SECCIÓN III. | Q9: Cuadro 5. | V9: Cuadro 8. | AD9: Cuadro 9. | AL9: Cuadro 10. | AT9: Cuadro 11.
K10: COSTOS HORARIOS DE MANO DE OBRA. | Q10: COSTOS UNITARIOS DE ACTIVIDADES PARA REFORESTACIÓN | V10: CONCENTRADO DE ACTIVIDADES DE REFORESTACIÓN O RESTAURACIÓN Y SU MANTENIMIENTO | AD10: CONCENTRADO DE ACTIVIDADES DE REFORESTACIÓN O RESTAURACIÓN Y SU MANTENIMIENTO | AL10: CONCENTRADO DE ACTIVIDADES DE REFORESTACIÓN O RESTAURACIÓN Y SU MANTENIMIENTO | AT10: COSTOS DE REFERENCIA PARA REFORESTACIÓN O RESTAURACIÓN Y SU MANTENIMIENTO PARA
B11: Concepto | C11: Costos de referencia, en pesos por hectárea, para las diferentes zonas | K11: Profesión u Oficio | L11: Salario real ($) | M11: Costo horario ($) | Q11: O RESTAURACIÓN Y SU MANTENIMIENTO. | V11: PARA COMPENSACIÓN AMBIENTAL POR CAMBIO DE USO DEL SUELO EN TERRENOS | AD11: PARA COMPENSACIÓN AMBIENTAL POR CAMBIO DE USO DEL SUELO EN TERRENOS | AL11: PARA COMPENSACIÓN AMBIENTAL POR CAMBIO DE USO DEL SUELO EN TERRENOS | AT11: COMPENSACIÓN AMBIENTAL POR CAMBIO DE USO DE SUELO EN TERRENOS FORESTALES.
C12: ecológicas | K12: Jornalero o Peón. | L12: 300.68 | M12: 37.58 | V12: FORESTALES PARA EL ECOSISTEMA TEMPLADO FRÍO. | AD12: FORESTALES PARA EL ECOSISTEMA TROPICAL. | AL12: FORESTALES PARA LA ZONA DE HUMEDALES O TRANSICIÓN TIERRA MAR. | AT12: Concepto. | AU12: Costos de referencia, en pesos por hectárea, para las diferentes zonas
B13: Templada | C13: Tropical | D13: Árida | E13: Zona inundable o transición | K13: Brigada de topografía (topógrafo y estadalero). | L13: 1275.67 | M13: 159.46 | Q13: Actividad | R13: Unidad de Medida | S13: Costo Unitario ($) | V13: Tipo de actividad | W13: Actividad específica | X13: Unidad de | Y13: Costo | Z13: Cantidad | AA13: Costo ($) | AD13: Tipo de actividad | AE13: Actividad específica | AF13: Unidad de | AG13: Costo | AH13: Cantidad | AI13: Costo ($) | AU13: ecológicas
E14: tierra mar (humedales) | K14: Brigada de campo (proyectista y ayudante). | L14: 1952.55 | M14: 244.07 | Q14: Cercado con postes de madera | R14: Km | S14: 57495.3 | X14: medida | Y14: Unitario | Z14: mínima (ha) | AF14: medida | AG14: Unitario ($) | AH14: mínima ($) | AL14: Tipo de actividad | AM14: Actividad específica | AN14: Unidad de | AO14: Costo | AP14: Cantidad | AQ14: Costo ($) | AT14: Templada | AU14: Tropical | AV14: Árida | AW14: Zona inundable o transición tierra
B15: Actividades y obras de restauración o reforestación y su mantenimiento. | C15: 58647.44 | D15: 44382.98 | E15: 32714.84 | F15: 76880 | K15: Asesoría técnica especializada para supervisión de vivero forestal. | L15: 1301.7 | M15: 162.71 | Q15: Brechas corta fuego | R15: Km | S15: 7987.7 | Y15: ($) | AD15: Restauración de suelos | AE15: Terrazas individuales para reforestación. | AF15: Piezas | AG15: 12.92 | AH15: 417 | AI15: 5387.64 | AN15: medida | AO15: Unitario ($) | AP15: mínima ($) | AW15: mar (humedales)
K16: Los cargos por mano de obra se calculan multiplicando el costo de la mano de obra (especializada y no especializada) requerida para la realización de la actividad, por el consumo de mano de obra de la actividad o práctica que se va a realizar. | Q16: Zanja bordo manual | R16: M | S16: 29.83.85 | V16: Restauración de suelos | W16: Terrazas o zanjas a nivel construidas manualmente. | X16: m | Y16: 27.85 | Z16: 660 | AA16: 18381 | AD16: Reforestación | AE16: Producción de planta | AF16: Planta | AG16: 4.5 | AH16: 625 | AI16: 2812.5 | AL16: Reforestación | AM16: Terrazas individuales | AN16: Pieza | AO16: 12.92 | AP16: 2500 | AQ16: 32300 | AT16: Actividades y obras de restauración | AU16: 58647.44 | AV16: 44382.98 | AW16: 32714.84 | AX16: 76880
K17: Para el caso de las actividades realizadas con maquinaria los valores se calcularon empleando las fórmulas establecidas en el Reglamento de la Ley de Obras Públicas y Servicios Relacionados con las Mismas, a continuación se muestra un ejemplo de dichos cálculos: | Q17: Zanja bordo con maquinaria | R17: M | S17: 15.18 | V17: Restauración de suelos | W17: Terrazas individuales | X17: Pieza | Y17: 12.92 | Z17: 880 | AA17: 11369.6 | AD17: Transporte de planta | AE17: Planta | AF17: 0.55 | AG17: 625 | AH17: 343.75 | AL17: Producción de planta | AM17: Planta | AN17: 4.5 | AO17: 2500 | AP17: 11250 | AT17: o reforestación y su mantenimiento.
Q18: Roturación con bulldozer | R18: M | S18: 8.16 | V18: Reforestación | W18: Producción de planta | X18: Planta | Y18: 6 | Z18: 1100 | AA18: 6600 | AD18: Reforestación a cepa común | AE18: Planta | AF18: 7.89 | AG18: 625 | AH18: 4931.25 | AL18: Transporte de planta | AM18: Planta | AN18: 0.55 | AO18: 2500 | AP18: 1375
Q19: Zampeado seco | R19: metro cuadrado (m2) | S19: 169.45 | V19: Transporte de planta | W19: Planta | X19: 0.55 | Y19: 1100 | Z19: 605 | AD19: Mantenimiento 1er año. | AE19: Producción de planta para replante | AF19: Planta | AG19: 4.5 | AH19: 312 | AI19: 1404 | AL19: Reforestación | AM19: Planta | AN19: 3.32 | AO19: 2500 | AP19: 8300
B20: Cuadro 11. | Q20: Apertura de canales | R20: metro cubico (m3) | S20: 434.47 | V20: Reforestación con pala plantadora | W20: Planta | X20: 3.32 | Y20: 1100 | Z20: 3652 | AD20: Transporte de planta para replante | AE20: Planta | AF20: 0.55 | AG20: 312 | AH20: 171.6 | AL20: Mantenimiento 1er año. | AM20: Producción de planta para replante | AN20: Planta | AO20: 4.5 | AP20: 750 | AQ20: 5625
B21: COSTOS DE REFERENCIA PARA REFORESTACIÓN O RESTAURACIÓN Y SU MANTENIMIENTO PARA | Q21: Terrazas individuales | R21: Pieza | S21: 12.92 | V21: Mantenimiento 1er año. | W21: Producción de planta para replante | X21: Planta | Y21: 6 | Z21: 550 | AA21: 3300 | AD21: Reforestación de la planta | AE21: Planta | AF21: 7.89 | AG21: 312 | AH21: 2461.68 | AL21: Transporte de planta de replante | AM21: Planta | AN21: 0.55 | AO21: 750 | AP21: 687.5
B22: COMPENSACIÓN AMBIENTAL POR CAMBIO DE USO DE SUELO EN TERRENOS FORESTALES. | Q22: Reforestación con apertura de cepa común de 20 cm de diámetro por 30 cm de profundidad. | R22: Pieza | S22: 7.89 | V22: Transporte de planta de replante | W22: Planta | X22: 0.55 | Y22: 550 | Z22: 302.5 | AD22: Deshierbe en terrazas individuales | AE22: Deshierbe | AF22: 8.34 | AG22: 625 | AH22: 5212.5 | AL22: Reforestación de la planta de replante. | AM22: Planta | AN22: 3.32 | AO22: 750 | AP22: 4150
B23: Concepto. | C23: Costos de referencia, en pesos por hectárea, para las diferentes zonas | Q23: Reforestación usando pala plantadora | R23: Pieza | S23: 3.32 | V23: Reforestación de la planta de replante con pala plantadora. | W23: Planta | X23: 3.32 | Y23: 550 | Z23: 1826 | AD23: Mantenimiento 2do año | AE23: Producción de planta para replante | AF23: Planta | AG23: 4.5 | AH23: 188 | AI23: 846 | AL23: Mantenimiento 2do año. | AM23: Producción de planta para replante | AN23: Planta | AO23: 4.5 | AP23: 500 | AQ23: 3375
C24: ecológicas | Q24: Reforestación con pala plantadora en manglares | R24: Pieza | S24: 5.19 | V24: Mantenimiento 2do año. | W24: Producción de planta para replante | X24: Planta | Y24: 6 | Z24: 330 | AA24: 1980 | AD24: Transporte de planta para replante | AE24: Planta | AF24: 0.55 | AG24: 188 | AH24: 103.4 | AL24: Transporte de planta de replante | AM24: Planta | AN24: 0.55 | AO24: 500 | AP24: 412.5
B25: Templada | C25: Tropical | D25: Árida | E25: Zona inundable o transición tierra | Q25: Producción planta ciclo corto | R25: Pieza | S25: 4.5 | V25: Transporte de planta de replante | W25: Planta | X25: 0.55 | Y25: 330 | Z25: 181.5 | AD25: Reforestación de la planta | AE25: Planta | AF25: 7.89 | AG25: 188 | AH25: 1483.32 | AL25: Reforestación de la planta de replante. | AM25: Planta | AN25: 3.32 | AO25: 500 | AP25: 2490
E26: mar (humedales) | Q26: Producción planta ciclo largo | R26: Pieza | S26: 6 | V26: Reforestación de la planta de replante con pala plantadora. | W26: Planta | X26: 3.32 | Y26: 330 | Z26: 1095.6 | AD26: Deshierbe en terrazas individuales | AE26: Deshierbe | AF26: 8.34 | AG26: 625 | AH26: 5212.5 | AL26: Mantenimiento 3er año. | AM26: Producción de planta para replante | AN26: Planta | AO26: 4.5 | AP26: 250 | AQ26: 3375
B27: Actividades y obras de restauración | C27: 58647.44 | D27: 44382.98 | E27: 32714.84 | F27: 76880 | Q27: Transporte de planta | R27: Pieza | S27: 0.55 | V27: Mantenimiento 3er año. | W27: Producción de planta para replante | X27: Planta | Y27: 6 | Z27: 220 | AA27: 1320 | AD27: Mantenimiento 3er año. | AE27: Producción de planta para replante | AF27: Planta | AG27: 4.5 | AH27: 125 | AI27: 562.5 | AL27: Transporte de planta de replante | AM27: Planta | AN27: 0.55 | AO27: 250 | AP27: 412.5
B28: o reforestación y su mantenimiento. | Q28: Deshierbe circular en terrazas individuales | R28: Pieza | S28: 8.34 | V28: Transporte de planta de replante | W28: Planta | X28: 0.55 | Y28: 220 | Z28: 121 | AD28: Transporte de planta para replante | AE28: Planta | AF28: 0.55 | AG28: 125 | AH28: 68.75 | AL28: Reforestación de la planta de replante. | AM28: Planta | AN28: 3.32 | AO28: 250 | AP28: 2490
Q29: Asesoría técnica | R29: ha | S29: 2730 | V29: Reforestación de la planta de replante con pala plantadora. | W29: Planta | X29: 3.32 | Y29: 220 | Z29: 730.4 | AD29: Reforestación de la planta | AE29: Planta | AF29: 7.89 | AG29: 125 | AH29: 986.25 | AL29: Asistencia técnica | AM29: Asesoría técnica | AN29: Ha | AO29: 2730 | AP29: 1 | AQ29: 2730
V30: Protección | W30: Brechas cortafuego | X30: km | Y30: 7987.7 | Z30: 0.068 | AA30: 543.16 | AD30: Deshierbe en terrazas individuales | AE30: Deshierbe | AF30: 8.34 | AG30: 625 | AH30: 5212.5 | AL30: Total | AM30: 76880
V31: Cercado | W31: km | X31: 57495.3 | Y31: 0.068 | Z31: 3909.68 | AD31: Protección | AE31: Brechas cortafuego | AF31: Km | AG31: 7987.7 | AH31: 0.068 | AI31: 543.16
V32: Asistencia técnica | W32: Asesoría técnica | X32: Hectárea | Y32: 2730 | Z32: 1 | AA32: 2730 | AD32: Cercado | AE32: Km | AF32: 57495.3 | AG32: 0.068 | AH32: 3909.68
V33: Costo total | W33: 58647.44 | AD33: Asistencia técnica | AE33: Asesoría técnica | AF33: Hectárea | AG33: 2730 | AH33: 1 | AI33: 2730
AD34: Costo total | AE34: 44382.98
A40: Cuadro 1.
A41: AGRUPACIÓN DE LOS TIPOS DE VEGETACIÓN DE LA SERIE VII DE INEGI EN CUATRO
A42: ECOSISTEMAS, USADOS PARA LA DEFINICIÓN DE LOS COSTOS DE REFORESTACIÓN O
A43: RESTAURACIÓN Y SU MANTENIMIENTO PARA COMPENSACIÓN AMBIENTAL POR CAMBIO DE USO
A44: DEL SUELO EN TERRENOS FORESTALES.
A45: Ecosistema | B45: Tipos de vegetación dominante según la Serie II del INEGI (incluye la | C45: Grupo Climático
B46: vegetación secundaria de los mismos) | C46: Dominante, según
C47: Köppen modificado
...

Sheet Deforestation by type
A1: Source: | B1: https://snmf.cnf.gob.mx/deforestacion/
B4: DEFORESTACIÓN POR TIPO DE ECORREGIÓN PROMEDIO ANUAL 2001-2023
B6: ECORREGIÓN | C6: DEFORESTACIÓN (ha/año)
B7: California Mediterránea | C7: 2472 | F7: Árido/semiárido | G7: =C7+C8-G10 -> 5602.36 | H7: =G7/$G$11 -> 0.026978003
B8: Desiertos de América del Norte | C8: 5207 | F8: Templado frío | G8: =C13+C9+C10 -> 57282 | H8: =G8/$G$11 -> 0.27583982
B9: Elevaciones Semiáridas Meridionales | C9: 9603 | F9: Tropical | G9: =C11+C12 -> 142703 | H9: =G9/$G$11 -> 0.68718218
B10: Grandes Planicies | C10: 12188 | F10: Humedal | G10: 2076.64 | H10: =G10/$G$11 -> 0.01
B11: Selvas Cálido-Húmedas | C11: 86701 | G11: =SUM(G7:G10) -> 207664
B12: Selvas Cálido-Secas | C12: 56002
B13: Sierras Templadas | C13: 35491
C15: =SUM(C7:C13) -> 207664

Sheet MXN to USD
A1: Tipo de cambio para solventar obligaciones denominadas en dólares de los EE.UU.A., pagaderas en la República Mexicana
A2: http://www.banxico.org.mx/portal-mercado-cambiario/
B4: AVERAGE PER YEAR
B5: Year | C5: MXN/USD
B6: 2006 | C6: =SUMIF($C$31:$C$4564,B6,$F$31:$F$4564)/COUNTIF($C$31:$C$4564,B6) -> 10.901017
B7: 2007 | C7: =SUMIF($C$31:$C$4564,B7,$F$31:$F$4564)/COUNTIF($C$31:$C$4564,B7) -> 10.926903
B8: 2008 | C8: =SUMIF($C$31:$C$4564,B8,$F$31:$F$4564)/COUNTIF($C$31:$C$4564,B8) -> 11.138302
B9: 2009 | C9: =SUMIF($C$31:$C$4564,B9,$F$31:$F$4564)/COUNTIF($C$31:$C$4564,B9) -> 13.509501
B10: 2010 | C10: =SUMIF($C$31:$C$4564,B10,$F$31:$F$4564)/COUNTIF($C$31:$C$4564,B10) -> 12.636678
B11: 2011 | C11: =SUMIF($C$31:$C$4564,B11,$F$31:$F$4564)/COUNTIF($C$31:$C$4564,B11) -> 12.427293
B12: 2012 | C12: =SUMIF($C$31:$C$4564,B12,$F$31:$F$4564)/COUNTIF($C$31:$C$4564,B12) -> 13.168532
B13: 2013 | C13: =SUMIF($C$31:$C$4564,B13,$F$31:$F$4564)/COUNTIF($C$31:$C$4564,B13) -> 12.767464
B14: 2014 | C14: =SUMIF($C$31:$C$4564,B14,$F$31:$F$4564)/COUNTIF($C$31:$C$4564,B14) -> 13.29829
B15: 2015 | C15: =SUMIF($C$31:$C$4564,B15,$F$31:$F$4564)/COUNTIF($C$31:$C$4564,B15) -> 15.854176
B16: 2016 | C16: =SUMIF($C$31:$C$4564,B16,$F$31:$F$4564)/COUNTIF($C$31:$C$4564,B16) -> 18.656701
B17: 2017 | C17: =SUMIF($C$31:$C$4564,B17,$F$31:$F$4564)/COUNTIF($C$31:$C$4564,B17) -> 18.929111
B18: 2018 | C18: =SUMIF($C$31:$C$4564,B18,$F$31:$F$4564)/COUNTIF($C$31:$C$4564,B18) -> 18.822825
B19: 2019 | C19: =SUMIF($J$31:$J$4564,B19,$M$31:$M$4564)/COUNTIF($J$31:$J$4564,B19) -> 19.26177
B20: 2020 | C20: =SUMIF($J$31:$J$4564,B20,$M$31:$M$4564)/COUNTIF($J$31:$J$4564,B20) -> 21.49609
B21: 2021 | C21: =SUMIF($J$31:$J$4564,B21,$M$31:$M$4564)/COUNTIF($J$31:$J$4564,B21) -> 20.281794
B22: 2022 | C22: =SUMIF($J$31:$J$4564,B22,$M$31:$M$4564)/COUNTIF($J$31:$J$4564,B22) -> 20.125
B23: 2023 | C23: =SUMIF($J$31:$J$4564,B23,$M$31:$M$4564)/COUNTIF($J$31:$J$4564,B23) -> 17.762
B24: 2024 | C24: =SUMIF($J$31:$J$4564,B24,$M$31:$M$4564)/COUNTIF($J$31:$J$4564,B24) -> 18.302356
B25: 2025 | C25: =SUMIF($J$31:$J$4564,B25,$M$31:$M$4564)/COUNTIF($J$31:$J$4564,B25) -> 20.518102
A27: 2006-2018 | H27: 2019-2024 | I27: https://www.banxico.org.mx/tipcamb/tipCamMIAction.do?idioma=sp
A28: Información diaria | H28: Información diaria
A29: Fecha | B29: Fecha corregida | C29: Año | D29: Determinación | E29: Publicación DOF | F29: Para solventar obligaciones | H29: Fecha | I29: Fecha corregida | J29: Año | K29: Determinación | L29: Publicación DOF | M29: Para solventar obligaciones
A31: 01/01/2006 | B31: =DATE(RIGHT(A31,4),LEFT(RIGHT(A31,7),2),LEFT(A31,2)) -> 38718 | C31: =YEAR(B31) -> 2006 | D31: N/E | E31: N/E | F31: 10.7109 | H31: 01/01/2019 | I31: =DATE(RIGHT(H31,4),LEFT(RIGHT(A31,7),2),LEFT(A31,2)) -> 43466 | J31: =YEAR(I31) -> 2019 | K31: N/E | L31: N/E | M31: 19.6566
A32: 02/01/2006 | B32: =DATE(RIGHT(A32,4),LEFT(RIGHT(A32,7),2),LEFT(A32,2)) -> 38719 | C32: =YEAR(B32) -> 2006 | D32: 10.6253 | E32: 10.6344 | F32: 10.7109 | H32: 02/01/2019 | I32: =DATE(RIGHT(H32,4),LEFT(RIGHT(A32,7),2),LEFT(A32,2)) -> 43467 | J32: =YEAR(I32) -> 2019 | K32: 19.5878 | L32: 19.6512 | M32: 19.6566
A33: 03/01/2006 | B33: =DATE(RIGHT(A33,4),LEFT(RIGHT(A33,7),2),LEFT(A33,2)) -> 38720 | C33: =YEAR(B33) -> 2006 | D33: 10.6455 | E33: 10.6253 | F33: 10.6344 | H33: 03/01/2019 | I33: =DATE(RIGHT(H33,4),LEFT(RIGHT(A33,7),2),LEFT(A33,2)) -> 43468 | J33: =YEAR(I33) -> 2019 | K33: 19.6073 | L33: 19.5878 | M33: 19.6512
A34: 04/01/2006 | B34: =DATE(RIGHT(A34,4),LEFT(RIGHT(A34,7),2),LEFT(A34,2)) -> 38721 | C34: =YEAR(B34) -> 2006 | D34: 10.5815 | E34: 10.6455 | F34: 10.6253 | H34: 04/01/2019 | I34: =DATE(RIGHT(H34,4),LEFT(RIGHT(A34,7),2),LEFT(A34,2)) -> 43469 | J34: =YEAR(I34) -> 2019 | K34: 19.4902 | L34: 19.6073 | M34: 19.5878
A35: 05/01/2006 | B35: =DATE(RIGHT(A35,4),LEFT(RIGHT(A35,7),2),LEFT(A35,2)) -> 38722 | C35: =YEAR(B35) -> 2006 | D35: 10.5907 | E35: 10.5815 | F35: 10.6455 | H35: 05/01/2019 | I35: =DATE(RIGHT(H35,4),LEFT(RIGHT(A35,7),2),LEFT(A35,2)) -> 43470 | J35: =YEAR(I35) -> 2019 | K35: N/E | L35: N/E | M35: 19.6073
A36: 06/01/2006 | B36: =DATE(RIGHT(A36,4),LEFT(RIGHT(A36,7),2),LEFT(A36,2)) -> 38723 | C36: =YEAR(B36) -> 2006 | D36: 10.5726 | E36: 10.5907 | F36: 10.5815 | H36: 06/01/2019 | I36: =DATE(RIGHT(H36,4),LEFT(RIGHT(A36,7),2),LEFT(A36,2)) -> 43471 | J36: =YEAR(I36) -> 2019 | K36: N/E | L36: N/E | M36: 19.6073
A37: 07/01/2006 | B37: =DATE(RIGHT(A37,4),LEFT(RIGHT(A37,7),2),LEFT(A37,2)) -> 38724 | C37: =YEAR(B37) -> 2006 | D37: N/E | E37: N/E | F37: 10.5907 | H37: 07/01/2019 | I37: =DATE(RIGHT(H37,4),LEFT(RIGHT(A37,7),2),LEFT(A37,2)) -> 43472 | J37: =YEAR(I37) -> 2019 | K37: 19.3208 | L37: 19.4902 | M37: 19.6073
A38: 08/01/2006 | B38: =DATE(RIGHT(A38,4),LEFT(RIGHT(A38,7),2),LEFT(A38,2)) -> 38725 | C38: =YEAR(B38) -> 2006 | D38: N/E | E38: N/E | F38: 10.5907 | H38: 08/01/2019 | I38: =DATE(RIGHT(H38,4),LEFT(RIGHT(A38,7),2),LEFT(A38,2)) -> 43473 | J38: =YEAR(I38) -> 2019 | K38: 19.3479 | L38: 19.3208 | M38: 19.4902
A39: 09/01/2006 | B39: =DATE(RIGHT(A39,4),LEFT(RIGHT(A39,7),2),LEFT(A39,2)) -> 38726 | C39: =YEAR(B39) -> 2006 | D39: 10.5446 | E39: 10.5726 | F39: 10.5907 | H39: 09/01/2019 | I39: =DATE(RIGHT(H39,4),LEFT(RIGHT(A39,7),2),LEFT(A39,2)) -> 43474 | J39: =YEAR(I39) -> 2019 | K39: 19.2456 | L39: 19.3479 | M39: 19.3208
A40: 10/01/2006 | B40: =DATE(RIGHT(A40,4),LEFT(RIGHT(A40,7),2),LEFT(A40,2)) -> 38727 | C40: =YEAR(B40) -> 2006 | D40: 10.599 | E40: 10.5446 | F40: 10.5726 | H40: 10/01/2019 | I40: =DATE(RIGHT(H40,4),LEFT(RIGHT(A40,7),2),LEFT(A40,2)) -> 43475 | J40: =YEAR(I40) -> 2019 | K40: 19.1714 | L40: 19.2456 | M40: 19.3479
A41: 11/01/2006 | B41: =DATE(RIGHT(A41,4),LEFT(RIGHT(A41,7),2),LEFT(A41,2)) -> 38728 | C41: =YEAR(B41) -> 2006 | D41: 10.6097 | E41: 10.599 | F41: 10.5446 | H41: 11/01/2019 | I41: =DATE(RIGHT(H41,4),LEFT(RIGHT(A41,7),2),LEFT(A41,2)) -> 43476 | J41: =YEAR(I41) -> 2019 | K41: 19.1236 | L41: 19.1714 | M41: 19.2456
A42: 12/01/2006 | B42: =DATE(RIGHT(A42,4),LEFT(RIGHT(A42,7),2),LEFT(A42,2)) -> 38729 | C42: =YEAR(B42) -> 2006 | D42: 10.5732 | E42: 10.6097 | F42: 10.599 | H42: 12/01/2019 | I42: =DATE(RIGHT(H42,4),LEFT(RIGHT(A42,7),2),LEFT(A42,2)) -> 43477 | J42: =YEAR(I42) -> 2019 | K42: N/E | L42: N/E | M42: 19.1714
A43: 13/01/2006 | B43: =DATE(RIGHT(A43,4),LEFT(RIGHT(A43,7),2),LEFT(A43,2)) -> 38730 | C43: =YEAR(B43) -> 2006 | D43: 10.5752 | E43: 10.5732 | F43: 10.6097 | H43: 13/01/2019 | I43: =DATE(RIGHT(H43,4),LEFT(RIGHT(A43,7),2),LEFT(A43,2)) -> 43478 | J43: =YEAR(I43) -> 2019 | K43: N/E | L43: N/E | M43: 19.1714
...

Sheet USD 2012
A1: Year | B1: CPI-U | C1: Multiply by to get 2012 Dollars
A2: 1990 | B2: 130.7 | C2: =B$24/B2 -> 1.7594032
A3: 1991 | B3: 136.2 | C3: =B$24/B3 -> 1.6883554
A4: 1992 | B4: 140.3 | C4: =B$24/B4 -> 1.6390164
A5: 1993 | B5: 144.5 | C5: =B$24/B5 -> 1.5913772
A6: 1994 | B6: 148.2 | C6: =B$24/B6 -> 1.5516464
A7: 1995 | B7: 152.4 | C7: =B$24/B7 -> 1.5088845
A8: 1996 | B8: 156.9 | C8: =B$24/B8 -> 1.4656087
A9: 1997 | B9: 160.5 | C9: =B$24/B9 -> 1.4327352
A10: 1998 | B10: 163 | C10: =B$24/B10 -> 1.4107607
A11: 1999 | B11: 166.6 | C11: =B$24/B11 -> 1.3802761
A12: 2000 | B12: 172.2 | C12: =B$24/B12 -> 1.3353891
A13: 2001 | B13: 177.1 | C13: =B$24/B13 -> 1.2984416
... A28: 2016 | B28: 241.237 | C28: =B$24/B28 -> 0.95322857
A29: 2017 | C29: =AVERAGE(C28,C30) -> 0.93361428
A30: 2018 | C30: 0.914 | D30: 2018 to 2012 USD
A31: 2019 | C31: 0.898 | D31: 2019 to 2012 USD
A32: 2020 | C32: 0.887 | D32: 2020 to 2012 USD
A33: 2021 | C33: 0.831 | D33: 2021 to 2012 USD (est.)
A34: 2022 | C34: {=TREND($C$29:$C$33,$A$29:$A$33,A34)} -> 0.82305429 | D34: 2022 to 2012 USD (est)
A35: 2023 | C35: {=TREND($C$29:$C$33,$A$29:$A$33,A35)} -> 0.79983143 | D35: 2023 to 2012 USD (est.)

Sheet Calculations
B2: UPDATED COSTS (2023) | F2: Maintenance / Forest management | I2: Restoration | L2: Avoided deforestation
B3: Ecosystem | C3: Initial reforestation cost (2023 mxn/ha) | D3: Initial reforestation Cost (2012 usd/acre) | F3: Annual Maintenance Cost (2023 mxn/ha) | G3: Annual Maintenance Cost (2012 usd/acre) | I3: Annual Restoration Cost (2023 mxn/ha) | J3: Annual Restoration Cost (2012 usd/acre) | L3: Annual Protection Cost (2023 mxn/ha) | M3: Annual Protection Cost (2012 usd/acre)
B4: Árido/semiárido | C4: ='Updated costs 2023'!F53 -> 32714.84 | D4: =C4/$C$12/'MXN to USD'!$C$23*'USD 2012'!$C$35 -> 596.16965 | F4: =('Updated costs 2023'!A42+'Updated costs 2023'!A45+'Updated costs 2023'!A48*($C$13-2))/$C$13 -> 1242.136 | G4: =F4/$C$12/'MXN to USD'!$C$23*'USD 2012'!$C$35 -> 22.635715 | I4: =(C4-'Updated costs 2023'!A42-'Updated costs 2023'!A45-'Updated costs 2023'!A48)/$C$13+F4 -> 3996.061 | J4: =I4/$C$12/'MXN to USD'!$C$23*'USD 2012'!$C$35 -> 72.821089 | L4: ='Updated costs 2023'!G50+'Updated costs 2023'!F51 -> 4452.84 | M4: =L4/$C$12/'MXN to USD'!$C$23*'USD 2012'!$C$35 -> 81.145072
B5: Templado frío | C5: ='Updated costs 2023'!L54 -> 58647.44 | D5: =C5/$C$12/'MXN to USD'!$C$23*'USD 2012'!$C$35 -> 1068.7451 | F5: =('Updated costs 2023'!J43+'Updated costs 2023'!J46+'Updated costs 2023'!J49*($C$13-2))/$C$13 -> 2605.68 | G5: =F5/$C$12/'MXN to USD'!$C$23*'USD 2012'!$C$35 -> 47.483874 | I5: =(C5-F5)/$C$13+F5 -> 8209.856 | J5: =I5/$C$12/'MXN to USD'!$C$23*'USD 2012'!$C$35 -> 149.60999 | L5: ='Updated costs 2023'!P51+'Updated costs 2023'!O52 -> 4452.84 | M5: =L5/$C$12/'MXN to USD'!$C$23*'USD 2012'!$C$35 -> 81.145072
B6: Tropical | C6: ='Updated costs 2023'!C81 -> 44382.98 | D6: =C6/$C$12/'MXN to USD'!$C$23*'USD 2012'!$C$35 -> 808.8007 | F6: =('Updated costs 2023'!A67+'Updated costs 2023'!A71+'Updated costs 2023'!A75*($C$13-2))/$C$13 -> 7153.5 | G6: =F6/$C$12/'MXN to USD'!$C$23*'USD 2012'!$C$35 -> 130.35979 | I6: =(C6-F6)/$C$13+F6 -> 10876.448 | J6: =I6/$C$12/'MXN to USD'!$C$23*'USD 2012'!$C$35 -> 198.20388 | L6: ='Updated costs 2023'!G78+'Updated costs 2023'!F79 -> 4452.84 | M6: =L6/$C$12/'MXN to USD'!$C$23*'USD 2012'!$C$35 -> 81.145072
B7: Humedal | C7: ='Updated costs 2023'!L77 -> 76880 | D7: =C7/$C$12/'MXN to USD'!$C$23*'USD 2012'!$C$35 -> 1401.001 | F7: =('Updated costs 2023'!J68+'Updated costs 2023'!J71+'Updated costs 2023'!J74*($C$13-2))/$C$13 -> 6696 | G7: =F7/$C$12/'MXN to USD'!$C$23*'USD 2012'!$C$35 -> 122.02266 | I7: =(C7-F7)/$C$13+F7 -> 13714.4 | J7: =I7/$C$12/'MXN to USD'!$C$23*'USD 2012'!$C$35 -> 249.9205 | L7: ='Updated costs 2023'!F79 -> 3909.68 | M7: =L7/$C$12/'MXN to USD'!$C$23*'USD 2012'!$C$35 -> 71.246949
B8: Weighted average by deforestation by type
F9: =SUMPRODUCT(F4:F7,$D$15:$D$18) -> 5734.9784 | G9: =F9/$C$12/'MXN to USD'!$C$23*'USD 2012'!$C$35 -> 104.50976 | I9: =SUMPRODUCT(I4:I7,$D$15:$D$18) -> 9983.6562 | J9: =I9/$C$12/'MXN to USD'!$C$23*'USD 2012'!$C$35 -> 181.93434 | L9: =SUMPRODUCT(L4:L7,$D$15:$D$18) -> 4447.4084 | M9: =L9/$C$12/'MXN to USD'!$C$23*'USD 2012'!$C$35 -> 81.046091
B11: Conversion factors
B12: 1ha = | C12: 2.47105 | D12: acres
B13: Years to dilute initial cost | C13: 10
C14: Potential reforestation ecosystem
B15: ='Deforestation by type'!F7 -> Árido/semiárido | C15: ='Deforestation by type'!G7 -> 5602.36 | D15: ='Deforestation by type'!H7 -> 0.026978003
B16: ='Deforestation by type'!F8 -> Templado frío | C16: ='Deforestation by type'!G8 -> 57282 | D16: ='Deforestation by type'!H8 -> 0.27583982
B17: ='Deforestation by type'!F9 -> Tropical | C17: ='Deforestation by type'!G9 -> 142703 | D17: ='Deforestation by type'!H9 -> 0.68718218
B18: ='Deforestation by type'!F10 -> Humedal | C18: ='Deforestation by type'!G10 -> 2076.64 | D18: ='Deforestation by type'!H10 -> 0.01
C19: =SUM(C15:C18) -> 207664
B21: PREVIOUS DATA (2014)
B22: Ecosystem | C22: Total Maintenance Cost (2014 mxn/ha) | D22: Total Maintenance Cost (2012 usd/acre)
B23: Árido/semiárido | C23: 1163.2 | D23: =C23/$C$12/'MXN to USD'!$C$14*'USD 2012'!$C$26 -> 34.383787
B24: Templado frío | C24: 2239.6 | D24: =C24/$C$12/'MXN to USD'!$C$14*'USD 2012'!$C$26 -> 66.201797
B25: Tropical | C25: 5863.98 | D25: =C25/$C$12/'MXN to USD'!$C$14*'USD 2012'!$C$26 -> 173.33721
B26: Humedal | C26: 5090 | D26: =C26/$C$12/'MXN to USD'!$C$14*'USD 2012'!$C$26 -> 150.45863
B27: Manglar | C27: 8968.25 | D27: =C27/$C$12/'MXN to USD'!$C$14*'USD 2012'!$C$26 -> 265.09835
B28: Average | C28: =AVERAGE(C23:C27) -> 4665.006 | D28: =C28/$C$12/'MXN to USD'!$C$14*'USD 2012'!$C$26 -> 137.89595

Sheet ICoLUPpUA
B1: policy implementation cost ($ / acre)
A2: forest set asides | B2: =Calculations!G9 -> 104.50976
A3: afforestation and reforestation | B3: =Calculations!J9 -> 181.93434
A4: improved forest management | B4: =Calculations!G9 -> 104.50976
A5: avoid deforestation | B5: =Calculations!M9 -> 81.046091
A6: peatland restoration | B6: =Calculations!J7 -> 249.9205
A7: forest restoration | B7: =Calculations!J6 -> 198.20388
